{"schema_version":1,"source":"clob_ws_market","recv_ts_ns":1768250245709650446,"event_type":"book","market":"0xe51aa24ab1bbfefce466d642ad98587d13123e4ef95ec9aa73b712e775d4cbba","server_ts_ms":1768250245585,"raw":{"market":"0xe51aa24ab1bbfefce466d642ad98587d13123e4ef95ec9aa73b712e775d4cbba","asset_id":"96886111393998001968863279421729456597655847484197549086072988901191634450924","bids":[{"price":"0.01","size":"24290.24"},{"price":"0.02","size":"7594.51"},{"price":"0.03","size":"5964.69"},{"price":"0.04","size":"5411.4"},{"price":"0.05","size":"5356.39"},{"price":"0.06","size":"5328"},{"price":"0.07","size":"5039.28"},{"price":"0.08","size":"5022.7"},{"price":"0.09","size":"5320.9"},{"price":"0.1","size":"5158.44"},{"price":"0.11","size":"18.3"},{"price":"0.12","size":"30.3"},{"price":"0.13","size":"16.5"},{"price":"0.14","size":"15.8"},{"price":"0.15","size":"104.19"},{"price":"0.16","size":"24.69"},{"price":"0.17","size":"14.19"},{"price":"0.18","size":"13.8"},{"price":"0.19","size":"13.4"},{"price":"0.2","size":"38.1"},{"price":"0.21","size":"12.8"},{"price":"0.22","size":"12.6"},{"price":"0.23","size":"12.3"},{"price":"0.24","size":"22.1"},{"price":"0.25","size":"16.9"},{"price":"0.26","size":"21.8"},{"price":"0.27","size":"11.6"},{"price":"0.28","size":"11.4"},{"price":"0.29","size":"61.3"},{"price":"0.3","size":"26.2"},{"price":"0.31","size":"11.1"},{"price":"0.32","size":"11"},{"price":"0.33","size":"110.9"},{"price":"0.34","size":"10.8"},{"price":"0.35","size":"15.7"},{"price":"0.36","size":"10.6"},{"price":"0.37","size":"10.6"},{"price":"0.38","size":"22.5"},{"price":"0.39","size":"10.5"},{"price":"0.4","size":"45.4"},{"price":"0.41","size":"311.4"},{"price":"0.42","size":"820.82"},{"price":"0.43","size":"826.3"},{"price":"0.44","size":"1062.3"},{"price":"0.45","size":"582.3"},{"price":"0.46","size":"626.2"},{"price":"0.47","size":"562.2"},{"price":"0.48","size":"567.2"},{"price":"0.49","size":"573.2"},{"price":"0.5","size":"917.2"},{"price":"0.51","size":"591.2"},{"price":"0.52","size":"590.2"},{"price":"0.53","size":"567.2"},{"price":"0.54","size":"642.61"},{"price":"0.55","size":"362.97"},{"price":"0.56","size":"341.3"},{"price":"0.57","size":"320.62"},{"price":"0.58","size":"567.3"},{"price":"0.59","size":"562.4"},{"price":"0.6","size":"693.02"},{"price":"0.61","size":"625.5"},{"price":"0.62","size":"700.5"},{"price":"0.63","size":"672.32"},{"price":"0.64","size":"680.6"},{"price":"0.65","size":"536.14"},{"price":"0.66","size":"602.8"},{"price":"0.67","size":"572.9"},{"price":"0.68","size":"573"},{"price":"0.69","size":"595.1"},{"price":"0.7","size":"603.2"},{"price":"0.71","size":"1318.72"},{"price":"0.72","size":"1043.04"},{"price":"0.73","size":"663.6"},{"price":"0.74","size":"911.17"},{"price":"0.75","size":"694.3"},{"price":"0.76","size":"717.6"},{"price":"0.77","size":"1183.3"},{"price":"0.78","size":"1526.53"},{"price":"0.79","size":"1178.8"},{"price":"0.8","size":"1445.08"},{"price":"0.81","size":"1229.8"},{"price":"0.82","size":"1467.57"},{"price":"0.83","size":"1470.51"},{"price":"0.84","size":"1718.59"},{"price":"0.85","size":"1762.5"},{"price":"0.86","size":"1755.6"},{"price":"0.87","size":"1588.93"},{"price":"0.88","size":"2555.4"},{"price":"0.89","size":"1898.8"},{"price":"0.9","size":"3455.34"},{"price":"0.91","size":"2701.44"},{"price":"0.92","size":"2317.36"},{"price":"0.93","size":"1526.82"},{"price":"0.94","size":"1588.55"}],"asks":[{"price":"0.99","size":"21009.9"},{"price":"0.98","size":"6847.25"},{"price":"0.97","size":"1844.33"},{"price":"0.96","size":"292.4"},{"price":"0.95","size":"1499.79"}],"hash":"f39e92ff1a8db5306d732f0351d3133bc8d70103","timestamp":"1768250245585","event_type":"book"}}
{"schema_version":1,"source":"clob_ws_market","recv_ts_ns":1768250245720338241,"event_type":"last_trade_price","market":"0xe51aa24ab1bbfefce466d642ad98587d13123e4ef95ec9aa73b712e775d4cbba","server_ts_ms":1768250245615,"raw":{"market":"0xe51aa24ab1bbfefce466d642ad98587d13123e4ef95ec9aa73b712e775d4cbba","asset_id":"96886111393998001968863279421729456597655847484197549086072988901191634450924","price":"0.95","size":"25.55","fee_rate_bps":"1000","side":"BUY","timestamp":"1768250245615","event_type":"last_trade_price","transaction_hash":"0xf43a84b2e63299a720b0b7e0b48c9d24cf406214518d9f1aa733863ea8bffce7"}}
{"schema_version":1,"source":"clob_ws_market","recv_ts_ns":1768250245728326997,"event_type":"price_change","market":"0xe51aa24ab1bbfefce466d642ad98587d13123e4ef95ec9aa73b712e775d4cbba","server_ts_ms":1768250245685,"raw":{"market":"0xe51aa24ab1bbfefce466d642ad98587d13123e4ef95ec9aa73b712e775d4cbba","price_changes":[{"asset_id":"54232589582260339592359130012520874109228367674780084862642636038394766871668","price":"0.02","size":"5847.25","side":"BUY","hash":"8bbd6cf906e8792f77204cf8fce9afc5b30becc5","best_bid":"0.05","best_ask":"0.06"},{"asset_id":"96886111393998001968863279421729456597655847484197549086072988901191634450924","price":"0.98","size":"5847.25","side":"SELL","hash":"51218b2900419e10861b859256e8b0463f12f83c","best_bid":"0.94","best_ask":"0.95"}],"timestamp":"1768250245685","event_type":"price_change"}}
{"schema_version":1,"source":"clob_ws_market","recv_ts_ns":1768250245837387946,"event_type":"price_change","market":"0xe51aa24ab1bbfefce466d642ad98587d13123e4ef95ec9aa73b712e775d4cbba","server_ts_ms":1768250245802,"raw":{"market":"0xe51aa24ab1bbfefce466d642ad98587d13123e4ef95ec9aa73b712e775d4cbba","price_changes":[{"asset_id":"54232589582260339592359130012520874109228367674780084862642636038394766871668","price":"0.02","size":"5819.25","side":"BUY","hash":"41113e63b30d2800fb9d49a60e344e0af14dee6c","best_bid":"0.05","best_ask":"0.06"},{"asset_id":"96886111393998001968863279421729456597655847484197549086072988901191634450924","price":"0.98","size":"5819.25","side":"SELL","hash":"3d909952f81a7a79c787661b48d202b42eb54bb7","best_bid":"0.94","best_ask":"0.95"}],"timestamp":"1768250245802","event_type":"price_change"}}
{"schema_version":1,"source":"clob_ws_market","recv_ts_ns":1768250245874713039,"event_type":"price_change","market":"0xe51aa24ab1bbfefce466d642ad98587d13123e4ef95ec9aa73b712e775d4cbba","server_ts_ms":1768250245853,"raw":{"market":"0xe51aa24ab1bbfefce466d642ad98587d13123e4ef95ec9aa73b712e775d4cbba","price_changes":[{"asset_id":"54232589582260339592359130012520874109228367674780084862642636038394766871668","price":"0.02","size":"5847.25","side":"BUY","hash":"d666a3a59f676807af5589fc8bef684e69fd39d0","best_bid":"0.05","best_ask":"0.06"},{"asset_id":"96886111393998001968863279421729456597655847484197549086072988901191634450924","price":"0.98","size":"5847.25","side":"SELL","hash":"786ae80272c53ee9ba13a3d446ec7764fbe83e47","best_bid":"0.94","best_ask":"0.95"}],"timestamp":"1768250245853","event_type":"price_change"}}
{"schema_version":1,"source":"clob_ws_market","recv_ts_ns":1768250245881719329,"event_type":"price_change","market":"0xe51aa24ab1bbfefce466d642ad98587d13123e4ef95ec9aa73b712e775d4cbba","server_ts_ms":1768250245859,"raw":{"market":"0xe51aa24ab1bbfefce466d642ad98587d13123e4ef95ec9aa73b712e775d4cbba","price_changes":[{"asset_id":"54232589582260339592359130012520874109228367674780084862642636038394766871668","price":"0.07","size":"1506.82","side":"SELL","hash":"126e430d83fb9068920f0a64bb4c50e71e465127","best_bid":"0.05","best_ask":"0.06"},{"asset_id":"96886111393998001968863279421729456597655847484197549086072988901191634450924","price":"0.93","size":"1506.82","side":"BUY","hash":"232533a17a70304bf9feccf0b570c0a35e9eccbd","best_bid":"0.94","best_ask":"0.95"}],"timestamp":"1768250245859","event_type":"price_change"}}
{"schema_version":1,"source":"clob_ws_market","recv_ts_ns":1768250245895250515,"event_type":"price_change","market":"0xe51aa24ab1bbfefce466d642ad98587d13123e4ef95ec9aa73b712e775d4cbba","server_ts_ms":1768250245871,"raw":{"market":"0xe51aa24ab1bbfefce466d642ad98587d13123e4ef95ec9aa73b712e775d4cbba","price_changes":[{"asset_id":"96886111393998001968863279421729456597655847484197549086072988901191634450924","price":"0.94","size":"1576.55","side":"BUY","hash":"6ef068750b37d42189420db6a04a925d518bf726","best_bid":"0.94","best_ask":"0.95"},{"asset_id":"54232589582260339592359130012520874109228367674780084862642636038394766871668","price":"0.06","size":"1576.55","side":"SELL","hash":"80daa07fc5b8ffe1163528f74d1b9b14639bd135","best_bid":"0.05","best_ask":"0.06"}],"timestamp":"1768250245871","event_type":"price_change"}}
{"schema_version":1,"source":"clob_ws_market","recv_ts_ns":1768250245920593099,"event_type":"price_change","market":"0xe51aa24ab1bbfefce466d642ad98587d13123e4ef95ec9aa73b712e775d4cbba","server_ts_ms":1768250245898,"raw":{"market":"0xe51aa24ab1bbfefce466d642ad98587d13123e4ef95ec9aa73b712e775d4cbba","price_changes":[{"asset_id":"96886111393998001968863279421729456597655847484197549086072988901191634450924","price":"0.95","size":"1598.53","side":"SELL","hash":"e33f00d478261806092fbf69b9bca126df8481a7","best_bid":"0.94","best_ask":"0.95"},{"asset_id":"54232589582260339592359130012520874109228367674780084862642636038394766871668","price":"0.05","size":"1598.53","side":"BUY","hash":"0d80e40c85bd700150419212f42dadffa4b8b0c3","best_bid":"0.05","best_ask":"0.06"}],"timestamp":"1768250245898","event_type":"price_change"}}
{"schema_version":1,"source":"clob_ws_market","recv_ts_ns":1768250245929591534,"event_type":"price_change","market":"0xe51aa24ab1bbfefce466d642ad98587d13123e4ef95ec9aa73b712e775d4cbba","server_ts_ms":1768250245903,"raw":{"market":"0xe51aa24ab1bbfefce466d642ad98587d13123e4ef95ec9aa73b712e775d4cbba","price_changes":[{"asset_id":"96886111393998001968863279421729456597655847484197549086072988901191634450924","price":"0.99","size":"21034.9","side":"SELL","hash":"965e3f6d606e236a3aff66a303e5952df6a87a32","best_bid":"0.94","best_ask":"0.95"},{"asset_id":"54232589582260339592359130012520874109228367674780084862642636038394766871668","price":"0.01","size":"21034.9","side":"BUY","hash":"c0461c0fcd594b6c5d37a5aafa36ce588e3d2fef","best_bid":"0.05","best_ask":"0.06"}],"timestamp":"1768250245903","event_type":"price_change"}}
{"schema_version":1,"source":"clob_ws_market","recv_ts_ns":1768250245935271201,"event_type":"price_change","market":"0xe51aa24ab1bbfefce466d642ad98587d13123e4ef95ec9aa73b712e775d4cbba","server_ts_ms":1768250245905,"raw":{"market":"0xe51aa24ab1bbfefce466d642ad98587d13123e4ef95ec9aa73b712e775d4cbba","price_changes":[{"asset_id":"54232589582260339592359130012520874109228367674780084862642636038394766871668","price":"0.06","size":"1596.55","side":"SELL","hash":"29c81d520a1784775facabe5af5181c133f8518c","best_bid":"0.05","best_ask":"0.06"},{"asset_id":"96886111393998001968863279421729456597655847484197549086072988901191634450924","price":"0.94","size":"1596.55","side":"BUY","hash":"19af9abaf8cec398d54e5cc4a5b64e2855bc2a7c","best_bid":"0.94","best_ask":"0.95"}],"timestamp":"1768250245905","event_type":"price_change"}}
{"schema_version":1,"source":"clob_ws_market","recv_ts_ns":1768250245940563792,"event_type":"price_change","market":"0xe51aa24ab1bbfefce466d642ad98587d13123e4ef95ec9aa73b712e775d4cbba","server_ts_ms":1768250245906,"raw":{"market":"0xe51aa24ab1bbfefce466d642ad98587d13123e4ef95ec9aa73b712e775d4cbba","price_changes":[{"asset_id":"96886111393998001968863279421729456597655847484197549086072988901191634450924","price":"0.98","size":"5822.25","side":"SELL","hash":"5d49a97664161001b68d0ce7a76d60d48cad292f","best_bid":"0.94","best_ask":"0.95"},{"asset_id":"54232589582260339592359130012520874109228367674780084862642636038394766871668","price":"0.02","size":"5822.25","side":"BUY","hash":"1e6643e3339d3a720a25ccd0a27040a1e5a714b4","best_bid":"0.05","best_ask":"0.06"}],"timestamp":"1768250245906","event_type":"price_change"}}
{"schema_version":1,"source":"clob_ws_market","recv_ts_ns":1768250245955871215,"event_type":"price_change","market":"0xe51aa24ab1bbfefce466d642ad98587d13123e4ef95ec9aa73b712e775d4cbba","server_ts_ms":1768250245909,"raw":{"market":"0xe51aa24ab1bbfefce466d642ad98587d13123e4ef95ec9aa73b712e775d4cbba","price_changes":[{"asset_id":"54232589582260339592359130012520874109228367674780084862642636038394766871668","price":"0.03","size":"1827.9","side":"BUY","hash":"9f256b6b02fe6e59307269af5f09693ac48d26b4","best_bid":"0.05","best_ask":"0.06"},{"asset_id":"96886111393998001968863279421729456597655847484197549086072988901191634450924","price":"0.97","size":"1827.9","side":"SELL","hash":"165e0e8b7e98a51eadedfb9e2d5239d1eea3eb97","best_bid":"0.94","best_ask":"0.95"}],"timestamp":"1768250245909","event_type":"price_change"}}
{"schema_version":1,"source":"clob_ws_market","recv_ts_ns":1768250245961193354,"event_type":"price_change","market":"0xe51aa24ab1bbfefce466d642ad98587d13123e4ef95ec9aa73b712e775d4cbba","server_ts_ms":1768250245917,"raw":{"market":"0xe51aa24ab1bbfefce466d642ad98587d13123e4ef95ec9aa73b712e775d4cbba","price_changes":[{"asset_id":"54232589582260339592359130012520874109228367674780084862642636038394766871668","price":"0.05","size":"229.74","side":"BUY","hash":"dc8a18ffd8db20d485adc661120405c389b93dab","best_bid":"0.05","best_ask":"0.06"},{"asset_id":"96886111393998001968863279421729456597655847484197549086072988901191634450924","price":"0.95","size":"229.74","side":"SELL","hash":"155210b5a782da675bc07fee01473627d5ab4f29","best_bid":"0.94","best_ask":"0.95"}],"timestamp":"1768250245917","event_type":"price_change"}}
{"schema_version":1,"source":"clob_ws_market","recv_ts_ns":1768250245966505709,"event_type":"price_change","market":"0xe51aa24ab1bbfefce466d642ad98587d13123e4ef95ec9aa73b712e775d4cbba","server_ts_ms":1768250245918,"raw":{"market":"0xe51aa24ab1bbfefce466d642ad98587d13123e4ef95ec9aa73b712e775d4cbba","price_changes":[{"asset_id":"54232589582260339592359130012520874109228367674780084862642636038394766871668","price":"0.03","size":"1812.6","side":"BUY","hash":"a11d1c75bb8248bd206299158a8be6bc5a804331","best_bid":"0.05","best_ask":"0.06"},{"asset_id":"96886111393998001968863279421729456597655847484197549086072988901191634450924","price":"0.97","size":"1812.6","side":"SELL","hash":"9a1de381b720c55f83b58fa91e0dc95e04847618","best_bid":"0.94","best_ask":"0.95"}],"timestamp":"1768250245918","event_type":"price_change"}}
{"schema_version":1,"source":"clob_ws_market","recv_ts_ns":1768250245971438268,"event_type":"price_change","market":"0xe51aa24ab1bbfefce466d642ad98587d13123e4ef95ec9aa73b712e775d4cbba","server_ts_ms":1768250245933,"raw":{"market":"0xe51aa24ab1bbfefce466d642ad98587d13123e4ef95ec9aa73b712e775d4cbba","price_changes":[{"asset_id":"96886111393998001968863279421729456597655847484197549086072988901191634450924","price":"0.94","size":"1626.55","side":"BUY","hash":"2671b24b9a984f36d209501f0fdbba82d7da7b9a","best_bid":"0.94","best_ask":"0.95"},{"asset_id":"54232589582260339592359130012520874109228367674780084862642636038394766871668","price":"0.06","size":"1626.55","side":"SELL","hash":"fc442584c033cd5ad3e0ce743ab62aaadb952962","best_bid":"0.05","best_ask":"0.06"}],"timestamp":"1768250245933","event_type":"price_change"}}
{"schema_version":1,"source":"clob_ws_market","recv_ts_ns":1768250245976358982,"event_type":"price_change","market":"0xe51aa24ab1bbfefce466d642ad98587d13123e4ef95ec9aa73b712e775d4cbba","server_ts_ms":1768250245935,"raw":{"market":"0xe51aa24ab1bbfefce466d642ad98587d13123e4ef95ec9aa73b712e775d4cbba","price_changes":[{"asset_id":"54232589582260339592359130012520874109228367674780084862642636038394766871668","price":"0.06","size":"1637.55","side":"SELL","hash":"83f7fda895fd38c6a8d087d8e345bd60fee92da2","best_bid":"0.05","best_ask":"0.06"},{"asset_id":"96886111393998001968863279421729456597655847484197549086072988901191634450924","price":"0.94","size":"1637.55","side":"BUY","hash":"d89f221bd2e868c1463651e0ae55e15ff9c77565","best_bid":"0.94","best_ask":"0.95"}],"timestamp":"1768250245935","event_type":"price_change"}}
{"schema_version":1,"source":"clob_ws_market","recv_ts_ns":1768250245981783046,"event_type":"price_change","market":"0xe51aa24ab1bbfefce466d642ad98587d13123e4ef95ec9aa73b712e775d4cbba","server_ts_ms":1768250245936,"raw":{"market":"0xe51aa24ab1bbfefce466d642ad98587d13123e4ef95ec9aa73b712e775d4cbba","price_changes":[{"asset_id":"54232589582260339592359130012520874109228367674780084862642636038394766871668","price":"0.01","size":"20928.9","side":"BUY","hash":"e091e6ceb5e967dd9acfeada77ae4c481f4d8b05","best_bid":"0.05","best_ask":"0.06"},{"asset_id":"96886111393998001968863279421729456597655847484197549086072988901191634450924","price":"0.99","size":"20928.9","side":"SELL","hash":"96823812d6ed7500caea02609a94693b3409a5d5","best_bid":"0.94","best_ask":"0.95"}],"timestamp":"1768250245936","event_type":"price_change"}}
{"schema_version":1,"source":"clob_ws_market","recv_ts_ns":1768250245986753731,"event_type":"price_change","market":"0xe51aa24ab1bbfefce466d642ad98587d13123e4ef95ec9aa73b712e775d4cbba","server_ts_ms":1768250245936,"raw":{"market":"0xe51aa24ab1bbfefce466d642ad98587d13123e4ef95ec9aa73b712e775d4cbba","price_changes":[{"asset_id":"54232589582260339592359130012520874109228367674780084862642636038394766871668","price":"0.05","size":"123.74","side":"BUY","hash":"e091e6ceb5e967dd9acfeada77ae4c481f4d8b05","best_bid":"0.05","best_ask":"0.06"},{"asset_id":"96886111393998001968863279421729456597655847484197549086072988901191634450924","price":"0.95","size":"123.74","side":"SELL","hash":"96823812d6ed7500caea02609a94693b3409a5d5","best_bid":"0.94","best_ask":"0.95"}],"timestamp":"1768250245936","event_type":"price_change"}}
{"schema_version":1,"source":"clob_ws_market","recv_ts_ns":1768250245991442764,"event_type":"price_change","market":"0xe51aa24ab1bbfefce466d642ad98587d13123e4ef95ec9aa73b712e775d4cbba","server_ts_ms":1768250245938,"raw":{"market":"0xe51aa24ab1bbfefce466d642ad98587d13123e4ef95ec9aa73b712e775d4cbba","price_changes":[{"asset_id":"96886111393998001968863279421729456597655847484197549086072988901191634450924","price":"0.91","size":"3002.44","side":"BUY","hash":"e2ae341646e5cf527c4d412839b0d575c494de4d","best_bid":"0.94","best_ask":"0.95"},{"asset_id":"54232589582260339592359130012520874109228367674780084862642636038394766871668","price":"0.09","size":"3002.44","side":"SELL","hash":"f3fb95d33bf9ef44853d8e15d881d08ecf4b178d","best_bid":"0.05","best_ask":"0.06"}],"timestamp":"1768250245938","event_type":"price_change"}}
{"schema_version":1,"source":"clob_ws_market","recv_ts_ns":1768250245996197268,"event_type":"price_change","market":"0xe51aa24ab1bbfefce466d642ad98587d13123e4ef95ec9aa73b712e775d4cbba","server_ts_ms":1768250245942,"raw":{"market":"0xe51aa24ab1bbfefce466d642ad98587d13123e4ef95ec9aa73b712e775d4cbba","price_changes":[{"asset_id":"96886111393998001968863279421729456597655847484197549086072988901191634450924","price":"0.94","size":"1649.55","side":"BUY","hash":"9396321981079311b820c702caa65e9cf8278c5c","best_bid":"0.94","best_ask":"0.95"},{"asset_id":"54232589582260339592359130012520874109228367674780084862642636038394766871668","price":"0.06","size":"1649.55","side":"SELL","hash":"94244df065af68abb2eee181d28daad8564054fb","best_bid":"0.05","best_ask":"0.06"}],"timestamp":"1768250245942","event_type":"price_change"}}
{"schema_version":1,"source":"clob_ws_market","recv_ts_ns":1768250246036066545,"event_type":"price_change","market":"0xe51aa24ab1bbfefce466d642ad98587d13123e4ef95ec9aa73b712e775d4cbba","server_ts_ms":1768250245953,"raw":{"market":"0xe51aa24ab1bbfefce466d642ad98587d13123e4ef95ec9aa73b712e775d4cbba","price_changes":[{"asset_id":"96886111393998001968863279421729456597655847484197549086072988901191634450924","price":"0.92","size":"2423.36","side":"BUY","hash":"accff63151c3542e323d6f2c0063e75fd4b15368","best_bid":"0.94","best_ask":"0.95"},{"asset_id":"54232589582260339592359130012520874109228367674780084862642636038394766871668","price":"0.08","size":"2423.36","side":"SELL","hash":"a53205608057ea8f7b3872afd19274e42c79748a","best_bid":"0.05","best_ask":"0.06"}],"timestamp":"1768250245953","event_type":"price_change"}}
{"schema_version":1,"source":"clob_ws_market","recv_ts_ns":1768250246045172079,"event_type":"price_change","market":"0xe51aa24ab1bbfefce466d642ad98587d13123e4ef95ec9aa73b712e775d4cbba","server_ts_ms":1768250245957,"raw":{"market":"0xe51aa24ab1bbfefce466d642ad98587d13123e4ef95ec9aa73b712e775d4cbba","price_changes":[{"asset_id":"96886111393998001968863279421729456597655847484197549086072988901191634450924","price":"0.94","size":"1900.55","side":"BUY","hash":"8e65ec15d5a9ba2d88d0d8441f5879c6f4d9138a","best_bid":"0.94","best_ask":"0.95"},{"asset_id":"54232589582260339592359130012520874109228367674780084862642636038394766871668","price":"0.06","size":"1900.55","side":"SELL","hash":"722efa0f4f93adc33c52509c4d2e2ca2664ed3ed","best_bid":"0.05","best_ask":"0.06"}],"timestamp":"1768250245957","event_type":"price_change"}}
{"schema_version":1,"source":"clob_ws_market","recv_ts_ns":1768250246054025992,"event_type":"price_change","market":"0xe51aa24ab1bbfefce466d642ad98587d13123e4ef95ec9aa73b712e775d4cbba","server_ts_ms":1768250245964,"raw":{"market":"0xe51aa24ab1bbfefce466d642ad98587d13123e4ef95ec9aa73b712e775d4cbba","price_changes":[{"asset_id":"96886111393998001968863279421729456597655847484197549086072988901191634450924","price":"0.94","size":"2010.55","side":"BUY","hash":"1b77f8ec4761bc2307beb5a3057adb07f5e06983","best_bid":"0.94","best_ask":"0.95"},{"asset_id":"54232589582260339592359130012520874109228367674780084862642636038394766871668","price":"0.06","size":"2010.55","side":"SELL","hash":"eb98421466e8f07ce8bbb459145dbba9eb3dc080","best_bid":"0.05","best_ask":"0.06"}],"timestamp":"1768250245964","event_type":"price_change"}}
{"schema_version":1,"source":"clob_ws_market","recv_ts_ns":1768250246057545862,"event_type":"price_change","market":"0xe51aa24ab1bbfefce466d642ad98587d13123e4ef95ec9aa73b712e775d4cbba","server_ts_ms":1768250245965,"raw":{"market":"0xe51aa24ab1bbfefce466d642ad98587d13123e4ef95ec9aa73b712e775d4cbba","price_changes":[{"asset_id":"54232589582260339592359130012520874109228367674780084862642636038394766871668","price":"0.04","size":"1692.4","side":"BUY","hash":"052804b08cc90bc472ff0d3843ee33c67f34b3f8","best_bid":"0.05","best_ask":"0.06"},{"asset_id":"96886111393998001968863279421729456597655847484197549086072988901191634450924","price":"0.96","size":"1692.4","side":"SELL","hash":"5599d761764189989a5002a75622b6341108afee","best_bid":"0.94","best_ask":"0.95"}],"timestamp":"1768250245965","event_type":"price_change"}}
{"schema_version":1,"source":"clob_ws_market","recv_ts_ns":1768250246065146159,"event_type":"price_change","market":"0xe51aa24ab1bbfefce466d642ad98587d13123e4ef95ec9aa73b712e775d4cbba","server_ts_ms":1768250245968,"raw":{"market":"0xe51aa24ab1bbfefce466d642ad98587d13123e4ef95ec9aa73b712e775d4cbba","price_changes":[{"asset_id":"54232589582260339592359130012520874109228367674780084862642636038394766871668","price":"0.06","size":"1999.55","side":"SELL","hash":"134570746d312c5af210d118909f78113824627c","best_bid":"0.05","best_ask":"0.06"},{"asset_id":"96886111393998001968863279421729456597655847484197549086072988901191634450924","price":"0.94","size":"1999.55","side":"BUY","hash":"61522852de419ed869812caf607adcf06ebe873d","best_bid":"0.94","best_ask":"0.95"}],"timestamp":"1768250245968","event_type":"price_change"}}
{"schema_version":1,"source":"clob_ws_market","recv_ts_ns":1768250246088366856,"event_type":"price_change","market":"0xe51aa24ab1bbfefce466d642ad98587d13123e4ef95ec9aa73b712e775d4cbba","server_ts_ms":1768250245995,"raw":{"market":"0xe51aa24ab1bbfefce466d642ad98587d13123e4ef95ec9aa73b712e775d4cbba","price_changes":[{"asset_id":"54232589582260339592359130012520874109228367674780084862642636038394766871668","price":"0.06","size":"2014.55","side":"SELL","hash":"f07ad61cf773e03acf7d42216a2bedc96bc117d4","best_bid":"0.05","best_ask":"0.06"},{"asset_id":"96886111393998001968863279421729456597655847484197549086072988901191634450924","price":"0.94","size":"2014.55","side":"BUY","hash":"df1d9972c10d2932515370587f309a4ad9a67f8e","best_bid":"0.94","best_ask":"0.95"}],"timestamp":"1768250245995","event_type":"price_change"}}
{"schema_version":1,"source":"clob_ws_market","recv_ts_ns":1768250246099105484,"event_type":"price_change","market":"0xe51aa24ab1bbfefce466d642ad98587d13123e4ef95ec9aa73b712e775d4cbba","server_ts_ms":1768250245996,"raw":{"market":"0xe51aa24ab1bbfefce466d642ad98587d13123e4ef95ec9aa73b712e775d4cbba","price_changes":[{"asset_id":"96886111393998001968863279421729456597655847484197549086072988901191634450924","price":"0.92","size":"2724.36","side":"BUY","hash":"c7938a301bfc836c5ab76940c1f44900571b92ca","best_bid":"0.94","best_ask":"0.95"},{"asset_id":"54232589582260339592359130012520874109228367674780084862642636038394766871668","price":"0.08","size":"2724.36","side":"SELL","hash":"c9758020bcb520caec4c3f257fdde1c057480528","best_bid":"0.05","best_ask":"0.06"}],"timestamp":"1768250245996","event_type":"price_change"}}
{"schema_version":1,"source":"clob_ws_market","recv_ts_ns":1768250246109447759,"event_type":"price_change","market":"0xe51aa24ab1bbfefce466d642ad98587d13123e4ef95ec9aa73b712e775d4cbba","server_ts_ms":1768250245998,"raw":{"market":"0xe51aa24ab1bbfefce466d642ad98587d13123e4ef95ec9aa73b712e775d4cbba","price_changes":[{"asset_id":"96886111393998001968863279421729456597655847484197549086072988901191634450924","price":"0.94","size":"2019.55","side":"BUY","hash":"15332c0c37c3081a4931ffdbd64a5747db5f4531","best_bid":"0.94","best_ask":"0.95"},{"asset_id":"54232589582260339592359130012520874109228367674780084862642636038394766871668","price":"0.06","size":"2019.55","side":"SELL","hash":"6d5716e0f949d857f6f3cb462a7a8c72343f77ce","best_bid":"0.05","best_ask":"0.06"}],"timestamp":"1768250245998","event_type":"price_change"}}
{"schema_version":1,"source":"clob_ws_market","recv_ts_ns":1768250246125004409,"event_type":"price_change","market":"0xe51aa24ab1bbfefce466d642ad98587d13123e4ef95ec9aa73b712e775d4cbba","server_ts_ms":1768250246000,"raw":{"market":"0xe51aa24ab1bbfefce466d642ad98587d13123e4ef95ec9aa73b712e775d4cbba","price_changes":[{"asset_id":"54232589582260339592359130012520874109228367674780084862642636038394766871668","price":"0.02","size":"5722.25","side":"BUY","hash":"8dd4ee2323bf0c8b9aca8b5d00ae16d6ae898e37","best_bid":"0.05","best_ask":"0.06"},{"asset_id":"96886111393998001968863279421729456597655847484197549086072988901191634450924","price":"0.98","size":"5722.25","side":"SELL","hash":"5ae043568b9838921ca13eaf9e5a4c6c39ae16e7","best_bid":"0.94","best_ask":"0.95"}],"timestamp":"1768250246000","event_type":"price_change"}}
{"schema_version":1,"source":"clob_ws_market","recv_ts_ns":1768250246134621796,"event_type":"price_change","market":"0xe51aa24ab1bbfefce466d642ad98587d13123e4ef95ec9aa73b712e775d4cbba","server_ts_ms":1768250246001,"raw":{"market":"0xe51aa24ab1bbfefce466d642ad98587d13123e4ef95ec9aa73b712e775d4cbba","price_changes":[{"asset_id":"96886111393998001968863279421729456597655847484197549086072988901191634450924","price":"0.96","size":"1687.4","side":"SELL","hash":"02b2ab9bdc34e0916e7196f312e505948c5c3935","best_bid":"0.94","best_ask":"0.95"},{"asset_id":"54232589582260339592359130012520874109228367674780084862642636038394766871668","price":"0.04","size":"1687.4","side":"BUY","hash":"fae330e433bf41494ccefb2725891e0c37a27495","best_bid":"0.05","best_ask":"0.06"}],"timestamp":"1768250246001","event_type":"price_change"}}
{"schema_version":1,"source":"clob_ws_market","recv_ts_ns":1768250246162676471,"event_type":"price_change","market":"0xe51aa24ab1bbfefce466d642ad98587d13123e4ef95ec9aa73b712e775d4cbba","server_ts_ms":1768250246006,"raw":{"market":"0xe51aa24ab1bbfefce466d642ad98587d13123e4ef95ec9aa73b712e775d4cbba","price_changes":[{"asset_id":"96886111393998001968863279421729456597655847484197549086072988901191634450924","price":"0.93","size":"1490.82","side":"BUY","hash":"7a97fdcad5ce8c3ee90416448eec05a15ca49b21","best_bid":"0.94","best_ask":"0.95"},{"asset_id":"54232589582260339592359130012520874109228367674780084862642636038394766871668","price":"0.07","size":"1490.82","side":"SELL","hash":"504da7606484036002cc34e69dd67e27a8284f3a","best_bid":"0.05","best_ask":"0.06"}],"timestamp":"1768250246006","event_type":"price_change"}}
{"schema_version":1,"source":"clob_ws_market","recv_ts_ns":1768250246206982907,"event_type":"price_change","market":"0xe51aa24ab1bbfefce466d642ad98587d13123e4ef95ec9aa73b712e775d4cbba","server_ts_ms":1768250246013,"raw":{"market":"0xe51aa24ab1bbfefce466d642ad98587d13123e4ef95ec9aa73b712e775d4cbba","price_changes":[{"asset_id":"96886111393998001968863279421729456597655847484197549086072988901191634450924","price":"0.94","size":"2049.55","side":"BUY","hash":"f0bb6fc980def124c3008f9261090e0539c8af23","best_bid":"0.94","best_ask":"0.95"},{"asset_id":"54232589582260339592359130012520874109228367674780084862642636038394766871668","price":"0.06","size":"2049.55","side":"SELL","hash":"8641065c99f444e25ef1eaae2e891f6e431f0f9e","best_bid":"0.05","best_ask":"0.06"}],"timestamp":"1768250246013","event_type":"price_change"}}
{"schema_version":1,"source":"clob_ws_market","recv_ts_ns":1768250246216821216,"event_type":"price_change","market":"0xe51aa24ab1bbfefce466d642ad98587d13123e4ef95ec9aa73b712e775d4cbba","server_ts_ms":1768250246030,"raw":{"market":"0xe51aa24ab1bbfefce466d642ad98587d13123e4ef95ec9aa73b712e775d4cbba","price_changes":[{"asset_id":"96886111393998001968863279421729456597655847484197549086072988901191634450924","price":"0.93","size":"1474.82","side":"BUY","hash":"1309232e02d998107a510f9c40359c1648acbb3a","best_bid":"0.94","best_ask":"0.95"},{"asset_id":"54232589582260339592359130012520874109228367674780084862642636038394766871668","price":"0.07","size":"1474.82","side":"SELL","hash":"8503e50f4f1b1287ed91ce1f03f3bb0114fa22a0","best_bid":"0.05","best_ask":"0.06"}],"timestamp":"1768250246030","event_type":"price_change"}}
{"schema_version":1,"source":"clob_ws_market","recv_ts_ns":1768250246225649859,"event_type":"price_change","market":"0xe51aa24ab1bbfefce466d642ad98587d13123e4ef95ec9aa73b712e775d4cbba","server_ts_ms":1768250246035,"raw":{"market":"0xe51aa24ab1bbfefce466d642ad98587d13123e4ef95ec9aa73b712e775d4cbba","price_changes":[{"asset_id":"96886111393998001968863279421729456597655847484197549086072988901191634450924","price":"0.9","size":"3445.34","side":"BUY","hash":"3d9fd65b9ed41d7dd533b5a4320debeb12f3268b","best_bid":"0.94","best_ask":"0.95"},{"asset_id":"54232589582260339592359130012520874109228367674780084862642636038394766871668","price":"0.1","size":"3445.34","side":"SELL","hash":"61b61cebf02f8ebcbb5c89b376b8555d00fe47cc","best_bid":"0.05","best_ask":"0.06"}],"timestamp":"1768250246035","event_type":"price_change"}}
{"schema_version":1,"source":"clob_ws_market","recv_ts_ns":1768250246237896913,"event_type":"price_change","market":"0xe51aa24ab1bbfefce466d642ad98587d13123e4ef95ec9aa73b712e775d4cbba","server_ts_ms":1768250246042,"raw":{"market":"0xe51aa24ab1bbfefce466d642ad98587d13123e4ef95ec9aa73b712e775d4cbba","price_changes":[{"asset_id":"96886111393998001968863279421729456597655847484197549086072988901191634450924","price":"0.94","size":"2065.55","side":"BUY","hash":"00357ffe02acc6e6977b407aae262915902bc1f2","best_bid":"0.94","best_ask":"0.95"},{"asset_id":"54232589582260339592359130012520874109228367674780084862642636038394766871668","price":"0.06","size":"2065.55","side":"SELL","hash":"2dadec573221dd46cc1431792a2405adf984ad58","best_bid":"0.05","best_ask":"0.06"}],"timestamp":"1768250246042","event_type":"price_change"}}
{"schema_version":1,"source":"clob_ws_market","recv_ts_ns":1768250246241750222,"event_type":"price_change","market":"0xe51aa24ab1bbfefce466d642ad98587d13123e4ef95ec9aa73b712e775d4cbba","server_ts_ms":1768250246043,"raw":{"market":"0xe51aa24ab1bbfefce466d642ad98587d13123e4ef95ec9aa73b712e775d4cbba","price_changes":[{"asset_id":"54232589582260339592359130012520874109228367674780084862642636038394766871668","price":"0.01","size":"21028.9","side":"BUY","hash":"0aab0b6f422bffa541a530da92512f0f6cdf3f39","best_bid":"0.05","best_ask":"0.06"},{"asset_id":"96886111393998001968863279421729456597655847484197549086072988901191634450924","price":"0.99","size":"21028.9","side":"SELL","hash":"271e0790a6130aa51f383694372aab864badebc7","best_bid":"0.94","best_ask":"0.95"}],"timestamp":"1768250246043","event_type":"price_change"}}
{"schema_version":1,"source":"clob_ws_market","recv_ts_ns":1768250246291806290,"event_type":"price_change","market":"0xe51aa24ab1bbfefce466d642ad98587d13123e4ef95ec9aa73b712e775d4cbba","server_ts_ms":1768250246064,"raw":{"market":"0xe51aa24ab1bbfefce466d642ad98587d13123e4ef95ec9aa73b712e775d4cbba","price_changes":[{"asset_id":"96886111393998001968863279421729456597655847484197549086072988901191634450924","price":"0.91","size":"3012.44","side":"BUY","hash":"c491225099b77244422a2d95dd39cf2455da3c36","best_bid":"0.94","best_ask":"0.95"},{"asset_id":"54232589582260339592359130012520874109228367674780084862642636038394766871668","price":"0.09","size":"3012.44","side":"SELL","hash":"32085369db3982c6dde3acd71266eaac3c18b64f","best_bid":"0.05","best_ask":"0.06"}],"timestamp":"1768250246064","event_type":"price_change"}}
{"schema_version":1,"source":"clob_ws_market","recv_ts_ns":1768250246299028587,"event_type":"price_change","market":"0xe51aa24ab1bbfefce466d642ad98587d13123e4ef95ec9aa73b712e775d4cbba","server_ts_ms":1768250246069,"raw":{"market":"0xe51aa24ab1bbfefce466d642ad98587d13123e4ef95ec9aa73b712e775d4cbba","price_changes":[{"asset_id":"96886111393998001968863279421729456597655847484197549086072988901191634450924","price":"0.94","size":"2081.55","side":"BUY","hash":"051586c1db210191565bc9f69e1a6a7686dc1ac1","best_bid":"0.94","best_ask":"0.95"},{"asset_id":"54232589582260339592359130012520874109228367674780084862642636038394766871668","price":"0.06","size":"2081.55","side":"SELL","hash":"ae3ed5613904a18c59ac3d6cccc9f130280c77ae","best_bid":"0.05","best_ask":"0.06"}],"timestamp":"1768250246069","event_type":"price_change"}}
{"schema_version":1,"source":"clob_ws_market","recv_ts_ns":1768250246314210118,"event_type":"price_change","market":"0xe51aa24ab1bbfefce466d642ad98587d13123e4ef95ec9aa73b712e775d4cbba","server_ts_ms":1768250246086,"raw":{"market":"0xe51aa24ab1bbfefce466d642ad98587d13123e4ef95ec9aa73b712e775d4cbba","price_changes":[{"asset_id":"96886111393998001968863279421729456597655847484197549086072988901191634450924","price":"0.93","size":"1458.82","side":"BUY","hash":"cc9e4e66936947e99867abddbe64d4fdf2914a32","best_bid":"0.94","best_ask":"0.95"},{"asset_id":"54232589582260339592359130012520874109228367674780084862642636038394766871668","price":"0.07","size":"1458.82","side":"SELL","hash":"55bbaa016574ef0826b43da2c2e295e7a0895a65","best_bid":"0.05","best_ask":"0.06"}],"timestamp":"1768250246086","event_type":"price_change"}}
{"schema_version":1,"source":"clob_ws_market","recv_ts_ns":1768250246317694603,"event_type":"price_change","market":"0xe51aa24ab1bbfefce466d642ad98587d13123e4ef95ec9aa73b712e775d4cbba","server_ts_ms":1768250246097,"raw":{"market":"0xe51aa24ab1bbfefce466d642ad98587d13123e4ef95ec9aa73b712e775d4cbba","price_changes":[{"asset_id":"96886111393998001968863279421729456597655847484197549086072988901191634450924","price":"0.9","size":"3439.34","side":"BUY","hash":"bba616fbf941b3712e53c544256fbdc80eca99d5","best_bid":"0.94","best_ask":"0.95"},{"asset_id":"54232589582260339592359130012520874109228367674780084862642636038394766871668","price":"0.1","size":"3439.34","side":"SELL","hash":"9908ed69a4da9189329746f20fed56081741258f","best_bid":"0.05","best_ask":"0.06"}],"timestamp":"1768250246097","event_type":"price_change"}}
{"schema_version":1,"source":"clob_ws_market","recv_ts_ns":1768250246321972473,"event_type":"price_change","market":"0xe51aa24ab1bbfefce466d642ad98587d13123e4ef95ec9aa73b712e775d4cbba","server_ts_ms":1768250246097,"raw":{"market":"0xe51aa24ab1bbfefce466d642ad98587d13123e4ef95ec9aa73b712e775d4cbba","price_changes":[{"asset_id":"96886111393998001968863279421729456597655847484197549086072988901191634450924","price":"0.99","size":"21023.9","side":"SELL","hash":"bba616fbf941b3712e53c544256fbdc80eca99d5","best_bid":"0.94","best_ask":"0.95"},{"asset_id":"54232589582260339592359130012520874109228367674780084862642636038394766871668","price":"0.01","size":"21023.9","side":"BUY","hash":"9908ed69a4da9189329746f20fed56081741258f","best_bid":"0.05","best_ask":"0.06"}],"timestamp":"1768250246097","event_type":"price_change"}}
{"schema_version":1,"source":"clob_ws_market","recv_ts_ns":1768250246329699394,"event_type":"price_change","market":"0xe51aa24ab1bbfefce466d642ad98587d13123e4ef95ec9aa73b712e775d4cbba","server_ts_ms":1768250246116,"raw":{"market":"0xe51aa24ab1bbfefce466d642ad98587d13123e4ef95ec9aa73b712e775d4cbba","price_changes":[{"asset_id":"54232589582260339592359130012520874109228367674780084862642636038394766871668","price":"0.02","size":"5672.25","side":"BUY","hash":"dc377746417bb330be3ce79cba9b44ca054ebb04","best_bid":"0.05","best_ask":"0.06"},{"asset_id":"96886111393998001968863279421729456597655847484197549086072988901191634450924","price":"0.98","size":"5672.25","side":"SELL","hash":"f0465bba2912c1f0418f8eb3b9bacff841a255d6","best_bid":"0.94","best_ask":"0.95"}],"timestamp":"1768250246116","event_type":"price_change"}}
{"schema_version":1,"source":"clob_ws_market","recv_ts_ns":1768250246335190912,"event_type":"price_change","market":"0xe51aa24ab1bbfefce466d642ad98587d13123e4ef95ec9aa73b712e775d4cbba","server_ts_ms":1768250246125,"raw":{"market":"0xe51aa24ab1bbfefce466d642ad98587d13123e4ef95ec9aa73b712e775d4cbba","price_changes":[{"asset_id":"54232589582260339592359130012520874109228367674780084862642636038394766871668","price":"0.03","size":"1796.6","side":"BUY","hash":"ccaaee2709bf0737295583b55e567377d71ae1ec","best_bid":"0.05","best_ask":"0.06"},{"asset_id":"96886111393998001968863279421729456597655847484197549086072988901191634450924","price":"0.97","size":"1796.6","side":"SELL","hash":"a2e44a3c7b0dc9a498816aa0b96dfb2a358a9bca","best_bid":"0.94","best_ask":"0.95"}],"timestamp":"1768250246125","event_type":"price_change"}}
{"schema_version":1,"source":"clob_ws_market","recv_ts_ns":1768250246340485869,"event_type":"price_change","market":"0xe51aa24ab1bbfefce466d642ad98587d13123e4ef95ec9aa73b712e775d4cbba","server_ts_ms":1768250246126,"raw":{"market":"0xe51aa24ab1bbfefce466d642ad98587d13123e4ef95ec9aa73b712e775d4cbba","price_changes":[{"asset_id":"96886111393998001968863279421729456597655847484197549086072988901191634450924","price":"0.94","size":"2097.55","side":"BUY","hash":"afd1aa4bb5cca0f574b4625c31d6853b34f8fb62","best_bid":"0.94","best_ask":"0.95"},{"asset_id":"54232589582260339592359130012520874109228367674780084862642636038394766871668","price":"0.06","size":"2097.55","side":"SELL","hash":"a8f128388ff649440072f7648ace3faa841b3d05","best_bid":"0.05","best_ask":"0.06"}],"timestamp":"1768250246126","event_type":"price_change"}}
{"schema_version":1,"source":"clob_ws_market","recv_ts_ns":1768250246345427046,"event_type":"price_change","market":"0xe51aa24ab1bbfefce466d642ad98587d13123e4ef95ec9aa73b712e775d4cbba","server_ts_ms":1768250246127,"raw":{"market":"0xe51aa24ab1bbfefce466d642ad98587d13123e4ef95ec9aa73b712e775d4cbba","price_changes":[{"asset_id":"54232589582260339592359130012520874109228367674780084862642636038394766871668","price":"0.02","size":"5656.25","side":"BUY","hash":"a11b2eaa9574456a1fecaf648efd218804dd9228","best_bid":"0.05","best_ask":"0.06"},{"asset_id":"96886111393998001968863279421729456597655847484197549086072988901191634450924","price":"0.98","size":"5656.25","side":"SELL","hash":"57335973d67bd0059406d79f4cc1bb1dea769a52","best_bid":"0.94","best_ask":"0.95"}],"timestamp":"1768250246127","event_type":"price_change"}}
{"schema_version":1,"source":"clob_ws_market","recv_ts_ns":1768250246349699956,"event_type":"price_change","market":"0xe51aa24ab1bbfefce466d642ad98587d13123e4ef95ec9aa73b712e775d4cbba","server_ts_ms":1768250246129,"raw":{"market":"0xe51aa24ab1bbfefce466d642ad98587d13123e4ef95ec9aa73b712e775d4cbba","price_changes":[{"asset_id":"96886111393998001968863279421729456597655847484197549086072988901191634450924","price":"0.92","size":"2729.36","side":"BUY","hash":"ae5337f68707a8838e5b7c21725326d2b958f22e","best_bid":"0.94","best_ask":"0.95"},{"asset_id":"54232589582260339592359130012520874109228367674780084862642636038394766871668","price":"0.08","size":"2729.36","side":"SELL","hash":"22cdd78e656d09a768f6105ac50033e07f0a4e1a","best_bid":"0.05","best_ask":"0.06"}],"timestamp":"1768250246129","event_type":"price_change"}}
{"schema_version":1,"source":"clob_ws_market","recv_ts_ns":1768250246355222959,"event_type":"price_change","market":"0xe51aa24ab1bbfefce466d642ad98587d13123e4ef95ec9aa73b712e775d4cbba","server_ts_ms":1768250246130,"raw":{"market":"0xe51aa24ab1bbfefce466d642ad98587d13123e4ef95ec9aa73b712e775d4cbba","price_changes":[{"asset_id":"96886111393998001968863279421729456597655847484197549086072988901191634450924","price":"0.99","size":"21028.9","side":"SELL","hash":"6887c7078037abfd4f85a4195cae93f07df1a8c7","best_bid":"0.94","best_ask":"0.95"},{"asset_id":"54232589582260339592359130012520874109228367674780084862642636038394766871668","price":"0.01","size":"21028.9","side":"BUY","hash":"b94dbb2ef175b01a07a15f0304ab7d2b42f7e96f","best_bid":"0.05","best_ask":"0.06"}],"timestamp":"1768250246130","event_type":"price_change"}}
{"schema_version":1,"source":"clob_ws_market","recv_ts_ns":1768250246360554325,"event_type":"price_change","market":"0xe51aa24ab1bbfefce466d642ad98587d13123e4ef95ec9aa73b712e775d4cbba","server_ts_ms":1768250246135,"raw":{"market":"0xe51aa24ab1bbfefce466d642ad98587d13123e4ef95ec9aa73b712e775d4cbba","price_changes":[{"asset_id":"96886111393998001968863279421729456597655847484197549086072988901191634450924","price":"0.94","size":"2128.55","side":"BUY","hash":"5849d5d6fbe13ba97620447cdeb9cb734c1114c1","best_bid":"0.94","best_ask":"0.95"},{"asset_id":"54232589582260339592359130012520874109228367674780084862642636038394766871668","price":"0.06","size":"2128.55","side":"SELL","hash":"eb6e96e0c27cfb131625094196237a10013ba411","best_bid":"0.05","best_ask":"0.06"}],"timestamp":"1768250246135","event_type":"price_change"}}
{"schema_version":1,"source":"clob_ws_market","recv_ts_ns":1768250246365731409,"event_type":"price_change","market":"0xe51aa24ab1bbfefce466d642ad98587d13123e4ef95ec9aa73b712e775d4cbba","server_ts_ms":1768250246136,"raw":{"market":"0xe51aa24ab1bbfefce466d642ad98587d13123e4ef95ec9aa73b712e775d4cbba","price_changes":[{"asset_id":"96886111393998001968863279421729456597655847484197549086072988901191634450924","price":"0.93","size":"1423.82","side":"BUY","hash":"1c52c47ac93c58d2cfe7b3ba810545b9f863b697","best_bid":"0.94","best_ask":"0.95"},{"asset_id":"54232589582260339592359130012520874109228367674780084862642636038394766871668","price":"0.07","size":"1423.82","side":"SELL","hash":"b9046ec132d56ce91d275aa3f54457c014d1ebe7","best_bid":"0.05","best_ask":"0.06"}],"timestamp":"1768250246136","event_type":"price_change"}}
{"schema_version":1,"source":"clob_ws_market","recv_ts_ns":1768250246369959503,"event_type":"price_change","market":"0xe51aa24ab1bbfefce466d642ad98587d13123e4ef95ec9aa73b712e775d4cbba","server_ts_ms":1768250246141,"raw":{"market":"0xe51aa24ab1bbfefce466d642ad98587d13123e4ef95ec9aa73b712e775d4cbba","price_changes":[{"asset_id":"96886111393998001968863279421729456597655847484197549086072988901191634450924","price":"0.88","size":"2355.4","side":"BUY","hash":"fd869ba1c61db9330525706b0c474fc2e00f8882","best_bid":"0.94","best_ask":"0.95"},{"asset_id":"54232589582260339592359130012520874109228367674780084862642636038394766871668","price":"0.12","size":"2355.4","side":"SELL","hash":"24d355cfe850fe3bbbbf6bf426898ffe3964c1a9","best_bid":"0.05","best_ask":"0.06"}],"timestamp":"1768250246141","event_type":"price_change"}}
{"schema_version":1,"source":"clob_ws_market","recv_ts_ns":1768250246374485710,"event_type":"price_change","market":"0xe51aa24ab1bbfefce466d642ad98587d13123e4ef95ec9aa73b712e775d4cbba","server_ts_ms":1768250246154,"raw":{"market":"0xe51aa24ab1bbfefce466d642ad98587d13123e4ef95ec9aa73b712e775d4cbba","price_changes":[{"asset_id":"54232589582260339592359130012520874109228367674780084862642636038394766871668","price":"0.02","size":"5672.25","side":"BUY","hash":"cf80a67678e7dec5c5ee3cc5908edd476636ccad","best_bid":"0.05","best_ask":"0.06"},{"asset_id":"96886111393998001968863279421729456597655847484197549086072988901191634450924","price":"0.98","size":"5672.25","side":"SELL","hash":"ff613e08d28fbc7b88356d390f2f769be9555178","best_bid":"0.94","best_ask":"0.95"}],"timestamp":"1768250246154","event_type":"price_change"}}
{"schema_version":1,"source":"clob_ws_market","recv_ts_ns":1768250246379386541,"event_type":"price_change","market":"0xe51aa24ab1bbfefce466d642ad98587d13123e4ef95ec9aa73b712e775d4cbba","server_ts_ms":1768250246154,"raw":{"market":"0xe51aa24ab1bbfefce466d642ad98587d13123e4ef95ec9aa73b712e775d4cbba","price_changes":[{"asset_id":"96886111393998001968863279421729456597655847484197549086072988901191634450924","price":"0.93","size":"1407.82","side":"BUY","hash":"f62e4a97cc136fd2fd15bfda6ade97f46393651c","best_bid":"0.94","best_ask":"0.95"},{"asset_id":"54232589582260339592359130012520874109228367674780084862642636038394766871668","price":"0.07","size":"1407.82","side":"SELL","hash":"e22b672e5af1d51f065ed97adef305a1e4e37a6e","best_bid":"0.05","best_ask":"0.06"}],"timestamp":"1768250246154","event_type":"price_change"}}
{"schema_version":1,"source":"clob_ws_market","recv_ts_ns":1768250246385448449,"event_type":"price_change","market":"0xe51aa24ab1bbfefce466d642ad98587d13123e4ef95ec9aa73b712e775d4cbba","server_ts_ms":1768250246156,"raw":{"market":"0xe51aa24ab1bbfefce466d642ad98587d13123e4ef95ec9aa73b712e775d4cbba","price_changes":[{"asset_id":"54232589582260339592359130012520874109228367674780084862642636038394766871668","price":"0.01","size":"21012.9","side":"BUY","hash":"628bfe0b6beac2eafb37879513cee36e66c9340c","best_bid":"0.05","best_ask":"0.06"},{"asset_id":"96886111393998001968863279421729456597655847484197549086072988901191634450924","price":"0.99","size":"21012.9","side":"SELL","hash":"21ab216d8968443dbfb6e5f0ef16a527249c3eef","best_bid":"0.94","best_ask":"0.95"}],"timestamp":"1768250246156","event_type":"price_change"}}
{"schema_version":1,"source":"clob_ws_market","recv_ts_ns":1768250246389293606,"event_type":"price_change","market":"0xe51aa24ab1bbfefce466d642ad98587d13123e4ef95ec9aa73b712e775d4cbba","server_ts_ms":1768250246157,"raw":{"market":"0xe51aa24ab1bbfefce466d642ad98587d13123e4ef95ec9aa73b712e775d4cbba","price_changes":[{"asset_id":"54232589582260339592359130012520874109228367674780084862642636038394766871668","price":"0.01","size":"20996.9","side":"BUY","hash":"2e440dcd7f34060a3e80ba6c27458b03bf44688d","best_bid":"0.05","best_ask":"0.06"},{"asset_id":"96886111393998001968863279421729456597655847484197549086072988901191634450924","price":"0.99","size":"20996.9","side":"SELL","hash":"395406ff8f9a09fe6aee6751be92dfddecb61fee","best_bid":"0.94","best_ask":"0.95"}],"timestamp":"1768250246157","event_type":"price_change"}}
{"schema_version":1,"source":"clob_ws_market","recv_ts_ns":1768250246393437947,"event_type":"price_change","market":"0xe51aa24ab1bbfefce466d642ad98587d13123e4ef95ec9aa73b712e775d4cbba","server_ts_ms":1768250246159,"raw":{"market":"0xe51aa24ab1bbfefce466d642ad98587d13123e4ef95ec9aa73b712e775d4cbba","price_changes":[{"asset_id":"96886111393998001968863279421729456597655847484197549086072988901191634450924","price":"0.89","size":"2098.8","side":"BUY","hash":"1ba7e32502bc2cd05733eff1dd5833a160316d53","best_bid":"0.94","best_ask":"0.95"},{"asset_id":"54232589582260339592359130012520874109228367674780084862642636038394766871668","price":"0.11","size":"2098.8","side":"SELL","hash":"2b26658782b6fea7a3337d7d466414559ced87fd","best_bid":"0.05","best_ask":"0.06"}],"timestamp":"1768250246159","event_type":"price_change"}}
{"schema_version":1,"source":"clob_ws_market","recv_ts_ns":1768250246397217313,"event_type":"price_change","market":"0xe51aa24ab1bbfefce466d642ad98587d13123e4ef95ec9aa73b712e775d4cbba","server_ts_ms":1768250246164,"raw":{"market":"0xe51aa24ab1bbfefce466d642ad98587d13123e4ef95ec9aa73b712e775d4cbba","price_changes":[{"asset_id":"54232589582260339592359130012520874109228367674780084862642636038394766871668","price":"0.01","size":"21012.9","side":"BUY","hash":"9a39e403b99ef9c0a2c463f0e967dc70bfee02fb","best_bid":"0.05","best_ask":"0.06"},{"asset_id":"96886111393998001968863279421729456597655847484197549086072988901191634450924","price":"0.99","size":"21012.9","side":"SELL","hash":"924e509a179056a0848b902321b922f208d2a599","best_bid":"0.94","best_ask":"0.95"}],"timestamp":"1768250246164","event_type":"price_change"}}
{"schema_version":1,"source":"clob_ws_market","recv_ts_ns":1768250246401379629,"event_type":"price_change","market":"0xe51aa24ab1bbfefce466d642ad98587d13123e4ef95ec9aa73b712e775d4cbba","server_ts_ms":1768250246165,"raw":{"market":"0xe51aa24ab1bbfefce466d642ad98587d13123e4ef95ec9aa73b712e775d4cbba","price_changes":[{"asset_id":"54232589582260339592359130012520874109228367674780084862642636038394766871668","price":"0.03","size":"1830.6","side":"BUY","hash":"7114150f27a93681e3863ae9603f960ae34c4423","best_bid":"0.05","best_ask":"0.06"},{"asset_id":"96886111393998001968863279421729456597655847484197549086072988901191634450924","price":"0.97","size":"1830.6","side":"SELL","hash":"f9ee75ece68c1f4104e7a5bbd05c22768ac44c25","best_bid":"0.94","best_ask":"0.95"}],"timestamp":"1768250246165","event_type":"price_change"}}
{"schema_version":1,"source":"clob_ws_market","recv_ts_ns":1768250246404470692,"event_type":"price_change","market":"0xe51aa24ab1bbfefce466d642ad98587d13123e4ef95ec9aa73b712e775d4cbba","server_ts_ms":1768250246167,"raw":{"market":"0xe51aa24ab1bbfefce466d642ad98587d13123e4ef95ec9aa73b712e775d4cbba","price_changes":[{"asset_id":"96886111393998001968863279421729456597655847484197549086072988901191634450924","price":"0.92","size":"2549.36","side":"BUY","hash":"2a9151b7be44bb79bfad724e5ce1c6da8693a65f","best_bid":"0.94","best_ask":"0.95"},{"asset_id":"54232589582260339592359130012520874109228367674780084862642636038394766871668","price":"0.08","size":"2549.36","side":"SELL","hash":"24e06c661177de3c16634d89f5f6957a55534335","best_bid":"0.05","best_ask":"0.06"}],"timestamp":"1768250246167","event_type":"price_change"}}
{"schema_version":1,"source":"clob_ws_market","recv_ts_ns":1768250246408409736,"event_type":"price_change","market":"0xe51aa24ab1bbfefce466d642ad98587d13123e4ef95ec9aa73b712e775d4cbba","server_ts_ms":1768250246169,"raw":{"market":"0xe51aa24ab1bbfefce466d642ad98587d13123e4ef95ec9aa73b712e775d4cbba","price_changes":[{"asset_id":"96886111393998001968863279421729456597655847484197549086072988901191634450924","price":"0.94","size":"2097.55","side":"BUY","hash":"db71316f596f773e91cac6241d0ffc8b3e659827","best_bid":"0.94","best_ask":"0.95"},{"asset_id":"54232589582260339592359130012520874109228367674780084862642636038394766871668","price":"0.06","size":"2097.55","side":"SELL","hash":"01a4d5c3e5c5ee9821cf627d762cf49e9a63a97d","best_bid":"0.05","best_ask":"0.06"}],"timestamp":"1768250246169","event_type":"price_change"}}
{"schema_version":1,"source":"clob_ws_market","recv_ts_ns":1768250246411960478,"event_type":"price_change","market":"0xe51aa24ab1bbfefce466d642ad98587d13123e4ef95ec9aa73b712e775d4cbba","server_ts_ms":1768250246188,"raw":{"market":"0xe51aa24ab1bbfefce466d642ad98587d13123e4ef95ec9aa73b712e775d4cbba","price_changes":[{"asset_id":"54232589582260339592359130012520874109228367674780084862642636038394766871668","price":"0.02","size":"5656.25","side":"BUY","hash":"b9ceffa413e427065bcb1e44f1ab7310f9b74344","best_bid":"0.05","best_ask":"0.06"},{"asset_id":"96886111393998001968863279421729456597655847484197549086072988901191634450924","price":"0.98","size":"5656.25","side":"SELL","hash":"0200f78731185f5b5273c79853ec89c5b0b37301","best_bid":"0.94","best_ask":"0.95"}],"timestamp":"1768250246188","event_type":"price_change"}}
{"schema_version":1,"source":"clob_ws_market","recv_ts_ns":1768250246415127404,"event_type":"price_change","market":"0xe51aa24ab1bbfefce466d642ad98587d13123e4ef95ec9aa73b712e775d4cbba","server_ts_ms":1768250246194,"raw":{"market":"0xe51aa24ab1bbfefce466d642ad98587d13123e4ef95ec9aa73b712e775d4cbba","price_changes":[{"asset_id":"96886111393998001968863279421729456597655847484197549086072988901191634450924","price":"0.94","size":"2113.55","side":"BUY","hash":"f342e21c8202e6bf5969cee87ea378532a96d608","best_bid":"0.94","best_ask":"0.95"},{"asset_id":"54232589582260339592359130012520874109228367674780084862642636038394766871668","price":"0.06","size":"2113.55","side":"SELL","hash":"6f3e782385f9dbcfeac9c2dab54ccb3e35b0abfe","best_bid":"0.05","best_ask":"0.06"}],"timestamp":"1768250246194","event_type":"price_change"}}
{"schema_version":1,"source":"clob_ws_market","recv_ts_ns":1768250246419671263,"event_type":"price_change","market":"0xe51aa24ab1bbfefce466d642ad98587d13123e4ef95ec9aa73b712e775d4cbba","server_ts_ms":1768250246203,"raw":{"market":"0xe51aa24ab1bbfefce466d642ad98587d13123e4ef95ec9aa73b712e775d4cbba","price_changes":[{"asset_id":"96886111393998001968863279421729456597655847484197549086072988901191634450924","price":"0.89","size":"1898.8","side":"BUY","hash":"fb47f061e8b98fefdd6f81b27ebc9f6d9999f6af","best_bid":"0.94","best_ask":"0.95"},{"asset_id":"54232589582260339592359130012520874109228367674780084862642636038394766871668","price":"0.11","size":"1898.8","side":"SELL","hash":"4a444a0aeceafc8b4e23050d951a3dd07d8fe612","best_bid":"0.05","best_ask":"0.06"}],"timestamp":"1768250246203","event_type":"price_change"}}
{"schema_version":1,"source":"clob_ws_market","recv_ts_ns":1768250246424180216,"event_type":"price_change","market":"0xe51aa24ab1bbfefce466d642ad98587d13123e4ef95ec9aa73b712e775d4cbba","server_ts_ms":1768250246204,"raw":{"market":"0xe51aa24ab1bbfefce466d642ad98587d13123e4ef95ec9aa73b712e775d4cbba","price_changes":[{"asset_id":"96886111393998001968863279421729456597655847484197549086072988901191634450924","price":"0.93","size":"1482.82","side":"BUY","hash":"8fc461b1b866e9ca53905ab8e9be25db748f1551","best_bid":"0.94","best_ask":"0.95"},{"asset_id":"54232589582260339592359130012520874109228367674780084862642636038394766871668","price":"0.07","size":"1482.82","side":"SELL","hash":"4e290abb7b8ad06cdb323953a3c8f5e8cc91a951","best_bid":"0.05","best_ask":"0.06"}],"timestamp":"1768250246204","event_type":"price_change"}}
{"schema_version":1,"source":"clob_ws_market","recv_ts_ns":1768250246428642142,"event_type":"price_change","market":"0xe51aa24ab1bbfefce466d642ad98587d13123e4ef95ec9aa73b712e775d4cbba","server_ts_ms":1768250246207,"raw":{"market":"0xe51aa24ab1bbfefce466d642ad98587d13123e4ef95ec9aa73b712e775d4cbba","price_changes":[{"asset_id":"54232589582260339592359130012520874109228367674780084862642636038394766871668","price":"0.01","size":"21028.9","side":"BUY","hash":"6f1826900e3b485d51cfdb7484839a2ab0420f00","best_bid":"0.05","best_ask":"0.06"},{"asset_id":"96886111393998001968863279421729456597655847484197549086072988901191634450924","price":"0.99","size":"21028.9","side":"SELL","hash":"cca0e2864c6a45a8272300c2372694ad77e7b5d4","best_bid":"0.94","best_ask":"0.95"}],"timestamp":"1768250246207","event_type":"price_change"}}
{"schema_version":1,"source":"clob_ws_market","recv_ts_ns":1768250246432766886,"event_type":"price_change","market":"0xe51aa24ab1bbfefce466d642ad98587d13123e4ef95ec9aa73b712e775d4cbba","server_ts_ms":1768250246216,"raw":{"market":"0xe51aa24ab1bbfefce466d642ad98587d13123e4ef95ec9aa73b712e775d4cbba","price_changes":[{"asset_id":"96886111393998001968863279421729456597655847484197549086072988901191634450924","price":"0.93","size":"1662.82","side":"BUY","hash":"a3708de7d4dd197ebb10334c698d1f97777cc079","best_bid":"0.94","best_ask":"0.95"},{"asset_id":"54232589582260339592359130012520874109228367674780084862642636038394766871668","price":"0.07","size":"1662.82","side":"SELL","hash":"18d1a83e4b248161e7521a94009f32151b2e71c0","best_bid":"0.05","best_ask":"0.06"}],"timestamp":"1768250246216","event_type":"price_change"}}
{"schema_version":1,"source":"clob_ws_market","recv_ts_ns":1768250246436532149,"event_type":"price_change","market":"0xe51aa24ab1bbfefce466d642ad98587d13123e4ef95ec9aa73b712e775d4cbba","server_ts_ms":1768250246222,"raw":{"market":"0xe51aa24ab1bbfefce466d642ad98587d13123e4ef95ec9aa73b712e775d4cbba","price_changes":[{"asset_id":"54232589582260339592359130012520874109228367674780084862642636038394766871668","price":"0.02","size":"5672.25","side":"BUY","hash":"2b3527563c8d2ffb3c0ae4074787a3e17b9e0301","best_bid":"0.05","best_ask":"0.06"},{"asset_id":"96886111393998001968863279421729456597655847484197549086072988901191634450924","price":"0.98","size":"5672.25","side":"SELL","hash":"18a7bd9eace9f2f440e957e795f444e2b70b0d85","best_bid":"0.94","best_ask":"0.95"}],"timestamp":"1768250246222","event_type":"price_change"}}
{"schema_version":1,"source":"clob_ws_market","recv_ts_ns":1768250246441517524,"event_type":"price_change","market":"0xe51aa24ab1bbfefce466d642ad98587d13123e4ef95ec9aa73b712e775d4cbba","server_ts_ms":1768250246222,"raw":{"market":"0xe51aa24ab1bbfefce466d642ad98587d13123e4ef95ec9aa73b712e775d4cbba","price_changes":[{"asset_id":"54232589582260339592359130012520874109228367674780084862642636038394766871668","price":"0.01","size":"21012.9","side":"BUY","hash":"fd86ccb6e0ea4d47b933f0e9e2b3163001fd71e7","best_bid":"0.05","best_ask":"0.06"},{"asset_id":"96886111393998001968863279421729456597655847484197549086072988901191634450924","price":"0.99","size":"21012.9","side":"SELL","hash":"4dc644e4504ab60375e45fe0fa7c667c6df12604","best_bid":"0.94","best_ask":"0.95"}],"timestamp":"1768250246222","event_type":"price_change"}}
{"schema_version":1,"source":"clob_ws_market","recv_ts_ns":1768250246445533485,"event_type":"price_change","market":"0xe51aa24ab1bbfefce466d642ad98587d13123e4ef95ec9aa73b712e775d4cbba","server_ts_ms":1768250246223,"raw":{"market":"0xe51aa24ab1bbfefce466d642ad98587d13123e4ef95ec9aa73b712e775d4cbba","price_changes":[{"asset_id":"96886111393998001968863279421729456597655847484197549086072988901191634450924","price":"0.94","size":"2097.55","side":"BUY","hash":"f60eebfe9b62621b241c253fc4efea5f3c54bffb","best_bid":"0.94","best_ask":"0.95"},{"asset_id":"54232589582260339592359130012520874109228367674780084862642636038394766871668","price":"0.06","size":"2097.55","side":"SELL","hash":"534a06017c8078d726aa65dcb8e22f982aa6f6e4","best_bid":"0.05","best_ask":"0.06"}],"timestamp":"1768250246223","event_type":"price_change"}}
{"schema_version":1,"source":"clob_ws_market","recv_ts_ns":1768250246449639343,"event_type":"price_change","market":"0xe51aa24ab1bbfefce466d642ad98587d13123e4ef95ec9aa73b712e775d4cbba","server_ts_ms":1768250246224,"raw":{"market":"0xe51aa24ab1bbfefce466d642ad98587d13123e4ef95ec9aa73b712e775d4cbba","price_changes":[{"asset_id":"96886111393998001968863279421729456597655847484197549086072988901191634450924","price":"0.94","size":"2081.55","side":"BUY","hash":"d7b6f201334ae63003f151c58496399a6e876133","best_bid":"0.94","best_ask":"0.95"},{"asset_id":"54232589582260339592359130012520874109228367674780084862642636038394766871668","price":"0.06","size":"2081.55","side":"SELL","hash":"96690f9204ebc418358d31991c0dc1bdff8d8c54","best_bid":"0.05","best_ask":"0.06"}],"timestamp":"1768250246224","event_type":"price_change"}}
{"schema_version":1,"source":"clob_ws_market","recv_ts_ns":1768250246453717459,"event_type":"price_change","market":"0xe51aa24ab1bbfefce466d642ad98587d13123e4ef95ec9aa73b712e775d4cbba","server_ts_ms":1768250246228,"raw":{"market":"0xe51aa24ab1bbfefce466d642ad98587d13123e4ef95ec9aa73b712e775d4cbba","price_changes":[{"asset_id":"54232589582260339592359130012520874109228367674780084862642636038394766871668","price":"0.01","size":"21028.9","side":"BUY","hash":"f6af46c8c05394733123d6945504720329d56004","best_bid":"0.05","best_ask":"0.06"},{"asset_id":"96886111393998001968863279421729456597655847484197549086072988901191634450924","price":"0.99","size":"21028.9","side":"SELL","hash":"9d474bd177286994a1bccff60ce4b2aa2ae3f52f","best_bid":"0.94","best_ask":"0.95"}],"timestamp":"1768250246228","event_type":"price_change"}}
{"schema_version":1,"source":"clob_ws_market","recv_ts_ns":1768250246463439112,"event_type":"price_change","market":"0xe51aa24ab1bbfefce466d642ad98587d13123e4ef95ec9aa73b712e775d4cbba","server_ts_ms":1768250246248,"raw":{"market":"0xe51aa24ab1bbfefce466d642ad98587d13123e4ef95ec9aa73b712e775d4cbba","price_changes":[{"asset_id":"96886111393998001968863279421729456597655847484197549086072988901191634450924","price":"0.01","size":"24295.73","side":"BUY","hash":"2530b032a80686296887259fbff283c80866673e","best_bid":"0.94","best_ask":"0.95"},{"asset_id":"54232589582260339592359130012520874109228367674780084862642636038394766871668","price":"0.99","size":"24295.73","side":"SELL","hash":"737bbfd5a9f1353735f61e540df951f9bb11a28e","best_bid":"0.05","best_ask":"0.06"}],"timestamp":"1768250246248","event_type":"price_change"}}
{"schema_version":1,"source":"clob_ws_market","recv_ts_ns":1768250246471274161,"event_type":"price_change","market":"0xe51aa24ab1bbfefce466d642ad98587d13123e4ef95ec9aa73b712e775d4cbba","server_ts_ms":1768250246258,"raw":{"market":"0xe51aa24ab1bbfefce466d642ad98587d13123e4ef95ec9aa73b712e775d4cbba","price_changes":[{"asset_id":"54232589582260339592359130012520874109228367674780084862642636038394766871668","price":"0.01","size":"21044.9","side":"BUY","hash":"dc7a82b81f7646b51d422c360ca285bf370415c6","best_bid":"0.05","best_ask":"0.06"},{"asset_id":"96886111393998001968863279421729456597655847484197549086072988901191634450924","price":"0.99","size":"21044.9","side":"SELL","hash":"7a0f1b56a3fbb8ee37651e3818067575bbaaf9f0","best_bid":"0.94","best_ask":"0.95"}],"timestamp":"1768250246258","event_type":"price_change"}}
{"schema_version":1,"source":"clob_ws_market","recv_ts_ns":1768250246476083159,"event_type":"price_change","market":"0xe51aa24ab1bbfefce466d642ad98587d13123e4ef95ec9aa73b712e775d4cbba","server_ts_ms":1768250246259,"raw":{"market":"0xe51aa24ab1bbfefce466d642ad98587d13123e4ef95ec9aa73b712e775d4cbba","price_changes":[{"asset_id":"54232589582260339592359130012520874109228367674780084862642636038394766871668","price":"0.01","size":"21028.9","side":"BUY","hash":"5f1eae2002ed481e947b77a51185ef861fc2417b","best_bid":"0.05","best_ask":"0.06"},{"asset_id":"96886111393998001968863279421729456597655847484197549086072988901191634450924","price":"0.99","size":"21028.9","side":"SELL","hash":"f54d5e280a3e4a2500a643a483b6b5cc80b26fe0","best_bid":"0.94","best_ask":"0.95"}],"timestamp":"1768250246259","event_type":"price_change"}}
{"schema_version":1,"source":"clob_ws_market","recv_ts_ns":1768250246480543927,"event_type":"price_change","market":"0xe51aa24ab1bbfefce466d642ad98587d13123e4ef95ec9aa73b712e775d4cbba","server_ts_ms":1768250246260,"raw":{"market":"0xe51aa24ab1bbfefce466d642ad98587d13123e4ef95ec9aa73b712e775d4cbba","price_changes":[{"asset_id":"96886111393998001968863279421729456597655847484197549086072988901191634450924","price":"0.94","size":"2097.55","side":"BUY","hash":"d90a36a0308295400e688b9fa7a6cefd0363b23b","best_bid":"0.94","best_ask":"0.95"},{"asset_id":"54232589582260339592359130012520874109228367674780084862642636038394766871668","price":"0.06","size":"2097.55","side":"SELL","hash":"397991d69334a53b665d4f3f935748b25a0707e5","best_bid":"0.05","best_ask":"0.06"}],"timestamp":"1768250246260","event_type":"price_change"}}
{"schema_version":1,"source":"clob_ws_market","recv_ts_ns":1768250246485153134,"event_type":"price_change","market":"0xe51aa24ab1bbfefce466d642ad98587d13123e4ef95ec9aa73b712e775d4cbba","server_ts_ms":1768250246270,"raw":{"market":"0xe51aa24ab1bbfefce466d642ad98587d13123e4ef95ec9aa73b712e775d4cbba","price_changes":[{"asset_id":"96886111393998001968863279421729456597655847484197549086072988901191634450924","price":"0.94","size":"2113.55","side":"BUY","hash":"f8ca209168d4c259661e17e601bdf0c4413d56ba","best_bid":"0.94","best_ask":"0.95"},{"asset_id":"54232589582260339592359130012520874109228367674780084862642636038394766871668","price":"0.06","size":"2113.55","side":"SELL","hash":"b8507eaf52ce0fba2f8aab8bb77dde817db4a01f","best_bid":"0.05","best_ask":"0.06"}],"timestamp":"1768250246270","event_type":"price_change"}}
{"schema_version":1,"source":"clob_ws_market","recv_ts_ns":1768250246489598112,"event_type":"price_change","market":"0xe51aa24ab1bbfefce466d642ad98587d13123e4ef95ec9aa73b712e775d4cbba","server_ts_ms":1768250246271,"raw":{"market":"0xe51aa24ab1bbfefce466d642ad98587d13123e4ef95ec9aa73b712e775d4cbba","price_changes":[{"asset_id":"96886111393998001968863279421729456597655847484197549086072988901191634450924","price":"0.94","size":"2134.55","side":"BUY","hash":"5c82a59b587af89e2c42bb00a09d938babd96a01","best_bid":"0.94","best_ask":"0.95"},{"asset_id":"54232589582260339592359130012520874109228367674780084862642636038394766871668","price":"0.06","size":"2134.55","side":"SELL","hash":"1ef74f6285bc8334886f3920d00867ef9329d4af","best_bid":"0.05","best_ask":"0.06"}],"timestamp":"1768250246271","event_type":"price_change"}}
{"schema_version":1,"source":"clob_ws_market","recv_ts_ns":1768250246495617369,"event_type":"price_change","market":"0xe51aa24ab1bbfefce466d642ad98587d13123e4ef95ec9aa73b712e775d4cbba","server_ts_ms":1768250246272,"raw":{"market":"0xe51aa24ab1bbfefce466d642ad98587d13123e4ef95ec9aa73b712e775d4cbba","price_changes":[{"asset_id":"96886111393998001968863279421729456597655847484197549086072988901191634450924","price":"0.93","size":"1587.82","side":"BUY","hash":"80babad7f6c831c902d161338894d37dccd9cf11","best_bid":"0.94","best_ask":"0.95"},{"asset_id":"54232589582260339592359130012520874109228367674780084862642636038394766871668","price":"0.07","size":"1587.82","side":"SELL","hash":"58ab77ed380dde66a777f36c13379cde3f65479b","best_bid":"0.05","best_ask":"0.06"}],"timestamp":"1768250246272","event_type":"price_change"}}
{"schema_version":1,"source":"clob_ws_market","recv_ts_ns":1768250246500677235,"event_type":"price_change","market":"0xe51aa24ab1bbfefce466d642ad98587d13123e4ef95ec9aa73b712e775d4cbba","server_ts_ms":1768250246273,"raw":{"market":"0xe51aa24ab1bbfefce466d642ad98587d13123e4ef95ec9aa73b712e775d4cbba","price_changes":[{"asset_id":"96886111393998001968863279421729456597655847484197549086072988901191634450924","price":"0.95","size":"103.74","side":"SELL","hash":"e4eed0e5c5e786a8393746093e994e5651ae1ef7","best_bid":"0.94","best_ask":"0.95"},{"asset_id":"54232589582260339592359130012520874109228367674780084862642636038394766871668","price":"0.05","size":"103.74","side":"BUY","hash":"ec621fe378ed42f8c3d20ab48835a670324fa045","best_bid":"0.05","best_ask":"0.06"}],"timestamp":"1768250246273","event_type":"price_change"}}
{"schema_version":1,"source":"clob_ws_market","recv_ts_ns":1768250246505531113,"event_type":"price_change","market":"0xe51aa24ab1bbfefce466d642ad98587d13123e4ef95ec9aa73b712e775d4cbba","server_ts_ms":1768250246278,"raw":{"market":"0xe51aa24ab1bbfefce466d642ad98587d13123e4ef95ec9aa73b712e775d4cbba","price_changes":[{"asset_id":"54232589582260339592359130012520874109228367674780084862642636038394766871668","price":"0.03","size":"1579.6","side":"BUY","hash":"84f9f1dee73085b07be005ce120f0b4d191f3b55","best_bid":"0.05","best_ask":"0.06"},{"asset_id":"96886111393998001968863279421729456597655847484197549086072988901191634450924","price":"0.97","size":"1579.6","side":"SELL","hash":"18a01c053d9066472f3a8be446c153b7fd3ec292","best_bid":"0.94","best_ask":"0.95"}],"timestamp":"1768250246278","event_type":"price_change"}}
{"schema_version":1,"source":"clob_ws_market","recv_ts_ns":1768250246510273046,"event_type":"price_change","market":"0xe51aa24ab1bbfefce466d642ad98587d13123e4ef95ec9aa73b712e775d4cbba","server_ts_ms":1768250246278,"raw":{"market":"0xe51aa24ab1bbfefce466d642ad98587d13123e4ef95ec9aa73b712e775d4cbba","price_changes":[{"asset_id":"54232589582260339592359130012520874109228367674780084862642636038394766871668","price":"0.03","size":"1278.6","side":"BUY","hash":"9dc36ef11de6163634326d2b93f3d8bb8ce71071","best_bid":"0.05","best_ask":"0.06"},{"asset_id":"96886111393998001968863279421729456597655847484197549086072988901191634450924","price":"0.97","size":"1278.6","side":"SELL","hash":"877789f65cacac4912a61f8a64b4d8cd91f5a3b2","best_bid":"0.94","best_ask":"0.95"}],"timestamp":"1768250246278","event_type":"price_change"}}
{"schema_version":1,"source":"clob_ws_market","recv_ts_ns":1768250246514811744,"event_type":"price_change","market":"0xe51aa24ab1bbfefce466d642ad98587d13123e4ef95ec9aa73b712e775d4cbba","server_ts_ms":1768250246283,"raw":{"market":"0xe51aa24ab1bbfefce466d642ad98587d13123e4ef95ec9aa73b712e775d4cbba","price_changes":[{"asset_id":"96886111393998001968863279421729456597655847484197549086072988901191634450924","price":"0.94","size":"2122.55","side":"BUY","hash":"a38f2ec31cacd3a7fecff76a27f67f16f98a3ea2","best_bid":"0.94","best_ask":"0.95"},{"asset_id":"54232589582260339592359130012520874109228367674780084862642636038394766871668","price":"0.06","size":"2122.55","side":"SELL","hash":"33ba5636ad675af6828fab1dcdd9f9fc6902d1d9","best_bid":"0.05","best_ask":"0.06"}],"timestamp":"1768250246283","event_type":"price_change"}}
{"schema_version":1,"source":"clob_ws_market","recv_ts_ns":1768250246520013684,"event_type":"price_change","market":"0xe51aa24ab1bbfefce466d642ad98587d13123e4ef95ec9aa73b712e775d4cbba","server_ts_ms":1768250246285,"raw":{"market":"0xe51aa24ab1bbfefce466d642ad98587d13123e4ef95ec9aa73b712e775d4cbba","price_changes":[{"asset_id":"54232589582260339592359130012520874109228367674780084862642636038394766871668","price":"0.04","size":"1671.4","side":"BUY","hash":"027ff93e397377afceefd2bc60666067d21d5816","best_bid":"0.05","best_ask":"0.06"},{"asset_id":"96886111393998001968863279421729456597655847484197549086072988901191634450924","price":"0.96","size":"1671.4","side":"SELL","hash":"7d8b73ae66ca22a6ed2ee7f1a3449435a0cd0ad9","best_bid":"0.94","best_ask":"0.95"}],"timestamp":"1768250246285","event_type":"price_change"}}
{"schema_version":1,"source":"clob_ws_market","recv_ts_ns":1768250246524616334,"event_type":"price_change","market":"0xe51aa24ab1bbfefce466d642ad98587d13123e4ef95ec9aa73b712e775d4cbba","server_ts_ms":1768250246288,"raw":{"market":"0xe51aa24ab1bbfefce466d642ad98587d13123e4ef95ec9aa73b712e775d4cbba","price_changes":[{"asset_id":"96886111393998001968863279421729456597655847484197549086072988901191634450924","price":"0.89","size":"2098.8","side":"BUY","hash":"dcf8784d759d91a269c96ca479ce007ed394608c","best_bid":"0.94","best_ask":"0.95"},{"asset_id":"54232589582260339592359130012520874109228367674780084862642636038394766871668","price":"0.11","size":"2098.8","side":"SELL","hash":"de76efef3e0108619ccfa8531ab8c4f17b09ab3a","best_bid":"0.05","best_ask":"0.06"}],"timestamp":"1768250246288","event_type":"price_change"}}
{"schema_version":1,"source":"clob_ws_market","recv_ts_ns":1768250246528489294,"event_type":"price_change","market":"0xe51aa24ab1bbfefce466d642ad98587d13123e4ef95ec9aa73b712e775d4cbba","server_ts_ms":1768250246289,"raw":{"market":"0xe51aa24ab1bbfefce466d642ad98587d13123e4ef95ec9aa73b712e775d4cbba","price_changes":[{"asset_id":"54232589582260339592359130012520874109228367674780084862642636038394766871668","price":"0.01","size":"21012.9","side":"BUY","hash":"a275bd6c0cf096374b0e4e065d7b7203a4547c73","best_bid":"0.05","best_ask":"0.06"},{"asset_id":"96886111393998001968863279421729456597655847484197549086072988901191634450924","price":"0.99","size":"21012.9","side":"SELL","hash":"131847a09c8210f9e8a2696dd7e18afee04ed5d9","best_bid":"0.94","best_ask":"0.95"}],"timestamp":"1768250246289","event_type":"price_change"}}
{"schema_version":1,"source":"clob_ws_market","recv_ts_ns":1768250246535206683,"event_type":"price_change","market":"0xe51aa24ab1bbfefce466d642ad98587d13123e4ef95ec9aa73b712e775d4cbba","server_ts_ms":1768250246292,"raw":{"market":"0xe51aa24ab1bbfefce466d642ad98587d13123e4ef95ec9aa73b712e775d4cbba","price_changes":[{"asset_id":"54232589582260339592359130012520874109228367674780084862642636038394766871668","price":"0.02","size":"5656.25","side":"BUY","hash":"f2cd77a20c39907d7e5273c739344f1a788d7e45","best_bid":"0.05","best_ask":"0.06"},{"asset_id":"96886111393998001968863279421729456597655847484197549086072988901191634450924","price":"0.98","size":"5656.25","side":"SELL","hash":"ee2c72c6c68894632f671477337443ffb814b45c","best_bid":"0.94","best_ask":"0.95"}],"timestamp":"1768250246292","event_type":"price_change"}}
{"schema_version":1,"source":"clob_ws_market","recv_ts_ns":1768250246538673819,"event_type":"price_change","market":"0xe51aa24ab1bbfefce466d642ad98587d13123e4ef95ec9aa73b712e775d4cbba","server_ts_ms":1768250246292,"raw":{"market":"0xe51aa24ab1bbfefce466d642ad98587d13123e4ef95ec9aa73b712e775d4cbba","price_changes":[{"asset_id":"54232589582260339592359130012520874109228367674780084862642636038394766871668","price":"0.02","size":"5355.25","side":"BUY","hash":"40563f175f5fc97e39e781ed5a44adbc36580c80","best_bid":"0.05","best_ask":"0.06"},{"asset_id":"96886111393998001968863279421729456597655847484197549086072988901191634450924","price":"0.98","size":"5355.25","side":"SELL","hash":"3a4cd241a9db526477ef6c19a3b2988d83ea98d5","best_bid":"0.94","best_ask":"0.95"}],"timestamp":"1768250246292","event_type":"price_change"}}
{"schema_version":1,"source":"clob_ws_market","recv_ts_ns":1768250246542385754,"event_type":"price_change","market":"0xe51aa24ab1bbfefce466d642ad98587d13123e4ef95ec9aa73b712e775d4cbba","server_ts_ms":1768250246296,"raw":{"market":"0xe51aa24ab1bbfefce466d642ad98587d13123e4ef95ec9aa73b712e775d4cbba","price_changes":[{"asset_id":"96886111393998001968863279421729456597655847484197549086072988901191634450924","price":"0.94","size":"2106.55","side":"BUY","hash":"3b4831f2a45a6a1fa71862d16029399dbb2c1f73","best_bid":"0.94","best_ask":"0.95"},{"asset_id":"54232589582260339592359130012520874109228367674780084862642636038394766871668","price":"0.06","size":"2106.55","side":"SELL","hash":"27ec4c38b804fc77f6da3c33835df72827a8d63c","best_bid":"0.05","best_ask":"0.06"}],"timestamp":"1768250246296","event_type":"price_change"}}
{"schema_version":1,"source":"clob_ws_market","recv_ts_ns":1768250246545659918,"event_type":"price_change","market":"0xe51aa24ab1bbfefce466d642ad98587d13123e4ef95ec9aa73b712e775d4cbba","server_ts_ms":1768250246298,"raw":{"market":"0xe51aa24ab1bbfefce466d642ad98587d13123e4ef95ec9aa73b712e775d4cbba","price_changes":[{"asset_id":"54232589582260339592359130012520874109228367674780084862642636038394766871668","price":"0.01","size":"21028.9","side":"BUY","hash":"82e4df308f6b18cd17b133ed574b9ddb0fddc701","best_bid":"0.05","best_ask":"0.06"},{"asset_id":"96886111393998001968863279421729456597655847484197549086072988901191634450924","price":"0.99","size":"21028.9","side":"SELL","hash":"ce4989a85e2f6637e6a531eb0752c26abb10d993","best_bid":"0.94","best_ask":"0.95"}],"timestamp":"1768250246298","event_type":"price_change"}}
{"schema_version":1,"source":"clob_ws_market","recv_ts_ns":1768250246548944589,"event_type":"price_change","market":"0xe51aa24ab1bbfefce466d642ad98587d13123e4ef95ec9aa73b712e775d4cbba","server_ts_ms":1768250246303,"raw":{"market":"0xe51aa24ab1bbfefce466d642ad98587d13123e4ef95ec9aa73b712e775d4cbba","price_changes":[{"asset_id":"54232589582260339592359130012520874109228367674780084862642636038394766871668","price":"0.02","size":"4355.25","side":"BUY","hash":"fd7a34da9430c31e38ceada4f92ed6cdcac42f4f","best_bid":"0.05","best_ask":"0.06"},{"asset_id":"96886111393998001968863279421729456597655847484197549086072988901191634450924","price":"0.98","size":"4355.25","side":"SELL","hash":"04a96c083823a7ca09d55040c09e54f0997181be","best_bid":"0.94","best_ask":"0.95"}],"timestamp":"1768250246303","event_type":"price_change"}}
{"schema_version":1,"source":"clob_ws_market","recv_ts_ns":1768250246552469336,"event_type":"price_change","market":"0xe51aa24ab1bbfefce466d642ad98587d13123e4ef95ec9aa73b712e775d4cbba","server_ts_ms":1768250246307,"raw":{"market":"0xe51aa24ab1bbfefce466d642ad98587d13123e4ef95ec9aa73b712e775d4cbba","price_changes":[{"asset_id":"96886111393998001968863279421729456597655847484197549086072988901191634450924","price":"0.94","size":"2114.55","side":"BUY","hash":"11e87cee1e84ae713b21428c24c8ab31236355ce","best_bid":"0.94","best_ask":"0.95"},{"asset_id":"54232589582260339592359130012520874109228367674780084862642636038394766871668","price":"0.06","size":"2114.55","side":"SELL","hash":"07bbabc7853e59581dad402707f13dccaf7515ae","best_bid":"0.05","best_ask":"0.06"}],"timestamp":"1768250246307","event_type":"price_change"}}
{"schema_version":1,"source":"clob_ws_market","recv_ts_ns":1768250246558952184,"event_type":"best_bid_ask","market":"0xe51aa24ab1bbfefce466d642ad98587d13123e4ef95ec9aa73b712e775d4cbba","server_ts_ms":1768250246318,"raw":{"market":"0xe51aa24ab1bbfefce466d642ad98587d13123e4ef95ec9aa73b712e775d4cbba","asset_id":"96886111393998001968863279421729456597655847484197549086072988901191634450924","best_bid":"0.94","best_ask":"0.95","spread":"0.01","timestamp":"1768250246318","event_type":"best_bid_ask"}}
{"schema_version":1,"source":"clob_ws_market","recv_ts_ns":1768250246561775809,"event_type":"price_change","market":"0xe51aa24ab1bbfefce466d642ad98587d13123e4ef95ec9aa73b712e775d4cbba","server_ts_ms":1768250246317,"raw":{"market":"0xe51aa24ab1bbfefce466d642ad98587d13123e4ef95ec9aa73b712e775d4cbba","price_changes":[{"asset_id":"96886111393998001968863279421729456597655847484197549086072988901191634450924","price":"0.94","size":"2031.21","side":"BUY","hash":"b8d1f583e6ad762762b2d41eef22e2b5eb91f5bc","best_bid":"0.94","best_ask":"0.95"},{"asset_id":"54232589582260339592359130012520874109228367674780084862642636038394766871668","price":"0.06","size":"2031.21","side":"SELL","hash":"75ae5467c179f8a7edeb2c3423dd690936e85c1d","best_bid":"0.05","best_ask":"0.06"}],"timestamp":"1768250246317","event_type":"price_change"}}
{"schema_version":1,"source":"clob_ws_market","recv_ts_ns":1768250246572582310,"event_type":"book","market":"0xe51aa24ab1bbfefce466d642ad98587d13123e4ef95ec9aa73b712e775d4cbba","server_ts_ms":1768250246317,"raw":{"market":"0xe51aa24ab1bbfefce466d642ad98587d13123e4ef95ec9aa73b712e775d4cbba","asset_id":"96886111393998001968863279421729456597655847484197549086072988901191634450924","bids":[{"price":"0.01","size":"24295.73"},{"price":"0.02","size":"7594.51"},{"price":"0.03","size":"5964.69"},{"price":"0.04","size":"5411.4"},{"price":"0.05","size":"5356.39"},{"price":"0.06","size":"5328"},{"price":"0.07","size":"5039.28"},{"price":"0.08","size":"5022.7"},{"price":"0.09","size":"5320.9"},{"price":"0.1","size":"5158.44"},{"price":"0.11","size":"18.3"},{"price":"0.12","size":"30.3"},{"price":"0.13","size":"16.5"},{"price":"0.14","size":"15.8"},{"price":"0.15","size":"104.19"},{"price":"0.16","size":"24.69"},{"price":"0.17","size":"14.19"},{"price":"0.18","size":"13.8"},{"price":"0.19","size":"13.4"},{"price":"0.2","size":"38.1"},{"price":"0.21","size":"12.8"},{"price":"0.22","size":"12.6"},{"price":"0.23","size":"12.3"},{"price":"0.24","size":"22.1"},{"price":"0.25","size":"16.9"},{"price":"0.26","size":"21.8"},{"price":"0.27","size":"11.6"},{"price":"0.28","size":"11.4"},{"price":"0.29","size":"61.3"},{"price":"0.3","size":"26.2"},{"price":"0.31","size":"11.1"},{"price":"0.32","size":"11"},{"price":"0.33","size":"110.9"},{"price":"0.34","size":"10.8"},{"price":"0.35","size":"15.7"},{"price":"0.36","size":"10.6"},{"price":"0.37","size":"10.6"},{"price":"0.38","size":"22.5"},{"price":"0.39","size":"10.5"},{"price":"0.4","size":"45.4"},{"price":"0.41","size":"311.4"},{"price":"0.42","size":"820.82"},{"price":"0.43","size":"826.3"},{"price":"0.44","size":"1062.3"},{"price":"0.45","size":"582.3"},{"price":"0.46","size":"626.2"},{"price":"0.47","size":"562.2"},{"price":"0.48","size":"567.2"},{"price":"0.49","size":"573.2"},{"price":"0.5","size":"917.2"},{"price":"0.51","size":"591.2"},{"price":"0.52","size":"590.2"},{"price":"0.53","size":"567.2"},{"price":"0.54","size":"642.61"},{"price":"0.55","size":"362.97"},{"price":"0.56","size":"341.3"},{"price":"0.57","size":"320.62"},{"price":"0.58","size":"567.3"},{"price":"0.59","size":"562.4"},{"price":"0.6","size":"693.02"},{"price":"0.61","size":"625.5"},{"price":"0.62","size":"700.5"},{"price":"0.63","size":"672.32"},{"price":"0.64","size":"680.6"},{"price":"0.65","size":"536.14"},{"price":"0.66","size":"602.8"},{"price":"0.67","size":"572.9"},{"price":"0.68","size":"573"},{"price":"0.69","size":"595.1"},{"price":"0.7","size":"603.2"},{"price":"0.71","size":"1318.72"},{"price":"0.72","size":"1043.04"},{"price":"0.73","size":"663.6"},{"price":"0.74","size":"911.17"},{"price":"0.75","size":"694.3"},{"price":"0.76","size":"717.6"},{"price":"0.77","size":"1183.3"},{"price":"0.78","size":"1526.53"},{"price":"0.79","size":"1178.8"},{"price":"0.8","size":"1445.08"},{"price":"0.81","size":"1229.8"},{"price":"0.82","size":"1467.57"},{"price":"0.83","size":"1470.51"},{"price":"0.84","size":"1718.59"},{"price":"0.85","size":"1762.5"},{"price":"0.86","size":"1755.6"},{"price":"0.87","size":"1588.93"},{"price":"0.88","size":"2355.4"},{"price":"0.89","size":"2098.8"},{"price":"0.9","size":"3439.34"},{"price":"0.91","size":"3012.44"},{"price":"0.92","size":"2549.36"},{"price":"0.93","size":"1587.82"},{"price":"0.94","size":"2031.21"}],"asks":[{"price":"0.99","size":"21028.9"},{"price":"0.98","size":"4355.25"},{"price":"0.97","size":"1278.6"},{"price":"0.96","size":"1671.4"},{"price":"0.95","size":"103.74"}],"hash":"b8d1f583e6ad762762b2d41eef22e2b5eb91f5bc","timestamp":"1768250246317","event_type":"book"}}
{"schema_version":1,"source":"clob_ws_market","recv_ts_ns":1768250246575869593,"event_type":"price_change","market":"0xe51aa24ab1bbfefce466d642ad98587d13123e4ef95ec9aa73b712e775d4cbba","server_ts_ms":1768250246318,"raw":{"market":"0xe51aa24ab1bbfefce466d642ad98587d13123e4ef95ec9aa73b712e775d4cbba","price_changes":[{"asset_id":"54232589582260339592359130012520874109228367674780084862642636038394766871668","price":"0.03","size":"1294.6","side":"BUY","hash":"a747a1442293a6c22a936b9dbac9c8548d149b95","best_bid":"0.05","best_ask":"0.06"},{"asset_id":"96886111393998001968863279421729456597655847484197549086072988901191634450924","price":"0.97","size":"1294.6","side":"SELL","hash":"9966b9b23210723c85f8979f8f854b6766e36a8b","best_bid":"0.94","best_ask":"0.95"}],"timestamp":"1768250246318","event_type":"price_change"}}
{"schema_version":1,"source":"clob_ws_market","recv_ts_ns":1768250246580023260,"event_type":"price_change","market":"0xe51aa24ab1bbfefce466d642ad98587d13123e4ef95ec9aa73b712e775d4cbba","server_ts_ms":1768250246319,"raw":{"market":"0xe51aa24ab1bbfefce466d642ad98587d13123e4ef95ec9aa73b712e775d4cbba","price_changes":[{"asset_id":"54232589582260339592359130012520874109228367674780084862642636038394766871668","price":"0.01","size":"21044.9","side":"BUY","hash":"1a406178c120ca6dbd90c646f43e10968ac79931","best_bid":"0.05","best_ask":"0.06"},{"asset_id":"96886111393998001968863279421729456597655847484197549086072988901191634450924","price":"0.99","size":"21044.9","side":"SELL","hash":"a9694c6c7bd94f89f41953fe930a7042ef620f26","best_bid":"0.94","best_ask":"0.95"}],"timestamp":"1768250246319","event_type":"price_change"}}
{"schema_version":1,"source":"clob_ws_market","recv_ts_ns":1768250246586805904,"event_type":"price_change","market":"0xe51aa24ab1bbfefce466d642ad98587d13123e4ef95ec9aa73b712e775d4cbba","server_ts_ms":1768250246321,"raw":{"market":"0xe51aa24ab1bbfefce466d642ad98587d13123e4ef95ec9aa73b712e775d4cbba","price_changes":[{"asset_id":"54232589582260339592359130012520874109228367674780084862642636038394766871668","price":"0.02","size":"4371.25","side":"BUY","hash":"7013860e6f52f1b90378c72e19f02660754d2f6f","best_bid":"0.05","best_ask":"0.06"},{"asset_id":"96886111393998001968863279421729456597655847484197549086072988901191634450924","price":"0.98","size":"4371.25","side":"SELL","hash":"139d5ef290bbdd92cd68025e011255e09344cebe","best_bid":"0.94","best_ask":"0.95"}],"timestamp":"1768250246321","event_type":"price_change"}}
{"schema_version":1,"source":"clob_ws_market","recv_ts_ns":1768250246590170713,"event_type":"price_change","market":"0xe51aa24ab1bbfefce466d642ad98587d13123e4ef95ec9aa73b712e775d4cbba","server_ts_ms":1768250246321,"raw":{"market":"0xe51aa24ab1bbfefce466d642ad98587d13123e4ef95ec9aa73b712e775d4cbba","price_changes":[{"asset_id":"96886111393998001968863279421729456597655847484197549086072988901191634450924","price":"0.93","size":"1571.82","side":"BUY","hash":"89e04de78207426d328d743c2566d1eeaecf0c0e","best_bid":"0.94","best_ask":"0.95"},{"asset_id":"54232589582260339592359130012520874109228367674780084862642636038394766871668","price":"0.07","size":"1571.82","side":"SELL","hash":"8700e542dcf778d1633c5e380b041b19323e734d","best_bid":"0.05","best_ask":"0.06"}],"timestamp":"1768250246321","event_type":"price_change"}}
{"schema_version":1,"source":"clob_ws_market","recv_ts_ns":1768250246593458777,"event_type":"price_change","market":"0xe51aa24ab1bbfefce466d642ad98587d13123e4ef95ec9aa73b712e775d4cbba","server_ts_ms":1768250246322,"raw":{"market":"0xe51aa24ab1bbfefce466d642ad98587d13123e4ef95ec9aa73b712e775d4cbba","price_changes":[{"asset_id":"54232589582260339592359130012520874109228367674780084862642636038394766871668","price":"0.03","size":"1278.6","side":"BUY","hash":"c00d6db55c012f0bec198ae800b503e72d5bcd6c","best_bid":"0.05","best_ask":"0.06"},{"asset_id":"96886111393998001968863279421729456597655847484197549086072988901191634450924","price":"0.97","size":"1278.6","side":"SELL","hash":"9e9241811d781c88da1eddd8940533ae3b24c4a7","best_bid":"0.94","best_ask":"0.95"}],"timestamp":"1768250246322","event_type":"price_change"}}
{"schema_version":1,"source":"clob_ws_market","recv_ts_ns":1768250246596483941,"event_type":"price_change","market":"0xe51aa24ab1bbfefce466d642ad98587d13123e4ef95ec9aa73b712e775d4cbba","server_ts_ms":1768250246329,"raw":{"market":"0xe51aa24ab1bbfefce466d642ad98587d13123e4ef95ec9aa73b712e775d4cbba","price_changes":[{"asset_id":"54232589582260339592359130012520874109228367674780084862642636038394766871668","price":"0.01","size":"21028.9","side":"BUY","hash":"c8eafb58bfffebdc39d295d2f079d654a19b564c","best_bid":"0.05","best_ask":"0.06"},{"asset_id":"96886111393998001968863279421729456597655847484197549086072988901191634450924","price":"0.99","size":"21028.9","side":"SELL","hash":"4060ffa454fa02329ee92adcb900a34fb8f5ebaf","best_bid":"0.94","best_ask":"0.95"}],"timestamp":"1768250246329","event_type":"price_change"}}
{"schema_version":1,"source":"clob_ws_market","recv_ts_ns":1768250246599418541,"event_type":"price_change","market":"0xe51aa24ab1bbfefce466d642ad98587d13123e4ef95ec9aa73b712e775d4cbba","server_ts_ms":1768250246339,"raw":{"market":"0xe51aa24ab1bbfefce466d642ad98587d13123e4ef95ec9aa73b712e775d4cbba","price_changes":[{"asset_id":"96886111393998001968863279421729456597655847484197549086072988901191634450924","price":"0.93","size":"1391.82","side":"BUY","hash":"9e81204b0be59ccfc44436ee77caf5cdaf2f2b6d","best_bid":"0.94","best_ask":"0.95"},{"asset_id":"54232589582260339592359130012520874109228367674780084862642636038394766871668","price":"0.07","size":"1391.82","side":"SELL","hash":"078aebd103b6ec5391b52a0069d692877538362f","best_bid":"0.05","best_ask":"0.06"}],"timestamp":"1768250246339","event_type":"price_change"}}
{"schema_version":1,"source":"clob_ws_market","recv_ts_ns":1768250246602793508,"event_type":"price_change","market":"0xe51aa24ab1bbfefce466d642ad98587d13123e4ef95ec9aa73b712e775d4cbba","server_ts_ms":1768250246340,"raw":{"market":"0xe51aa24ab1bbfefce466d642ad98587d13123e4ef95ec9aa73b712e775d4cbba","price_changes":[{"asset_id":"54232589582260339592359130012520874109228367674780084862642636038394766871668","price":"0.03","size":"1262.6","side":"BUY","hash":"6960f09eb3671dcfa7719d6c48f1dddd5306300d","best_bid":"0.05","best_ask":"0.06"},{"asset_id":"96886111393998001968863279421729456597655847484197549086072988901191634450924","price":"0.97","size":"1262.6","side":"SELL","hash":"97f74c1d8d8cbda60391ad632085c7c8e772e3f4","best_bid":"0.94","best_ask":"0.95"}],"timestamp":"1768250246340","event_type":"price_change"}}
{"schema_version":1,"source":"clob_ws_market","recv_ts_ns":1768250246605845588,"event_type":"price_change","market":"0xe51aa24ab1bbfefce466d642ad98587d13123e4ef95ec9aa73b712e775d4cbba","server_ts_ms":1768250246341,"raw":{"market":"0xe51aa24ab1bbfefce466d642ad98587d13123e4ef95ec9aa73b712e775d4cbba","price_changes":[{"asset_id":"96886111393998001968863279421729456597655847484197549086072988901191634450924","price":"0.94","size":"2047.21","side":"BUY","hash":"9b065cb52fbddb28809f51f49160573b8479fc90","best_bid":"0.94","best_ask":"0.95"},{"asset_id":"54232589582260339592359130012520874109228367674780084862642636038394766871668","price":"0.06","size":"2047.21","side":"SELL","hash":"b840f10f8288bd5cfd336aca38e5693e704d74d6","best_bid":"0.05","best_ask":"0.06"}],"timestamp":"1768250246341","event_type":"price_change"}}
{"schema_version":1,"source":"clob_ws_market","recv_ts_ns":1768250246610969981,"event_type":"price_change","market":"0xe51aa24ab1bbfefce466d642ad98587d13123e4ef95ec9aa73b712e775d4cbba","server_ts_ms":1768250246352,"raw":{"market":"0xe51aa24ab1bbfefce466d642ad98587d13123e4ef95ec9aa73b712e775d4cbba","price_changes":[{"asset_id":"96886111393998001968863279421729456597655847484197549086072988901191634450924","price":"0.9","size":"3433.34","side":"BUY","hash":"2186531f693f4e93afebbc0bc34932fa0a05c7e7","best_bid":"0.94","best_ask":"0.95"},{"asset_id":"54232589582260339592359130012520874109228367674780084862642636038394766871668","price":"0.1","size":"3433.34","side":"SELL","hash":"94de716b47a7a5d089a3f7870c72fb67dc10626c","best_bid":"0.05","best_ask":"0.06"}],"timestamp":"1768250246352","event_type":"price_change"}}
{"schema_version":1,"source":"clob_ws_market","recv_ts_ns":1768250246614312785,"event_type":"price_change","market":"0xe51aa24ab1bbfefce466d642ad98587d13123e4ef95ec9aa73b712e775d4cbba","server_ts_ms":1768250246353,"raw":{"market":"0xe51aa24ab1bbfefce466d642ad98587d13123e4ef95ec9aa73b712e775d4cbba","price_changes":[{"asset_id":"96886111393998001968863279421729456597655847484197549086072988901191634450924","price":"0.94","size":"2063.21","side":"BUY","hash":"e598387baf1611de46dddae23a66128bdf7e57b2","best_bid":"0.94","best_ask":"0.95"},{"asset_id":"54232589582260339592359130012520874109228367674780084862642636038394766871668","price":"0.06","size":"2063.21","side":"SELL","hash":"a7ccd8e51a92ab6ed6ac0acc01177892330c162a","best_bid":"0.05","best_ask":"0.06"}],"timestamp":"1768250246353","event_type":"price_change"}}
{"schema_version":1,"source":"clob_ws_market","recv_ts_ns":1768250246617882652,"event_type":"price_change","market":"0xe51aa24ab1bbfefce466d642ad98587d13123e4ef95ec9aa73b712e775d4cbba","server_ts_ms":1768250246363,"raw":{"market":"0xe51aa24ab1bbfefce466d642ad98587d13123e4ef95ec9aa73b712e775d4cbba","price_changes":[{"asset_id":"54232589582260339592359130012520874109228367674780084862642636038394766871668","price":"0.02","size":"4387.25","side":"BUY","hash":"2c94b9ebe28b4b128850b435d068223c2284a811","best_bid":"0.05","best_ask":"0.06"},{"asset_id":"96886111393998001968863279421729456597655847484197549086072988901191634450924","price":"0.98","size":"4387.25","side":"SELL","hash":"d1cefaf2e30fdff35e518aecc234b7c7db7f2469","best_bid":"0.94","best_ask":"0.95"}],"timestamp":"1768250246363","event_type":"price_change"}}
{"schema_version":1,"source":"clob_ws_market","recv_ts_ns":1768250246620742909,"event_type":"price_change","market":"0xe51aa24ab1bbfefce466d642ad98587d13123e4ef95ec9aa73b712e775d4cbba","server_ts_ms":1768250246369,"raw":{"market":"0xe51aa24ab1bbfefce466d642ad98587d13123e4ef95ec9aa73b712e775d4cbba","price_changes":[{"asset_id":"54232589582260339592359130012520874109228367674780084862642636038394766871668","price":"0.04","size":"1637.5","side":"BUY","hash":"11f26ff0b2b1ff224b6c4a6b04fb1bc7c855767a","best_bid":"0.05","best_ask":"0.06"},{"asset_id":"96886111393998001968863279421729456597655847484197549086072988901191634450924","price":"0.96","size":"1637.5","side":"SELL","hash":"644ef0ce1b8f1db16113fd0dc4eb8222a3f321e8","best_bid":"0.94","best_ask":"0.95"}],"timestamp":"1768250246369","event_type":"price_change"}}
{"schema_version":1,"source":"clob_ws_market","recv_ts_ns":1768250246623333146,"event_type":"price_change","market":"0xe51aa24ab1bbfefce466d642ad98587d13123e4ef95ec9aa73b712e775d4cbba","server_ts_ms":1768250246370,"raw":{"market":"0xe51aa24ab1bbfefce466d642ad98587d13123e4ef95ec9aa73b712e775d4cbba","price_changes":[{"asset_id":"96886111393998001968863279421729456597655847484197549086072988901191634450924","price":"0.94","size":"2043.21","side":"BUY","hash":"1671e12c2167f353ede2299c6cb8216d247158a0","best_bid":"0.94","best_ask":"0.95"},{"asset_id":"54232589582260339592359130012520874109228367674780084862642636038394766871668","price":"0.06","size":"2043.21","side":"SELL","hash":"1dbca6fdb3edfee7650e66dfb64229e07c5398e2","best_bid":"0.05","best_ask":"0.06"}],"timestamp":"1768250246370","event_type":"price_change"}}
{"schema_version":1,"source":"clob_ws_market","recv_ts_ns":1768250246627307928,"event_type":"price_change","market":"0xe51aa24ab1bbfefce466d642ad98587d13123e4ef95ec9aa73b712e775d4cbba","server_ts_ms":1768250246371,"raw":{"market":"0xe51aa24ab1bbfefce466d642ad98587d13123e4ef95ec9aa73b712e775d4cbba","price_changes":[{"asset_id":"54232589582260339592359130012520874109228367674780084862642636038394766871668","price":"0.02","size":"4359.25","side":"BUY","hash":"77ed531e8a4f2a4c1d31c4f96ad6d0190ab02978","best_bid":"0.05","best_ask":"0.06"},{"asset_id":"96886111393998001968863279421729456597655847484197549086072988901191634450924","price":"0.98","size":"4359.25","side":"SELL","hash":"3538e3bfe528c93c7908a74818ac1a691c09fbfb","best_bid":"0.94","best_ask":"0.95"}],"timestamp":"1768250246371","event_type":"price_change"}}
{"schema_version":1,"source":"clob_ws_market","recv_ts_ns":1768250246630932875,"event_type":"price_change","market":"0xe51aa24ab1bbfefce466d642ad98587d13123e4ef95ec9aa73b712e775d4cbba","server_ts_ms":1768250246384,"raw":{"market":"0xe51aa24ab1bbfefce466d642ad98587d13123e4ef95ec9aa73b712e775d4cbba","price_changes":[{"asset_id":"96886111393998001968863279421729456597655847484197549086072988901191634450924","price":"0.94","size":"2073.21","side":"BUY","hash":"65fe7eb08db4acfe27dd400f49cc1dd9df25e5af","best_bid":"0.94","best_ask":"0.95"},{"asset_id":"54232589582260339592359130012520874109228367674780084862642636038394766871668","price":"0.06","size":"2073.21","side":"SELL","hash":"282c3f9cdadf1058e8df60734f73010848e9b6a1","best_bid":"0.05","best_ask":"0.06"}],"timestamp":"1768250246384","event_type":"price_change"}}
{"schema_version":1,"source":"clob_ws_market","recv_ts_ns":1768250246636147092,"event_type":"price_change","market":"0xe51aa24ab1bbfefce466d642ad98587d13123e4ef95ec9aa73b712e775d4cbba","server_ts_ms":1768250246389,"raw":{"market":"0xe51aa24ab1bbfefce466d642ad98587d13123e4ef95ec9aa73b712e775d4cbba","price_changes":[{"asset_id":"54232589582260339592359130012520874109228367674780084862642636038394766871668","price":"0.02","size":"4375.25","side":"BUY","hash":"6602a4ef4628034700e81e12f1c7ec5df9d0ce5a","best_bid":"0.05","best_ask":"0.06"},{"asset_id":"96886111393998001968863279421729456597655847484197549086072988901191634450924","price":"0.98","size":"4375.25","side":"SELL","hash":"d66c80bbc965d5ec3a8833efce3d50218037645c","best_bid":"0.94","best_ask":"0.95"}],"timestamp":"1768250246389","event_type":"price_change"}}
{"schema_version":1,"source":"clob_ws_market","recv_ts_ns":1768250246639268382,"event_type":"best_bid_ask","market":"0xe51aa24ab1bbfefce466d642ad98587d13123e4ef95ec9aa73b712e775d4cbba","server_ts_ms":1768250246402,"raw":{"market":"0xe51aa24ab1bbfefce466d642ad98587d13123e4ef95ec9aa73b712e775d4cbba","asset_id":"96886111393998001968863279421729456597655847484197549086072988901191634450924","best_bid":"0.94","best_ask":"0.95","spread":"0.01","timestamp":"1768250246402","event_type":"best_bid_ask"}}
{"schema_version":1,"source":"clob_ws_market","recv_ts_ns":1768250246640360993,"event_type":"price_change","market":"0xe51aa24ab1bbfefce466d642ad98587d13123e4ef95ec9aa73b712e775d4cbba","server_ts_ms":1768250246400,"raw":{"market":"0xe51aa24ab1bbfefce466d642ad98587d13123e4ef95ec9aa73b712e775d4cbba","price_changes":[{"asset_id":"96886111393998001968863279421729456597655847484197549086072988901191634450924","price":"0.95","size":"70.41","side":"SELL","hash":"3e21b68488a505966d2c7c46c24f1c4ffc70c845","best_bid":"0.94","best_ask":"0.95"},{"asset_id":"54232589582260339592359130012520874109228367674780084862642636038394766871668","price":"0.05","size":"70.41","side":"BUY","hash":"a84d9df4427a582a10d327315e9076293b5152e6","best_bid":"0.05","best_ask":"0.06"}],"timestamp":"1768250246400","event_type":"price_change"}}
{"schema_version":1,"source":"clob_ws_market","recv_ts_ns":1768250246642336973,"event_type":"price_change","market":"0xe51aa24ab1bbfefce466d642ad98587d13123e4ef95ec9aa73b712e775d4cbba","server_ts_ms":1768250246400,"raw":{"market":"0xe51aa24ab1bbfefce466d642ad98587d13123e4ef95ec9aa73b712e775d4cbba","price_changes":[{"asset_id":"54232589582260339592359130012520874109228367674780084862642636038394766871668","price":"0.05","size":"70.41","side":"BUY","hash":"a84d9df4427a582a10d327315e9076293b5152e6","best_bid":"0.05","best_ask":"0.06"},{"asset_id":"96886111393998001968863279421729456597655847484197549086072988901191634450924","price":"0.95","size":"70.41","side":"SELL","hash":"3e21b68488a505966d2c7c46c24f1c4ffc70c845","best_bid":"0.94","best_ask":"0.95"}],"timestamp":"1768250246400","event_type":"price_change"}}
{"schema_version":1,"source":"clob_ws_market","recv_ts_ns":1768250246648007584,"event_type":"book","market":"0xe51aa24ab1bbfefce466d642ad98587d13123e4ef95ec9aa73b712e775d4cbba","server_ts_ms":1768250246400,"raw":{"market":"0xe51aa24ab1bbfefce466d642ad98587d13123e4ef95ec9aa73b712e775d4cbba","asset_id":"96886111393998001968863279421729456597655847484197549086072988901191634450924","bids":[{"price":"0.01","size":"24295.73"},{"price":"0.02","size":"7594.51"},{"price":"0.03","size":"5964.69"},{"price":"0.04","size":"5411.4"},{"price":"0.05","size":"5356.39"},{"price":"0.06","size":"5328"},{"price":"0.07","size":"5039.28"},{"price":"0.08","size":"5022.7"},{"price":"0.09","size":"5320.9"},{"price":"0.1","size":"5158.44"},{"price":"0.11","size":"18.3"},{"price":"0.12","size":"30.3"},{"price":"0.13","size":"16.5"},{"price":"0.14","size":"15.8"},{"price":"0.15","size":"104.19"},{"price":"0.16","size":"24.69"},{"price":"0.17","size":"14.19"},{"price":"0.18","size":"13.8"},{"price":"0.19","size":"13.4"},{"price":"0.2","size":"38.1"},{"price":"0.21","size":"12.8"},{"price":"0.22","size":"12.6"},{"price":"0.23","size":"12.3"},{"price":"0.24","size":"22.1"},{"price":"0.25","size":"16.9"},{"price":"0.26","size":"21.8"},{"price":"0.27","size":"11.6"},{"price":"0.28","size":"11.4"},{"price":"0.29","size":"61.3"},{"price":"0.3","size":"26.2"},{"price":"0.31","size":"11.1"},{"price":"0.32","size":"11"},{"price":"0.33","size":"110.9"},{"price":"0.34","size":"10.8"},{"price":"0.35","size":"15.7"},{"price":"0.36","size":"10.6"},{"price":"0.37","size":"10.6"},{"price":"0.38","size":"22.5"},{"price":"0.39","size":"10.5"},{"price":"0.4","size":"45.4"},{"price":"0.41","size":"311.4"},{"price":"0.42","size":"820.82"},{"price":"0.43","size":"826.3"},{"price":"0.44","size":"1062.3"},{"price":"0.45","size":"582.3"},{"price":"0.46","size":"626.2"},{"price":"0.47","size":"562.2"},{"price":"0.48","size":"567.2"},{"price":"0.49","size":"573.2"},{"price":"0.5","size":"917.2"},{"price":"0.51","size":"591.2"},{"price":"0.52","size":"590.2"},{"price":"0.53","size":"567.2"},{"price":"0.54","size":"642.61"},{"price":"0.55","size":"362.97"},{"price":"0.56","size":"341.3"},{"price":"0.57","size":"320.62"},{"price":"0.58","size":"567.3"},{"price":"0.59","size":"562.4"},{"price":"0.6","size":"693.02"},{"price":"0.61","size":"625.5"},{"price":"0.62","size":"700.5"},{"price":"0.63","size":"672.32"},{"price":"0.64","size":"680.6"},{"price":"0.65","size":"536.14"},{"price":"0.66","size":"602.8"},{"price":"0.67","size":"572.9"},{"price":"0.68","size":"573"},{"price":"0.69","size":"595.1"},{"price":"0.7","size":"603.2"},{"price":"0.71","size":"1318.72"},{"price":"0.72","size":"1043.04"},{"price":"0.73","size":"663.6"},{"price":"0.74","size":"911.17"},{"price":"0.75","size":"694.3"},{"price":"0.76","size":"717.6"},{"price":"0.77","size":"1183.3"},{"price":"0.78","size":"1526.53"},{"price":"0.79","size":"1178.8"},{"price":"0.8","size":"1445.08"},{"price":"0.81","size":"1229.8"},{"price":"0.82","size":"1467.57"},{"price":"0.83","size":"1470.51"},{"price":"0.84","size":"1718.59"},{"price":"0.85","size":"1762.5"},{"price":"0.86","size":"1755.6"},{"price":"0.87","size":"1588.93"},{"price":"0.88","size":"2355.4"},{"price":"0.89","size":"2098.8"},{"price":"0.9","size":"3433.34"},{"price":"0.91","size":"3012.44"},{"price":"0.92","size":"2549.36"},{"price":"0.93","size":"1391.82"},{"price":"0.94","size":"2073.21"}],"asks":[{"price":"0.99","size":"21028.9"},{"price":"0.98","size":"4375.25"},{"price":"0.97","size":"1262.6"},{"price":"0.96","size":"1637.5"},{"price":"0.95","size":"70.41"}],"hash":"3e21b68488a505966d2c7c46c24f1c4ffc70c845","timestamp":"1768250246400","event_type":"book"}}
{"schema_version":1,"source":"clob_ws_market","recv_ts_ns":1768250246649565261,"event_type":"price_change","market":"0xe51aa24ab1bbfefce466d642ad98587d13123e4ef95ec9aa73b712e775d4cbba","server_ts_ms":1768250246413,"raw":{"market":"0xe51aa24ab1bbfefce466d642ad98587d13123e4ef95ec9aa73b712e775d4cbba","price_changes":[{"asset_id":"54232589582260339592359130012520874109228367674780084862642636038394766871668","price":"0.01","size":"21059.9","side":"BUY","hash":"27e0f0e796c28742a025815a7cdd2b2f0c3507ff","best_bid":"0.05","best_ask":"0.06"},{"asset_id":"96886111393998001968863279421729456597655847484197549086072988901191634450924","price":"0.99","size":"21059.9","side":"SELL","hash":"c11ba59b81a4614f510906e3fc4b80800ca3edc3","best_bid":"0.94","best_ask":"0.95"}],"timestamp":"1768250246413","event_type":"price_change"}}
{"schema_version":1,"source":"clob_ws_market","recv_ts_ns":1768250246656895133,"event_type":"price_change","market":"0xe51aa24ab1bbfefce466d642ad98587d13123e4ef95ec9aa73b712e775d4cbba","server_ts_ms":1768250246437,"raw":{"market":"0xe51aa24ab1bbfefce466d642ad98587d13123e4ef95ec9aa73b712e775d4cbba","price_changes":[{"asset_id":"54232589582260339592359130012520874109228367674780084862642636038394766871668","price":"0.02","size":"5375.25","side":"BUY","hash":"5c248dd2289a4c7b3ff6b2fd7cf8daeda58dc543","best_bid":"0.05","best_ask":"0.06"},{"asset_id":"96886111393998001968863279421729456597655847484197549086072988901191634450924","price":"0.98","size":"5375.25","side":"SELL","hash":"eea185de9caea95e1ffe98fa0a77aa4c7bae4fcb","best_bid":"0.94","best_ask":"0.95"}],"timestamp":"1768250246437","event_type":"price_change"}}
{"schema_version":1,"source":"clob_ws_market","recv_ts_ns":1768250246674023664,"event_type":"price_change","market":"0xe51aa24ab1bbfefce466d642ad98587d13123e4ef95ec9aa73b712e775d4cbba","server_ts_ms":1768250246458,"raw":{"market":"0xe51aa24ab1bbfefce466d642ad98587d13123e4ef95ec9aa73b712e775d4cbba","price_changes":[{"asset_id":"96886111393998001968863279421729456597655847484197549086072988901191634450924","price":"0.91","size":"3018.44","side":"BUY","hash":"e296f56d1a201f730ba0c05d01717a818870477f","best_bid":"0.94","best_ask":"0.95"},{"asset_id":"54232589582260339592359130012520874109228367674780084862642636038394766871668","price":"0.09","size":"3018.44","side":"SELL","hash":"fbd84e883f5a3af7cdccfacd723b977cecebfe6a","best_bid":"0.05","best_ask":"0.06"}],"timestamp":"1768250246458","event_type":"price_change"}}
{"schema_version":1,"source":"clob_ws_market","recv_ts_ns":1768250246677453675,"event_type":"price_change","market":"0xe51aa24ab1bbfefce466d642ad98587d13123e4ef95ec9aa73b712e775d4cbba","server_ts_ms":1768250246537,"raw":{"market":"0xe51aa24ab1bbfefce466d642ad98587d13123e4ef95ec9aa73b712e775d4cbba","price_changes":[{"asset_id":"96886111393998001968863279421729456597655847484197549086072988901191634450924","price":"0.94","size":"2065.21","side":"BUY","hash":"fe9c1a0ae7b450c399fe38448a2486127bcdbba6","best_bid":"0.94","best_ask":"0.95"},{"asset_id":"54232589582260339592359130012520874109228367674780084862642636038394766871668","price":"0.06","size":"2065.21","side":"SELL","hash":"6a0f4cf47b5200c55c8e435adefb4f0c85a9dd16","best_bid":"0.05","best_ask":"0.06"}],"timestamp":"1768250246537","event_type":"price_change"}}
{"schema_version":1,"source":"clob_ws_market","recv_ts_ns":1768250246679661398,"event_type":"price_change","market":"0xe51aa24ab1bbfefce466d642ad98587d13123e4ef95ec9aa73b712e775d4cbba","server_ts_ms":1768250246560,"raw":{"market":"0xe51aa24ab1bbfefce466d642ad98587d13123e4ef95ec9aa73b712e775d4cbba","price_changes":[{"asset_id":"96886111393998001968863279421729456597655847484197549086072988901191634450924","price":"0.93","size":"1571.82","side":"BUY","hash":"1e6d93f365f88e4abfd37653d919c5d8d3d62290","best_bid":"0.94","best_ask":"0.95"},{"asset_id":"54232589582260339592359130012520874109228367674780084862642636038394766871668","price":"0.07","size":"1571.82","side":"SELL","hash":"c2ea5b3826ae9b9f2b5562da7ae856c0598542e2","best_bid":"0.05","best_ask":"0.06"}],"timestamp":"1768250246560","event_type":"price_change"}}
{"schema_version":1,"source":"clob_ws_market","recv_ts_ns":1768250246682691509,"event_type":"best_bid_ask","market":"0xe51aa24ab1bbfefce466d642ad98587d13123e4ef95ec9aa73b712e775d4cbba","server_ts_ms":1768250246564,"raw":{"market":"0xe51aa24ab1bbfefce466d642ad98587d13123e4ef95ec9aa73b712e775d4cbba","asset_id":"96886111393998001968863279421729456597655847484197549086072988901191634450924","best_bid":"0.94","best_ask":"0.95","spread":"0.01","timestamp":"1768250246564","event_type":"best_bid_ask"}}
{"schema_version":1,"source":"clob_ws_market","recv_ts_ns":1768250246683823969,"event_type":"price_change","market":"0xe51aa24ab1bbfefce466d642ad98587d13123e4ef95ec9aa73b712e775d4cbba","server_ts_ms":1768250246563,"raw":{"market":"0xe51aa24ab1bbfefce466d642ad98587d13123e4ef95ec9aa73b712e775d4cbba","price_changes":[{"asset_id":"96886111393998001968863279421729456597655847484197549086072988901191634450924","price":"0.95","size":"58.41","side":"SELL","hash":"19ade3077bec097a318ae5c586691b1dd118fbe4","best_bid":"0.94","best_ask":"0.95"},{"asset_id":"54232589582260339592359130012520874109228367674780084862642636038394766871668","price":"0.05","size":"58.41","side":"BUY","hash":"88d8efbc7a911ebffd9db241e9669379a7a09655","best_bid":"0.05","best_ask":"0.06"}],"timestamp":"1768250246563","event_type":"price_change"}}
{"schema_version":1,"source":"clob_ws_market","recv_ts_ns":1768250246691163750,"event_type":"book","market":"0xe51aa24ab1bbfefce466d642ad98587d13123e4ef95ec9aa73b712e775d4cbba","server_ts_ms":1768250246563,"raw":{"market":"0xe51aa24ab1bbfefce466d642ad98587d13123e4ef95ec9aa73b712e775d4cbba","asset_id":"96886111393998001968863279421729456597655847484197549086072988901191634450924","bids":[{"price":"0.01","size":"24295.73"},{"price":"0.02","size":"7594.51"},{"price":"0.03","size":"5964.69"},{"price":"0.04","size":"5411.4"},{"price":"0.05","size":"5356.39"},{"price":"0.06","size":"5328"},{"price":"0.07","size":"5039.28"},{"price":"0.08","size":"5022.7"},{"price":"0.09","size":"5320.9"},{"price":"0.1","size":"5158.44"},{"price":"0.11","size":"18.3"},{"price":"0.12","size":"30.3"},{"price":"0.13","size":"16.5"},{"price":"0.14","size":"15.8"},{"price":"0.15","size":"104.19"},{"price":"0.16","size":"24.69"},{"price":"0.17","size":"14.19"},{"price":"0.18","size":"13.8"},{"price":"0.19","size":"13.4"},{"price":"0.2","size":"38.1"},{"price":"0.21","size":"12.8"},{"price":"0.22","size":"12.6"},{"price":"0.23","size":"12.3"},{"price":"0.24","size":"22.1"},{"price":"0.25","size":"16.9"},{"price":"0.26","size":"21.8"},{"price":"0.27","size":"11.6"},{"price":"0.28","size":"11.4"},{"price":"0.29","size":"61.3"},{"price":"0.3","size":"26.2"},{"price":"0.31","size":"11.1"},{"price":"0.32","size":"11"},{"price":"0.33","size":"110.9"},{"price":"0.34","size":"10.8"},{"price":"0.35","size":"15.7"},{"price":"0.36","size":"10.6"},{"price":"0.37","size":"10.6"},{"price":"0.38","size":"22.5"},{"price":"0.39","size":"10.5"},{"price":"0.4","size":"45.4"},{"price":"0.41","size":"311.4"},{"price":"0.42","size":"820.82"},{"price":"0.43","size":"826.3"},{"price":"0.44","size":"1062.3"},{"price":"0.45","size":"582.3"},{"price":"0.46","size":"626.2"},{"price":"0.47","size":"562.2"},{"price":"0.48","size":"567.2"},{"price":"0.49","size":"573.2"},{"price":"0.5","size":"917.2"},{"price":"0.51","size":"591.2"},{"price":"0.52","size":"590.2"},{"price":"0.53","size":"567.2"},{"price":"0.54","size":"642.61"},{"price":"0.55","size":"362.97"},{"price":"0.56","size":"341.3"},{"price":"0.57","size":"320.62"},{"price":"0.58","size":"567.3"},{"price":"0.59","size":"562.4"},{"price":"0.6","size":"693.02"},{"price":"0.61","size":"625.5"},{"price":"0.62","size":"700.5"},{"price":"0.63","size":"672.32"},{"price":"0.64","size":"680.6"},{"price":"0.65","size":"536.14"},{"price":"0.66","size":"602.8"},{"price":"0.67","size":"572.9"},{"price":"0.68","size":"573"},{"price":"0.69","size":"595.1"},{"price":"0.7","size":"603.2"},{"price":"0.71","size":"1318.72"},{"price":"0.72","size":"1043.04"},{"price":"0.73","size":"663.6"},{"price":"0.74","size":"911.17"},{"price":"0.75","size":"694.3"},{"price":"0.76","size":"717.6"},{"price":"0.77","size":"1183.3"},{"price":"0.78","size":"1526.53"},{"price":"0.79","size":"1178.8"},{"price":"0.8","size":"1445.08"},{"price":"0.81","size":"1229.8"},{"price":"0.82","size":"1467.57"},{"price":"0.83","size":"1470.51"},{"price":"0.84","size":"1718.59"},{"price":"0.85","size":"1762.5"},{"price":"0.86","size":"1755.6"},{"price":"0.87","size":"1588.93"},{"price":"0.88","size":"2355.4"},{"price":"0.89","size":"2098.8"},{"price":"0.9","size":"3433.34"},{"price":"0.91","size":"3018.44"},{"price":"0.92","size":"2549.36"},{"price":"0.93","size":"1571.82"},{"price":"0.94","size":"2065.21"}],"asks":[{"price":"0.99","size":"21059.9"},{"price":"0.98","size":"5375.25"},{"price":"0.97","size":"1262.6"},{"price":"0.96","size":"1637.5"},{"price":"0.95","size":"58.41"}],"hash":"19ade3077bec097a318ae5c586691b1dd118fbe4","timestamp":"1768250246563","event_type":"book"}}
{"schema_version":1,"source":"clob_ws_market","recv_ts_ns":1768250246693807388,"event_type":"price_change","market":"0xe51aa24ab1bbfefce466d642ad98587d13123e4ef95ec9aa73b712e775d4cbba","server_ts_ms":1768250246567,"raw":{"market":"0xe51aa24ab1bbfefce466d642ad98587d13123e4ef95ec9aa73b712e775d4cbba","price_changes":[{"asset_id":"96886111393998001968863279421729456597655847484197549086072988901191634450924","price":"0.94","size":"1955.21","side":"BUY","hash":"a52d7aa8a1a56c0aba18d89a0593c85019bdaf1d","best_bid":"0.94","best_ask":"0.95"},{"asset_id":"54232589582260339592359130012520874109228367674780084862642636038394766871668","price":"0.06","size":"1955.21","side":"SELL","hash":"5bce198621d3268ef18f62aa3168e0c8ad9b6da7","best_bid":"0.05","best_ask":"0.06"}],"timestamp":"1768250246567","event_type":"price_change"}}
{"schema_version":1,"source":"clob_ws_market","recv_ts_ns":1768250246696991482,"event_type":"price_change","market":"0xe51aa24ab1bbfefce466d642ad98587d13123e4ef95ec9aa73b712e775d4cbba","server_ts_ms":1768250246586,"raw":{"market":"0xe51aa24ab1bbfefce466d642ad98587d13123e4ef95ec9aa73b712e775d4cbba","price_changes":[{"asset_id":"96886111393998001968863279421729456597655847484197549086072988901191634450924","price":"0.94","size":"1925.21","side":"BUY","hash":"20e62d980d66996fcecc29d699dfcd68222e0a33","best_bid":"0.94","best_ask":"0.95"},{"asset_id":"54232589582260339592359130012520874109228367674780084862642636038394766871668","price":"0.06","size":"1925.21","side":"SELL","hash":"fe613f4c312e0727ccf345a0b89edc6a5d72a896","best_bid":"0.05","best_ask":"0.06"}],"timestamp":"1768250246586","event_type":"price_change"}}
{"schema_version":1,"source":"clob_ws_market","recv_ts_ns":1768250246700171833,"event_type":"last_trade_price","market":"0xe51aa24ab1bbfefce466d642ad98587d13123e4ef95ec9aa73b712e775d4cbba","server_ts_ms":1768250246591,"raw":{"market":"0xe51aa24ab1bbfefce466d642ad98587d13123e4ef95ec9aa73b712e775d4cbba","asset_id":"96886111393998001968863279421729456597655847484197549086072988901191634450924","price":"0.95","size":"12","fee_rate_bps":"1000","side":"BUY","timestamp":"1768250246591","event_type":"last_trade_price","transaction_hash":"0xb1b602182e600f7a1286ea7f0b69022582e77d836e3eab8e543a8e6062ec2c8e"}}
{"schema_version":1,"source":"clob_ws_market","recv_ts_ns":1768250246702086484,"event_type":"price_change","market":"0xe51aa24ab1bbfefce466d642ad98587d13123e4ef95ec9aa73b712e775d4cbba","server_ts_ms":1768250246597,"raw":{"market":"0xe51aa24ab1bbfefce466d642ad98587d13123e4ef95ec9aa73b712e775d4cbba","price_changes":[{"asset_id":"96886111393998001968863279421729456597655847484197549086072988901191634450924","price":"0.78","size":"1449.6","side":"BUY","hash":"1cc95901e9682621ccc53dce59f78315c211383b","best_bid":"0.94","best_ask":"0.95"},{"asset_id":"54232589582260339592359130012520874109228367674780084862642636038394766871668","price":"0.22","size":"1449.6","side":"SELL","hash":"ba4dd1ea7b32c33bfaa60a771edb62c4bef187d5","best_bid":"0.05","best_ask":"0.06"}],"timestamp":"1768250246597","event_type":"price_change"}}
{"schema_version":1,"source":"clob_ws_market","recv_ts_ns":1768250246706002244,"event_type":"price_change","market":"0xe51aa24ab1bbfefce466d642ad98587d13123e4ef95ec9aa73b712e775d4cbba","server_ts_ms":1768250246598,"raw":{"market":"0xe51aa24ab1bbfefce466d642ad98587d13123e4ef95ec9aa73b712e775d4cbba","price_changes":[{"asset_id":"96886111393998001968863279421729456597655847484197549086072988901191634450924","price":"0.79","size":"1254.75","side":"BUY","hash":"98c084a756712acdbfd6a0162921d42ef39257dd","best_bid":"0.94","best_ask":"0.95"},{"asset_id":"54232589582260339592359130012520874109228367674780084862642636038394766871668","price":"0.21","size":"1254.75","side":"SELL","hash":"a70a511d76bd391eba182aaab8b6c2f5bff2132f","best_bid":"0.05","best_ask":"0.06"}],"timestamp":"1768250246598","event_type":"price_change"}}
{"schema_version":1,"source":"clob_ws_market","recv_ts_ns":1768250246709134613,"event_type":"price_change","market":"0xe51aa24ab1bbfefce466d642ad98587d13123e4ef95ec9aa73b712e775d4cbba","server_ts_ms":1768250246611,"raw":{"market":"0xe51aa24ab1bbfefce466d642ad98587d13123e4ef95ec9aa73b712e775d4cbba","price_changes":[{"asset_id":"96886111393998001968863279421729456597655847484197549086072988901191634450924","price":"0.84","size":"1668.59","side":"BUY","hash":"a065fed878d530578b02539e731951fd85280056","best_bid":"0.94","best_ask":"0.95"},{"asset_id":"54232589582260339592359130012520874109228367674780084862642636038394766871668","price":"0.16","size":"1668.59","side":"SELL","hash":"c69b0a4e367d39b327358c2a7ca79c915f449051","best_bid":"0.05","best_ask":"0.06"}],"timestamp":"1768250246611","event_type":"price_change"}}
{"schema_version":1,"source":"clob_ws_market","recv_ts_ns":1768250246712866448,"event_type":"price_change","market":"0xe51aa24ab1bbfefce466d642ad98587d13123e4ef95ec9aa73b712e775d4cbba","server_ts_ms":1768250246613,"raw":{"market":"0xe51aa24ab1bbfefce466d642ad98587d13123e4ef95ec9aa73b712e775d4cbba","price_changes":[{"asset_id":"96886111393998001968863279421729456597655847484197549086072988901191634450924","price":"0.9","size":"3467.84","side":"BUY","hash":"ec54f075b83fdbb508bbbab71b8ee7f2baa72bdc","best_bid":"0.94","best_ask":"0.95"},{"asset_id":"54232589582260339592359130012520874109228367674780084862642636038394766871668","price":"0.1","size":"3467.84","side":"SELL","hash":"1c96e835243f3f53750656104b01e44c591d3f11","best_bid":"0.05","best_ask":"0.06"}],"timestamp":"1768250246613","event_type":"price_change"}}
{"schema_version":1,"source":"clob_ws_market","recv_ts_ns":1768250246715496455,"event_type":"price_change","market":"0xe51aa24ab1bbfefce466d642ad98587d13123e4ef95ec9aa73b712e775d4cbba","server_ts_ms":1768250246615,"raw":{"market":"0xe51aa24ab1bbfefce466d642ad98587d13123e4ef95ec9aa73b712e775d4cbba","price_changes":[{"asset_id":"96886111393998001968863279421729456597655847484197549086072988901191634450924","price":"0.89","size":"2066.7","side":"BUY","hash":"a5795fb08c73886639ba03d42fae89f8ca4d7522","best_bid":"0.94","best_ask":"0.95"},{"asset_id":"54232589582260339592359130012520874109228367674780084862642636038394766871668","price":"0.11","size":"2066.7","side":"SELL","hash":"50f9959d7f4a6c05ea38c2bb49456c22b528315b","best_bid":"0.05","best_ask":"0.06"}],"timestamp":"1768250246615","event_type":"price_change"}}
{"schema_version":1,"source":"clob_ws_market","recv_ts_ns":1768250246717879453,"event_type":"price_change","market":"0xe51aa24ab1bbfefce466d642ad98587d13123e4ef95ec9aa73b712e775d4cbba","server_ts_ms":1768250246616,"raw":{"market":"0xe51aa24ab1bbfefce466d642ad98587d13123e4ef95ec9aa73b712e775d4cbba","price_changes":[{"asset_id":"54232589582260339592359130012520874109228367674780084862642636038394766871668","price":"0.06","size":"1905.21","side":"SELL","hash":"d3d0ad3df1d80362e51c0df58b6891c06b0a3953","best_bid":"0.05","best_ask":"0.06"},{"asset_id":"96886111393998001968863279421729456597655847484197549086072988901191634450924","price":"0.94","size":"1905.21","side":"BUY","hash":"d974f7093dcabf1498a94e166b5ad48149b989ac","best_bid":"0.94","best_ask":"0.95"}],"timestamp":"1768250246616","event_type":"price_change"}}
{"schema_version":1,"source":"clob_ws_market","recv_ts_ns":1768250246720578430,"event_type":"price_change","market":"0xe51aa24ab1bbfefce466d642ad98587d13123e4ef95ec9aa73b712e775d4cbba","server_ts_ms":1768250246618,"raw":{"market":"0xe51aa24ab1bbfefce466d642ad98587d13123e4ef95ec9aa73b712e775d4cbba","price_changes":[{"asset_id":"96886111393998001968863279421729456597655847484197549086072988901191634450924","price":"0.96","size":"1632","side":"SELL","hash":"03c636022d7f0262a268aa04ac319b9a50eae33c","best_bid":"0.94","best_ask":"0.95"},{"asset_id":"54232589582260339592359130012520874109228367674780084862642636038394766871668","price":"0.04","size":"1632","side":"BUY","hash":"1ff7ac8c73d16b41bb02bfff801941997bb9aaec","best_bid":"0.05","best_ask":"0.06"}],"timestamp":"1768250246618","event_type":"price_change"}}
{"schema_version":1,"source":"clob_ws_market","recv_ts_ns":1768250246726073827,"event_type":"price_change","market":"0xe51aa24ab1bbfefce466d642ad98587d13123e4ef95ec9aa73b712e775d4cbba","server_ts_ms":1768250246636,"raw":{"market":"0xe51aa24ab1bbfefce466d642ad98587d13123e4ef95ec9aa73b712e775d4cbba","price_changes":[{"asset_id":"96886111393998001968863279421729456597655847484197549086072988901191634450924","price":"0.94","size":"1875.21","side":"BUY","hash":"5cb9b68b54c56b4b6daee7fff1b10c8cef86409c","best_bid":"0.94","best_ask":"0.95"},{"asset_id":"54232589582260339592359130012520874109228367674780084862642636038394766871668","price":"0.06","size":"1875.21","side":"SELL","hash":"a2913ba1fed81d2adf53ed995078e3b09478ff5b","best_bid":"0.05","best_ask":"0.06"}],"timestamp":"1768250246636","event_type":"price_change"}}
{"schema_version":1,"source":"clob_ws_market","recv_ts_ns":1768250246729713054,"event_type":"price_change","market":"0xe51aa24ab1bbfefce466d642ad98587d13123e4ef95ec9aa73b712e775d4cbba","server_ts_ms":1768250246646,"raw":{"market":"0xe51aa24ab1bbfefce466d642ad98587d13123e4ef95ec9aa73b712e775d4cbba","price_changes":[{"asset_id":"96886111393998001968863279421729456597655847484197549086072988901191634450924","price":"0.94","size":"1895.21","side":"BUY","hash":"0c90e5d5d20a6bf078271ce7925d6a227937c17f","best_bid":"0.94","best_ask":"0.95"},{"asset_id":"54232589582260339592359130012520874109228367674780084862642636038394766871668","price":"0.06","size":"1895.21","side":"SELL","hash":"b4ce52c89acd1e8b8666322f421ac75aa35c4faa","best_bid":"0.05","best_ask":"0.06"}],"timestamp":"1768250246646","event_type":"price_change"}}
{"schema_version":1,"source":"clob_ws_market","recv_ts_ns":1768250246737358888,"event_type":"price_change","market":"0xe51aa24ab1bbfefce466d642ad98587d13123e4ef95ec9aa73b712e775d4cbba","server_ts_ms":1768250246647,"raw":{"market":"0xe51aa24ab1bbfefce466d642ad98587d13123e4ef95ec9aa73b712e775d4cbba","price_changes":[{"asset_id":"96886111393998001968863279421729456597655847484197549086072988901191634450924","price":"0.94","size":"1865.21","side":"BUY","hash":"5719c3107355be171ac90cbf6dd409b7031f4166","best_bid":"0.94","best_ask":"0.95"},{"asset_id":"54232589582260339592359130012520874109228367674780084862642636038394766871668","price":"0.06","size":"1865.21","side":"SELL","hash":"80e7a088ecc6e179719cc0bf9be447014a7227ff","best_bid":"0.05","best_ask":"0.06"}],"timestamp":"1768250246647","event_type":"price_change"}}
{"schema_version":1,"source":"clob_ws_market","recv_ts_ns":1768250246741406779,"event_type":"price_change","market":"0xe51aa24ab1bbfefce466d642ad98587d13123e4ef95ec9aa73b712e775d4cbba","server_ts_ms":1768250246665,"raw":{"market":"0xe51aa24ab1bbfefce466d642ad98587d13123e4ef95ec9aa73b712e775d4cbba","price_changes":[{"asset_id":"96886111393998001968863279421729456597655847484197549086072988901191634450924","price":"0.97","size":"1268.1","side":"SELL","hash":"8a0a5ffe5d78fd36925f08254f2d940af82e2787","best_bid":"0.94","best_ask":"0.95"},{"asset_id":"54232589582260339592359130012520874109228367674780084862642636038394766871668","price":"0.03","size":"1268.1","side":"BUY","hash":"dc9f0224f5ef0ca1613a2214ae1b1d0f413354a2","best_bid":"0.05","best_ask":"0.06"}],"timestamp":"1768250246665","event_type":"price_change"}}
{"schema_version":1,"source":"clob_ws_market","recv_ts_ns":1768250246746364293,"event_type":"price_change","market":"0xe51aa24ab1bbfefce466d642ad98587d13123e4ef95ec9aa73b712e775d4cbba","server_ts_ms":1768250246675,"raw":{"market":"0xe51aa24ab1bbfefce466d642ad98587d13123e4ef95ec9aa73b712e775d4cbba","price_changes":[{"asset_id":"54232589582260339592359130012520874109228367674780084862642636038394766871668","price":"0.03","size":"1234.1","side":"BUY","hash":"caaa9a804da988e7a0d9d0c936c7719976702366","best_bid":"0.05","best_ask":"0.06"},{"asset_id":"96886111393998001968863279421729456597655847484197549086072988901191634450924","price":"0.97","size":"1234.1","side":"SELL","hash":"813a8af171910796b3bc2ab9776dfe305f46ad6c","best_bid":"0.94","best_ask":"0.95"}],"timestamp":"1768250246675","event_type":"price_change"}}
{"schema_version":1,"source":"clob_ws_market","recv_ts_ns":1768250246752645920,"event_type":"best_bid_ask","market":"0xe51aa24ab1bbfefce466d642ad98587d13123e4ef95ec9aa73b712e775d4cbba","server_ts_ms":1768250246724,"raw":{"market":"0xe51aa24ab1bbfefce466d642ad98587d13123e4ef95ec9aa73b712e775d4cbba","asset_id":"96886111393998001968863279421729456597655847484197549086072988901191634450924","best_bid":"0.94","best_ask":"0.95","spread":"0.01","timestamp":"1768250246724","event_type":"best_bid_ask"}}
{"schema_version":1,"source":"clob_ws_market","recv_ts_ns":1768250246754729926,"event_type":"price_change","market":"0xe51aa24ab1bbfefce466d642ad98587d13123e4ef95ec9aa73b712e775d4cbba","server_ts_ms":1768250246722,"raw":{"market":"0xe51aa24ab1bbfefce466d642ad98587d13123e4ef95ec9aa73b712e775d4cbba","price_changes":[{"asset_id":"96886111393998001968863279421729456597655847484197549086072988901191634450924","price":"0.94","size":"1856.21","side":"BUY","hash":"6805461d3ffcf91a004cf9c18cd14d0a45aea93f","best_bid":"0.94","best_ask":"0.95"},{"asset_id":"54232589582260339592359130012520874109228367674780084862642636038394766871668","price":"0.06","size":"1856.21","side":"SELL","hash":"6bfeffb34c0758916218aec36f70ef2b2b381fb4","best_bid":"0.05","best_ask":"0.06"}],"timestamp":"1768250246722","event_type":"price_change"}}
{"schema_version":1,"source":"clob_ws_market","recv_ts_ns":1768250246765091031,"event_type":"book","market":"0xe51aa24ab1bbfefce466d642ad98587d13123e4ef95ec9aa73b712e775d4cbba","server_ts_ms":1768250246722,"raw":{"market":"0xe51aa24ab1bbfefce466d642ad98587d13123e4ef95ec9aa73b712e775d4cbba","asset_id":"96886111393998001968863279421729456597655847484197549086072988901191634450924","bids":[{"price":"0.01","size":"24295.73"},{"price":"0.02","size":"7594.51"},{"price":"0.03","size":"5964.69"},{"price":"0.04","size":"5411.4"},{"price":"0.05","size":"5356.39"},{"price":"0.06","size":"5328"},{"price":"0.07","size":"5039.28"},{"price":"0.08","size":"5022.7"},{"price":"0.09","size":"5320.9"},{"price":"0.1","size":"5158.44"},{"price":"0.11","size":"18.3"},{"price":"0.12","size":"30.3"},{"price":"0.13","size":"16.5"},{"price":"0.14","size":"15.8"},{"price":"0.15","size":"104.19"},{"price":"0.16","size":"24.69"},{"price":"0.17","size":"14.19"},{"price":"0.18","size":"13.8"},{"price":"0.19","size":"13.4"},{"price":"0.2","size":"38.1"},{"price":"0.21","size":"12.8"},{"price":"0.22","size":"12.6"},{"price":"0.23","size":"12.3"},{"price":"0.24","size":"22.1"},{"price":"0.25","size":"16.9"},{"price":"0.26","size":"21.8"},{"price":"0.27","size":"11.6"},{"price":"0.28","size":"11.4"},{"price":"0.29","size":"61.3"},{"price":"0.3","size":"26.2"},{"price":"0.31","size":"11.1"},{"price":"0.32","size":"11"},{"price":"0.33","size":"110.9"},{"price":"0.34","size":"10.8"},{"price":"0.35","size":"15.7"},{"price":"0.36","size":"10.6"},{"price":"0.37","size":"10.6"},{"price":"0.38","size":"22.5"},{"price":"0.39","size":"10.5"},{"price":"0.4","size":"45.4"},{"price":"0.41","size":"311.4"},{"price":"0.42","size":"820.82"},{"price":"0.43","size":"826.3"},{"price":"0.44","size":"1062.3"},{"price":"0.45","size":"582.3"},{"price":"0.46","size":"626.2"},{"price":"0.47","size":"562.2"},{"price":"0.48","size":"567.2"},{"price":"0.49","size":"573.2"},{"price":"0.5","size":"917.2"},{"price":"0.51","size":"591.2"},{"price":"0.52","size":"590.2"},{"price":"0.53","size":"567.2"},{"price":"0.54","size":"642.61"},{"price":"0.55","size":"362.97"},{"price":"0.56","size":"341.3"},{"price":"0.57","size":"320.62"},{"price":"0.58","size":"567.3"},{"price":"0.59","size":"562.4"},{"price":"0.6","size":"693.02"},{"price":"0.61","size":"625.5"},{"price":"0.62","size":"700.5"},{"price":"0.63","size":"672.32"},{"price":"0.64","size":"680.6"},{"price":"0.65","size":"536.14"},{"price":"0.66","size":"602.8"},{"price":"0.67","size":"572.9"},{"price":"0.68","size":"573"},{"price":"0.69","size":"595.1"},{"price":"0.7","size":"603.2"},{"price":"0.71","size":"1318.72"},{"price":"0.72","size":"1043.04"},{"price":"0.73","size":"663.6"},{"price":"0.74","size":"911.17"},{"price":"0.75","size":"694.3"},{"price":"0.76","size":"717.6"},{"price":"0.77","size":"1183.3"},{"price":"0.78","size":"1449.6"},{"price":"0.79","size":"1254.75"},{"price":"0.8","size":"1445.08"},{"price":"0.81","size":"1229.8"},{"price":"0.82","size":"1467.57"},{"price":"0.83","size":"1470.51"},{"price":"0.84","size":"1668.59"},{"price":"0.85","size":"1762.5"},{"price":"0.86","size":"1755.6"},{"price":"0.87","size":"1588.93"},{"price":"0.88","size":"2355.4"},{"price":"0.89","size":"2066.7"},{"price":"0.9","size":"3467.84"},{"price":"0.91","size":"3018.44"},{"price":"0.92","size":"2549.36"},{"price":"0.93","size":"1571.82"},{"price":"0.94","size":"1856.21"}],"asks":[{"price":"0.99","size":"21059.9"},{"price":"0.98","size":"5375.25"},{"price":"0.97","size":"1234.1"},{"price":"0.96","size":"1632"},{"price":"0.95","size":"58.41"}],"hash":"6805461d3ffcf91a004cf9c18cd14d0a45aea93f","timestamp":"1768250246722","event_type":"book"}}
{"schema_version":1,"source":"clob_ws_market","recv_ts_ns":1768250246767814675,"event_type":"price_change","market":"0xe51aa24ab1bbfefce466d642ad98587d13123e4ef95ec9aa73b712e775d4cbba","server_ts_ms":1768250246724,"raw":{"market":"0xe51aa24ab1bbfefce466d642ad98587d13123e4ef95ec9aa73b712e775d4cbba","price_changes":[{"asset_id":"54232589582260339592359130012520874109228367674780084862642636038394766871668","price":"0.02","size":"5425.25","side":"BUY","hash":"3c9018134800ddfbfa372707c91d01437137c706","best_bid":"0.05","best_ask":"0.06"},{"asset_id":"96886111393998001968863279421729456597655847484197549086072988901191634450924","price":"0.98","size":"5425.25","side":"SELL","hash":"61e0d7aaf52bd00eb7791f0326cc50f452c0f91a","best_bid":"0.94","best_ask":"0.95"}],"timestamp":"1768250246724","event_type":"price_change"}}
{"schema_version":1,"source":"clob_ws_market","recv_ts_ns":1768250246887393478,"event_type":"best_bid_ask","market":"0xe51aa24ab1bbfefce466d642ad98587d13123e4ef95ec9aa73b712e775d4cbba","server_ts_ms":1768250246863,"raw":{"market":"0xe51aa24ab1bbfefce466d642ad98587d13123e4ef95ec9aa73b712e775d4cbba","asset_id":"96886111393998001968863279421729456597655847484197549086072988901191634450924","best_bid":"0.94","best_ask":"0.95","spread":"0.01","timestamp":"1768250246863","event_type":"best_bid_ask"}}
{"schema_version":1,"source":"clob_ws_market","recv_ts_ns":1768250246890144901,"event_type":"price_change","market":"0xe51aa24ab1bbfefce466d642ad98587d13123e4ef95ec9aa73b712e775d4cbba","server_ts_ms":1768250246861,"raw":{"market":"0xe51aa24ab1bbfefce466d642ad98587d13123e4ef95ec9aa73b712e775d4cbba","price_changes":[{"asset_id":"96886111393998001968863279421729456597655847484197549086072988901191634450924","price":"0.94","size":"1846.21","side":"BUY","hash":"ffa64f70f1e88efd3f9f4e03967c2f6413ea8298","best_bid":"0.94","best_ask":"0.95"},{"asset_id":"54232589582260339592359130012520874109228367674780084862642636038394766871668","price":"0.06","size":"1846.21","side":"SELL","hash":"a474e90c1ac587cf76c28ba77e6a864549f606de","best_bid":"0.05","best_ask":"0.06"}],"timestamp":"1768250246861","event_type":"price_change"}}
{"schema_version":1,"source":"clob_ws_market","recv_ts_ns":1768250246899646581,"event_type":"book","market":"0xe51aa24ab1bbfefce466d642ad98587d13123e4ef95ec9aa73b712e775d4cbba","server_ts_ms":1768250246861,"raw":{"market":"0xe51aa24ab1bbfefce466d642ad98587d13123e4ef95ec9aa73b712e775d4cbba","asset_id":"96886111393998001968863279421729456597655847484197549086072988901191634450924","bids":[{"price":"0.01","size":"24295.73"},{"price":"0.02","size":"7594.51"},{"price":"0.03","size":"5964.69"},{"price":"0.04","size":"5411.4"},{"price":"0.05","size":"5356.39"},{"price":"0.06","size":"5328"},{"price":"0.07","size":"5039.28"},{"price":"0.08","size":"5022.7"},{"price":"0.09","size":"5320.9"},{"price":"0.1","size":"5158.44"},{"price":"0.11","size":"18.3"},{"price":"0.12","size":"30.3"},{"price":"0.13","size":"16.5"},{"price":"0.14","size":"15.8"},{"price":"0.15","size":"104.19"},{"price":"0.16","size":"24.69"},{"price":"0.17","size":"14.19"},{"price":"0.18","size":"13.8"},{"price":"0.19","size":"13.4"},{"price":"0.2","size":"38.1"},{"price":"0.21","size":"12.8"},{"price":"0.22","size":"12.6"},{"price":"0.23","size":"12.3"},{"price":"0.24","size":"22.1"},{"price":"0.25","size":"16.9"},{"price":"0.26","size":"21.8"},{"price":"0.27","size":"11.6"},{"price":"0.28","size":"11.4"},{"price":"0.29","size":"61.3"},{"price":"0.3","size":"26.2"},{"price":"0.31","size":"11.1"},{"price":"0.32","size":"11"},{"price":"0.33","size":"110.9"},{"price":"0.34","size":"10.8"},{"price":"0.35","size":"15.7"},{"price":"0.36","size":"10.6"},{"price":"0.37","size":"10.6"},{"price":"0.38","size":"22.5"},{"price":"0.39","size":"10.5"},{"price":"0.4","size":"45.4"},{"price":"0.41","size":"311.4"},{"price":"0.42","size":"820.82"},{"price":"0.43","size":"826.3"},{"price":"0.44","size":"1062.3"},{"price":"0.45","size":"582.3"},{"price":"0.46","size":"626.2"},{"price":"0.47","size":"562.2"},{"price":"0.48","size":"567.2"},{"price":"0.49","size":"573.2"},{"price":"0.5","size":"917.2"},{"price":"0.51","size":"591.2"},{"price":"0.52","size":"590.2"},{"price":"0.53","size":"567.2"},{"price":"0.54","size":"642.61"},{"price":"0.55","size":"362.97"},{"price":"0.56","size":"341.3"},{"price":"0.57","size":"320.62"},{"price":"0.58","size":"567.3"},{"price":"0.59","size":"562.4"},{"price":"0.6","size":"693.02"},{"price":"0.61","size":"625.5"},{"price":"0.62","size":"700.5"},{"price":"0.63","size":"672.32"},{"price":"0.64","size":"680.6"},{"price":"0.65","size":"536.14"},{"price":"0.66","size":"602.8"},{"price":"0.67","size":"572.9"},{"price":"0.68","size":"573"},{"price":"0.69","size":"595.1"},{"price":"0.7","size":"603.2"},{"price":"0.71","size":"1318.72"},{"price":"0.72","size":"1043.04"},{"price":"0.73","size":"663.6"},{"price":"0.74","size":"911.17"},{"price":"0.75","size":"694.3"},{"price":"0.76","size":"717.6"},{"price":"0.77","size":"1183.3"},{"price":"0.78","size":"1449.6"},{"price":"0.79","size":"1254.75"},{"price":"0.8","size":"1445.08"},{"price":"0.81","size":"1229.8"},{"price":"0.82","size":"1467.57"},{"price":"0.83","size":"1470.51"},{"price":"0.84","size":"1668.59"},{"price":"0.85","size":"1762.5"},{"price":"0.86","size":"1755.6"},{"price":"0.87","size":"1588.93"},{"price":"0.88","size":"2355.4"},{"price":"0.89","size":"2066.7"},{"price":"0.9","size":"3467.84"},{"price":"0.91","size":"3018.44"},{"price":"0.92","size":"2549.36"},{"price":"0.93","size":"1571.82"},{"price":"0.94","size":"1846.21"}],"asks":[{"price":"0.99","size":"21059.9"},{"price":"0.98","size":"5425.25"},{"price":"0.97","size":"1234.1"},{"price":"0.96","size":"1632"},{"price":"0.95","size":"58.41"}],"hash":"ffa64f70f1e88efd3f9f4e03967c2f6413ea8298","timestamp":"1768250246861","event_type":"book"}}
{"schema_version":1,"source":"clob_ws_market","recv_ts_ns":1768250246903554699,"event_type":"price_change","market":"0xe51aa24ab1bbfefce466d642ad98587d13123e4ef95ec9aa73b712e775d4cbba","server_ts_ms":1768250246864,"raw":{"market":"0xe51aa24ab1bbfefce466d642ad98587d13123e4ef95ec9aa73b712e775d4cbba","price_changes":[{"asset_id":"54232589582260339592359130012520874109228367674780084862642636038394766871668","price":"0.05","size":"158.41","side":"BUY","hash":"7aa09844c8bc33bd074ac7cd23c2fd4d696e8308","best_bid":"0.05","best_ask":"0.06"},{"asset_id":"96886111393998001968863279421729456597655847484197549086072988901191634450924","price":"0.95","size":"158.41","side":"SELL","hash":"2f219e299e4788e86a4a63b8971aee1c6e4be0a1","best_bid":"0.94","best_ask":"0.95"}],"timestamp":"1768250246864","event_type":"price_change"}}
{"schema_version":1,"source":"clob_ws_market","recv_ts_ns":1768250246908818965,"event_type":"best_bid_ask","market":"0xe51aa24ab1bbfefce466d642ad98587d13123e4ef95ec9aa73b712e775d4cbba","server_ts_ms":1768250246867,"raw":{"market":"0xe51aa24ab1bbfefce466d642ad98587d13123e4ef95ec9aa73b712e775d4cbba","asset_id":"96886111393998001968863279421729456597655847484197549086072988901191634450924","best_bid":"0.94","best_ask":"0.95","spread":"0.01","timestamp":"1768250246867","event_type":"best_bid_ask"}}
{"schema_version":1,"source":"clob_ws_market","recv_ts_ns":1768250246910488945,"event_type":"price_change","market":"0xe51aa24ab1bbfefce466d642ad98587d13123e4ef95ec9aa73b712e775d4cbba","server_ts_ms":1768250246866,"raw":{"market":"0xe51aa24ab1bbfefce466d642ad98587d13123e4ef95ec9aa73b712e775d4cbba","price_changes":[{"asset_id":"96886111393998001968863279421729456597655847484197549086072988901191634450924","price":"0.95","size":"152.99","side":"SELL","hash":"0d021f863854d783c938c55d83fea222d434e761","best_bid":"0.94","best_ask":"0.95"},{"asset_id":"54232589582260339592359130012520874109228367674780084862642636038394766871668","price":"0.05","size":"152.99","side":"BUY","hash":"e6239e8a6ca5f676ff1288443e4282edf82c991a","best_bid":"0.05","best_ask":"0.06"}],"timestamp":"1768250246866","event_type":"price_change"}}
{"schema_version":1,"source":"clob_ws_market","recv_ts_ns":1768250246917082720,"event_type":"book","market":"0xe51aa24ab1bbfefce466d642ad98587d13123e4ef95ec9aa73b712e775d4cbba","server_ts_ms":1768250246866,"raw":{"market":"0xe51aa24ab1bbfefce466d642ad98587d13123e4ef95ec9aa73b712e775d4cbba","asset_id":"96886111393998001968863279421729456597655847484197549086072988901191634450924","bids":[{"price":"0.01","size":"24295.73"},{"price":"0.02","size":"7594.51"},{"price":"0.03","size":"5964.69"},{"price":"0.04","size":"5411.4"},{"price":"0.05","size":"5356.39"},{"price":"0.06","size":"5328"},{"price":"0.07","size":"5039.28"},{"price":"0.08","size":"5022.7"},{"price":"0.09","size":"5320.9"},{"price":"0.1","size":"5158.44"},{"price":"0.11","size":"18.3"},{"price":"0.12","size":"30.3"},{"price":"0.13","size":"16.5"},{"price":"0.14","size":"15.8"},{"price":"0.15","size":"104.19"},{"price":"0.16","size":"24.69"},{"price":"0.17","size":"14.19"},{"price":"0.18","size":"13.8"},{"price":"0.19","size":"13.4"},{"price":"0.2","size":"38.1"},{"price":"0.21","size":"12.8"},{"price":"0.22","size":"12.6"},{"price":"0.23","size":"12.3"},{"price":"0.24","size":"22.1"},{"price":"0.25","size":"16.9"},{"price":"0.26","size":"21.8"},{"price":"0.27","size":"11.6"},{"price":"0.28","size":"11.4"},{"price":"0.29","size":"61.3"},{"price":"0.3","size":"26.2"},{"price":"0.31","size":"11.1"},{"price":"0.32","size":"11"},{"price":"0.33","size":"110.9"},{"price":"0.34","size":"10.8"},{"price":"0.35","size":"15.7"},{"price":"0.36","size":"10.6"},{"price":"0.37","size":"10.6"},{"price":"0.38","size":"22.5"},{"price":"0.39","size":"10.5"},{"price":"0.4","size":"45.4"},{"price":"0.41","size":"311.4"},{"price":"0.42","size":"820.82"},{"price":"0.43","size":"826.3"},{"price":"0.44","size":"1062.3"},{"price":"0.45","size":"582.3"},{"price":"0.46","size":"626.2"},{"price":"0.47","size":"562.2"},{"price":"0.48","size":"567.2"},{"price":"0.49","size":"573.2"},{"price":"0.5","size":"917.2"},{"price":"0.51","size":"591.2"},{"price":"0.52","size":"590.2"},{"price":"0.53","size":"567.2"},{"price":"0.54","size":"642.61"},{"price":"0.55","size":"362.97"},{"price":"0.56","size":"341.3"},{"price":"0.57","size":"320.62"},{"price":"0.58","size":"567.3"},{"price":"0.59","size":"562.4"},{"price":"0.6","size":"693.02"},{"price":"0.61","size":"625.5"},{"price":"0.62","size":"700.5"},{"price":"0.63","size":"672.32"},{"price":"0.64","size":"680.6"},{"price":"0.65","size":"536.14"},{"price":"0.66","size":"602.8"},{"price":"0.67","size":"572.9"},{"price":"0.68","size":"573"},{"price":"0.69","size":"595.1"},{"price":"0.7","size":"603.2"},{"price":"0.71","size":"1318.72"},{"price":"0.72","size":"1043.04"},{"price":"0.73","size":"663.6"},{"price":"0.74","size":"911.17"},{"price":"0.75","size":"694.3"},{"price":"0.76","size":"717.6"},{"price":"0.77","size":"1183.3"},{"price":"0.78","size":"1449.6"},{"price":"0.79","size":"1254.75"},{"price":"0.8","size":"1445.08"},{"price":"0.81","size":"1229.8"},{"price":"0.82","size":"1467.57"},{"price":"0.83","size":"1470.51"},{"price":"0.84","size":"1668.59"},{"price":"0.85","size":"1762.5"},{"price":"0.86","size":"1755.6"},{"price":"0.87","size":"1588.93"},{"price":"0.88","size":"2355.4"},{"price":"0.89","size":"2066.7"},{"price":"0.9","size":"3467.84"},{"price":"0.91","size":"3018.44"},{"price":"0.92","size":"2549.36"},{"price":"0.93","size":"1571.82"},{"price":"0.94","size":"1846.21"}],"asks":[{"price":"0.99","size":"21059.9"},{"price":"0.98","size":"5425.25"},{"price":"0.97","size":"1234.1"},{"price":"0.96","size":"1632"},{"price":"0.95","size":"152.99"}],"hash":"0d021f863854d783c938c55d83fea222d434e761","timestamp":"1768250246866","event_type":"book"}}
{"schema_version":1,"source":"clob_ws_market","recv_ts_ns":1768250246919103110,"event_type":"price_change","market":"0xe51aa24ab1bbfefce466d642ad98587d13123e4ef95ec9aa73b712e775d4cbba","server_ts_ms":1768250246876,"raw":{"market":"0xe51aa24ab1bbfefce466d642ad98587d13123e4ef95ec9aa73b712e775d4cbba","price_changes":[{"asset_id":"54232589582260339592359130012520874109228367674780084862642636038394766871668","price":"0.01","size":"21028.9","side":"BUY","hash":"bd109ff5da776ba7227611a547a5e3ca058ac09d","best_bid":"0.05","best_ask":"0.06"},{"asset_id":"96886111393998001968863279421729456597655847484197549086072988901191634450924","price":"0.99","size":"21028.9","side":"SELL","hash":"de032fda7254ab5f8f6aae101d3ebe75cf647ebb","best_bid":"0.94","best_ask":"0.95"}],"timestamp":"1768250246876","event_type":"price_change"}}
{"schema_version":1,"source":"clob_ws_market","recv_ts_ns":1768250246925634109,"event_type":"last_trade_price","market":"0xe51aa24ab1bbfefce466d642ad98587d13123e4ef95ec9aa73b712e775d4cbba","server_ts_ms":1768250246897,"raw":{"market":"0xe51aa24ab1bbfefce466d642ad98587d13123e4ef95ec9aa73b712e775d4cbba","asset_id":"96886111393998001968863279421729456597655847484197549086072988901191634450924","price":"0.95","size":"5.410525","fee_rate_bps":"1000","side":"BUY","timestamp":"1768250246897","event_type":"last_trade_price","transaction_hash":"0xcf44ca3d2487541280be2b935ba7189a98c4e7b8953b539b5caef98eae946088"}}
{"schema_version":1,"source":"clob_ws_market","recv_ts_ns":1768250246953232715,"event_type":"price_change","market":"0xe51aa24ab1bbfefce466d642ad98587d13123e4ef95ec9aa73b712e775d4cbba","server_ts_ms":1768250246929,"raw":{"market":"0xe51aa24ab1bbfefce466d642ad98587d13123e4ef95ec9aa73b712e775d4cbba","price_changes":[{"asset_id":"54232589582260339592359130012520874109228367674780084862642636038394766871668","price":"0.01","size":"21059.9","side":"BUY","hash":"970215c02bab162d2fcb25c993371bdfc7524e9c","best_bid":"0.05","best_ask":"0.06"},{"asset_id":"96886111393998001968863279421729456597655847484197549086072988901191634450924","price":"0.99","size":"21059.9","side":"SELL","hash":"88d56aef1d910ce32e796d183b147a18c171afd1","best_bid":"0.94","best_ask":"0.95"}],"timestamp":"1768250246929","event_type":"price_change"}}
{"schema_version":1,"source":"clob_ws_market","recv_ts_ns":1768250246977613908,"event_type":"price_change","market":"0xe51aa24ab1bbfefce466d642ad98587d13123e4ef95ec9aa73b712e775d4cbba","server_ts_ms":1768250246955,"raw":{"market":"0xe51aa24ab1bbfefce466d642ad98587d13123e4ef95ec9aa73b712e775d4cbba","price_changes":[{"asset_id":"96886111393998001968863279421729456597655847484197549086072988901191634450924","price":"0.93","size":"1391.82","side":"BUY","hash":"d48eaa26d4ff6a2c1d6f9d10f584b49ce5c0cb4e","best_bid":"0.94","best_ask":"0.95"},{"asset_id":"54232589582260339592359130012520874109228367674780084862642636038394766871668","price":"0.07","size":"1391.82","side":"SELL","hash":"c51e0696a24b2716dc6b1ec72cdb77fe25080777","best_bid":"0.05","best_ask":"0.06"}],"timestamp":"1768250246955","event_type":"price_change"}}
{"schema_version":1,"source":"clob_ws_market","recv_ts_ns":1768250247027365234,"event_type":"price_change","market":"0xe51aa24ab1bbfefce466d642ad98587d13123e4ef95ec9aa73b712e775d4cbba","server_ts_ms":1768250247000,"raw":{"market":"0xe51aa24ab1bbfefce466d642ad98587d13123e4ef95ec9aa73b712e775d4cbba","price_changes":[{"asset_id":"54232589582260339592359130012520874109228367674780084862642636038394766871668","price":"0.01","size":"20959.9","side":"BUY","hash":"12f58fed51ce2b165ba30a28387696e9883507f2","best_bid":"0.05","best_ask":"0.06"},{"asset_id":"96886111393998001968863279421729456597655847484197549086072988901191634450924","price":"0.99","size":"20959.9","side":"SELL","hash":"3af8f83e86e3b3bea09d5685fa8d3bcc690f712b","best_bid":"0.94","best_ask":"0.95"}],"timestamp":"1768250247000","event_type":"price_change"}}
{"schema_version":1,"source":"clob_ws_market","recv_ts_ns":1768250247031209646,"event_type":"price_change","market":"0xe51aa24ab1bbfefce466d642ad98587d13123e4ef95ec9aa73b712e775d4cbba","server_ts_ms":1768250247005,"raw":{"market":"0xe51aa24ab1bbfefce466d642ad98587d13123e4ef95ec9aa73b712e775d4cbba","price_changes":[{"asset_id":"96886111393998001968863279421729456597655847484197549086072988901191634450924","price":"0.84","size":"1673.59","side":"BUY","hash":"c285d0c01ad0d9320566e4638369116f029751f4","best_bid":"0.94","best_ask":"0.95"},{"asset_id":"54232589582260339592359130012520874109228367674780084862642636038394766871668","price":"0.16","size":"1673.59","side":"SELL","hash":"0b7a10e1cf456c02bcebf06615cf910c0e257d34","best_bid":"0.05","best_ask":"0.06"}],"timestamp":"1768250247005","event_type":"price_change"}}
{"schema_version":1,"source":"clob_ws_market","recv_ts_ns":1768250247136405200,"event_type":"price_change","market":"0xe51aa24ab1bbfefce466d642ad98587d13123e4ef95ec9aa73b712e775d4cbba","server_ts_ms":1768250247115,"raw":{"market":"0xe51aa24ab1bbfefce466d642ad98587d13123e4ef95ec9aa73b712e775d4cbba","price_changes":[{"asset_id":"54232589582260339592359130012520874109228367674780084862642636038394766871668","price":"0.01","size":"21059.9","side":"BUY","hash":"6b416b30b7980d403de5b0195cff4fa5e42913be","best_bid":"0.05","best_ask":"0.06"},{"asset_id":"96886111393998001968863279421729456597655847484197549086072988901191634450924","price":"0.99","size":"21059.9","side":"SELL","hash":"cbd38055e8c11b8b009c90d71f604f812640b8c7","best_bid":"0.94","best_ask":"0.95"}],"timestamp":"1768250247115","event_type":"price_change"}}
{"schema_version":1,"source":"clob_ws_market","recv_ts_ns":1768250247142755704,"event_type":"best_bid_ask","market":"0xe51aa24ab1bbfefce466d642ad98587d13123e4ef95ec9aa73b712e775d4cbba","server_ts_ms":1768250247120,"raw":{"market":"0xe51aa24ab1bbfefce466d642ad98587d13123e4ef95ec9aa73b712e775d4cbba","asset_id":"96886111393998001968863279421729456597655847484197549086072988901191634450924","best_bid":"0.94","best_ask":"0.95","spread":"0.01","timestamp":"1768250247120","event_type":"best_bid_ask"}}
{"schema_version":1,"source":"clob_ws_market","recv_ts_ns":1768250247144998938,"event_type":"price_change","market":"0xe51aa24ab1bbfefce466d642ad98587d13123e4ef95ec9aa73b712e775d4cbba","server_ts_ms":1768250247118,"raw":{"market":"0xe51aa24ab1bbfefce466d642ad98587d13123e4ef95ec9aa73b712e775d4cbba","price_changes":[{"asset_id":"96886111393998001968863279421729456597655847484197549086072988901191634450924","price":"0.95","size":"132.99","side":"SELL","hash":"3286ec11157db37aaba66a2cef095fb63301e486","best_bid":"0.94","best_ask":"0.95"},{"asset_id":"54232589582260339592359130012520874109228367674780084862642636038394766871668","price":"0.05","size":"132.99","side":"BUY","hash":"786289ca2cc3a62bd8fd87d21e4950a4535f53a7","best_bid":"0.05","best_ask":"0.06"}],"timestamp":"1768250247118","event_type":"price_change"}}
{"schema_version":1,"source":"clob_ws_market","recv_ts_ns":1768250247157791989,"event_type":"book","market":"0xe51aa24ab1bbfefce466d642ad98587d13123e4ef95ec9aa73b712e775d4cbba","server_ts_ms":1768250247118,"raw":{"market":"0xe51aa24ab1bbfefce466d642ad98587d13123e4ef95ec9aa73b712e775d4cbba","asset_id":"96886111393998001968863279421729456597655847484197549086072988901191634450924","bids":[{"price":"0.01","size":"24295.73"},{"price":"0.02","size":"7594.51"},{"price":"0.03","size":"5964.69"},{"price":"0.04","size":"5411.4"},{"price":"0.05","size":"5356.39"},{"price":"0.06","size":"5328"},{"price":"0.07","size":"5039.28"},{"price":"0.08","size":"5022.7"},{"price":"0.09","size":"5320.9"},{"price":"0.1","size":"5158.44"},{"price":"0.11","size":"18.3"},{"price":"0.12","size":"30.3"},{"price":"0.13","size":"16.5"},{"price":"0.14","size":"15.8"},{"price":"0.15","size":"104.19"},{"price":"0.16","size":"24.69"},{"price":"0.17","size":"14.19"},{"price":"0.18","size":"13.8"},{"price":"0.19","size":"13.4"},{"price":"0.2","size":"38.1"},{"price":"0.21","size":"12.8"},{"price":"0.22","size":"12.6"},{"price":"0.23","size":"12.3"},{"price":"0.24","size":"22.1"},{"price":"0.25","size":"16.9"},{"price":"0.26","size":"21.8"},{"price":"0.27","size":"11.6"},{"price":"0.28","size":"11.4"},{"price":"0.29","size":"61.3"},{"price":"0.3","size":"26.2"},{"price":"0.31","size":"11.1"},{"price":"0.32","size":"11"},{"price":"0.33","size":"110.9"},{"price":"0.34","size":"10.8"},{"price":"0.35","size":"15.7"},{"price":"0.36","size":"10.6"},{"price":"0.37","size":"10.6"},{"price":"0.38","size":"22.5"},{"price":"0.39","size":"10.5"},{"price":"0.4","size":"45.4"},{"price":"0.41","size":"311.4"},{"price":"0.42","size":"820.82"},{"price":"0.43","size":"826.3"},{"price":"0.44","size":"1062.3"},{"price":"0.45","size":"582.3"},{"price":"0.46","size":"626.2"},{"price":"0.47","size":"562.2"},{"price":"0.48","size":"567.2"},{"price":"0.49","size":"573.2"},{"price":"0.5","size":"917.2"},{"price":"0.51","size":"591.2"},{"price":"0.52","size":"590.2"},{"price":"0.53","size":"567.2"},{"price":"0.54","size":"642.61"},{"price":"0.55","size":"362.97"},{"price":"0.56","size":"341.3"},{"price":"0.57","size":"320.62"},{"price":"0.58","size":"567.3"},{"price":"0.59","size":"562.4"},{"price":"0.6","size":"693.02"},{"price":"0.61","size":"625.5"},{"price":"0.62","size":"700.5"},{"price":"0.63","size":"672.32"},{"price":"0.64","size":"680.6"},{"price":"0.65","size":"536.14"},{"price":"0.66","size":"602.8"},{"price":"0.67","size":"572.9"},{"price":"0.68","size":"573"},{"price":"0.69","size":"595.1"},{"price":"0.7","size":"603.2"},{"price":"0.71","size":"1318.72"},{"price":"0.72","size":"1043.04"},{"price":"0.73","size":"663.6"},{"price":"0.74","size":"911.17"},{"price":"0.75","size":"694.3"},{"price":"0.76","size":"717.6"},{"price":"0.77","size":"1183.3"},{"price":"0.78","size":"1449.6"},{"price":"0.79","size":"1254.75"},{"price":"0.8","size":"1445.08"},{"price":"0.81","size":"1229.8"},{"price":"0.82","size":"1467.57"},{"price":"0.83","size":"1470.51"},{"price":"0.84","size":"1673.59"},{"price":"0.85","size":"1762.5"},{"price":"0.86","size":"1755.6"},{"price":"0.87","size":"1588.93"},{"price":"0.88","size":"2355.4"},{"price":"0.89","size":"2066.7"},{"price":"0.9","size":"3467.84"},{"price":"0.91","size":"3018.44"},{"price":"0.92","size":"2549.36"},{"price":"0.93","size":"1391.82"},{"price":"0.94","size":"1846.21"}],"asks":[{"price":"0.99","size":"21059.9"},{"price":"0.98","size":"5425.25"},{"price":"0.97","size":"1234.1"},{"price":"0.96","size":"1632"},{"price":"0.95","size":"132.99"}],"hash":"3286ec11157db37aaba66a2cef095fb63301e486","timestamp":"1768250247118","event_type":"book"}}
{"schema_version":1,"source":"clob_ws_market","recv_ts_ns":1768250247162403457,"event_type":"best_bid_ask","market":"0xe51aa24ab1bbfefce466d642ad98587d13123e4ef95ec9aa73b712e775d4cbba","server_ts_ms":1768250247123,"raw":{"market":"0xe51aa24ab1bbfefce466d642ad98587d13123e4ef95ec9aa73b712e775d4cbba","asset_id":"96886111393998001968863279421729456597655847484197549086072988901191634450924","best_bid":"0.94","best_ask":"0.95","spread":"0.01","timestamp":"1768250247123","event_type":"best_bid_ask"}}
{"schema_version":1,"source":"clob_ws_market","recv_ts_ns":1768250247164577045,"event_type":"price_change","market":"0xe51aa24ab1bbfefce466d642ad98587d13123e4ef95ec9aa73b712e775d4cbba","server_ts_ms":1768250247122,"raw":{"market":"0xe51aa24ab1bbfefce466d642ad98587d13123e4ef95ec9aa73b712e775d4cbba","price_changes":[{"asset_id":"96886111393998001968863279421729456597655847484197549086072988901191634450924","price":"0.95","size":"112.99","side":"SELL","hash":"231f274c521fdef9295c90fa131e4d12b7a83e65","best_bid":"0.94","best_ask":"0.95"},{"asset_id":"54232589582260339592359130012520874109228367674780084862642636038394766871668","price":"0.05","size":"112.99","side":"BUY","hash":"c9344a9a18c4c73af372fb465c98b76e01abded6","best_bid":"0.05","best_ask":"0.06"}],"timestamp":"1768250247122","event_type":"price_change"}}
{"schema_version":1,"source":"clob_ws_market","recv_ts_ns":1768250247174381820,"event_type":"book","market":"0xe51aa24ab1bbfefce466d642ad98587d13123e4ef95ec9aa73b712e775d4cbba","server_ts_ms":1768250247122,"raw":{"market":"0xe51aa24ab1bbfefce466d642ad98587d13123e4ef95ec9aa73b712e775d4cbba","asset_id":"96886111393998001968863279421729456597655847484197549086072988901191634450924","bids":[{"price":"0.01","size":"24295.73"},{"price":"0.02","size":"7594.51"},{"price":"0.03","size":"5964.69"},{"price":"0.04","size":"5411.4"},{"price":"0.05","size":"5356.39"},{"price":"0.06","size":"5328"},{"price":"0.07","size":"5039.28"},{"price":"0.08","size":"5022.7"},{"price":"0.09","size":"5320.9"},{"price":"0.1","size":"5158.44"},{"price":"0.11","size":"18.3"},{"price":"0.12","size":"30.3"},{"price":"0.13","size":"16.5"},{"price":"0.14","size":"15.8"},{"price":"0.15","size":"104.19"},{"price":"0.16","size":"24.69"},{"price":"0.17","size":"14.19"},{"price":"0.18","size":"13.8"},{"price":"0.19","size":"13.4"},{"price":"0.2","size":"38.1"},{"price":"0.21","size":"12.8"},{"price":"0.22","size":"12.6"},{"price":"0.23","size":"12.3"},{"price":"0.24","size":"22.1"},{"price":"0.25","size":"16.9"},{"price":"0.26","size":"21.8"},{"price":"0.27","size":"11.6"},{"price":"0.28","size":"11.4"},{"price":"0.29","size":"61.3"},{"price":"0.3","size":"26.2"},{"price":"0.31","size":"11.1"},{"price":"0.32","size":"11"},{"price":"0.33","size":"110.9"},{"price":"0.34","size":"10.8"},{"price":"0.35","size":"15.7"},{"price":"0.36","size":"10.6"},{"price":"0.37","size":"10.6"},{"price":"0.38","size":"22.5"},{"price":"0.39","size":"10.5"},{"price":"0.4","size":"45.4"},{"price":"0.41","size":"311.4"},{"price":"0.42","size":"820.82"},{"price":"0.43","size":"826.3"},{"price":"0.44","size":"1062.3"},{"price":"0.45","size":"582.3"},{"price":"0.46","size":"626.2"},{"price":"0.47","size":"562.2"},{"price":"0.48","size":"567.2"},{"price":"0.49","size":"573.2"},{"price":"0.5","size":"917.2"},{"price":"0.51","size":"591.2"},{"price":"0.52","size":"590.2"},{"price":"0.53","size":"567.2"},{"price":"0.54","size":"642.61"},{"price":"0.55","size":"362.97"},{"price":"0.56","size":"341.3"},{"price":"0.57","size":"320.62"},{"price":"0.58","size":"567.3"},{"price":"0.59","size":"562.4"},{"price":"0.6","size":"693.02"},{"price":"0.61","size":"625.5"},{"price":"0.62","size":"700.5"},{"price":"0.63","size":"672.32"},{"price":"0.64","size":"680.6"},{"price":"0.65","size":"536.14"},{"price":"0.66","size":"602.8"},{"price":"0.67","size":"572.9"},{"price":"0.68","size":"573"},{"price":"0.69","size":"595.1"},{"price":"0.7","size":"603.2"},{"price":"0.71","size":"1318.72"},{"price":"0.72","size":"1043.04"},{"price":"0.73","size":"663.6"},{"price":"0.74","size":"911.17"},{"price":"0.75","size":"694.3"},{"price":"0.76","size":"717.6"},{"price":"0.77","size":"1183.3"},{"price":"0.78","size":"1449.6"},{"price":"0.79","size":"1254.75"},{"price":"0.8","size":"1445.08"},{"price":"0.81","size":"1229.8"},{"price":"0.82","size":"1467.57"},{"price":"0.83","size":"1470.51"},{"price":"0.84","size":"1673.59"},{"price":"0.85","size":"1762.5"},{"price":"0.86","size":"1755.6"},{"price":"0.87","size":"1588.93"},{"price":"0.88","size":"2355.4"},{"price":"0.89","size":"2066.7"},{"price":"0.9","size":"3467.84"},{"price":"0.91","size":"3018.44"},{"price":"0.92","size":"2549.36"},{"price":"0.93","size":"1391.82"},{"price":"0.94","size":"1846.21"}],"asks":[{"price":"0.99","size":"21059.9"},{"price":"0.98","size":"5425.25"},{"price":"0.97","size":"1234.1"},{"price":"0.96","size":"1632"},{"price":"0.95","size":"112.99"}],"hash":"231f274c521fdef9295c90fa131e4d12b7a83e65","timestamp":"1768250247122","event_type":"book"}}
{"schema_version":1,"source":"clob_ws_market","recv_ts_ns":1768250247176940436,"event_type":"price_change","market":"0xe51aa24ab1bbfefce466d642ad98587d13123e4ef95ec9aa73b712e775d4cbba","server_ts_ms":1768250247124,"raw":{"market":"0xe51aa24ab1bbfefce466d642ad98587d13123e4ef95ec9aa73b712e775d4cbba","price_changes":[{"asset_id":"54232589582260339592359130012520874109228367674780084862642636038394766871668","price":"0.01","size":"21028.9","side":"BUY","hash":"0b1b5fb0a58fe9452cd39cfbdb0ba228c5c1344f","best_bid":"0.05","best_ask":"0.06"},{"asset_id":"96886111393998001968863279421729456597655847484197549086072988901191634450924","price":"0.99","size":"21028.9","side":"SELL","hash":"16367e0b21eab44ceb040cfaf018690a086f3d65","best_bid":"0.94","best_ask":"0.95"}],"timestamp":"1768250247124","event_type":"price_change"}}
{"schema_version":1,"source":"clob_ws_market","recv_ts_ns":1768250247181759406,"event_type":"price_change","market":"0xe51aa24ab1bbfefce466d642ad98587d13123e4ef95ec9aa73b712e775d4cbba","server_ts_ms":1768250247145,"raw":{"market":"0xe51aa24ab1bbfefce466d642ad98587d13123e4ef95ec9aa73b712e775d4cbba","price_changes":[{"asset_id":"96886111393998001968863279421729456597655847484197549086072988901191634450924","price":"0.97","size":"1228.6","side":"SELL","hash":"7e9b3861157c9bfcbf4a7225ed00c646b395af6c","best_bid":"0.94","best_ask":"0.95"},{"asset_id":"54232589582260339592359130012520874109228367674780084862642636038394766871668","price":"0.03","size":"1228.6","side":"BUY","hash":"9c1c6f930a281cadded235d0655dd95446c6b7b1","best_bid":"0.05","best_ask":"0.06"}],"timestamp":"1768250247145","event_type":"price_change"}}
{"schema_version":1,"source":"clob_ws_market","recv_ts_ns":1768250247185722056,"event_type":"price_change","market":"0xe51aa24ab1bbfefce466d642ad98587d13123e4ef95ec9aa73b712e775d4cbba","server_ts_ms":1768250247150,"raw":{"market":"0xe51aa24ab1bbfefce466d642ad98587d13123e4ef95ec9aa73b712e775d4cbba","price_changes":[{"asset_id":"54232589582260339592359130012520874109228367674780084862642636038394766871668","price":"0.03","size":"1048.6","side":"BUY","hash":"8ac330498097c2cbd7fccc4f9e64acc3f008ead6","best_bid":"0.05","best_ask":"0.06"},{"asset_id":"96886111393998001968863279421729456597655847484197549086072988901191634450924","price":"0.97","size":"1048.6","side":"SELL","hash":"c2be8ad64ec88bbd701dadd492d32defdcfde273","best_bid":"0.94","best_ask":"0.95"}],"timestamp":"1768250247150","event_type":"price_change"}}
{"schema_version":1,"source":"clob_ws_market","recv_ts_ns":1768250247190097936,"event_type":"last_trade_price","market":"0xe51aa24ab1bbfefce466d642ad98587d13123e4ef95ec9aa73b712e775d4cbba","server_ts_ms":1768250247152,"raw":{"market":"0xe51aa24ab1bbfefce466d642ad98587d13123e4ef95ec9aa73b712e775d4cbba","asset_id":"96886111393998001968863279421729456597655847484197549086072988901191634450924","price":"0.95","size":"20","fee_rate_bps":"1000","side":"BUY","timestamp":"1768250247152","event_type":"last_trade_price","transaction_hash":"0x853dd385c462fc02105dd235e8b339f9f2f75fef7ed580043535c03c48f240b9"}}
{"schema_version":1,"source":"clob_ws_market","recv_ts_ns":1768250247192925505,"event_type":"price_change","market":"0xe51aa24ab1bbfefce466d642ad98587d13123e4ef95ec9aa73b712e775d4cbba","server_ts_ms":1768250247168,"raw":{"market":"0xe51aa24ab1bbfefce466d642ad98587d13123e4ef95ec9aa73b712e775d4cbba","price_changes":[{"asset_id":"96886111393998001968863279421729456597655847484197549086072988901191634450924","price":"0.73","size":"668.6","side":"BUY","hash":"f429b77e343d8f5c651c8c92275fd6c4bb09e0c9","best_bid":"0.94","best_ask":"0.95"},{"asset_id":"54232589582260339592359130012520874109228367674780084862642636038394766871668","price":"0.27","size":"668.6","side":"SELL","hash":"3155e68b78ce623bd4109f1772c4d97f89714502","best_bid":"0.05","best_ask":"0.06"}],"timestamp":"1768250247168","event_type":"price_change"}}
{"schema_version":1,"source":"clob_ws_market","recv_ts_ns":1768250247199080086,"event_type":"price_change","market":"0xe51aa24ab1bbfefce466d642ad98587d13123e4ef95ec9aa73b712e775d4cbba","server_ts_ms":1768250247170,"raw":{"market":"0xe51aa24ab1bbfefce466d642ad98587d13123e4ef95ec9aa73b712e775d4cbba","price_changes":[{"asset_id":"54232589582260339592359130012520874109228367674780084862642636038394766871668","price":"0.01","size":"21059.9","side":"BUY","hash":"5dfefce26c7d791c4f4812db27dfbe115f15bfe0","best_bid":"0.05","best_ask":"0.06"},{"asset_id":"96886111393998001968863279421729456597655847484197549086072988901191634450924","price":"0.99","size":"21059.9","side":"SELL","hash":"d11bf459c2962e536ef2de9b3a9c45131171b4c5","best_bid":"0.94","best_ask":"0.95"}],"timestamp":"1768250247170","event_type":"price_change"}}
{"schema_version":1,"source":"clob_ws_market","recv_ts_ns":1768250247220914879,"event_type":"last_trade_price","market":"0xe51aa24ab1bbfefce466d642ad98587d13123e4ef95ec9aa73b712e775d4cbba","server_ts_ms":1768250247152,"raw":{"market":"0xe51aa24ab1bbfefce466d642ad98587d13123e4ef95ec9aa73b712e775d4cbba","asset_id":"96886111393998001968863279421729456597655847484197549086072988901191634450924","price":"0.95","size":"20","fee_rate_bps":"1000","side":"BUY","timestamp":"1768250247152","event_type":"last_trade_price","transaction_hash":"0x1b34edad3557e416a3cdf8c45964a1d369f2f904ea11e34566875e8b96230119"}}
{"schema_version":1,"source":"clob_ws_market","recv_ts_ns":1768250247240159956,"event_type":"price_change","market":"0xe51aa24ab1bbfefce466d642ad98587d13123e4ef95ec9aa73b712e775d4cbba","server_ts_ms":1768250247204,"raw":{"market":"0xe51aa24ab1bbfefce466d642ad98587d13123e4ef95ec9aa73b712e775d4cbba","price_changes":[{"asset_id":"96886111393998001968863279421729456597655847484197549086072988901191634450924","price":"0.96","size":"1637.5","side":"SELL","hash":"228733edebb171371cf3f62615a9c95812237c6f","best_bid":"0.94","best_ask":"0.95"},{"asset_id":"54232589582260339592359130012520874109228367674780084862642636038394766871668","price":"0.04","size":"1637.5","side":"BUY","hash":"d9d0ebae636935ccdf1ee8e6f61ddf39106554e0","best_bid":"0.05","best_ask":"0.06"}],"timestamp":"1768250247204","event_type":"price_change"}}
{"schema_version":1,"source":"clob_ws_market","recv_ts_ns":1768250247245298522,"event_type":"price_change","market":"0xe51aa24ab1bbfefce466d642ad98587d13123e4ef95ec9aa73b712e775d4cbba","server_ts_ms":1768250247213,"raw":{"market":"0xe51aa24ab1bbfefce466d642ad98587d13123e4ef95ec9aa73b712e775d4cbba","price_changes":[{"asset_id":"54232589582260339592359130012520874109228367674780084862642636038394766871668","price":"0.05","size":"12.99","side":"BUY","hash":"945c9bbf68062efd2a6080d8eec6409b06af5d85","best_bid":"0.05","best_ask":"0.06"},{"asset_id":"96886111393998001968863279421729456597655847484197549086072988901191634450924","price":"0.95","size":"12.99","side":"SELL","hash":"2d26b6ce37da49acfdca9ac3b0f5bc10fc77c923","best_bid":"0.94","best_ask":"0.95"}],"timestamp":"1768250247213","event_type":"price_change"}}
{"schema_version":1,"source":"clob_ws_market","recv_ts_ns":1768250247289583074,"event_type":"best_bid_ask","market":"0xe51aa24ab1bbfefce466d642ad98587d13123e4ef95ec9aa73b712e775d4cbba","server_ts_ms":1768250247265,"raw":{"market":"0xe51aa24ab1bbfefce466d642ad98587d13123e4ef95ec9aa73b712e775d4cbba","asset_id":"96886111393998001968863279421729456597655847484197549086072988901191634450924","best_bid":"0.94","best_ask":"0.95","spread":"0.01","timestamp":"1768250247265","event_type":"best_bid_ask"}}
{"schema_version":1,"source":"clob_ws_market","recv_ts_ns":1768250247294756580,"event_type":"price_change","market":"0xe51aa24ab1bbfefce466d642ad98587d13123e4ef95ec9aa73b712e775d4cbba","server_ts_ms":1768250247262,"raw":{"market":"0xe51aa24ab1bbfefce466d642ad98587d13123e4ef95ec9aa73b712e775d4cbba","price_changes":[{"asset_id":"96886111393998001968863279421729456597655847484197549086072988901191634450924","price":"0.94","size":"1786.21","side":"BUY","hash":"0329994b22438e008d4b20c3f399125c557cd65b","best_bid":"0.94","best_ask":"0.95"},{"asset_id":"54232589582260339592359130012520874109228367674780084862642636038394766871668","price":"0.06","size":"1786.21","side":"SELL","hash":"3b8a9ca9db248d325c12c5a8e37e668457575d7c","best_bid":"0.05","best_ask":"0.06"}],"timestamp":"1768250247262","event_type":"price_change"}}
{"schema_version":1,"source":"clob_ws_market","recv_ts_ns":1768250247307568326,"event_type":"book","market":"0xe51aa24ab1bbfefce466d642ad98587d13123e4ef95ec9aa73b712e775d4cbba","server_ts_ms":1768250247262,"raw":{"market":"0xe51aa24ab1bbfefce466d642ad98587d13123e4ef95ec9aa73b712e775d4cbba","asset_id":"96886111393998001968863279421729456597655847484197549086072988901191634450924","bids":[{"price":"0.01","size":"24295.73"},{"price":"0.02","size":"7594.51"},{"price":"0.03","size":"5964.69"},{"price":"0.04","size":"5411.4"},{"price":"0.05","size":"5356.39"},{"price":"0.06","size":"5328"},{"price":"0.07","size":"5039.28"},{"price":"0.08","size":"5022.7"},{"price":"0.09","size":"5320.9"},{"price":"0.1","size":"5158.44"},{"price":"0.11","size":"18.3"},{"price":"0.12","size":"30.3"},{"price":"0.13","size":"16.5"},{"price":"0.14","size":"15.8"},{"price":"0.15","size":"104.19"},{"price":"0.16","size":"24.69"},{"price":"0.17","size":"14.19"},{"price":"0.18","size":"13.8"},{"price":"0.19","size":"13.4"},{"price":"0.2","size":"38.1"},{"price":"0.21","size":"12.8"},{"price":"0.22","size":"12.6"},{"price":"0.23","size":"12.3"},{"price":"0.24","size":"22.1"},{"price":"0.25","size":"16.9"},{"price":"0.26","size":"21.8"},{"price":"0.27","size":"11.6"},{"price":"0.28","size":"11.4"},{"price":"0.29","size":"61.3"},{"price":"0.3","size":"26.2"},{"price":"0.31","size":"11.1"},{"price":"0.32","size":"11"},{"price":"0.33","size":"110.9"},{"price":"0.34","size":"10.8"},{"price":"0.35","size":"15.7"},{"price":"0.36","size":"10.6"},{"price":"0.37","size":"10.6"},{"price":"0.38","size":"22.5"},{"price":"0.39","size":"10.5"},{"price":"0.4","size":"45.4"},{"price":"0.41","size":"311.4"},{"price":"0.42","size":"820.82"},{"price":"0.43","size":"826.3"},{"price":"0.44","size":"1062.3"},{"price":"0.45","size":"582.3"},{"price":"0.46","size":"626.2"},{"price":"0.47","size":"562.2"},{"price":"0.48","size":"567.2"},{"price":"0.49","size":"573.2"},{"price":"0.5","size":"917.2"},{"price":"0.51","size":"591.2"},{"price":"0.52","size":"590.2"},{"price":"0.53","size":"567.2"},{"price":"0.54","size":"642.61"},{"price":"0.55","size":"362.97"},{"price":"0.56","size":"341.3"},{"price":"0.57","size":"320.62"},{"price":"0.58","size":"567.3"},{"price":"0.59","size":"562.4"},{"price":"0.6","size":"693.02"},{"price":"0.61","size":"625.5"},{"price":"0.62","size":"700.5"},{"price":"0.63","size":"672.32"},{"price":"0.64","size":"680.6"},{"price":"0.65","size":"536.14"},{"price":"0.66","size":"602.8"},{"price":"0.67","size":"572.9"},{"price":"0.68","size":"573"},{"price":"0.69","size":"595.1"},{"price":"0.7","size":"603.2"},{"price":"0.71","size":"1318.72"},{"price":"0.72","size":"1043.04"},{"price":"0.73","size":"668.6"},{"price":"0.74","size":"911.17"},{"price":"0.75","size":"694.3"},{"price":"0.76","size":"717.6"},{"price":"0.77","size":"1183.3"},{"price":"0.78","size":"1449.6"},{"price":"0.79","size":"1254.75"},{"price":"0.8","size":"1445.08"},{"price":"0.81","size":"1229.8"},{"price":"0.82","size":"1467.57"},{"price":"0.83","size":"1470.51"},{"price":"0.84","size":"1673.59"},{"price":"0.85","size":"1762.5"},{"price":"0.86","size":"1755.6"},{"price":"0.87","size":"1588.93"},{"price":"0.88","size":"2355.4"},{"price":"0.89","size":"2066.7"},{"price":"0.9","size":"3467.84"},{"price":"0.91","size":"3018.44"},{"price":"0.92","size":"2549.36"},{"price":"0.93","size":"1391.82"},{"price":"0.94","size":"1786.21"}],"asks":[{"price":"0.99","size":"21059.9"},{"price":"0.98","size":"5425.25"},{"price":"0.97","size":"1048.6"},{"price":"0.96","size":"1637.5"},{"price":"0.95","size":"12.99"}],"hash":"0329994b22438e008d4b20c3f399125c557cd65b","timestamp":"1768250247262","event_type":"book"}}
{"schema_version":1,"source":"clob_ws_market","recv_ts_ns":1768250247317732281,"event_type":"price_change","market":"0xe51aa24ab1bbfefce466d642ad98587d13123e4ef95ec9aa73b712e775d4cbba","server_ts_ms":1768250247265,"raw":{"market":"0xe51aa24ab1bbfefce466d642ad98587d13123e4ef95ec9aa73b712e775d4cbba","price_changes":[{"asset_id":"96886111393998001968863279421729456597655847484197549086072988901191634450924","price":"0.84","size":"1668.59","side":"BUY","hash":"8ae2b082f08bb2effb6b794cbe1ff9b5ecfea03c","best_bid":"0.94","best_ask":"0.95"},{"asset_id":"54232589582260339592359130012520874109228367674780084862642636038394766871668","price":"0.16","size":"1668.59","side":"SELL","hash":"7a24778352fb48c4282feb4ba9dc53ef1f31c31e","best_bid":"0.05","best_ask":"0.06"}],"timestamp":"1768250247265","event_type":"price_change"}}
{"schema_version":1,"source":"clob_ws_market","recv_ts_ns":1768250247323512404,"event_type":"price_change","market":"0xe51aa24ab1bbfefce466d642ad98587d13123e4ef95ec9aa73b712e775d4cbba","server_ts_ms":1768250247266,"raw":{"market":"0xe51aa24ab1bbfefce466d642ad98587d13123e4ef95ec9aa73b712e775d4cbba","price_changes":[{"asset_id":"54232589582260339592359130012520874109228367674780084862642636038394766871668","price":"0.06","size":"1806.21","side":"SELL","hash":"fcb1d234c592aeb2a5dfdb5a7bfc1b3714d77f0c","best_bid":"0.05","best_ask":"0.06"},{"asset_id":"96886111393998001968863279421729456597655847484197549086072988901191634450924","price":"0.94","size":"1806.21","side":"BUY","hash":"106fe9ffabcd6bf4bc0fcc5ca5914ff4d9f32308","best_bid":"0.94","best_ask":"0.95"}],"timestamp":"1768250247266","event_type":"price_change"}}
{"schema_version":1,"source":"clob_ws_market","recv_ts_ns":1768250247326747499,"event_type":"price_change","market":"0xe51aa24ab1bbfefce466d642ad98587d13123e4ef95ec9aa73b712e775d4cbba","server_ts_ms":1768250247280,"raw":{"market":"0xe51aa24ab1bbfefce466d642ad98587d13123e4ef95ec9aa73b712e775d4cbba","price_changes":[{"asset_id":"96886111393998001968863279421729456597655847484197549086072988901191634450924","price":"0.94","size":"1818.21","side":"BUY","hash":"8d9b9a9c575d90566ae5ee58934aaac55232d369","best_bid":"0.94","best_ask":"0.95"},{"asset_id":"54232589582260339592359130012520874109228367674780084862642636038394766871668","price":"0.06","size":"1818.21","side":"SELL","hash":"542d3cf60d9bc1eaecbe4a6afc744365f5abb9d2","best_bid":"0.05","best_ask":"0.06"}],"timestamp":"1768250247280","event_type":"price_change"}}
{"schema_version":1,"source":"clob_ws_market","recv_ts_ns":1768250247330515625,"event_type":"price_change","market":"0xe51aa24ab1bbfefce466d642ad98587d13123e4ef95ec9aa73b712e775d4cbba","server_ts_ms":1768250247283,"raw":{"market":"0xe51aa24ab1bbfefce466d642ad98587d13123e4ef95ec9aa73b712e775d4cbba","price_changes":[{"asset_id":"96886111393998001968863279421729456597655847484197549086072988901191634450924","price":"0.94","size":"1842.21","side":"BUY","hash":"8b5066fa2eea1260bfc18ccdc80aabfc91d44de4","best_bid":"0.94","best_ask":"0.95"},{"asset_id":"54232589582260339592359130012520874109228367674780084862642636038394766871668","price":"0.06","size":"1842.21","side":"SELL","hash":"32785d65b57be809dec9e3f7457018d8119ae889","best_bid":"0.05","best_ask":"0.06"}],"timestamp":"1768250247283","event_type":"price_change"}}
{"schema_version":1,"source":"clob_ws_market","recv_ts_ns":1768250247340008058,"event_type":"price_change","market":"0xe51aa24ab1bbfefce466d642ad98587d13123e4ef95ec9aa73b712e775d4cbba","server_ts_ms":1768250247316,"raw":{"market":"0xe51aa24ab1bbfefce466d642ad98587d13123e4ef95ec9aa73b712e775d4cbba","price_changes":[{"asset_id":"96886111393998001968863279421729456597655847484197549086072988901191634450924","price":"0.94","size":"1830.21","side":"BUY","hash":"2617ef9de7330bef83a7fcf94b2581255b4af4b7","best_bid":"0.94","best_ask":"0.95"},{"asset_id":"54232589582260339592359130012520874109228367674780084862642636038394766871668","price":"0.06","size":"1830.21","side":"SELL","hash":"0629cb6f05df3ea6b3dd999c1cde9afee7caee9d","best_bid":"0.05","best_ask":"0.06"}],"timestamp":"1768250247316","event_type":"price_change"}}
{"schema_version":1,"source":"clob_ws_market","recv_ts_ns":1768250247366024338,"event_type":"price_change","market":"0xe51aa24ab1bbfefce466d642ad98587d13123e4ef95ec9aa73b712e775d4cbba","server_ts_ms":1768250247334,"raw":{"market":"0xe51aa24ab1bbfefce466d642ad98587d13123e4ef95ec9aa73b712e775d4cbba","price_changes":[{"asset_id":"96886111393998001968863279421729456597655847484197549086072988901191634450924","price":"0.63","size":"703.32","side":"BUY","hash":"6789acd9d98c3e3269878498b3475796b78ca692","best_bid":"0.94","best_ask":"0.95"},{"asset_id":"54232589582260339592359130012520874109228367674780084862642636038394766871668","price":"0.37","size":"703.32","side":"SELL","hash":"b93b5e3895610022bea46b4d96e67669f48665a7","best_bid":"0.05","best_ask":"0.06"}],"timestamp":"1768250247334","event_type":"price_change"}}
{"schema_version":1,"source":"clob_ws_market","recv_ts_ns":1768250247371355429,"event_type":"price_change","market":"0xe51aa24ab1bbfefce466d642ad98587d13123e4ef95ec9aa73b712e775d4cbba","server_ts_ms":1768250247336,"raw":{"market":"0xe51aa24ab1bbfefce466d642ad98587d13123e4ef95ec9aa73b712e775d4cbba","price_changes":[{"asset_id":"96886111393998001968863279421729456597655847484197549086072988901191634450924","price":"0.94","size":"1818.21","side":"BUY","hash":"e4b940a46e7cb63c5b3d0569b12ccb276d79e725","best_bid":"0.94","best_ask":"0.95"},{"asset_id":"54232589582260339592359130012520874109228367674780084862642636038394766871668","price":"0.06","size":"1818.21","side":"SELL","hash":"95fe85c214a42fbdc80ab31ba88035c897810f84","best_bid":"0.05","best_ask":"0.06"}],"timestamp":"1768250247336","event_type":"price_change"}}
{"schema_version":1,"source":"clob_ws_market","recv_ts_ns":1768250247376758462,"event_type":"price_change","market":"0xe51aa24ab1bbfefce466d642ad98587d13123e4ef95ec9aa73b712e775d4cbba","server_ts_ms":1768250247339,"raw":{"market":"0xe51aa24ab1bbfefce466d642ad98587d13123e4ef95ec9aa73b712e775d4cbba","price_changes":[{"asset_id":"54232589582260339592359130012520874109228367674780084862642636038394766871668","price":"0.06","size":"1829.21","side":"SELL","hash":"5f6133b1f3e66e9512cfc8567521196d038d5b5f","best_bid":"0.05","best_ask":"0.06"},{"asset_id":"96886111393998001968863279421729456597655847484197549086072988901191634450924","price":"0.94","size":"1829.21","side":"BUY","hash":"52b7c292bbb45b55814f1221648fb3f7f9b746fe","best_bid":"0.94","best_ask":"0.95"}],"timestamp":"1768250247339","event_type":"price_change"}}
{"schema_version":1,"source":"clob_ws_market","recv_ts_ns":1768250247381657594,"event_type":"price_change","market":"0xe51aa24ab1bbfefce466d642ad98587d13123e4ef95ec9aa73b712e775d4cbba","server_ts_ms":1768250247342,"raw":{"market":"0xe51aa24ab1bbfefce466d642ad98587d13123e4ef95ec9aa73b712e775d4cbba","price_changes":[{"asset_id":"96886111393998001968863279421729456597655847484197549086072988901191634450924","price":"0.94","size":"1841.21","side":"BUY","hash":"f90d96295a82150991f74beb51b093250dfb2d47","best_bid":"0.94","best_ask":"0.95"},{"asset_id":"54232589582260339592359130012520874109228367674780084862642636038394766871668","price":"0.06","size":"1841.21","side":"SELL","hash":"2ecb8d3b93e24fadf0b25dcfb8a773d2917d6c8a","best_bid":"0.05","best_ask":"0.06"}],"timestamp":"1768250247342","event_type":"price_change"}}
{"schema_version":1,"source":"clob_ws_market","recv_ts_ns":1768250247386220829,"event_type":"price_change","market":"0xe51aa24ab1bbfefce466d642ad98587d13123e4ef95ec9aa73b712e775d4cbba","server_ts_ms":1768250247351,"raw":{"market":"0xe51aa24ab1bbfefce466d642ad98587d13123e4ef95ec9aa73b712e775d4cbba","price_changes":[{"asset_id":"54232589582260339592359130012520874109228367674780084862642636038394766871668","price":"0.03","size":"1228.6","side":"BUY","hash":"e1a5de5260ac463833a6096b6537f2d02a582b38","best_bid":"0.05","best_ask":"0.06"},{"asset_id":"96886111393998001968863279421729456597655847484197549086072988901191634450924","price":"0.97","size":"1228.6","side":"SELL","hash":"29496a13b199c647ae73868a0501941e29c72e49","best_bid":"0.94","best_ask":"0.95"}],"timestamp":"1768250247351","event_type":"price_change"}}
{"schema_version":1,"source":"clob_ws_market","recv_ts_ns":1768250247391705792,"event_type":"price_change","market":"0xe51aa24ab1bbfefce466d642ad98587d13123e4ef95ec9aa73b712e775d4cbba","server_ts_ms":1768250247363,"raw":{"market":"0xe51aa24ab1bbfefce466d642ad98587d13123e4ef95ec9aa73b712e775d4cbba","price_changes":[{"asset_id":"54232589582260339592359130012520874109228367674780084862642636038394766871668","price":"0.06","size":"1826.21","side":"SELL","hash":"3f1a1b7c63542e2c9b71306fae28df20b922e5f6","best_bid":"0.05","best_ask":"0.06"},{"asset_id":"96886111393998001968863279421729456597655847484197549086072988901191634450924","price":"0.94","size":"1826.21","side":"BUY","hash":"85c265ad2e411ba0fba52b590d78cc9820c01942","best_bid":"0.94","best_ask":"0.95"}],"timestamp":"1768250247363","event_type":"price_change"}}
{"schema_version":1,"source":"clob_ws_market","recv_ts_ns":1768250247396594705,"event_type":"price_change","market":"0xe51aa24ab1bbfefce466d642ad98587d13123e4ef95ec9aa73b712e775d4cbba","server_ts_ms":1768250247375,"raw":{"market":"0xe51aa24ab1bbfefce466d642ad98587d13123e4ef95ec9aa73b712e775d4cbba","price_changes":[{"asset_id":"96886111393998001968863279421729456597655847484197549086072988901191634450924","price":"0.94","size":"1814.21","side":"BUY","hash":"385cccbda91f3e105583b26b7f69f6bfc221540d","best_bid":"0.94","best_ask":"0.95"},{"asset_id":"54232589582260339592359130012520874109228367674780084862642636038394766871668","price":"0.06","size":"1814.21","side":"SELL","hash":"a28899ed62ea86120d5fe2cc9cb4c65bcabc6451","best_bid":"0.05","best_ask":"0.06"}],"timestamp":"1768250247375","event_type":"price_change"}}
{"schema_version":1,"source":"clob_ws_market","recv_ts_ns":1768250247424375841,"event_type":"price_change","market":"0xe51aa24ab1bbfefce466d642ad98587d13123e4ef95ec9aa73b712e775d4cbba","server_ts_ms":1768250247403,"raw":{"market":"0xe51aa24ab1bbfefce466d642ad98587d13123e4ef95ec9aa73b712e775d4cbba","price_changes":[{"asset_id":"96886111393998001968863279421729456597655847484197549086072988901191634450924","price":"0.92","size":"2729.36","side":"BUY","hash":"70bd0a860773d8aa60f064379b4c61200c110fa7","best_bid":"0.94","best_ask":"0.95"},{"asset_id":"54232589582260339592359130012520874109228367674780084862642636038394766871668","price":"0.08","size":"2729.36","side":"SELL","hash":"49702c48c2edd7812c325b66393df6529784aa86","best_bid":"0.05","best_ask":"0.06"}],"timestamp":"1768250247403","event_type":"price_change"}}
{"schema_version":1,"source":"clob_ws_market","recv_ts_ns":1768250247466290103,"event_type":"price_change","market":"0xe51aa24ab1bbfefce466d642ad98587d13123e4ef95ec9aa73b712e775d4cbba","server_ts_ms":1768250247445,"raw":{"market":"0xe51aa24ab1bbfefce466d642ad98587d13123e4ef95ec9aa73b712e775d4cbba","price_changes":[{"asset_id":"96886111393998001968863279421729456597655847484197549086072988901191634450924","price":"0.99","size":"21209.86","side":"SELL","hash":"aa0c0dc9436ed9b4fdb85e50d92ea64ca3c9a5bb","best_bid":"0.94","best_ask":"0.95"},{"asset_id":"54232589582260339592359130012520874109228367674780084862642636038394766871668","price":"0.01","size":"21209.86","side":"BUY","hash":"29c1cd3012f36a89574db6f906042b965d689540","best_bid":"0.05","best_ask":"0.06"}],"timestamp":"1768250247445","event_type":"price_change"}}
{"schema_version":1,"source":"clob_ws_market","recv_ts_ns":1768250247585871667,"event_type":"price_change","market":"0xe51aa24ab1bbfefce466d642ad98587d13123e4ef95ec9aa73b712e775d4cbba","server_ts_ms":1768250247562,"raw":{"market":"0xe51aa24ab1bbfefce466d642ad98587d13123e4ef95ec9aa73b712e775d4cbba","price_changes":[{"asset_id":"54232589582260339592359130012520874109228367674780084862642636038394766871668","price":"0.01","size":"21178.86","side":"BUY","hash":"84a5c62a7fa6e9819ed5bb42f35f45ea8bfa961e","best_bid":"0.05","best_ask":"0.06"},{"asset_id":"96886111393998001968863279421729456597655847484197549086072988901191634450924","price":"0.99","size":"21178.86","side":"SELL","hash":"308c4724cb84d252f93a88729d568be22b6dd0a3","best_bid":"0.94","best_ask":"0.95"}],"timestamp":"1768250247562","event_type":"price_change"}}
{"schema_version":1,"source":"clob_ws_market","recv_ts_ns":1768250247628540456,"event_type":"price_change","market":"0xe51aa24ab1bbfefce466d642ad98587d13123e4ef95ec9aa73b712e775d4cbba","server_ts_ms":1768250247607,"raw":{"market":"0xe51aa24ab1bbfefce466d642ad98587d13123e4ef95ec9aa73b712e775d4cbba","price_changes":[{"asset_id":"54232589582260339592359130012520874109228367674780084862642636038394766871668","price":"0.01","size":"21209.86","side":"BUY","hash":"7676d188cb669fb33cdabe7281b764b740410086","best_bid":"0.05","best_ask":"0.06"},{"asset_id":"96886111393998001968863279421729456597655847484197549086072988901191634450924","price":"0.99","size":"21209.86","side":"SELL","hash":"99c6635427bd6ee8775abccf83618f0d6b40013a","best_bid":"0.94","best_ask":"0.95"}],"timestamp":"1768250247607","event_type":"price_change"}}
{"schema_version":1,"source":"clob_ws_market","recv_ts_ns":1768250247654424244,"event_type":"price_change","market":"0xe51aa24ab1bbfefce466d642ad98587d13123e4ef95ec9aa73b712e775d4cbba","server_ts_ms":1768250247632,"raw":{"market":"0xe51aa24ab1bbfefce466d642ad98587d13123e4ef95ec9aa73b712e775d4cbba","price_changes":[{"asset_id":"96886111393998001968863279421729456597655847484197549086072988901191634450924","price":"0.73","size":"663.6","side":"BUY","hash":"40a08461eacec39ee3b763da9017f70e93bd4c3d","best_bid":"0.94","best_ask":"0.95"},{"asset_id":"54232589582260339592359130012520874109228367674780084862642636038394766871668","price":"0.27","size":"663.6","side":"SELL","hash":"6cb00bfe66464d3b19fcddc58abece2185795b83","best_bid":"0.05","best_ask":"0.06"}],"timestamp":"1768250247632","event_type":"price_change"}}
{"schema_version":1,"source":"clob_ws_market","recv_ts_ns":1768250247692922198,"event_type":"best_bid_ask","market":"0xe51aa24ab1bbfefce466d642ad98587d13123e4ef95ec9aa73b712e775d4cbba","server_ts_ms":1768250247660,"raw":{"market":"0xe51aa24ab1bbfefce466d642ad98587d13123e4ef95ec9aa73b712e775d4cbba","asset_id":"96886111393998001968863279421729456597655847484197549086072988901191634450924","best_bid":"0.94","best_ask":"0.95","spread":"0.01","timestamp":"1768250247660","event_type":"best_bid_ask"}}
{"schema_version":1,"source":"clob_ws_market","recv_ts_ns":1768250247695211240,"event_type":"price_change","market":"0xe51aa24ab1bbfefce466d642ad98587d13123e4ef95ec9aa73b712e775d4cbba","server_ts_ms":1768250247658,"raw":{"market":"0xe51aa24ab1bbfefce466d642ad98587d13123e4ef95ec9aa73b712e775d4cbba","price_changes":[{"asset_id":"96886111393998001968863279421729456597655847484197549086072988901191634450924","price":"0.95","size":"11.79","side":"SELL","hash":"b6f8f0547d16625d5a2dadc157f92b6688596b64","best_bid":"0.94","best_ask":"0.95"},{"asset_id":"54232589582260339592359130012520874109228367674780084862642636038394766871668","price":"0.05","size":"11.79","side":"BUY","hash":"cba4c4250c2b6035d1925ed6c6945389537ee813","best_bid":"0.05","best_ask":"0.06"}],"timestamp":"1768250247658","event_type":"price_change"}}
{"schema_version":1,"source":"clob_ws_market","recv_ts_ns":1768250247704802861,"event_type":"book","market":"0xe51aa24ab1bbfefce466d642ad98587d13123e4ef95ec9aa73b712e775d4cbba","server_ts_ms":1768250247658,"raw":{"market":"0xe51aa24ab1bbfefce466d642ad98587d13123e4ef95ec9aa73b712e775d4cbba","asset_id":"96886111393998001968863279421729456597655847484197549086072988901191634450924","bids":[{"price":"0.01","size":"24295.73"},{"price":"0.02","size":"7594.51"},{"price":"0.03","size":"5964.69"},{"price":"0.04","size":"5411.4"},{"price":"0.05","size":"5356.39"},{"price":"0.06","size":"5328"},{"price":"0.07","size":"5039.28"},{"price":"0.08","size":"5022.7"},{"price":"0.09","size":"5320.9"},{"price":"0.1","size":"5158.44"},{"price":"0.11","size":"18.3"},{"price":"0.12","size":"30.3"},{"price":"0.13","size":"16.5"},{"price":"0.14","size":"15.8"},{"price":"0.15","size":"104.19"},{"price":"0.16","size":"24.69"},{"price":"0.17","size":"14.19"},{"price":"0.18","size":"13.8"},{"price":"0.19","size":"13.4"},{"price":"0.2","size":"38.1"},{"price":"0.21","size":"12.8"},{"price":"0.22","size":"12.6"},{"price":"0.23","size":"12.3"},{"price":"0.24","size":"22.1"},{"price":"0.25","size":"16.9"},{"price":"0.26","size":"21.8"},{"price":"0.27","size":"11.6"},{"price":"0.28","size":"11.4"},{"price":"0.29","size":"61.3"},{"price":"0.3","size":"26.2"},{"price":"0.31","size":"11.1"},{"price":"0.32","size":"11"},{"price":"0.33","size":"110.9"},{"price":"0.34","size":"10.8"},{"price":"0.35","size":"15.7"},{"price":"0.36","size":"10.6"},{"price":"0.37","size":"10.6"},{"price":"0.38","size":"22.5"},{"price":"0.39","size":"10.5"},{"price":"0.4","size":"45.4"},{"price":"0.41","size":"311.4"},{"price":"0.42","size":"820.82"},{"price":"0.43","size":"826.3"},{"price":"0.44","size":"1062.3"},{"price":"0.45","size":"582.3"},{"price":"0.46","size":"626.2"},{"price":"0.47","size":"562.2"},{"price":"0.48","size":"567.2"},{"price":"0.49","size":"573.2"},{"price":"0.5","size":"917.2"},{"price":"0.51","size":"591.2"},{"price":"0.52","size":"590.2"},{"price":"0.53","size":"567.2"},{"price":"0.54","size":"642.61"},{"price":"0.55","size":"362.97"},{"price":"0.56","size":"341.3"},{"price":"0.57","size":"320.62"},{"price":"0.58","size":"567.3"},{"price":"0.59","size":"562.4"},{"price":"0.6","size":"693.02"},{"price":"0.61","size":"625.5"},{"price":"0.62","size":"700.5"},{"price":"0.63","size":"703.32"},{"price":"0.64","size":"680.6"},{"price":"0.65","size":"536.14"},{"price":"0.66","size":"602.8"},{"price":"0.67","size":"572.9"},{"price":"0.68","size":"573"},{"price":"0.69","size":"595.1"},{"price":"0.7","size":"603.2"},{"price":"0.71","size":"1318.72"},{"price":"0.72","size":"1043.04"},{"price":"0.73","size":"663.6"},{"price":"0.74","size":"911.17"},{"price":"0.75","size":"694.3"},{"price":"0.76","size":"717.6"},{"price":"0.77","size":"1183.3"},{"price":"0.78","size":"1449.6"},{"price":"0.79","size":"1254.75"},{"price":"0.8","size":"1445.08"},{"price":"0.81","size":"1229.8"},{"price":"0.82","size":"1467.57"},{"price":"0.83","size":"1470.51"},{"price":"0.84","size":"1668.59"},{"price":"0.85","size":"1762.5"},{"price":"0.86","size":"1755.6"},{"price":"0.87","size":"1588.93"},{"price":"0.88","size":"2355.4"},{"price":"0.89","size":"2066.7"},{"price":"0.9","size":"3467.84"},{"price":"0.91","size":"3018.44"},{"price":"0.92","size":"2729.36"},{"price":"0.93","size":"1391.82"},{"price":"0.94","size":"1814.21"}],"asks":[{"price":"0.99","size":"21209.86"},{"price":"0.98","size":"5425.25"},{"price":"0.97","size":"1228.6"},{"price":"0.96","size":"1637.5"},{"price":"0.95","size":"11.79"}],"hash":"b6f8f0547d16625d5a2dadc157f92b6688596b64","timestamp":"1768250247658","event_type":"book"}}
{"schema_version":1,"source":"clob_ws_market","recv_ts_ns":1768250247732954841,"event_type":"last_trade_price","market":"0xe51aa24ab1bbfefce466d642ad98587d13123e4ef95ec9aa73b712e775d4cbba","server_ts_ms":1768250247710,"raw":{"market":"0xe51aa24ab1bbfefce466d642ad98587d13123e4ef95ec9aa73b712e775d4cbba","asset_id":"96886111393998001968863279421729456597655847484197549086072988901191634450924","price":"0.95","size":"1.2","fee_rate_bps":"1000","side":"BUY","timestamp":"1768250247710","event_type":"last_trade_price","transaction_hash":"0xaf092458149c802e8354505d899d88be23a66b69775480d1af1f16172b56a0f5"}}
{"schema_version":1,"source":"clob_ws_market","recv_ts_ns":1768250247770861597,"event_type":"price_change","market":"0xe51aa24ab1bbfefce466d642ad98587d13123e4ef95ec9aa73b712e775d4cbba","server_ts_ms":1768250247741,"raw":{"market":"0xe51aa24ab1bbfefce466d642ad98587d13123e4ef95ec9aa73b712e775d4cbba","price_changes":[{"asset_id":"54232589582260339592359130012520874109228367674780084862642636038394766871668","price":"0.05","size":"111.79","side":"BUY","hash":"71d9a5d683089aedb3fb83afa62e00a8dc9a2ede","best_bid":"0.05","best_ask":"0.06"},{"asset_id":"96886111393998001968863279421729456597655847484197549086072988901191634450924","price":"0.95","size":"111.79","side":"SELL","hash":"9b5ca88b73c9470070a17a848938ccdd51af09a4","best_bid":"0.94","best_ask":"0.95"}],"timestamp":"1768250247741","event_type":"price_change"}}
{"schema_version":1,"source":"clob_ws_market","recv_ts_ns":1768250247880715013,"event_type":"price_change","market":"0xe51aa24ab1bbfefce466d642ad98587d13123e4ef95ec9aa73b712e775d4cbba","server_ts_ms":1768250247859,"raw":{"market":"0xe51aa24ab1bbfefce466d642ad98587d13123e4ef95ec9aa73b712e775d4cbba","price_changes":[{"asset_id":"54232589582260339592359130012520874109228367674780084862642636038394766871668","price":"0.01","size":"21178.86","side":"BUY","hash":"3b99ab27f4789209f0efb6cf1d82b9706003a1ef","best_bid":"0.05","best_ask":"0.06"},{"asset_id":"96886111393998001968863279421729456597655847484197549086072988901191634450924","price":"0.99","size":"21178.86","side":"SELL","hash":"432cde4af032d9f4ca2638a664d3e38fa534e8db","best_bid":"0.94","best_ask":"0.95"}],"timestamp":"1768250247859","event_type":"price_change"}}
{"schema_version":1,"source":"clob_ws_market","recv_ts_ns":1768250247904813317,"event_type":"best_bid_ask","market":"0xe51aa24ab1bbfefce466d642ad98587d13123e4ef95ec9aa73b712e775d4cbba","server_ts_ms":1768250247874,"raw":{"market":"0xe51aa24ab1bbfefce466d642ad98587d13123e4ef95ec9aa73b712e775d4cbba","asset_id":"96886111393998001968863279421729456597655847484197549086072988901191634450924","best_bid":"0.94","best_ask":"0.95","spread":"0.01","timestamp":"1768250247874","event_type":"best_bid_ask"}}
{"schema_version":1,"source":"clob_ws_market","recv_ts_ns":1768250247907091128,"event_type":"price_change","market":"0xe51aa24ab1bbfefce466d642ad98587d13123e4ef95ec9aa73b712e775d4cbba","server_ts_ms":1768250247871,"raw":{"market":"0xe51aa24ab1bbfefce466d642ad98587d13123e4ef95ec9aa73b712e775d4cbba","price_changes":[{"asset_id":"54232589582260339592359130012520874109228367674780084862642636038394766871668","price":"0.05","size":"61.79","side":"BUY","hash":"5c786b90d7298a56246a96d20ae6f80b132ac9ab","best_bid":"0.05","best_ask":"0.06"},{"asset_id":"96886111393998001968863279421729456597655847484197549086072988901191634450924","price":"0.95","size":"61.79","side":"SELL","hash":"61b80d75ba0910b1b4cc6ea2d168b4379f3e06b9","best_bid":"0.94","best_ask":"0.95"}],"timestamp":"1768250247871","event_type":"price_change"}}
{"schema_version":1,"source":"clob_ws_market","recv_ts_ns":1768250247914788667,"event_type":"price_change","market":"0xe51aa24ab1bbfefce466d642ad98587d13123e4ef95ec9aa73b712e775d4cbba","server_ts_ms":1768250247871,"raw":{"market":"0xe51aa24ab1bbfefce466d642ad98587d13123e4ef95ec9aa73b712e775d4cbba","price_changes":[{"asset_id":"96886111393998001968863279421729456597655847484197549086072988901191634450924","price":"0.95","size":"61.79","side":"SELL","hash":"61b80d75ba0910b1b4cc6ea2d168b4379f3e06b9","best_bid":"0.94","best_ask":"0.95"},{"asset_id":"54232589582260339592359130012520874109228367674780084862642636038394766871668","price":"0.05","size":"61.79","side":"BUY","hash":"5c786b90d7298a56246a96d20ae6f80b132ac9ab","best_bid":"0.05","best_ask":"0.06"}],"timestamp":"1768250247871","event_type":"price_change"}}
