{"schema_version":1,"source":"clob_ws_market","recv_ts_ns":1768250250513705698,"event_type":"book","market":"0xe51aa24ab1bbfefce466d642ad98587d13123e4ef95ec9aa73b712e775d4cbba","server_ts_ms":1768250250293,"raw":{"market":"0xe51aa24ab1bbfefce466d642ad98587d13123e4ef95ec9aa73b712e775d4cbba","asset_id":"96886111393998001968863279421729456597655847484197549086072988901191634450924","bids":[{"price":"0.01","size":"24275.73"},{"price":"0.02","size":"7594.51"},{"price":"0.03","size":"5964.69"},{"price":"0.04","size":"5411.4"},{"price":"0.05","size":"5356.39"},{"price":"0.06","size":"5328"},{"price":"0.07","size":"5039.28"},{"price":"0.08","size":"5022.7"},{"price":"0.09","size":"5320.9"},{"price":"0.1","size":"5158.44"},{"price":"0.11","size":"18.3"},{"price":"0.12","size":"30.3"},{"price":"0.13","size":"16.5"},{"price":"0.14","size":"15.8"},{"price":"0.15","size":"104.19"},{"price":"0.16","size":"24.69"},{"price":"0.17","size":"14.19"},{"price":"0.18","size":"13.8"},{"price":"0.19","size":"13.4"},{"price":"0.2","size":"38.1"},{"price":"0.21","size":"12.8"},{"price":"0.22","size":"12.6"},{"price":"0.23","size":"12.3"},{"price":"0.24","size":"22.1"},{"price":"0.25","size":"16.9"},{"price":"0.26","size":"21.8"},{"price":"0.27","size":"11.6"},{"price":"0.28","size":"11.4"},{"price":"0.29","size":"61.3"},{"price":"0.3","size":"26.2"},{"price":"0.31","size":"11.1"},{"price":"0.32","size":"11"},{"price":"0.33","size":"110.9"},{"price":"0.34","size":"10.8"},{"price":"0.35","size":"15.7"},{"price":"0.36","size":"10.6"},{"price":"0.37","size":"10.6"},{"price":"0.38","size":"22.5"},{"price":"0.39","size":"10.5"},{"price":"0.4","size":"45.4"},{"price":"0.41","size":"311.4"},{"price":"0.42","size":"820.82"},{"price":"0.43","size":"826.3"},{"price":"0.44","size":"1062.3"},{"price":"0.45","size":"582.3"},{"price":"0.46","size":"626.2"},{"price":"0.47","size":"562.2"},{"price":"0.48","size":"567.2"},{"price":"0.49","size":"573.2"},{"price":"0.5","size":"917.2"},{"price":"0.51","size":"591.2"},{"price":"0.52","size":"590.2"},{"price":"0.53","size":"567.2"},{"price":"0.54","size":"636.61"},{"price":"0.55","size":"368.97"},{"price":"0.56","size":"341.3"},{"price":"0.57","size":"320.62"},{"price":"0.58","size":"567.3"},{"price":"0.59","size":"562.4"},{"price":"0.6","size":"693.02"},{"price":"0.61","size":"625.5"},{"price":"0.62","size":"700.5"},{"price":"0.63","size":"734.32"},{"price":"0.64","size":"680.6"},{"price":"0.65","size":"536.14"},{"price":"0.66","size":"602.8"},{"price":"0.67","size":"572.9"},{"price":"0.68","size":"573"},{"price":"0.69","size":"595.1"},{"price":"0.7","size":"603.2"},{"price":"0.71","size":"1318.72"},{"price":"0.72","size":"1043.04"},{"price":"0.73","size":"663.6"},{"price":"0.74","size":"911.17"},{"price":"0.75","size":"694.3"},{"price":"0.76","size":"717.6"},{"price":"0.77","size":"1183.3"},{"price":"0.78","size":"1449.6"},{"price":"0.79","size":"1254.75"},{"price":"0.8","size":"1445.08"},{"price":"0.81","size":"1229.8"},{"price":"0.82","size":"1467.57"},{"price":"0.83","size":"1470.51"},{"price":"0.84","size":"1668.59"},{"price":"0.85","size":"1762.5"},{"price":"0.86","size":"1755.6"},{"price":"0.87","size":"1588.93"},{"price":"0.88","size":"2355.4"},{"price":"0.89","size":"2066.7"},{"price":"0.9","size":"3467.84"},{"price":"0.91","size":"1623.44"},{"price":"0.92","size":"2724.36"},{"price":"0.93","size":"1530.32"},{"price":"0.94","size":"1176.58"}],"asks":[{"price":"0.99","size":"21094.86"},{"price":"0.98","size":"6493.25"},{"price":"0.97","size":"1260.33"},{"price":"0.96","size":"1775.74"}],"hash":"322008ac984d8d0e617c391f15e6c2da2c6303fe","timestamp":"1768250250293","event_type":"book"}}
{"schema_version":1,"source":"clob_ws_market","recv_ts_ns":1768250250516753724,"event_type":"price_change","market":"0xe51aa24ab1bbfefce466d642ad98587d13123e4ef95ec9aa73b712e775d4cbba","server_ts_ms":1768250250322,"raw":{"market":"0xe51aa24ab1bbfefce466d642ad98587d13123e4ef95ec9aa73b712e775d4cbba","price_changes":[{"asset_id":"96886111393998001968863279421729456597655847484197549086072988901191634450924","price":"0.89","size":"1866.7","side":"BUY","hash":"cf89a775455d996c261bb6ee5c4a00fcf5391836","best_bid":"0.94","best_ask":"0.96"},{"asset_id":"54232589582260339592359130012520874109228367674780084862642636038394766871668","price":"0.11","size":"1866.7","side":"SELL","hash":"9677d822d1a2c2ff424de45701855ecfb80e25a2","best_bid":"0.04","best_ask":"0.06"}],"timestamp":"1768250250322","event_type":"price_change"}}
{"schema_version":1,"source":"clob_ws_market","recv_ts_ns":1768250250520561094,"event_type":"price_change","market":"0xe51aa24ab1bbfefce466d642ad98587d13123e4ef95ec9aa73b712e775d4cbba","server_ts_ms":1768250250323,"raw":{"market":"0xe51aa24ab1bbfefce466d642ad98587d13123e4ef95ec9aa73b712e775d4cbba","price_changes":[{"asset_id":"96886111393998001968863279421729456597655847484197549086072988901191634450924","price":"0.93","size":"1524.82","side":"BUY","hash":"2ae9df02c5d3116edff3a49397d139ea28faf1ef","best_bid":"0.94","best_ask":"0.96"},{"asset_id":"54232589582260339592359130012520874109228367674780084862642636038394766871668","price":"0.07","size":"1524.82","side":"SELL","hash":"c599381977ce5a09b1fa560bec1eb2d6c3cf935c","best_bid":"0.04","best_ask":"0.06"}],"timestamp":"1768250250323","event_type":"price_change"}}
{"schema_version":1,"source":"clob_ws_market","recv_ts_ns":1768250250523711413,"event_type":"price_change","market":"0xe51aa24ab1bbfefce466d642ad98587d13123e4ef95ec9aa73b712e775d4cbba","server_ts_ms":1768250250329,"raw":{"market":"0xe51aa24ab1bbfefce466d642ad98587d13123e4ef95ec9aa73b712e775d4cbba","price_changes":[{"asset_id":"96886111393998001968863279421729456597655847484197549086072988901191634450924","price":"0.93","size":"1519.32","side":"BUY","hash":"c0edfaa4ad76d12ef9a509e4f6ac7acbed3878d9","best_bid":"0.94","best_ask":"0.96"},{"asset_id":"54232589582260339592359130012520874109228367674780084862642636038394766871668","price":"0.07","size":"1519.32","side":"SELL","hash":"90bb3e3171f7e5a0c2b59cafeccf9e0dff33bd0c","best_bid":"0.04","best_ask":"0.06"}],"timestamp":"1768250250329","event_type":"price_change"}}
{"schema_version":1,"source":"clob_ws_market","recv_ts_ns":1768250250529990098,"event_type":"price_change","market":"0xe51aa24ab1bbfefce466d642ad98587d13123e4ef95ec9aa73b712e775d4cbba","server_ts_ms":1768250250335,"raw":{"market":"0xe51aa24ab1bbfefce466d642ad98587d13123e4ef95ec9aa73b712e775d4cbba","price_changes":[{"asset_id":"54232589582260339592359130012520874109228367674780084862642636038394766871668","price":"0.04","size":"1770.74","side":"BUY","hash":"df9780a2555dd638edbc114e227ec9fd743cdf45","best_bid":"0.04","best_ask":"0.06"},{"asset_id":"96886111393998001968863279421729456597655847484197549086072988901191634450924","price":"0.96","size":"1770.74","side":"SELL","hash":"137cc80fdbdf3879d961cac0f9d27c31ca47522f","best_bid":"0.94","best_ask":"0.96"}],"timestamp":"1768250250335","event_type":"price_change"}}
{"schema_version":1,"source":"clob_ws_market","recv_ts_ns":1768250250532926184,"event_type":"price_change","market":"0xe51aa24ab1bbfefce466d642ad98587d13123e4ef95ec9aa73b712e775d4cbba","server_ts_ms":1768250250338,"raw":{"market":"0xe51aa24ab1bbfefce466d642ad98587d13123e4ef95ec9aa73b712e775d4cbba","price_changes":[{"asset_id":"96886111393998001968863279421729456597655847484197549086072988901191634450924","price":"0.9","size":"3667.84","side":"BUY","hash":"2995fd6ef175285be84a9a5665929b7ad917309b","best_bid":"0.94","best_ask":"0.96"},{"asset_id":"54232589582260339592359130012520874109228367674780084862642636038394766871668","price":"0.1","size":"3667.84","side":"SELL","hash":"7192c23e0d75e569de7422c4d439ad9c521c946d","best_bid":"0.04","best_ask":"0.06"}],"timestamp":"1768250250338","event_type":"price_change"}}
{"schema_version":1,"source":"clob_ws_market","recv_ts_ns":1768250250535887312,"event_type":"last_trade_price","market":"0xe51aa24ab1bbfefce466d642ad98587d13123e4ef95ec9aa73b712e775d4cbba","server_ts_ms":1768250250341,"raw":{"market":"0xe51aa24ab1bbfefce466d642ad98587d13123e4ef95ec9aa73b712e775d4cbba","asset_id":"96886111393998001968863279421729456597655847484197549086072988901191634450924","price":"0.95","size":"9","fee_rate_bps":"1000","side":"BUY","timestamp":"1768250250341","event_type":"last_trade_price","transaction_hash":"0x3fa7e1c91f5d60f3d7112b2aa217a3302092bad544dc561c7ed154db6204dc5a"}}
{"schema_version":1,"source":"clob_ws_market","recv_ts_ns":1768250250538475237,"event_type":"price_change","market":"0xe51aa24ab1bbfefce466d642ad98587d13123e4ef95ec9aa73b712e775d4cbba","server_ts_ms":1768250250351,"raw":{"market":"0xe51aa24ab1bbfefce466d642ad98587d13123e4ef95ec9aa73b712e775d4cbba","price_changes":[{"asset_id":"54232589582260339592359130012520874109228367674780084862642636038394766871668","price":"0.02","size":"6443.25","side":"BUY","hash":"02fe6762f0b95c58b0fc1a5716e51888439c4563","best_bid":"0.04","best_ask":"0.06"},{"asset_id":"96886111393998001968863279421729456597655847484197549086072988901191634450924","price":"0.98","size":"6443.25","side":"SELL","hash":"f4f880e824157bb8c4960aaffde5aaf7c70a84a8","best_bid":"0.94","best_ask":"0.96"}],"timestamp":"1768250250351","event_type":"price_change"}}
{"schema_version":1,"source":"clob_ws_market","recv_ts_ns":1768250250541779491,"event_type":"price_change","market":"0xe51aa24ab1bbfefce466d642ad98587d13123e4ef95ec9aa73b712e775d4cbba","server_ts_ms":1768250250366,"raw":{"market":"0xe51aa24ab1bbfefce466d642ad98587d13123e4ef95ec9aa73b712e775d4cbba","price_changes":[{"asset_id":"96886111393998001968863279421729456597655847484197549086072988901191634450924","price":"0.94","size":"1182.08","side":"BUY","hash":"90433ec3b6138e217b03fd523bb4ed256f42cffc","best_bid":"0.94","best_ask":"0.96"},{"asset_id":"54232589582260339592359130012520874109228367674780084862642636038394766871668","price":"0.06","size":"1182.08","side":"SELL","hash":"a0148146a2ef45e6b6c902a523e55c0a5fb94ad0","best_bid":"0.04","best_ask":"0.06"}],"timestamp":"1768250250366","event_type":"price_change"}}
{"schema_version":1,"source":"clob_ws_market","recv_ts_ns":1768250250544788488,"event_type":"price_change","market":"0xe51aa24ab1bbfefce466d642ad98587d13123e4ef95ec9aa73b712e775d4cbba","server_ts_ms":1768250250374,"raw":{"market":"0xe51aa24ab1bbfefce466d642ad98587d13123e4ef95ec9aa73b712e775d4cbba","price_changes":[{"asset_id":"96886111393998001968863279421729456597655847484197549086072988901191634450924","price":"0.94","size":"1187.58","side":"BUY","hash":"0d0f25607b38a92f268318232d5af86daa868648","best_bid":"0.94","best_ask":"0.96"},{"asset_id":"54232589582260339592359130012520874109228367674780084862642636038394766871668","price":"0.06","size":"1187.58","side":"SELL","hash":"fa9d983a7de2c137244848e332685ef1c2696a3f","best_bid":"0.04","best_ask":"0.06"}],"timestamp":"1768250250374","event_type":"price_change"}}
{"schema_version":1,"source":"clob_ws_market","recv_ts_ns":1768250250553535180,"event_type":"price_change","market":"0xe51aa24ab1bbfefce466d642ad98587d13123e4ef95ec9aa73b712e775d4cbba","server_ts_ms":1768250250409,"raw":{"market":"0xe51aa24ab1bbfefce466d642ad98587d13123e4ef95ec9aa73b712e775d4cbba","price_changes":[{"asset_id":"96886111393998001968863279421729456597655847484197549086072988901191634450924","price":"0.98","size":"6468.25","side":"SELL","hash":"31b874d41e022f5223626b5254fb470d5e56b0b3","best_bid":"0.94","best_ask":"0.96"},{"asset_id":"54232589582260339592359130012520874109228367674780084862642636038394766871668","price":"0.02","size":"6468.25","side":"BUY","hash":"d7bfa2a0925e99e8ad887a6a3856d7f95e1f253c","best_bid":"0.04","best_ask":"0.06"}],"timestamp":"1768250250409","event_type":"price_change"}}
{"schema_version":1,"source":"clob_ws_market","recv_ts_ns":1768250250558235599,"event_type":"price_change","market":"0xe51aa24ab1bbfefce466d642ad98587d13123e4ef95ec9aa73b712e775d4cbba","server_ts_ms":1768250250411,"raw":{"market":"0xe51aa24ab1bbfefce466d642ad98587d13123e4ef95ec9aa73b712e775d4cbba","price_changes":[{"asset_id":"96886111393998001968863279421729456597655847484197549086072988901191634450924","price":"0.99","size":"21069.86","side":"SELL","hash":"6144cdf8ee6423c80d689c1a6284f2d1cac20f87","best_bid":"0.94","best_ask":"0.96"},{"asset_id":"54232589582260339592359130012520874109228367674780084862642636038394766871668","price":"0.01","size":"21069.86","side":"BUY","hash":"8fdd4de8a56e9da4eea3a81c411df961cd9ea988","best_bid":"0.04","best_ask":"0.06"}],"timestamp":"1768250250411","event_type":"price_change"}}
{"schema_version":1,"source":"clob_ws_market","recv_ts_ns":1768250250579063271,"event_type":"price_change","market":"0xe51aa24ab1bbfefce466d642ad98587d13123e4ef95ec9aa73b712e775d4cbba","server_ts_ms":1768250250526,"raw":{"market":"0xe51aa24ab1bbfefce466d642ad98587d13123e4ef95ec9aa73b712e775d4cbba","price_changes":[{"asset_id":"54232589582260339592359130012520874109228367674780084862642636038394766871668","price":"0.01","size":"21037.86","side":"BUY","hash":"1527dead951a2c2109d47efbe942a962405146ed","best_bid":"0.04","best_ask":"0.06"},{"asset_id":"96886111393998001968863279421729456597655847484197549086072988901191634450924","price":"0.99","size":"21037.86","side":"SELL","hash":"1b4b1255ec4f552fb61dcb4ca801253ae3468a46","best_bid":"0.94","best_ask":"0.96"}],"timestamp":"1768250250526","event_type":"price_change"}}
{"schema_version":1,"source":"clob_ws_market","recv_ts_ns":1768250250586497423,"event_type":"price_change","market":"0xe51aa24ab1bbfefce466d642ad98587d13123e4ef95ec9aa73b712e775d4cbba","server_ts_ms":1768250250565,"raw":{"market":"0xe51aa24ab1bbfefce466d642ad98587d13123e4ef95ec9aa73b712e775d4cbba","price_changes":[{"asset_id":"54232589582260339592359130012520874109228367674780084862642636038394766871668","price":"0.01","size":"21071.86","side":"BUY","hash":"41943c7bab54d5b532271872c083815b8106e3f1","best_bid":"0.04","best_ask":"0.06"},{"asset_id":"96886111393998001968863279421729456597655847484197549086072988901191634450924","price":"0.99","size":"21071.86","side":"SELL","hash":"255f8554efea0323f661c8926b9b0262bfb3d50b","best_bid":"0.94","best_ask":"0.96"}],"timestamp":"1768250250565","event_type":"price_change"}}
{"schema_version":1,"source":"clob_ws_market","recv_ts_ns":1768250250706395517,"event_type":"price_change","market":"0xe51aa24ab1bbfefce466d642ad98587d13123e4ef95ec9aa73b712e775d4cbba","server_ts_ms":1768250250685,"raw":{"market":"0xe51aa24ab1bbfefce466d642ad98587d13123e4ef95ec9aa73b712e775d4cbba","price_changes":[{"asset_id":"54232589582260339592359130012520874109228367674780084862642636038394766871668","price":"0.01","size":"21037.86","side":"BUY","hash":"56cc83f1207b4f70f34ce7e1e91674e040d8a47a","best_bid":"0.04","best_ask":"0.06"},{"asset_id":"96886111393998001968863279421729456597655847484197549086072988901191634450924","price":"0.99","size":"21037.86","side":"SELL","hash":"e58b31c3509d4c4d33324fe587d67bf62b609b57","best_bid":"0.94","best_ask":"0.96"}],"timestamp":"1768250250685","event_type":"price_change"}}
{"schema_version":1,"source":"clob_ws_market","recv_ts_ns":1768250250766291284,"event_type":"price_change","market":"0xe51aa24ab1bbfefce466d642ad98587d13123e4ef95ec9aa73b712e775d4cbba","server_ts_ms":1768250250745,"raw":{"market":"0xe51aa24ab1bbfefce466d642ad98587d13123e4ef95ec9aa73b712e775d4cbba","price_changes":[{"asset_id":"54232589582260339592359130012520874109228367674780084862642636038394766871668","price":"0.01","size":"21071.86","side":"BUY","hash":"4e0ed65b8ce40932fbbe28c62be96cab4597b6ea","best_bid":"0.04","best_ask":"0.06"},{"asset_id":"96886111393998001968863279421729456597655847484197549086072988901191634450924","price":"0.99","size":"21071.86","side":"SELL","hash":"ae52d9675483d0d4de9b9c24696a6d0f084e34ec","best_bid":"0.94","best_ask":"0.96"}],"timestamp":"1768250250745","event_type":"price_change"}}
{"schema_version":1,"source":"clob_ws_market","recv_ts_ns":1768250250777610192,"event_type":"best_bid_ask","market":"0xe51aa24ab1bbfefce466d642ad98587d13123e4ef95ec9aa73b712e775d4cbba","server_ts_ms":1768250250754,"raw":{"market":"0xe51aa24ab1bbfefce466d642ad98587d13123e4ef95ec9aa73b712e775d4cbba","asset_id":"96886111393998001968863279421729456597655847484197549086072988901191634450924","best_bid":"0.94","best_ask":"0.95","spread":"0.01","timestamp":"1768250250754","event_type":"best_bid_ask"}}
{"schema_version":1,"source":"clob_ws_market","recv_ts_ns":1768250250780642856,"event_type":"price_change","market":"0xe51aa24ab1bbfefce466d642ad98587d13123e4ef95ec9aa73b712e775d4cbba","server_ts_ms":1768250250753,"raw":{"market":"0xe51aa24ab1bbfefce466d642ad98587d13123e4ef95ec9aa73b712e775d4cbba","price_changes":[{"asset_id":"54232589582260339592359130012520874109228367674780084862642636038394766871668","price":"0.05","size":"100","side":"BUY","hash":"287c87d158733dd55ffcc47c3ce5b27d4f1ab234","best_bid":"0.05","best_ask":"0.06"},{"asset_id":"96886111393998001968863279421729456597655847484197549086072988901191634450924","price":"0.95","size":"100","side":"SELL","hash":"b7782dee0d83165f2df6574983446fde8646e790","best_bid":"0.94","best_ask":"0.95"}],"timestamp":"1768250250753","event_type":"price_change"}}
{"schema_version":1,"source":"clob_ws_market","recv_ts_ns":1768250250804250465,"event_type":"price_change","market":"0xe51aa24ab1bbfefce466d642ad98587d13123e4ef95ec9aa73b712e775d4cbba","server_ts_ms":1768250250781,"raw":{"market":"0xe51aa24ab1bbfefce466d642ad98587d13123e4ef95ec9aa73b712e775d4cbba","price_changes":[{"asset_id":"96886111393998001968863279421729456597655847484197549086072988901191634450924","price":"0.94","size":"1182.08","side":"BUY","hash":"b8885b73bec04757905818e2e08cf5fb5e6b5c56","best_bid":"0.94","best_ask":"0.95"},{"asset_id":"54232589582260339592359130012520874109228367674780084862642636038394766871668","price":"0.06","size":"1182.08","side":"SELL","hash":"ac45e84252cbbed7f25afbafeb68960a032ecf7f","best_bid":"0.05","best_ask":"0.06"}],"timestamp":"1768250250781","event_type":"price_change"}}
{"schema_version":1,"source":"clob_ws_market","recv_ts_ns":1768250250810403903,"event_type":"price_change","market":"0xe51aa24ab1bbfefce466d642ad98587d13123e4ef95ec9aa73b712e775d4cbba","server_ts_ms":1768250250786,"raw":{"market":"0xe51aa24ab1bbfefce466d642ad98587d13123e4ef95ec9aa73b712e775d4cbba","price_changes":[{"asset_id":"96886111393998001968863279421729456597655847484197549086072988901191634450924","price":"0.94","size":"1176.58","side":"BUY","hash":"c1477a97849242a3d1c529e531d178d5693aa59c","best_bid":"0.94","best_ask":"0.95"},{"asset_id":"54232589582260339592359130012520874109228367674780084862642636038394766871668","price":"0.06","size":"1176.58","side":"SELL","hash":"fb4f57442cee3cd3eb3e533130957e0ab82c24b9","best_bid":"0.05","best_ask":"0.06"}],"timestamp":"1768250250786","event_type":"price_change"}}
{"schema_version":1,"source":"clob_ws_market","recv_ts_ns":1768250250839618048,"event_type":"price_change","market":"0xe51aa24ab1bbfefce466d642ad98587d13123e4ef95ec9aa73b712e775d4cbba","server_ts_ms":1768250250816,"raw":{"market":"0xe51aa24ab1bbfefce466d642ad98587d13123e4ef95ec9aa73b712e775d4cbba","price_changes":[{"asset_id":"54232589582260339592359130012520874109228367674780084862642636038394766871668","price":"0.04","size":"1775.74","side":"BUY","hash":"765db60fe655370cec78c8b5bdf1c8323b5662ec","best_bid":"0.05","best_ask":"0.06"},{"asset_id":"96886111393998001968863279421729456597655847484197549086072988901191634450924","price":"0.96","size":"1775.74","side":"SELL","hash":"0edf0adf99a0b5576f7ce48011d681bef41efca2","best_bid":"0.94","best_ask":"0.95"}],"timestamp":"1768250250816","event_type":"price_change"}}
{"schema_version":1,"source":"clob_ws_market","recv_ts_ns":1768250250853535228,"event_type":"price_change","market":"0xe51aa24ab1bbfefce466d642ad98587d13123e4ef95ec9aa73b712e775d4cbba","server_ts_ms":1768250250827,"raw":{"market":"0xe51aa24ab1bbfefce466d642ad98587d13123e4ef95ec9aa73b712e775d4cbba","price_changes":[{"asset_id":"96886111393998001968863279421729456597655847484197549086072988901191634450924","price":"0.93","size":"1524.82","side":"BUY","hash":"6d9a1c4fee6f7ca39cfff250610a346dde55618d","best_bid":"0.94","best_ask":"0.95"},{"asset_id":"54232589582260339592359130012520874109228367674780084862642636038394766871668","price":"0.07","size":"1524.82","side":"SELL","hash":"1e70e1095969ec69020d495ab8505e633dae4fea","best_bid":"0.05","best_ask":"0.06"}],"timestamp":"1768250250827","event_type":"price_change"}}
{"schema_version":1,"source":"clob_ws_market","recv_ts_ns":1768250250917027400,"event_type":"price_change","market":"0xe51aa24ab1bbfefce466d642ad98587d13123e4ef95ec9aa73b712e775d4cbba","server_ts_ms":1768250250855,"raw":{"market":"0xe51aa24ab1bbfefce466d642ad98587d13123e4ef95ec9aa73b712e775d4cbba","price_changes":[{"asset_id":"96886111393998001968863279421729456597655847484197549086072988901191634450924","price":"0.93","size":"1530.32","side":"BUY","hash":"fef62935102899c864c7be9d0207d7a461b6a64f","best_bid":"0.94","best_ask":"0.95"},{"asset_id":"54232589582260339592359130012520874109228367674780084862642636038394766871668","price":"0.07","size":"1530.32","side":"SELL","hash":"da427ddf653b080d70a08fcb145c12dec3148fc6","best_bid":"0.05","best_ask":"0.06"}],"timestamp":"1768250250855","event_type":"price_change"}}
{"schema_version":1,"source":"clob_ws_market","recv_ts_ns":1768250250958083213,"event_type":"price_change","market":"0xe51aa24ab1bbfefce466d642ad98587d13123e4ef95ec9aa73b712e775d4cbba","server_ts_ms":1768250250899,"raw":{"market":"0xe51aa24ab1bbfefce466d642ad98587d13123e4ef95ec9aa73b712e775d4cbba","price_changes":[{"asset_id":"54232589582260339592359130012520874109228367674780084862642636038394766871668","price":"0.06","size":"1156.58","side":"SELL","hash":"1bd7434ebaa2d34102417ec7c0d4f4b7bfebc8f1","best_bid":"0.05","best_ask":"0.06"},{"asset_id":"96886111393998001968863279421729456597655847484197549086072988901191634450924","price":"0.94","size":"1156.58","side":"BUY","hash":"af24c85f5c48aa455bfd0837bd98d6b4879841cb","best_bid":"0.94","best_ask":"0.95"}],"timestamp":"1768250250899","event_type":"price_change"}}
{"schema_version":1,"source":"clob_ws_market","recv_ts_ns":1768250250970232953,"event_type":"price_change","market":"0xe51aa24ab1bbfefce466d642ad98587d13123e4ef95ec9aa73b712e775d4cbba","server_ts_ms":1768250250935,"raw":{"market":"0xe51aa24ab1bbfefce466d642ad98587d13123e4ef95ec9aa73b712e775d4cbba","price_changes":[{"asset_id":"54232589582260339592359130012520874109228367674780084862642636038394766871668","price":"0.06","size":"1176.58","side":"SELL","hash":"ef790c724952bb5bf90ead505ee46d8c875d1c52","best_bid":"0.05","best_ask":"0.06"},{"asset_id":"96886111393998001968863279421729456597655847484197549086072988901191634450924","price":"0.94","size":"1176.58","side":"BUY","hash":"b767f2cf1ab67f51dc5c4d3e92b2d7440dc4dfab","best_bid":"0.94","best_ask":"0.95"}],"timestamp":"1768250250935","event_type":"price_change"}}
{"schema_version":1,"source":"clob_ws_market","recv_ts_ns":1768250250996098373,"event_type":"best_bid_ask","market":"0xe51aa24ab1bbfefce466d642ad98587d13123e4ef95ec9aa73b712e775d4cbba","server_ts_ms":1768250250967,"raw":{"market":"0xe51aa24ab1bbfefce466d642ad98587d13123e4ef95ec9aa73b712e775d4cbba","asset_id":"96886111393998001968863279421729456597655847484197549086072988901191634450924","best_bid":"0.94","best_ask":"0.96","spread":"0.02","timestamp":"1768250250967","event_type":"best_bid_ask"}}
{"schema_version":1,"source":"clob_ws_market","recv_ts_ns":1768250250997910812,"event_type":"price_change","market":"0xe51aa24ab1bbfefce466d642ad98587d13123e4ef95ec9aa73b712e775d4cbba","server_ts_ms":1768250250967,"raw":{"market":"0xe51aa24ab1bbfefce466d642ad98587d13123e4ef95ec9aa73b712e775d4cbba","price_changes":[{"asset_id":"54232589582260339592359130012520874109228367674780084862642636038394766871668","price":"0.05","size":"0","side":"BUY","hash":"bf5dfc97cc91a77ebd61bed02fb2b3f445ebcda6","best_bid":"0.04","best_ask":"0.06"},{"asset_id":"96886111393998001968863279421729456597655847484197549086072988901191634450924","price":"0.95","size":"0","side":"SELL","hash":"5ad9423a885cbc458cfafe31482dd183ece45eed","best_bid":"0.94","best_ask":"0.96"}],"timestamp":"1768250250967","event_type":"price_change"}}
{"schema_version":1,"source":"clob_ws_market","recv_ts_ns":1768250251001620983,"event_type":"price_change","market":"0xe51aa24ab1bbfefce466d642ad98587d13123e4ef95ec9aa73b712e775d4cbba","server_ts_ms":1768250250972,"raw":{"market":"0xe51aa24ab1bbfefce466d642ad98587d13123e4ef95ec9aa73b712e775d4cbba","price_changes":[{"asset_id":"54232589582260339592359130012520874109228367674780084862642636038394766871668","price":"0.04","size":"1770.74","side":"BUY","hash":"741f0e02176f64e797dbe601c1dd1005a85e862b","best_bid":"0.04","best_ask":"0.06"},{"asset_id":"96886111393998001968863279421729456597655847484197549086072988901191634450924","price":"0.96","size":"1770.74","side":"SELL","hash":"0da025864873c7d35d8a694d77267fe59c0feab9","best_bid":"0.94","best_ask":"0.96"}],"timestamp":"1768250250972","event_type":"price_change"}}
{"schema_version":1,"source":"clob_ws_market","recv_ts_ns":1768250251013707965,"event_type":"price_change","market":"0xe51aa24ab1bbfefce466d642ad98587d13123e4ef95ec9aa73b712e775d4cbba","server_ts_ms":1768250250992,"raw":{"market":"0xe51aa24ab1bbfefce466d642ad98587d13123e4ef95ec9aa73b712e775d4cbba","price_changes":[{"asset_id":"96886111393998001968863279421729456597655847484197549086072988901191634450924","price":"0.93","size":"1524.82","side":"BUY","hash":"aae80bb231eeed013d3ca89444cc97f097fd5b8c","best_bid":"0.94","best_ask":"0.96"},{"asset_id":"54232589582260339592359130012520874109228367674780084862642636038394766871668","price":"0.07","size":"1524.82","side":"SELL","hash":"6b1d29774a79865e62ad60a20e4b74feb4589757","best_bid":"0.04","best_ask":"0.06"}],"timestamp":"1768250250992","event_type":"price_change"}}
{"schema_version":1,"source":"clob_ws_market","recv_ts_ns":1768250251016890929,"event_type":"price_change","market":"0xe51aa24ab1bbfefce466d642ad98587d13123e4ef95ec9aa73b712e775d4cbba","server_ts_ms":1768250250994,"raw":{"market":"0xe51aa24ab1bbfefce466d642ad98587d13123e4ef95ec9aa73b712e775d4cbba","price_changes":[{"asset_id":"96886111393998001968863279421729456597655847484197549086072988901191634450924","price":"0.93","size":"1519.32","side":"BUY","hash":"d6d886e57fe085455ed9a22c5f6f23fb08c8c206","best_bid":"0.94","best_ask":"0.96"},{"asset_id":"54232589582260339592359130012520874109228367674780084862642636038394766871668","price":"0.07","size":"1519.32","side":"SELL","hash":"8862749aebba30f85a63cb0bf9fa2a779795ed63","best_bid":"0.04","best_ask":"0.06"}],"timestamp":"1768250250994","event_type":"price_change"}}
{"schema_version":1,"source":"clob_ws_market","recv_ts_ns":1768250251037063525,"event_type":"price_change","market":"0xe51aa24ab1bbfefce466d642ad98587d13123e4ef95ec9aa73b712e775d4cbba","server_ts_ms":1768250251004,"raw":{"market":"0xe51aa24ab1bbfefce466d642ad98587d13123e4ef95ec9aa73b712e775d4cbba","price_changes":[{"asset_id":"54232589582260339592359130012520874109228367674780084862642636038394766871668","price":"0.02","size":"6368.25","side":"BUY","hash":"d7348284c0be92c8b3103efcadbeb7d3ddc509a5","best_bid":"0.04","best_ask":"0.06"},{"asset_id":"96886111393998001968863279421729456597655847484197549086072988901191634450924","price":"0.98","size":"6368.25","side":"SELL","hash":"1fc52f777d7a92bb2b2a71b204748c5b5d88a351","best_bid":"0.94","best_ask":"0.96"}],"timestamp":"1768250251004","event_type":"price_change"}}
{"schema_version":1,"source":"clob_ws_market","recv_ts_ns":1768250251057309937,"event_type":"price_change","market":"0xe51aa24ab1bbfefce466d642ad98587d13123e4ef95ec9aa73b712e775d4cbba","server_ts_ms":1768250251022,"raw":{"market":"0xe51aa24ab1bbfefce466d642ad98587d13123e4ef95ec9aa73b712e775d4cbba","price_changes":[{"asset_id":"96886111393998001968863279421729456597655847484197549086072988901191634450924","price":"0.94","size":"1182.08","side":"BUY","hash":"92d5f535ac987b67fbb04325da680d8a82e0338e","best_bid":"0.94","best_ask":"0.96"},{"asset_id":"54232589582260339592359130012520874109228367674780084862642636038394766871668","price":"0.06","size":"1182.08","side":"SELL","hash":"cb165ca9aa05d5d3cd97074268acab9a13d0e758","best_bid":"0.04","best_ask":"0.06"}],"timestamp":"1768250251022","event_type":"price_change"}}
{"schema_version":1,"source":"clob_ws_market","recv_ts_ns":1768250251062462749,"event_type":"price_change","market":"0xe51aa24ab1bbfefce466d642ad98587d13123e4ef95ec9aa73b712e775d4cbba","server_ts_ms":1768250251024,"raw":{"market":"0xe51aa24ab1bbfefce466d642ad98587d13123e4ef95ec9aa73b712e775d4cbba","price_changes":[{"asset_id":"96886111393998001968863279421729456597655847484197549086072988901191634450924","price":"0.94","size":"1187.58","side":"BUY","hash":"2094ef7899152bf313833cd3b321aebf07a1efee","best_bid":"0.94","best_ask":"0.96"},{"asset_id":"54232589582260339592359130012520874109228367674780084862642636038394766871668","price":"0.06","size":"1187.58","side":"SELL","hash":"08718ab2ef09d98c1192303a0c2dcb97b9004d45","best_bid":"0.04","best_ask":"0.06"}],"timestamp":"1768250251024","event_type":"price_change"}}
{"schema_version":1,"source":"clob_ws_market","recv_ts_ns":1768250251068008856,"event_type":"price_change","market":"0xe51aa24ab1bbfefce466d642ad98587d13123e4ef95ec9aa73b712e775d4cbba","server_ts_ms":1768250251042,"raw":{"market":"0xe51aa24ab1bbfefce466d642ad98587d13123e4ef95ec9aa73b712e775d4cbba","price_changes":[{"asset_id":"54232589582260339592359130012520874109228367674780084862642636038394766871668","price":"0.02","size":"6468.25","side":"BUY","hash":"2fb03da8f47d1ead884d523cb9ac0ca23714c5ed","best_bid":"0.04","best_ask":"0.06"},{"asset_id":"96886111393998001968863279421729456597655847484197549086072988901191634450924","price":"0.98","size":"6468.25","side":"SELL","hash":"635bc4b03c17fe9e7f8b5284bce87e6cdc9a05b5","best_bid":"0.94","best_ask":"0.96"}],"timestamp":"1768250251042","event_type":"price_change"}}
{"schema_version":1,"source":"clob_ws_market","recv_ts_ns":1768250251083268510,"event_type":"best_bid_ask","market":"0xe51aa24ab1bbfefce466d642ad98587d13123e4ef95ec9aa73b712e775d4cbba","server_ts_ms":1768250251055,"raw":{"market":"0xe51aa24ab1bbfefce466d642ad98587d13123e4ef95ec9aa73b712e775d4cbba","asset_id":"96886111393998001968863279421729456597655847484197549086072988901191634450924","best_bid":"0.94","best_ask":"0.96","spread":"0.02","timestamp":"1768250251055","event_type":"best_bid_ask"}}
{"schema_version":1,"source":"clob_ws_market","recv_ts_ns":1768250251088718037,"event_type":"price_change","market":"0xe51aa24ab1bbfefce466d642ad98587d13123e4ef95ec9aa73b712e775d4cbba","server_ts_ms":1768250251053,"raw":{"market":"0xe51aa24ab1bbfefce466d642ad98587d13123e4ef95ec9aa73b712e775d4cbba","price_changes":[{"asset_id":"54232589582260339592359130012520874109228367674780084862642636038394766871668","price":"0.04","size":"1767.74","side":"BUY","hash":"f97885018acb9425d718990e54eef722dce88053","best_bid":"0.04","best_ask":"0.06"},{"asset_id":"96886111393998001968863279421729456597655847484197549086072988901191634450924","price":"0.96","size":"1767.74","side":"SELL","hash":"207a495db261a6d924b435be7021a300a3bfe37e","best_bid":"0.94","best_ask":"0.96"}],"timestamp":"1768250251053","event_type":"price_change"}}
{"schema_version":1,"source":"clob_ws_market","recv_ts_ns":1768250251106737946,"event_type":"book","market":"0xe51aa24ab1bbfefce466d642ad98587d13123e4ef95ec9aa73b712e775d4cbba","server_ts_ms":1768250251053,"raw":{"market":"0xe51aa24ab1bbfefce466d642ad98587d13123e4ef95ec9aa73b712e775d4cbba","asset_id":"96886111393998001968863279421729456597655847484197549086072988901191634450924","bids":[{"price":"0.01","size":"24275.73"},{"price":"0.02","size":"7594.51"},{"price":"0.03","size":"5964.69"},{"price":"0.04","size":"5411.4"},{"price":"0.05","size":"5356.39"},{"price":"0.06","size":"5328"},{"price":"0.07","size":"5039.28"},{"price":"0.08","size":"5022.7"},{"price":"0.09","size":"5320.9"},{"price":"0.1","size":"5158.44"},{"price":"0.11","size":"18.3"},{"price":"0.12","size":"30.3"},{"price":"0.13","size":"16.5"},{"price":"0.14","size":"15.8"},{"price":"0.15","size":"104.19"},{"price":"0.16","size":"24.69"},{"price":"0.17","size":"14.19"},{"price":"0.18","size":"13.8"},{"price":"0.19","size":"13.4"},{"price":"0.2","size":"38.1"},{"price":"0.21","size":"12.8"},{"price":"0.22","size":"12.6"},{"price":"0.23","size":"12.3"},{"price":"0.24","size":"22.1"},{"price":"0.25","size":"16.9"},{"price":"0.26","size":"21.8"},{"price":"0.27","size":"11.6"},{"price":"0.28","size":"11.4"},{"price":"0.29","size":"61.3"},{"price":"0.3","size":"26.2"},{"price":"0.31","size":"11.1"},{"price":"0.32","size":"11"},{"price":"0.33","size":"110.9"},{"price":"0.34","size":"10.8"},{"price":"0.35","size":"15.7"},{"price":"0.36","size":"10.6"},{"price":"0.37","size":"10.6"},{"price":"0.38","size":"22.5"},{"price":"0.39","size":"10.5"},{"price":"0.4","size":"45.4"},{"price":"0.41","size":"311.4"},{"price":"0.42","size":"820.82"},{"price":"0.43","size":"826.3"},{"price":"0.44","size":"1062.3"},{"price":"0.45","size":"582.3"},{"price":"0.46","size":"626.2"},{"price":"0.47","size":"562.2"},{"price":"0.48","size":"567.2"},{"price":"0.49","size":"573.2"},{"price":"0.5","size":"917.2"},{"price":"0.51","size":"591.2"},{"price":"0.52","size":"590.2"},{"price":"0.53","size":"567.2"},{"price":"0.54","size":"636.61"},{"price":"0.55","size":"368.97"},{"price":"0.56","size":"341.3"},{"price":"0.57","size":"320.62"},{"price":"0.58","size":"567.3"},{"price":"0.59","size":"562.4"},{"price":"0.6","size":"693.02"},{"price":"0.61","size":"625.5"},{"price":"0.62","size":"700.5"},{"price":"0.63","size":"734.32"},{"price":"0.64","size":"680.6"},{"price":"0.65","size":"536.14"},{"price":"0.66","size":"602.8"},{"price":"0.67","size":"572.9"},{"price":"0.68","size":"573"},{"price":"0.69","size":"595.1"},{"price":"0.7","size":"603.2"},{"price":"0.71","size":"1318.72"},{"price":"0.72","size":"1043.04"},{"price":"0.73","size":"663.6"},{"price":"0.74","size":"911.17"},{"price":"0.75","size":"694.3"},{"price":"0.76","size":"717.6"},{"price":"0.77","size":"1183.3"},{"price":"0.78","size":"1449.6"},{"price":"0.79","size":"1254.75"},{"price":"0.8","size":"1445.08"},{"price":"0.81","size":"1229.8"},{"price":"0.82","size":"1467.57"},{"price":"0.83","size":"1470.51"},{"price":"0.84","size":"1668.59"},{"price":"0.85","size":"1762.5"},{"price":"0.86","size":"1755.6"},{"price":"0.87","size":"1588.93"},{"price":"0.88","size":"2355.4"},{"price":"0.89","size":"1866.7"},{"price":"0.9","size":"3667.84"},{"price":"0.91","size":"1623.44"},{"price":"0.92","size":"2724.36"},{"price":"0.93","size":"1519.32"},{"price":"0.94","size":"1187.58"}],"asks":[{"price":"0.99","size":"21071.86"},{"price":"0.98","size":"6468.25"},{"price":"0.97","size":"1260.33"},{"price":"0.96","size":"1767.74"}],"hash":"207a495db261a6d924b435be7021a300a3bfe37e","timestamp":"1768250251053","event_type":"book"}}
{"schema_version":1,"source":"clob_ws_market","recv_ts_ns":1768250251111751600,"event_type":"last_trade_price","market":"0xe51aa24ab1bbfefce466d642ad98587d13123e4ef95ec9aa73b712e775d4cbba","server_ts_ms":1768250251084,"raw":{"market":"0xe51aa24ab1bbfefce466d642ad98587d13123e4ef95ec9aa73b712e775d4cbba","asset_id":"96886111393998001968863279421729456597655847484197549086072988901191634450924","price":"0.96","size":"3","fee_rate_bps":"1000","side":"BUY","timestamp":"1768250251084","event_type":"last_trade_price","transaction_hash":"0xfd3bec4ddf65585492387e9f75827823fddd4058579ea61e5f8ea4a940a5bc29"}}
{"schema_version":1,"source":"clob_ws_market","recv_ts_ns":1768250251245283319,"event_type":"best_bid_ask","market":"0xe51aa24ab1bbfefce466d642ad98587d13123e4ef95ec9aa73b712e775d4cbba","server_ts_ms":1768250251175,"raw":{"market":"0xe51aa24ab1bbfefce466d642ad98587d13123e4ef95ec9aa73b712e775d4cbba","asset_id":"96886111393998001968863279421729456597655847484197549086072988901191634450924","best_bid":"0.94","best_ask":"0.96","spread":"0.02","timestamp":"1768250251175","event_type":"best_bid_ask"}}
{"schema_version":1,"source":"clob_ws_market","recv_ts_ns":1768250251248207680,"event_type":"price_change","market":"0xe51aa24ab1bbfefce466d642ad98587d13123e4ef95ec9aa73b712e775d4cbba","server_ts_ms":1768250251173,"raw":{"market":"0xe51aa24ab1bbfefce466d642ad98587d13123e4ef95ec9aa73b712e775d4cbba","price_changes":[{"asset_id":"54232589582260339592359130012520874109228367674780084862642636038394766871668","price":"0.04","size":"1747.74","side":"BUY","hash":"a88fb15a4e2d7c39bcd9cb50f99135acfd43c737","best_bid":"0.04","best_ask":"0.06"},{"asset_id":"96886111393998001968863279421729456597655847484197549086072988901191634450924","price":"0.96","size":"1747.74","side":"SELL","hash":"ef070a20b68407a7063999d83ddd8c33a8efc4de","best_bid":"0.94","best_ask":"0.96"}],"timestamp":"1768250251173","event_type":"price_change"}}
{"schema_version":1,"source":"clob_ws_market","recv_ts_ns":1768250251262291998,"event_type":"book","market":"0xe51aa24ab1bbfefce466d642ad98587d13123e4ef95ec9aa73b712e775d4cbba","server_ts_ms":1768250251173,"raw":{"market":"0xe51aa24ab1bbfefce466d642ad98587d13123e4ef95ec9aa73b712e775d4cbba","asset_id":"96886111393998001968863279421729456597655847484197549086072988901191634450924","bids":[{"price":"0.01","size":"24275.73"},{"price":"0.02","size":"7594.51"},{"price":"0.03","size":"5964.69"},{"price":"0.04","size":"5411.4"},{"price":"0.05","size":"5356.39"},{"price":"0.06","size":"5328"},{"price":"0.07","size":"5039.28"},{"price":"0.08","size":"5022.7"},{"price":"0.09","size":"5320.9"},{"price":"0.1","size":"5158.44"},{"price":"0.11","size":"18.3"},{"price":"0.12","size":"30.3"},{"price":"0.13","size":"16.5"},{"price":"0.14","size":"15.8"},{"price":"0.15","size":"104.19"},{"price":"0.16","size":"24.69"},{"price":"0.17","size":"14.19"},{"price":"0.18","size":"13.8"},{"price":"0.19","size":"13.4"},{"price":"0.2","size":"38.1"},{"price":"0.21","size":"12.8"},{"price":"0.22","size":"12.6"},{"price":"0.23","size":"12.3"},{"price":"0.24","size":"22.1"},{"price":"0.25","size":"16.9"},{"price":"0.26","size":"21.8"},{"price":"0.27","size":"11.6"},{"price":"0.28","size":"11.4"},{"price":"0.29","size":"61.3"},{"price":"0.3","size":"26.2"},{"price":"0.31","size":"11.1"},{"price":"0.32","size":"11"},{"price":"0.33","size":"110.9"},{"price":"0.34","size":"10.8"},{"price":"0.35","size":"15.7"},{"price":"0.36","size":"10.6"},{"price":"0.37","size":"10.6"},{"price":"0.38","size":"22.5"},{"price":"0.39","size":"10.5"},{"price":"0.4","size":"45.4"},{"price":"0.41","size":"311.4"},{"price":"0.42","size":"820.82"},{"price":"0.43","size":"826.3"},{"price":"0.44","size":"1062.3"},{"price":"0.45","size":"582.3"},{"price":"0.46","size":"626.2"},{"price":"0.47","size":"562.2"},{"price":"0.48","size":"567.2"},{"price":"0.49","size":"573.2"},{"price":"0.5","size":"917.2"},{"price":"0.51","size":"591.2"},{"price":"0.52","size":"590.2"},{"price":"0.53","size":"567.2"},{"price":"0.54","size":"636.61"},{"price":"0.55","size":"368.97"},{"price":"0.56","size":"341.3"},{"price":"0.57","size":"320.62"},{"price":"0.58","size":"567.3"},{"price":"0.59","size":"562.4"},{"price":"0.6","size":"693.02"},{"price":"0.61","size":"625.5"},{"price":"0.62","size":"700.5"},{"price":"0.63","size":"734.32"},{"price":"0.64","size":"680.6"},{"price":"0.65","size":"536.14"},{"price":"0.66","size":"602.8"},{"price":"0.67","size":"572.9"},{"price":"0.68","size":"573"},{"price":"0.69","size":"595.1"},{"price":"0.7","size":"603.2"},{"price":"0.71","size":"1318.72"},{"price":"0.72","size":"1043.04"},{"price":"0.73","size":"663.6"},{"price":"0.74","size":"911.17"},{"price":"0.75","size":"694.3"},{"price":"0.76","size":"717.6"},{"price":"0.77","size":"1183.3"},{"price":"0.78","size":"1449.6"},{"price":"0.79","size":"1254.75"},{"price":"0.8","size":"1445.08"},{"price":"0.81","size":"1229.8"},{"price":"0.82","size":"1467.57"},{"price":"0.83","size":"1470.51"},{"price":"0.84","size":"1668.59"},{"price":"0.85","size":"1762.5"},{"price":"0.86","size":"1755.6"},{"price":"0.87","size":"1588.93"},{"price":"0.88","size":"2355.4"},{"price":"0.89","size":"1866.7"},{"price":"0.9","size":"3667.84"},{"price":"0.91","size":"1623.44"},{"price":"0.92","size":"2724.36"},{"price":"0.93","size":"1519.32"},{"price":"0.94","size":"1187.58"}],"asks":[{"price":"0.99","size":"21071.86"},{"price":"0.98","size":"6468.25"},{"price":"0.97","size":"1260.33"},{"price":"0.96","size":"1747.74"}],"hash":"ef070a20b68407a7063999d83ddd8c33a8efc4de","timestamp":"1768250251173","event_type":"book"}}
{"schema_version":1,"source":"clob_ws_market","recv_ts_ns":1768250251271511668,"event_type":"price_change","market":"0xe51aa24ab1bbfefce466d642ad98587d13123e4ef95ec9aa73b712e775d4cbba","server_ts_ms":1768250251203,"raw":{"market":"0xe51aa24ab1bbfefce466d642ad98587d13123e4ef95ec9aa73b712e775d4cbba","price_changes":[{"asset_id":"54232589582260339592359130012520874109228367674780084862642636038394766871668","price":"0.01","size":"21037.86","side":"BUY","hash":"3abdc769aa3c1c672a96625fa6b8ecbb2013f654","best_bid":"0.04","best_ask":"0.06"},{"asset_id":"96886111393998001968863279421729456597655847484197549086072988901191634450924","price":"0.99","size":"21037.86","side":"SELL","hash":"4d6caf1701acaa2133884f0cf96169cbdf98d46a","best_bid":"0.94","best_ask":"0.96"}],"timestamp":"1768250251203","event_type":"price_change"}}
{"schema_version":1,"source":"clob_ws_market","recv_ts_ns":1768250251277229458,"event_type":"price_change","market":"0xe51aa24ab1bbfefce466d642ad98587d13123e4ef95ec9aa73b712e775d4cbba","server_ts_ms":1768250251243,"raw":{"market":"0xe51aa24ab1bbfefce466d642ad98587d13123e4ef95ec9aa73b712e775d4cbba","price_changes":[{"asset_id":"54232589582260339592359130012520874109228367674780084862642636038394766871668","price":"0.01","size":"21070.86","side":"BUY","hash":"bdf6169c7c223ccfd385b1415de9f23d94b94c42","best_bid":"0.04","best_ask":"0.06"},{"asset_id":"96886111393998001968863279421729456597655847484197549086072988901191634450924","price":"0.99","size":"21070.86","side":"SELL","hash":"02ad50557af8150e0fd7d2d03bc23cc458b6ce73","best_bid":"0.94","best_ask":"0.96"}],"timestamp":"1768250251243","event_type":"price_change"}}
{"schema_version":1,"source":"clob_ws_market","recv_ts_ns":1768250251283950493,"event_type":"best_bid_ask","market":"0xe51aa24ab1bbfefce466d642ad98587d13123e4ef95ec9aa73b712e775d4cbba","server_ts_ms":1768250251250,"raw":{"market":"0xe51aa24ab1bbfefce466d642ad98587d13123e4ef95ec9aa73b712e775d4cbba","asset_id":"96886111393998001968863279421729456597655847484197549086072988901191634450924","best_bid":"0.94","best_ask":"0.95","spread":"0.01","timestamp":"1768250251250","event_type":"best_bid_ask"}}
{"schema_version":1,"source":"clob_ws_market","recv_ts_ns":1768250251286245187,"event_type":"price_change","market":"0xe51aa24ab1bbfefce466d642ad98587d13123e4ef95ec9aa73b712e775d4cbba","server_ts_ms":1768250251249,"raw":{"market":"0xe51aa24ab1bbfefce466d642ad98587d13123e4ef95ec9aa73b712e775d4cbba","price_changes":[{"asset_id":"54232589582260339592359130012520874109228367674780084862642636038394766871668","price":"0.05","size":"100","side":"BUY","hash":"efaa62ee3216f1dd845789dea5f7301d5461b2c6","best_bid":"0.05","best_ask":"0.06"},{"asset_id":"96886111393998001968863279421729456597655847484197549086072988901191634450924","price":"0.95","size":"100","side":"SELL","hash":"626d69c87f313f07844be862c40ba1ceb6e54c08","best_bid":"0.94","best_ask":"0.95"}],"timestamp":"1768250251249","event_type":"price_change"}}
{"schema_version":1,"source":"clob_ws_market","recv_ts_ns":1768250251304738559,"event_type":"price_change","market":"0xe51aa24ab1bbfefce466d642ad98587d13123e4ef95ec9aa73b712e775d4cbba","server_ts_ms":1768250251282,"raw":{"market":"0xe51aa24ab1bbfefce466d642ad98587d13123e4ef95ec9aa73b712e775d4cbba","price_changes":[{"asset_id":"96886111393998001968863279421729456597655847484197549086072988901191634450924","price":"0.94","size":"1182.08","side":"BUY","hash":"720db45b979cc56acdad5296f32628ffed6b99da","best_bid":"0.94","best_ask":"0.95"},{"asset_id":"54232589582260339592359130012520874109228367674780084862642636038394766871668","price":"0.06","size":"1182.08","side":"SELL","hash":"9f3561a099031e74d17d67890a878cad4e070438","best_bid":"0.05","best_ask":"0.06"}],"timestamp":"1768250251282","event_type":"price_change"}}
{"schema_version":1,"source":"clob_ws_market","recv_ts_ns":1768250251329470847,"event_type":"price_change","market":"0xe51aa24ab1bbfefce466d642ad98587d13123e4ef95ec9aa73b712e775d4cbba","server_ts_ms":1768250251293,"raw":{"market":"0xe51aa24ab1bbfefce466d642ad98587d13123e4ef95ec9aa73b712e775d4cbba","price_changes":[{"asset_id":"96886111393998001968863279421729456597655847484197549086072988901191634450924","price":"0.94","size":"1176.58","side":"BUY","hash":"2318d6202099fd4bb98d900a9e97aec59b4f32f1","best_bid":"0.94","best_ask":"0.95"},{"asset_id":"54232589582260339592359130012520874109228367674780084862642636038394766871668","price":"0.06","size":"1176.58","side":"SELL","hash":"e24160e88416df6d7ff1df7719cd31035f56c916","best_bid":"0.05","best_ask":"0.06"}],"timestamp":"1768250251293","event_type":"price_change"}}
{"schema_version":1,"source":"clob_ws_market","recv_ts_ns":1768250251336472229,"event_type":"price_change","market":"0xe51aa24ab1bbfefce466d642ad98587d13123e4ef95ec9aa73b712e775d4cbba","server_ts_ms":1768250251303,"raw":{"market":"0xe51aa24ab1bbfefce466d642ad98587d13123e4ef95ec9aa73b712e775d4cbba","price_changes":[{"asset_id":"96886111393998001968863279421729456597655847484197549086072988901191634450924","price":"0.01","size":"24281.22","side":"BUY","hash":"460f0e628de37a3cf5bfeb07e1d31a2de701af96","best_bid":"0.94","best_ask":"0.95"},{"asset_id":"54232589582260339592359130012520874109228367674780084862642636038394766871668","price":"0.99","size":"24281.22","side":"SELL","hash":"702c40c8a4e30031719ed02cc8f07d4f12a60fe6","best_bid":"0.05","best_ask":"0.06"}],"timestamp":"1768250251303","event_type":"price_change"}}
{"schema_version":1,"source":"clob_ws_market","recv_ts_ns":1768250251341786555,"event_type":"best_bid_ask","market":"0xe51aa24ab1bbfefce466d642ad98587d13123e4ef95ec9aa73b712e775d4cbba","server_ts_ms":1768250251310,"raw":{"market":"0xe51aa24ab1bbfefce466d642ad98587d13123e4ef95ec9aa73b712e775d4cbba","asset_id":"96886111393998001968863279421729456597655847484197549086072988901191634450924","best_bid":"0.94","best_ask":"0.95","spread":"0.01","timestamp":"1768250251310","event_type":"best_bid_ask"}}
{"schema_version":1,"source":"clob_ws_market","recv_ts_ns":1768250251343436743,"event_type":"price_change","market":"0xe51aa24ab1bbfefce466d642ad98587d13123e4ef95ec9aa73b712e775d4cbba","server_ts_ms":1768250251309,"raw":{"market":"0xe51aa24ab1bbfefce466d642ad98587d13123e4ef95ec9aa73b712e775d4cbba","price_changes":[{"asset_id":"54232589582260339592359130012520874109228367674780084862642636038394766871668","price":"0.05","size":"97.89","side":"BUY","hash":"ccd766b6266aa52da7268f4fd9864570027c4f57","best_bid":"0.05","best_ask":"0.06"},{"asset_id":"96886111393998001968863279421729456597655847484197549086072988901191634450924","price":"0.95","size":"97.89","side":"SELL","hash":"e11bcf1256ae5cc7791bf5189d7845d02c51ed1d","best_bid":"0.94","best_ask":"0.95"}],"timestamp":"1768250251309","event_type":"price_change"}}
{"schema_version":1,"source":"clob_ws_market","recv_ts_ns":1768250251349531918,"event_type":"book","market":"0xe51aa24ab1bbfefce466d642ad98587d13123e4ef95ec9aa73b712e775d4cbba","server_ts_ms":1768250251309,"raw":{"market":"0xe51aa24ab1bbfefce466d642ad98587d13123e4ef95ec9aa73b712e775d4cbba","asset_id":"96886111393998001968863279421729456597655847484197549086072988901191634450924","bids":[{"price":"0.01","size":"24281.22"},{"price":"0.02","size":"7594.51"},{"price":"0.03","size":"5964.69"},{"price":"0.04","size":"5411.4"},{"price":"0.05","size":"5356.39"},{"price":"0.06","size":"5328"},{"price":"0.07","size":"5039.28"},{"price":"0.08","size":"5022.7"},{"price":"0.09","size":"5320.9"},{"price":"0.1","size":"5158.44"},{"price":"0.11","size":"18.3"},{"price":"0.12","size":"30.3"},{"price":"0.13","size":"16.5"},{"price":"0.14","size":"15.8"},{"price":"0.15","size":"104.19"},{"price":"0.16","size":"24.69"},{"price":"0.17","size":"14.19"},{"price":"0.18","size":"13.8"},{"price":"0.19","size":"13.4"},{"price":"0.2","size":"38.1"},{"price":"0.21","size":"12.8"},{"price":"0.22","size":"12.6"},{"price":"0.23","size":"12.3"},{"price":"0.24","size":"22.1"},{"price":"0.25","size":"16.9"},{"price":"0.26","size":"21.8"},{"price":"0.27","size":"11.6"},{"price":"0.28","size":"11.4"},{"price":"0.29","size":"61.3"},{"price":"0.3","size":"26.2"},{"price":"0.31","size":"11.1"},{"price":"0.32","size":"11"},{"price":"0.33","size":"110.9"},{"price":"0.34","size":"10.8"},{"price":"0.35","size":"15.7"},{"price":"0.36","size":"10.6"},{"price":"0.37","size":"10.6"},{"price":"0.38","size":"22.5"},{"price":"0.39","size":"10.5"},{"price":"0.4","size":"45.4"},{"price":"0.41","size":"311.4"},{"price":"0.42","size":"820.82"},{"price":"0.43","size":"826.3"},{"price":"0.44","size":"1062.3"},{"price":"0.45","size":"582.3"},{"price":"0.46","size":"626.2"},{"price":"0.47","size":"562.2"},{"price":"0.48","size":"567.2"},{"price":"0.49","size":"573.2"},{"price":"0.5","size":"917.2"},{"price":"0.51","size":"591.2"},{"price":"0.52","size":"590.2"},{"price":"0.53","size":"567.2"},{"price":"0.54","size":"636.61"},{"price":"0.55","size":"368.97"},{"price":"0.56","size":"341.3"},{"price":"0.57","size":"320.62"},{"price":"0.58","size":"567.3"},{"price":"0.59","size":"562.4"},{"price":"0.6","size":"693.02"},{"price":"0.61","size":"625.5"},{"price":"0.62","size":"700.5"},{"price":"0.63","size":"734.32"},{"price":"0.64","size":"680.6"},{"price":"0.65","size":"536.14"},{"price":"0.66","size":"602.8"},{"price":"0.67","size":"572.9"},{"price":"0.68","size":"573"},{"price":"0.69","size":"595.1"},{"price":"0.7","size":"603.2"},{"price":"0.71","size":"1318.72"},{"price":"0.72","size":"1043.04"},{"price":"0.73","size":"663.6"},{"price":"0.74","size":"911.17"},{"price":"0.75","size":"694.3"},{"price":"0.76","size":"717.6"},{"price":"0.77","size":"1183.3"},{"price":"0.78","size":"1449.6"},{"price":"0.79","size":"1254.75"},{"price":"0.8","size":"1445.08"},{"price":"0.81","size":"1229.8"},{"price":"0.82","size":"1467.57"},{"price":"0.83","size":"1470.51"},{"price":"0.84","size":"1668.59"},{"price":"0.85","size":"1762.5"},{"price":"0.86","size":"1755.6"},{"price":"0.87","size":"1588.93"},{"price":"0.88","size":"2355.4"},{"price":"0.89","size":"1866.7"},{"price":"0.9","size":"3667.84"},{"price":"0.91","size":"1623.44"},{"price":"0.92","size":"2724.36"},{"price":"0.93","size":"1519.32"},{"price":"0.94","size":"1176.58"}],"asks":[{"price":"0.99","size":"21070.86"},{"price":"0.98","size":"6468.25"},{"price":"0.97","size":"1260.33"},{"price":"0.96","size":"1747.74"},{"price":"0.95","size":"97.89"}],"hash":"e11bcf1256ae5cc7791bf5189d7845d02c51ed1d","timestamp":"1768250251309","event_type":"book"}}
{"schema_version":1,"source":"clob_ws_market","recv_ts_ns":1768250251351361651,"event_type":"price_change","market":"0xe51aa24ab1bbfefce466d642ad98587d13123e4ef95ec9aa73b712e775d4cbba","server_ts_ms":1768250251310,"raw":{"market":"0xe51aa24ab1bbfefce466d642ad98587d13123e4ef95ec9aa73b712e775d4cbba","price_changes":[{"asset_id":"96886111393998001968863279421729456597655847484197549086072988901191634450924","price":"0.93","size":"1524.82","side":"BUY","hash":"e4bb550d98f44fc7d8298fe0161dd912e37ef2e3","best_bid":"0.94","best_ask":"0.95"},{"asset_id":"54232589582260339592359130012520874109228367674780084862642636038394766871668","price":"0.07","size":"1524.82","side":"SELL","hash":"56fd28a97e9973d809126e88e76cd10fbab32458","best_bid":"0.05","best_ask":"0.06"}],"timestamp":"1768250251310","event_type":"price_change"}}
{"schema_version":1,"source":"clob_ws_market","recv_ts_ns":1768250251365645105,"event_type":"best_bid_ask","market":"0xe51aa24ab1bbfefce466d642ad98587d13123e4ef95ec9aa73b712e775d4cbba","server_ts_ms":1768250251315,"raw":{"market":"0xe51aa24ab1bbfefce466d642ad98587d13123e4ef95ec9aa73b712e775d4cbba","asset_id":"96886111393998001968863279421729456597655847484197549086072988901191634450924","best_bid":"0.94","best_ask":"0.95","spread":"0.01","timestamp":"1768250251315","event_type":"best_bid_ask"}}
{"schema_version":1,"source":"clob_ws_market","recv_ts_ns":1768250251367296075,"event_type":"price_change","market":"0xe51aa24ab1bbfefce466d642ad98587d13123e4ef95ec9aa73b712e775d4cbba","server_ts_ms":1768250251313,"raw":{"market":"0xe51aa24ab1bbfefce466d642ad98587d13123e4ef95ec9aa73b712e775d4cbba","price_changes":[{"asset_id":"54232589582260339592359130012520874109228367674780084862642636038394766871668","price":"0.05","size":"61.89","side":"BUY","hash":"c90a3235022e0291013138b5c6f18b349019b5ef","best_bid":"0.05","best_ask":"0.06"},{"asset_id":"96886111393998001968863279421729456597655847484197549086072988901191634450924","price":"0.95","size":"61.89","side":"SELL","hash":"9b0d92301187f27f751a6f4ebee3e81209bca5e5","best_bid":"0.94","best_ask":"0.95"}],"timestamp":"1768250251313","event_type":"price_change"}}
