{"schema_version":1,"source":"clob_ws_market","recv_ts_ns":1768250247928537323,"event_type":"book","market":"0xe51aa24ab1bbfefce466d642ad98587d13123e4ef95ec9aa73b712e775d4cbba","server_ts_ms":1768250247871,"raw":{"market":"0xe51aa24ab1bbfefce466d642ad98587d13123e4ef95ec9aa73b712e775d4cbba","asset_id":"96886111393998001968863279421729456597655847484197549086072988901191634450924","bids":[{"price":"0.01","size":"24295.73"},{"price":"0.02","size":"7594.51"},{"price":"0.03","size":"5964.69"},{"price":"0.04","size":"5411.4"},{"price":"0.05","size":"5356.39"},{"price":"0.06","size":"5328"},{"price":"0.07","size":"5039.28"},{"price":"0.08","size":"5022.7"},{"price":"0.09","size":"5320.9"},{"price":"0.1","size":"5158.44"},{"price":"0.11","size":"18.3"},{"price":"0.12","size":"30.3"},{"price":"0.13","size":"16.5"},{"price":"0.14","size":"15.8"},{"price":"0.15","size":"104.19"},{"price":"0.16","size":"24.69"},{"price":"0.17","size":"14.19"},{"price":"0.18","size":"13.8"},{"price":"0.19","size":"13.4"},{"price":"0.2","size":"38.1"},{"price":"0.21","size":"12.8"},{"price":"0.22","size":"12.6"},{"price":"0.23","size":"12.3"},{"price":"0.24","size":"22.1"},{"price":"0.25","size":"16.9"},{"price":"0.26","size":"21.8"},{"price":"0.27","size":"11.6"},{"price":"0.28","size":"11.4"},{"price":"0.29","size":"61.3"},{"price":"0.3","size":"26.2"},{"price":"0.31","size":"11.1"},{"price":"0.32","size":"11"},{"price":"0.33","size":"110.9"},{"price":"0.34","size":"10.8"},{"price":"0.35","size":"15.7"},{"price":"0.36","size":"10.6"},{"price":"0.37","size":"10.6"},{"price":"0.38","size":"22.5"},{"price":"0.39","size":"10.5"},{"price":"0.4","size":"45.4"},{"price":"0.41","size":"311.4"},{"price":"0.42","size":"820.82"},{"price":"0.43","size":"826.3"},{"price":"0.44","size":"1062.3"},{"price":"0.45","size":"582.3"},{"price":"0.46","size":"626.2"},{"price":"0.47","size":"562.2"},{"price":"0.48","size":"567.2"},{"price":"0.49","size":"573.2"},{"price":"0.5","size":"917.2"},{"price":"0.51","size":"591.2"},{"price":"0.52","size":"590.2"},{"price":"0.53","size":"567.2"},{"price":"0.54","size":"642.61"},{"price":"0.55","size":"362.97"},{"price":"0.56","size":"341.3"},{"price":"0.57","size":"320.62"},{"price":"0.58","size":"567.3"},{"price":"0.59","size":"562.4"},{"price":"0.6","size":"693.02"},{"price":"0.61","size":"625.5"},{"price":"0.62","size":"700.5"},{"price":"0.63","size":"703.32"},{"price":"0.64","size":"680.6"},{"price":"0.65","size":"536.14"},{"price":"0.66","size":"602.8"},{"price":"0.67","size":"572.9"},{"price":"0.68","size":"573"},{"price":"0.69","size":"595.1"},{"price":"0.7","size":"603.2"},{"price":"0.71","size":"1318.72"},{"price":"0.72","size":"1043.04"},{"price":"0.73","size":"663.6"},{"price":"0.74","size":"911.17"},{"price":"0.75","size":"694.3"},{"price":"0.76","size":"717.6"},{"price":"0.77","size":"1183.3"},{"price":"0.78","size":"1449.6"},{"price":"0.79","size":"1254.75"},{"price":"0.8","size":"1445.08"},{"price":"0.81","size":"1229.8"},{"price":"0.82","size":"1467.57"},{"price":"0.83","size":"1470.51"},{"price":"0.84","size":"1668.59"},{"price":"0.85","size":"1762.5"},{"price":"0.86","size":"1755.6"},{"price":"0.87","size":"1588.93"},{"price":"0.88","size":"2355.4"},{"price":"0.89","size":"2066.7"},{"price":"0.9","size":"3467.84"},{"price":"0.91","size":"3018.44"},{"price":"0.92","size":"2729.36"},{"price":"0.93","size":"1391.82"},{"price":"0.94","size":"1814.21"}],"asks":[{"price":"0.99","size":"21178.86"},{"price":"0.98","size":"5425.25"},{"price":"0.97","size":"1228.6"},{"price":"0.96","size":"1637.5"},{"price":"0.95","size":"61.79"}],"hash":"61b80d75ba0910b1b4cc6ea2d168b4379f3e06b9","timestamp":"1768250247871","event_type":"book"}}
{"schema_version":1,"source":"clob_ws_market","recv_ts_ns":1768250247932648290,"event_type":"price_change","market":"0xe51aa24ab1bbfefce466d642ad98587d13123e4ef95ec9aa73b712e775d4cbba","server_ts_ms":1768250247893,"raw":{"market":"0xe51aa24ab1bbfefce466d642ad98587d13123e4ef95ec9aa73b712e775d4cbba","price_changes":[{"asset_id":"96886111393998001968863279421729456597655847484197549086072988901191634450924","price":"0.94","size":"1826.21","side":"BUY","hash":"bb9e02d0808830241d814c0e5afa7ff78e92d15d","best_bid":"0.94","best_ask":"0.95"},{"asset_id":"54232589582260339592359130012520874109228367674780084862642636038394766871668","price":"0.06","size":"1826.21","side":"SELL","hash":"3ea97d474a504c435a951d6e3f8d7b850eecd5b8","best_bid":"0.05","best_ask":"0.06"}],"timestamp":"1768250247893","event_type":"price_change"}}
{"schema_version":1,"source":"clob_ws_market","recv_ts_ns":1768250247937785247,"event_type":"price_change","market":"0xe51aa24ab1bbfefce466d642ad98587d13123e4ef95ec9aa73b712e775d4cbba","server_ts_ms":1768250247898,"raw":{"market":"0xe51aa24ab1bbfefce466d642ad98587d13123e4ef95ec9aa73b712e775d4cbba","price_changes":[{"asset_id":"96886111393998001968863279421729456597655847484197549086072988901191634450924","price":"0.94","size":"1850.21","side":"BUY","hash":"f2be2fa8416b1a97bd580c92684f193e9f936ff0","best_bid":"0.94","best_ask":"0.95"},{"asset_id":"54232589582260339592359130012520874109228367674780084862642636038394766871668","price":"0.06","size":"1850.21","side":"SELL","hash":"18aa8d4ab84eee20ebdb9d78e34519aee5330929","best_bid":"0.05","best_ask":"0.06"}],"timestamp":"1768250247898","event_type":"price_change"}}
{"schema_version":1,"source":"clob_ws_market","recv_ts_ns":1768250247941412994,"event_type":"last_trade_price","market":"0xe51aa24ab1bbfefce466d642ad98587d13123e4ef95ec9aa73b712e775d4cbba","server_ts_ms":1768250247900,"raw":{"market":"0xe51aa24ab1bbfefce466d642ad98587d13123e4ef95ec9aa73b712e775d4cbba","asset_id":"96886111393998001968863279421729456597655847484197549086072988901191634450924","price":"0.95","size":"50","fee_rate_bps":"1000","side":"BUY","timestamp":"1768250247900","event_type":"last_trade_price","transaction_hash":"0x2b1a4c9dc2a9d5f7f31c7e4c9a5351ee3717634ba3c0e20d54cdbe7bd9bb17e6"}}
{"schema_version":1,"source":"clob_ws_market","recv_ts_ns":1768250247946676023,"event_type":"price_change","market":"0xe51aa24ab1bbfefce466d642ad98587d13123e4ef95ec9aa73b712e775d4cbba","server_ts_ms":1768250247907,"raw":{"market":"0xe51aa24ab1bbfefce466d642ad98587d13123e4ef95ec9aa73b712e775d4cbba","price_changes":[{"asset_id":"96886111393998001968863279421729456597655847484197549086072988901191634450924","price":"0.92","size":"2724.36","side":"BUY","hash":"7f679a13ee1e8f18384f57c0139c99f2c576e715","best_bid":"0.94","best_ask":"0.95"},{"asset_id":"54232589582260339592359130012520874109228367674780084862642636038394766871668","price":"0.08","size":"2724.36","side":"SELL","hash":"2710abd5450be4b1bb2dc5171a6ddc7a876fbc82","best_bid":"0.05","best_ask":"0.06"}],"timestamp":"1768250247907","event_type":"price_change"}}
{"schema_version":1,"source":"clob_ws_market","recv_ts_ns":1768250247950643202,"event_type":"price_change","market":"0xe51aa24ab1bbfefce466d642ad98587d13123e4ef95ec9aa73b712e775d4cbba","server_ts_ms":1768250247907,"raw":{"market":"0xe51aa24ab1bbfefce466d642ad98587d13123e4ef95ec9aa73b712e775d4cbba","price_changes":[{"asset_id":"96886111393998001968863279421729456597655847484197549086072988901191634450924","price":"0.99","size":"21173.86","side":"SELL","hash":"7f679a13ee1e8f18384f57c0139c99f2c576e715","best_bid":"0.94","best_ask":"0.95"},{"asset_id":"54232589582260339592359130012520874109228367674780084862642636038394766871668","price":"0.01","size":"21173.86","side":"BUY","hash":"2710abd5450be4b1bb2dc5171a6ddc7a876fbc82","best_bid":"0.05","best_ask":"0.06"}],"timestamp":"1768250247907","event_type":"price_change"}}
{"schema_version":1,"source":"clob_ws_market","recv_ts_ns":1768250247954485527,"event_type":"price_change","market":"0xe51aa24ab1bbfefce466d642ad98587d13123e4ef95ec9aa73b712e775d4cbba","server_ts_ms":1768250247909,"raw":{"market":"0xe51aa24ab1bbfefce466d642ad98587d13123e4ef95ec9aa73b712e775d4cbba","price_changes":[{"asset_id":"54232589582260339592359130012520874109228367674780084862642636038394766871668","price":"0.01","size":"21204.86","side":"BUY","hash":"402bb5aa78cccbe986c75b0fd94b4567c8a2f2b0","best_bid":"0.05","best_ask":"0.06"},{"asset_id":"96886111393998001968863279421729456597655847484197549086072988901191634450924","price":"0.99","size":"21204.86","side":"SELL","hash":"d0c197bf910032f74d92435814281e9de5430011","best_bid":"0.94","best_ask":"0.95"}],"timestamp":"1768250247909","event_type":"price_change"}}
{"schema_version":1,"source":"clob_ws_market","recv_ts_ns":1768250247967187091,"event_type":"price_change","market":"0xe51aa24ab1bbfefce466d642ad98587d13123e4ef95ec9aa73b712e775d4cbba","server_ts_ms":1768250247923,"raw":{"market":"0xe51aa24ab1bbfefce466d642ad98587d13123e4ef95ec9aa73b712e775d4cbba","price_changes":[{"asset_id":"96886111393998001968863279421729456597655847484197549086072988901191634450924","price":"0.94","size":"1858.21","side":"BUY","hash":"46c3b0e8e2b6a774d24fc6cd7515f0497f5da8aa","best_bid":"0.94","best_ask":"0.95"},{"asset_id":"54232589582260339592359130012520874109228367674780084862642636038394766871668","price":"0.06","size":"1858.21","side":"SELL","hash":"c793a49cd864feaaa585d5034de1f17418bcc855","best_bid":"0.05","best_ask":"0.06"}],"timestamp":"1768250247923","event_type":"price_change"}}
{"schema_version":1,"source":"clob_ws_market","recv_ts_ns":1768250247971179096,"event_type":"price_change","market":"0xe51aa24ab1bbfefce466d642ad98587d13123e4ef95ec9aa73b712e775d4cbba","server_ts_ms":1768250247925,"raw":{"market":"0xe51aa24ab1bbfefce466d642ad98587d13123e4ef95ec9aa73b712e775d4cbba","price_changes":[{"asset_id":"96886111393998001968863279421729456597655847484197549086072988901191634450924","price":"0.94","size":"1846.21","side":"BUY","hash":"eae0f40686b4909aa55dfd8b9d728dd505acd791","best_bid":"0.94","best_ask":"0.95"},{"asset_id":"54232589582260339592359130012520874109228367674780084862642636038394766871668","price":"0.06","size":"1846.21","side":"SELL","hash":"15d06fe3f608512303096214a280b6792304b190","best_bid":"0.05","best_ask":"0.06"}],"timestamp":"1768250247925","event_type":"price_change"}}
{"schema_version":1,"source":"clob_ws_market","recv_ts_ns":1768250247974370123,"event_type":"price_change","market":"0xe51aa24ab1bbfefce466d642ad98587d13123e4ef95ec9aa73b712e775d4cbba","server_ts_ms":1768250247936,"raw":{"market":"0xe51aa24ab1bbfefce466d642ad98587d13123e4ef95ec9aa73b712e775d4cbba","price_changes":[{"asset_id":"54232589582260339592359130012520874109228367674780084862642636038394766871668","price":"0.06","size":"1857.21","side":"SELL","hash":"74580a5119b8c86b68e2283485746742de5199b2","best_bid":"0.05","best_ask":"0.06"},{"asset_id":"96886111393998001968863279421729456597655847484197549086072988901191634450924","price":"0.94","size":"1857.21","side":"BUY","hash":"96c2bde9799aead46aa11c775bd634c69a8183b5","best_bid":"0.94","best_ask":"0.95"}],"timestamp":"1768250247936","event_type":"price_change"}}
{"schema_version":1,"source":"clob_ws_market","recv_ts_ns":1768250247977658948,"event_type":"price_change","market":"0xe51aa24ab1bbfefce466d642ad98587d13123e4ef95ec9aa73b712e775d4cbba","server_ts_ms":1768250247940,"raw":{"market":"0xe51aa24ab1bbfefce466d642ad98587d13123e4ef95ec9aa73b712e775d4cbba","price_changes":[{"asset_id":"96886111393998001968863279421729456597655847484197549086072988901191634450924","price":"0.99","size":"21209.86","side":"SELL","hash":"fe990d7a5d32dd8ba3d4199483f77e176f413570","best_bid":"0.94","best_ask":"0.95"},{"asset_id":"54232589582260339592359130012520874109228367674780084862642636038394766871668","price":"0.01","size":"21209.86","side":"BUY","hash":"f415fcb6151b45212b072aba75c86afb5b762dd8","best_bid":"0.05","best_ask":"0.06"}],"timestamp":"1768250247940","event_type":"price_change"}}
{"schema_version":1,"source":"clob_ws_market","recv_ts_ns":1768250247981521153,"event_type":"price_change","market":"0xe51aa24ab1bbfefce466d642ad98587d13123e4ef95ec9aa73b712e775d4cbba","server_ts_ms":1768250247940,"raw":{"market":"0xe51aa24ab1bbfefce466d642ad98587d13123e4ef95ec9aa73b712e775d4cbba","price_changes":[{"asset_id":"96886111393998001968863279421729456597655847484197549086072988901191634450924","price":"0.92","size":"2729.36","side":"BUY","hash":"c552a89a8760a4922927fa72ccdf706e62e8d991","best_bid":"0.94","best_ask":"0.95"},{"asset_id":"54232589582260339592359130012520874109228367674780084862642636038394766871668","price":"0.08","size":"2729.36","side":"SELL","hash":"f2378f9407242c7d3dc9c66b9eab720fe765cd8c","best_bid":"0.05","best_ask":"0.06"}],"timestamp":"1768250247940","event_type":"price_change"}}
{"schema_version":1,"source":"clob_ws_market","recv_ts_ns":1768250247985289464,"event_type":"price_change","market":"0xe51aa24ab1bbfefce466d642ad98587d13123e4ef95ec9aa73b712e775d4cbba","server_ts_ms":1768250247941,"raw":{"market":"0xe51aa24ab1bbfefce466d642ad98587d13123e4ef95ec9aa73b712e775d4cbba","price_changes":[{"asset_id":"96886111393998001968863279421729456597655847484197549086072988901191634450924","price":"0.94","size":"1833.21","side":"BUY","hash":"3460370a15e57c5dea58caebbe9a8142e2057d07","best_bid":"0.94","best_ask":"0.95"},{"asset_id":"54232589582260339592359130012520874109228367674780084862642636038394766871668","price":"0.06","size":"1833.21","side":"SELL","hash":"21b07b3d2a06af6ba97abf4c678ab6e93c70377e","best_bid":"0.05","best_ask":"0.06"}],"timestamp":"1768250247941","event_type":"price_change"}}
{"schema_version":1,"source":"clob_ws_market","recv_ts_ns":1768250248005544983,"event_type":"price_change","market":"0xe51aa24ab1bbfefce466d642ad98587d13123e4ef95ec9aa73b712e775d4cbba","server_ts_ms":1768250247964,"raw":{"market":"0xe51aa24ab1bbfefce466d642ad98587d13123e4ef95ec9aa73b712e775d4cbba","price_changes":[{"asset_id":"96886111393998001968863279421729456597655847484197549086072988901191634450924","price":"0.94","size":"1863.21","side":"BUY","hash":"38547af89cfc320ed0eeefe79b91d4c6a9574528","best_bid":"0.94","best_ask":"0.95"},{"asset_id":"54232589582260339592359130012520874109228367674780084862642636038394766871668","price":"0.06","size":"1863.21","side":"SELL","hash":"62f44ed93f2447914e7f6bb643855ae02874051a","best_bid":"0.05","best_ask":"0.06"}],"timestamp":"1768250247964","event_type":"price_change"}}
{"schema_version":1,"source":"clob_ws_market","recv_ts_ns":1768250248009413170,"event_type":"price_change","market":"0xe51aa24ab1bbfefce466d642ad98587d13123e4ef95ec9aa73b712e775d4cbba","server_ts_ms":1768250247965,"raw":{"market":"0xe51aa24ab1bbfefce466d642ad98587d13123e4ef95ec9aa73b712e775d4cbba","price_changes":[{"asset_id":"54232589582260339592359130012520874109228367674780084862642636038394766871668","price":"0.06","size":"1852.21","side":"SELL","hash":"1ceec0af443bd62c300c1b372a3268d2b826c93d","best_bid":"0.05","best_ask":"0.06"},{"asset_id":"96886111393998001968863279421729456597655847484197549086072988901191634450924","price":"0.94","size":"1852.21","side":"BUY","hash":"3a1938f30b0f00e8f013ca330d5359e78b5ab92f","best_bid":"0.94","best_ask":"0.95"}],"timestamp":"1768250247965","event_type":"price_change"}}
{"schema_version":1,"source":"clob_ws_market","recv_ts_ns":1768250248013483205,"event_type":"price_change","market":"0xe51aa24ab1bbfefce466d642ad98587d13123e4ef95ec9aa73b712e775d4cbba","server_ts_ms":1768250247968,"raw":{"market":"0xe51aa24ab1bbfefce466d642ad98587d13123e4ef95ec9aa73b712e775d4cbba","price_changes":[{"asset_id":"96886111393998001968863279421729456597655847484197549086072988901191634450924","price":"0.94","size":"1867.21","side":"BUY","hash":"461cad7fb10e581929a5bbdf7dfd5727bf147c31","best_bid":"0.94","best_ask":"0.95"},{"asset_id":"54232589582260339592359130012520874109228367674780084862642636038394766871668","price":"0.06","size":"1867.21","side":"SELL","hash":"c928e96ea535d50ba700aec27d386cf956b1c1d4","best_bid":"0.05","best_ask":"0.06"}],"timestamp":"1768250247968","event_type":"price_change"}}
{"schema_version":1,"source":"clob_ws_market","recv_ts_ns":1768250248041527996,"event_type":"price_change","market":"0xe51aa24ab1bbfefce466d642ad98587d13123e4ef95ec9aa73b712e775d4cbba","server_ts_ms":1768250248001,"raw":{"market":"0xe51aa24ab1bbfefce466d642ad98587d13123e4ef95ec9aa73b712e775d4cbba","price_changes":[{"asset_id":"54232589582260339592359130012520874109228367674780084862642636038394766871668","price":"0.01","size":"21109.86","side":"BUY","hash":"9f01a0084059b1f8d6539a1e32380c731d30748a","best_bid":"0.05","best_ask":"0.06"},{"asset_id":"96886111393998001968863279421729456597655847484197549086072988901191634450924","price":"0.99","size":"21109.86","side":"SELL","hash":"ebadc1d1dcd7a52bc5d25ca02270d992918faa42","best_bid":"0.94","best_ask":"0.95"}],"timestamp":"1768250248001","event_type":"price_change"}}
{"schema_version":1,"source":"clob_ws_market","recv_ts_ns":1768250248045885582,"event_type":"price_change","market":"0xe51aa24ab1bbfefce466d642ad98587d13123e4ef95ec9aa73b712e775d4cbba","server_ts_ms":1768250248009,"raw":{"market":"0xe51aa24ab1bbfefce466d642ad98587d13123e4ef95ec9aa73b712e775d4cbba","price_changes":[{"asset_id":"96886111393998001968863279421729456597655847484197549086072988901191634450924","price":"0.94","size":"1855.21","side":"BUY","hash":"602203b006f80496f63f5bc1035f09242e04efe9","best_bid":"0.94","best_ask":"0.95"},{"asset_id":"54232589582260339592359130012520874109228367674780084862642636038394766871668","price":"0.06","size":"1855.21","side":"SELL","hash":"022c75b507b82226192f1cb7bef792b24a612298","best_bid":"0.05","best_ask":"0.06"}],"timestamp":"1768250248009","event_type":"price_change"}}
{"schema_version":1,"source":"clob_ws_market","recv_ts_ns":1768250248079556403,"event_type":"price_change","market":"0xe51aa24ab1bbfefce466d642ad98587d13123e4ef95ec9aa73b712e775d4cbba","server_ts_ms":1768250248053,"raw":{"market":"0xe51aa24ab1bbfefce466d642ad98587d13123e4ef95ec9aa73b712e775d4cbba","price_changes":[{"asset_id":"54232589582260339592359130012520874109228367674780084862642636038394766871668","price":"0.01","size":"21209.86","side":"BUY","hash":"b9b94476f0eb0a15a48758a5612fa3053a90604e","best_bid":"0.05","best_ask":"0.06"},{"asset_id":"96886111393998001968863279421729456597655847484197549086072988901191634450924","price":"0.99","size":"21209.86","side":"SELL","hash":"067298f8ac1b808b034fb9a83e9549ce861a1ab8","best_bid":"0.94","best_ask":"0.95"}],"timestamp":"1768250248053","event_type":"price_change"}}
{"schema_version":1,"source":"clob_ws_market","recv_ts_ns":1768250248197083364,"event_type":"price_change","market":"0xe51aa24ab1bbfefce466d642ad98587d13123e4ef95ec9aa73b712e775d4cbba","server_ts_ms":1768250248172,"raw":{"market":"0xe51aa24ab1bbfefce466d642ad98587d13123e4ef95ec9aa73b712e775d4cbba","price_changes":[{"asset_id":"54232589582260339592359130012520874109228367674780084862642636038394766871668","price":"0.01","size":"21178.86","side":"BUY","hash":"3100625d1159444530c3c4cbfc2c35243a4a4d17","best_bid":"0.05","best_ask":"0.06"},{"asset_id":"96886111393998001968863279421729456597655847484197549086072988901191634450924","price":"0.99","size":"21178.86","side":"SELL","hash":"4dcfe833e3d3bc3ef88737ac363d05ca8766ca6c","best_bid":"0.94","best_ask":"0.95"}],"timestamp":"1768250248172","event_type":"price_change"}}
{"schema_version":1,"source":"clob_ws_market","recv_ts_ns":1768250248201021222,"event_type":"price_change","market":"0xe51aa24ab1bbfefce466d642ad98587d13123e4ef95ec9aa73b712e775d4cbba","server_ts_ms":1768250248174,"raw":{"market":"0xe51aa24ab1bbfefce466d642ad98587d13123e4ef95ec9aa73b712e775d4cbba","price_changes":[{"asset_id":"54232589582260339592359130012520874109228367674780084862642636038394766871668","price":"0.02","size":"5409.25","side":"BUY","hash":"49bddb8fe6cd61377d29984c21da938467e8e104","best_bid":"0.05","best_ask":"0.06"},{"asset_id":"96886111393998001968863279421729456597655847484197549086072988901191634450924","price":"0.98","size":"5409.25","side":"SELL","hash":"4c2d074ad52ce71561c35af5b33478c6abee37c3","best_bid":"0.94","best_ask":"0.95"}],"timestamp":"1768250248174","event_type":"price_change"}}
{"schema_version":1,"source":"clob_ws_market","recv_ts_ns":1768250248203975560,"event_type":"price_change","market":"0xe51aa24ab1bbfefce466d642ad98587d13123e4ef95ec9aa73b712e775d4cbba","server_ts_ms":1768250248177,"raw":{"market":"0xe51aa24ab1bbfefce466d642ad98587d13123e4ef95ec9aa73b712e775d4cbba","price_changes":[{"asset_id":"96886111393998001968863279421729456597655847484197549086072988901191634450924","price":"0.94","size":"1839.21","side":"BUY","hash":"992cf41375378f431fda780c55be9830768a3cb6","best_bid":"0.94","best_ask":"0.95"},{"asset_id":"54232589582260339592359130012520874109228367674780084862642636038394766871668","price":"0.06","size":"1839.21","side":"SELL","hash":"317b8e28b96d5d09b7b269723c3ae9afb60f228e","best_bid":"0.05","best_ask":"0.06"}],"timestamp":"1768250248177","event_type":"price_change"}}
{"schema_version":1,"source":"clob_ws_market","recv_ts_ns":1768250248207145518,"event_type":"price_change","market":"0xe51aa24ab1bbfefce466d642ad98587d13123e4ef95ec9aa73b712e775d4cbba","server_ts_ms":1768250248180,"raw":{"market":"0xe51aa24ab1bbfefce466d642ad98587d13123e4ef95ec9aa73b712e775d4cbba","price_changes":[{"asset_id":"54232589582260339592359130012520874109228367674780084862642636038394766871668","price":"0.02","size":"5393.25","side":"BUY","hash":"4a1254d4be09226ad28c9f8f1ab3db2c59a514a7","best_bid":"0.05","best_ask":"0.06"},{"asset_id":"96886111393998001968863279421729456597655847484197549086072988901191634450924","price":"0.98","size":"5393.25","side":"SELL","hash":"5c14772aa8ba6baaf0a7f8e4234e4ee8f7404d80","best_bid":"0.94","best_ask":"0.95"}],"timestamp":"1768250248180","event_type":"price_change"}}
{"schema_version":1,"source":"clob_ws_market","recv_ts_ns":1768250248209851533,"event_type":"price_change","market":"0xe51aa24ab1bbfefce466d642ad98587d13123e4ef95ec9aa73b712e775d4cbba","server_ts_ms":1768250248181,"raw":{"market":"0xe51aa24ab1bbfefce466d642ad98587d13123e4ef95ec9aa73b712e775d4cbba","price_changes":[{"asset_id":"54232589582260339592359130012520874109228367674780084862642636038394766871668","price":"0.03","size":"1212.6","side":"BUY","hash":"b8ecf50776d8f80263ef550a0349a323fea4d112","best_bid":"0.05","best_ask":"0.06"},{"asset_id":"96886111393998001968863279421729456597655847484197549086072988901191634450924","price":"0.97","size":"1212.6","side":"SELL","hash":"039332d957456484011d1f798f47c420186c6a07","best_bid":"0.94","best_ask":"0.95"}],"timestamp":"1768250248181","event_type":"price_change"}}
{"schema_version":1,"source":"clob_ws_market","recv_ts_ns":1768250248212470969,"event_type":"price_change","market":"0xe51aa24ab1bbfefce466d642ad98587d13123e4ef95ec9aa73b712e775d4cbba","server_ts_ms":1768250248182,"raw":{"market":"0xe51aa24ab1bbfefce466d642ad98587d13123e4ef95ec9aa73b712e775d4cbba","price_changes":[{"asset_id":"54232589582260339592359130012520874109228367674780084862642636038394766871668","price":"0.01","size":"21162.86","side":"BUY","hash":"37c1f0f1df54885af0a71bbc63d600e14e5cc3b5","best_bid":"0.05","best_ask":"0.06"},{"asset_id":"96886111393998001968863279421729456597655847484197549086072988901191634450924","price":"0.99","size":"21162.86","side":"SELL","hash":"210d1616ae8cb65259bc20c178e149e8e8d8f87e","best_bid":"0.94","best_ask":"0.95"}],"timestamp":"1768250248182","event_type":"price_change"}}
{"schema_version":1,"source":"clob_ws_market","recv_ts_ns":1768250248219869312,"event_type":"price_change","market":"0xe51aa24ab1bbfefce466d642ad98587d13123e4ef95ec9aa73b712e775d4cbba","server_ts_ms":1768250248185,"raw":{"market":"0xe51aa24ab1bbfefce466d642ad98587d13123e4ef95ec9aa73b712e775d4cbba","price_changes":[{"asset_id":"54232589582260339592359130012520874109228367674780084862642636038394766871668","price":"0.01","size":"21178.86","side":"BUY","hash":"23d82941c5349e0e5e57297cbadc095f9ad9cc55","best_bid":"0.05","best_ask":"0.06"},{"asset_id":"96886111393998001968863279421729456597655847484197549086072988901191634450924","price":"0.99","size":"21178.86","side":"SELL","hash":"f48943774697794f3fd18a705c1b393ccee3619d","best_bid":"0.94","best_ask":"0.95"}],"timestamp":"1768250248185","event_type":"price_change"}}
{"schema_version":1,"source":"clob_ws_market","recv_ts_ns":1768250248222993444,"event_type":"price_change","market":"0xe51aa24ab1bbfefce466d642ad98587d13123e4ef95ec9aa73b712e775d4cbba","server_ts_ms":1768250248192,"raw":{"market":"0xe51aa24ab1bbfefce466d642ad98587d13123e4ef95ec9aa73b712e775d4cbba","price_changes":[{"asset_id":"96886111393998001968863279421729456597655847484197549086072988901191634450924","price":"0.94","size":"1823.21","side":"BUY","hash":"bc33a39afa43db886e30b98aeea19c4b867687f5","best_bid":"0.94","best_ask":"0.95"},{"asset_id":"54232589582260339592359130012520874109228367674780084862642636038394766871668","price":"0.06","size":"1823.21","side":"SELL","hash":"a42014bc099669ef4c4db652306149251c77b678","best_bid":"0.05","best_ask":"0.06"}],"timestamp":"1768250248192","event_type":"price_change"}}
{"schema_version":1,"source":"clob_ws_market","recv_ts_ns":1768250248225736126,"event_type":"price_change","market":"0xe51aa24ab1bbfefce466d642ad98587d13123e4ef95ec9aa73b712e775d4cbba","server_ts_ms":1768250248200,"raw":{"market":"0xe51aa24ab1bbfefce466d642ad98587d13123e4ef95ec9aa73b712e775d4cbba","price_changes":[{"asset_id":"54232589582260339592359130012520874109228367674780084862642636038394766871668","price":"0.02","size":"5377.25","side":"BUY","hash":"8fe8c68f85175aa79311e1cbd818c850af34d7de","best_bid":"0.05","best_ask":"0.06"},{"asset_id":"96886111393998001968863279421729456597655847484197549086072988901191634450924","price":"0.98","size":"5377.25","side":"SELL","hash":"58dde0d8cf2b5f5a0330246a3f967479417e8f05","best_bid":"0.94","best_ask":"0.95"}],"timestamp":"1768250248200","event_type":"price_change"}}
{"schema_version":1,"source":"clob_ws_market","recv_ts_ns":1768250248237661653,"event_type":"best_bid_ask","market":"0xe51aa24ab1bbfefce466d642ad98587d13123e4ef95ec9aa73b712e775d4cbba","server_ts_ms":1768250248215,"raw":{"market":"0xe51aa24ab1bbfefce466d642ad98587d13123e4ef95ec9aa73b712e775d4cbba","asset_id":"96886111393998001968863279421729456597655847484197549086072988901191634450924","best_bid":"0.94","best_ask":"0.96","spread":"0.02","timestamp":"1768250248215","event_type":"best_bid_ask"}}
{"schema_version":1,"source":"clob_ws_market","recv_ts_ns":1768250248239793711,"event_type":"price_change","market":"0xe51aa24ab1bbfefce466d642ad98587d13123e4ef95ec9aa73b712e775d4cbba","server_ts_ms":1768250248214,"raw":{"market":"0xe51aa24ab1bbfefce466d642ad98587d13123e4ef95ec9aa73b712e775d4cbba","price_changes":[{"asset_id":"54232589582260339592359130012520874109228367674780084862642636038394766871668","price":"0.05","size":"0","side":"BUY","hash":"ca9c067cba851e258be771279d785ec50aa6910b","best_bid":"0.04","best_ask":"0.06"},{"asset_id":"96886111393998001968863279421729456597655847484197549086072988901191634450924","price":"0.95","size":"0","side":"SELL","hash":"687ce5aa04e2f3c49a9d4d2d7730633dcfa39ece","best_bid":"0.94","best_ask":"0.96"}],"timestamp":"1768250248214","event_type":"price_change"}}
{"schema_version":1,"source":"clob_ws_market","recv_ts_ns":1768250248249191015,"event_type":"price_change","market":"0xe51aa24ab1bbfefce466d642ad98587d13123e4ef95ec9aa73b712e775d4cbba","server_ts_ms":1768250248216,"raw":{"market":"0xe51aa24ab1bbfefce466d642ad98587d13123e4ef95ec9aa73b712e775d4cbba","price_changes":[{"asset_id":"54232589582260339592359130012520874109228367674780084862642636038394766871668","price":"0.01","size":"21209.86","side":"BUY","hash":"432abf78b8176428d6e7ed017a1a817d8136f4f7","best_bid":"0.04","best_ask":"0.06"},{"asset_id":"96886111393998001968863279421729456597655847484197549086072988901191634450924","price":"0.99","size":"21209.86","side":"SELL","hash":"b4b47768cd3df7205582d38e8401421d8e3f56f2","best_bid":"0.94","best_ask":"0.96"}],"timestamp":"1768250248216","event_type":"price_change"}}
{"schema_version":1,"source":"clob_ws_market","recv_ts_ns":1768250248261915876,"event_type":"price_change","market":"0xe51aa24ab1bbfefce466d642ad98587d13123e4ef95ec9aa73b712e775d4cbba","server_ts_ms":1768250248240,"raw":{"market":"0xe51aa24ab1bbfefce466d642ad98587d13123e4ef95ec9aa73b712e775d4cbba","price_changes":[{"asset_id":"96886111393998001968863279421729456597655847484197549086072988901191634450924","price":"0.93","size":"1386.32","side":"BUY","hash":"031c6384ecd4c9d96c1764b1cf906b090b47cf47","best_bid":"0.94","best_ask":"0.96"},{"asset_id":"54232589582260339592359130012520874109228367674780084862642636038394766871668","price":"0.07","size":"1386.32","side":"SELL","hash":"ae074c46fa9771527a9c8994ee03eb7da107e85c","best_bid":"0.04","best_ask":"0.06"}],"timestamp":"1768250248240","event_type":"price_change"}}
{"schema_version":1,"source":"clob_ws_market","recv_ts_ns":1768250248279824296,"event_type":"price_change","market":"0xe51aa24ab1bbfefce466d642ad98587d13123e4ef95ec9aa73b712e775d4cbba","server_ts_ms":1768250248250,"raw":{"market":"0xe51aa24ab1bbfefce466d642ad98587d13123e4ef95ec9aa73b712e775d4cbba","price_changes":[{"asset_id":"96886111393998001968863279421729456597655847484197549086072988901191634450924","price":"0.93","size":"1380.82","side":"BUY","hash":"3dc293c2086f1a27d3cc962647af6917cb885997","best_bid":"0.94","best_ask":"0.96"},{"asset_id":"54232589582260339592359130012520874109228367674780084862642636038394766871668","price":"0.07","size":"1380.82","side":"SELL","hash":"e6c908c37a8d953e4c219df4a3debe27072e6370","best_bid":"0.04","best_ask":"0.06"}],"timestamp":"1768250248250","event_type":"price_change"}}
{"schema_version":1,"source":"clob_ws_market","recv_ts_ns":1768250248284970186,"event_type":"price_change","market":"0xe51aa24ab1bbfefce466d642ad98587d13123e4ef95ec9aa73b712e775d4cbba","server_ts_ms":1768250248255,"raw":{"market":"0xe51aa24ab1bbfefce466d642ad98587d13123e4ef95ec9aa73b712e775d4cbba","price_changes":[{"asset_id":"54232589582260339592359130012520874109228367674780084862642636038394766871668","price":"0.01","size":"21109.86","side":"BUY","hash":"63c170493bad5f9d1180b246f6ecab902497aab2","best_bid":"0.04","best_ask":"0.06"},{"asset_id":"96886111393998001968863279421729456597655847484197549086072988901191634450924","price":"0.99","size":"21109.86","side":"SELL","hash":"86350bb50d893e0d486ce854f7b2339022e9d7f0","best_bid":"0.94","best_ask":"0.96"}],"timestamp":"1768250248255","event_type":"price_change"}}
{"schema_version":1,"source":"clob_ws_market","recv_ts_ns":1768250248289907831,"event_type":"price_change","market":"0xe51aa24ab1bbfefce466d642ad98587d13123e4ef95ec9aa73b712e775d4cbba","server_ts_ms":1768250248256,"raw":{"market":"0xe51aa24ab1bbfefce466d642ad98587d13123e4ef95ec9aa73b712e775d4cbba","price_changes":[{"asset_id":"96886111393998001968863279421729456597655847484197549086072988901191634450924","price":"0.93","size":"1375.32","side":"BUY","hash":"2653781331a1f19f3b8f178ea3fa4250642ba61b","best_bid":"0.94","best_ask":"0.96"},{"asset_id":"54232589582260339592359130012520874109228367674780084862642636038394766871668","price":"0.07","size":"1375.32","side":"SELL","hash":"b975afbcba54f9372e2b16786256f2ed3b200867","best_bid":"0.04","best_ask":"0.06"}],"timestamp":"1768250248256","event_type":"price_change"}}
{"schema_version":1,"source":"clob_ws_market","recv_ts_ns":1768250248294392284,"event_type":"price_change","market":"0xe51aa24ab1bbfefce466d642ad98587d13123e4ef95ec9aa73b712e775d4cbba","server_ts_ms":1768250248263,"raw":{"market":"0xe51aa24ab1bbfefce466d642ad98587d13123e4ef95ec9aa73b712e775d4cbba","price_changes":[{"asset_id":"96886111393998001968863279421729456597655847484197549086072988901191634450924","price":"0.93","size":"1369.82","side":"BUY","hash":"46c1b8a5d79555248f74cf5d6cb702e383617a40","best_bid":"0.94","best_ask":"0.96"},{"asset_id":"54232589582260339592359130012520874109228367674780084862642636038394766871668","price":"0.07","size":"1369.82","side":"SELL","hash":"e5a0207c94564a66047fbbb7d8f3a2408e06d1b2","best_bid":"0.04","best_ask":"0.06"}],"timestamp":"1768250248263","event_type":"price_change"}}
{"schema_version":1,"source":"clob_ws_market","recv_ts_ns":1768250248297648818,"event_type":"price_change","market":"0xe51aa24ab1bbfefce466d642ad98587d13123e4ef95ec9aa73b712e775d4cbba","server_ts_ms":1768250248265,"raw":{"market":"0xe51aa24ab1bbfefce466d642ad98587d13123e4ef95ec9aa73b712e775d4cbba","price_changes":[{"asset_id":"96886111393998001968863279421729456597655847484197549086072988901191634450924","price":"0.94","size":"1803.21","side":"BUY","hash":"bd15ff5c5acd7daebc065429540055d4914a52b5","best_bid":"0.94","best_ask":"0.96"},{"asset_id":"54232589582260339592359130012520874109228367674780084862642636038394766871668","price":"0.06","size":"1803.21","side":"SELL","hash":"55238448cf37b955cce172287d4feb7f293c9a0b","best_bid":"0.04","best_ask":"0.06"}],"timestamp":"1768250248265","event_type":"price_change"}}
{"schema_version":1,"source":"clob_ws_market","recv_ts_ns":1768250248301374700,"event_type":"price_change","market":"0xe51aa24ab1bbfefce466d642ad98587d13123e4ef95ec9aa73b712e775d4cbba","server_ts_ms":1768250248266,"raw":{"market":"0xe51aa24ab1bbfefce466d642ad98587d13123e4ef95ec9aa73b712e775d4cbba","price_changes":[{"asset_id":"54232589582260339592359130012520874109228367674780084862642636038394766871668","price":"0.02","size":"5477.25","side":"BUY","hash":"34285fd79153f473ff9bd37c0e24f108bf976f2b","best_bid":"0.04","best_ask":"0.06"},{"asset_id":"96886111393998001968863279421729456597655847484197549086072988901191634450924","price":"0.98","size":"5477.25","side":"SELL","hash":"3d2f454bbbeccd08c274cc256d35e9d27ebf2ec0","best_bid":"0.94","best_ask":"0.96"}],"timestamp":"1768250248266","event_type":"price_change"}}
{"schema_version":1,"source":"clob_ws_market","recv_ts_ns":1768250248304679432,"event_type":"price_change","market":"0xe51aa24ab1bbfefce466d642ad98587d13123e4ef95ec9aa73b712e775d4cbba","server_ts_ms":1768250248268,"raw":{"market":"0xe51aa24ab1bbfefce466d642ad98587d13123e4ef95ec9aa73b712e775d4cbba","price_changes":[{"asset_id":"96886111393998001968863279421729456597655847484197549086072988901191634450924","price":"0.94","size":"1808.71","side":"BUY","hash":"55f7022e1c495a169395620dbb30d6f427627e21","best_bid":"0.94","best_ask":"0.96"},{"asset_id":"54232589582260339592359130012520874109228367674780084862642636038394766871668","price":"0.06","size":"1808.71","side":"SELL","hash":"34916bc87773f22ab4d9806474f4dc6eabd01191","best_bid":"0.04","best_ask":"0.06"}],"timestamp":"1768250248268","event_type":"price_change"}}
{"schema_version":1,"source":"clob_ws_market","recv_ts_ns":1768250248308675529,"event_type":"price_change","market":"0xe51aa24ab1bbfefce466d642ad98587d13123e4ef95ec9aa73b712e775d4cbba","server_ts_ms":1768250248270,"raw":{"market":"0xe51aa24ab1bbfefce466d642ad98587d13123e4ef95ec9aa73b712e775d4cbba","price_changes":[{"asset_id":"96886111393998001968863279421729456597655847484197549086072988901191634450924","price":"0.93","size":"1364.32","side":"BUY","hash":"13d77aa0a319c59184abad56d7a4cd7ca618abd0","best_bid":"0.94","best_ask":"0.96"},{"asset_id":"54232589582260339592359130012520874109228367674780084862642636038394766871668","price":"0.07","size":"1364.32","side":"SELL","hash":"270cd833097ef4b1289e923722197a1d6133f166","best_bid":"0.04","best_ask":"0.06"}],"timestamp":"1768250248270","event_type":"price_change"}}
{"schema_version":1,"source":"clob_ws_market","recv_ts_ns":1768250248313296985,"event_type":"best_bid_ask","market":"0xe51aa24ab1bbfefce466d642ad98587d13123e4ef95ec9aa73b712e775d4cbba","server_ts_ms":1768250248278,"raw":{"market":"0xe51aa24ab1bbfefce466d642ad98587d13123e4ef95ec9aa73b712e775d4cbba","asset_id":"96886111393998001968863279421729456597655847484197549086072988901191634450924","best_bid":"0.95","best_ask":"0.96","spread":"0.01","timestamp":"1768250248278","event_type":"best_bid_ask"}}
{"schema_version":1,"source":"clob_ws_market","recv_ts_ns":1768250248314559421,"event_type":"price_change","market":"0xe51aa24ab1bbfefce466d642ad98587d13123e4ef95ec9aa73b712e775d4cbba","server_ts_ms":1768250248277,"raw":{"market":"0xe51aa24ab1bbfefce466d642ad98587d13123e4ef95ec9aa73b712e775d4cbba","price_changes":[{"asset_id":"96886111393998001968863279421729456597655847484197549086072988901191634450924","price":"0.95","size":"20","side":"BUY","hash":"480267fd4a5ec2f359df1673944305a35b11551f","best_bid":"0.95","best_ask":"0.96"},{"asset_id":"54232589582260339592359130012520874109228367674780084862642636038394766871668","price":"0.05","size":"20","side":"SELL","hash":"980ed7a1aa83b09521419b3a317a114787d2e50e","best_bid":"0.04","best_ask":"0.05"}],"timestamp":"1768250248277","event_type":"price_change"}}
{"schema_version":1,"source":"clob_ws_market","recv_ts_ns":1768250248324786071,"event_type":"price_change","market":"0xe51aa24ab1bbfefce466d642ad98587d13123e4ef95ec9aa73b712e775d4cbba","server_ts_ms":1768250248301,"raw":{"market":"0xe51aa24ab1bbfefce466d642ad98587d13123e4ef95ec9aa73b712e775d4cbba","price_changes":[{"asset_id":"96886111393998001968863279421729456597655847484197549086072988901191634450924","price":"0.95","size":"25.5","side":"BUY","hash":"4db684835b00ab5c785b8fb06458698fdcc37cee","best_bid":"0.95","best_ask":"0.96"},{"asset_id":"54232589582260339592359130012520874109228367674780084862642636038394766871668","price":"0.05","size":"25.5","side":"SELL","hash":"b406763f3ddb52b796d11195263edab907ffa3bc","best_bid":"0.04","best_ask":"0.05"}],"timestamp":"1768250248301","event_type":"price_change"}}
{"schema_version":1,"source":"clob_ws_market","recv_ts_ns":1768250248330589982,"event_type":"price_change","market":"0xe51aa24ab1bbfefce466d642ad98587d13123e4ef95ec9aa73b712e775d4cbba","server_ts_ms":1768250248303,"raw":{"market":"0xe51aa24ab1bbfefce466d642ad98587d13123e4ef95ec9aa73b712e775d4cbba","price_changes":[{"asset_id":"96886111393998001968863279421729456597655847484197549086072988901191634450924","price":"0.94","size":"1814.21","side":"BUY","hash":"3d2440c785cbbbc168b4dd521b24e0696c94ff59","best_bid":"0.95","best_ask":"0.96"},{"asset_id":"54232589582260339592359130012520874109228367674780084862642636038394766871668","price":"0.06","size":"1814.21","side":"SELL","hash":"b44d1a2e25caeb96f6618e701c4d5551d881545e","best_bid":"0.04","best_ask":"0.05"}],"timestamp":"1768250248303","event_type":"price_change"}}
{"schema_version":1,"source":"clob_ws_market","recv_ts_ns":1768250248341103132,"event_type":"price_change","market":"0xe51aa24ab1bbfefce466d642ad98587d13123e4ef95ec9aa73b712e775d4cbba","server_ts_ms":1768250248312,"raw":{"market":"0xe51aa24ab1bbfefce466d642ad98587d13123e4ef95ec9aa73b712e775d4cbba","price_changes":[{"asset_id":"96886111393998001968863279421729456597655847484197549086072988901191634450924","price":"0.94","size":"1819.71","side":"BUY","hash":"6abf36b24d30f9fae06dabbe708a397da4d92a8b","best_bid":"0.95","best_ask":"0.96"},{"asset_id":"54232589582260339592359130012520874109228367674780084862642636038394766871668","price":"0.06","size":"1819.71","side":"SELL","hash":"95d7a476d1cf4e51648a96dd78d01d297fea2af8","best_bid":"0.04","best_ask":"0.05"}],"timestamp":"1768250248312","event_type":"price_change"}}
{"schema_version":1,"source":"clob_ws_market","recv_ts_ns":1768250248368925097,"event_type":"price_change","market":"0xe51aa24ab1bbfefce466d642ad98587d13123e4ef95ec9aa73b712e775d4cbba","server_ts_ms":1768250248335,"raw":{"market":"0xe51aa24ab1bbfefce466d642ad98587d13123e4ef95ec9aa73b712e775d4cbba","price_changes":[{"asset_id":"96886111393998001968863279421729456597655847484197549086072988901191634450924","price":"0.94","size":"1814.21","side":"BUY","hash":"76a709ff60b3a322b8bd529338b8bf5576818de4","best_bid":"0.95","best_ask":"0.96"},{"asset_id":"54232589582260339592359130012520874109228367674780084862642636038394766871668","price":"0.06","size":"1814.21","side":"SELL","hash":"4ce334c40475791974d3e973a7864d4b3b11d8d1","best_bid":"0.04","best_ask":"0.05"}],"timestamp":"1768250248335","event_type":"price_change"}}
{"schema_version":1,"source":"clob_ws_market","recv_ts_ns":1768250248393973276,"event_type":"price_change","market":"0xe51aa24ab1bbfefce466d642ad98587d13123e4ef95ec9aa73b712e775d4cbba","server_ts_ms":1768250248362,"raw":{"market":"0xe51aa24ab1bbfefce466d642ad98587d13123e4ef95ec9aa73b712e775d4cbba","price_changes":[{"asset_id":"96886111393998001968863279421729456597655847484197549086072988901191634450924","price":"0.95","size":"31","side":"BUY","hash":"8b18422437ef3b8a374fedf65c3a77787e9616f6","best_bid":"0.95","best_ask":"0.96"},{"asset_id":"54232589582260339592359130012520874109228367674780084862642636038394766871668","price":"0.05","size":"31","side":"SELL","hash":"ebfd3a531e6a31dea267bd83fc283e5585ee3d00","best_bid":"0.04","best_ask":"0.05"}],"timestamp":"1768250248362","event_type":"price_change"}}
{"schema_version":1,"source":"clob_ws_market","recv_ts_ns":1768250248399202512,"event_type":"price_change","market":"0xe51aa24ab1bbfefce466d642ad98587d13123e4ef95ec9aa73b712e775d4cbba","server_ts_ms":1768250248366,"raw":{"market":"0xe51aa24ab1bbfefce466d642ad98587d13123e4ef95ec9aa73b712e775d4cbba","price_changes":[{"asset_id":"54232589582260339592359130012520874109228367674780084862642636038394766871668","price":"0.06","size":"1834.21","side":"SELL","hash":"9ccc0559f3770d8f20f76893d82eff4a260f9cd2","best_bid":"0.04","best_ask":"0.05"},{"asset_id":"96886111393998001968863279421729456597655847484197549086072988901191634450924","price":"0.94","size":"1834.21","side":"BUY","hash":"660be351a7b9c8f11b74548c2809abeab4e0d2e5","best_bid":"0.95","best_ask":"0.96"}],"timestamp":"1768250248366","event_type":"price_change"}}
{"schema_version":1,"source":"clob_ws_market","recv_ts_ns":1768250248408602550,"event_type":"price_change","market":"0xe51aa24ab1bbfefce466d642ad98587d13123e4ef95ec9aa73b712e775d4cbba","server_ts_ms":1768250248367,"raw":{"market":"0xe51aa24ab1bbfefce466d642ad98587d13123e4ef95ec9aa73b712e775d4cbba","price_changes":[{"asset_id":"54232589582260339592359130012520874109228367674780084862642636038394766871668","price":"0.06","size":"1814.21","side":"SELL","hash":"15e793d9681a5487da55ca3239bbf43a401ea046","best_bid":"0.04","best_ask":"0.05"},{"asset_id":"96886111393998001968863279421729456597655847484197549086072988901191634450924","price":"0.94","size":"1814.21","side":"BUY","hash":"238c1bd5ede2a00302554514842a088d65d691cd","best_bid":"0.95","best_ask":"0.96"}],"timestamp":"1768250248367","event_type":"price_change"}}
{"schema_version":1,"source":"clob_ws_market","recv_ts_ns":1768250248413691941,"event_type":"price_change","market":"0xe51aa24ab1bbfefce466d642ad98587d13123e4ef95ec9aa73b712e775d4cbba","server_ts_ms":1768250248371,"raw":{"market":"0xe51aa24ab1bbfefce466d642ad98587d13123e4ef95ec9aa73b712e775d4cbba","price_changes":[{"asset_id":"96886111393998001968863279421729456597655847484197549086072988901191634450924","price":"0.95","size":"67","side":"BUY","hash":"b787d7c803d2e37b14e64a50d2bc9fdd9b4d7a77","best_bid":"0.95","best_ask":"0.96"},{"asset_id":"54232589582260339592359130012520874109228367674780084862642636038394766871668","price":"0.05","size":"67","side":"SELL","hash":"8c9beec8864f7a3f07e8a830a199ec435aa168fd","best_bid":"0.04","best_ask":"0.05"}],"timestamp":"1768250248371","event_type":"price_change"}}
{"schema_version":1,"source":"clob_ws_market","recv_ts_ns":1768250248419943510,"event_type":"price_change","market":"0xe51aa24ab1bbfefce466d642ad98587d13123e4ef95ec9aa73b712e775d4cbba","server_ts_ms":1768250248372,"raw":{"market":"0xe51aa24ab1bbfefce466d642ad98587d13123e4ef95ec9aa73b712e775d4cbba","price_changes":[{"asset_id":"96886111393998001968863279421729456597655847484197549086072988901191634450924","price":"0.95","size":"79","side":"BUY","hash":"ec2f82a750c77e032abf5cf7da6847982f94b208","best_bid":"0.95","best_ask":"0.96"},{"asset_id":"54232589582260339592359130012520874109228367674780084862642636038394766871668","price":"0.05","size":"79","side":"SELL","hash":"75a11fdd832e4d526d749110682124ca796ecb7c","best_bid":"0.04","best_ask":"0.05"}],"timestamp":"1768250248372","event_type":"price_change"}}
{"schema_version":1,"source":"clob_ws_market","recv_ts_ns":1768250248425153310,"event_type":"price_change","market":"0xe51aa24ab1bbfefce466d642ad98587d13123e4ef95ec9aa73b712e775d4cbba","server_ts_ms":1768250248377,"raw":{"market":"0xe51aa24ab1bbfefce466d642ad98587d13123e4ef95ec9aa73b712e775d4cbba","price_changes":[{"asset_id":"96886111393998001968863279421729456597655847484197549086072988901191634450924","price":"0.95","size":"98","side":"BUY","hash":"88538ceef158b583d1646478ad08f2cf79a01f2a","best_bid":"0.95","best_ask":"0.96"},{"asset_id":"54232589582260339592359130012520874109228367674780084862642636038394766871668","price":"0.05","size":"98","side":"SELL","hash":"fc3e4fd731fac90a4db66324164c7cbacc11fb8e","best_bid":"0.04","best_ask":"0.05"}],"timestamp":"1768250248377","event_type":"price_change"}}
{"schema_version":1,"source":"clob_ws_market","recv_ts_ns":1768250248430388098,"event_type":"price_change","market":"0xe51aa24ab1bbfefce466d642ad98587d13123e4ef95ec9aa73b712e775d4cbba","server_ts_ms":1768250248394,"raw":{"market":"0xe51aa24ab1bbfefce466d642ad98587d13123e4ef95ec9aa73b712e775d4cbba","price_changes":[{"asset_id":"96886111393998001968863279421729456597655847484197549086072988901191634450924","price":"0.94","size":"1819.21","side":"BUY","hash":"5a8f499bd4225abb7b7674575cc770c0b6b38955","best_bid":"0.95","best_ask":"0.96"},{"asset_id":"54232589582260339592359130012520874109228367674780084862642636038394766871668","price":"0.06","size":"1819.21","side":"SELL","hash":"181dd0918f37befee513d11aba30244c6fae3420","best_bid":"0.04","best_ask":"0.05"}],"timestamp":"1768250248394","event_type":"price_change"}}
{"schema_version":1,"source":"clob_ws_market","recv_ts_ns":1768250248434309278,"event_type":"price_change","market":"0xe51aa24ab1bbfefce466d642ad98587d13123e4ef95ec9aa73b712e775d4cbba","server_ts_ms":1768250248396,"raw":{"market":"0xe51aa24ab1bbfefce466d642ad98587d13123e4ef95ec9aa73b712e775d4cbba","price_changes":[{"asset_id":"96886111393998001968863279421729456597655847484197549086072988901191634450924","price":"0.94","size":"1795.21","side":"BUY","hash":"f778e60d5938e6aff6f4af45da5f135ec65c3651","best_bid":"0.95","best_ask":"0.96"},{"asset_id":"54232589582260339592359130012520874109228367674780084862642636038394766871668","price":"0.06","size":"1795.21","side":"SELL","hash":"ef00f865ba8ab71ada38a66fd520ea25f0d1e076","best_bid":"0.04","best_ask":"0.05"}],"timestamp":"1768250248396","event_type":"price_change"}}
{"schema_version":1,"source":"clob_ws_market","recv_ts_ns":1768250248437728836,"event_type":"price_change","market":"0xe51aa24ab1bbfefce466d642ad98587d13123e4ef95ec9aa73b712e775d4cbba","server_ts_ms":1768250248401,"raw":{"market":"0xe51aa24ab1bbfefce466d642ad98587d13123e4ef95ec9aa73b712e775d4cbba","price_changes":[{"asset_id":"96886111393998001968863279421729456597655847484197549086072988901191634450924","price":"0.94","size":"1787.21","side":"BUY","hash":"e78137173608bf2823c3e0e63d0bb0ea96fe450e","best_bid":"0.95","best_ask":"0.96"},{"asset_id":"54232589582260339592359130012520874109228367674780084862642636038394766871668","price":"0.06","size":"1787.21","side":"SELL","hash":"fd36ee3591f03a089820436dc15e20d6aee86305","best_bid":"0.04","best_ask":"0.05"}],"timestamp":"1768250248401","event_type":"price_change"}}
{"schema_version":1,"source":"clob_ws_market","recv_ts_ns":1768250248440510152,"event_type":"price_change","market":"0xe51aa24ab1bbfefce466d642ad98587d13123e4ef95ec9aa73b712e775d4cbba","server_ts_ms":1768250248403,"raw":{"market":"0xe51aa24ab1bbfefce466d642ad98587d13123e4ef95ec9aa73b712e775d4cbba","price_changes":[{"asset_id":"96886111393998001968863279421729456597655847484197549086072988901191634450924","price":"0.95","size":"103.5","side":"BUY","hash":"1155bc2039342502efd3397e02f191b28a546179","best_bid":"0.95","best_ask":"0.96"},{"asset_id":"54232589582260339592359130012520874109228367674780084862642636038394766871668","price":"0.05","size":"103.5","side":"SELL","hash":"67d67ee810eb17287ab736d2c4a9612afba16361","best_bid":"0.04","best_ask":"0.05"}],"timestamp":"1768250248403","event_type":"price_change"}}
{"schema_version":1,"source":"clob_ws_market","recv_ts_ns":1768250248447253630,"event_type":"price_change","market":"0xe51aa24ab1bbfefce466d642ad98587d13123e4ef95ec9aa73b712e775d4cbba","server_ts_ms":1768250248410,"raw":{"market":"0xe51aa24ab1bbfefce466d642ad98587d13123e4ef95ec9aa73b712e775d4cbba","price_changes":[{"asset_id":"96886111393998001968863279421729456597655847484197549086072988901191634450924","price":"0.94","size":"1775.21","side":"BUY","hash":"319fbf1cdec16a727c6870345ac9b46ef4516222","best_bid":"0.95","best_ask":"0.96"},{"asset_id":"54232589582260339592359130012520874109228367674780084862642636038394766871668","price":"0.06","size":"1775.21","side":"SELL","hash":"5f00429640b6a0f47731a389fe13807a73d15806","best_bid":"0.04","best_ask":"0.05"}],"timestamp":"1768250248410","event_type":"price_change"}}
{"schema_version":1,"source":"clob_ws_market","recv_ts_ns":1768250248464153620,"event_type":"price_change","market":"0xe51aa24ab1bbfefce466d642ad98587d13123e4ef95ec9aa73b712e775d4cbba","server_ts_ms":1768250248442,"raw":{"market":"0xe51aa24ab1bbfefce466d642ad98587d13123e4ef95ec9aa73b712e775d4cbba","price_changes":[{"asset_id":"96886111393998001968863279421729456597655847484197549086072988901191634450924","price":"0.94","size":"1767.69","side":"BUY","hash":"ef82085e4c09437916d964cb002280eab706b35c","best_bid":"0.95","best_ask":"0.96"},{"asset_id":"54232589582260339592359130012520874109228367674780084862642636038394766871668","price":"0.06","size":"1767.69","side":"SELL","hash":"9e03dbd1c5a45aabcdddd463e79a587041177250","best_bid":"0.04","best_ask":"0.05"}],"timestamp":"1768250248442","event_type":"price_change"}}
{"schema_version":1,"source":"clob_ws_market","recv_ts_ns":1768250248470901719,"event_type":"price_change","market":"0xe51aa24ab1bbfefce466d642ad98587d13123e4ef95ec9aa73b712e775d4cbba","server_ts_ms":1768250248446,"raw":{"market":"0xe51aa24ab1bbfefce466d642ad98587d13123e4ef95ec9aa73b712e775d4cbba","price_changes":[{"asset_id":"96886111393998001968863279421729456597655847484197549086072988901191634450924","price":"0.94","size":"1760.69","side":"BUY","hash":"124dfedb825f56a78f00e146380a027afde34b09","best_bid":"0.95","best_ask":"0.96"},{"asset_id":"54232589582260339592359130012520874109228367674780084862642636038394766871668","price":"0.06","size":"1760.69","side":"SELL","hash":"2cbabd8afe8285edb5abe325df8e1fb45f413004","best_bid":"0.04","best_ask":"0.05"}],"timestamp":"1768250248446","event_type":"price_change"}}
{"schema_version":1,"source":"clob_ws_market","recv_ts_ns":1768250248519698901,"event_type":"price_change","market":"0xe51aa24ab1bbfefce466d642ad98587d13123e4ef95ec9aa73b712e775d4cbba","server_ts_ms":1768250248493,"raw":{"market":"0xe51aa24ab1bbfefce466d642ad98587d13123e4ef95ec9aa73b712e775d4cbba","price_changes":[{"asset_id":"96886111393998001968863279421729456597655847484197549086072988901191634450924","price":"0.95","size":"110.5","side":"BUY","hash":"44b79adf76ab9ff6d8c74133f37eddc30d9a4cd2","best_bid":"0.95","best_ask":"0.96"},{"asset_id":"54232589582260339592359130012520874109228367674780084862642636038394766871668","price":"0.05","size":"110.5","side":"SELL","hash":"0d2d2c8b328d537c077e35f67f8c17d099abb8ff","best_bid":"0.04","best_ask":"0.05"}],"timestamp":"1768250248493","event_type":"price_change"}}
{"schema_version":1,"source":"clob_ws_market","recv_ts_ns":1768250248539233709,"event_type":"price_change","market":"0xe51aa24ab1bbfefce466d642ad98587d13123e4ef95ec9aa73b712e775d4cbba","server_ts_ms":1768250248517,"raw":{"market":"0xe51aa24ab1bbfefce466d642ad98587d13123e4ef95ec9aa73b712e775d4cbba","price_changes":[{"asset_id":"96886111393998001968863279421729456597655847484197549086072988901191634450924","price":"0.95","size":"115.5","side":"BUY","hash":"b0103cda32d95af72c7e3fda7897c3dd09d460a8","best_bid":"0.95","best_ask":"0.96"},{"asset_id":"54232589582260339592359130012520874109228367674780084862642636038394766871668","price":"0.05","size":"115.5","side":"SELL","hash":"28ee5f23e14cfa4375c567c99b0f02e18bced41a","best_bid":"0.04","best_ask":"0.05"}],"timestamp":"1768250248517","event_type":"price_change"}}
{"schema_version":1,"source":"clob_ws_market","recv_ts_ns":1768250248544772778,"event_type":"price_change","market":"0xe51aa24ab1bbfefce466d642ad98587d13123e4ef95ec9aa73b712e775d4cbba","server_ts_ms":1768250248519,"raw":{"market":"0xe51aa24ab1bbfefce466d642ad98587d13123e4ef95ec9aa73b712e775d4cbba","price_changes":[{"asset_id":"96886111393998001968863279421729456597655847484197549086072988901191634450924","price":"0.97","size":"1207.6","side":"SELL","hash":"4be4674c98923462cfa7e4e959923632838215e9","best_bid":"0.95","best_ask":"0.96"},{"asset_id":"54232589582260339592359130012520874109228367674780084862642636038394766871668","price":"0.03","size":"1207.6","side":"BUY","hash":"12f52b8a197af81b59fd15de052be57176e16d92","best_bid":"0.04","best_ask":"0.05"}],"timestamp":"1768250248519","event_type":"price_change"}}
{"schema_version":1,"source":"clob_ws_market","recv_ts_ns":1768250248614594248,"event_type":"price_change","market":"0xe51aa24ab1bbfefce466d642ad98587d13123e4ef95ec9aa73b712e775d4cbba","server_ts_ms":1768250248568,"raw":{"market":"0xe51aa24ab1bbfefce466d642ad98587d13123e4ef95ec9aa73b712e775d4cbba","price_changes":[{"asset_id":"96886111393998001968863279421729456597655847484197549086072988901191634450924","price":"0.95","size":"120.5","side":"BUY","hash":"d0b17dca4433902a2e1f9571b9c9a66d1cc5cf86","best_bid":"0.95","best_ask":"0.96"},{"asset_id":"54232589582260339592359130012520874109228367674780084862642636038394766871668","price":"0.05","size":"120.5","side":"SELL","hash":"e832f235139785e75e731bff3e31bdd02c682d73","best_bid":"0.04","best_ask":"0.05"}],"timestamp":"1768250248568","event_type":"price_change"}}
{"schema_version":1,"source":"clob_ws_market","recv_ts_ns":1768250248644921235,"event_type":"price_change","market":"0xe51aa24ab1bbfefce466d642ad98587d13123e4ef95ec9aa73b712e775d4cbba","server_ts_ms":1768250248586,"raw":{"market":"0xe51aa24ab1bbfefce466d642ad98587d13123e4ef95ec9aa73b712e775d4cbba","price_changes":[{"asset_id":"96886111393998001968863279421729456597655847484197549086072988901191634450924","price":"0.95","size":"108.5","side":"BUY","hash":"febb127ab02fcdf3970837c7031a9d9b371384d1","best_bid":"0.95","best_ask":"0.96"},{"asset_id":"54232589582260339592359130012520874109228367674780084862642636038394766871668","price":"0.05","size":"108.5","side":"SELL","hash":"6ba99b20f9c2333147e8391d494935db9e104959","best_bid":"0.04","best_ask":"0.05"}],"timestamp":"1768250248586","event_type":"price_change"}}
{"schema_version":1,"source":"clob_ws_market","recv_ts_ns":1768250248660546800,"event_type":"price_change","market":"0xe51aa24ab1bbfefce466d642ad98587d13123e4ef95ec9aa73b712e775d4cbba","server_ts_ms":1768250248591,"raw":{"market":"0xe51aa24ab1bbfefce466d642ad98587d13123e4ef95ec9aa73b712e775d4cbba","price_changes":[{"asset_id":"96886111393998001968863279421729456597655847484197549086072988901191634450924","price":"0.95","size":"123.5","side":"BUY","hash":"85943357d9883c5a135b1ee19cea62e3a46ea152","best_bid":"0.95","best_ask":"0.96"},{"asset_id":"54232589582260339592359130012520874109228367674780084862642636038394766871668","price":"0.05","size":"123.5","side":"SELL","hash":"5c5063dc2c4aedcbfd4631fd1bf62e2629937fc8","best_bid":"0.04","best_ask":"0.05"}],"timestamp":"1768250248591","event_type":"price_change"}}
{"schema_version":1,"source":"clob_ws_market","recv_ts_ns":1768250248664283588,"event_type":"price_change","market":"0xe51aa24ab1bbfefce466d642ad98587d13123e4ef95ec9aa73b712e775d4cbba","server_ts_ms":1768250248592,"raw":{"market":"0xe51aa24ab1bbfefce466d642ad98587d13123e4ef95ec9aa73b712e775d4cbba","price_changes":[{"asset_id":"54232589582260339592359130012520874109228367674780084862642636038394766871668","price":"0.05","size":"136.5","side":"SELL","hash":"f49e23d4b3ee934458dea20c0f1d4e7b7cddb6f4","best_bid":"0.04","best_ask":"0.05"},{"asset_id":"96886111393998001968863279421729456597655847484197549086072988901191634450924","price":"0.95","size":"136.5","side":"BUY","hash":"f1f19427b741344e600964ee71cbe4a93d1fff52","best_bid":"0.95","best_ask":"0.96"}],"timestamp":"1768250248592","event_type":"price_change"}}
{"schema_version":1,"source":"clob_ws_market","recv_ts_ns":1768250248667633471,"event_type":"price_change","market":"0xe51aa24ab1bbfefce466d642ad98587d13123e4ef95ec9aa73b712e775d4cbba","server_ts_ms":1768250248593,"raw":{"market":"0xe51aa24ab1bbfefce466d642ad98587d13123e4ef95ec9aa73b712e775d4cbba","price_changes":[{"asset_id":"96886111393998001968863279421729456597655847484197549086072988901191634450924","price":"0.95","size":"100.5","side":"BUY","hash":"d040080460d32a90f47ce4f510e31a3041cfe8e9","best_bid":"0.95","best_ask":"0.96"},{"asset_id":"54232589582260339592359130012520874109228367674780084862642636038394766871668","price":"0.05","size":"100.5","side":"SELL","hash":"18728693921bb142a08bb08609c4625e75d46107","best_bid":"0.04","best_ask":"0.05"}],"timestamp":"1768250248593","event_type":"price_change"}}
{"schema_version":1,"source":"clob_ws_market","recv_ts_ns":1768250248674524427,"event_type":"price_change","market":"0xe51aa24ab1bbfefce466d642ad98587d13123e4ef95ec9aa73b712e775d4cbba","server_ts_ms":1768250248599,"raw":{"market":"0xe51aa24ab1bbfefce466d642ad98587d13123e4ef95ec9aa73b712e775d4cbba","price_changes":[{"asset_id":"54232589582260339592359130012520874109228367674780084862642636038394766871668","price":"0.03","size":"1223.6","side":"BUY","hash":"0597d192497ddff89b877dc392b7080bc8b73617","best_bid":"0.04","best_ask":"0.05"},{"asset_id":"96886111393998001968863279421729456597655847484197549086072988901191634450924","price":"0.97","size":"1223.6","side":"SELL","hash":"9dfa6c67c24b019929689b47a21503d3d0f95c02","best_bid":"0.95","best_ask":"0.96"}],"timestamp":"1768250248599","event_type":"price_change"}}
{"schema_version":1,"source":"clob_ws_market","recv_ts_ns":1768250248677364434,"event_type":"price_change","market":"0xe51aa24ab1bbfefce466d642ad98587d13123e4ef95ec9aa73b712e775d4cbba","server_ts_ms":1768250248599,"raw":{"market":"0xe51aa24ab1bbfefce466d642ad98587d13123e4ef95ec9aa73b712e775d4cbba","price_changes":[{"asset_id":"96886111393998001968863279421729456597655847484197549086072988901191634450924","price":"0.95","size":"81.5","side":"BUY","hash":"ff07f929fda7b721837de609f613c1384e928ed8","best_bid":"0.95","best_ask":"0.96"},{"asset_id":"54232589582260339592359130012520874109228367674780084862642636038394766871668","price":"0.05","size":"81.5","side":"SELL","hash":"68bb0166755200c4945fb2d63275ef8ccb5c0437","best_bid":"0.04","best_ask":"0.05"}],"timestamp":"1768250248599","event_type":"price_change"}}
{"schema_version":1,"source":"clob_ws_market","recv_ts_ns":1768250248682384181,"event_type":"price_change","market":"0xe51aa24ab1bbfefce466d642ad98587d13123e4ef95ec9aa73b712e775d4cbba","server_ts_ms":1768250248601,"raw":{"market":"0xe51aa24ab1bbfefce466d642ad98587d13123e4ef95ec9aa73b712e775d4cbba","price_changes":[{"asset_id":"96886111393998001968863279421729456597655847484197549086072988901191634450924","price":"0.94","size":"1776.69","side":"BUY","hash":"c3145194809b4defcc7a78663ad964dd5ac89ad4","best_bid":"0.95","best_ask":"0.96"},{"asset_id":"54232589582260339592359130012520874109228367674780084862642636038394766871668","price":"0.06","size":"1776.69","side":"SELL","hash":"8765f46b7a076e495f3faa4316d4e4aefcf07abd","best_bid":"0.04","best_ask":"0.05"}],"timestamp":"1768250248601","event_type":"price_change"}}
{"schema_version":1,"source":"clob_ws_market","recv_ts_ns":1768250248687110448,"event_type":"price_change","market":"0xe51aa24ab1bbfefce466d642ad98587d13123e4ef95ec9aa73b712e775d4cbba","server_ts_ms":1768250248603,"raw":{"market":"0xe51aa24ab1bbfefce466d642ad98587d13123e4ef95ec9aa73b712e775d4cbba","price_changes":[{"asset_id":"54232589582260339592359130012520874109228367674780084862642636038394766871668","price":"0.03","size":"1239.6","side":"BUY","hash":"b7bab2aafd9661727319994d121aa3c7b152383a","best_bid":"0.04","best_ask":"0.05"},{"asset_id":"96886111393998001968863279421729456597655847484197549086072988901191634450924","price":"0.97","size":"1239.6","side":"SELL","hash":"8bcba936a2c5567b5736a8a80c4254aed161d719","best_bid":"0.95","best_ask":"0.96"}],"timestamp":"1768250248603","event_type":"price_change"}}
{"schema_version":1,"source":"clob_ws_market","recv_ts_ns":1768250248690934389,"event_type":"price_change","market":"0xe51aa24ab1bbfefce466d642ad98587d13123e4ef95ec9aa73b712e775d4cbba","server_ts_ms":1768250248604,"raw":{"market":"0xe51aa24ab1bbfefce466d642ad98587d13123e4ef95ec9aa73b712e775d4cbba","price_changes":[{"asset_id":"54232589582260339592359130012520874109228367674780084862642636038394766871668","price":"0.02","size":"5493.25","side":"BUY","hash":"5e8313c914dfb3a14f89a4f99078061e7a912c81","best_bid":"0.04","best_ask":"0.05"},{"asset_id":"96886111393998001968863279421729456597655847484197549086072988901191634450924","price":"0.98","size":"5493.25","side":"SELL","hash":"43f4e0b08a0974323dfc39ad3bcdf804372ec016","best_bid":"0.95","best_ask":"0.96"}],"timestamp":"1768250248604","event_type":"price_change"}}
{"schema_version":1,"source":"clob_ws_market","recv_ts_ns":1768250248695736860,"event_type":"price_change","market":"0xe51aa24ab1bbfefce466d642ad98587d13123e4ef95ec9aa73b712e775d4cbba","server_ts_ms":1768250248605,"raw":{"market":"0xe51aa24ab1bbfefce466d642ad98587d13123e4ef95ec9aa73b712e775d4cbba","price_changes":[{"asset_id":"96886111393998001968863279421729456597655847484197549086072988901191634450924","price":"0.95","size":"97.5","side":"BUY","hash":"2835e707de9dd0403829f7fc7deab23f9915f3a8","best_bid":"0.95","best_ask":"0.96"},{"asset_id":"54232589582260339592359130012520874109228367674780084862642636038394766871668","price":"0.05","size":"97.5","side":"SELL","hash":"6fe18463e03f8211ca1e1f5becff950a61392253","best_bid":"0.04","best_ask":"0.05"}],"timestamp":"1768250248605","event_type":"price_change"}}
{"schema_version":1,"source":"clob_ws_market","recv_ts_ns":1768250248699933630,"event_type":"price_change","market":"0xe51aa24ab1bbfefce466d642ad98587d13123e4ef95ec9aa73b712e775d4cbba","server_ts_ms":1768250248606,"raw":{"market":"0xe51aa24ab1bbfefce466d642ad98587d13123e4ef95ec9aa73b712e775d4cbba","price_changes":[{"asset_id":"54232589582260339592359130012520874109228367674780084862642636038394766871668","price":"0.04","size":"1653.5","side":"BUY","hash":"c7d3e44c5adca980e793aaaf80081ac8963a50d7","best_bid":"0.04","best_ask":"0.05"},{"asset_id":"96886111393998001968863279421729456597655847484197549086072988901191634450924","price":"0.96","size":"1653.5","side":"SELL","hash":"bce6fe8d5d7a64312f8b8ac0ee0b6b1b6fac7469","best_bid":"0.95","best_ask":"0.96"}],"timestamp":"1768250248606","event_type":"price_change"}}
{"schema_version":1,"source":"clob_ws_market","recv_ts_ns":1768250248703503013,"event_type":"price_change","market":"0xe51aa24ab1bbfefce466d642ad98587d13123e4ef95ec9aa73b712e775d4cbba","server_ts_ms":1768250248609,"raw":{"market":"0xe51aa24ab1bbfefce466d642ad98587d13123e4ef95ec9aa73b712e775d4cbba","price_changes":[{"asset_id":"54232589582260339592359130012520874109228367674780084862642636038394766871668","price":"0.03","size":"1255.6","side":"BUY","hash":"c414001fc5d90336233895d2e7395f4bf2df5698","best_bid":"0.04","best_ask":"0.05"},{"asset_id":"96886111393998001968863279421729456597655847484197549086072988901191634450924","price":"0.97","size":"1255.6","side":"SELL","hash":"2233a28e7511e6039f0142722c37d0a8b9ee4d98","best_bid":"0.95","best_ask":"0.96"}],"timestamp":"1768250248609","event_type":"price_change"}}
{"schema_version":1,"source":"clob_ws_market","recv_ts_ns":1768250248726827002,"event_type":"price_change","market":"0xe51aa24ab1bbfefce466d642ad98587d13123e4ef95ec9aa73b712e775d4cbba","server_ts_ms":1768250248615,"raw":{"market":"0xe51aa24ab1bbfefce466d642ad98587d13123e4ef95ec9aa73b712e775d4cbba","price_changes":[{"asset_id":"54232589582260339592359130012520874109228367674780084862642636038394766871668","price":"0.06","size":"1765.69","side":"SELL","hash":"412f294e0701ff10a422de01305d5a2068314016","best_bid":"0.04","best_ask":"0.05"},{"asset_id":"96886111393998001968863279421729456597655847484197549086072988901191634450924","price":"0.94","size":"1765.69","side":"BUY","hash":"933dd86330e65b20c8acc1a6e5dba896a13d161f","best_bid":"0.95","best_ask":"0.96"}],"timestamp":"1768250248615","event_type":"price_change"}}
{"schema_version":1,"source":"clob_ws_market","recv_ts_ns":1768250248736207583,"event_type":"price_change","market":"0xe51aa24ab1bbfefce466d642ad98587d13123e4ef95ec9aa73b712e775d4cbba","server_ts_ms":1768250248616,"raw":{"market":"0xe51aa24ab1bbfefce466d642ad98587d13123e4ef95ec9aa73b712e775d4cbba","price_changes":[{"asset_id":"96886111393998001968863279421729456597655847484197549086072988901191634450924","price":"0.94","size":"1750.69","side":"BUY","hash":"4dfc8737ac8454d624bb380fb18582d5d8aa43c5","best_bid":"0.95","best_ask":"0.96"},{"asset_id":"54232589582260339592359130012520874109228367674780084862642636038394766871668","price":"0.06","size":"1750.69","side":"SELL","hash":"56efa4c0fb86248c3a5e0c27141d709f0d98ade7","best_bid":"0.04","best_ask":"0.05"}],"timestamp":"1768250248616","event_type":"price_change"}}
{"schema_version":1,"source":"clob_ws_market","recv_ts_ns":1768250248740298898,"event_type":"price_change","market":"0xe51aa24ab1bbfefce466d642ad98587d13123e4ef95ec9aa73b712e775d4cbba","server_ts_ms":1768250248618,"raw":{"market":"0xe51aa24ab1bbfefce466d642ad98587d13123e4ef95ec9aa73b712e775d4cbba","price_changes":[{"asset_id":"96886111393998001968863279421729456597655847484197549086072988901191634450924","price":"0.94","size":"1766.69","side":"BUY","hash":"289681df793893d50f91054881657b11ff561d02","best_bid":"0.95","best_ask":"0.96"},{"asset_id":"54232589582260339592359130012520874109228367674780084862642636038394766871668","price":"0.06","size":"1766.69","side":"SELL","hash":"2f90e46a01071f2365419438eb1472ce7e7b2122","best_bid":"0.04","best_ask":"0.05"}],"timestamp":"1768250248618","event_type":"price_change"}}
{"schema_version":1,"source":"clob_ws_market","recv_ts_ns":1768250248753691437,"event_type":"price_change","market":"0xe51aa24ab1bbfefce466d642ad98587d13123e4ef95ec9aa73b712e775d4cbba","server_ts_ms":1768250248646,"raw":{"market":"0xe51aa24ab1bbfefce466d642ad98587d13123e4ef95ec9aa73b712e775d4cbba","price_changes":[{"asset_id":"96886111393998001968863279421729456597655847484197549086072988901191634450924","price":"0.94","size":"1736.69","side":"BUY","hash":"2c159e7402a301fdd6af5be87de660d724cd49ad","best_bid":"0.95","best_ask":"0.96"},{"asset_id":"54232589582260339592359130012520874109228367674780084862642636038394766871668","price":"0.06","size":"1736.69","side":"SELL","hash":"efcd7174a976fd31b90ea96e74bf71239d13c577","best_bid":"0.04","best_ask":"0.05"}],"timestamp":"1768250248646","event_type":"price_change"}}
{"schema_version":1,"source":"clob_ws_market","recv_ts_ns":1768250248784421339,"event_type":"price_change","market":"0xe51aa24ab1bbfefce466d642ad98587d13123e4ef95ec9aa73b712e775d4cbba","server_ts_ms":1768250248707,"raw":{"market":"0xe51aa24ab1bbfefce466d642ad98587d13123e4ef95ec9aa73b712e775d4cbba","price_changes":[{"asset_id":"54232589582260339592359130012520874109228367674780084862642636038394766871668","price":"0.03","size":"1291.6","side":"BUY","hash":"bd045c7896a963c0d784cdee1f8e8d7d362d5e3f","best_bid":"0.04","best_ask":"0.05"},{"asset_id":"96886111393998001968863279421729456597655847484197549086072988901191634450924","price":"0.97","size":"1291.6","side":"SELL","hash":"4c8e427943c00560ca9827e24fa4346544a063e4","best_bid":"0.95","best_ask":"0.96"}],"timestamp":"1768250248707","event_type":"price_change"}}
{"schema_version":1,"source":"clob_ws_market","recv_ts_ns":1768250248789427901,"event_type":"price_change","market":"0xe51aa24ab1bbfefce466d642ad98587d13123e4ef95ec9aa73b712e775d4cbba","server_ts_ms":1768250248712,"raw":{"market":"0xe51aa24ab1bbfefce466d642ad98587d13123e4ef95ec9aa73b712e775d4cbba","price_changes":[{"asset_id":"96886111393998001968863279421729456597655847484197549086072988901191634450924","price":"0.97","size":"1310.6","side":"SELL","hash":"1a7af79683a142cce2ff06a3f26ef349241d542e","best_bid":"0.95","best_ask":"0.96"},{"asset_id":"54232589582260339592359130012520874109228367674780084862642636038394766871668","price":"0.03","size":"1310.6","side":"BUY","hash":"1221510f7c3632336a352c35d9c53bd6e9f5e63d","best_bid":"0.04","best_ask":"0.05"}],"timestamp":"1768250248712","event_type":"price_change"}}
{"schema_version":1,"source":"clob_ws_market","recv_ts_ns":1768250248791818653,"event_type":"price_change","market":"0xe51aa24ab1bbfefce466d642ad98587d13123e4ef95ec9aa73b712e775d4cbba","server_ts_ms":1768250248714,"raw":{"market":"0xe51aa24ab1bbfefce466d642ad98587d13123e4ef95ec9aa73b712e775d4cbba","price_changes":[{"asset_id":"96886111393998001968863279421729456597655847484197549086072988901191634450924","price":"0.54","size":"636.61","side":"BUY","hash":"9be1c869773e4f8857b92a0ba454e639cb763430","best_bid":"0.95","best_ask":"0.96"},{"asset_id":"54232589582260339592359130012520874109228367674780084862642636038394766871668","price":"0.46","size":"636.61","side":"SELL","hash":"c8150f7b723a26f28c6614dd4d70592955bae089","best_bid":"0.04","best_ask":"0.05"}],"timestamp":"1768250248714","event_type":"price_change"}}
{"schema_version":1,"source":"clob_ws_market","recv_ts_ns":1768250248794371176,"event_type":"price_change","market":"0xe51aa24ab1bbfefce466d642ad98587d13123e4ef95ec9aa73b712e775d4cbba","server_ts_ms":1768250248717,"raw":{"market":"0xe51aa24ab1bbfefce466d642ad98587d13123e4ef95ec9aa73b712e775d4cbba","price_changes":[{"asset_id":"54232589582260339592359130012520874109228367674780084862642636038394766871668","price":"0.03","size":"1322.6","side":"BUY","hash":"ee6265974e9c86b30da71d1afe705bb7a82174fb","best_bid":"0.04","best_ask":"0.05"},{"asset_id":"96886111393998001968863279421729456597655847484197549086072988901191634450924","price":"0.97","size":"1322.6","side":"SELL","hash":"fd12426f59af2b1c80fe6006d55bb3461ec4bd5c","best_bid":"0.95","best_ask":"0.96"}],"timestamp":"1768250248717","event_type":"price_change"}}
{"schema_version":1,"source":"clob_ws_market","recv_ts_ns":1768250248838250617,"event_type":"best_bid_ask","market":"0xe51aa24ab1bbfefce466d642ad98587d13123e4ef95ec9aa73b712e775d4cbba","server_ts_ms":1768250248756,"raw":{"market":"0xe51aa24ab1bbfefce466d642ad98587d13123e4ef95ec9aa73b712e775d4cbba","asset_id":"96886111393998001968863279421729456597655847484197549086072988901191634450924","best_bid":"0.94","best_ask":"0.96","spread":"0.02","timestamp":"1768250248756","event_type":"best_bid_ask"}}
{"schema_version":1,"source":"clob_ws_market","recv_ts_ns":1768250248840199079,"event_type":"price_change","market":"0xe51aa24ab1bbfefce466d642ad98587d13123e4ef95ec9aa73b712e775d4cbba","server_ts_ms":1768250248754,"raw":{"market":"0xe51aa24ab1bbfefce466d642ad98587d13123e4ef95ec9aa73b712e775d4cbba","price_changes":[{"asset_id":"96886111393998001968863279421729456597655847484197549086072988901191634450924","price":"0.94","size":"1401.27","side":"BUY","hash":"75393b95cc6b48b7554f1f373d1ebffac8112fb4","best_bid":"0.94","best_ask":"0.96"},{"asset_id":"54232589582260339592359130012520874109228367674780084862642636038394766871668","price":"0.06","size":"1401.27","side":"SELL","hash":"b4d823698e2cc9811c72d66641a24317408b0e51","best_bid":"0.04","best_ask":"0.06"}],"timestamp":"1768250248754","event_type":"price_change"}}
{"schema_version":1,"source":"clob_ws_market","recv_ts_ns":1768250248843220138,"event_type":"price_change","market":"0xe51aa24ab1bbfefce466d642ad98587d13123e4ef95ec9aa73b712e775d4cbba","server_ts_ms":1768250248754,"raw":{"market":"0xe51aa24ab1bbfefce466d642ad98587d13123e4ef95ec9aa73b712e775d4cbba","price_changes":[{"asset_id":"96886111393998001968863279421729456597655847484197549086072988901191634450924","price":"0.95","size":"0","side":"BUY","hash":"75393b95cc6b48b7554f1f373d1ebffac8112fb4","best_bid":"0.94","best_ask":"0.96"},{"asset_id":"54232589582260339592359130012520874109228367674780084862642636038394766871668","price":"0.05","size":"0","side":"SELL","hash":"b4d823698e2cc9811c72d66641a24317408b0e51","best_bid":"0.04","best_ask":"0.06"}],"timestamp":"1768250248754","event_type":"price_change"}}
{"schema_version":1,"source":"clob_ws_market","recv_ts_ns":1768250248846445473,"event_type":"price_change","market":"0xe51aa24ab1bbfefce466d642ad98587d13123e4ef95ec9aa73b712e775d4cbba","server_ts_ms":1768250248754,"raw":{"market":"0xe51aa24ab1bbfefce466d642ad98587d13123e4ef95ec9aa73b712e775d4cbba","price_changes":[{"asset_id":"54232589582260339592359130012520874109228367674780084862642636038394766871668","price":"0.05","size":"0","side":"SELL","hash":"b4d823698e2cc9811c72d66641a24317408b0e51","best_bid":"0.04","best_ask":"0.06"},{"asset_id":"96886111393998001968863279421729456597655847484197549086072988901191634450924","price":"0.95","size":"0","side":"BUY","hash":"75393b95cc6b48b7554f1f373d1ebffac8112fb4","best_bid":"0.94","best_ask":"0.96"}],"timestamp":"1768250248754","event_type":"price_change"}}
{"schema_version":1,"source":"clob_ws_market","recv_ts_ns":1768250248853367021,"event_type":"book","market":"0xe51aa24ab1bbfefce466d642ad98587d13123e4ef95ec9aa73b712e775d4cbba","server_ts_ms":1768250248754,"raw":{"market":"0xe51aa24ab1bbfefce466d642ad98587d13123e4ef95ec9aa73b712e775d4cbba","asset_id":"96886111393998001968863279421729456597655847484197549086072988901191634450924","bids":[{"price":"0.01","size":"24295.73"},{"price":"0.02","size":"7594.51"},{"price":"0.03","size":"5964.69"},{"price":"0.04","size":"5411.4"},{"price":"0.05","size":"5356.39"},{"price":"0.06","size":"5328"},{"price":"0.07","size":"5039.28"},{"price":"0.08","size":"5022.7"},{"price":"0.09","size":"5320.9"},{"price":"0.1","size":"5158.44"},{"price":"0.11","size":"18.3"},{"price":"0.12","size":"30.3"},{"price":"0.13","size":"16.5"},{"price":"0.14","size":"15.8"},{"price":"0.15","size":"104.19"},{"price":"0.16","size":"24.69"},{"price":"0.17","size":"14.19"},{"price":"0.18","size":"13.8"},{"price":"0.19","size":"13.4"},{"price":"0.2","size":"38.1"},{"price":"0.21","size":"12.8"},{"price":"0.22","size":"12.6"},{"price":"0.23","size":"12.3"},{"price":"0.24","size":"22.1"},{"price":"0.25","size":"16.9"},{"price":"0.26","size":"21.8"},{"price":"0.27","size":"11.6"},{"price":"0.28","size":"11.4"},{"price":"0.29","size":"61.3"},{"price":"0.3","size":"26.2"},{"price":"0.31","size":"11.1"},{"price":"0.32","size":"11"},{"price":"0.33","size":"110.9"},{"price":"0.34","size":"10.8"},{"price":"0.35","size":"15.7"},{"price":"0.36","size":"10.6"},{"price":"0.37","size":"10.6"},{"price":"0.38","size":"22.5"},{"price":"0.39","size":"10.5"},{"price":"0.4","size":"45.4"},{"price":"0.41","size":"311.4"},{"price":"0.42","size":"820.82"},{"price":"0.43","size":"826.3"},{"price":"0.44","size":"1062.3"},{"price":"0.45","size":"582.3"},{"price":"0.46","size":"626.2"},{"price":"0.47","size":"562.2"},{"price":"0.48","size":"567.2"},{"price":"0.49","size":"573.2"},{"price":"0.5","size":"917.2"},{"price":"0.51","size":"591.2"},{"price":"0.52","size":"590.2"},{"price":"0.53","size":"567.2"},{"price":"0.54","size":"636.61"},{"price":"0.55","size":"362.97"},{"price":"0.56","size":"341.3"},{"price":"0.57","size":"320.62"},{"price":"0.58","size":"567.3"},{"price":"0.59","size":"562.4"},{"price":"0.6","size":"693.02"},{"price":"0.61","size":"625.5"},{"price":"0.62","size":"700.5"},{"price":"0.63","size":"703.32"},{"price":"0.64","size":"680.6"},{"price":"0.65","size":"536.14"},{"price":"0.66","size":"602.8"},{"price":"0.67","size":"572.9"},{"price":"0.68","size":"573"},{"price":"0.69","size":"595.1"},{"price":"0.7","size":"603.2"},{"price":"0.71","size":"1318.72"},{"price":"0.72","size":"1043.04"},{"price":"0.73","size":"663.6"},{"price":"0.74","size":"911.17"},{"price":"0.75","size":"694.3"},{"price":"0.76","size":"717.6"},{"price":"0.77","size":"1183.3"},{"price":"0.78","size":"1449.6"},{"price":"0.79","size":"1254.75"},{"price":"0.8","size":"1445.08"},{"price":"0.81","size":"1229.8"},{"price":"0.82","size":"1467.57"},{"price":"0.83","size":"1470.51"},{"price":"0.84","size":"1668.59"},{"price":"0.85","size":"1762.5"},{"price":"0.86","size":"1755.6"},{"price":"0.87","size":"1588.93"},{"price":"0.88","size":"2355.4"},{"price":"0.89","size":"2066.7"},{"price":"0.9","size":"3467.84"},{"price":"0.91","size":"3018.44"},{"price":"0.92","size":"2729.36"},{"price":"0.93","size":"1364.32"},{"price":"0.94","size":"1401.27"}],"asks":[{"price":"0.99","size":"21109.86"},{"price":"0.98","size":"5493.25"},{"price":"0.97","size":"1322.6"},{"price":"0.96","size":"1653.5"}],"hash":"75393b95cc6b48b7554f1f373d1ebffac8112fb4","timestamp":"1768250248754","event_type":"book"}}
{"schema_version":1,"source":"clob_ws_market","recv_ts_ns":1768250248858855232,"event_type":"best_bid_ask","market":"0xe51aa24ab1bbfefce466d642ad98587d13123e4ef95ec9aa73b712e775d4cbba","server_ts_ms":1768250248816,"raw":{"market":"0xe51aa24ab1bbfefce466d642ad98587d13123e4ef95ec9aa73b712e775d4cbba","asset_id":"96886111393998001968863279421729456597655847484197549086072988901191634450924","best_bid":"0.94","best_ask":"0.96","spread":"0.02","timestamp":"1768250248816","event_type":"best_bid_ask"}}
{"schema_version":1,"source":"clob_ws_market","recv_ts_ns":1768250248860741994,"event_type":"price_change","market":"0xe51aa24ab1bbfefce466d642ad98587d13123e4ef95ec9aa73b712e775d4cbba","server_ts_ms":1768250248814,"raw":{"market":"0xe51aa24ab1bbfefce466d642ad98587d13123e4ef95ec9aa73b712e775d4cbba","price_changes":[{"asset_id":"96886111393998001968863279421729456597655847484197549086072988901191634450924","price":"0.94","size":"1381.27","side":"BUY","hash":"d31afdafaf4a1a9ea77ae572db56c8c151c196da","best_bid":"0.94","best_ask":"0.96"},{"asset_id":"54232589582260339592359130012520874109228367674780084862642636038394766871668","price":"0.06","size":"1381.27","side":"SELL","hash":"fda2bd482d307f6ab93a8f06614089001ddee002","best_bid":"0.04","best_ask":"0.06"}],"timestamp":"1768250248814","event_type":"price_change"}}
{"schema_version":1,"source":"clob_ws_market","recv_ts_ns":1768250248868377738,"event_type":"book","market":"0xe51aa24ab1bbfefce466d642ad98587d13123e4ef95ec9aa73b712e775d4cbba","server_ts_ms":1768250248814,"raw":{"market":"0xe51aa24ab1bbfefce466d642ad98587d13123e4ef95ec9aa73b712e775d4cbba","asset_id":"96886111393998001968863279421729456597655847484197549086072988901191634450924","bids":[{"price":"0.01","size":"24295.73"},{"price":"0.02","size":"7594.51"},{"price":"0.03","size":"5964.69"},{"price":"0.04","size":"5411.4"},{"price":"0.05","size":"5356.39"},{"price":"0.06","size":"5328"},{"price":"0.07","size":"5039.28"},{"price":"0.08","size":"5022.7"},{"price":"0.09","size":"5320.9"},{"price":"0.1","size":"5158.44"},{"price":"0.11","size":"18.3"},{"price":"0.12","size":"30.3"},{"price":"0.13","size":"16.5"},{"price":"0.14","size":"15.8"},{"price":"0.15","size":"104.19"},{"price":"0.16","size":"24.69"},{"price":"0.17","size":"14.19"},{"price":"0.18","size":"13.8"},{"price":"0.19","size":"13.4"},{"price":"0.2","size":"38.1"},{"price":"0.21","size":"12.8"},{"price":"0.22","size":"12.6"},{"price":"0.23","size":"12.3"},{"price":"0.24","size":"22.1"},{"price":"0.25","size":"16.9"},{"price":"0.26","size":"21.8"},{"price":"0.27","size":"11.6"},{"price":"0.28","size":"11.4"},{"price":"0.29","size":"61.3"},{"price":"0.3","size":"26.2"},{"price":"0.31","size":"11.1"},{"price":"0.32","size":"11"},{"price":"0.33","size":"110.9"},{"price":"0.34","size":"10.8"},{"price":"0.35","size":"15.7"},{"price":"0.36","size":"10.6"},{"price":"0.37","size":"10.6"},{"price":"0.38","size":"22.5"},{"price":"0.39","size":"10.5"},{"price":"0.4","size":"45.4"},{"price":"0.41","size":"311.4"},{"price":"0.42","size":"820.82"},{"price":"0.43","size":"826.3"},{"price":"0.44","size":"1062.3"},{"price":"0.45","size":"582.3"},{"price":"0.46","size":"626.2"},{"price":"0.47","size":"562.2"},{"price":"0.48","size":"567.2"},{"price":"0.49","size":"573.2"},{"price":"0.5","size":"917.2"},{"price":"0.51","size":"591.2"},{"price":"0.52","size":"590.2"},{"price":"0.53","size":"567.2"},{"price":"0.54","size":"636.61"},{"price":"0.55","size":"362.97"},{"price":"0.56","size":"341.3"},{"price":"0.57","size":"320.62"},{"price":"0.58","size":"567.3"},{"price":"0.59","size":"562.4"},{"price":"0.6","size":"693.02"},{"price":"0.61","size":"625.5"},{"price":"0.62","size":"700.5"},{"price":"0.63","size":"703.32"},{"price":"0.64","size":"680.6"},{"price":"0.65","size":"536.14"},{"price":"0.66","size":"602.8"},{"price":"0.67","size":"572.9"},{"price":"0.68","size":"573"},{"price":"0.69","size":"595.1"},{"price":"0.7","size":"603.2"},{"price":"0.71","size":"1318.72"},{"price":"0.72","size":"1043.04"},{"price":"0.73","size":"663.6"},{"price":"0.74","size":"911.17"},{"price":"0.75","size":"694.3"},{"price":"0.76","size":"717.6"},{"price":"0.77","size":"1183.3"},{"price":"0.78","size":"1449.6"},{"price":"0.79","size":"1254.75"},{"price":"0.8","size":"1445.08"},{"price":"0.81","size":"1229.8"},{"price":"0.82","size":"1467.57"},{"price":"0.83","size":"1470.51"},{"price":"0.84","size":"1668.59"},{"price":"0.85","size":"1762.5"},{"price":"0.86","size":"1755.6"},{"price":"0.87","size":"1588.93"},{"price":"0.88","size":"2355.4"},{"price":"0.89","size":"2066.7"},{"price":"0.9","size":"3467.84"},{"price":"0.91","size":"3018.44"},{"price":"0.92","size":"2729.36"},{"price":"0.93","size":"1364.32"},{"price":"0.94","size":"1381.27"}],"asks":[{"price":"0.99","size":"21109.86"},{"price":"0.98","size":"5493.25"},{"price":"0.97","size":"1322.6"},{"price":"0.96","size":"1653.5"}],"hash":"d31afdafaf4a1a9ea77ae572db56c8c151c196da","timestamp":"1768250248814","event_type":"book"}}
{"schema_version":1,"source":"clob_ws_market","recv_ts_ns":1768250248869924281,"event_type":"price_change","market":"0xe51aa24ab1bbfefce466d642ad98587d13123e4ef95ec9aa73b712e775d4cbba","server_ts_ms":1768250248824,"raw":{"market":"0xe51aa24ab1bbfefce466d642ad98587d13123e4ef95ec9aa73b712e775d4cbba","price_changes":[{"asset_id":"96886111393998001968863279421729456597655847484197549086072988901191634450924","price":"0.94","size":"1371.27","side":"BUY","hash":"ca96c1b0a1d4e752f7e44e1655494ef294255504","best_bid":"0.94","best_ask":"0.96"},{"asset_id":"54232589582260339592359130012520874109228367674780084862642636038394766871668","price":"0.06","size":"1371.27","side":"SELL","hash":"9f323b107f8d977aa6ee9ab098e3a93df2ea9caa","best_bid":"0.04","best_ask":"0.06"}],"timestamp":"1768250248824","event_type":"price_change"}}
{"schema_version":1,"source":"clob_ws_market","recv_ts_ns":1768250248872228821,"event_type":"price_change","market":"0xe51aa24ab1bbfefce466d642ad98587d13123e4ef95ec9aa73b712e775d4cbba","server_ts_ms":1768250248834,"raw":{"market":"0xe51aa24ab1bbfefce466d642ad98587d13123e4ef95ec9aa73b712e775d4cbba","price_changes":[{"asset_id":"54232589582260339592359130012520874109228367674780084862642636038394766871668","price":"0.04","size":"1659","side":"BUY","hash":"8c33480ab877eaad1b3205a192d511c606f4783c","best_bid":"0.04","best_ask":"0.06"},{"asset_id":"96886111393998001968863279421729456597655847484197549086072988901191634450924","price":"0.96","size":"1659","side":"SELL","hash":"36ece0daa0a94c94d2262db687e3fe013776fbfa","best_bid":"0.94","best_ask":"0.96"}],"timestamp":"1768250248834","event_type":"price_change"}}
{"schema_version":1,"source":"clob_ws_market","recv_ts_ns":1768250248874916304,"event_type":"price_change","market":"0xe51aa24ab1bbfefce466d642ad98587d13123e4ef95ec9aa73b712e775d4cbba","server_ts_ms":1768250248834,"raw":{"market":"0xe51aa24ab1bbfefce466d642ad98587d13123e4ef95ec9aa73b712e775d4cbba","price_changes":[{"asset_id":"54232589582260339592359130012520874109228367674780084862642636038394766871668","price":"0.04","size":"1679","side":"BUY","hash":"39f5a02fd6bfa8bf9d56fcd1a31d0b421ec5b80a","best_bid":"0.04","best_ask":"0.06"},{"asset_id":"96886111393998001968863279421729456597655847484197549086072988901191634450924","price":"0.96","size":"1679","side":"SELL","hash":"e7d71ae251cc112a4d4e4f15be30fd9488e23475","best_bid":"0.94","best_ask":"0.96"}],"timestamp":"1768250248834","event_type":"price_change"}}
{"schema_version":1,"source":"clob_ws_market","recv_ts_ns":1768250248877446771,"event_type":"price_change","market":"0xe51aa24ab1bbfefce466d642ad98587d13123e4ef95ec9aa73b712e775d4cbba","server_ts_ms":1768250248835,"raw":{"market":"0xe51aa24ab1bbfefce466d642ad98587d13123e4ef95ec9aa73b712e775d4cbba","price_changes":[{"asset_id":"54232589582260339592359130012520874109228367674780084862642636038394766871668","price":"0.04","size":"1684.5","side":"BUY","hash":"1ddb1b4b1bd84feeac2b6fc400e9ec43b4ad39b4","best_bid":"0.04","best_ask":"0.06"},{"asset_id":"96886111393998001968863279421729456597655847484197549086072988901191634450924","price":"0.96","size":"1684.5","side":"SELL","hash":"77099938eae95bb569a5c60c588fa1f9d257fa79","best_bid":"0.94","best_ask":"0.96"}],"timestamp":"1768250248835","event_type":"price_change"}}
{"schema_version":1,"source":"clob_ws_market","recv_ts_ns":1768250248880639426,"event_type":"price_change","market":"0xe51aa24ab1bbfefce466d642ad98587d13123e4ef95ec9aa73b712e775d4cbba","server_ts_ms":1768250248847,"raw":{"market":"0xe51aa24ab1bbfefce466d642ad98587d13123e4ef95ec9aa73b712e775d4cbba","price_changes":[{"asset_id":"54232589582260339592359130012520874109228367674780084862642636038394766871668","price":"0.02","size":"5443.25","side":"BUY","hash":"222191e34653d8317602537c93304772006649c9","best_bid":"0.04","best_ask":"0.06"},{"asset_id":"96886111393998001968863279421729456597655847484197549086072988901191634450924","price":"0.98","size":"5443.25","side":"SELL","hash":"599ba2262bd0c656d4a2dbb286d68d380959ae75","best_bid":"0.94","best_ask":"0.96"}],"timestamp":"1768250248847","event_type":"price_change"}}
{"schema_version":1,"source":"clob_ws_market","recv_ts_ns":1768250248900710426,"event_type":"price_change","market":"0xe51aa24ab1bbfefce466d642ad98587d13123e4ef95ec9aa73b712e775d4cbba","server_ts_ms":1768250248870,"raw":{"market":"0xe51aa24ab1bbfefce466d642ad98587d13123e4ef95ec9aa73b712e775d4cbba","price_changes":[{"asset_id":"96886111393998001968863279421729456597655847484197549086072988901191634450924","price":"0.94","size":"1376.77","side":"BUY","hash":"403ee5a9aa60dedd4b31d2bc83c22a44882d2e27","best_bid":"0.94","best_ask":"0.96"},{"asset_id":"54232589582260339592359130012520874109228367674780084862642636038394766871668","price":"0.06","size":"1376.77","side":"SELL","hash":"b9562e3811bad38d9dc410b5052e3a54877eff00","best_bid":"0.04","best_ask":"0.06"}],"timestamp":"1768250248870","event_type":"price_change"}}
{"schema_version":1,"source":"clob_ws_market","recv_ts_ns":1768250248905733753,"event_type":"price_change","market":"0xe51aa24ab1bbfefce466d642ad98587d13123e4ef95ec9aa73b712e775d4cbba","server_ts_ms":1768250248873,"raw":{"market":"0xe51aa24ab1bbfefce466d642ad98587d13123e4ef95ec9aa73b712e775d4cbba","price_changes":[{"asset_id":"96886111393998001968863279421729456597655847484197549086072988901191634450924","price":"0.96","size":"1690","side":"SELL","hash":"18a275233da351be8817d8c67b554de1404c80c3","best_bid":"0.94","best_ask":"0.96"},{"asset_id":"54232589582260339592359130012520874109228367674780084862642636038394766871668","price":"0.04","size":"1690","side":"BUY","hash":"562f8ddbc6741ab5b903db0d9801b0342d4b8b69","best_bid":"0.04","best_ask":"0.06"}],"timestamp":"1768250248873","event_type":"price_change"}}
{"schema_version":1,"source":"clob_ws_market","recv_ts_ns":1768250248927138104,"event_type":"best_bid_ask","market":"0xe51aa24ab1bbfefce466d642ad98587d13123e4ef95ec9aa73b712e775d4cbba","server_ts_ms":1768250248893,"raw":{"market":"0xe51aa24ab1bbfefce466d642ad98587d13123e4ef95ec9aa73b712e775d4cbba","asset_id":"96886111393998001968863279421729456597655847484197549086072988901191634450924","best_bid":"0.94","best_ask":"0.96","spread":"0.02","timestamp":"1768250248893","event_type":"best_bid_ask"}}
{"schema_version":1,"source":"clob_ws_market","recv_ts_ns":1768250248929860409,"event_type":"price_change","market":"0xe51aa24ab1bbfefce466d642ad98587d13123e4ef95ec9aa73b712e775d4cbba","server_ts_ms":1768250248892,"raw":{"market":"0xe51aa24ab1bbfefce466d642ad98587d13123e4ef95ec9aa73b712e775d4cbba","price_changes":[{"asset_id":"54232589582260339592359130012520874109228367674780084862642636038394766871668","price":"0.04","size":"1655","side":"BUY","hash":"66c68862c9a02bb7bc68ea26e5711dda19eda628","best_bid":"0.04","best_ask":"0.06"},{"asset_id":"96886111393998001968863279421729456597655847484197549086072988901191634450924","price":"0.96","size":"1655","side":"SELL","hash":"76d27127c9560b74bc4020b22c8f6b8cc2ea53a8","best_bid":"0.94","best_ask":"0.96"}],"timestamp":"1768250248892","event_type":"price_change"}}
{"schema_version":1,"source":"clob_ws_market","recv_ts_ns":1768250248942732160,"event_type":"book","market":"0xe51aa24ab1bbfefce466d642ad98587d13123e4ef95ec9aa73b712e775d4cbba","server_ts_ms":1768250248892,"raw":{"market":"0xe51aa24ab1bbfefce466d642ad98587d13123e4ef95ec9aa73b712e775d4cbba","asset_id":"96886111393998001968863279421729456597655847484197549086072988901191634450924","bids":[{"price":"0.01","size":"24295.73"},{"price":"0.02","size":"7594.51"},{"price":"0.03","size":"5964.69"},{"price":"0.04","size":"5411.4"},{"price":"0.05","size":"5356.39"},{"price":"0.06","size":"5328"},{"price":"0.07","size":"5039.28"},{"price":"0.08","size":"5022.7"},{"price":"0.09","size":"5320.9"},{"price":"0.1","size":"5158.44"},{"price":"0.11","size":"18.3"},{"price":"0.12","size":"30.3"},{"price":"0.13","size":"16.5"},{"price":"0.14","size":"15.8"},{"price":"0.15","size":"104.19"},{"price":"0.16","size":"24.69"},{"price":"0.17","size":"14.19"},{"price":"0.18","size":"13.8"},{"price":"0.19","size":"13.4"},{"price":"0.2","size":"38.1"},{"price":"0.21","size":"12.8"},{"price":"0.22","size":"12.6"},{"price":"0.23","size":"12.3"},{"price":"0.24","size":"22.1"},{"price":"0.25","size":"16.9"},{"price":"0.26","size":"21.8"},{"price":"0.27","size":"11.6"},{"price":"0.28","size":"11.4"},{"price":"0.29","size":"61.3"},{"price":"0.3","size":"26.2"},{"price":"0.31","size":"11.1"},{"price":"0.32","size":"11"},{"price":"0.33","size":"110.9"},{"price":"0.34","size":"10.8"},{"price":"0.35","size":"15.7"},{"price":"0.36","size":"10.6"},{"price":"0.37","size":"10.6"},{"price":"0.38","size":"22.5"},{"price":"0.39","size":"10.5"},{"price":"0.4","size":"45.4"},{"price":"0.41","size":"311.4"},{"price":"0.42","size":"820.82"},{"price":"0.43","size":"826.3"},{"price":"0.44","size":"1062.3"},{"price":"0.45","size":"582.3"},{"price":"0.46","size":"626.2"},{"price":"0.47","size":"562.2"},{"price":"0.48","size":"567.2"},{"price":"0.49","size":"573.2"},{"price":"0.5","size":"917.2"},{"price":"0.51","size":"591.2"},{"price":"0.52","size":"590.2"},{"price":"0.53","size":"567.2"},{"price":"0.54","size":"636.61"},{"price":"0.55","size":"362.97"},{"price":"0.56","size":"341.3"},{"price":"0.57","size":"320.62"},{"price":"0.58","size":"567.3"},{"price":"0.59","size":"562.4"},{"price":"0.6","size":"693.02"},{"price":"0.61","size":"625.5"},{"price":"0.62","size":"700.5"},{"price":"0.63","size":"703.32"},{"price":"0.64","size":"680.6"},{"price":"0.65","size":"536.14"},{"price":"0.66","size":"602.8"},{"price":"0.67","size":"572.9"},{"price":"0.68","size":"573"},{"price":"0.69","size":"595.1"},{"price":"0.7","size":"603.2"},{"price":"0.71","size":"1318.72"},{"price":"0.72","size":"1043.04"},{"price":"0.73","size":"663.6"},{"price":"0.74","size":"911.17"},{"price":"0.75","size":"694.3"},{"price":"0.76","size":"717.6"},{"price":"0.77","size":"1183.3"},{"price":"0.78","size":"1449.6"},{"price":"0.79","size":"1254.75"},{"price":"0.8","size":"1445.08"},{"price":"0.81","size":"1229.8"},{"price":"0.82","size":"1467.57"},{"price":"0.83","size":"1470.51"},{"price":"0.84","size":"1668.59"},{"price":"0.85","size":"1762.5"},{"price":"0.86","size":"1755.6"},{"price":"0.87","size":"1588.93"},{"price":"0.88","size":"2355.4"},{"price":"0.89","size":"2066.7"},{"price":"0.9","size":"3467.84"},{"price":"0.91","size":"3018.44"},{"price":"0.92","size":"2729.36"},{"price":"0.93","size":"1364.32"},{"price":"0.94","size":"1376.77"}],"asks":[{"price":"0.99","size":"21109.86"},{"price":"0.98","size":"5443.25"},{"price":"0.97","size":"1322.6"},{"price":"0.96","size":"1655"}],"hash":"76d27127c9560b74bc4020b22c8f6b8cc2ea53a8","timestamp":"1768250248892","event_type":"book"}}
{"schema_version":1,"source":"clob_ws_market","recv_ts_ns":1768250248945855772,"event_type":"price_change","market":"0xe51aa24ab1bbfefce466d642ad98587d13123e4ef95ec9aa73b712e775d4cbba","server_ts_ms":1768250248913,"raw":{"market":"0xe51aa24ab1bbfefce466d642ad98587d13123e4ef95ec9aa73b712e775d4cbba","price_changes":[{"asset_id":"96886111393998001968863279421729456597655847484197549086072988901191634450924","price":"0.93","size":"1369.82","side":"BUY","hash":"c817bebf520532217fae2a726c8fda769a5b63ef","best_bid":"0.94","best_ask":"0.96"},{"asset_id":"54232589582260339592359130012520874109228367674780084862642636038394766871668","price":"0.07","size":"1369.82","side":"SELL","hash":"58c96794ad875354d3052824b88b721b586ee6f4","best_bid":"0.04","best_ask":"0.06"}],"timestamp":"1768250248913","event_type":"price_change"}}
{"schema_version":1,"source":"clob_ws_market","recv_ts_ns":1768250248956215597,"event_type":"price_change","market":"0xe51aa24ab1bbfefce466d642ad98587d13123e4ef95ec9aa73b712e775d4cbba","server_ts_ms":1768250248919,"raw":{"market":"0xe51aa24ab1bbfefce466d642ad98587d13123e4ef95ec9aa73b712e775d4cbba","price_changes":[{"asset_id":"54232589582260339592359130012520874109228367674780084862642636038394766871668","price":"0.03","size":"1286.6","side":"BUY","hash":"d02924a1a33e1b184d79b2d740e7bab117058e78","best_bid":"0.04","best_ask":"0.06"},{"asset_id":"96886111393998001968863279421729456597655847484197549086072988901191634450924","price":"0.97","size":"1286.6","side":"SELL","hash":"91dce73430242839e685c1315dbe2e9b1c7e67bf","best_bid":"0.94","best_ask":"0.96"}],"timestamp":"1768250248919","event_type":"price_change"}}
{"schema_version":1,"source":"clob_ws_market","recv_ts_ns":1768250248960599680,"event_type":"price_change","market":"0xe51aa24ab1bbfefce466d642ad98587d13123e4ef95ec9aa73b712e775d4cbba","server_ts_ms":1768250248920,"raw":{"market":"0xe51aa24ab1bbfefce466d642ad98587d13123e4ef95ec9aa73b712e775d4cbba","price_changes":[{"asset_id":"54232589582260339592359130012520874109228367674780084862642636038394766871668","price":"0.03","size":"1294.6","side":"BUY","hash":"3d9305bf95f0e4bc183eb78f233d5553fb3bdffc","best_bid":"0.04","best_ask":"0.06"},{"asset_id":"96886111393998001968863279421729456597655847484197549086072988901191634450924","price":"0.97","size":"1294.6","side":"SELL","hash":"cd8be024061e7af034df598ccd47903325bc40e2","best_bid":"0.94","best_ask":"0.96"}],"timestamp":"1768250248920","event_type":"price_change"}}
{"schema_version":1,"source":"clob_ws_market","recv_ts_ns":1768250248965396684,"event_type":"price_change","market":"0xe51aa24ab1bbfefce466d642ad98587d13123e4ef95ec9aa73b712e775d4cbba","server_ts_ms":1768250248922,"raw":{"market":"0xe51aa24ab1bbfefce466d642ad98587d13123e4ef95ec9aa73b712e775d4cbba","price_changes":[{"asset_id":"54232589582260339592359130012520874109228367674780084862642636038394766871668","price":"0.06","size":"1387.77","side":"SELL","hash":"23bfce361376fdca73b016f01cff81561f93b5fe","best_bid":"0.04","best_ask":"0.06"},{"asset_id":"96886111393998001968863279421729456597655847484197549086072988901191634450924","price":"0.94","size":"1387.77","side":"BUY","hash":"4d2ac820769ff530aeb26aee0721b92080d21284","best_bid":"0.94","best_ask":"0.96"}],"timestamp":"1768250248922","event_type":"price_change"}}
{"schema_version":1,"source":"clob_ws_market","recv_ts_ns":1768250248968697024,"event_type":"price_change","market":"0xe51aa24ab1bbfefce466d642ad98587d13123e4ef95ec9aa73b712e775d4cbba","server_ts_ms":1768250248923,"raw":{"market":"0xe51aa24ab1bbfefce466d642ad98587d13123e4ef95ec9aa73b712e775d4cbba","price_changes":[{"asset_id":"96886111393998001968863279421729456597655847484197549086072988901191634450924","price":"0.97","size":"1275.6","side":"SELL","hash":"cf9ee7ac4ed4f030892a3ecc9d79677311b898f0","best_bid":"0.94","best_ask":"0.96"},{"asset_id":"54232589582260339592359130012520874109228367674780084862642636038394766871668","price":"0.03","size":"1275.6","side":"BUY","hash":"71f5cca1af6911408e12d7a8948669c063f802cb","best_bid":"0.04","best_ask":"0.06"}],"timestamp":"1768250248923","event_type":"price_change"}}
{"schema_version":1,"source":"clob_ws_market","recv_ts_ns":1768250248971619693,"event_type":"price_change","market":"0xe51aa24ab1bbfefce466d642ad98587d13123e4ef95ec9aa73b712e775d4cbba","server_ts_ms":1768250248926,"raw":{"market":"0xe51aa24ab1bbfefce466d642ad98587d13123e4ef95ec9aa73b712e775d4cbba","price_changes":[{"asset_id":"96886111393998001968863279421729456597655847484197549086072988901191634450924","price":"0.94","size":"1407.77","side":"BUY","hash":"d337ac0c0780d96f4949f5f8f9d4240f506571e9","best_bid":"0.94","best_ask":"0.96"},{"asset_id":"54232589582260339592359130012520874109228367674780084862642636038394766871668","price":"0.06","size":"1407.77","side":"SELL","hash":"7550880c80134fdf070bafcb758ada89cec76a33","best_bid":"0.04","best_ask":"0.06"}],"timestamp":"1768250248926","event_type":"price_change"}}
{"schema_version":1,"source":"clob_ws_market","recv_ts_ns":1768250248974628628,"event_type":"price_change","market":"0xe51aa24ab1bbfefce466d642ad98587d13123e4ef95ec9aa73b712e775d4cbba","server_ts_ms":1768250248927,"raw":{"market":"0xe51aa24ab1bbfefce466d642ad98587d13123e4ef95ec9aa73b712e775d4cbba","price_changes":[{"asset_id":"96886111393998001968863279421729456597655847484197549086072988901191634450924","price":"0.94","size":"1402.77","side":"BUY","hash":"da09d6f520c061223a37a81ce4ec2807d6e5edd6","best_bid":"0.94","best_ask":"0.96"},{"asset_id":"54232589582260339592359130012520874109228367674780084862642636038394766871668","price":"0.06","size":"1402.77","side":"SELL","hash":"8e512746f4419b594de2a0fbadc09eeb87476108","best_bid":"0.04","best_ask":"0.06"}],"timestamp":"1768250248927","event_type":"price_change"}}
{"schema_version":1,"source":"clob_ws_market","recv_ts_ns":1768250248977487889,"event_type":"price_change","market":"0xe51aa24ab1bbfefce466d642ad98587d13123e4ef95ec9aa73b712e775d4cbba","server_ts_ms":1768250248938,"raw":{"market":"0xe51aa24ab1bbfefce466d642ad98587d13123e4ef95ec9aa73b712e775d4cbba","price_changes":[{"asset_id":"96886111393998001968863279421729456597655847484197549086072988901191634450924","price":"0.94","size":"1386.77","side":"BUY","hash":"b85ffb74912ad2109e640c74c6bb917a201c502e","best_bid":"0.94","best_ask":"0.96"},{"asset_id":"54232589582260339592359130012520874109228367674780084862642636038394766871668","price":"0.06","size":"1386.77","side":"SELL","hash":"c8a17cfc880170a9cc9377a2a28c7cd36584fd96","best_bid":"0.04","best_ask":"0.06"}],"timestamp":"1768250248938","event_type":"price_change"}}
{"schema_version":1,"source":"clob_ws_market","recv_ts_ns":1768250248980647016,"event_type":"last_trade_price","market":"0xe51aa24ab1bbfefce466d642ad98587d13123e4ef95ec9aa73b712e775d4cbba","server_ts_ms":1768250248941,"raw":{"market":"0xe51aa24ab1bbfefce466d642ad98587d13123e4ef95ec9aa73b712e775d4cbba","asset_id":"96886111393998001968863279421729456597655847484197549086072988901191634450924","price":"0.96","size":"35","fee_rate_bps":"1000","side":"BUY","timestamp":"1768250248941","event_type":"last_trade_price","transaction_hash":"0x411c3fe2e3736707936d815e7aaf5391d430aaadb4bf239414e4154348acdf79"}}
{"schema_version":1,"source":"clob_ws_market","recv_ts_ns":1768250248983344110,"event_type":"price_change","market":"0xe51aa24ab1bbfefce466d642ad98587d13123e4ef95ec9aa73b712e775d4cbba","server_ts_ms":1768250248943,"raw":{"market":"0xe51aa24ab1bbfefce466d642ad98587d13123e4ef95ec9aa73b712e775d4cbba","price_changes":[{"asset_id":"54232589582260339592359130012520874109228367674780084862642636038394766871668","price":"0.03","size":"1263.6","side":"BUY","hash":"3fbd3a442980d4857db5904578124b0ccf373072","best_bid":"0.04","best_ask":"0.06"},{"asset_id":"96886111393998001968863279421729456597655847484197549086072988901191634450924","price":"0.97","size":"1263.6","side":"SELL","hash":"a60592f3286e93237baf59b25b1813ac002afbb5","best_bid":"0.94","best_ask":"0.96"}],"timestamp":"1768250248943","event_type":"price_change"}}
{"schema_version":1,"source":"clob_ws_market","recv_ts_ns":1768250248986158036,"event_type":"price_change","market":"0xe51aa24ab1bbfefce466d642ad98587d13123e4ef95ec9aa73b712e775d4cbba","server_ts_ms":1768250248946,"raw":{"market":"0xe51aa24ab1bbfefce466d642ad98587d13123e4ef95ec9aa73b712e775d4cbba","price_changes":[{"asset_id":"54232589582260339592359130012520874109228367674780084862642636038394766871668","price":"0.03","size":"1255.6","side":"BUY","hash":"c142c37fa63f59675b0d3e61e043871605289208","best_bid":"0.04","best_ask":"0.06"},{"asset_id":"96886111393998001968863279421729456597655847484197549086072988901191634450924","price":"0.97","size":"1255.6","side":"SELL","hash":"ebce6c1250fee567f9bd90c91c93731682dd8637","best_bid":"0.94","best_ask":"0.96"}],"timestamp":"1768250248946","event_type":"price_change"}}
{"schema_version":1,"source":"clob_ws_market","recv_ts_ns":1768250248989048418,"event_type":"price_change","market":"0xe51aa24ab1bbfefce466d642ad98587d13123e4ef95ec9aa73b712e775d4cbba","server_ts_ms":1768250248947,"raw":{"market":"0xe51aa24ab1bbfefce466d642ad98587d13123e4ef95ec9aa73b712e775d4cbba","price_changes":[{"asset_id":"96886111393998001968863279421729456597655847484197549086072988901191634450924","price":"0.94","size":"1402.77","side":"BUY","hash":"9fe82718abc8fb5962ee7bddcebd143b1978382e","best_bid":"0.94","best_ask":"0.96"},{"asset_id":"54232589582260339592359130012520874109228367674780084862642636038394766871668","price":"0.06","size":"1402.77","side":"SELL","hash":"94e0c7b9682361db75ba051349d833d7856d5312","best_bid":"0.04","best_ask":"0.06"}],"timestamp":"1768250248947","event_type":"price_change"}}
{"schema_version":1,"source":"clob_ws_market","recv_ts_ns":1768250249011092216,"event_type":"price_change","market":"0xe51aa24ab1bbfefce466d642ad98587d13123e4ef95ec9aa73b712e775d4cbba","server_ts_ms":1768250248970,"raw":{"market":"0xe51aa24ab1bbfefce466d642ad98587d13123e4ef95ec9aa73b712e775d4cbba","price_changes":[{"asset_id":"96886111393998001968863279421729456597655847484197549086072988901191634450924","price":"0.93","size":"1349.82","side":"BUY","hash":"203ff59422cfdc5ec7a7201c8465270c7fa02d08","best_bid":"0.94","best_ask":"0.96"},{"asset_id":"54232589582260339592359130012520874109228367674780084862642636038394766871668","price":"0.07","size":"1349.82","side":"SELL","hash":"b2253c81dd8206574d80132199977062363c6584","best_bid":"0.04","best_ask":"0.06"}],"timestamp":"1768250248970","event_type":"price_change"}}
{"schema_version":1,"source":"clob_ws_market","recv_ts_ns":1768250249018109215,"event_type":"price_change","market":"0xe51aa24ab1bbfefce466d642ad98587d13123e4ef95ec9aa73b712e775d4cbba","server_ts_ms":1768250248987,"raw":{"market":"0xe51aa24ab1bbfefce466d642ad98587d13123e4ef95ec9aa73b712e775d4cbba","price_changes":[{"asset_id":"54232589582260339592359130012520874109228367674780084862642636038394766871668","price":"0.06","size":"1391.77","side":"SELL","hash":"8de9bc0a4d33396f9a906e27970ee8f9f5fc271c","best_bid":"0.04","best_ask":"0.06"},{"asset_id":"96886111393998001968863279421729456597655847484197549086072988901191634450924","price":"0.94","size":"1391.77","side":"BUY","hash":"7c6d3eab4ad1ad02f4ce9edf53132d6732f6185b","best_bid":"0.94","best_ask":"0.96"}],"timestamp":"1768250248987","event_type":"price_change"}}
{"schema_version":1,"source":"clob_ws_market","recv_ts_ns":1768250249021619961,"event_type":"price_change","market":"0xe51aa24ab1bbfefce466d642ad98587d13123e4ef95ec9aa73b712e775d4cbba","server_ts_ms":1768250248992,"raw":{"market":"0xe51aa24ab1bbfefce466d642ad98587d13123e4ef95ec9aa73b712e775d4cbba","price_changes":[{"asset_id":"96886111393998001968863279421729456597655847484197549086072988901191634450924","price":"0.94","size":"1371.77","side":"BUY","hash":"047e6493be601f7c663d6b85fc336132a347f623","best_bid":"0.94","best_ask":"0.96"},{"asset_id":"54232589582260339592359130012520874109228367674780084862642636038394766871668","price":"0.06","size":"1371.77","side":"SELL","hash":"0cd32010de102205d5457c4658746f1591ec3b3c","best_bid":"0.04","best_ask":"0.06"}],"timestamp":"1768250248992","event_type":"price_change"}}
{"schema_version":1,"source":"clob_ws_market","recv_ts_ns":1768250249028925942,"event_type":"price_change","market":"0xe51aa24ab1bbfefce466d642ad98587d13123e4ef95ec9aa73b712e775d4cbba","server_ts_ms":1768250249000,"raw":{"market":"0xe51aa24ab1bbfefce466d642ad98587d13123e4ef95ec9aa73b712e775d4cbba","price_changes":[{"asset_id":"54232589582260339592359130012520874109228367674780084862642636038394766871668","price":"0.02","size":"5343.25","side":"BUY","hash":"4fbef6be58996e8d7cc78fb01d80798b1987c004","best_bid":"0.04","best_ask":"0.06"},{"asset_id":"96886111393998001968863279421729456597655847484197549086072988901191634450924","price":"0.98","size":"5343.25","side":"SELL","hash":"bcdfd6eff4a74c2ca8b4c036d59ac0f012da5b13","best_bid":"0.94","best_ask":"0.96"}],"timestamp":"1768250249000","event_type":"price_change"}}
{"schema_version":1,"source":"clob_ws_market","recv_ts_ns":1768250249033070471,"event_type":"price_change","market":"0xe51aa24ab1bbfefce466d642ad98587d13123e4ef95ec9aa73b712e775d4cbba","server_ts_ms":1768250249003,"raw":{"market":"0xe51aa24ab1bbfefce466d642ad98587d13123e4ef95ec9aa73b712e775d4cbba","price_changes":[{"asset_id":"96886111393998001968863279421729456597655847484197549086072988901191634450924","price":"0.97","size":"1267.6","side":"SELL","hash":"1f5141d0db28fc99845d5ec0776e8fea11feb554","best_bid":"0.94","best_ask":"0.96"},{"asset_id":"54232589582260339592359130012520874109228367674780084862642636038394766871668","price":"0.03","size":"1267.6","side":"BUY","hash":"b62d8018517b8652334e70be1e1f2717ec39b3ef","best_bid":"0.04","best_ask":"0.06"}],"timestamp":"1768250249003","event_type":"price_change"}}
{"schema_version":1,"source":"clob_ws_market","recv_ts_ns":1768250249036605400,"event_type":"price_change","market":"0xe51aa24ab1bbfefce466d642ad98587d13123e4ef95ec9aa73b712e775d4cbba","server_ts_ms":1768250249003,"raw":{"market":"0xe51aa24ab1bbfefce466d642ad98587d13123e4ef95ec9aa73b712e775d4cbba","price_changes":[{"asset_id":"96886111393998001968863279421729456597655847484197549086072988901191634450924","price":"0.94","size":"1355.77","side":"BUY","hash":"1f644f683061b26489e26ef9886dc665a7817c98","best_bid":"0.94","best_ask":"0.96"},{"asset_id":"54232589582260339592359130012520874109228367674780084862642636038394766871668","price":"0.06","size":"1355.77","side":"SELL","hash":"beda412f700eda67019a4ff4681391c782f558ff","best_bid":"0.04","best_ask":"0.06"}],"timestamp":"1768250249003","event_type":"price_change"}}
{"schema_version":1,"source":"clob_ws_market","recv_ts_ns":1768250249040711095,"event_type":"price_change","market":"0xe51aa24ab1bbfefce466d642ad98587d13123e4ef95ec9aa73b712e775d4cbba","server_ts_ms":1768250249005,"raw":{"market":"0xe51aa24ab1bbfefce466d642ad98587d13123e4ef95ec9aa73b712e775d4cbba","price_changes":[{"asset_id":"54232589582260339592359130012520874109228367674780084862642636038394766871668","price":"0.03","size":"1280.6","side":"BUY","hash":"e2fb239a3ec9d9d62975478e8dfd86fccd4892a7","best_bid":"0.04","best_ask":"0.06"},{"asset_id":"96886111393998001968863279421729456597655847484197549086072988901191634450924","price":"0.97","size":"1280.6","side":"SELL","hash":"140ef2212afe89362ca9a77a109aa7d4acb75f19","best_bid":"0.94","best_ask":"0.96"}],"timestamp":"1768250249005","event_type":"price_change"}}
{"schema_version":1,"source":"clob_ws_market","recv_ts_ns":1768250249065344997,"event_type":"price_change","market":"0xe51aa24ab1bbfefce466d642ad98587d13123e4ef95ec9aa73b712e775d4cbba","server_ts_ms":1768250249009,"raw":{"market":"0xe51aa24ab1bbfefce466d642ad98587d13123e4ef95ec9aa73b712e775d4cbba","price_changes":[{"asset_id":"54232589582260339592359130012520874109228367674780084862642636038394766871668","price":"0.01","size":"21093.86","side":"BUY","hash":"b2838044346a2c1f7202f482fc3e86b42dcb21e2","best_bid":"0.04","best_ask":"0.06"},{"asset_id":"96886111393998001968863279421729456597655847484197549086072988901191634450924","price":"0.99","size":"21093.86","side":"SELL","hash":"cc11e9593958f0cf9aeb2d7574ffdac1ccb96b3f","best_bid":"0.94","best_ask":"0.96"}],"timestamp":"1768250249009","event_type":"price_change"}}
{"schema_version":1,"source":"clob_ws_market","recv_ts_ns":1768250249070204134,"event_type":"best_bid_ask","market":"0xe51aa24ab1bbfefce466d642ad98587d13123e4ef95ec9aa73b712e775d4cbba","server_ts_ms":1768250249017,"raw":{"market":"0xe51aa24ab1bbfefce466d642ad98587d13123e4ef95ec9aa73b712e775d4cbba","asset_id":"96886111393998001968863279421729456597655847484197549086072988901191634450924","best_bid":"0.94","best_ask":"0.96","spread":"0.02","timestamp":"1768250249017","event_type":"best_bid_ask"}}
{"schema_version":1,"source":"clob_ws_market","recv_ts_ns":1768250249072328275,"event_type":"price_change","market":"0xe51aa24ab1bbfefce466d642ad98587d13123e4ef95ec9aa73b712e775d4cbba","server_ts_ms":1768250249016,"raw":{"market":"0xe51aa24ab1bbfefce466d642ad98587d13123e4ef95ec9aa73b712e775d4cbba","price_changes":[{"asset_id":"54232589582260339592359130012520874109228367674780084862642636038394766871668","price":"0.04","size":"1647.48","side":"BUY","hash":"27bcc3f2be247039ac5152e5e5b994a0a6252bf5","best_bid":"0.04","best_ask":"0.06"},{"asset_id":"96886111393998001968863279421729456597655847484197549086072988901191634450924","price":"0.96","size":"1647.48","side":"SELL","hash":"69c2180f0c48ce91f7e1c60fc30582e09826fa7e","best_bid":"0.94","best_ask":"0.96"}],"timestamp":"1768250249016","event_type":"price_change"}}
{"schema_version":1,"source":"clob_ws_market","recv_ts_ns":1768250249081504170,"event_type":"book","market":"0xe51aa24ab1bbfefce466d642ad98587d13123e4ef95ec9aa73b712e775d4cbba","server_ts_ms":1768250249016,"raw":{"market":"0xe51aa24ab1bbfefce466d642ad98587d13123e4ef95ec9aa73b712e775d4cbba","asset_id":"96886111393998001968863279421729456597655847484197549086072988901191634450924","bids":[{"price":"0.01","size":"24295.73"},{"price":"0.02","size":"7594.51"},{"price":"0.03","size":"5964.69"},{"price":"0.04","size":"5411.4"},{"price":"0.05","size":"5356.39"},{"price":"0.06","size":"5328"},{"price":"0.07","size":"5039.28"},{"price":"0.08","size":"5022.7"},{"price":"0.09","size":"5320.9"},{"price":"0.1","size":"5158.44"},{"price":"0.11","size":"18.3"},{"price":"0.12","size":"30.3"},{"price":"0.13","size":"16.5"},{"price":"0.14","size":"15.8"},{"price":"0.15","size":"104.19"},{"price":"0.16","size":"24.69"},{"price":"0.17","size":"14.19"},{"price":"0.18","size":"13.8"},{"price":"0.19","size":"13.4"},{"price":"0.2","size":"38.1"},{"price":"0.21","size":"12.8"},{"price":"0.22","size":"12.6"},{"price":"0.23","size":"12.3"},{"price":"0.24","size":"22.1"},{"price":"0.25","size":"16.9"},{"price":"0.26","size":"21.8"},{"price":"0.27","size":"11.6"},{"price":"0.28","size":"11.4"},{"price":"0.29","size":"61.3"},{"price":"0.3","size":"26.2"},{"price":"0.31","size":"11.1"},{"price":"0.32","size":"11"},{"price":"0.33","size":"110.9"},{"price":"0.34","size":"10.8"},{"price":"0.35","size":"15.7"},{"price":"0.36","size":"10.6"},{"price":"0.37","size":"10.6"},{"price":"0.38","size":"22.5"},{"price":"0.39","size":"10.5"},{"price":"0.4","size":"45.4"},{"price":"0.41","size":"311.4"},{"price":"0.42","size":"820.82"},{"price":"0.43","size":"826.3"},{"price":"0.44","size":"1062.3"},{"price":"0.45","size":"582.3"},{"price":"0.46","size":"626.2"},{"price":"0.47","size":"562.2"},{"price":"0.48","size":"567.2"},{"price":"0.49","size":"573.2"},{"price":"0.5","size":"917.2"},{"price":"0.51","size":"591.2"},{"price":"0.52","size":"590.2"},{"price":"0.53","size":"567.2"},{"price":"0.54","size":"636.61"},{"price":"0.55","size":"362.97"},{"price":"0.56","size":"341.3"},{"price":"0.57","size":"320.62"},{"price":"0.58","size":"567.3"},{"price":"0.59","size":"562.4"},{"price":"0.6","size":"693.02"},{"price":"0.61","size":"625.5"},{"price":"0.62","size":"700.5"},{"price":"0.63","size":"703.32"},{"price":"0.64","size":"680.6"},{"price":"0.65","size":"536.14"},{"price":"0.66","size":"602.8"},{"price":"0.67","size":"572.9"},{"price":"0.68","size":"573"},{"price":"0.69","size":"595.1"},{"price":"0.7","size":"603.2"},{"price":"0.71","size":"1318.72"},{"price":"0.72","size":"1043.04"},{"price":"0.73","size":"663.6"},{"price":"0.74","size":"911.17"},{"price":"0.75","size":"694.3"},{"price":"0.76","size":"717.6"},{"price":"0.77","size":"1183.3"},{"price":"0.78","size":"1449.6"},{"price":"0.79","size":"1254.75"},{"price":"0.8","size":"1445.08"},{"price":"0.81","size":"1229.8"},{"price":"0.82","size":"1467.57"},{"price":"0.83","size":"1470.51"},{"price":"0.84","size":"1668.59"},{"price":"0.85","size":"1762.5"},{"price":"0.86","size":"1755.6"},{"price":"0.87","size":"1588.93"},{"price":"0.88","size":"2355.4"},{"price":"0.89","size":"2066.7"},{"price":"0.9","size":"3467.84"},{"price":"0.91","size":"3018.44"},{"price":"0.92","size":"2729.36"},{"price":"0.93","size":"1349.82"},{"price":"0.94","size":"1355.77"}],"asks":[{"price":"0.99","size":"21093.86"},{"price":"0.98","size":"5343.25"},{"price":"0.97","size":"1280.6"},{"price":"0.96","size":"1647.48"}],"hash":"69c2180f0c48ce91f7e1c60fc30582e09826fa7e","timestamp":"1768250249016","event_type":"book"}}
{"schema_version":1,"source":"clob_ws_market","recv_ts_ns":1768250249084100059,"event_type":"price_change","market":"0xe51aa24ab1bbfefce466d642ad98587d13123e4ef95ec9aa73b712e775d4cbba","server_ts_ms":1768250249018,"raw":{"market":"0xe51aa24ab1bbfefce466d642ad98587d13123e4ef95ec9aa73b712e775d4cbba","price_changes":[{"asset_id":"96886111393998001968863279421729456597655847484197549086072988901191634450924","price":"0.93","size":"1365.82","side":"BUY","hash":"aa21dd572c4eba47ef3a05d6f8571aa9eb4af6a5","best_bid":"0.94","best_ask":"0.96"},{"asset_id":"54232589582260339592359130012520874109228367674780084862642636038394766871668","price":"0.07","size":"1365.82","side":"SELL","hash":"7f504b72b0cfc06501a201dd7270aede8e7b75d9","best_bid":"0.04","best_ask":"0.06"}],"timestamp":"1768250249018","event_type":"price_change"}}
{"schema_version":1,"source":"clob_ws_market","recv_ts_ns":1768250249087439564,"event_type":"price_change","market":"0xe51aa24ab1bbfefce466d642ad98587d13123e4ef95ec9aa73b712e775d4cbba","server_ts_ms":1768250249019,"raw":{"market":"0xe51aa24ab1bbfefce466d642ad98587d13123e4ef95ec9aa73b712e775d4cbba","price_changes":[{"asset_id":"96886111393998001968863279421729456597655847484197549086072988901191634450924","price":"0.94","size":"1339.77","side":"BUY","hash":"18b5ce0b3b277a5ce011ddbb3d030cebf7ab45c3","best_bid":"0.94","best_ask":"0.96"},{"asset_id":"54232589582260339592359130012520874109228367674780084862642636038394766871668","price":"0.06","size":"1339.77","side":"SELL","hash":"9d9a892a23193527beb8cd83af645f84d63cfa30","best_bid":"0.04","best_ask":"0.06"}],"timestamp":"1768250249019","event_type":"price_change"}}
{"schema_version":1,"source":"clob_ws_market","recv_ts_ns":1768250249090330951,"event_type":"price_change","market":"0xe51aa24ab1bbfefce466d642ad98587d13123e4ef95ec9aa73b712e775d4cbba","server_ts_ms":1768250249020,"raw":{"market":"0xe51aa24ab1bbfefce466d642ad98587d13123e4ef95ec9aa73b712e775d4cbba","price_changes":[{"asset_id":"54232589582260339592359130012520874109228367674780084862642636038394766871668","price":"0.03","size":"1264.6","side":"BUY","hash":"ba8c3c13adc3bea3f3c8a760335d92d882b63caa","best_bid":"0.04","best_ask":"0.06"},{"asset_id":"96886111393998001968863279421729456597655847484197549086072988901191634450924","price":"0.97","size":"1264.6","side":"SELL","hash":"20658234416d39449d47c42d7939a35e7d57c385","best_bid":"0.94","best_ask":"0.96"}],"timestamp":"1768250249020","event_type":"price_change"}}
{"schema_version":1,"source":"clob_ws_market","recv_ts_ns":1768250249096628222,"event_type":"price_change","market":"0xe51aa24ab1bbfefce466d642ad98587d13123e4ef95ec9aa73b712e775d4cbba","server_ts_ms":1768250249030,"raw":{"market":"0xe51aa24ab1bbfefce466d642ad98587d13123e4ef95ec9aa73b712e775d4cbba","price_changes":[{"asset_id":"96886111393998001968863279421729456597655847484197549086072988901191634450924","price":"0.94","size":"1323.77","side":"BUY","hash":"82d7ebf1cb6185ece878b753cfaee2b563413698","best_bid":"0.94","best_ask":"0.96"},{"asset_id":"54232589582260339592359130012520874109228367674780084862642636038394766871668","price":"0.06","size":"1323.77","side":"SELL","hash":"d59d04d2f247e5d5440c6903709997bea76610cc","best_bid":"0.04","best_ask":"0.06"}],"timestamp":"1768250249030","event_type":"price_change"}}
{"schema_version":1,"source":"clob_ws_market","recv_ts_ns":1768250249101998595,"event_type":"price_change","market":"0xe51aa24ab1bbfefce466d642ad98587d13123e4ef95ec9aa73b712e775d4cbba","server_ts_ms":1768250249047,"raw":{"market":"0xe51aa24ab1bbfefce466d642ad98587d13123e4ef95ec9aa73b712e775d4cbba","price_changes":[{"asset_id":"54232589582260339592359130012520874109228367674780084862642636038394766871668","price":"0.02","size":"5443.25","side":"BUY","hash":"0faf6a122130b16924a66b4f065e4b36fbc34f64","best_bid":"0.04","best_ask":"0.06"},{"asset_id":"96886111393998001968863279421729456597655847484197549086072988901191634450924","price":"0.98","size":"5443.25","side":"SELL","hash":"03b82a9420381f22db459a5c33af9ae662191423","best_bid":"0.94","best_ask":"0.96"}],"timestamp":"1768250249047","event_type":"price_change"}}
{"schema_version":1,"source":"clob_ws_market","recv_ts_ns":1768250249106984667,"event_type":"price_change","market":"0xe51aa24ab1bbfefce466d642ad98587d13123e4ef95ec9aa73b712e775d4cbba","server_ts_ms":1768250249048,"raw":{"market":"0xe51aa24ab1bbfefce466d642ad98587d13123e4ef95ec9aa73b712e775d4cbba","price_changes":[{"asset_id":"96886111393998001968863279421729456597655847484197549086072988901191634450924","price":"0.96","size":"1722.74","side":"SELL","hash":"6d38ea0fe266525a561176da7285e3b261c7f47d","best_bid":"0.94","best_ask":"0.96"},{"asset_id":"54232589582260339592359130012520874109228367674780084862642636038394766871668","price":"0.04","size":"1722.74","side":"BUY","hash":"56ddd2942f07cf8fcd1e1c5e5b52c248f74ffb2e","best_bid":"0.04","best_ask":"0.06"}],"timestamp":"1768250249048","event_type":"price_change"}}
{"schema_version":1,"source":"clob_ws_market","recv_ts_ns":1768250249112680776,"event_type":"price_change","market":"0xe51aa24ab1bbfefce466d642ad98587d13123e4ef95ec9aa73b712e775d4cbba","server_ts_ms":1768250249053,"raw":{"market":"0xe51aa24ab1bbfefce466d642ad98587d13123e4ef95ec9aa73b712e775d4cbba","price_changes":[{"asset_id":"54232589582260339592359130012520874109228367674780084862642636038394766871668","price":"0.02","size":"5459.25","side":"BUY","hash":"aa99399d11eb3bc728a781fb179535603b74e53d","best_bid":"0.04","best_ask":"0.06"},{"asset_id":"96886111393998001968863279421729456597655847484197549086072988901191634450924","price":"0.98","size":"5459.25","side":"SELL","hash":"24127dd2cb956d17d7623b8fb4d51349b09739a7","best_bid":"0.94","best_ask":"0.96"}],"timestamp":"1768250249053","event_type":"price_change"}}
{"schema_version":1,"source":"clob_ws_market","recv_ts_ns":1768250249118512776,"event_type":"price_change","market":"0xe51aa24ab1bbfefce466d642ad98587d13123e4ef95ec9aa73b712e775d4cbba","server_ts_ms":1768250249056,"raw":{"market":"0xe51aa24ab1bbfefce466d642ad98587d13123e4ef95ec9aa73b712e775d4cbba","price_changes":[{"asset_id":"54232589582260339592359130012520874109228367674780084862642636038394766871668","price":"0.04","size":"1738.74","side":"BUY","hash":"02cebe5dec3f701906486a87c88a9373e2771f10","best_bid":"0.04","best_ask":"0.06"},{"asset_id":"96886111393998001968863279421729456597655847484197549086072988901191634450924","price":"0.96","size":"1738.74","side":"SELL","hash":"ae03087e1c22ddcc4204a177a9cb09872e6c4b7a","best_bid":"0.94","best_ask":"0.96"}],"timestamp":"1768250249056","event_type":"price_change"}}
{"schema_version":1,"source":"clob_ws_market","recv_ts_ns":1768250249122666390,"event_type":"price_change","market":"0xe51aa24ab1bbfefce466d642ad98587d13123e4ef95ec9aa73b712e775d4cbba","server_ts_ms":1768250249058,"raw":{"market":"0xe51aa24ab1bbfefce466d642ad98587d13123e4ef95ec9aa73b712e775d4cbba","price_changes":[{"asset_id":"96886111393998001968863279421729456597655847484197549086072988901191634450924","price":"0.93","size":"1381.82","side":"BUY","hash":"1a935b58bcfe12555b9954e0f0f18e49d73965e4","best_bid":"0.94","best_ask":"0.96"},{"asset_id":"54232589582260339592359130012520874109228367674780084862642636038394766871668","price":"0.07","size":"1381.82","side":"SELL","hash":"eb915da96339f1684c694e5c2d9e58b3d2e40d78","best_bid":"0.04","best_ask":"0.06"}],"timestamp":"1768250249058","event_type":"price_change"}}
{"schema_version":1,"source":"clob_ws_market","recv_ts_ns":1768250249133329460,"event_type":"price_change","market":"0xe51aa24ab1bbfefce466d642ad98587d13123e4ef95ec9aa73b712e775d4cbba","server_ts_ms":1768250249088,"raw":{"market":"0xe51aa24ab1bbfefce466d642ad98587d13123e4ef95ec9aa73b712e775d4cbba","price_changes":[{"asset_id":"54232589582260339592359130012520874109228367674780084862642636038394766871668","price":"0.03","size":"1251.6","side":"BUY","hash":"eee7963ca4fcf503b2995b013bca4b354b6400bb","best_bid":"0.04","best_ask":"0.06"},{"asset_id":"96886111393998001968863279421729456597655847484197549086072988901191634450924","price":"0.97","size":"1251.6","side":"SELL","hash":"ef37b13dc7e67cc7ee0b40bc36dc081106316698","best_bid":"0.94","best_ask":"0.96"}],"timestamp":"1768250249088","event_type":"price_change"}}
{"schema_version":1,"source":"clob_ws_market","recv_ts_ns":1768250249135826753,"event_type":"price_change","market":"0xe51aa24ab1bbfefce466d642ad98587d13123e4ef95ec9aa73b712e775d4cbba","server_ts_ms":1768250249089,"raw":{"market":"0xe51aa24ab1bbfefce466d642ad98587d13123e4ef95ec9aa73b712e775d4cbba","price_changes":[{"asset_id":"96886111393998001968863279421729456597655847484197549086072988901191634450924","price":"0.97","size":"1239.6","side":"SELL","hash":"3c672e1ae074bd73209bab250621276deb53a114","best_bid":"0.94","best_ask":"0.96"},{"asset_id":"54232589582260339592359130012520874109228367674780084862642636038394766871668","price":"0.03","size":"1239.6","side":"BUY","hash":"4f361fd828d458969d1cd342582a047a6be12c16","best_bid":"0.04","best_ask":"0.06"}],"timestamp":"1768250249089","event_type":"price_change"}}
{"schema_version":1,"source":"clob_ws_market","recv_ts_ns":1768250249191683183,"event_type":"price_change","market":"0xe51aa24ab1bbfefce466d642ad98587d13123e4ef95ec9aa73b712e775d4cbba","server_ts_ms":1768250249107,"raw":{"market":"0xe51aa24ab1bbfefce466d642ad98587d13123e4ef95ec9aa73b712e775d4cbba","price_changes":[{"asset_id":"96886111393998001968863279421729456597655847484197549086072988901191634450924","price":"0.94","size":"1343.77","side":"BUY","hash":"790d7ad454c79dbdc38d3f36e83e47a41f0343cb","best_bid":"0.94","best_ask":"0.96"},{"asset_id":"54232589582260339592359130012520874109228367674780084862642636038394766871668","price":"0.06","size":"1343.77","side":"SELL","hash":"f9878afbc245a1f4e8ba7435d9aeddfa7df42de0","best_bid":"0.04","best_ask":"0.06"}],"timestamp":"1768250249107","event_type":"price_change"}}
{"schema_version":1,"source":"clob_ws_market","recv_ts_ns":1768250249197767543,"event_type":"price_change","market":"0xe51aa24ab1bbfefce466d642ad98587d13123e4ef95ec9aa73b712e775d4cbba","server_ts_ms":1768250249109,"raw":{"market":"0xe51aa24ab1bbfefce466d642ad98587d13123e4ef95ec9aa73b712e775d4cbba","price_changes":[{"asset_id":"96886111393998001968863279421729456597655847484197549086072988901191634450924","price":"0.93","size":"1397.82","side":"BUY","hash":"913d9fbadf45011f7e739f27d37555bf959316e5","best_bid":"0.94","best_ask":"0.96"},{"asset_id":"54232589582260339592359130012520874109228367674780084862642636038394766871668","price":"0.07","size":"1397.82","side":"SELL","hash":"9303b4d73d2d0facfbf23ce0d378ced7c8134181","best_bid":"0.04","best_ask":"0.06"}],"timestamp":"1768250249109","event_type":"price_change"}}
{"schema_version":1,"source":"clob_ws_market","recv_ts_ns":1768250249201716059,"event_type":"price_change","market":"0xe51aa24ab1bbfefce466d642ad98587d13123e4ef95ec9aa73b712e775d4cbba","server_ts_ms":1768250249110,"raw":{"market":"0xe51aa24ab1bbfefce466d642ad98587d13123e4ef95ec9aa73b712e775d4cbba","price_changes":[{"asset_id":"96886111393998001968863279421729456597655847484197549086072988901191634450924","price":"0.55","size":"368.97","side":"BUY","hash":"2a34b636b31661e1df63c40bb19c76faffe8edb7","best_bid":"0.94","best_ask":"0.96"},{"asset_id":"54232589582260339592359130012520874109228367674780084862642636038394766871668","price":"0.45","size":"368.97","side":"SELL","hash":"e2e13060fa0fa95cfdd1d266395e83eec5fd30ec","best_bid":"0.04","best_ask":"0.06"}],"timestamp":"1768250249110","event_type":"price_change"}}
{"schema_version":1,"source":"clob_ws_market","recv_ts_ns":1768250249212867789,"event_type":"price_change","market":"0xe51aa24ab1bbfefce466d642ad98587d13123e4ef95ec9aa73b712e775d4cbba","server_ts_ms":1768250249132,"raw":{"market":"0xe51aa24ab1bbfefce466d642ad98587d13123e4ef95ec9aa73b712e775d4cbba","price_changes":[{"asset_id":"54232589582260339592359130012520874109228367674780084862642636038394766871668","price":"0.03","size":"1254.9","side":"BUY","hash":"897621dec599a828810a071b0357708b6d5b16e1","best_bid":"0.04","best_ask":"0.06"},{"asset_id":"96886111393998001968863279421729456597655847484197549086072988901191634450924","price":"0.97","size":"1254.9","side":"SELL","hash":"d494c51597553bc253965cf9dd7c6657d41273a8","best_bid":"0.94","best_ask":"0.96"}],"timestamp":"1768250249132","event_type":"price_change"}}
{"schema_version":1,"source":"clob_ws_market","recv_ts_ns":1768250249226550202,"event_type":"price_change","market":"0xe51aa24ab1bbfefce466d642ad98587d13123e4ef95ec9aa73b712e775d4cbba","server_ts_ms":1768250249135,"raw":{"market":"0xe51aa24ab1bbfefce466d642ad98587d13123e4ef95ec9aa73b712e775d4cbba","price_changes":[{"asset_id":"54232589582260339592359130012520874109228367674780084862642636038394766871668","price":"0.03","size":"1271.33","side":"BUY","hash":"74c3932e57bde0c750876e2f7050bf001f547dbe","best_bid":"0.04","best_ask":"0.06"},{"asset_id":"96886111393998001968863279421729456597655847484197549086072988901191634450924","price":"0.97","size":"1271.33","side":"SELL","hash":"0cf4fbda2543db459bea8f1cbf20fa9042b4a134","best_bid":"0.94","best_ask":"0.96"}],"timestamp":"1768250249135","event_type":"price_change"}}
{"schema_version":1,"source":"clob_ws_market","recv_ts_ns":1768250249331766012,"event_type":"price_change","market":"0xe51aa24ab1bbfefce466d642ad98587d13123e4ef95ec9aa73b712e775d4cbba","server_ts_ms":1768250249161,"raw":{"market":"0xe51aa24ab1bbfefce466d642ad98587d13123e4ef95ec9aa73b712e775d4cbba","price_changes":[{"asset_id":"54232589582260339592359130012520874109228367674780084862642636038394766871668","price":"0.03","size":"1255.33","side":"BUY","hash":"dac2897d11af56368af5715975965fe43fb5a805","best_bid":"0.04","best_ask":"0.06"},{"asset_id":"96886111393998001968863279421729456597655847484197549086072988901191634450924","price":"0.97","size":"1255.33","side":"SELL","hash":"e0b6bfe105e99aa0afd41bcb253613073427b8f7","best_bid":"0.94","best_ask":"0.96"}],"timestamp":"1768250249161","event_type":"price_change"}}
{"schema_version":1,"source":"clob_ws_market","recv_ts_ns":1768250249337419508,"event_type":"price_change","market":"0xe51aa24ab1bbfefce466d642ad98587d13123e4ef95ec9aa73b712e775d4cbba","server_ts_ms":1768250249166,"raw":{"market":"0xe51aa24ab1bbfefce466d642ad98587d13123e4ef95ec9aa73b712e775d4cbba","price_changes":[{"asset_id":"96886111393998001968863279421729456597655847484197549086072988901191634450924","price":"0.94","size":"1327.77","side":"BUY","hash":"7f297d2356bcf75f732de123950ca081a14f89e0","best_bid":"0.94","best_ask":"0.96"},{"asset_id":"54232589582260339592359130012520874109228367674780084862642636038394766871668","price":"0.06","size":"1327.77","side":"SELL","hash":"25ba43fdb387d301e8dc575de0de0de7ba2fb01c","best_bid":"0.04","best_ask":"0.06"}],"timestamp":"1768250249166","event_type":"price_change"}}
{"schema_version":1,"source":"clob_ws_market","recv_ts_ns":1768250249344075831,"event_type":"price_change","market":"0xe51aa24ab1bbfefce466d642ad98587d13123e4ef95ec9aa73b712e775d4cbba","server_ts_ms":1768250249168,"raw":{"market":"0xe51aa24ab1bbfefce466d642ad98587d13123e4ef95ec9aa73b712e775d4cbba","price_changes":[{"asset_id":"96886111393998001968863279421729456597655847484197549086072988901191634450924","price":"0.94","size":"1311.77","side":"BUY","hash":"9be31bdb3ba9ec8dd4fbf9992696c47730497bbc","best_bid":"0.94","best_ask":"0.96"},{"asset_id":"54232589582260339592359130012520874109228367674780084862642636038394766871668","price":"0.06","size":"1311.77","side":"SELL","hash":"20de7509626c8462e4a93cc2270617208a8b831c","best_bid":"0.04","best_ask":"0.06"}],"timestamp":"1768250249168","event_type":"price_change"}}
{"schema_version":1,"source":"clob_ws_market","recv_ts_ns":1768250249352718749,"event_type":"price_change","market":"0xe51aa24ab1bbfefce466d642ad98587d13123e4ef95ec9aa73b712e775d4cbba","server_ts_ms":1768250249216,"raw":{"market":"0xe51aa24ab1bbfefce466d642ad98587d13123e4ef95ec9aa73b712e775d4cbba","price_changes":[{"asset_id":"96886111393998001968863279421729456597655847484197549086072988901191634450924","price":"0.92","size":"2724.36","side":"BUY","hash":"030921cc5f994127817fe5041211f125c47208ac","best_bid":"0.94","best_ask":"0.96"},{"asset_id":"54232589582260339592359130012520874109228367674780084862642636038394766871668","price":"0.08","size":"2724.36","side":"SELL","hash":"f0431174e1fc92b410000bf89fb05d99e8e7b1a8","best_bid":"0.04","best_ask":"0.06"}],"timestamp":"1768250249216","event_type":"price_change"}}
{"schema_version":1,"source":"clob_ws_market","recv_ts_ns":1768250249355777018,"event_type":"price_change","market":"0xe51aa24ab1bbfefce466d642ad98587d13123e4ef95ec9aa73b712e775d4cbba","server_ts_ms":1768250249216,"raw":{"market":"0xe51aa24ab1bbfefce466d642ad98587d13123e4ef95ec9aa73b712e775d4cbba","price_changes":[{"asset_id":"96886111393998001968863279421729456597655847484197549086072988901191634450924","price":"0.99","size":"21088.86","side":"SELL","hash":"030921cc5f994127817fe5041211f125c47208ac","best_bid":"0.94","best_ask":"0.96"},{"asset_id":"54232589582260339592359130012520874109228367674780084862642636038394766871668","price":"0.01","size":"21088.86","side":"BUY","hash":"f0431174e1fc92b410000bf89fb05d99e8e7b1a8","best_bid":"0.04","best_ask":"0.06"}],"timestamp":"1768250249216","event_type":"price_change"}}
{"schema_version":1,"source":"clob_ws_market","recv_ts_ns":1768250249415682095,"event_type":"price_change","market":"0xe51aa24ab1bbfefce466d642ad98587d13123e4ef95ec9aa73b712e775d4cbba","server_ts_ms":1768250249235,"raw":{"market":"0xe51aa24ab1bbfefce466d642ad98587d13123e4ef95ec9aa73b712e775d4cbba","price_changes":[{"asset_id":"54232589582260339592359130012520874109228367674780084862642636038394766871668","price":"0.04","size":"1754.74","side":"BUY","hash":"c60e85d2e44bf1a228ff64f98f5d1cf286aee108","best_bid":"0.04","best_ask":"0.06"},{"asset_id":"96886111393998001968863279421729456597655847484197549086072988901191634450924","price":"0.96","size":"1754.74","side":"SELL","hash":"76a0f41895963ca8da9f19d0a4c36a277481626d","best_bid":"0.94","best_ask":"0.96"}],"timestamp":"1768250249235","event_type":"price_change"}}
{"schema_version":1,"source":"clob_ws_market","recv_ts_ns":1768250249428153860,"event_type":"price_change","market":"0xe51aa24ab1bbfefce466d642ad98587d13123e4ef95ec9aa73b712e775d4cbba","server_ts_ms":1768250249240,"raw":{"market":"0xe51aa24ab1bbfefce466d642ad98587d13123e4ef95ec9aa73b712e775d4cbba","price_changes":[{"asset_id":"96886111393998001968863279421729456597655847484197549086072988901191634450924","price":"0.93","size":"1417.82","side":"BUY","hash":"46b8df715feab59a33ea05fc8fcd357a8e9c6ed9","best_bid":"0.94","best_ask":"0.96"},{"asset_id":"54232589582260339592359130012520874109228367674780084862642636038394766871668","price":"0.07","size":"1417.82","side":"SELL","hash":"aa99ea4af7fe8bcf039ece672da1fa9928611f9d","best_bid":"0.04","best_ask":"0.06"}],"timestamp":"1768250249240","event_type":"price_change"}}
{"schema_version":1,"source":"clob_ws_market","recv_ts_ns":1768250249432466229,"event_type":"price_change","market":"0xe51aa24ab1bbfefce466d642ad98587d13123e4ef95ec9aa73b712e775d4cbba","server_ts_ms":1768250249241,"raw":{"market":"0xe51aa24ab1bbfefce466d642ad98587d13123e4ef95ec9aa73b712e775d4cbba","price_changes":[{"asset_id":"96886111393998001968863279421729456597655847484197549086072988901191634450924","price":"0.93","size":"1433.82","side":"BUY","hash":"ffd5970a938f57a33fc486d01df4c9bf8a3005ca","best_bid":"0.94","best_ask":"0.96"},{"asset_id":"54232589582260339592359130012520874109228367674780084862642636038394766871668","price":"0.07","size":"1433.82","side":"SELL","hash":"633ec311815430228b8904432d9163d6e23b5c6a","best_bid":"0.04","best_ask":"0.06"}],"timestamp":"1768250249241","event_type":"price_change"}}
{"schema_version":1,"source":"clob_ws_market","recv_ts_ns":1768250249436346583,"event_type":"price_change","market":"0xe51aa24ab1bbfefce466d642ad98587d13123e4ef95ec9aa73b712e775d4cbba","server_ts_ms":1768250249243,"raw":{"market":"0xe51aa24ab1bbfefce466d642ad98587d13123e4ef95ec9aa73b712e775d4cbba","price_changes":[{"asset_id":"96886111393998001968863279421729456597655847484197549086072988901191634450924","price":"0.99","size":"21093.86","side":"SELL","hash":"3d40dc85034a33826ad42258085eacbc0113c260","best_bid":"0.94","best_ask":"0.96"},{"asset_id":"54232589582260339592359130012520874109228367674780084862642636038394766871668","price":"0.01","size":"21093.86","side":"BUY","hash":"b5df40f0bcce7927269d058cf03d0317c7aeb0f1","best_bid":"0.04","best_ask":"0.06"}],"timestamp":"1768250249243","event_type":"price_change"}}
{"schema_version":1,"source":"clob_ws_market","recv_ts_ns":1768250249439821027,"event_type":"price_change","market":"0xe51aa24ab1bbfefce466d642ad98587d13123e4ef95ec9aa73b712e775d4cbba","server_ts_ms":1768250249243,"raw":{"market":"0xe51aa24ab1bbfefce466d642ad98587d13123e4ef95ec9aa73b712e775d4cbba","price_changes":[{"asset_id":"96886111393998001968863279421729456597655847484197549086072988901191634450924","price":"0.91","size":"3023.44","side":"BUY","hash":"3e72dbea6dccacf319cb3bdfc97343ce4304749c","best_bid":"0.94","best_ask":"0.96"},{"asset_id":"54232589582260339592359130012520874109228367674780084862642636038394766871668","price":"0.09","size":"3023.44","side":"SELL","hash":"38b330d39e169a92ecd89fa13f91f39a2935fdf8","best_bid":"0.04","best_ask":"0.06"}],"timestamp":"1768250249243","event_type":"price_change"}}
{"schema_version":1,"source":"clob_ws_market","recv_ts_ns":1768250249443363702,"event_type":"price_change","market":"0xe51aa24ab1bbfefce466d642ad98587d13123e4ef95ec9aa73b712e775d4cbba","server_ts_ms":1768250249245,"raw":{"market":"0xe51aa24ab1bbfefce466d642ad98587d13123e4ef95ec9aa73b712e775d4cbba","price_changes":[{"asset_id":"96886111393998001968863279421729456597655847484197549086072988901191634450924","price":"0.93","size":"1449.82","side":"BUY","hash":"c066593290e24a437102b6dfa58f0e0bd7f36458","best_bid":"0.94","best_ask":"0.96"},{"asset_id":"54232589582260339592359130012520874109228367674780084862642636038394766871668","price":"0.07","size":"1449.82","side":"SELL","hash":"9770a66d2430ab21f2f3c0f5cead21deffccef1c","best_bid":"0.04","best_ask":"0.06"}],"timestamp":"1768250249245","event_type":"price_change"}}
{"schema_version":1,"source":"clob_ws_market","recv_ts_ns":1768250249452110756,"event_type":"best_bid_ask","market":"0xe51aa24ab1bbfefce466d642ad98587d13123e4ef95ec9aa73b712e775d4cbba","server_ts_ms":1768250249251,"raw":{"market":"0xe51aa24ab1bbfefce466d642ad98587d13123e4ef95ec9aa73b712e775d4cbba","asset_id":"96886111393998001968863279421729456597655847484197549086072988901191634450924","best_bid":"0.94","best_ask":"0.95","spread":"0.01","timestamp":"1768250249251","event_type":"best_bid_ask"}}
{"schema_version":1,"source":"clob_ws_market","recv_ts_ns":1768250249454180706,"event_type":"price_change","market":"0xe51aa24ab1bbfefce466d642ad98587d13123e4ef95ec9aa73b712e775d4cbba","server_ts_ms":1768250249250,"raw":{"market":"0xe51aa24ab1bbfefce466d642ad98587d13123e4ef95ec9aa73b712e775d4cbba","price_changes":[{"asset_id":"54232589582260339592359130012520874109228367674780084862642636038394766871668","price":"0.05","size":"100","side":"BUY","hash":"22ef95a2691aeb36ed9060fd89fb568156077468","best_bid":"0.05","best_ask":"0.06"},{"asset_id":"96886111393998001968863279421729456597655847484197549086072988901191634450924","price":"0.95","size":"100","side":"SELL","hash":"67a720ecf710663cc2515decd21142f6a3931294","best_bid":"0.94","best_ask":"0.95"}],"timestamp":"1768250249250","event_type":"price_change"}}
{"schema_version":1,"source":"clob_ws_market","recv_ts_ns":1768250249485588683,"event_type":"price_change","market":"0xe51aa24ab1bbfefce466d642ad98587d13123e4ef95ec9aa73b712e775d4cbba","server_ts_ms":1768250249263,"raw":{"market":"0xe51aa24ab1bbfefce466d642ad98587d13123e4ef95ec9aa73b712e775d4cbba","price_changes":[{"asset_id":"96886111393998001968863279421729456597655847484197549086072988901191634450924","price":"0.94","size":"1306.27","side":"BUY","hash":"6fa72a4fa7a97e90bf4d9ae894ee0801b79a76fa","best_bid":"0.94","best_ask":"0.95"},{"asset_id":"54232589582260339592359130012520874109228367674780084862642636038394766871668","price":"0.06","size":"1306.27","side":"SELL","hash":"44be5f76a48ef6d6dc5847e1f0e40bf1a4d3fa52","best_bid":"0.05","best_ask":"0.06"}],"timestamp":"1768250249263","event_type":"price_change"}}
{"schema_version":1,"source":"clob_ws_market","recv_ts_ns":1768250249491797068,"event_type":"price_change","market":"0xe51aa24ab1bbfefce466d642ad98587d13123e4ef95ec9aa73b712e775d4cbba","server_ts_ms":1768250249268,"raw":{"market":"0xe51aa24ab1bbfefce466d642ad98587d13123e4ef95ec9aa73b712e775d4cbba","price_changes":[{"asset_id":"54232589582260339592359130012520874109228367674780084862642636038394766871668","price":"0.03","size":"1266.33","side":"BUY","hash":"1b9db0321ec9e3f75a195c1389e26ca6bd16a238","best_bid":"0.05","best_ask":"0.06"},{"asset_id":"96886111393998001968863279421729456597655847484197549086072988901191634450924","price":"0.97","size":"1266.33","side":"SELL","hash":"96d439e298de43e6dff46a89f9e14c5d535688cf","best_bid":"0.94","best_ask":"0.95"}],"timestamp":"1768250249268","event_type":"price_change"}}
{"schema_version":1,"source":"clob_ws_market","recv_ts_ns":1768250249499490789,"event_type":"price_change","market":"0xe51aa24ab1bbfefce466d642ad98587d13123e4ef95ec9aa73b712e775d4cbba","server_ts_ms":1768250249269,"raw":{"market":"0xe51aa24ab1bbfefce466d642ad98587d13123e4ef95ec9aa73b712e775d4cbba","price_changes":[{"asset_id":"96886111393998001968863279421729456597655847484197549086072988901191634450924","price":"0.97","size":"1278.33","side":"SELL","hash":"6697dedee27c870e6fbfe0911527067b3c8a6e9f","best_bid":"0.94","best_ask":"0.95"},{"asset_id":"54232589582260339592359130012520874109228367674780084862642636038394766871668","price":"0.03","size":"1278.33","side":"BUY","hash":"b036fb4990eb7bcbb12a8ba9acc297216d6d4f01","best_bid":"0.05","best_ask":"0.06"}],"timestamp":"1768250249269","event_type":"price_change"}}
{"schema_version":1,"source":"clob_ws_market","recv_ts_ns":1768250249513242838,"event_type":"price_change","market":"0xe51aa24ab1bbfefce466d642ad98587d13123e4ef95ec9aa73b712e775d4cbba","server_ts_ms":1768250249271,"raw":{"market":"0xe51aa24ab1bbfefce466d642ad98587d13123e4ef95ec9aa73b712e775d4cbba","price_changes":[{"asset_id":"96886111393998001968863279421729456597655847484197549086072988901191634450924","price":"0.94","size":"1290.27","side":"BUY","hash":"5356b4d8398f4bde8aed84751b35b84c3ebdbe5a","best_bid":"0.94","best_ask":"0.95"},{"asset_id":"54232589582260339592359130012520874109228367674780084862642636038394766871668","price":"0.06","size":"1290.27","side":"SELL","hash":"b169277107996777e2b45c7fed3579e960d5bc4a","best_bid":"0.05","best_ask":"0.06"}],"timestamp":"1768250249271","event_type":"price_change"}}
{"schema_version":1,"source":"clob_ws_market","recv_ts_ns":1768250249549714691,"event_type":"price_change","market":"0xe51aa24ab1bbfefce466d642ad98587d13123e4ef95ec9aa73b712e775d4cbba","server_ts_ms":1768250249278,"raw":{"market":"0xe51aa24ab1bbfefce466d642ad98587d13123e4ef95ec9aa73b712e775d4cbba","price_changes":[{"asset_id":"54232589582260339592359130012520874109228367674780084862642636038394766871668","price":"0.03","size":"1262.33","side":"BUY","hash":"baddc7d7787e31fee7c65c7a19bce39f57901ef4","best_bid":"0.05","best_ask":"0.06"},{"asset_id":"96886111393998001968863279421729456597655847484197549086072988901191634450924","price":"0.97","size":"1262.33","side":"SELL","hash":"93bc7fddb113f580bd6ca1387135abd750c7f479","best_bid":"0.94","best_ask":"0.95"}],"timestamp":"1768250249278","event_type":"price_change"}}
{"schema_version":1,"source":"clob_ws_market","recv_ts_ns":1768250249557685275,"event_type":"price_change","market":"0xe51aa24ab1bbfefce466d642ad98587d13123e4ef95ec9aa73b712e775d4cbba","server_ts_ms":1768250249279,"raw":{"market":"0xe51aa24ab1bbfefce466d642ad98587d13123e4ef95ec9aa73b712e775d4cbba","price_changes":[{"asset_id":"96886111393998001968863279421729456597655847484197549086072988901191634450924","price":"0.94","size":"1274.27","side":"BUY","hash":"cc4850fe2eade0935d02c4268fded1458c471294","best_bid":"0.94","best_ask":"0.95"},{"asset_id":"54232589582260339592359130012520874109228367674780084862642636038394766871668","price":"0.06","size":"1274.27","side":"SELL","hash":"0206f2278c9967bfdd3715bc6ca0bbcb7725f622","best_bid":"0.05","best_ask":"0.06"}],"timestamp":"1768250249279","event_type":"price_change"}}
{"schema_version":1,"source":"clob_ws_market","recv_ts_ns":1768250249563494385,"event_type":"price_change","market":"0xe51aa24ab1bbfefce466d642ad98587d13123e4ef95ec9aa73b712e775d4cbba","server_ts_ms":1768250249280,"raw":{"market":"0xe51aa24ab1bbfefce466d642ad98587d13123e4ef95ec9aa73b712e775d4cbba","price_changes":[{"asset_id":"96886111393998001968863279421729456597655847484197549086072988901191634450924","price":"0.94","size":"1268.77","side":"BUY","hash":"0eb7a38aa40193cae8224e5bd7d3858cd94dd27f","best_bid":"0.94","best_ask":"0.95"},{"asset_id":"54232589582260339592359130012520874109228367674780084862642636038394766871668","price":"0.06","size":"1268.77","side":"SELL","hash":"cab7f8f13eca19a9f2ab60d90f4aced933a3a8b5","best_bid":"0.05","best_ask":"0.06"}],"timestamp":"1768250249280","event_type":"price_change"}}
{"schema_version":1,"source":"clob_ws_market","recv_ts_ns":1768250249567550904,"event_type":"price_change","market":"0xe51aa24ab1bbfefce466d642ad98587d13123e4ef95ec9aa73b712e775d4cbba","server_ts_ms":1768250249281,"raw":{"market":"0xe51aa24ab1bbfefce466d642ad98587d13123e4ef95ec9aa73b712e775d4cbba","price_changes":[{"asset_id":"96886111393998001968863279421729456597655847484197549086072988901191634450924","price":"0.94","size":"1263.27","side":"BUY","hash":"d8fc965849ebd11e4de8ccc83bb86783cf863b70","best_bid":"0.94","best_ask":"0.95"},{"asset_id":"54232589582260339592359130012520874109228367674780084862642636038394766871668","price":"0.06","size":"1263.27","side":"SELL","hash":"0b5c034fbc892a48d5974522a0d63c84f167a7e9","best_bid":"0.05","best_ask":"0.06"}],"timestamp":"1768250249281","event_type":"price_change"}}
{"schema_version":1,"source":"clob_ws_market","recv_ts_ns":1768250249587423782,"event_type":"price_change","market":"0xe51aa24ab1bbfefce466d642ad98587d13123e4ef95ec9aa73b712e775d4cbba","server_ts_ms":1768250249286,"raw":{"market":"0xe51aa24ab1bbfefce466d642ad98587d13123e4ef95ec9aa73b712e775d4cbba","price_changes":[{"asset_id":"96886111393998001968863279421729456597655847484197549086072988901191634450924","price":"0.94","size":"1247.27","side":"BUY","hash":"a7ac34e798997faefe915eb6e3b6e7a758426a93","best_bid":"0.94","best_ask":"0.95"},{"asset_id":"54232589582260339592359130012520874109228367674780084862642636038394766871668","price":"0.06","size":"1247.27","side":"SELL","hash":"62f4f36627fac6f6262e7c517a7f300e6ce9785a","best_bid":"0.05","best_ask":"0.06"}],"timestamp":"1768250249286","event_type":"price_change"}}
{"schema_version":1,"source":"clob_ws_market","recv_ts_ns":1768250249613554865,"event_type":"price_change","market":"0xe51aa24ab1bbfefce466d642ad98587d13123e4ef95ec9aa73b712e775d4cbba","server_ts_ms":1768250249292,"raw":{"market":"0xe51aa24ab1bbfefce466d642ad98587d13123e4ef95ec9aa73b712e775d4cbba","price_changes":[{"asset_id":"96886111393998001968863279421729456597655847484197549086072988901191634450924","price":"0.93","size":"1455.32","side":"BUY","hash":"582a1cb46815d056ceed940278b109781c53126b","best_bid":"0.94","best_ask":"0.95"},{"asset_id":"54232589582260339592359130012520874109228367674780084862642636038394766871668","price":"0.07","size":"1455.32","side":"SELL","hash":"98270971b57f88f519e1a8003e7ce48fe6ad2823","best_bid":"0.05","best_ask":"0.06"}],"timestamp":"1768250249292","event_type":"price_change"}}
{"schema_version":1,"source":"clob_ws_market","recv_ts_ns":1768250249622841630,"event_type":"price_change","market":"0xe51aa24ab1bbfefce466d642ad98587d13123e4ef95ec9aa73b712e775d4cbba","server_ts_ms":1768250249294,"raw":{"market":"0xe51aa24ab1bbfefce466d642ad98587d13123e4ef95ec9aa73b712e775d4cbba","price_changes":[{"asset_id":"96886111393998001968863279421729456597655847484197549086072988901191634450924","price":"0.94","size":"1231.27","side":"BUY","hash":"5cfef3e6469e96632fdf954d1290b8c5ac7321e8","best_bid":"0.94","best_ask":"0.95"},{"asset_id":"54232589582260339592359130012520874109228367674780084862642636038394766871668","price":"0.06","size":"1231.27","side":"SELL","hash":"431eeb95e938f16de4ddd5a0e339e583dae2e2b1","best_bid":"0.05","best_ask":"0.06"}],"timestamp":"1768250249294","event_type":"price_change"}}
{"schema_version":1,"source":"clob_ws_market","recv_ts_ns":1768250249625149835,"event_type":"price_change","market":"0xe51aa24ab1bbfefce466d642ad98587d13123e4ef95ec9aa73b712e775d4cbba","server_ts_ms":1768250249296,"raw":{"market":"0xe51aa24ab1bbfefce466d642ad98587d13123e4ef95ec9aa73b712e775d4cbba","price_changes":[{"asset_id":"54232589582260339592359130012520874109228367674780084862642636038394766871668","price":"0.02","size":"5443.25","side":"BUY","hash":"4c175de4f3b8058bdeb2b8c4971668782ddc761d","best_bid":"0.05","best_ask":"0.06"},{"asset_id":"96886111393998001968863279421729456597655847484197549086072988901191634450924","price":"0.98","size":"5443.25","side":"SELL","hash":"7ea46dc82653dd5c536f0c60d02c666690841e49","best_bid":"0.94","best_ask":"0.95"}],"timestamp":"1768250249296","event_type":"price_change"}}
{"schema_version":1,"source":"clob_ws_market","recv_ts_ns":1768250249627496791,"event_type":"price_change","market":"0xe51aa24ab1bbfefce466d642ad98587d13123e4ef95ec9aa73b712e775d4cbba","server_ts_ms":1768250249302,"raw":{"market":"0xe51aa24ab1bbfefce466d642ad98587d13123e4ef95ec9aa73b712e775d4cbba","price_changes":[{"asset_id":"96886111393998001968863279421729456597655847484197549086072988901191634450924","price":"0.95","size":"112","side":"SELL","hash":"26bb4e09c4dbd339fcbd9dff5658b94d50dfba67","best_bid":"0.94","best_ask":"0.95"},{"asset_id":"54232589582260339592359130012520874109228367674780084862642636038394766871668","price":"0.05","size":"112","side":"BUY","hash":"ba98c437f17df5e2cff560b97c837f8a8bf33dd8","best_bid":"0.05","best_ask":"0.06"}],"timestamp":"1768250249302","event_type":"price_change"}}
{"schema_version":1,"source":"clob_ws_market","recv_ts_ns":1768250249636755359,"event_type":"price_change","market":"0xe51aa24ab1bbfefce466d642ad98587d13123e4ef95ec9aa73b712e775d4cbba","server_ts_ms":1768250249307,"raw":{"market":"0xe51aa24ab1bbfefce466d642ad98587d13123e4ef95ec9aa73b712e775d4cbba","price_changes":[{"asset_id":"54232589582260339592359130012520874109228367674780084862642636038394766871668","price":"0.04","size":"1778.74","side":"BUY","hash":"48e0138dc578afcc37322427e78f4465a8c994c5","best_bid":"0.05","best_ask":"0.06"},{"asset_id":"96886111393998001968863279421729456597655847484197549086072988901191634450924","price":"0.96","size":"1778.74","side":"SELL","hash":"5d33c99263e366804048699350d90bec0b6a58e3","best_bid":"0.94","best_ask":"0.95"}],"timestamp":"1768250249307","event_type":"price_change"}}
{"schema_version":1,"source":"clob_ws_market","recv_ts_ns":1768250249643838103,"event_type":"price_change","market":"0xe51aa24ab1bbfefce466d642ad98587d13123e4ef95ec9aa73b712e775d4cbba","server_ts_ms":1768250249309,"raw":{"market":"0xe51aa24ab1bbfefce466d642ad98587d13123e4ef95ec9aa73b712e775d4cbba","price_changes":[{"asset_id":"54232589582260339592359130012520874109228367674780084862642636038394766871668","price":"0.04","size":"1786.74","side":"BUY","hash":"1fabbd08ad362d460f43a5d5325c3907dac7f09e","best_bid":"0.05","best_ask":"0.06"},{"asset_id":"96886111393998001968863279421729456597655847484197549086072988901191634450924","price":"0.96","size":"1786.74","side":"SELL","hash":"34de2a9c4b4c8532801853136096537fb0537129","best_bid":"0.94","best_ask":"0.95"}],"timestamp":"1768250249309","event_type":"price_change"}}
{"schema_version":1,"source":"clob_ws_market","recv_ts_ns":1768250249650044950,"event_type":"price_change","market":"0xe51aa24ab1bbfefce466d642ad98587d13123e4ef95ec9aa73b712e775d4cbba","server_ts_ms":1768250249309,"raw":{"market":"0xe51aa24ab1bbfefce466d642ad98587d13123e4ef95ec9aa73b712e775d4cbba","price_changes":[{"asset_id":"96886111393998001968863279421729456597655847484197549086072988901191634450924","price":"0.93","size":"1471.32","side":"BUY","hash":"cf6eee2a85fdf41a6b9df2863a0d72806175faaf","best_bid":"0.94","best_ask":"0.95"},{"asset_id":"54232589582260339592359130012520874109228367674780084862642636038394766871668","price":"0.07","size":"1471.32","side":"SELL","hash":"6ffa2c888651197a03311c558ebd851bce4286e0","best_bid":"0.05","best_ask":"0.06"}],"timestamp":"1768250249309","event_type":"price_change"}}
{"schema_version":1,"source":"clob_ws_market","recv_ts_ns":1768250249655681838,"event_type":"price_change","market":"0xe51aa24ab1bbfefce466d642ad98587d13123e4ef95ec9aa73b712e775d4cbba","server_ts_ms":1768250249313,"raw":{"market":"0xe51aa24ab1bbfefce466d642ad98587d13123e4ef95ec9aa73b712e775d4cbba","price_changes":[{"asset_id":"96886111393998001968863279421729456597655847484197549086072988901191634450924","price":"0.96","size":"1805.74","side":"SELL","hash":"8aa60aa350d4a967551e4522d3e6b3f0563b1b82","best_bid":"0.94","best_ask":"0.95"},{"asset_id":"54232589582260339592359130012520874109228367674780084862642636038394766871668","price":"0.04","size":"1805.74","side":"BUY","hash":"404d4d99601243c66c9ff8ffc6a32fe4ad79fa3a","best_bid":"0.05","best_ask":"0.06"}],"timestamp":"1768250249313","event_type":"price_change"}}
{"schema_version":1,"source":"clob_ws_market","recv_ts_ns":1768250249664764250,"event_type":"price_change","market":"0xe51aa24ab1bbfefce466d642ad98587d13123e4ef95ec9aa73b712e775d4cbba","server_ts_ms":1768250249314,"raw":{"market":"0xe51aa24ab1bbfefce466d642ad98587d13123e4ef95ec9aa73b712e775d4cbba","price_changes":[{"asset_id":"54232589582260339592359130012520874109228367674780084862642636038394766871668","price":"0.05","size":"123","side":"BUY","hash":"ee4fe607fbf2d748c09d32ff48b7375580e5ce3c","best_bid":"0.05","best_ask":"0.06"},{"asset_id":"96886111393998001968863279421729456597655847484197549086072988901191634450924","price":"0.95","size":"123","side":"SELL","hash":"20f8cce3d2fab6af3cca340ddb97fa2da7a3bba5","best_bid":"0.94","best_ask":"0.95"}],"timestamp":"1768250249314","event_type":"price_change"}}
{"schema_version":1,"source":"clob_ws_market","recv_ts_ns":1768250249673079448,"event_type":"price_change","market":"0xe51aa24ab1bbfefce466d642ad98587d13123e4ef95ec9aa73b712e775d4cbba","server_ts_ms":1768250249318,"raw":{"market":"0xe51aa24ab1bbfefce466d642ad98587d13123e4ef95ec9aa73b712e775d4cbba","price_changes":[{"asset_id":"96886111393998001968863279421729456597655847484197549086072988901191634450924","price":"0.93","size":"1476.82","side":"BUY","hash":"7762600e15376eb074c9173808f6bdd14f8b20fd","best_bid":"0.94","best_ask":"0.95"},{"asset_id":"54232589582260339592359130012520874109228367674780084862642636038394766871668","price":"0.07","size":"1476.82","side":"SELL","hash":"9321c0f326492d495207a5dbf86c541534ce9907","best_bid":"0.05","best_ask":"0.06"}],"timestamp":"1768250249318","event_type":"price_change"}}
{"schema_version":1,"source":"clob_ws_market","recv_ts_ns":1768250249677439760,"event_type":"price_change","market":"0xe51aa24ab1bbfefce466d642ad98587d13123e4ef95ec9aa73b712e775d4cbba","server_ts_ms":1768250249321,"raw":{"market":"0xe51aa24ab1bbfefce466d642ad98587d13123e4ef95ec9aa73b712e775d4cbba","price_changes":[{"asset_id":"96886111393998001968863279421729456597655847484197549086072988901191634450924","price":"0.93","size":"1492.82","side":"BUY","hash":"282006e8b51caf780933625a965c42233b928c2a","best_bid":"0.94","best_ask":"0.95"},{"asset_id":"54232589582260339592359130012520874109228367674780084862642636038394766871668","price":"0.07","size":"1492.82","side":"SELL","hash":"d5eff7dbddd924d5ddd7863dd3ee44c1041dd349","best_bid":"0.05","best_ask":"0.06"}],"timestamp":"1768250249321","event_type":"price_change"}}
{"schema_version":1,"source":"clob_ws_market","recv_ts_ns":1768250249683469928,"event_type":"price_change","market":"0xe51aa24ab1bbfefce466d642ad98587d13123e4ef95ec9aa73b712e775d4cbba","server_ts_ms":1768250249323,"raw":{"market":"0xe51aa24ab1bbfefce466d642ad98587d13123e4ef95ec9aa73b712e775d4cbba","price_changes":[{"asset_id":"54232589582260339592359130012520874109228367674780084862642636038394766871668","price":"0.04","size":"1810.74","side":"BUY","hash":"103cd40469bc99e61d03b747c78214db8d6c8056","best_bid":"0.05","best_ask":"0.06"},{"asset_id":"96886111393998001968863279421729456597655847484197549086072988901191634450924","price":"0.96","size":"1810.74","side":"SELL","hash":"fa1d6f37e419931fe69591ee628acba50d7c7e6e","best_bid":"0.94","best_ask":"0.95"}],"timestamp":"1768250249323","event_type":"price_change"}}
{"schema_version":1,"source":"clob_ws_market","recv_ts_ns":1768250249687889216,"event_type":"price_change","market":"0xe51aa24ab1bbfefce466d642ad98587d13123e4ef95ec9aa73b712e775d4cbba","server_ts_ms":1768250249324,"raw":{"market":"0xe51aa24ab1bbfefce466d642ad98587d13123e4ef95ec9aa73b712e775d4cbba","price_changes":[{"asset_id":"54232589582260339592359130012520874109228367674780084862642636038394766871668","price":"0.04","size":"1826.74","side":"BUY","hash":"a94591aa584f3ca89cfefcbcdfa8bbe0e8d787ae","best_bid":"0.05","best_ask":"0.06"},{"asset_id":"96886111393998001968863279421729456597655847484197549086072988901191634450924","price":"0.96","size":"1826.74","side":"SELL","hash":"90050ec4eddcd33e8883ac08cdbb54b3ef9959bf","best_bid":"0.94","best_ask":"0.95"}],"timestamp":"1768250249324","event_type":"price_change"}}
{"schema_version":1,"source":"clob_ws_market","recv_ts_ns":1768250249710801175,"event_type":"price_change","market":"0xe51aa24ab1bbfefce466d642ad98587d13123e4ef95ec9aa73b712e775d4cbba","server_ts_ms":1768250249327,"raw":{"market":"0xe51aa24ab1bbfefce466d642ad98587d13123e4ef95ec9aa73b712e775d4cbba","price_changes":[{"asset_id":"96886111393998001968863279421729456597655847484197549086072988901191634450924","price":"0.93","size":"1508.82","side":"BUY","hash":"8875e6bcb33b88370a96ac255bbd31cea2713d91","best_bid":"0.94","best_ask":"0.95"},{"asset_id":"54232589582260339592359130012520874109228367674780084862642636038394766871668","price":"0.07","size":"1508.82","side":"SELL","hash":"6a419dda54537af8984c20fe5b7b6bd4691096a0","best_bid":"0.05","best_ask":"0.06"}],"timestamp":"1768250249327","event_type":"price_change"}}
{"schema_version":1,"source":"clob_ws_market","recv_ts_ns":1768250249715607934,"event_type":"price_change","market":"0xe51aa24ab1bbfefce466d642ad98587d13123e4ef95ec9aa73b712e775d4cbba","server_ts_ms":1768250249329,"raw":{"market":"0xe51aa24ab1bbfefce466d642ad98587d13123e4ef95ec9aa73b712e775d4cbba","price_changes":[{"asset_id":"96886111393998001968863279421729456597655847484197549086072988901191634450924","price":"0.93","size":"1514.32","side":"BUY","hash":"24266d25195570060d25db5130fc2dd840732d2c","best_bid":"0.94","best_ask":"0.95"},{"asset_id":"54232589582260339592359130012520874109228367674780084862642636038394766871668","price":"0.07","size":"1514.32","side":"SELL","hash":"5558bd77e3f351a91258b916935dd0acfac2ea44","best_bid":"0.05","best_ask":"0.06"}],"timestamp":"1768250249329","event_type":"price_change"}}
{"schema_version":1,"source":"clob_ws_market","recv_ts_ns":1768250249723829087,"event_type":"price_change","market":"0xe51aa24ab1bbfefce466d642ad98587d13123e4ef95ec9aa73b712e775d4cbba","server_ts_ms":1768250249330,"raw":{"market":"0xe51aa24ab1bbfefce466d642ad98587d13123e4ef95ec9aa73b712e775d4cbba","price_changes":[{"asset_id":"54232589582260339592359130012520874109228367674780084862642636038394766871668","price":"0.03","size":"1278.33","side":"BUY","hash":"214b38354445626544952bba7396edc82fc4bf0b","best_bid":"0.05","best_ask":"0.06"},{"asset_id":"96886111393998001968863279421729456597655847484197549086072988901191634450924","price":"0.97","size":"1278.33","side":"SELL","hash":"04ffae2ff9553f32d89447787c0d6d666d0ecd4e","best_bid":"0.94","best_ask":"0.95"}],"timestamp":"1768250249330","event_type":"price_change"}}
{"schema_version":1,"source":"clob_ws_market","recv_ts_ns":1768250249728727234,"event_type":"price_change","market":"0xe51aa24ab1bbfefce466d642ad98587d13123e4ef95ec9aa73b712e775d4cbba","server_ts_ms":1768250249331,"raw":{"market":"0xe51aa24ab1bbfefce466d642ad98587d13123e4ef95ec9aa73b712e775d4cbba","price_changes":[{"asset_id":"96886111393998001968863279421729456597655847484197549086072988901191634450924","price":"0.97","size":"1266.33","side":"SELL","hash":"48360701ad4fbd45e664311158f3ddc9c0848856","best_bid":"0.94","best_ask":"0.95"},{"asset_id":"54232589582260339592359130012520874109228367674780084862642636038394766871668","price":"0.03","size":"1266.33","side":"BUY","hash":"66acb49552d8366f2658ae76fc68a7d96eafa287","best_bid":"0.05","best_ask":"0.06"}],"timestamp":"1768250249331","event_type":"price_change"}}
{"schema_version":1,"source":"clob_ws_market","recv_ts_ns":1768250249748530740,"event_type":"price_change","market":"0xe51aa24ab1bbfefce466d642ad98587d13123e4ef95ec9aa73b712e775d4cbba","server_ts_ms":1768250249338,"raw":{"market":"0xe51aa24ab1bbfefce466d642ad98587d13123e4ef95ec9aa73b712e775d4cbba","price_changes":[{"asset_id":"54232589582260339592359130012520874109228367674780084862642636038394766871668","price":"0.03","size":"1255.33","side":"BUY","hash":"7a1cb86584b6a2deb41cce9ded24545c3c780ba4","best_bid":"0.05","best_ask":"0.06"},{"asset_id":"96886111393998001968863279421729456597655847484197549086072988901191634450924","price":"0.97","size":"1255.33","side":"SELL","hash":"60c174ababa0a8cf90129d3274696085c7b6a2ab","best_bid":"0.94","best_ask":"0.95"}],"timestamp":"1768250249338","event_type":"price_change"}}
{"schema_version":1,"source":"clob_ws_market","recv_ts_ns":1768250249758468826,"event_type":"price_change","market":"0xe51aa24ab1bbfefce466d642ad98587d13123e4ef95ec9aa73b712e775d4cbba","server_ts_ms":1768250249340,"raw":{"market":"0xe51aa24ab1bbfefce466d642ad98587d13123e4ef95ec9aa73b712e775d4cbba","price_changes":[{"asset_id":"54232589582260339592359130012520874109228367674780084862642636038394766871668","price":"0.02","size":"6443.25","side":"BUY","hash":"0844645c4ea38974faa29d5dc75146974ba9134b","best_bid":"0.05","best_ask":"0.06"},{"asset_id":"96886111393998001968863279421729456597655847484197549086072988901191634450924","price":"0.98","size":"6443.25","side":"SELL","hash":"c4434dd421db76bd0db8b63516b8e52d78634b4b","best_bid":"0.94","best_ask":"0.95"}],"timestamp":"1768250249340","event_type":"price_change"}}
{"schema_version":1,"source":"clob_ws_market","recv_ts_ns":1768250249788208396,"event_type":"price_change","market":"0xe51aa24ab1bbfefce466d642ad98587d13123e4ef95ec9aa73b712e775d4cbba","server_ts_ms":1768250249347,"raw":{"market":"0xe51aa24ab1bbfefce466d642ad98587d13123e4ef95ec9aa73b712e775d4cbba","price_changes":[{"asset_id":"96886111393998001968863279421729456597655847484197549086072988901191634450924","price":"0.93","size":"1530.32","side":"BUY","hash":"0df7834109c4f0671c9cdb997108a91a5940321c","best_bid":"0.94","best_ask":"0.95"},{"asset_id":"54232589582260339592359130012520874109228367674780084862642636038394766871668","price":"0.07","size":"1530.32","side":"SELL","hash":"6b8bfe35ab3659c84faea9e49878ee8b990c0c69","best_bid":"0.05","best_ask":"0.06"}],"timestamp":"1768250249347","event_type":"price_change"}}
{"schema_version":1,"source":"clob_ws_market","recv_ts_ns":1768250249809928037,"event_type":"price_change","market":"0xe51aa24ab1bbfefce466d642ad98587d13123e4ef95ec9aa73b712e775d4cbba","server_ts_ms":1768250249359,"raw":{"market":"0xe51aa24ab1bbfefce466d642ad98587d13123e4ef95ec9aa73b712e775d4cbba","price_changes":[{"asset_id":"96886111393998001968863279421729456597655847484197549086072988901191634450924","price":"0.91","size":"1623.44","side":"BUY","hash":"ab81d8c5d3f5af3fa2f4450348ca436b9cee14b9","best_bid":"0.94","best_ask":"0.95"},{"asset_id":"54232589582260339592359130012520874109228367674780084862642636038394766871668","price":"0.09","size":"1623.44","side":"SELL","hash":"15a2c09914e8fd9dad192c337e392f52a6f53142","best_bid":"0.05","best_ask":"0.06"}],"timestamp":"1768250249359","event_type":"price_change"}}
{"schema_version":1,"source":"clob_ws_market","recv_ts_ns":1768250249888732101,"event_type":"price_change","market":"0xe51aa24ab1bbfefce466d642ad98587d13123e4ef95ec9aa73b712e775d4cbba","server_ts_ms":1768250249466,"raw":{"market":"0xe51aa24ab1bbfefce466d642ad98587d13123e4ef95ec9aa73b712e775d4cbba","price_changes":[{"asset_id":"54232589582260339592359130012520874109228367674780084862642636038394766871668","price":"0.05","size":"23","side":"BUY","hash":"0482091b6c6a2a711dcd50a6ce70f7a6674bb1ac","best_bid":"0.05","best_ask":"0.06"},{"asset_id":"96886111393998001968863279421729456597655847484197549086072988901191634450924","price":"0.95","size":"23","side":"SELL","hash":"75d15f515d2a042783d05553438cf0487d2203e3","best_bid":"0.94","best_ask":"0.95"}],"timestamp":"1768250249466","event_type":"price_change"}}
{"schema_version":1,"source":"clob_ws_market","recv_ts_ns":1768250249893603241,"event_type":"price_change","market":"0xe51aa24ab1bbfefce466d642ad98587d13123e4ef95ec9aa73b712e775d4cbba","server_ts_ms":1768250249479,"raw":{"market":"0xe51aa24ab1bbfefce466d642ad98587d13123e4ef95ec9aa73b712e775d4cbba","price_changes":[{"asset_id":"54232589582260339592359130012520874109228367674780084862642636038394766871668","price":"0.01","size":"21062.86","side":"BUY","hash":"85f7728500d09641247016ad918e79014848f1d0","best_bid":"0.05","best_ask":"0.06"},{"asset_id":"96886111393998001968863279421729456597655847484197549086072988901191634450924","price":"0.99","size":"21062.86","side":"SELL","hash":"8b9e14b0c14d633d0dc4b4069b8aa9869e448700","best_bid":"0.94","best_ask":"0.95"}],"timestamp":"1768250249479","event_type":"price_change"}}
{"schema_version":1,"source":"clob_ws_market","recv_ts_ns":1768250249898776230,"event_type":"price_change","market":"0xe51aa24ab1bbfefce466d642ad98587d13123e4ef95ec9aa73b712e775d4cbba","server_ts_ms":1768250249524,"raw":{"market":"0xe51aa24ab1bbfefce466d642ad98587d13123e4ef95ec9aa73b712e775d4cbba","price_changes":[{"asset_id":"54232589582260339592359130012520874109228367674780084862642636038394766871668","price":"0.01","size":"21094.86","side":"BUY","hash":"9cf85bebaebbbd3f2ef06f27ab1b4ec753d9291b","best_bid":"0.05","best_ask":"0.06"},{"asset_id":"96886111393998001968863279421729456597655847484197549086072988901191634450924","price":"0.99","size":"21094.86","side":"SELL","hash":"b0266d72e1a18245e0dd8644775fca5719a77e5a","best_bid":"0.94","best_ask":"0.95"}],"timestamp":"1768250249524","event_type":"price_change"}}
{"schema_version":1,"source":"clob_ws_market","recv_ts_ns":1768250249907361950,"event_type":"price_change","market":"0xe51aa24ab1bbfefce466d642ad98587d13123e4ef95ec9aa73b712e775d4cbba","server_ts_ms":1768250249587,"raw":{"market":"0xe51aa24ab1bbfefce466d642ad98587d13123e4ef95ec9aa73b712e775d4cbba","price_changes":[{"asset_id":"54232589582260339592359130012520874109228367674780084862642636038394766871668","price":"0.04","size":"1818.74","side":"BUY","hash":"ef0309f9eee4859c2b7f6a6e71f20a95807decd8","best_bid":"0.05","best_ask":"0.06"},{"asset_id":"96886111393998001968863279421729456597655847484197549086072988901191634450924","price":"0.96","size":"1818.74","side":"SELL","hash":"023cc3bab9672fde58542fca5ad4ee8e81acc5fc","best_bid":"0.94","best_ask":"0.95"}],"timestamp":"1768250249587","event_type":"price_change"}}
{"schema_version":1,"source":"clob_ws_market","recv_ts_ns":1768250249957020591,"event_type":"price_change","market":"0xe51aa24ab1bbfefce466d642ad98587d13123e4ef95ec9aa73b712e775d4cbba","server_ts_ms":1768250249640,"raw":{"market":"0xe51aa24ab1bbfefce466d642ad98587d13123e4ef95ec9aa73b712e775d4cbba","price_changes":[{"asset_id":"54232589582260339592359130012520874109228367674780084862642636038394766871668","price":"0.05","size":"12","side":"BUY","hash":"e35836af09bfaea64c31f756fcd967e1bbfe67fe","best_bid":"0.05","best_ask":"0.06"},{"asset_id":"96886111393998001968863279421729456597655847484197549086072988901191634450924","price":"0.95","size":"12","side":"SELL","hash":"eb85760fe4cafb261af55360093b4be218e3a7b5","best_bid":"0.94","best_ask":"0.95"}],"timestamp":"1768250249640","event_type":"price_change"}}
{"schema_version":1,"source":"clob_ws_market","recv_ts_ns":1768250250078274170,"event_type":"price_change","market":"0xe51aa24ab1bbfefce466d642ad98587d13123e4ef95ec9aa73b712e775d4cbba","server_ts_ms":1768250249745,"raw":{"market":"0xe51aa24ab1bbfefce466d642ad98587d13123e4ef95ec9aa73b712e775d4cbba","price_changes":[{"asset_id":"54232589582260339592359130012520874109228367674780084862642636038394766871668","price":"0.05","size":"112","side":"BUY","hash":"db2b377caf18e24607d95933a3fc233a534b9e2e","best_bid":"0.05","best_ask":"0.06"},{"asset_id":"96886111393998001968863279421729456597655847484197549086072988901191634450924","price":"0.95","size":"112","side":"SELL","hash":"dc4f0c7cf439b94c6ca16f3585dea82a2e60e849","best_bid":"0.94","best_ask":"0.95"}],"timestamp":"1768250249745","event_type":"price_change"}}
{"schema_version":1,"source":"clob_ws_market","recv_ts_ns":1768250250083293144,"event_type":"price_change","market":"0xe51aa24ab1bbfefce466d642ad98587d13123e4ef95ec9aa73b712e775d4cbba","server_ts_ms":1768250249756,"raw":{"market":"0xe51aa24ab1bbfefce466d642ad98587d13123e4ef95ec9aa73b712e775d4cbba","price_changes":[{"asset_id":"54232589582260339592359130012520874109228367674780084862642636038394766871668","price":"0.01","size":"21062.86","side":"BUY","hash":"6604ed70242df90e30058e3a11fccf25ef52d33d","best_bid":"0.05","best_ask":"0.06"},{"asset_id":"96886111393998001968863279421729456597655847484197549086072988901191634450924","price":"0.99","size":"21062.86","side":"SELL","hash":"22b7fac9b2b336b072d7aa3827ca85e510adea69","best_bid":"0.94","best_ask":"0.95"}],"timestamp":"1768250249756","event_type":"price_change"}}
{"schema_version":1,"source":"clob_ws_market","recv_ts_ns":1768250250159008684,"event_type":"price_change","market":"0xe51aa24ab1bbfefce466d642ad98587d13123e4ef95ec9aa73b712e775d4cbba","server_ts_ms":1768250249799,"raw":{"market":"0xe51aa24ab1bbfefce466d642ad98587d13123e4ef95ec9aa73b712e775d4cbba","price_changes":[{"asset_id":"54232589582260339592359130012520874109228367674780084862642636038394766871668","price":"0.01","size":"21094.86","side":"BUY","hash":"78f30a796139eb9fa26cb1af82229a2e1702a1ec","best_bid":"0.05","best_ask":"0.06"},{"asset_id":"96886111393998001968863279421729456597655847484197549086072988901191634450924","price":"0.99","size":"21094.86","side":"SELL","hash":"0cba28fc9678cdd4eb4d5dbdd8bdcd90610896f9","best_bid":"0.94","best_ask":"0.95"}],"timestamp":"1768250249799","event_type":"price_change"}}
{"schema_version":1,"source":"clob_ws_market","recv_ts_ns":1768250250262653279,"event_type":"best_bid_ask","market":"0xe51aa24ab1bbfefce466d642ad98587d13123e4ef95ec9aa73b712e775d4cbba","server_ts_ms":1768250249926,"raw":{"market":"0xe51aa24ab1bbfefce466d642ad98587d13123e4ef95ec9aa73b712e775d4cbba","asset_id":"96886111393998001968863279421729456597655847484197549086072988901191634450924","best_bid":"0.94","best_ask":"0.95","spread":"0.01","timestamp":"1768250249926","event_type":"best_bid_ask"}}
{"schema_version":1,"source":"clob_ws_market","recv_ts_ns":1768250250265696354,"event_type":"price_change","market":"0xe51aa24ab1bbfefce466d642ad98587d13123e4ef95ec9aa73b712e775d4cbba","server_ts_ms":1768250249924,"raw":{"market":"0xe51aa24ab1bbfefce466d642ad98587d13123e4ef95ec9aa73b712e775d4cbba","price_changes":[{"asset_id":"96886111393998001968863279421729456597655847484197549086072988901191634450924","price":"0.94","size":"1171.27","side":"BUY","hash":"11538a317c1af652d24a86b78fc2a583cc836812","best_bid":"0.94","best_ask":"0.95"},{"asset_id":"54232589582260339592359130012520874109228367674780084862642636038394766871668","price":"0.06","size":"1171.27","side":"SELL","hash":"69f7f75457456f00527113cd986eb9e08ec9b8c9","best_bid":"0.05","best_ask":"0.06"}],"timestamp":"1768250249924","event_type":"price_change"}}
{"schema_version":1,"source":"clob_ws_market","recv_ts_ns":1768250250279091764,"event_type":"book","market":"0xe51aa24ab1bbfefce466d642ad98587d13123e4ef95ec9aa73b712e775d4cbba","server_ts_ms":1768250249924,"raw":{"market":"0xe51aa24ab1bbfefce466d642ad98587d13123e4ef95ec9aa73b712e775d4cbba","asset_id":"96886111393998001968863279421729456597655847484197549086072988901191634450924","bids":[{"price":"0.01","size":"24295.73"},{"price":"0.02","size":"7594.51"},{"price":"0.03","size":"5964.69"},{"price":"0.04","size":"5411.4"},{"price":"0.05","size":"5356.39"},{"price":"0.06","size":"5328"},{"price":"0.07","size":"5039.28"},{"price":"0.08","size":"5022.7"},{"price":"0.09","size":"5320.9"},{"price":"0.1","size":"5158.44"},{"price":"0.11","size":"18.3"},{"price":"0.12","size":"30.3"},{"price":"0.13","size":"16.5"},{"price":"0.14","size":"15.8"},{"price":"0.15","size":"104.19"},{"price":"0.16","size":"24.69"},{"price":"0.17","size":"14.19"},{"price":"0.18","size":"13.8"},{"price":"0.19","size":"13.4"},{"price":"0.2","size":"38.1"},{"price":"0.21","size":"12.8"},{"price":"0.22","size":"12.6"},{"price":"0.23","size":"12.3"},{"price":"0.24","size":"22.1"},{"price":"0.25","size":"16.9"},{"price":"0.26","size":"21.8"},{"price":"0.27","size":"11.6"},{"price":"0.28","size":"11.4"},{"price":"0.29","size":"61.3"},{"price":"0.3","size":"26.2"},{"price":"0.31","size":"11.1"},{"price":"0.32","size":"11"},{"price":"0.33","size":"110.9"},{"price":"0.34","size":"10.8"},{"price":"0.35","size":"15.7"},{"price":"0.36","size":"10.6"},{"price":"0.37","size":"10.6"},{"price":"0.38","size":"22.5"},{"price":"0.39","size":"10.5"},{"price":"0.4","size":"45.4"},{"price":"0.41","size":"311.4"},{"price":"0.42","size":"820.82"},{"price":"0.43","size":"826.3"},{"price":"0.44","size":"1062.3"},{"price":"0.45","size":"582.3"},{"price":"0.46","size":"626.2"},{"price":"0.47","size":"562.2"},{"price":"0.48","size":"567.2"},{"price":"0.49","size":"573.2"},{"price":"0.5","size":"917.2"},{"price":"0.51","size":"591.2"},{"price":"0.52","size":"590.2"},{"price":"0.53","size":"567.2"},{"price":"0.54","size":"636.61"},{"price":"0.55","size":"368.97"},{"price":"0.56","size":"341.3"},{"price":"0.57","size":"320.62"},{"price":"0.58","size":"567.3"},{"price":"0.59","size":"562.4"},{"price":"0.6","size":"693.02"},{"price":"0.61","size":"625.5"},{"price":"0.62","size":"700.5"},{"price":"0.63","size":"703.32"},{"price":"0.64","size":"680.6"},{"price":"0.65","size":"536.14"},{"price":"0.66","size":"602.8"},{"price":"0.67","size":"572.9"},{"price":"0.68","size":"573"},{"price":"0.69","size":"595.1"},{"price":"0.7","size":"603.2"},{"price":"0.71","size":"1318.72"},{"price":"0.72","size":"1043.04"},{"price":"0.73","size":"663.6"},{"price":"0.74","size":"911.17"},{"price":"0.75","size":"694.3"},{"price":"0.76","size":"717.6"},{"price":"0.77","size":"1183.3"},{"price":"0.78","size":"1449.6"},{"price":"0.79","size":"1254.75"},{"price":"0.8","size":"1445.08"},{"price":"0.81","size":"1229.8"},{"price":"0.82","size":"1467.57"},{"price":"0.83","size":"1470.51"},{"price":"0.84","size":"1668.59"},{"price":"0.85","size":"1762.5"},{"price":"0.86","size":"1755.6"},{"price":"0.87","size":"1588.93"},{"price":"0.88","size":"2355.4"},{"price":"0.89","size":"2066.7"},{"price":"0.9","size":"3467.84"},{"price":"0.91","size":"1623.44"},{"price":"0.92","size":"2724.36"},{"price":"0.93","size":"1530.32"},{"price":"0.94","size":"1171.27"}],"asks":[{"price":"0.99","size":"21094.86"},{"price":"0.98","size":"6443.25"},{"price":"0.97","size":"1255.33"},{"price":"0.96","size":"1818.74"},{"price":"0.95","size":"112"}],"hash":"11538a317c1af652d24a86b78fc2a583cc836812","timestamp":"1768250249924","event_type":"book"}}
{"schema_version":1,"source":"clob_ws_market","recv_ts_ns":1768250250282492377,"event_type":"price_change","market":"0xe51aa24ab1bbfefce466d642ad98587d13123e4ef95ec9aa73b712e775d4cbba","server_ts_ms":1768250249927,"raw":{"market":"0xe51aa24ab1bbfefce466d642ad98587d13123e4ef95ec9aa73b712e775d4cbba","price_changes":[{"asset_id":"96886111393998001968863279421729456597655847484197549086072988901191634450924","price":"0.97","size":"1260.33","side":"SELL","hash":"71e90725b0004347906989cadd58f7a472d9b6f9","best_bid":"0.94","best_ask":"0.95"},{"asset_id":"54232589582260339592359130012520874109228367674780084862642636038394766871668","price":"0.03","size":"1260.33","side":"BUY","hash":"e1acdc9ccf9ddd1335e43c16565ca25a160a5016","best_bid":"0.05","best_ask":"0.06"}],"timestamp":"1768250249927","event_type":"price_change"}}
{"schema_version":1,"source":"clob_ws_market","recv_ts_ns":1768250250286724259,"event_type":"price_change","market":"0xe51aa24ab1bbfefce466d642ad98587d13123e4ef95ec9aa73b712e775d4cbba","server_ts_ms":1768250249927,"raw":{"market":"0xe51aa24ab1bbfefce466d642ad98587d13123e4ef95ec9aa73b712e775d4cbba","price_changes":[{"asset_id":"54232589582260339592359130012520874109228367674780084862642636038394766871668","price":"0.01","size":"21062.86","side":"BUY","hash":"8e34eb8e536407358203615c7e7c6e02f31dc64c","best_bid":"0.05","best_ask":"0.06"},{"asset_id":"96886111393998001968863279421729456597655847484197549086072988901191634450924","price":"0.99","size":"21062.86","side":"SELL","hash":"9fa6002bc92961369fa371a293a0743751181cab","best_bid":"0.94","best_ask":"0.95"}],"timestamp":"1768250249927","event_type":"price_change"}}
{"schema_version":1,"source":"clob_ws_market","recv_ts_ns":1768250250297567736,"event_type":"price_change","market":"0xe51aa24ab1bbfefce466d642ad98587d13123e4ef95ec9aa73b712e775d4cbba","server_ts_ms":1768250249972,"raw":{"market":"0xe51aa24ab1bbfefce466d642ad98587d13123e4ef95ec9aa73b712e775d4cbba","price_changes":[{"asset_id":"54232589582260339592359130012520874109228367674780084862642636038394766871668","price":"0.01","size":"21094.86","side":"BUY","hash":"9a0015452927db14d0fe940c793513050fefa6dd","best_bid":"0.05","best_ask":"0.06"},{"asset_id":"96886111393998001968863279421729456597655847484197549086072988901191634450924","price":"0.99","size":"21094.86","side":"SELL","hash":"cec4a5a11dfaed2f400a0610d7702cc9d7dd0607","best_bid":"0.94","best_ask":"0.95"}],"timestamp":"1768250249972","event_type":"price_change"}}
{"schema_version":1,"source":"clob_ws_market","recv_ts_ns":1768250250312290049,"event_type":"price_change","market":"0xe51aa24ab1bbfefce466d642ad98587d13123e4ef95ec9aa73b712e775d4cbba","server_ts_ms":1768250249998,"raw":{"market":"0xe51aa24ab1bbfefce466d642ad98587d13123e4ef95ec9aa73b712e775d4cbba","price_changes":[{"asset_id":"96886111393998001968863279421729456597655847484197549086072988901191634450924","price":"0.63","size":"734.32","side":"BUY","hash":"b67aa8c1eddf0d739844d99dac4d62ac8a41aa80","best_bid":"0.94","best_ask":"0.95"},{"asset_id":"54232589582260339592359130012520874109228367674780084862642636038394766871668","price":"0.37","size":"734.32","side":"SELL","hash":"ac317bc30e4567239dcd3c59763d62441ae0865a","best_bid":"0.05","best_ask":"0.06"}],"timestamp":"1768250249998","event_type":"price_change"}}
{"schema_version":1,"source":"clob_ws_market","recv_ts_ns":1768250250316519944,"event_type":"price_change","market":"0xe51aa24ab1bbfefce466d642ad98587d13123e4ef95ec9aa73b712e775d4cbba","server_ts_ms":1768250250000,"raw":{"market":"0xe51aa24ab1bbfefce466d642ad98587d13123e4ef95ec9aa73b712e775d4cbba","price_changes":[{"asset_id":"54232589582260339592359130012520874109228367674780084862642636038394766871668","price":"0.02","size":"6343.25","side":"BUY","hash":"d9fcd401bd4af41e1a9e191d704543515ff33898","best_bid":"0.05","best_ask":"0.06"},{"asset_id":"96886111393998001968863279421729456597655847484197549086072988901191634450924","price":"0.98","size":"6343.25","side":"SELL","hash":"81d8b3dc4f1225c1ba2fd2fdb3fd6ded7fe27645","best_bid":"0.94","best_ask":"0.95"}],"timestamp":"1768250250000","event_type":"price_change"}}
{"schema_version":1,"source":"clob_ws_market","recv_ts_ns":1768250250337874434,"event_type":"price_change","market":"0xe51aa24ab1bbfefce466d642ad98587d13123e4ef95ec9aa73b712e775d4cbba","server_ts_ms":1768250250023,"raw":{"market":"0xe51aa24ab1bbfefce466d642ad98587d13123e4ef95ec9aa73b712e775d4cbba","price_changes":[{"asset_id":"96886111393998001968863279421729456597655847484197549086072988901191634450924","price":"0.98","size":"6368.25","side":"SELL","hash":"0affe1d30bf8a2597858ae64d459aac6c7fb0fae","best_bid":"0.94","best_ask":"0.95"},{"asset_id":"54232589582260339592359130012520874109228367674780084862642636038394766871668","price":"0.02","size":"6368.25","side":"BUY","hash":"3ab84b41e22ac9183e100dd828984a84fe86ad99","best_bid":"0.05","best_ask":"0.06"}],"timestamp":"1768250250023","event_type":"price_change"}}
{"schema_version":1,"source":"clob_ws_market","recv_ts_ns":1768250250353689142,"event_type":"price_change","market":"0xe51aa24ab1bbfefce466d642ad98587d13123e4ef95ec9aa73b712e775d4cbba","server_ts_ms":1768250250026,"raw":{"market":"0xe51aa24ab1bbfefce466d642ad98587d13123e4ef95ec9aa73b712e775d4cbba","price_changes":[{"asset_id":"96886111393998001968863279421729456597655847484197549086072988901191634450924","price":"0.99","size":"21069.86","side":"SELL","hash":"734e482a07b16e8829bf08285c9f90ceeacee3dd","best_bid":"0.94","best_ask":"0.95"},{"asset_id":"54232589582260339592359130012520874109228367674780084862642636038394766871668","price":"0.01","size":"21069.86","side":"BUY","hash":"d8d8307b651b17e1e34c5f4febba823e215ceaee","best_bid":"0.05","best_ask":"0.06"}],"timestamp":"1768250250026","event_type":"price_change"}}
{"schema_version":1,"source":"clob_ws_market","recv_ts_ns":1768250250374476969,"event_type":"price_change","market":"0xe51aa24ab1bbfefce466d642ad98587d13123e4ef95ec9aa73b712e775d4cbba","server_ts_ms":1768250250033,"raw":{"market":"0xe51aa24ab1bbfefce466d642ad98587d13123e4ef95ec9aa73b712e775d4cbba","price_changes":[{"asset_id":"54232589582260339592359130012520874109228367674780084862642636038394766871668","price":"0.02","size":"6418.25","side":"BUY","hash":"d864d5c994279ad927a96c06ab3dc05462e04d02","best_bid":"0.05","best_ask":"0.06"},{"asset_id":"96886111393998001968863279421729456597655847484197549086072988901191634450924","price":"0.98","size":"6418.25","side":"SELL","hash":"2c7491177cae496b6737cb61316139c92f575def","best_bid":"0.94","best_ask":"0.95"}],"timestamp":"1768250250033","event_type":"price_change"}}
{"schema_version":1,"source":"clob_ws_market","recv_ts_ns":1768250250399548114,"event_type":"price_change","market":"0xe51aa24ab1bbfefce466d642ad98587d13123e4ef95ec9aa73b712e775d4cbba","server_ts_ms":1768250250066,"raw":{"market":"0xe51aa24ab1bbfefce466d642ad98587d13123e4ef95ec9aa73b712e775d4cbba","price_changes":[{"asset_id":"54232589582260339592359130012520874109228367674780084862642636038394766871668","price":"0.02","size":"6518.25","side":"BUY","hash":"0cfbd85b0363315fac7a7e9b8e886eb6d8f4ec7e","best_bid":"0.05","best_ask":"0.06"},{"asset_id":"96886111393998001968863279421729456597655847484197549086072988901191634450924","price":"0.98","size":"6518.25","side":"SELL","hash":"e49308aead54fa0fa5f9768d95f24e400b615ba7","best_bid":"0.94","best_ask":"0.95"}],"timestamp":"1768250250066","event_type":"price_change"}}
{"schema_version":1,"source":"clob_ws_market","recv_ts_ns":1768250250407337784,"event_type":"best_bid_ask","market":"0xe51aa24ab1bbfefce466d642ad98587d13123e4ef95ec9aa73b712e775d4cbba","server_ts_ms":1768250250075,"raw":{"market":"0xe51aa24ab1bbfefce466d642ad98587d13123e4ef95ec9aa73b712e775d4cbba","asset_id":"96886111393998001968863279421729456597655847484197549086072988901191634450924","best_bid":"0.94","best_ask":"0.95","spread":"0.01","timestamp":"1768250250075","event_type":"best_bid_ask"}}
{"schema_version":1,"source":"clob_ws_market","recv_ts_ns":1768250250409437579,"event_type":"price_change","market":"0xe51aa24ab1bbfefce466d642ad98587d13123e4ef95ec9aa73b712e775d4cbba","server_ts_ms":1768250250073,"raw":{"market":"0xe51aa24ab1bbfefce466d642ad98587d13123e4ef95ec9aa73b712e775d4cbba","price_changes":[{"asset_id":"96886111393998001968863279421729456597655847484197549086072988901191634450924","price":"0.95","size":"109","side":"SELL","hash":"4f543b5732cd52d60ca15b5a615512524342de2d","best_bid":"0.94","best_ask":"0.95"},{"asset_id":"54232589582260339592359130012520874109228367674780084862642636038394766871668","price":"0.05","size":"109","side":"BUY","hash":"ed247156a91c2466c179290d2df3afd867ece16b","best_bid":"0.05","best_ask":"0.06"}],"timestamp":"1768250250073","event_type":"price_change"}}
{"schema_version":1,"source":"clob_ws_market","recv_ts_ns":1768250250417495266,"event_type":"book","market":"0xe51aa24ab1bbfefce466d642ad98587d13123e4ef95ec9aa73b712e775d4cbba","server_ts_ms":1768250250073,"raw":{"market":"0xe51aa24ab1bbfefce466d642ad98587d13123e4ef95ec9aa73b712e775d4cbba","asset_id":"96886111393998001968863279421729456597655847484197549086072988901191634450924","bids":[{"price":"0.01","size":"24295.73"},{"price":"0.02","size":"7594.51"},{"price":"0.03","size":"5964.69"},{"price":"0.04","size":"5411.4"},{"price":"0.05","size":"5356.39"},{"price":"0.06","size":"5328"},{"price":"0.07","size":"5039.28"},{"price":"0.08","size":"5022.7"},{"price":"0.09","size":"5320.9"},{"price":"0.1","size":"5158.44"},{"price":"0.11","size":"18.3"},{"price":"0.12","size":"30.3"},{"price":"0.13","size":"16.5"},{"price":"0.14","size":"15.8"},{"price":"0.15","size":"104.19"},{"price":"0.16","size":"24.69"},{"price":"0.17","size":"14.19"},{"price":"0.18","size":"13.8"},{"price":"0.19","size":"13.4"},{"price":"0.2","size":"38.1"},{"price":"0.21","size":"12.8"},{"price":"0.22","size":"12.6"},{"price":"0.23","size":"12.3"},{"price":"0.24","size":"22.1"},{"price":"0.25","size":"16.9"},{"price":"0.26","size":"21.8"},{"price":"0.27","size":"11.6"},{"price":"0.28","size":"11.4"},{"price":"0.29","size":"61.3"},{"price":"0.3","size":"26.2"},{"price":"0.31","size":"11.1"},{"price":"0.32","size":"11"},{"price":"0.33","size":"110.9"},{"price":"0.34","size":"10.8"},{"price":"0.35","size":"15.7"},{"price":"0.36","size":"10.6"},{"price":"0.37","size":"10.6"},{"price":"0.38","size":"22.5"},{"price":"0.39","size":"10.5"},{"price":"0.4","size":"45.4"},{"price":"0.41","size":"311.4"},{"price":"0.42","size":"820.82"},{"price":"0.43","size":"826.3"},{"price":"0.44","size":"1062.3"},{"price":"0.45","size":"582.3"},{"price":"0.46","size":"626.2"},{"price":"0.47","size":"562.2"},{"price":"0.48","size":"567.2"},{"price":"0.49","size":"573.2"},{"price":"0.5","size":"917.2"},{"price":"0.51","size":"591.2"},{"price":"0.52","size":"590.2"},{"price":"0.53","size":"567.2"},{"price":"0.54","size":"636.61"},{"price":"0.55","size":"368.97"},{"price":"0.56","size":"341.3"},{"price":"0.57","size":"320.62"},{"price":"0.58","size":"567.3"},{"price":"0.59","size":"562.4"},{"price":"0.6","size":"693.02"},{"price":"0.61","size":"625.5"},{"price":"0.62","size":"700.5"},{"price":"0.63","size":"734.32"},{"price":"0.64","size":"680.6"},{"price":"0.65","size":"536.14"},{"price":"0.66","size":"602.8"},{"price":"0.67","size":"572.9"},{"price":"0.68","size":"573"},{"price":"0.69","size":"595.1"},{"price":"0.7","size":"603.2"},{"price":"0.71","size":"1318.72"},{"price":"0.72","size":"1043.04"},{"price":"0.73","size":"663.6"},{"price":"0.74","size":"911.17"},{"price":"0.75","size":"694.3"},{"price":"0.76","size":"717.6"},{"price":"0.77","size":"1183.3"},{"price":"0.78","size":"1449.6"},{"price":"0.79","size":"1254.75"},{"price":"0.8","size":"1445.08"},{"price":"0.81","size":"1229.8"},{"price":"0.82","size":"1467.57"},{"price":"0.83","size":"1470.51"},{"price":"0.84","size":"1668.59"},{"price":"0.85","size":"1762.5"},{"price":"0.86","size":"1755.6"},{"price":"0.87","size":"1588.93"},{"price":"0.88","size":"2355.4"},{"price":"0.89","size":"2066.7"},{"price":"0.9","size":"3467.84"},{"price":"0.91","size":"1623.44"},{"price":"0.92","size":"2724.36"},{"price":"0.93","size":"1530.32"},{"price":"0.94","size":"1171.27"}],"asks":[{"price":"0.99","size":"21069.86"},{"price":"0.98","size":"6518.25"},{"price":"0.97","size":"1260.33"},{"price":"0.96","size":"1818.74"},{"price":"0.95","size":"109"}],"hash":"4f543b5732cd52d60ca15b5a615512524342de2d","timestamp":"1768250250073","event_type":"book"}}
{"schema_version":1,"source":"clob_ws_market","recv_ts_ns":1768250250419949870,"event_type":"price_change","market":"0xe51aa24ab1bbfefce466d642ad98587d13123e4ef95ec9aa73b712e775d4cbba","server_ts_ms":1768250250080,"raw":{"market":"0xe51aa24ab1bbfefce466d642ad98587d13123e4ef95ec9aa73b712e775d4cbba","price_changes":[{"asset_id":"54232589582260339592359130012520874109228367674780084862642636038394766871668","price":"0.04","size":"1794.74","side":"BUY","hash":"0fa9c7127c03c437af9679d586081dcd33ab6506","best_bid":"0.05","best_ask":"0.06"},{"asset_id":"96886111393998001968863279421729456597655847484197549086072988901191634450924","price":"0.96","size":"1794.74","side":"SELL","hash":"f249edefa4e96341d6dcf31b3ed27562340364c6","best_bid":"0.94","best_ask":"0.95"}],"timestamp":"1768250250080","event_type":"price_change"}}
{"schema_version":1,"source":"clob_ws_market","recv_ts_ns":1768250250452548956,"event_type":"last_trade_price","market":"0xe51aa24ab1bbfefce466d642ad98587d13123e4ef95ec9aa73b712e775d4cbba","server_ts_ms":1768250250104,"raw":{"market":"0xe51aa24ab1bbfefce466d642ad98587d13123e4ef95ec9aa73b712e775d4cbba","asset_id":"96886111393998001968863279421729456597655847484197549086072988901191634450924","price":"0.95","size":"3","fee_rate_bps":"1000","side":"BUY","timestamp":"1768250250104","event_type":"last_trade_price","transaction_hash":"0x3fa4f70548cdc9f4b979503a77e92fdbe9ba9eebc3aab4ffb56247caf7e1a248"}}
{"schema_version":1,"source":"clob_ws_market","recv_ts_ns":1768250250453725996,"event_type":"price_change","market":"0xe51aa24ab1bbfefce466d642ad98587d13123e4ef95ec9aa73b712e775d4cbba","server_ts_ms":1768250250128,"raw":{"market":"0xe51aa24ab1bbfefce466d642ad98587d13123e4ef95ec9aa73b712e775d4cbba","price_changes":[{"asset_id":"54232589582260339592359130012520874109228367674780084862642636038394766871668","price":"0.99","size":"24275.73","side":"SELL","hash":"7d0cdfb8fd0bc193a85b18acf21eda8e6a69d1d4","best_bid":"0.05","best_ask":"0.06"},{"asset_id":"96886111393998001968863279421729456597655847484197549086072988901191634450924","price":"0.01","size":"24275.73","side":"BUY","hash":"26b6f246cb07e583c7960a839ae574e2d4bae24e","best_bid":"0.94","best_ask":"0.95"}],"timestamp":"1768250250128","event_type":"price_change"}}
{"schema_version":1,"source":"clob_ws_market","recv_ts_ns":1768250250456413396,"event_type":"price_change","market":"0xe51aa24ab1bbfefce466d642ad98587d13123e4ef95ec9aa73b712e775d4cbba","server_ts_ms":1768250250149,"raw":{"market":"0xe51aa24ab1bbfefce466d642ad98587d13123e4ef95ec9aa73b712e775d4cbba","price_changes":[{"asset_id":"96886111393998001968863279421729456597655847484197549086072988901191634450924","price":"0.96","size":"1775.74","side":"SELL","hash":"7527b3af6b1091e02abcb592ba7250ecf8abcead","best_bid":"0.94","best_ask":"0.95"},{"asset_id":"54232589582260339592359130012520874109228367674780084862642636038394766871668","price":"0.04","size":"1775.74","side":"BUY","hash":"1b6e09290881dbc5d98e0bac0af4ef4ae1a9e2ba","best_bid":"0.05","best_ask":"0.06"}],"timestamp":"1768250250149","event_type":"price_change"}}
{"schema_version":1,"source":"clob_ws_market","recv_ts_ns":1768250250481528130,"event_type":"price_change","market":"0xe51aa24ab1bbfefce466d642ad98587d13123e4ef95ec9aa73b712e775d4cbba","server_ts_ms":1768250250213,"raw":{"market":"0xe51aa24ab1bbfefce466d642ad98587d13123e4ef95ec9aa73b712e775d4cbba","price_changes":[{"asset_id":"54232589582260339592359130012520874109228367674780084862642636038394766871668","price":"0.05","size":"9","side":"BUY","hash":"990fdb29f8a1501e319e9e35483e108ed2236a32","best_bid":"0.05","best_ask":"0.06"},{"asset_id":"96886111393998001968863279421729456597655847484197549086072988901191634450924","price":"0.95","size":"9","side":"SELL","hash":"3e6d906bea5f05718e6e1c4c878865151bd3d620","best_bid":"0.94","best_ask":"0.95"}],"timestamp":"1768250250213","event_type":"price_change"}}
{"schema_version":1,"source":"clob_ws_market","recv_ts_ns":1768250250485455275,"event_type":"price_change","market":"0xe51aa24ab1bbfefce466d642ad98587d13123e4ef95ec9aa73b712e775d4cbba","server_ts_ms":1768250250243,"raw":{"market":"0xe51aa24ab1bbfefce466d642ad98587d13123e4ef95ec9aa73b712e775d4cbba","price_changes":[{"asset_id":"96886111393998001968863279421729456597655847484197549086072988901191634450924","price":"0.94","size":"1176.58","side":"BUY","hash":"39ae4a22f62416b7e7e6ac377c82a29b8030a8da","best_bid":"0.94","best_ask":"0.95"},{"asset_id":"54232589582260339592359130012520874109228367674780084862642636038394766871668","price":"0.06","size":"1176.58","side":"SELL","hash":"a6d78ff2493db2b401d81862fb05a0cb4c9eba3c","best_bid":"0.05","best_ask":"0.06"}],"timestamp":"1768250250243","event_type":"price_change"}}
{"schema_version":1,"source":"clob_ws_market","recv_ts_ns":1768250250488923952,"event_type":"price_change","market":"0xe51aa24ab1bbfefce466d642ad98587d13123e4ef95ec9aa73b712e775d4cbba","server_ts_ms":1768250250270,"raw":{"market":"0xe51aa24ab1bbfefce466d642ad98587d13123e4ef95ec9aa73b712e775d4cbba","price_changes":[{"asset_id":"96886111393998001968863279421729456597655847484197549086072988901191634450924","price":"0.99","size":"21094.86","side":"SELL","hash":"135f582d63145507cde5751a72e4608c93b30408","best_bid":"0.94","best_ask":"0.95"},{"asset_id":"54232589582260339592359130012520874109228367674780084862642636038394766871668","price":"0.01","size":"21094.86","side":"BUY","hash":"da06b24fd307d3b07c75eb04a3172626f4552708","best_bid":"0.05","best_ask":"0.06"}],"timestamp":"1768250250270","event_type":"price_change"}}
{"schema_version":1,"source":"clob_ws_market","recv_ts_ns":1768250250493134391,"event_type":"price_change","market":"0xe51aa24ab1bbfefce466d642ad98587d13123e4ef95ec9aa73b712e775d4cbba","server_ts_ms":1768250250273,"raw":{"market":"0xe51aa24ab1bbfefce466d642ad98587d13123e4ef95ec9aa73b712e775d4cbba","price_changes":[{"asset_id":"96886111393998001968863279421729456597655847484197549086072988901191634450924","price":"0.98","size":"6493.25","side":"SELL","hash":"29e3ddb3241f205306aeb261b068a7a7d219b857","best_bid":"0.94","best_ask":"0.95"},{"asset_id":"54232589582260339592359130012520874109228367674780084862642636038394766871668","price":"0.02","size":"6493.25","side":"BUY","hash":"31d2d6cd5e94c316c199e74e51d1687c2ddd341b","best_bid":"0.05","best_ask":"0.06"}],"timestamp":"1768250250273","event_type":"price_change"}}
{"schema_version":1,"source":"clob_ws_market","recv_ts_ns":1768250250497848563,"event_type":"best_bid_ask","market":"0xe51aa24ab1bbfefce466d642ad98587d13123e4ef95ec9aa73b712e775d4cbba","server_ts_ms":1768250250295,"raw":{"market":"0xe51aa24ab1bbfefce466d642ad98587d13123e4ef95ec9aa73b712e775d4cbba","asset_id":"96886111393998001968863279421729456597655847484197549086072988901191634450924","best_bid":"0.94","best_ask":"0.96","spread":"0.02","timestamp":"1768250250295","event_type":"best_bid_ask"}}
{"schema_version":1,"source":"clob_ws_market","recv_ts_ns":1768250250499266431,"event_type":"price_change","market":"0xe51aa24ab1bbfefce466d642ad98587d13123e4ef95ec9aa73b712e775d4cbba","server_ts_ms":1768250250293,"raw":{"market":"0xe51aa24ab1bbfefce466d642ad98587d13123e4ef95ec9aa73b712e775d4cbba","price_changes":[{"asset_id":"96886111393998001968863279421729456597655847484197549086072988901191634450924","price":"0.95","size":"0","side":"SELL","hash":"322008ac984d8d0e617c391f15e6c2da2c6303fe","best_bid":"0.94","best_ask":"0.96"},{"asset_id":"54232589582260339592359130012520874109228367674780084862642636038394766871668","price":"0.05","size":"0","side":"BUY","hash":"796895414c7b2da3801fa557343ea0a3f5613780","best_bid":"0.04","best_ask":"0.06"}],"timestamp":"1768250250293","event_type":"price_change"}}
