{"schema_version":1,"source":"clob_ws_market","recv_ts_ns":1768250236288794536,"event_type":"price_change","market":"0x2a12fd3d8235c25c062dc9652970ef9f635636c4018df0909e1a51c673e125cb","server_ts_ms":1768250236194,"raw":{"market":"0x2a12fd3d8235c25c062dc9652970ef9f635636c4018df0909e1a51c673e125cb","price_changes":[{"asset_id":"63670753354844494163057275310194312729998307779831462269530137743341854359908","price":"0.88","size":"876.35","side":"SELL","hash":"cd8e9446f2b117258c7c402ef169bbdd0bf91d4a","best_bid":"0.87","best_ask":"0.88"},{"asset_id":"56386988715176239099720172290594769295756680374928571099138069977179519358166","price":"0.12","size":"876.35","side":"BUY","hash":"1e21c46ee87247109e3f8e11170defe06fdc424a","best_bid":"0.12","best_ask":"0.13"}],"timestamp":"1768250236194","event_type":"price_change"}}
{"schema_version":1,"source":"clob_ws_market","recv_ts_ns":1768250236293128132,"event_type":"price_change","market":"0x2a12fd3d8235c25c062dc9652970ef9f635636c4018df0909e1a51c673e125cb","server_ts_ms":1768250236197,"raw":{"market":"0x2a12fd3d8235c25c062dc9652970ef9f635636c4018df0909e1a51c673e125cb","price_changes":[{"asset_id":"56386988715176239099720172290594769295756680374928571099138069977179519358166","price":"0.1","size":"4419.5","side":"BUY","hash":"a36b33b96dcec7144a20a7a039e1af2981564285","best_bid":"0.12","best_ask":"0.13"},{"asset_id":"63670753354844494163057275310194312729998307779831462269530137743341854359908","price":"0.9","size":"4419.5","side":"SELL","hash":"30fef260005586530cf73e268243da458f8904bd","best_bid":"0.87","best_ask":"0.88"}],"timestamp":"1768250236197","event_type":"price_change"}}
{"schema_version":1,"source":"clob_ws_market","recv_ts_ns":1768250236344431420,"event_type":"price_change","market":"0x2a12fd3d8235c25c062dc9652970ef9f635636c4018df0909e1a51c673e125cb","server_ts_ms":1768250236231,"raw":{"market":"0x2a12fd3d8235c25c062dc9652970ef9f635636c4018df0909e1a51c673e125cb","price_changes":[{"asset_id":"63670753354844494163057275310194312729998307779831462269530137743341854359908","price":"0.83","size":"669.52","side":"BUY","hash":"87c080c28dae3694d76e0f2c469d43c4403be527","best_bid":"0.87","best_ask":"0.88"},{"asset_id":"56386988715176239099720172290594769295756680374928571099138069977179519358166","price":"0.17","size":"669.52","side":"SELL","hash":"e4d5549ffca773ffc1c8b6c2a9a58c85af2b48b8","best_bid":"0.12","best_ask":"0.13"}],"timestamp":"1768250236231","event_type":"price_change"}}
{"schema_version":1,"source":"clob_ws_market","recv_ts_ns":1768250236521151615,"event_type":"best_bid_ask","market":"0x2a12fd3d8235c25c062dc9652970ef9f635636c4018df0909e1a51c673e125cb","server_ts_ms":1768250236353,"raw":{"market":"0x2a12fd3d8235c25c062dc9652970ef9f635636c4018df0909e1a51c673e125cb","asset_id":"56386988715176239099720172290594769295756680374928571099138069977179519358166","best_bid":"0.12","best_ask":"0.13","spread":"0.01","timestamp":"1768250236353","event_type":"best_bid_ask"}}
{"schema_version":1,"source":"clob_ws_market","recv_ts_ns":1768250236526508082,"event_type":"price_change","market":"0x2a12fd3d8235c25c062dc9652970ef9f635636c4018df0909e1a51c673e125cb","server_ts_ms":1768250236351,"raw":{"market":"0x2a12fd3d8235c25c062dc9652970ef9f635636c4018df0909e1a51c673e125cb","price_changes":[{"asset_id":"63670753354844494163057275310194312729998307779831462269530137743341854359908","price":"0.87","size":"10.5","side":"BUY","hash":"3fb78f6172e1d069465520da15c80defecf2d063","best_bid":"0.87","best_ask":"0.88"},{"asset_id":"56386988715176239099720172290594769295756680374928571099138069977179519358166","price":"0.13","size":"10.5","side":"SELL","hash":"193fa23cf9b5c652de7462009821005cb9483982","best_bid":"0.12","best_ask":"0.13"}],"timestamp":"1768250236351","event_type":"price_change"}}
{"schema_version":1,"source":"clob_ws_market","recv_ts_ns":1768250236532262386,"event_type":"book","market":"0x2a12fd3d8235c25c062dc9652970ef9f635636c4018df0909e1a51c673e125cb","server_ts_ms":1768250236351,"raw":{"market":"0x2a12fd3d8235c25c062dc9652970ef9f635636c4018df0909e1a51c673e125cb","asset_id":"56386988715176239099720172290594769295756680374928571099138069977179519358166","bids":[{"price":"0.01","size":"10157.67"},{"price":"0.02","size":"6299.77"},{"price":"0.03","size":"5625.94"},{"price":"0.04","size":"5427"},{"price":"0.05","size":"3442"},{"price":"0.06","size":"1509.5"},{"price":"0.07","size":"1406.28"},{"price":"0.08","size":"1541.75"},{"price":"0.09","size":"1397"},{"price":"0.1","size":"4419.5"},{"price":"0.11","size":"1531.5"},{"price":"0.12","size":"876.35"}],"asks":[{"price":"0.99","size":"10178.95"},{"price":"0.98","size":"5982"},{"price":"0.97","size":"5238.94"},{"price":"0.96","size":"5040"},{"price":"0.95","size":"5050"},{"price":"0.94","size":"5005"},{"price":"0.93","size":"5019.28"},{"price":"0.92","size":"5005"},{"price":"0.91","size":"5005"},{"price":"0.9","size":"5030"},{"price":"0.89","size":"5"},{"price":"0.88","size":"5"},{"price":"0.87","size":"5"},{"price":"0.86","size":"5"},{"price":"0.85","size":"10"},{"price":"0.84","size":"5"},{"price":"0.83","size":"5"},{"price":"0.82","size":"5"},{"price":"0.81","size":"5"},{"price":"0.8","size":"5"},{"price":"0.79","size":"5"},{"price":"0.78","size":"5"},{"price":"0.77","size":"5"},{"price":"0.76","size":"5"},{"price":"0.75","size":"10"},{"price":"0.74","size":"5"},{"price":"0.73","size":"5"},{"price":"0.72","size":"5"},{"price":"0.71","size":"15"},{"price":"0.7","size":"10"},{"price":"0.69","size":"5"},{"price":"0.68","size":"5"},{"price":"0.67","size":"5"},{"price":"0.66","size":"505"},{"price":"0.65","size":"510"},{"price":"0.64","size":"510"},{"price":"0.63","size":"505"},{"price":"0.62","size":"505"},{"price":"0.61","size":"755"},{"price":"0.6","size":"760"},{"price":"0.59","size":"916"},{"price":"0.58","size":"671"},{"price":"0.57","size":"827"},{"price":"0.56","size":"827"},{"price":"0.55","size":"817"},{"price":"0.54","size":"872"},{"price":"0.53","size":"839.65"},{"price":"0.52","size":"829"},{"price":"0.51","size":"817"},{"price":"0.5","size":"838.4"},{"price":"0.49","size":"867.58"},{"price":"0.48","size":"817"},{"price":"0.47","size":"827"},{"price":"0.46","size":"847.8"},{"price":"0.45","size":"836.09"},{"price":"0.44","size":"825"},{"price":"0.43","size":"847"},{"price":"0.42","size":"817"},{"price":"0.41","size":"817"},{"price":"0.4","size":"817"},{"price":"0.39","size":"834.5"},{"price":"0.38","size":"817"},{"price":"0.37","size":"497.49"},{"price":"0.36","size":"817"},{"price":"0.35","size":"872"},{"price":"0.34","size":"906.8"},{"price":"0.33","size":"906.8"},{"price":"0.32","size":"902"},{"price":"0.31","size":"1008.96"},{"price":"0.3","size":"911.6"},{"price":"0.29","size":"897"},{"price":"0.28","size":"899.55"},{"price":"0.27","size":"912"},{"price":"0.26","size":"1270.97"},{"price":"0.25","size":"730.7"},{"price":"0.24","size":"912.05"},{"price":"0.23","size":"748.5"},{"price":"0.22","size":"967.5"},{"price":"0.21","size":"969.5"},{"price":"0.2","size":"920"},{"price":"0.19","size":"798.21"},{"price":"0.18","size":"761"},{"price":"0.17","size":"669.52"},{"price":"0.16","size":"196"},{"price":"0.15","size":"244.99"},{"price":"0.14","size":"1142.13"},{"price":"0.13","size":"10.5"}],"hash":"193fa23cf9b5c652de7462009821005cb9483982","timestamp":"1768250236351","event_type":"book"}}
{"schema_version":1,"source":"clob_ws_market","recv_ts_ns":1768250236566538879,"event_type":"last_trade_price","market":"0x2a12fd3d8235c25c062dc9652970ef9f635636c4018df0909e1a51c673e125cb","server_ts_ms":1768250236384,"raw":{"market":"0x2a12fd3d8235c25c062dc9652970ef9f635636c4018df0909e1a51c673e125cb","asset_id":"56386988715176239099720172290594769295756680374928571099138069977179519358166","price":"0.13","size":"25","fee_rate_bps":"1000","side":"BUY","timestamp":"1768250236384","event_type":"last_trade_price","transaction_hash":"0x4e8394d73cdd85d2e33dd86a160c77dbac6f1e7a521c0a79f40ec70d60aef7d6"}}
{"schema_version":1,"source":"clob_ws_market","recv_ts_ns":1768250236572436858,"event_type":"price_change","market":"0x2a12fd3d8235c25c062dc9652970ef9f635636c4018df0909e1a51c673e125cb","server_ts_ms":1768250236413,"raw":{"market":"0x2a12fd3d8235c25c062dc9652970ef9f635636c4018df0909e1a51c673e125cb","price_changes":[{"asset_id":"56386988715176239099720172290594769295756680374928571099138069977179519358166","price":"0.1","size":"4384.5","side":"BUY","hash":"1a98a1e8e7dd93197d7a3b4ac7cb5a23f6f75212","best_bid":"0.12","best_ask":"0.13"},{"asset_id":"63670753354844494163057275310194312729998307779831462269530137743341854359908","price":"0.9","size":"4384.5","side":"SELL","hash":"ed71735f74587db529f9a90ce5188a04078c06dc","best_bid":"0.87","best_ask":"0.88"}],"timestamp":"1768250236413","event_type":"price_change"}}
{"schema_version":1,"source":"clob_ws_market","recv_ts_ns":1768250236578157839,"event_type":"price_change","market":"0x2a12fd3d8235c25c062dc9652970ef9f635636c4018df0909e1a51c673e125cb","server_ts_ms":1768250236413,"raw":{"market":"0x2a12fd3d8235c25c062dc9652970ef9f635636c4018df0909e1a51c673e125cb","price_changes":[{"asset_id":"56386988715176239099720172290594769295756680374928571099138069977179519358166","price":"0.12","size":"841.35","side":"BUY","hash":"1a98a1e8e7dd93197d7a3b4ac7cb5a23f6f75212","best_bid":"0.12","best_ask":"0.13"},{"asset_id":"63670753354844494163057275310194312729998307779831462269530137743341854359908","price":"0.88","size":"841.35","side":"SELL","hash":"ed71735f74587db529f9a90ce5188a04078c06dc","best_bid":"0.87","best_ask":"0.88"}],"timestamp":"1768250236413","event_type":"price_change"}}
{"schema_version":1,"source":"clob_ws_market","recv_ts_ns":1768250236583391195,"event_type":"price_change","market":"0x2a12fd3d8235c25c062dc9652970ef9f635636c4018df0909e1a51c673e125cb","server_ts_ms":1768250236413,"raw":{"market":"0x2a12fd3d8235c25c062dc9652970ef9f635636c4018df0909e1a51c673e125cb","price_changes":[{"asset_id":"56386988715176239099720172290594769295756680374928571099138069977179519358166","price":"0.08","size":"1506.75","side":"BUY","hash":"1a98a1e8e7dd93197d7a3b4ac7cb5a23f6f75212","best_bid":"0.12","best_ask":"0.13"},{"asset_id":"63670753354844494163057275310194312729998307779831462269530137743341854359908","price":"0.92","size":"1506.75","side":"SELL","hash":"ed71735f74587db529f9a90ce5188a04078c06dc","best_bid":"0.87","best_ask":"0.88"}],"timestamp":"1768250236413","event_type":"price_change"}}
{"schema_version":1,"source":"clob_ws_market","recv_ts_ns":1768250236588651273,"event_type":"price_change","market":"0x2a12fd3d8235c25c062dc9652970ef9f635636c4018df0909e1a51c673e125cb","server_ts_ms":1768250236414,"raw":{"market":"0x2a12fd3d8235c25c062dc9652970ef9f635636c4018df0909e1a51c673e125cb","price_changes":[{"asset_id":"63670753354844494163057275310194312729998307779831462269530137743341854359908","price":"0.89","size":"1521.5","side":"SELL","hash":"3e02c9fd8a05bd5bb462a8dc652dc65f01baaf29","best_bid":"0.87","best_ask":"0.88"},{"asset_id":"56386988715176239099720172290594769295756680374928571099138069977179519358166","price":"0.11","size":"1521.5","side":"BUY","hash":"c83649e1f3c879ee06b55205a64407f83695092a","best_bid":"0.12","best_ask":"0.13"}],"timestamp":"1768250236414","event_type":"price_change"}}
{"schema_version":1,"source":"clob_ws_market","recv_ts_ns":1768250236593062771,"event_type":"price_change","market":"0x2a12fd3d8235c25c062dc9652970ef9f635636c4018df0909e1a51c673e125cb","server_ts_ms":1768250236414,"raw":{"market":"0x2a12fd3d8235c25c062dc9652970ef9f635636c4018df0909e1a51c673e125cb","price_changes":[{"asset_id":"56386988715176239099720172290594769295756680374928571099138069977179519358166","price":"0.1","size":"4409.5","side":"BUY","hash":"b81ffb87712429d68aeb16bc7cceed344414d59e","best_bid":"0.12","best_ask":"0.13"},{"asset_id":"63670753354844494163057275310194312729998307779831462269530137743341854359908","price":"0.9","size":"4409.5","side":"SELL","hash":"b396fa216d624885978bbffbbfd4896d06725611","best_bid":"0.87","best_ask":"0.88"}],"timestamp":"1768250236414","event_type":"price_change"}}
{"schema_version":1,"source":"clob_ws_market","recv_ts_ns":1768250236597353597,"event_type":"price_change","market":"0x2a12fd3d8235c25c062dc9652970ef9f635636c4018df0909e1a51c673e125cb","server_ts_ms":1768250236415,"raw":{"market":"0x2a12fd3d8235c25c062dc9652970ef9f635636c4018df0909e1a51c673e125cb","price_changes":[{"asset_id":"63670753354844494163057275310194312729998307779831462269530137743341854359908","price":"0.78","size":"978.8","side":"BUY","hash":"e3820d01277f74cc50561204bc0094718a20ae27","best_bid":"0.87","best_ask":"0.88"},{"asset_id":"56386988715176239099720172290594769295756680374928571099138069977179519358166","price":"0.22","size":"978.8","side":"SELL","hash":"c0ddcf986d6eb3366b0f8e4cb410a70523982c60","best_bid":"0.12","best_ask":"0.13"}],"timestamp":"1768250236415","event_type":"price_change"}}
{"schema_version":1,"source":"clob_ws_market","recv_ts_ns":1768250236601743412,"event_type":"price_change","market":"0x2a12fd3d8235c25c062dc9652970ef9f635636c4018df0909e1a51c673e125cb","server_ts_ms":1768250236418,"raw":{"market":"0x2a12fd3d8235c25c062dc9652970ef9f635636c4018df0909e1a51c673e125cb","price_changes":[{"asset_id":"63670753354844494163057275310194312729998307779831462269530137743341854359908","price":"0.75","size":"722.5","side":"BUY","hash":"d359f016e9c0eb54739856f8fc306663c7c0f498","best_bid":"0.87","best_ask":"0.88"},{"asset_id":"56386988715176239099720172290594769295756680374928571099138069977179519358166","price":"0.25","size":"722.5","side":"SELL","hash":"9571cbf9ae0c102e27eb4fa8ead5559eee591b0d","best_bid":"0.12","best_ask":"0.13"}],"timestamp":"1768250236418","event_type":"price_change"}}
{"schema_version":1,"source":"clob_ws_market","recv_ts_ns":1768250236605361565,"event_type":"price_change","market":"0x2a12fd3d8235c25c062dc9652970ef9f635636c4018df0909e1a51c673e125cb","server_ts_ms":1768250236420,"raw":{"market":"0x2a12fd3d8235c25c062dc9652970ef9f635636c4018df0909e1a51c673e125cb","price_changes":[{"asset_id":"63670753354844494163057275310194312729998307779831462269530137743341854359908","price":"0.86","size":"1147.63","side":"BUY","hash":"3e76d2e516744840e2d3eec584e21e948177310a","best_bid":"0.87","best_ask":"0.88"},{"asset_id":"56386988715176239099720172290594769295756680374928571099138069977179519358166","price":"0.14","size":"1147.63","side":"SELL","hash":"74cd57ccaf992f7119cabb2bf0fad925732f8395","best_bid":"0.12","best_ask":"0.13"}],"timestamp":"1768250236420","event_type":"price_change"}}
{"schema_version":1,"source":"clob_ws_market","recv_ts_ns":1768250236643425261,"event_type":"price_change","market":"0x2a12fd3d8235c25c062dc9652970ef9f635636c4018df0909e1a51c673e125cb","server_ts_ms":1768250236491,"raw":{"market":"0x2a12fd3d8235c25c062dc9652970ef9f635636c4018df0909e1a51c673e125cb","price_changes":[{"asset_id":"63670753354844494163057275310194312729998307779831462269530137743341854359908","price":"0.94","size":"1497","side":"SELL","hash":"2dd52c278c29832b590b12a7ca9e19e2e8f9f1ed","best_bid":"0.87","best_ask":"0.88"},{"asset_id":"56386988715176239099720172290594769295756680374928571099138069977179519358166","price":"0.06","size":"1497","side":"BUY","hash":"0948a7a1ac832c3d5c676e8154233bc9c5d8e0f4","best_bid":"0.12","best_ask":"0.13"}],"timestamp":"1768250236491","event_type":"price_change"}}
{"schema_version":1,"source":"clob_ws_market","recv_ts_ns":1768250236652765968,"event_type":"price_change","market":"0x2a12fd3d8235c25c062dc9652970ef9f635636c4018df0909e1a51c673e125cb","server_ts_ms":1768250236494,"raw":{"market":"0x2a12fd3d8235c25c062dc9652970ef9f635636c4018df0909e1a51c673e125cb","price_changes":[{"asset_id":"63670753354844494163057275310194312729998307779831462269530137743341854359908","price":"0.95","size":"3454.5","side":"SELL","hash":"796888dd56bf274ba6680c3535212513722746f2","best_bid":"0.87","best_ask":"0.88"},{"asset_id":"56386988715176239099720172290594769295756680374928571099138069977179519358166","price":"0.05","size":"3454.5","side":"BUY","hash":"09557bd3e4b54805256060027108db08e2902ca7","best_bid":"0.12","best_ask":"0.13"}],"timestamp":"1768250236494","event_type":"price_change"}}
{"schema_version":1,"source":"clob_ws_market","recv_ts_ns":1768250236675966569,"event_type":"price_change","market":"0x2a12fd3d8235c25c062dc9652970ef9f635636c4018df0909e1a51c673e125cb","server_ts_ms":1768250236524,"raw":{"market":"0x2a12fd3d8235c25c062dc9652970ef9f635636c4018df0909e1a51c673e125cb","price_changes":[{"asset_id":"63670753354844494163057275310194312729998307779831462269530137743341854359908","price":"0.85","size":"234.99","side":"BUY","hash":"58aeedb8e98dbc4eb7da5aa452d020f69d777b4b","best_bid":"0.87","best_ask":"0.88"},{"asset_id":"56386988715176239099720172290594769295756680374928571099138069977179519358166","price":"0.15","size":"234.99","side":"SELL","hash":"5df6a38a020d360858a1cdac14fa63cc92c7815e","best_bid":"0.12","best_ask":"0.13"}],"timestamp":"1768250236524","event_type":"price_change"}}
{"schema_version":1,"source":"clob_ws_market","recv_ts_ns":1768250236687570441,"event_type":"price_change","market":"0x2a12fd3d8235c25c062dc9652970ef9f635636c4018df0909e1a51c673e125cb","server_ts_ms":1768250236525,"raw":{"market":"0x2a12fd3d8235c25c062dc9652970ef9f635636c4018df0909e1a51c673e125cb","price_changes":[{"asset_id":"63670753354844494163057275310194312729998307779831462269530137743341854359908","price":"0.86","size":"1137.63","side":"BUY","hash":"865f0d134906a318e28fdddd8e8b224db5f5c81b","best_bid":"0.87","best_ask":"0.88"},{"asset_id":"56386988715176239099720172290594769295756680374928571099138069977179519358166","price":"0.14","size":"1137.63","side":"SELL","hash":"91b720185f04ca1e2e8202bbc60c79427efd391f","best_bid":"0.12","best_ask":"0.13"}],"timestamp":"1768250236525","event_type":"price_change"}}
{"schema_version":1,"source":"clob_ws_market","recv_ts_ns":1768250236691580822,"event_type":"price_change","market":"0x2a12fd3d8235c25c062dc9652970ef9f635636c4018df0909e1a51c673e125cb","server_ts_ms":1768250236526,"raw":{"market":"0x2a12fd3d8235c25c062dc9652970ef9f635636c4018df0909e1a51c673e125cb","price_changes":[{"asset_id":"56386988715176239099720172290594769295756680374928571099138069977179519358166","price":"0.11","size":"1511.5","side":"BUY","hash":"5dcc6ddf72ec9cd74b02f16541a7b225e1ce7500","best_bid":"0.12","best_ask":"0.13"},{"asset_id":"63670753354844494163057275310194312729998307779831462269530137743341854359908","price":"0.89","size":"1511.5","side":"SELL","hash":"6018c63acdbdf1625dc354e44e165c7c9d1a2137","best_bid":"0.87","best_ask":"0.88"}],"timestamp":"1768250236526","event_type":"price_change"}}
{"schema_version":1,"source":"clob_ws_market","recv_ts_ns":1768250236695487341,"event_type":"price_change","market":"0x2a12fd3d8235c25c062dc9652970ef9f635636c4018df0909e1a51c673e125cb","server_ts_ms":1768250236527,"raw":{"market":"0x2a12fd3d8235c25c062dc9652970ef9f635636c4018df0909e1a51c673e125cb","price_changes":[{"asset_id":"63670753354844494163057275310194312729998307779831462269530137743341854359908","price":"0.85","size":"224.99","side":"BUY","hash":"4a3319cf51274e0f82b631ada321b2f0351eb424","best_bid":"0.87","best_ask":"0.88"},{"asset_id":"56386988715176239099720172290594769295756680374928571099138069977179519358166","price":"0.15","size":"224.99","side":"SELL","hash":"a8d5620e1c78550782d1cee7b3f85783a0efa9bc","best_bid":"0.12","best_ask":"0.13"}],"timestamp":"1768250236527","event_type":"price_change"}}
{"schema_version":1,"source":"clob_ws_market","recv_ts_ns":1768250236699779622,"event_type":"price_change","market":"0x2a12fd3d8235c25c062dc9652970ef9f635636c4018df0909e1a51c673e125cb","server_ts_ms":1768250236527,"raw":{"market":"0x2a12fd3d8235c25c062dc9652970ef9f635636c4018df0909e1a51c673e125cb","price_changes":[{"asset_id":"56386988715176239099720172290594769295756680374928571099138069977179519358166","price":"0.1","size":"4399.5","side":"BUY","hash":"0e7c6f051180ca7740977944283f4f32a48b6bcd","best_bid":"0.12","best_ask":"0.13"},{"asset_id":"63670753354844494163057275310194312729998307779831462269530137743341854359908","price":"0.9","size":"4399.5","side":"SELL","hash":"37122743dcc302084001b6e160620ebf63b41906","best_bid":"0.87","best_ask":"0.88"}],"timestamp":"1768250236527","event_type":"price_change"}}
{"schema_version":1,"source":"clob_ws_market","recv_ts_ns":1768250236704732709,"event_type":"price_change","market":"0x2a12fd3d8235c25c062dc9652970ef9f635636c4018df0909e1a51c673e125cb","server_ts_ms":1768250236528,"raw":{"market":"0x2a12fd3d8235c25c062dc9652970ef9f635636c4018df0909e1a51c673e125cb","price_changes":[{"asset_id":"63670753354844494163057275310194312729998307779831462269530137743341854359908","price":"0.85","size":"214.99","side":"BUY","hash":"eb1dc38e721b55f0f3ea7c459c44326b1ec84c5b","best_bid":"0.87","best_ask":"0.88"},{"asset_id":"56386988715176239099720172290594769295756680374928571099138069977179519358166","price":"0.15","size":"214.99","side":"SELL","hash":"6a4c153cae793945ff7405ac308472250a76e469","best_bid":"0.12","best_ask":"0.13"}],"timestamp":"1768250236528","event_type":"price_change"}}
{"schema_version":1,"source":"clob_ws_market","recv_ts_ns":1768250236710422446,"event_type":"price_change","market":"0x2a12fd3d8235c25c062dc9652970ef9f635636c4018df0909e1a51c673e125cb","server_ts_ms":1768250236530,"raw":{"market":"0x2a12fd3d8235c25c062dc9652970ef9f635636c4018df0909e1a51c673e125cb","price_changes":[{"asset_id":"56386988715176239099720172290594769295756680374928571099138069977179519358166","price":"0.11","size":"1501.5","side":"BUY","hash":"121b9856f8b7d453e5e034bd591ff8990ef534f0","best_bid":"0.12","best_ask":"0.13"},{"asset_id":"63670753354844494163057275310194312729998307779831462269530137743341854359908","price":"0.89","size":"1501.5","side":"SELL","hash":"a0d7535732c20619b1cb5801434cf894181dff6e","best_bid":"0.87","best_ask":"0.88"}],"timestamp":"1768250236530","event_type":"price_change"}}
{"schema_version":1,"source":"clob_ws_market","recv_ts_ns":1768250236714726367,"event_type":"price_change","market":"0x2a12fd3d8235c25c062dc9652970ef9f635636c4018df0909e1a51c673e125cb","server_ts_ms":1768250236530,"raw":{"market":"0x2a12fd3d8235c25c062dc9652970ef9f635636c4018df0909e1a51c673e125cb","price_changes":[{"asset_id":"63670753354844494163057275310194312729998307779831462269530137743341854359908","price":"0.85","size":"204.99","side":"BUY","hash":"56bbe2703d868adbac7fdfdcfd751677382d07bf","best_bid":"0.87","best_ask":"0.88"},{"asset_id":"56386988715176239099720172290594769295756680374928571099138069977179519358166","price":"0.15","size":"204.99","side":"SELL","hash":"27e071909c241a42b8aeee05ea32ae731f4680e1","best_bid":"0.12","best_ask":"0.13"}],"timestamp":"1768250236530","event_type":"price_change"}}
{"schema_version":1,"source":"clob_ws_market","recv_ts_ns":1768250236718364411,"event_type":"price_change","market":"0x2a12fd3d8235c25c062dc9652970ef9f635636c4018df0909e1a51c673e125cb","server_ts_ms":1768250236531,"raw":{"market":"0x2a12fd3d8235c25c062dc9652970ef9f635636c4018df0909e1a51c673e125cb","price_changes":[{"asset_id":"56386988715176239099720172290594769295756680374928571099138069977179519358166","price":"0.08","size":"1496.75","side":"BUY","hash":"c7ab28bc0c40b34879faf7cd276f342b8d28afcf","best_bid":"0.12","best_ask":"0.13"},{"asset_id":"63670753354844494163057275310194312729998307779831462269530137743341854359908","price":"0.92","size":"1496.75","side":"SELL","hash":"befdd39be816834a3c73bf697fc5cb44a7aa700a","best_bid":"0.87","best_ask":"0.88"}],"timestamp":"1768250236531","event_type":"price_change"}}
{"schema_version":1,"source":"clob_ws_market","recv_ts_ns":1768250236721236003,"event_type":"price_change","market":"0x2a12fd3d8235c25c062dc9652970ef9f635636c4018df0909e1a51c673e125cb","server_ts_ms":1768250236532,"raw":{"market":"0x2a12fd3d8235c25c062dc9652970ef9f635636c4018df0909e1a51c673e125cb","price_changes":[{"asset_id":"56386988715176239099720172290594769295756680374928571099138069977179519358166","price":"0.09","size":"1387","side":"BUY","hash":"160ba697c4095db9dd92bfdbb3589683d3c08a7b","best_bid":"0.12","best_ask":"0.13"},{"asset_id":"63670753354844494163057275310194312729998307779831462269530137743341854359908","price":"0.91","size":"1387","side":"SELL","hash":"5ffc33b13499d305791c21f61bc95da0fbb595aa","best_bid":"0.87","best_ask":"0.88"}],"timestamp":"1768250236532","event_type":"price_change"}}
{"schema_version":1,"source":"clob_ws_market","recv_ts_ns":1768250236724443660,"event_type":"price_change","market":"0x2a12fd3d8235c25c062dc9652970ef9f635636c4018df0909e1a51c673e125cb","server_ts_ms":1768250236532,"raw":{"market":"0x2a12fd3d8235c25c062dc9652970ef9f635636c4018df0909e1a51c673e125cb","price_changes":[{"asset_id":"56386988715176239099720172290594769295756680374928571099138069977179519358166","price":"0.11","size":"1491.5","side":"BUY","hash":"19daf4fe7822d2f266a9c856be23fce4940c3f37","best_bid":"0.12","best_ask":"0.13"},{"asset_id":"63670753354844494163057275310194312729998307779831462269530137743341854359908","price":"0.89","size":"1491.5","side":"SELL","hash":"7b6a50b17c89a486387b624cfbdc71ff1fd8abb9","best_bid":"0.87","best_ask":"0.88"}],"timestamp":"1768250236532","event_type":"price_change"}}
{"schema_version":1,"source":"clob_ws_market","recv_ts_ns":1768250236728002072,"event_type":"price_change","market":"0x2a12fd3d8235c25c062dc9652970ef9f635636c4018df0909e1a51c673e125cb","server_ts_ms":1768250236532,"raw":{"market":"0x2a12fd3d8235c25c062dc9652970ef9f635636c4018df0909e1a51c673e125cb","price_changes":[{"asset_id":"56386988715176239099720172290594769295756680374928571099138069977179519358166","price":"0.12","size":"831.35","side":"BUY","hash":"b2a85875876ec4f50fd8578c4bd4b50cb11af502","best_bid":"0.12","best_ask":"0.13"},{"asset_id":"63670753354844494163057275310194312729998307779831462269530137743341854359908","price":"0.88","size":"831.35","side":"SELL","hash":"46f9904f2e33b2d07491ee0e98500c0a3230439c","best_bid":"0.87","best_ask":"0.88"}],"timestamp":"1768250236532","event_type":"price_change"}}
{"schema_version":1,"source":"clob_ws_market","recv_ts_ns":1768250236731182681,"event_type":"price_change","market":"0x2a12fd3d8235c25c062dc9652970ef9f635636c4018df0909e1a51c673e125cb","server_ts_ms":1768250236534,"raw":{"market":"0x2a12fd3d8235c25c062dc9652970ef9f635636c4018df0909e1a51c673e125cb","price_changes":[{"asset_id":"56386988715176239099720172290594769295756680374928571099138069977179519358166","price":"0.09","size":"1377","side":"BUY","hash":"abab3aa5b89c27572294e937c48904d93ce1efdd","best_bid":"0.12","best_ask":"0.13"},{"asset_id":"63670753354844494163057275310194312729998307779831462269530137743341854359908","price":"0.91","size":"1377","side":"SELL","hash":"9d5fda3a4122fd09fc3cadc31021421620c61543","best_bid":"0.87","best_ask":"0.88"}],"timestamp":"1768250236534","event_type":"price_change"}}
{"schema_version":1,"source":"clob_ws_market","recv_ts_ns":1768250236733909244,"event_type":"price_change","market":"0x2a12fd3d8235c25c062dc9652970ef9f635636c4018df0909e1a51c673e125cb","server_ts_ms":1768250236540,"raw":{"market":"0x2a12fd3d8235c25c062dc9652970ef9f635636c4018df0909e1a51c673e125cb","price_changes":[{"asset_id":"63670753354844494163057275310194312729998307779831462269530137743341854359908","price":"0.86","size":"1127.63","side":"BUY","hash":"dfd23349d72f0f7ca6ce4a47a5a92cf070799c29","best_bid":"0.87","best_ask":"0.88"},{"asset_id":"56386988715176239099720172290594769295756680374928571099138069977179519358166","price":"0.14","size":"1127.63","side":"SELL","hash":"6d502791745c65a14c02db06eb9e95b89ade65af","best_bid":"0.12","best_ask":"0.13"}],"timestamp":"1768250236540","event_type":"price_change"}}
{"schema_version":1,"source":"clob_ws_market","recv_ts_ns":1768250236737021195,"event_type":"price_change","market":"0x2a12fd3d8235c25c062dc9652970ef9f635636c4018df0909e1a51c673e125cb","server_ts_ms":1768250236541,"raw":{"market":"0x2a12fd3d8235c25c062dc9652970ef9f635636c4018df0909e1a51c673e125cb","price_changes":[{"asset_id":"63670753354844494163057275310194312729998307779831462269530137743341854359908","price":"0.85","size":"194.99","side":"BUY","hash":"10b3642f2a5e69c14dfbc548662a5938632811ec","best_bid":"0.87","best_ask":"0.88"},{"asset_id":"56386988715176239099720172290594769295756680374928571099138069977179519358166","price":"0.15","size":"194.99","side":"SELL","hash":"239479656a3c31bf05d2b389ffd1b7932c93b4ce","best_bid":"0.12","best_ask":"0.13"}],"timestamp":"1768250236541","event_type":"price_change"}}
{"schema_version":1,"source":"clob_ws_market","recv_ts_ns":1768250236740276633,"event_type":"price_change","market":"0x2a12fd3d8235c25c062dc9652970ef9f635636c4018df0909e1a51c673e125cb","server_ts_ms":1768250236553,"raw":{"market":"0x2a12fd3d8235c25c062dc9652970ef9f635636c4018df0909e1a51c673e125cb","price_changes":[{"asset_id":"56386988715176239099720172290594769295756680374928571099138069977179519358166","price":"0.1","size":"4409.5","side":"BUY","hash":"3c6c7e4c3989c5a2eddec328d04e4cd5a576cb73","best_bid":"0.12","best_ask":"0.13"},{"asset_id":"63670753354844494163057275310194312729998307779831462269530137743341854359908","price":"0.9","size":"4409.5","side":"SELL","hash":"90f0003b92d301a2b9692478b26053cce849c4be","best_bid":"0.87","best_ask":"0.88"}],"timestamp":"1768250236553","event_type":"price_change"}}
{"schema_version":1,"source":"clob_ws_market","recv_ts_ns":1768250236744867300,"event_type":"price_change","market":"0x2a12fd3d8235c25c062dc9652970ef9f635636c4018df0909e1a51c673e125cb","server_ts_ms":1768250236557,"raw":{"market":"0x2a12fd3d8235c25c062dc9652970ef9f635636c4018df0909e1a51c673e125cb","price_changes":[{"asset_id":"63670753354844494163057275310194312729998307779831462269530137743341854359908","price":"0.86","size":"1137.63","side":"BUY","hash":"2eb3678683ba6ca0298f6c1f3d0a6f769a65c57b","best_bid":"0.87","best_ask":"0.88"},{"asset_id":"56386988715176239099720172290594769295756680374928571099138069977179519358166","price":"0.14","size":"1137.63","side":"SELL","hash":"3da6eed0c4016b90923adbc0e579614fcfc08132","best_bid":"0.12","best_ask":"0.13"}],"timestamp":"1768250236557","event_type":"price_change"}}
{"schema_version":1,"source":"clob_ws_market","recv_ts_ns":1768250236747250134,"event_type":"price_change","market":"0x2a12fd3d8235c25c062dc9652970ef9f635636c4018df0909e1a51c673e125cb","server_ts_ms":1768250236560,"raw":{"market":"0x2a12fd3d8235c25c062dc9652970ef9f635636c4018df0909e1a51c673e125cb","price_changes":[{"asset_id":"63670753354844494163057275310194312729998307779831462269530137743341854359908","price":"0.86","size":"1147.63","side":"BUY","hash":"9d0fe0aec24152f65e441055edba8be2178993bc","best_bid":"0.87","best_ask":"0.88"},{"asset_id":"56386988715176239099720172290594769295756680374928571099138069977179519358166","price":"0.14","size":"1147.63","side":"SELL","hash":"395db3002a08f6c50f06f32f16c16962a8da8cfc","best_bid":"0.12","best_ask":"0.13"}],"timestamp":"1768250236560","event_type":"price_change"}}
{"schema_version":1,"source":"clob_ws_market","recv_ts_ns":1768250236749386187,"event_type":"price_change","market":"0x2a12fd3d8235c25c062dc9652970ef9f635636c4018df0909e1a51c673e125cb","server_ts_ms":1768250236561,"raw":{"market":"0x2a12fd3d8235c25c062dc9652970ef9f635636c4018df0909e1a51c673e125cb","price_changes":[{"asset_id":"56386988715176239099720172290594769295756680374928571099138069977179519358166","price":"0.09","size":"1387","side":"BUY","hash":"09bc9455a3d2e7cf18dc9dea736434b0af57d074","best_bid":"0.12","best_ask":"0.13"},{"asset_id":"63670753354844494163057275310194312729998307779831462269530137743341854359908","price":"0.91","size":"1387","side":"SELL","hash":"92393d15768a420b5591f2a27f5004ddf049e566","best_bid":"0.87","best_ask":"0.88"}],"timestamp":"1768250236561","event_type":"price_change"}}
{"schema_version":1,"source":"clob_ws_market","recv_ts_ns":1768250236751420844,"event_type":"price_change","market":"0x2a12fd3d8235c25c062dc9652970ef9f635636c4018df0909e1a51c673e125cb","server_ts_ms":1768250236562,"raw":{"market":"0x2a12fd3d8235c25c062dc9652970ef9f635636c4018df0909e1a51c673e125cb","price_changes":[{"asset_id":"63670753354844494163057275310194312729998307779831462269530137743341854359908","price":"0.86","size":"1157.63","side":"BUY","hash":"43edef179ac1562a65f7416a57c9201f804c3fb1","best_bid":"0.87","best_ask":"0.88"},{"asset_id":"56386988715176239099720172290594769295756680374928571099138069977179519358166","price":"0.14","size":"1157.63","side":"SELL","hash":"a75e592f0a0505baac66d0d593f151ab94b33d11","best_bid":"0.12","best_ask":"0.13"}],"timestamp":"1768250236562","event_type":"price_change"}}
{"schema_version":1,"source":"clob_ws_market","recv_ts_ns":1768250236753470197,"event_type":"price_change","market":"0x2a12fd3d8235c25c062dc9652970ef9f635636c4018df0909e1a51c673e125cb","server_ts_ms":1768250236564,"raw":{"market":"0x2a12fd3d8235c25c062dc9652970ef9f635636c4018df0909e1a51c673e125cb","price_changes":[{"asset_id":"56386988715176239099720172290594769295756680374928571099138069977179519358166","price":"0.11","size":"1501.5","side":"BUY","hash":"557b4f35ef0f4ac0c32927f3f19ee4cbb406aa17","best_bid":"0.12","best_ask":"0.13"},{"asset_id":"63670753354844494163057275310194312729998307779831462269530137743341854359908","price":"0.89","size":"1501.5","side":"SELL","hash":"046867d5f8e6a2c0ad1240ee8fe5eccc24234bfe","best_bid":"0.87","best_ask":"0.88"}],"timestamp":"1768250236564","event_type":"price_change"}}
{"schema_version":1,"source":"clob_ws_market","recv_ts_ns":1768250236757665426,"event_type":"price_change","market":"0x2a12fd3d8235c25c062dc9652970ef9f635636c4018df0909e1a51c673e125cb","server_ts_ms":1768250236565,"raw":{"market":"0x2a12fd3d8235c25c062dc9652970ef9f635636c4018df0909e1a51c673e125cb","price_changes":[{"asset_id":"56386988715176239099720172290594769295756680374928571099138069977179519358166","price":"0.1","size":"4419.5","side":"BUY","hash":"862a30352f56c80c6e1d683672c6abfa60364504","best_bid":"0.12","best_ask":"0.13"},{"asset_id":"63670753354844494163057275310194312729998307779831462269530137743341854359908","price":"0.9","size":"4419.5","side":"SELL","hash":"45bfffacac8d65d820f6aba29a25144504810c10","best_bid":"0.87","best_ask":"0.88"}],"timestamp":"1768250236565","event_type":"price_change"}}
{"schema_version":1,"source":"clob_ws_market","recv_ts_ns":1768250236761414340,"event_type":"price_change","market":"0x2a12fd3d8235c25c062dc9652970ef9f635636c4018df0909e1a51c673e125cb","server_ts_ms":1768250236565,"raw":{"market":"0x2a12fd3d8235c25c062dc9652970ef9f635636c4018df0909e1a51c673e125cb","price_changes":[{"asset_id":"56386988715176239099720172290594769295756680374928571099138069977179519358166","price":"0.07","size":"1416.28","side":"BUY","hash":"424a28a500a4c7a044eb19729d1645d38218600a","best_bid":"0.12","best_ask":"0.13"},{"asset_id":"63670753354844494163057275310194312729998307779831462269530137743341854359908","price":"0.93","size":"1416.28","side":"SELL","hash":"85b6383b88eb6e1a7ffe5de87a4eb69a11cf86be","best_bid":"0.87","best_ask":"0.88"}],"timestamp":"1768250236565","event_type":"price_change"}}
{"schema_version":1,"source":"clob_ws_market","recv_ts_ns":1768250236764654916,"event_type":"price_change","market":"0x2a12fd3d8235c25c062dc9652970ef9f635636c4018df0909e1a51c673e125cb","server_ts_ms":1768250236566,"raw":{"market":"0x2a12fd3d8235c25c062dc9652970ef9f635636c4018df0909e1a51c673e125cb","price_changes":[{"asset_id":"63670753354844494163057275310194312729998307779831462269530137743341854359908","price":"0.87","size":"20.5","side":"BUY","hash":"608d16856c651345143d1d973d285b289cd5df90","best_bid":"0.87","best_ask":"0.88"},{"asset_id":"56386988715176239099720172290594769295756680374928571099138069977179519358166","price":"0.13","size":"20.5","side":"SELL","hash":"54355903307ad3a79a779e7da709d464bc38378a","best_bid":"0.12","best_ask":"0.13"}],"timestamp":"1768250236566","event_type":"price_change"}}
{"schema_version":1,"source":"clob_ws_market","recv_ts_ns":1768250236768134068,"event_type":"price_change","market":"0x2a12fd3d8235c25c062dc9652970ef9f635636c4018df0909e1a51c673e125cb","server_ts_ms":1768250236568,"raw":{"market":"0x2a12fd3d8235c25c062dc9652970ef9f635636c4018df0909e1a51c673e125cb","price_changes":[{"asset_id":"63670753354844494163057275310194312729998307779831462269530137743341854359908","price":"0.86","size":"1167.63","side":"BUY","hash":"5dca8b3fc7b5d7131a218d64039822d4dd40c667","best_bid":"0.87","best_ask":"0.88"},{"asset_id":"56386988715176239099720172290594769295756680374928571099138069977179519358166","price":"0.14","size":"1167.63","side":"SELL","hash":"de45801f9e7c898c0ebac907be6d7eaaf1c030d5","best_bid":"0.12","best_ask":"0.13"}],"timestamp":"1768250236568","event_type":"price_change"}}
{"schema_version":1,"source":"clob_ws_market","recv_ts_ns":1768250236771486202,"event_type":"price_change","market":"0x2a12fd3d8235c25c062dc9652970ef9f635636c4018df0909e1a51c673e125cb","server_ts_ms":1768250236569,"raw":{"market":"0x2a12fd3d8235c25c062dc9652970ef9f635636c4018df0909e1a51c673e125cb","price_changes":[{"asset_id":"56386988715176239099720172290594769295756680374928571099138069977179519358166","price":"0.1","size":"3419.5","side":"BUY","hash":"82cfe95b67345eef7cb9199cc6ab23e7a2c81841","best_bid":"0.12","best_ask":"0.13"},{"asset_id":"63670753354844494163057275310194312729998307779831462269530137743341854359908","price":"0.9","size":"3419.5","side":"SELL","hash":"0ad41e64d0ccb002a1f81265a5d8f51909b377b1","best_bid":"0.87","best_ask":"0.88"}],"timestamp":"1768250236569","event_type":"price_change"}}
{"schema_version":1,"source":"clob_ws_market","recv_ts_ns":1768250236818942846,"event_type":"price_change","market":"0x2a12fd3d8235c25c062dc9652970ef9f635636c4018df0909e1a51c673e125cb","server_ts_ms":1768250236577,"raw":{"market":"0x2a12fd3d8235c25c062dc9652970ef9f635636c4018df0909e1a51c673e125cb","price_changes":[{"asset_id":"56386988715176239099720172290594769295756680374928571099138069977179519358166","price":"0.08","size":"1506.75","side":"BUY","hash":"1237a128150e8b7a85666a90e9890e3a024135f9","best_bid":"0.12","best_ask":"0.13"},{"asset_id":"63670753354844494163057275310194312729998307779831462269530137743341854359908","price":"0.92","size":"1506.75","side":"SELL","hash":"11b8ce90e244bdafae36c6faebac1e83547b6528","best_bid":"0.87","best_ask":"0.88"}],"timestamp":"1768250236577","event_type":"price_change"}}
{"schema_version":1,"source":"clob_ws_market","recv_ts_ns":1768250236821661602,"event_type":"price_change","market":"0x2a12fd3d8235c25c062dc9652970ef9f635636c4018df0909e1a51c673e125cb","server_ts_ms":1768250236581,"raw":{"market":"0x2a12fd3d8235c25c062dc9652970ef9f635636c4018df0909e1a51c673e125cb","price_changes":[{"asset_id":"63670753354844494163057275310194312729998307779831462269530137743341854359908","price":"0.84","size":"696","side":"BUY","hash":"57deb185ac33e6b661aa597e7240b4bd3f91b56f","best_bid":"0.87","best_ask":"0.88"},{"asset_id":"56386988715176239099720172290594769295756680374928571099138069977179519358166","price":"0.16","size":"696","side":"SELL","hash":"40fbb93bbe4333ea9c236e7a94fc58a4f93a781d","best_bid":"0.12","best_ask":"0.13"}],"timestamp":"1768250236581","event_type":"price_change"}}
{"schema_version":1,"source":"clob_ws_market","recv_ts_ns":1768250236880030545,"event_type":"price_change","market":"0x2a12fd3d8235c25c062dc9652970ef9f635636c4018df0909e1a51c673e125cb","server_ts_ms":1768250236592,"raw":{"market":"0x2a12fd3d8235c25c062dc9652970ef9f635636c4018df0909e1a51c673e125cb","price_changes":[{"asset_id":"56386988715176239099720172290594769295756680374928571099138069977179519358166","price":"0.1","size":"3429.5","side":"BUY","hash":"d73d8754ff2c6a15fbdb9dd8807e7c0d9e76d5b2","best_bid":"0.12","best_ask":"0.13"},{"asset_id":"63670753354844494163057275310194312729998307779831462269530137743341854359908","price":"0.9","size":"3429.5","side":"SELL","hash":"652460a05deb7637ff0b50163793f87c81d1abea","best_bid":"0.87","best_ask":"0.88"}],"timestamp":"1768250236592","event_type":"price_change"}}
{"schema_version":1,"source":"clob_ws_market","recv_ts_ns":1768250236885098931,"event_type":"price_change","market":"0x2a12fd3d8235c25c062dc9652970ef9f635636c4018df0909e1a51c673e125cb","server_ts_ms":1768250236593,"raw":{"market":"0x2a12fd3d8235c25c062dc9652970ef9f635636c4018df0909e1a51c673e125cb","price_changes":[{"asset_id":"63670753354844494163057275310194312729998307779831462269530137743341854359908","price":"0.86","size":"1177.63","side":"BUY","hash":"a4a842d30342fa497e56b220d9051bf474350136","best_bid":"0.87","best_ask":"0.88"},{"asset_id":"56386988715176239099720172290594769295756680374928571099138069977179519358166","price":"0.14","size":"1177.63","side":"SELL","hash":"9c6c4064f6f02924319d16a4140b455f773c45f4","best_bid":"0.12","best_ask":"0.13"}],"timestamp":"1768250236593","event_type":"price_change"}}
{"schema_version":1,"source":"clob_ws_market","recv_ts_ns":1768250236899956036,"event_type":"price_change","market":"0x2a12fd3d8235c25c062dc9652970ef9f635636c4018df0909e1a51c673e125cb","server_ts_ms":1768250236599,"raw":{"market":"0x2a12fd3d8235c25c062dc9652970ef9f635636c4018df0909e1a51c673e125cb","price_changes":[{"asset_id":"56386988715176239099720172290594769295756680374928571099138069977179519358166","price":"0.08","size":"1516.75","side":"BUY","hash":"22a17ff7b9e4746ce3ae2684c07df20f320fe85a","best_bid":"0.12","best_ask":"0.13"},{"asset_id":"63670753354844494163057275310194312729998307779831462269530137743341854359908","price":"0.92","size":"1516.75","side":"SELL","hash":"367203bdab46b1ff66a340be391632bcb660ba60","best_bid":"0.87","best_ask":"0.88"}],"timestamp":"1768250236599","event_type":"price_change"}}
{"schema_version":1,"source":"clob_ws_market","recv_ts_ns":1768250236904613490,"event_type":"price_change","market":"0x2a12fd3d8235c25c062dc9652970ef9f635636c4018df0909e1a51c673e125cb","server_ts_ms":1768250236603,"raw":{"market":"0x2a12fd3d8235c25c062dc9652970ef9f635636c4018df0909e1a51c673e125cb","price_changes":[{"asset_id":"63670753354844494163057275310194312729998307779831462269530137743341854359908","price":"0.95","size":"3442","side":"SELL","hash":"f77610f33c04bc740bc3e32d4c57bdec4144fca3","best_bid":"0.87","best_ask":"0.88"},{"asset_id":"56386988715176239099720172290594769295756680374928571099138069977179519358166","price":"0.05","size":"3442","side":"BUY","hash":"c04df436d1768ec8bbb2b73d2e0d75669d1ce685","best_bid":"0.12","best_ask":"0.13"}],"timestamp":"1768250236603","event_type":"price_change"}}
{"schema_version":1,"source":"clob_ws_market","recv_ts_ns":1768250236911849616,"event_type":"price_change","market":"0x2a12fd3d8235c25c062dc9652970ef9f635636c4018df0909e1a51c673e125cb","server_ts_ms":1768250236605,"raw":{"market":"0x2a12fd3d8235c25c062dc9652970ef9f635636c4018df0909e1a51c673e125cb","price_changes":[{"asset_id":"63670753354844494163057275310194312729998307779831462269530137743341854359908","price":"0.94","size":"1509.5","side":"SELL","hash":"f80e281d2d160c68cdc9a36653049325e740c280","best_bid":"0.87","best_ask":"0.88"},{"asset_id":"56386988715176239099720172290594769295756680374928571099138069977179519358166","price":"0.06","size":"1509.5","side":"BUY","hash":"9efd50eb5c3ad37bd025b8a13ec4bd2a663a1122","best_bid":"0.12","best_ask":"0.13"}],"timestamp":"1768250236605","event_type":"price_change"}}
{"schema_version":1,"source":"clob_ws_market","recv_ts_ns":1768250236916682960,"event_type":"price_change","market":"0x2a12fd3d8235c25c062dc9652970ef9f635636c4018df0909e1a51c673e125cb","server_ts_ms":1768250236607,"raw":{"market":"0x2a12fd3d8235c25c062dc9652970ef9f635636c4018df0909e1a51c673e125cb","price_changes":[{"asset_id":"63670753354844494163057275310194312729998307779831462269530137743341854359908","price":"0.86","size":"1187.63","side":"BUY","hash":"89cb713b8fab61849c86a1f65f59181dff866582","best_bid":"0.87","best_ask":"0.88"},{"asset_id":"56386988715176239099720172290594769295756680374928571099138069977179519358166","price":"0.14","size":"1187.63","side":"SELL","hash":"0343617b13562579832fa509d9e31e4448bea8ec","best_bid":"0.12","best_ask":"0.13"}],"timestamp":"1768250236607","event_type":"price_change"}}
{"schema_version":1,"source":"clob_ws_market","recv_ts_ns":1768250236975622520,"event_type":"price_change","market":"0x2a12fd3d8235c25c062dc9652970ef9f635636c4018df0909e1a51c673e125cb","server_ts_ms":1768250236655,"raw":{"market":"0x2a12fd3d8235c25c062dc9652970ef9f635636c4018df0909e1a51c673e125cb","price_changes":[{"asset_id":"63670753354844494163057275310194312729998307779831462269530137743341854359908","price":"0.84","size":"196","side":"BUY","hash":"dae822f33a6c6e382c5de0c138ac10dc7080a2eb","best_bid":"0.87","best_ask":"0.88"},{"asset_id":"56386988715176239099720172290594769295756680374928571099138069977179519358166","price":"0.16","size":"196","side":"SELL","hash":"45f39aad49a1a623d874dd9a3714b906983d0310","best_bid":"0.12","best_ask":"0.13"}],"timestamp":"1768250236655","event_type":"price_change"}}
{"schema_version":1,"source":"clob_ws_market","recv_ts_ns":1768250236993197291,"event_type":"price_change","market":"0x2a12fd3d8235c25c062dc9652970ef9f635636c4018df0909e1a51c673e125cb","server_ts_ms":1768250236667,"raw":{"market":"0x2a12fd3d8235c25c062dc9652970ef9f635636c4018df0909e1a51c673e125cb","price_changes":[{"asset_id":"56386988715176239099720172290594769295756680374928571099138069977179519358166","price":"0.11","size":"1413.5","side":"BUY","hash":"1900b3411983895a7b2f413dafa48993dc4cbc58","best_bid":"0.12","best_ask":"0.13"},{"asset_id":"63670753354844494163057275310194312729998307779831462269530137743341854359908","price":"0.89","size":"1413.5","side":"SELL","hash":"0d9ef8ca7aee4676ec6e768c09bed59b12715e5c","best_bid":"0.87","best_ask":"0.88"}],"timestamp":"1768250236667","event_type":"price_change"}}
{"schema_version":1,"source":"clob_ws_market","recv_ts_ns":1768250237012887169,"event_type":"price_change","market":"0x2a12fd3d8235c25c062dc9652970ef9f635636c4018df0909e1a51c673e125cb","server_ts_ms":1768250236750,"raw":{"market":"0x2a12fd3d8235c25c062dc9652970ef9f635636c4018df0909e1a51c673e125cb","price_changes":[{"asset_id":"63670753354844494163057275310194312729998307779831462269530137743341854359908","price":"0.82","size":"671","side":"BUY","hash":"d21714cf53162bbebac229b42d43e0403ee006f9","best_bid":"0.87","best_ask":"0.88"},{"asset_id":"56386988715176239099720172290594769295756680374928571099138069977179519358166","price":"0.18","size":"671","side":"SELL","hash":"aa321362d6789c3547d66ccec31c8b62bc8d5c81","best_bid":"0.12","best_ask":"0.13"}],"timestamp":"1768250236750","event_type":"price_change"}}
{"schema_version":1,"source":"clob_ws_market","recv_ts_ns":1768250237030844496,"event_type":"price_change","market":"0x2a12fd3d8235c25c062dc9652970ef9f635636c4018df0909e1a51c673e125cb","server_ts_ms":1768250236779,"raw":{"market":"0x2a12fd3d8235c25c062dc9652970ef9f635636c4018df0909e1a51c673e125cb","price_changes":[{"asset_id":"63670753354844494163057275310194312729998307779831462269530137743341854359908","price":"0.75","size":"727.5","side":"BUY","hash":"6127277cb992450ff0126612f165f7fb4aad9ffa","best_bid":"0.87","best_ask":"0.88"},{"asset_id":"56386988715176239099720172290594769295756680374928571099138069977179519358166","price":"0.25","size":"727.5","side":"SELL","hash":"039d88f57eab3b8b7d5ad2b261f1e2eaa1061f13","best_bid":"0.12","best_ask":"0.13"}],"timestamp":"1768250236779","event_type":"price_change"}}
{"schema_version":1,"source":"clob_ws_market","recv_ts_ns":1768250237036516404,"event_type":"price_change","market":"0x2a12fd3d8235c25c062dc9652970ef9f635636c4018df0909e1a51c673e125cb","server_ts_ms":1768250236798,"raw":{"market":"0x2a12fd3d8235c25c062dc9652970ef9f635636c4018df0909e1a51c673e125cb","price_changes":[{"asset_id":"63670753354844494163057275310194312729998307779831462269530137743341854359908","price":"0.83","size":"759.52","side":"BUY","hash":"5265f7f772cafae65c7cd7e88b79b4c6250b7a80","best_bid":"0.87","best_ask":"0.88"},{"asset_id":"56386988715176239099720172290594769295756680374928571099138069977179519358166","price":"0.17","size":"759.52","side":"SELL","hash":"c7c2c2ddeb42b2b7289ff8fe5038f1a6c1f2be27","best_bid":"0.12","best_ask":"0.13"}],"timestamp":"1768250236798","event_type":"price_change"}}
{"schema_version":1,"source":"clob_ws_market","recv_ts_ns":1768250237039843290,"event_type":"price_change","market":"0x2a12fd3d8235c25c062dc9652970ef9f635636c4018df0909e1a51c673e125cb","server_ts_ms":1768250236800,"raw":{"market":"0x2a12fd3d8235c25c062dc9652970ef9f635636c4018df0909e1a51c673e125cb","price_changes":[{"asset_id":"56386988715176239099720172290594769295756680374928571099138069977179519358166","price":"0.08","size":"1551.75","side":"BUY","hash":"d4c6e891467a36bb81fd976c00f3190ab2b86cf7","best_bid":"0.12","best_ask":"0.13"},{"asset_id":"63670753354844494163057275310194312729998307779831462269530137743341854359908","price":"0.92","size":"1551.75","side":"SELL","hash":"ee54969402be6abf0d1d3eb6b16423eaaabf230c","best_bid":"0.87","best_ask":"0.88"}],"timestamp":"1768250236800","event_type":"price_change"}}
{"schema_version":1,"source":"clob_ws_market","recv_ts_ns":1768250237043777109,"event_type":"price_change","market":"0x2a12fd3d8235c25c062dc9652970ef9f635636c4018df0909e1a51c673e125cb","server_ts_ms":1768250236802,"raw":{"market":"0x2a12fd3d8235c25c062dc9652970ef9f635636c4018df0909e1a51c673e125cb","price_changes":[{"asset_id":"56386988715176239099720172290594769295756680374928571099138069977179519358166","price":"0.12","size":"866.35","side":"BUY","hash":"f96cdf78cd4470404578023c0196fb08b335c2af","best_bid":"0.12","best_ask":"0.13"},{"asset_id":"63670753354844494163057275310194312729998307779831462269530137743341854359908","price":"0.88","size":"866.35","side":"SELL","hash":"0199e615ff6552e584ac53d6cdb07284a72cd161","best_bid":"0.87","best_ask":"0.88"}],"timestamp":"1768250236802","event_type":"price_change"}}
{"schema_version":1,"source":"clob_ws_market","recv_ts_ns":1768250237048672492,"event_type":"price_change","market":"0x2a12fd3d8235c25c062dc9652970ef9f635636c4018df0909e1a51c673e125cb","server_ts_ms":1768250236808,"raw":{"market":"0x2a12fd3d8235c25c062dc9652970ef9f635636c4018df0909e1a51c673e125cb","price_changes":[{"asset_id":"63670753354844494163057275310194312729998307779831462269530137743341854359908","price":"0.89","size":"1423.5","side":"SELL","hash":"64a2a0bef440c31c32da1239dda6e2980b888d8b","best_bid":"0.87","best_ask":"0.88"},{"asset_id":"56386988715176239099720172290594769295756680374928571099138069977179519358166","price":"0.11","size":"1423.5","side":"BUY","hash":"c5e9d5e5d931a21fe7fa79ff862d6256cafc78e6","best_bid":"0.12","best_ask":"0.13"}],"timestamp":"1768250236808","event_type":"price_change"}}
{"schema_version":1,"source":"clob_ws_market","recv_ts_ns":1768250237053158085,"event_type":"price_change","market":"0x2a12fd3d8235c25c062dc9652970ef9f635636c4018df0909e1a51c673e125cb","server_ts_ms":1768250236819,"raw":{"market":"0x2a12fd3d8235c25c062dc9652970ef9f635636c4018df0909e1a51c673e125cb","price_changes":[{"asset_id":"56386988715176239099720172290594769295756680374928571099138069977179519358166","price":"0.1","size":"3464.5","side":"BUY","hash":"1d8c1ec702ee47fb305f511513bba26a43e52def","best_bid":"0.12","best_ask":"0.13"},{"asset_id":"63670753354844494163057275310194312729998307779831462269530137743341854359908","price":"0.9","size":"3464.5","side":"SELL","hash":"7088b0c2dcc13a37b1ee91ff7ef05175a1628b8e","best_bid":"0.87","best_ask":"0.88"}],"timestamp":"1768250236819","event_type":"price_change"}}
{"schema_version":1,"source":"clob_ws_market","recv_ts_ns":1768250237071979837,"event_type":"price_change","market":"0x2a12fd3d8235c25c062dc9652970ef9f635636c4018df0909e1a51c673e125cb","server_ts_ms":1768250236990,"raw":{"market":"0x2a12fd3d8235c25c062dc9652970ef9f635636c4018df0909e1a51c673e125cb","price_changes":[{"asset_id":"63670753354844494163057275310194312729998307779831462269530137743341854359908","price":"0.75","size":"722.5","side":"BUY","hash":"e673d1c1530beea2bca2e527a68e55cf91ca673a","best_bid":"0.87","best_ask":"0.88"},{"asset_id":"56386988715176239099720172290594769295756680374928571099138069977179519358166","price":"0.25","size":"722.5","side":"SELL","hash":"c6b95e38ead189b997ac2551e14cf2cb10ce8857","best_bid":"0.12","best_ask":"0.13"}],"timestamp":"1768250236990","event_type":"price_change"}}
{"schema_version":1,"source":"clob_ws_market","recv_ts_ns":1768250237101048422,"event_type":"best_bid_ask","market":"0x2a12fd3d8235c25c062dc9652970ef9f635636c4018df0909e1a51c673e125cb","server_ts_ms":1768250237064,"raw":{"market":"0x2a12fd3d8235c25c062dc9652970ef9f635636c4018df0909e1a51c673e125cb","asset_id":"56386988715176239099720172290594769295756680374928571099138069977179519358166","best_bid":"0.12","best_ask":"0.13","spread":"0.01","timestamp":"1768250237064","event_type":"best_bid_ask"}}
{"schema_version":1,"source":"clob_ws_market","recv_ts_ns":1768250237104609960,"event_type":"price_change","market":"0x2a12fd3d8235c25c062dc9652970ef9f635636c4018df0909e1a51c673e125cb","server_ts_ms":1768250237062,"raw":{"market":"0x2a12fd3d8235c25c062dc9652970ef9f635636c4018df0909e1a51c673e125cb","price_changes":[{"asset_id":"63670753354844494163057275310194312729998307779831462269530137743341854359908","price":"0.87","size":"12.03","side":"BUY","hash":"cdd2ab45b6bebcf18bc2c3433b8db9d169aad8bb","best_bid":"0.87","best_ask":"0.88"},{"asset_id":"56386988715176239099720172290594769295756680374928571099138069977179519358166","price":"0.13","size":"12.03","side":"SELL","hash":"f59ed04ce9aea25936c999416da2c5eb9831dfc5","best_bid":"0.12","best_ask":"0.13"}],"timestamp":"1768250237062","event_type":"price_change"}}
{"schema_version":1,"source":"clob_ws_market","recv_ts_ns":1768250237109068444,"event_type":"book","market":"0x2a12fd3d8235c25c062dc9652970ef9f635636c4018df0909e1a51c673e125cb","server_ts_ms":1768250237062,"raw":{"market":"0x2a12fd3d8235c25c062dc9652970ef9f635636c4018df0909e1a51c673e125cb","asset_id":"56386988715176239099720172290594769295756680374928571099138069977179519358166","bids":[{"price":"0.01","size":"10157.67"},{"price":"0.02","size":"6299.77"},{"price":"0.03","size":"5625.94"},{"price":"0.04","size":"5427"},{"price":"0.05","size":"3442"},{"price":"0.06","size":"1509.5"},{"price":"0.07","size":"1416.28"},{"price":"0.08","size":"1551.75"},{"price":"0.09","size":"1387"},{"price":"0.1","size":"3464.5"},{"price":"0.11","size":"1423.5"},{"price":"0.12","size":"866.35"}],"asks":[{"price":"0.99","size":"10178.95"},{"price":"0.98","size":"5982"},{"price":"0.97","size":"5238.94"},{"price":"0.96","size":"5040"},{"price":"0.95","size":"5050"},{"price":"0.94","size":"5005"},{"price":"0.93","size":"5019.28"},{"price":"0.92","size":"5005"},{"price":"0.91","size":"5005"},{"price":"0.9","size":"5030"},{"price":"0.89","size":"5"},{"price":"0.88","size":"5"},{"price":"0.87","size":"5"},{"price":"0.86","size":"5"},{"price":"0.85","size":"10"},{"price":"0.84","size":"5"},{"price":"0.83","size":"5"},{"price":"0.82","size":"5"},{"price":"0.81","size":"5"},{"price":"0.8","size":"5"},{"price":"0.79","size":"5"},{"price":"0.78","size":"5"},{"price":"0.77","size":"5"},{"price":"0.76","size":"5"},{"price":"0.75","size":"10"},{"price":"0.74","size":"5"},{"price":"0.73","size":"5"},{"price":"0.72","size":"5"},{"price":"0.71","size":"15"},{"price":"0.7","size":"10"},{"price":"0.69","size":"5"},{"price":"0.68","size":"5"},{"price":"0.67","size":"5"},{"price":"0.66","size":"505"},{"price":"0.65","size":"510"},{"price":"0.64","size":"510"},{"price":"0.63","size":"505"},{"price":"0.62","size":"505"},{"price":"0.61","size":"755"},{"price":"0.6","size":"760"},{"price":"0.59","size":"916"},{"price":"0.58","size":"671"},{"price":"0.57","size":"827"},{"price":"0.56","size":"827"},{"price":"0.55","size":"817"},{"price":"0.54","size":"872"},{"price":"0.53","size":"839.65"},{"price":"0.52","size":"829"},{"price":"0.51","size":"817"},{"price":"0.5","size":"838.4"},{"price":"0.49","size":"867.58"},{"price":"0.48","size":"817"},{"price":"0.47","size":"827"},{"price":"0.46","size":"847.8"},{"price":"0.45","size":"836.09"},{"price":"0.44","size":"825"},{"price":"0.43","size":"847"},{"price":"0.42","size":"817"},{"price":"0.41","size":"817"},{"price":"0.4","size":"817"},{"price":"0.39","size":"834.5"},{"price":"0.38","size":"817"},{"price":"0.37","size":"497.49"},{"price":"0.36","size":"817"},{"price":"0.35","size":"872"},{"price":"0.34","size":"906.8"},{"price":"0.33","size":"906.8"},{"price":"0.32","size":"902"},{"price":"0.31","size":"1008.96"},{"price":"0.3","size":"911.6"},{"price":"0.29","size":"897"},{"price":"0.28","size":"899.55"},{"price":"0.27","size":"912"},{"price":"0.26","size":"1270.97"},{"price":"0.25","size":"722.5"},{"price":"0.24","size":"912.05"},{"price":"0.23","size":"748.5"},{"price":"0.22","size":"978.8"},{"price":"0.21","size":"969.5"},{"price":"0.2","size":"920"},{"price":"0.19","size":"798.21"},{"price":"0.18","size":"671"},{"price":"0.17","size":"759.52"},{"price":"0.16","size":"196"},{"price":"0.15","size":"194.99"},{"price":"0.14","size":"1187.63"},{"price":"0.13","size":"12.03"}],"hash":"f59ed04ce9aea25936c999416da2c5eb9831dfc5","timestamp":"1768250237062","event_type":"book"}}
{"schema_version":1,"source":"clob_ws_market","recv_ts_ns":1768250237114498785,"event_type":"price_change","market":"0x2a12fd3d8235c25c062dc9652970ef9f635636c4018df0909e1a51c673e125cb","server_ts_ms":1768250237073,"raw":{"market":"0x2a12fd3d8235c25c062dc9652970ef9f635636c4018df0909e1a51c673e125cb","price_changes":[{"asset_id":"63670753354844494163057275310194312729998307779831462269530137743341854359908","price":"0.85","size":"219.99","side":"BUY","hash":"4c3e94d411deb042608d4c5c6c9d9f9233c120bb","best_bid":"0.87","best_ask":"0.88"},{"asset_id":"56386988715176239099720172290594769295756680374928571099138069977179519358166","price":"0.15","size":"219.99","side":"SELL","hash":"5019ebf4668ee42caa9cab38a60a901fe0ce0a4f","best_bid":"0.12","best_ask":"0.13"}],"timestamp":"1768250237073","event_type":"price_change"}}
{"schema_version":1,"source":"clob_ws_market","recv_ts_ns":1768250237120127941,"event_type":"last_trade_price","market":"0x2a12fd3d8235c25c062dc9652970ef9f635636c4018df0909e1a51c673e125cb","server_ts_ms":1768250237089,"raw":{"market":"0x2a12fd3d8235c25c062dc9652970ef9f635636c4018df0909e1a51c673e125cb","asset_id":"56386988715176239099720172290594769295756680374928571099138069977179519358166","price":"0.13","size":"8.461537","fee_rate_bps":"1000","side":"BUY","timestamp":"1768250237089","event_type":"last_trade_price","transaction_hash":"0xbd56416987762266af4b1d461f90d785a418bd13c3cc47f9b97c765bcf0e92e4"}}
{"schema_version":1,"source":"clob_ws_market","recv_ts_ns":1768250237157844944,"event_type":"price_change","market":"0x2a12fd3d8235c25c062dc9652970ef9f635636c4018df0909e1a51c673e125cb","server_ts_ms":1768250237134,"raw":{"market":"0x2a12fd3d8235c25c062dc9652970ef9f635636c4018df0909e1a51c673e125cb","price_changes":[{"asset_id":"56386988715176239099720172290594769295756680374928571099138069977179519358166","price":"0.06","size":"1492.5","side":"BUY","hash":"dfc299af8c70f39f5b49e05928f1328e3df04d3b","best_bid":"0.12","best_ask":"0.13"},{"asset_id":"63670753354844494163057275310194312729998307779831462269530137743341854359908","price":"0.94","size":"1492.5","side":"SELL","hash":"8be14879a8784dc026c6d79f4151de529efb29e1","best_bid":"0.87","best_ask":"0.88"}],"timestamp":"1768250237134","event_type":"price_change"}}
{"schema_version":1,"source":"clob_ws_market","recv_ts_ns":1768250237205873076,"event_type":"price_change","market":"0x2a12fd3d8235c25c062dc9652970ef9f635636c4018df0909e1a51c673e125cb","server_ts_ms":1768250237167,"raw":{"market":"0x2a12fd3d8235c25c062dc9652970ef9f635636c4018df0909e1a51c673e125cb","price_changes":[{"asset_id":"56386988715176239099720172290594769295756680374928571099138069977179519358166","price":"0.05","size":"3462","side":"BUY","hash":"729db43f24d7d5013ffdf0e6072ea28e5efdb69e","best_bid":"0.12","best_ask":"0.13"},{"asset_id":"63670753354844494163057275310194312729998307779831462269530137743341854359908","price":"0.95","size":"3462","side":"SELL","hash":"d028429fa9f10b815ff9509a37f4151edba59532","best_bid":"0.87","best_ask":"0.88"}],"timestamp":"1768250237167","event_type":"price_change"}}
{"schema_version":1,"source":"clob_ws_market","recv_ts_ns":1768250237240165619,"event_type":"price_change","market":"0x2a12fd3d8235c25c062dc9652970ef9f635636c4018df0909e1a51c673e125cb","server_ts_ms":1768250237209,"raw":{"market":"0x2a12fd3d8235c25c062dc9652970ef9f635636c4018df0909e1a51c673e125cb","price_changes":[{"asset_id":"63670753354844494163057275310194312729998307779831462269530137743341854359908","price":"0.8","size":"914","side":"BUY","hash":"7235182c5316f777ace5dd379a4d80f5d4ab3b67","best_bid":"0.87","best_ask":"0.88"},{"asset_id":"56386988715176239099720172290594769295756680374928571099138069977179519358166","price":"0.2","size":"914","side":"SELL","hash":"eb4301f03215533b69faf3acabb7bf6be2621966","best_bid":"0.12","best_ask":"0.13"}],"timestamp":"1768250237209","event_type":"price_change"}}
{"schema_version":1,"source":"clob_ws_market","recv_ts_ns":1768250237245967467,"event_type":"price_change","market":"0x2a12fd3d8235c25c062dc9652970ef9f635636c4018df0909e1a51c673e125cb","server_ts_ms":1768250237209,"raw":{"market":"0x2a12fd3d8235c25c062dc9652970ef9f635636c4018df0909e1a51c673e125cb","price_changes":[{"asset_id":"63670753354844494163057275310194312729998307779831462269530137743341854359908","price":"0.91","size":"1382","side":"SELL","hash":"7235182c5316f777ace5dd379a4d80f5d4ab3b67","best_bid":"0.87","best_ask":"0.88"},{"asset_id":"56386988715176239099720172290594769295756680374928571099138069977179519358166","price":"0.09","size":"1382","side":"BUY","hash":"eb4301f03215533b69faf3acabb7bf6be2621966","best_bid":"0.12","best_ask":"0.13"}],"timestamp":"1768250237209","event_type":"price_change"}}
{"schema_version":1,"source":"clob_ws_market","recv_ts_ns":1768250237350610575,"event_type":"price_change","market":"0x2a12fd3d8235c25c062dc9652970ef9f635636c4018df0909e1a51c673e125cb","server_ts_ms":1768250237237,"raw":{"market":"0x2a12fd3d8235c25c062dc9652970ef9f635636c4018df0909e1a51c673e125cb","price_changes":[{"asset_id":"63670753354844494163057275310194312729998307779831462269530137743341854359908","price":"0.81","size":"804.21","side":"BUY","hash":"847d9cc4d27129a8a808bbe8dd54c93faf135432","best_bid":"0.87","best_ask":"0.88"},{"asset_id":"56386988715176239099720172290594769295756680374928571099138069977179519358166","price":"0.19","size":"804.21","side":"SELL","hash":"34a63b9e224f011d7722ea48a05fd61fc0403d42","best_bid":"0.12","best_ask":"0.13"}],"timestamp":"1768250237237","event_type":"price_change"}}
{"schema_version":1,"source":"clob_ws_market","recv_ts_ns":1768250237356840251,"event_type":"price_change","market":"0x2a12fd3d8235c25c062dc9652970ef9f635636c4018df0909e1a51c673e125cb","server_ts_ms":1768250237239,"raw":{"market":"0x2a12fd3d8235c25c062dc9652970ef9f635636c4018df0909e1a51c673e125cb","price_changes":[{"asset_id":"63670753354844494163057275310194312729998307779831462269530137743341854359908","price":"0.92","size":"1556.75","side":"SELL","hash":"fc000dee20641dad6d246fcf7b0c1e3d5510850d","best_bid":"0.87","best_ask":"0.88"},{"asset_id":"56386988715176239099720172290594769295756680374928571099138069977179519358166","price":"0.08","size":"1556.75","side":"BUY","hash":"06e7c08dca361e32b7b985a7e32c7036c601afbd","best_bid":"0.12","best_ask":"0.13"}],"timestamp":"1768250237239","event_type":"price_change"}}
{"schema_version":1,"source":"clob_ws_market","recv_ts_ns":1768250237386786676,"event_type":"price_change","market":"0x2a12fd3d8235c25c062dc9652970ef9f635636c4018df0909e1a51c673e125cb","server_ts_ms":1768250237243,"raw":{"market":"0x2a12fd3d8235c25c062dc9652970ef9f635636c4018df0909e1a51c673e125cb","price_changes":[{"asset_id":"56386988715176239099720172290594769295756680374928571099138069977179519358166","price":"0.22","size":"916.9","side":"SELL","hash":"adbecbfdce2edfc176209c7a236661ecdb91060a","best_bid":"0.12","best_ask":"0.13"},{"asset_id":"63670753354844494163057275310194312729998307779831462269530137743341854359908","price":"0.78","size":"916.9","side":"BUY","hash":"f78e255340e7897290acef6af833450472e6a070","best_bid":"0.87","best_ask":"0.88"}],"timestamp":"1768250237243","event_type":"price_change"}}
{"schema_version":1,"source":"clob_ws_market","recv_ts_ns":1768250237504603273,"event_type":"price_change","market":"0x2a12fd3d8235c25c062dc9652970ef9f635636c4018df0909e1a51c673e125cb","server_ts_ms":1768250237303,"raw":{"market":"0x2a12fd3d8235c25c062dc9652970ef9f635636c4018df0909e1a51c673e125cb","price_changes":[{"asset_id":"63670753354844494163057275310194312729998307779831462269530137743341854359908","price":"0.84","size":"696","side":"BUY","hash":"6b7237ba2484f979dd3197ff214f719014db901e","best_bid":"0.87","best_ask":"0.88"},{"asset_id":"56386988715176239099720172290594769295756680374928571099138069977179519358166","price":"0.16","size":"696","side":"SELL","hash":"85c154e2198ebd3a924460020037379be91b6185","best_bid":"0.12","best_ask":"0.13"}],"timestamp":"1768250237303","event_type":"price_change"}}
{"schema_version":1,"source":"clob_ws_market","recv_ts_ns":1768250237509531244,"event_type":"price_change","market":"0x2a12fd3d8235c25c062dc9652970ef9f635636c4018df0909e1a51c673e125cb","server_ts_ms":1768250237314,"raw":{"market":"0x2a12fd3d8235c25c062dc9652970ef9f635636c4018df0909e1a51c673e125cb","price_changes":[{"asset_id":"56386988715176239099720172290594769295756680374928571099138069977179519358166","price":"0.2","size":"975.9","side":"SELL","hash":"1be3b638bddc6ecba933a8335c2b3dda4474e4e8","best_bid":"0.12","best_ask":"0.13"},{"asset_id":"63670753354844494163057275310194312729998307779831462269530137743341854359908","price":"0.8","size":"975.9","side":"BUY","hash":"8df104ea012028076192a81938c7030c4d5ee2eb","best_bid":"0.87","best_ask":"0.88"}],"timestamp":"1768250237314","event_type":"price_change"}}
{"schema_version":1,"source":"clob_ws_market","recv_ts_ns":1768250237520144584,"event_type":"price_change","market":"0x2a12fd3d8235c25c062dc9652970ef9f635636c4018df0909e1a51c673e125cb","server_ts_ms":1768250237342,"raw":{"market":"0x2a12fd3d8235c25c062dc9652970ef9f635636c4018df0909e1a51c673e125cb","price_changes":[{"asset_id":"63670753354844494163057275310194312729998307779831462269530137743341854359908","price":"0.84","size":"196","side":"BUY","hash":"8b0f84b840c9768d62401d6ce564c5470b2a91a4","best_bid":"0.87","best_ask":"0.88"},{"asset_id":"56386988715176239099720172290594769295756680374928571099138069977179519358166","price":"0.16","size":"196","side":"SELL","hash":"a50f56b8dc6cc4c689081d752840e86f0b2ab646","best_bid":"0.12","best_ask":"0.13"}],"timestamp":"1768250237342","event_type":"price_change"}}
{"schema_version":1,"source":"clob_ws_market","recv_ts_ns":1768250237524887772,"event_type":"price_change","market":"0x2a12fd3d8235c25c062dc9652970ef9f635636c4018df0909e1a51c673e125cb","server_ts_ms":1768250237346,"raw":{"market":"0x2a12fd3d8235c25c062dc9652970ef9f635636c4018df0909e1a51c673e125cb","price_changes":[{"asset_id":"63670753354844494163057275310194312729998307779831462269530137743341854359908","price":"0.81","size":"798.21","side":"BUY","hash":"12a8d94ef519390bde7d0039acc9e4516dea182a","best_bid":"0.87","best_ask":"0.88"},{"asset_id":"56386988715176239099720172290594769295756680374928571099138069977179519358166","price":"0.19","size":"798.21","side":"SELL","hash":"088d288c9886615618e463d0579d3bc686fc766a","best_bid":"0.12","best_ask":"0.13"}],"timestamp":"1768250237346","event_type":"price_change"}}
{"schema_version":1,"source":"clob_ws_market","recv_ts_ns":1768250237530134179,"event_type":"price_change","market":"0x2a12fd3d8235c25c062dc9652970ef9f635636c4018df0909e1a51c673e125cb","server_ts_ms":1768250237346,"raw":{"market":"0x2a12fd3d8235c25c062dc9652970ef9f635636c4018df0909e1a51c673e125cb","price_changes":[{"asset_id":"63670753354844494163057275310194312729998307779831462269530137743341854359908","price":"0.92","size":"1551.75","side":"SELL","hash":"12a8d94ef519390bde7d0039acc9e4516dea182a","best_bid":"0.87","best_ask":"0.88"},{"asset_id":"56386988715176239099720172290594769295756680374928571099138069977179519358166","price":"0.08","size":"1551.75","side":"BUY","hash":"088d288c9886615618e463d0579d3bc686fc766a","best_bid":"0.12","best_ask":"0.13"}],"timestamp":"1768250237346","event_type":"price_change"}}
{"schema_version":1,"source":"clob_ws_market","recv_ts_ns":1768250237533956059,"event_type":"price_change","market":"0x2a12fd3d8235c25c062dc9652970ef9f635636c4018df0909e1a51c673e125cb","server_ts_ms":1768250237373,"raw":{"market":"0x2a12fd3d8235c25c062dc9652970ef9f635636c4018df0909e1a51c673e125cb","price_changes":[{"asset_id":"63670753354844494163057275310194312729998307779831462269530137743341854359908","price":"0.91","size":"1387","side":"SELL","hash":"fb353565b0b4f7231767f9918493d316407c99dd","best_bid":"0.87","best_ask":"0.88"},{"asset_id":"56386988715176239099720172290594769295756680374928571099138069977179519358166","price":"0.09","size":"1387","side":"BUY","hash":"c854b9489dc090c5cffde7e87b5eb992cdfc777f","best_bid":"0.12","best_ask":"0.13"}],"timestamp":"1768250237373","event_type":"price_change"}}
{"schema_version":1,"source":"clob_ws_market","recv_ts_ns":1768250237537464751,"event_type":"price_change","market":"0x2a12fd3d8235c25c062dc9652970ef9f635636c4018df0909e1a51c673e125cb","server_ts_ms":1768250237373,"raw":{"market":"0x2a12fd3d8235c25c062dc9652970ef9f635636c4018df0909e1a51c673e125cb","price_changes":[{"asset_id":"63670753354844494163057275310194312729998307779831462269530137743341854359908","price":"0.8","size":"981.9","side":"BUY","hash":"bed86dae88b6b83e59fcfbd9dbaa750c254bec95","best_bid":"0.87","best_ask":"0.88"},{"asset_id":"56386988715176239099720172290594769295756680374928571099138069977179519358166","price":"0.2","size":"981.9","side":"SELL","hash":"b89dafeb6339102b3f132f1c43038b29178befeb","best_bid":"0.12","best_ask":"0.13"}],"timestamp":"1768250237373","event_type":"price_change"}}
{"schema_version":1,"source":"clob_ws_market","recv_ts_ns":1768250237546804998,"event_type":"price_change","market":"0x2a12fd3d8235c25c062dc9652970ef9f635636c4018df0909e1a51c673e125cb","server_ts_ms":1768250237415,"raw":{"market":"0x2a12fd3d8235c25c062dc9652970ef9f635636c4018df0909e1a51c673e125cb","price_changes":[{"asset_id":"63670753354844494163057275310194312729998307779831462269530137743341854359908","price":"0.87","size":"10","side":"BUY","hash":"c88ef2cea79addc9d5b2ad98d5a4c8f567c6f5c5","best_bid":"0.87","best_ask":"0.88"},{"asset_id":"56386988715176239099720172290594769295756680374928571099138069977179519358166","price":"0.13","size":"10","side":"SELL","hash":"66cce531779fd2fa6668284f2989f90395ac5c8d","best_bid":"0.12","best_ask":"0.13"}],"timestamp":"1768250237415","event_type":"price_change"}}
{"schema_version":1,"source":"clob_ws_market","recv_ts_ns":1768250237617728634,"event_type":"price_change","market":"0x2a12fd3d8235c25c062dc9652970ef9f635636c4018df0909e1a51c673e125cb","server_ts_ms":1768250237537,"raw":{"market":"0x2a12fd3d8235c25c062dc9652970ef9f635636c4018df0909e1a51c673e125cb","price_changes":[{"asset_id":"63670753354844494163057275310194312729998307779831462269530137743341854359908","price":"0.84","size":"696","side":"BUY","hash":"f6c6f8234fa46097ec36a81f00d80b56af632829","best_bid":"0.87","best_ask":"0.88"},{"asset_id":"56386988715176239099720172290594769295756680374928571099138069977179519358166","price":"0.16","size":"696","side":"SELL","hash":"55167447fc3f8173885b7e028e22eae175e6a778","best_bid":"0.12","best_ask":"0.13"}],"timestamp":"1768250237537","event_type":"price_change"}}
{"schema_version":1,"source":"clob_ws_market","recv_ts_ns":1768250237913281788,"event_type":"best_bid_ask","market":"0x2a12fd3d8235c25c062dc9652970ef9f635636c4018df0909e1a51c673e125cb","server_ts_ms":1768250237876,"raw":{"market":"0x2a12fd3d8235c25c062dc9652970ef9f635636c4018df0909e1a51c673e125cb","asset_id":"56386988715176239099720172290594769295756680374928571099138069977179519358166","best_bid":"0.12","best_ask":"0.13","spread":"0.01","timestamp":"1768250237876","event_type":"best_bid_ask"}}
{"schema_version":1,"source":"clob_ws_market","recv_ts_ns":1768250237918552625,"event_type":"price_change","market":"0x2a12fd3d8235c25c062dc9652970ef9f635636c4018df0909e1a51c673e125cb","server_ts_ms":1768250237872,"raw":{"market":"0x2a12fd3d8235c25c062dc9652970ef9f635636c4018df0909e1a51c673e125cb","price_changes":[{"asset_id":"56386988715176239099720172290594769295756680374928571099138069977179519358166","price":"0.12","size":"854.48","side":"BUY","hash":"2f801e7c113aca5ae2d2338f1f82d2049756c734","best_bid":"0.12","best_ask":"0.13"},{"asset_id":"63670753354844494163057275310194312729998307779831462269530137743341854359908","price":"0.88","size":"854.48","side":"SELL","hash":"4df67465471e781d1887237b4456f3a87fb9fc70","best_bid":"0.87","best_ask":"0.88"}],"timestamp":"1768250237872","event_type":"price_change"}}
{"schema_version":1,"source":"clob_ws_market","recv_ts_ns":1768250237923374704,"event_type":"book","market":"0x2a12fd3d8235c25c062dc9652970ef9f635636c4018df0909e1a51c673e125cb","server_ts_ms":1768250237872,"raw":{"market":"0x2a12fd3d8235c25c062dc9652970ef9f635636c4018df0909e1a51c673e125cb","asset_id":"56386988715176239099720172290594769295756680374928571099138069977179519358166","bids":[{"price":"0.01","size":"10157.67"},{"price":"0.02","size":"6299.77"},{"price":"0.03","size":"5625.94"},{"price":"0.04","size":"5427"},{"price":"0.05","size":"3462"},{"price":"0.06","size":"1492.5"},{"price":"0.07","size":"1416.28"},{"price":"0.08","size":"1551.75"},{"price":"0.09","size":"1387"},{"price":"0.1","size":"3464.5"},{"price":"0.11","size":"1423.5"},{"price":"0.12","size":"854.48"}],"asks":[{"price":"0.99","size":"10178.95"},{"price":"0.98","size":"5982"},{"price":"0.97","size":"5238.94"},{"price":"0.96","size":"5040"},{"price":"0.95","size":"5050"},{"price":"0.94","size":"5005"},{"price":"0.93","size":"5019.28"},{"price":"0.92","size":"5005"},{"price":"0.91","size":"5005"},{"price":"0.9","size":"5030"},{"price":"0.89","size":"5"},{"price":"0.88","size":"5"},{"price":"0.87","size":"5"},{"price":"0.86","size":"5"},{"price":"0.85","size":"10"},{"price":"0.84","size":"5"},{"price":"0.83","size":"5"},{"price":"0.82","size":"5"},{"price":"0.81","size":"5"},{"price":"0.8","size":"5"},{"price":"0.79","size":"5"},{"price":"0.78","size":"5"},{"price":"0.77","size":"5"},{"price":"0.76","size":"5"},{"price":"0.75","size":"10"},{"price":"0.74","size":"5"},{"price":"0.73","size":"5"},{"price":"0.72","size":"5"},{"price":"0.71","size":"15"},{"price":"0.7","size":"10"},{"price":"0.69","size":"5"},{"price":"0.68","size":"5"},{"price":"0.67","size":"5"},{"price":"0.66","size":"505"},{"price":"0.65","size":"510"},{"price":"0.64","size":"510"},{"price":"0.63","size":"505"},{"price":"0.62","size":"505"},{"price":"0.61","size":"755"},{"price":"0.6","size":"760"},{"price":"0.59","size":"916"},{"price":"0.58","size":"671"},{"price":"0.57","size":"827"},{"price":"0.56","size":"827"},{"price":"0.55","size":"817"},{"price":"0.54","size":"872"},{"price":"0.53","size":"839.65"},{"price":"0.52","size":"829"},{"price":"0.51","size":"817"},{"price":"0.5","size":"838.4"},{"price":"0.49","size":"867.58"},{"price":"0.48","size":"817"},{"price":"0.47","size":"827"},{"price":"0.46","size":"847.8"},{"price":"0.45","size":"836.09"},{"price":"0.44","size":"825"},{"price":"0.43","size":"847"},{"price":"0.42","size":"817"},{"price":"0.41","size":"817"},{"price":"0.4","size":"817"},{"price":"0.39","size":"834.5"},{"price":"0.38","size":"817"},{"price":"0.37","size":"497.49"},{"price":"0.36","size":"817"},{"price":"0.35","size":"872"},{"price":"0.34","size":"906.8"},{"price":"0.33","size":"906.8"},{"price":"0.32","size":"902"},{"price":"0.31","size":"1008.96"},{"price":"0.3","size":"911.6"},{"price":"0.29","size":"897"},{"price":"0.28","size":"899.55"},{"price":"0.27","size":"912"},{"price":"0.26","size":"1270.97"},{"price":"0.25","size":"722.5"},{"price":"0.24","size":"912.05"},{"price":"0.23","size":"748.5"},{"price":"0.22","size":"916.9"},{"price":"0.21","size":"969.5"},{"price":"0.2","size":"981.9"},{"price":"0.19","size":"798.21"},{"price":"0.18","size":"671"},{"price":"0.17","size":"759.52"},{"price":"0.16","size":"696"},{"price":"0.15","size":"219.99"},{"price":"0.14","size":"1187.63"},{"price":"0.13","size":"10"}],"hash":"2f801e7c113aca5ae2d2338f1f82d2049756c734","timestamp":"1768250237872","event_type":"book"}}
{"schema_version":1,"source":"clob_ws_market","recv_ts_ns":1768250238121467321,"event_type":"price_change","market":"0x2a12fd3d8235c25c062dc9652970ef9f635636c4018df0909e1a51c673e125cb","server_ts_ms":1768250238006,"raw":{"market":"0x2a12fd3d8235c25c062dc9652970ef9f635636c4018df0909e1a51c673e125cb","price_changes":[{"asset_id":"56386988715176239099720172290594769295756680374928571099138069977179519358166","price":"0.12","size":"859.48","side":"BUY","hash":"7b8585825260e76e60d5fede91f3900de3163bdf","best_bid":"0.12","best_ask":"0.13"},{"asset_id":"63670753354844494163057275310194312729998307779831462269530137743341854359908","price":"0.88","size":"859.48","side":"SELL","hash":"fba11ae23bec952f72bc9a3af0d7c7b1b5d1a22c","best_bid":"0.87","best_ask":"0.88"}],"timestamp":"1768250238006","event_type":"price_change"}}
{"schema_version":1,"source":"clob_ws_market","recv_ts_ns":1768250238164646915,"event_type":"price_change","market":"0x2a12fd3d8235c25c062dc9652970ef9f635636c4018df0909e1a51c673e125cb","server_ts_ms":1768250238121,"raw":{"market":"0x2a12fd3d8235c25c062dc9652970ef9f635636c4018df0909e1a51c673e125cb","price_changes":[{"asset_id":"56386988715176239099720172290594769295756680374928571099138069977179519358166","price":"0.12","size":"864.48","side":"BUY","hash":"6b589114c8a24bd58741f16e3e08d63bc26fc037","best_bid":"0.12","best_ask":"0.13"},{"asset_id":"63670753354844494163057275310194312729998307779831462269530137743341854359908","price":"0.88","size":"864.48","side":"SELL","hash":"736198e7cf00ebb53ff13ee6a92a55f11749d215","best_bid":"0.87","best_ask":"0.88"}],"timestamp":"1768250238121","event_type":"price_change"}}
{"schema_version":1,"source":"clob_ws_market","recv_ts_ns":1768250238178294544,"event_type":"price_change","market":"0x2a12fd3d8235c25c062dc9652970ef9f635636c4018df0909e1a51c673e125cb","server_ts_ms":1768250238148,"raw":{"market":"0x2a12fd3d8235c25c062dc9652970ef9f635636c4018df0909e1a51c673e125cb","price_changes":[{"asset_id":"63670753354844494163057275310194312729998307779831462269530137743341854359908","price":"0.87","size":"410","side":"BUY","hash":"b1d27374bd19eebacc996bdb6664115e3bc264b2","best_bid":"0.87","best_ask":"0.88"},{"asset_id":"56386988715176239099720172290594769295756680374928571099138069977179519358166","price":"0.13","size":"410","side":"SELL","hash":"ae61ed4e04e13c23ea2a33bba6a1101230933c85","best_bid":"0.12","best_ask":"0.13"}],"timestamp":"1768250238148","event_type":"price_change"}}
{"schema_version":1,"source":"clob_ws_market","recv_ts_ns":1768250238193718169,"event_type":"price_change","market":"0x2a12fd3d8235c25c062dc9652970ef9f635636c4018df0909e1a51c673e125cb","server_ts_ms":1768250238168,"raw":{"market":"0x2a12fd3d8235c25c062dc9652970ef9f635636c4018df0909e1a51c673e125cb","price_changes":[{"asset_id":"63670753354844494163057275310194312729998307779831462269530137743341854359908","price":"0.86","size":"1338.63","side":"BUY","hash":"26d40daeaa644c70308de54151c8da6d477b5ce6","best_bid":"0.87","best_ask":"0.88"},{"asset_id":"56386988715176239099720172290594769295756680374928571099138069977179519358166","price":"0.14","size":"1338.63","side":"SELL","hash":"be5eb49781dabe1db387105eaeb175bf01752ba6","best_bid":"0.12","best_ask":"0.13"}],"timestamp":"1768250238168","event_type":"price_change"}}
{"schema_version":1,"source":"clob_ws_market","recv_ts_ns":1768250238354352622,"event_type":"price_change","market":"0x2a12fd3d8235c25c062dc9652970ef9f635636c4018df0909e1a51c673e125cb","server_ts_ms":1768250238333,"raw":{"market":"0x2a12fd3d8235c25c062dc9652970ef9f635636c4018df0909e1a51c673e125cb","price_changes":[{"asset_id":"56386988715176239099720172290594769295756680374928571099138069977179519358166","price":"0.05","size":"3442","side":"BUY","hash":"ef1605a18dabbe5cc9e3ceca9010bb58fcf7555a","best_bid":"0.12","best_ask":"0.13"},{"asset_id":"63670753354844494163057275310194312729998307779831462269530137743341854359908","price":"0.95","size":"3442","side":"SELL","hash":"65c4548e699c39a9f361c3eefd88af6e8b433fe0","best_bid":"0.87","best_ask":"0.88"}],"timestamp":"1768250238333","event_type":"price_change"}}
{"schema_version":1,"source":"clob_ws_market","recv_ts_ns":1768250238376574699,"event_type":"price_change","market":"0x2a12fd3d8235c25c062dc9652970ef9f635636c4018df0909e1a51c673e125cb","server_ts_ms":1768250238351,"raw":{"market":"0x2a12fd3d8235c25c062dc9652970ef9f635636c4018df0909e1a51c673e125cb","price_changes":[{"asset_id":"63670753354844494163057275310194312729998307779831462269530137743341854359908","price":"0.85","size":"194.99","side":"BUY","hash":"d5b3380d0236f6706034c8f0a1d6bebf61518dda","best_bid":"0.87","best_ask":"0.88"},{"asset_id":"56386988715176239099720172290594769295756680374928571099138069977179519358166","price":"0.15","size":"194.99","side":"SELL","hash":"6f102357e8f8532d2dff5ae989731282e495d306","best_bid":"0.12","best_ask":"0.13"}],"timestamp":"1768250238351","event_type":"price_change"}}
{"schema_version":1,"source":"clob_ws_market","recv_ts_ns":1768250238387841488,"event_type":"price_change","market":"0x2a12fd3d8235c25c062dc9652970ef9f635636c4018df0909e1a51c673e125cb","server_ts_ms":1768250238363,"raw":{"market":"0x2a12fd3d8235c25c062dc9652970ef9f635636c4018df0909e1a51c673e125cb","price_changes":[{"asset_id":"56386988715176239099720172290594769295756680374928571099138069977179519358166","price":"0.04","size":"5452","side":"BUY","hash":"3698e0ab1698124d88eeaf8fe09985f9f81bd6d4","best_bid":"0.12","best_ask":"0.13"},{"asset_id":"63670753354844494163057275310194312729998307779831462269530137743341854359908","price":"0.96","size":"5452","side":"SELL","hash":"5c2eebbe9d188cf89bc526514463c8d006d4279e","best_bid":"0.87","best_ask":"0.88"}],"timestamp":"1768250238363","event_type":"price_change"}}
{"schema_version":1,"source":"clob_ws_market","recv_ts_ns":1768250238476572743,"event_type":"price_change","market":"0x2a12fd3d8235c25c062dc9652970ef9f635636c4018df0909e1a51c673e125cb","server_ts_ms":1768250238448,"raw":{"market":"0x2a12fd3d8235c25c062dc9652970ef9f635636c4018df0909e1a51c673e125cb","price_changes":[{"asset_id":"63670753354844494163057275310194312729998307779831462269530137743341854359908","price":"0.84","size":"196","side":"BUY","hash":"ea7d94af31844ccd39988275b96d4ebfffc7dba9","best_bid":"0.87","best_ask":"0.88"},{"asset_id":"56386988715176239099720172290594769295756680374928571099138069977179519358166","price":"0.16","size":"196","side":"SELL","hash":"d0a553a4585d1ae7124386c000c55fb3cc707359","best_bid":"0.12","best_ask":"0.13"}],"timestamp":"1768250238448","event_type":"price_change"}}
{"schema_version":1,"source":"clob_ws_market","recv_ts_ns":1768250238500552498,"event_type":"price_change","market":"0x2a12fd3d8235c25c062dc9652970ef9f635636c4018df0909e1a51c673e125cb","server_ts_ms":1768250238476,"raw":{"market":"0x2a12fd3d8235c25c062dc9652970ef9f635636c4018df0909e1a51c673e125cb","price_changes":[{"asset_id":"63670753354844494163057275310194312729998307779831462269530137743341854359908","price":"0.86","size":"1333.13","side":"BUY","hash":"0ab16b50dfbf4adffa3330fcd8f3ec4be0cd5b5f","best_bid":"0.87","best_ask":"0.88"},{"asset_id":"56386988715176239099720172290594769295756680374928571099138069977179519358166","price":"0.14","size":"1333.13","side":"SELL","hash":"5fbc7cac7da6e94f4872327293cb2978ff368652","best_bid":"0.12","best_ask":"0.13"}],"timestamp":"1768250238476","event_type":"price_change"}}
{"schema_version":1,"source":"clob_ws_market","recv_ts_ns":1768250238563201085,"event_type":"price_change","market":"0x2a12fd3d8235c25c062dc9652970ef9f635636c4018df0909e1a51c673e125cb","server_ts_ms":1768250238527,"raw":{"market":"0x2a12fd3d8235c25c062dc9652970ef9f635636c4018df0909e1a51c673e125cb","price_changes":[{"asset_id":"63670753354844494163057275310194312729998307779831462269530137743341854359908","price":"0.87","size":"415.5","side":"BUY","hash":"bd3db06ef53cf07cf25385a40fef0618220a0c9c","best_bid":"0.87","best_ask":"0.88"},{"asset_id":"56386988715176239099720172290594769295756680374928571099138069977179519358166","price":"0.13","size":"415.5","side":"SELL","hash":"3b51b321bf02fd58957b759bdf830fb00c2575b8","best_bid":"0.12","best_ask":"0.13"}],"timestamp":"1768250238527","event_type":"price_change"}}
{"schema_version":1,"source":"clob_ws_market","recv_ts_ns":1768250238592967156,"event_type":"best_bid_ask","market":"0x2a12fd3d8235c25c062dc9652970ef9f635636c4018df0909e1a51c673e125cb","server_ts_ms":1768250238562,"raw":{"market":"0x2a12fd3d8235c25c062dc9652970ef9f635636c4018df0909e1a51c673e125cb","asset_id":"56386988715176239099720172290594769295756680374928571099138069977179519358166","best_bid":"0.12","best_ask":"0.13","spread":"0.01","timestamp":"1768250238562","event_type":"best_bid_ask"}}
{"schema_version":1,"source":"clob_ws_market","recv_ts_ns":1768250238598145241,"event_type":"price_change","market":"0x2a12fd3d8235c25c062dc9652970ef9f635636c4018df0909e1a51c673e125cb","server_ts_ms":1768250238560,"raw":{"market":"0x2a12fd3d8235c25c062dc9652970ef9f635636c4018df0909e1a51c673e125cb","price_changes":[{"asset_id":"56386988715176239099720172290594769295756680374928571099138069977179519358166","price":"0.12","size":"863.25","side":"BUY","hash":"f42bfcd7f095873f43d006771f35fb24cb0fe0b1","best_bid":"0.12","best_ask":"0.13"},{"asset_id":"63670753354844494163057275310194312729998307779831462269530137743341854359908","price":"0.88","size":"863.25","side":"SELL","hash":"72b2dc6c7fd04a1a4635d3d3b53f27b2061bc684","best_bid":"0.87","best_ask":"0.88"}],"timestamp":"1768250238560","event_type":"price_change"}}
{"schema_version":1,"source":"clob_ws_market","recv_ts_ns":1768250238603942819,"event_type":"book","market":"0x2a12fd3d8235c25c062dc9652970ef9f635636c4018df0909e1a51c673e125cb","server_ts_ms":1768250238560,"raw":{"market":"0x2a12fd3d8235c25c062dc9652970ef9f635636c4018df0909e1a51c673e125cb","asset_id":"56386988715176239099720172290594769295756680374928571099138069977179519358166","bids":[{"price":"0.01","size":"10157.67"},{"price":"0.02","size":"6299.77"},{"price":"0.03","size":"5625.94"},{"price":"0.04","size":"5452"},{"price":"0.05","size":"3442"},{"price":"0.06","size":"1492.5"},{"price":"0.07","size":"1416.28"},{"price":"0.08","size":"1551.75"},{"price":"0.09","size":"1387"},{"price":"0.1","size":"3464.5"},{"price":"0.11","size":"1423.5"},{"price":"0.12","size":"863.25"}],"asks":[{"price":"0.99","size":"10178.95"},{"price":"0.98","size":"5982"},{"price":"0.97","size":"5238.94"},{"price":"0.96","size":"5040"},{"price":"0.95","size":"5050"},{"price":"0.94","size":"5005"},{"price":"0.93","size":"5019.28"},{"price":"0.92","size":"5005"},{"price":"0.91","size":"5005"},{"price":"0.9","size":"5030"},{"price":"0.89","size":"5"},{"price":"0.88","size":"5"},{"price":"0.87","size":"5"},{"price":"0.86","size":"5"},{"price":"0.85","size":"10"},{"price":"0.84","size":"5"},{"price":"0.83","size":"5"},{"price":"0.82","size":"5"},{"price":"0.81","size":"5"},{"price":"0.8","size":"5"},{"price":"0.79","size":"5"},{"price":"0.78","size":"5"},{"price":"0.77","size":"5"},{"price":"0.76","size":"5"},{"price":"0.75","size":"10"},{"price":"0.74","size":"5"},{"price":"0.73","size":"5"},{"price":"0.72","size":"5"},{"price":"0.71","size":"15"},{"price":"0.7","size":"10"},{"price":"0.69","size":"5"},{"price":"0.68","size":"5"},{"price":"0.67","size":"5"},{"price":"0.66","size":"505"},{"price":"0.65","size":"510"},{"price":"0.64","size":"510"},{"price":"0.63","size":"505"},{"price":"0.62","size":"505"},{"price":"0.61","size":"755"},{"price":"0.6","size":"760"},{"price":"0.59","size":"916"},{"price":"0.58","size":"671"},{"price":"0.57","size":"827"},{"price":"0.56","size":"827"},{"price":"0.55","size":"817"},{"price":"0.54","size":"872"},{"price":"0.53","size":"839.65"},{"price":"0.52","size":"829"},{"price":"0.51","size":"817"},{"price":"0.5","size":"838.4"},{"price":"0.49","size":"867.58"},{"price":"0.48","size":"817"},{"price":"0.47","size":"827"},{"price":"0.46","size":"847.8"},{"price":"0.45","size":"836.09"},{"price":"0.44","size":"825"},{"price":"0.43","size":"847"},{"price":"0.42","size":"817"},{"price":"0.41","size":"817"},{"price":"0.4","size":"817"},{"price":"0.39","size":"834.5"},{"price":"0.38","size":"817"},{"price":"0.37","size":"497.49"},{"price":"0.36","size":"817"},{"price":"0.35","size":"872"},{"price":"0.34","size":"906.8"},{"price":"0.33","size":"906.8"},{"price":"0.32","size":"902"},{"price":"0.31","size":"1008.96"},{"price":"0.3","size":"911.6"},{"price":"0.29","size":"897"},{"price":"0.28","size":"899.55"},{"price":"0.27","size":"912"},{"price":"0.26","size":"1270.97"},{"price":"0.25","size":"722.5"},{"price":"0.24","size":"912.05"},{"price":"0.23","size":"748.5"},{"price":"0.22","size":"916.9"},{"price":"0.21","size":"969.5"},{"price":"0.2","size":"981.9"},{"price":"0.19","size":"798.21"},{"price":"0.18","size":"671"},{"price":"0.17","size":"759.52"},{"price":"0.16","size":"196"},{"price":"0.15","size":"194.99"},{"price":"0.14","size":"1333.13"},{"price":"0.13","size":"415.5"}],"hash":"f42bfcd7f095873f43d006771f35fb24cb0fe0b1","timestamp":"1768250238560","event_type":"book"}}
{"schema_version":1,"source":"clob_ws_market","recv_ts_ns":1768250238608747344,"event_type":"price_change","market":"0x2a12fd3d8235c25c062dc9652970ef9f635636c4018df0909e1a51c673e125cb","server_ts_ms":1768250238562,"raw":{"market":"0x2a12fd3d8235c25c062dc9652970ef9f635636c4018df0909e1a51c673e125cb","price_changes":[{"asset_id":"63670753354844494163057275310194312729998307779831462269530137743341854359908","price":"0.88","size":"878.25","side":"SELL","hash":"1247d250e8f8fa43969315dd945ac404682b1bd2","best_bid":"0.87","best_ask":"0.88"},{"asset_id":"56386988715176239099720172290594769295756680374928571099138069977179519358166","price":"0.12","size":"878.25","side":"BUY","hash":"7a3e73d85b6f37b7404e3c7e2027a492384d6b1c","best_bid":"0.12","best_ask":"0.13"}],"timestamp":"1768250238562","event_type":"price_change"}}
{"schema_version":1,"source":"clob_ws_market","recv_ts_ns":1768250238611800693,"event_type":"price_change","market":"0x2a12fd3d8235c25c062dc9652970ef9f635636c4018df0909e1a51c673e125cb","server_ts_ms":1768250238563,"raw":{"market":"0x2a12fd3d8235c25c062dc9652970ef9f635636c4018df0909e1a51c673e125cb","price_changes":[{"asset_id":"63670753354844494163057275310194312729998307779831462269530137743341854359908","price":"0.87","size":"410","side":"BUY","hash":"01a1ceac73f1ddc84b9a776fea958281b9d3bd2d","best_bid":"0.87","best_ask":"0.88"},{"asset_id":"56386988715176239099720172290594769295756680374928571099138069977179519358166","price":"0.13","size":"410","side":"SELL","hash":"4fe0484157000cb5de9c2dc1c24ef6debe5dd3f2","best_bid":"0.12","best_ask":"0.13"}],"timestamp":"1768250238563","event_type":"price_change"}}
{"schema_version":1,"source":"clob_ws_market","recv_ts_ns":1768250238625051505,"event_type":"price_change","market":"0x2a12fd3d8235c25c062dc9652970ef9f635636c4018df0909e1a51c673e125cb","server_ts_ms":1768250238600,"raw":{"market":"0x2a12fd3d8235c25c062dc9652970ef9f635636c4018df0909e1a51c673e125cb","price_changes":[{"asset_id":"63670753354844494163057275310194312729998307779831462269530137743341854359908","price":"0.86","size":"1338.63","side":"BUY","hash":"3d8ade05c24b58d37b919ed6ad447f421bfff913","best_bid":"0.87","best_ask":"0.88"},{"asset_id":"56386988715176239099720172290594769295756680374928571099138069977179519358166","price":"0.14","size":"1338.63","side":"SELL","hash":"3da635d41f37fe7beb0855d82be8285d555db3ac","best_bid":"0.12","best_ask":"0.13"}],"timestamp":"1768250238600","event_type":"price_change"}}
{"schema_version":1,"source":"clob_ws_market","recv_ts_ns":1768250238789024947,"event_type":"price_change","market":"0x2a12fd3d8235c25c062dc9652970ef9f635636c4018df0909e1a51c673e125cb","server_ts_ms":1768250238741,"raw":{"market":"0x2a12fd3d8235c25c062dc9652970ef9f635636c4018df0909e1a51c673e125cb","price_changes":[{"asset_id":"63670753354844494163057275310194312729998307779831462269530137743341854359908","price":"0.83","size":"669.52","side":"BUY","hash":"373d3de8e467fd77499bf2fd18d5ee371a43015b","best_bid":"0.87","best_ask":"0.88"},{"asset_id":"56386988715176239099720172290594769295756680374928571099138069977179519358166","price":"0.17","size":"669.52","side":"SELL","hash":"b55be9338e231030edc7b5f48d0af62880233964","best_bid":"0.12","best_ask":"0.13"}],"timestamp":"1768250238741","event_type":"price_change"}}
{"schema_version":1,"source":"clob_ws_market","recv_ts_ns":1768250238870157937,"event_type":"price_change","market":"0x2a12fd3d8235c25c062dc9652970ef9f635636c4018df0909e1a51c673e125cb","server_ts_ms":1768250238848,"raw":{"market":"0x2a12fd3d8235c25c062dc9652970ef9f635636c4018df0909e1a51c673e125cb","price_changes":[{"asset_id":"63670753354844494163057275310194312729998307779831462269530137743341854359908","price":"0.88","size":"863.25","side":"SELL","hash":"d41c88c51f5d61f66e348536563fdf76266c5fc5","best_bid":"0.87","best_ask":"0.88"},{"asset_id":"56386988715176239099720172290594769295756680374928571099138069977179519358166","price":"0.12","size":"863.25","side":"BUY","hash":"9c36168231b8c8bd37aff691645e94cdb3f13f5a","best_bid":"0.12","best_ask":"0.13"}],"timestamp":"1768250238848","event_type":"price_change"}}
{"schema_version":1,"source":"clob_ws_market","recv_ts_ns":1768250238878859297,"event_type":"price_change","market":"0x2a12fd3d8235c25c062dc9652970ef9f635636c4018df0909e1a51c673e125cb","server_ts_ms":1768250238857,"raw":{"market":"0x2a12fd3d8235c25c062dc9652970ef9f635636c4018df0909e1a51c673e125cb","price_changes":[{"asset_id":"63670753354844494163057275310194312729998307779831462269530137743341854359908","price":"0.86","size":"1187.63","side":"BUY","hash":"82561bdcc98e22addee1d143e0301690a464210a","best_bid":"0.87","best_ask":"0.88"},{"asset_id":"56386988715176239099720172290594769295756680374928571099138069977179519358166","price":"0.14","size":"1187.63","side":"SELL","hash":"fa549b72f58a0a00df57216d60103fb1b3fa31fd","best_bid":"0.12","best_ask":"0.13"}],"timestamp":"1768250238857","event_type":"price_change"}}
{"schema_version":1,"source":"clob_ws_market","recv_ts_ns":1768250238995880528,"event_type":"price_change","market":"0x2a12fd3d8235c25c062dc9652970ef9f635636c4018df0909e1a51c673e125cb","server_ts_ms":1768250238968,"raw":{"market":"0x2a12fd3d8235c25c062dc9652970ef9f635636c4018df0909e1a51c673e125cb","price_changes":[{"asset_id":"63670753354844494163057275310194312729998307779831462269530137743341854359908","price":"0.82","size":"761","side":"BUY","hash":"240b1b7f4553d97f81da7c1af4b10a0ca19e7d30","best_bid":"0.87","best_ask":"0.88"},{"asset_id":"56386988715176239099720172290594769295756680374928571099138069977179519358166","price":"0.18","size":"761","side":"SELL","hash":"674f878727cab9d80efc82ddd4ce6d1cfe685fe6","best_bid":"0.12","best_ask":"0.13"}],"timestamp":"1768250238968","event_type":"price_change"}}
{"schema_version":1,"source":"clob_ws_market","recv_ts_ns":1768250239020265695,"event_type":"best_bid_ask","market":"0x2a12fd3d8235c25c062dc9652970ef9f635636c4018df0909e1a51c673e125cb","server_ts_ms":1768250238991,"raw":{"market":"0x2a12fd3d8235c25c062dc9652970ef9f635636c4018df0909e1a51c673e125cb","asset_id":"56386988715176239099720172290594769295756680374928571099138069977179519358166","best_bid":"0.12","best_ask":"0.13","spread":"0.01","timestamp":"1768250238991","event_type":"best_bid_ask"}}
{"schema_version":1,"source":"clob_ws_market","recv_ts_ns":1768250239024489231,"event_type":"price_change","market":"0x2a12fd3d8235c25c062dc9652970ef9f635636c4018df0909e1a51c673e125cb","server_ts_ms":1768250238989,"raw":{"market":"0x2a12fd3d8235c25c062dc9652970ef9f635636c4018df0909e1a51c673e125cb","price_changes":[{"asset_id":"63670753354844494163057275310194312729998307779831462269530137743341854359908","price":"0.87","size":"401.53","side":"BUY","hash":"45aa32ba6dc19bef155b8249d818c54b45a474f7","best_bid":"0.87","best_ask":"0.88"},{"asset_id":"56386988715176239099720172290594769295756680374928571099138069977179519358166","price":"0.13","size":"401.53","side":"SELL","hash":"0340b868950265ba7d71ac6c9d131e6d14738f96","best_bid":"0.12","best_ask":"0.13"}],"timestamp":"1768250238989","event_type":"price_change"}}
{"schema_version":1,"source":"clob_ws_market","recv_ts_ns":1768250239028367857,"event_type":"book","market":"0x2a12fd3d8235c25c062dc9652970ef9f635636c4018df0909e1a51c673e125cb","server_ts_ms":1768250238989,"raw":{"market":"0x2a12fd3d8235c25c062dc9652970ef9f635636c4018df0909e1a51c673e125cb","asset_id":"56386988715176239099720172290594769295756680374928571099138069977179519358166","bids":[{"price":"0.01","size":"10157.67"},{"price":"0.02","size":"6299.77"},{"price":"0.03","size":"5625.94"},{"price":"0.04","size":"5452"},{"price":"0.05","size":"3442"},{"price":"0.06","size":"1492.5"},{"price":"0.07","size":"1416.28"},{"price":"0.08","size":"1551.75"},{"price":"0.09","size":"1387"},{"price":"0.1","size":"3464.5"},{"price":"0.11","size":"1423.5"},{"price":"0.12","size":"863.25"}],"asks":[{"price":"0.99","size":"10178.95"},{"price":"0.98","size":"5982"},{"price":"0.97","size":"5238.94"},{"price":"0.96","size":"5040"},{"price":"0.95","size":"5050"},{"price":"0.94","size":"5005"},{"price":"0.93","size":"5019.28"},{"price":"0.92","size":"5005"},{"price":"0.91","size":"5005"},{"price":"0.9","size":"5030"},{"price":"0.89","size":"5"},{"price":"0.88","size":"5"},{"price":"0.87","size":"5"},{"price":"0.86","size":"5"},{"price":"0.85","size":"10"},{"price":"0.84","size":"5"},{"price":"0.83","size":"5"},{"price":"0.82","size":"5"},{"price":"0.81","size":"5"},{"price":"0.8","size":"5"},{"price":"0.79","size":"5"},{"price":"0.78","size":"5"},{"price":"0.77","size":"5"},{"price":"0.76","size":"5"},{"price":"0.75","size":"10"},{"price":"0.74","size":"5"},{"price":"0.73","size":"5"},{"price":"0.72","size":"5"},{"price":"0.71","size":"15"},{"price":"0.7","size":"10"},{"price":"0.69","size":"5"},{"price":"0.68","size":"5"},{"price":"0.67","size":"5"},{"price":"0.66","size":"505"},{"price":"0.65","size":"510"},{"price":"0.64","size":"510"},{"price":"0.63","size":"505"},{"price":"0.62","size":"505"},{"price":"0.61","size":"755"},{"price":"0.6","size":"760"},{"price":"0.59","size":"916"},{"price":"0.58","size":"671"},{"price":"0.57","size":"827"},{"price":"0.56","size":"827"},{"price":"0.55","size":"817"},{"price":"0.54","size":"872"},{"price":"0.53","size":"839.65"},{"price":"0.52","size":"829"},{"price":"0.51","size":"817"},{"price":"0.5","size":"838.4"},{"price":"0.49","size":"867.58"},{"price":"0.48","size":"817"},{"price":"0.47","size":"827"},{"price":"0.46","size":"847.8"},{"price":"0.45","size":"836.09"},{"price":"0.44","size":"825"},{"price":"0.43","size":"847"},{"price":"0.42","size":"817"},{"price":"0.41","size":"817"},{"price":"0.4","size":"817"},{"price":"0.39","size":"834.5"},{"price":"0.38","size":"817"},{"price":"0.37","size":"497.49"},{"price":"0.36","size":"817"},{"price":"0.35","size":"872"},{"price":"0.34","size":"906.8"},{"price":"0.33","size":"906.8"},{"price":"0.32","size":"902"},{"price":"0.31","size":"1008.96"},{"price":"0.3","size":"911.6"},{"price":"0.29","size":"897"},{"price":"0.28","size":"899.55"},{"price":"0.27","size":"912"},{"price":"0.26","size":"1270.97"},{"price":"0.25","size":"722.5"},{"price":"0.24","size":"912.05"},{"price":"0.23","size":"748.5"},{"price":"0.22","size":"916.9"},{"price":"0.21","size":"969.5"},{"price":"0.2","size":"981.9"},{"price":"0.19","size":"798.21"},{"price":"0.18","size":"761"},{"price":"0.17","size":"669.52"},{"price":"0.16","size":"196"},{"price":"0.15","size":"194.99"},{"price":"0.14","size":"1187.63"},{"price":"0.13","size":"401.53"}],"hash":"0340b868950265ba7d71ac6c9d131e6d14738f96","timestamp":"1768250238989","event_type":"book"}}
{"schema_version":1,"source":"clob_ws_market","recv_ts_ns":1768250239037809615,"event_type":"price_change","market":"0x2a12fd3d8235c25c062dc9652970ef9f635636c4018df0909e1a51c673e125cb","server_ts_ms":1768250239007,"raw":{"market":"0x2a12fd3d8235c25c062dc9652970ef9f635636c4018df0909e1a51c673e125cb","price_changes":[{"asset_id":"63670753354844494163057275310194312729998307779831462269530137743341854359908","price":"0.8","size":"975.9","side":"BUY","hash":"ac229b84e3c74a2205a3a6056d6069a0781271c2","best_bid":"0.87","best_ask":"0.88"},{"asset_id":"56386988715176239099720172290594769295756680374928571099138069977179519358166","price":"0.2","size":"975.9","side":"SELL","hash":"fc9bc28e0d82418fe6e41354e3f91f9558a30cee","best_bid":"0.12","best_ask":"0.13"}],"timestamp":"1768250239007","event_type":"price_change"}}
{"schema_version":1,"source":"clob_ws_market","recv_ts_ns":1768250239042601167,"event_type":"price_change","market":"0x2a12fd3d8235c25c062dc9652970ef9f635636c4018df0909e1a51c673e125cb","server_ts_ms":1768250239007,"raw":{"market":"0x2a12fd3d8235c25c062dc9652970ef9f635636c4018df0909e1a51c673e125cb","price_changes":[{"asset_id":"63670753354844494163057275310194312729998307779831462269530137743341854359908","price":"0.91","size":"1382","side":"SELL","hash":"ac229b84e3c74a2205a3a6056d6069a0781271c2","best_bid":"0.87","best_ask":"0.88"},{"asset_id":"56386988715176239099720172290594769295756680374928571099138069977179519358166","price":"0.09","size":"1382","side":"BUY","hash":"fc9bc28e0d82418fe6e41354e3f91f9558a30cee","best_bid":"0.12","best_ask":"0.13"}],"timestamp":"1768250239007","event_type":"price_change"}}
{"schema_version":1,"source":"clob_ws_market","recv_ts_ns":1768250239059425734,"event_type":"last_trade_price","market":"0x2a12fd3d8235c25c062dc9652970ef9f635636c4018df0909e1a51c673e125cb","server_ts_ms":1768250239019,"raw":{"market":"0x2a12fd3d8235c25c062dc9652970ef9f635636c4018df0909e1a51c673e125cb","asset_id":"56386988715176239099720172290594769295756680374928571099138069977179519358166","price":"0.13","size":"8.461537","fee_rate_bps":"1000","side":"BUY","timestamp":"1768250239019","event_type":"last_trade_price","transaction_hash":"0x25466c90f7ed0131f276d577764cb34d131fe660c6ceda82c524881adfe8a12a"}}
{"schema_version":1,"source":"clob_ws_market","recv_ts_ns":1768250239061682343,"event_type":"price_change","market":"0x2a12fd3d8235c25c062dc9652970ef9f635636c4018df0909e1a51c673e125cb","server_ts_ms":1768250239038,"raw":{"market":"0x2a12fd3d8235c25c062dc9652970ef9f635636c4018df0909e1a51c673e125cb","price_changes":[{"asset_id":"63670753354844494163057275310194312729998307779831462269530137743341854359908","price":"0.8","size":"981.9","side":"BUY","hash":"ffb5e9f1df85d9a683a8a00dadf4dfbb04dd5ff4","best_bid":"0.87","best_ask":"0.88"},{"asset_id":"56386988715176239099720172290594769295756680374928571099138069977179519358166","price":"0.2","size":"981.9","side":"SELL","hash":"ef0018ed046fdc8f0b3caca920152ffd67935678","best_bid":"0.12","best_ask":"0.13"}],"timestamp":"1768250239038","event_type":"price_change"}}
{"schema_version":1,"source":"clob_ws_market","recv_ts_ns":1768250239065440526,"event_type":"price_change","market":"0x2a12fd3d8235c25c062dc9652970ef9f635636c4018df0909e1a51c673e125cb","server_ts_ms":1768250239039,"raw":{"market":"0x2a12fd3d8235c25c062dc9652970ef9f635636c4018df0909e1a51c673e125cb","price_changes":[{"asset_id":"63670753354844494163057275310194312729998307779831462269530137743341854359908","price":"0.91","size":"1387","side":"SELL","hash":"4f0a70a0b8493087964b60e19cf84af25bec9dc4","best_bid":"0.87","best_ask":"0.88"},{"asset_id":"56386988715176239099720172290594769295756680374928571099138069977179519358166","price":"0.09","size":"1387","side":"BUY","hash":"53ac28f5ff4836b9ac3e6a2e4480bc75bb5c7c03","best_bid":"0.12","best_ask":"0.13"}],"timestamp":"1768250239039","event_type":"price_change"}}
{"schema_version":1,"source":"clob_ws_market","recv_ts_ns":1768250239228529404,"event_type":"price_change","market":"0x2a12fd3d8235c25c062dc9652970ef9f635636c4018df0909e1a51c673e125cb","server_ts_ms":1768250239206,"raw":{"market":"0x2a12fd3d8235c25c062dc9652970ef9f635636c4018df0909e1a51c673e125cb","price_changes":[{"asset_id":"63670753354844494163057275310194312729998307779831462269530137743341854359908","price":"0.8","size":"975.9","side":"BUY","hash":"4d474d793386a4f02aa109b482764f3de625c0b2","best_bid":"0.87","best_ask":"0.88"},{"asset_id":"56386988715176239099720172290594769295756680374928571099138069977179519358166","price":"0.2","size":"975.9","side":"SELL","hash":"ff6f9bc9058ba1837fc73cdf002ad7e2bc61fda9","best_bid":"0.12","best_ask":"0.13"}],"timestamp":"1768250239206","event_type":"price_change"}}
{"schema_version":1,"source":"clob_ws_market","recv_ts_ns":1768250239237340158,"event_type":"price_change","market":"0x2a12fd3d8235c25c062dc9652970ef9f635636c4018df0909e1a51c673e125cb","server_ts_ms":1768250239206,"raw":{"market":"0x2a12fd3d8235c25c062dc9652970ef9f635636c4018df0909e1a51c673e125cb","price_changes":[{"asset_id":"63670753354844494163057275310194312729998307779831462269530137743341854359908","price":"0.91","size":"1382","side":"SELL","hash":"4d474d793386a4f02aa109b482764f3de625c0b2","best_bid":"0.87","best_ask":"0.88"},{"asset_id":"56386988715176239099720172290594769295756680374928571099138069977179519358166","price":"0.09","size":"1382","side":"BUY","hash":"ff6f9bc9058ba1837fc73cdf002ad7e2bc61fda9","best_bid":"0.12","best_ask":"0.13"}],"timestamp":"1768250239206","event_type":"price_change"}}
{"schema_version":1,"source":"clob_ws_market","recv_ts_ns":1768250239268373508,"event_type":"price_change","market":"0x2a12fd3d8235c25c062dc9652970ef9f635636c4018df0909e1a51c673e125cb","server_ts_ms":1768250239237,"raw":{"market":"0x2a12fd3d8235c25c062dc9652970ef9f635636c4018df0909e1a51c673e125cb","price_changes":[{"asset_id":"63670753354844494163057275310194312729998307779831462269530137743341854359908","price":"0.81","size":"804.21","side":"BUY","hash":"a011f773a8492b520553632425412cd556a7151a","best_bid":"0.87","best_ask":"0.88"},{"asset_id":"56386988715176239099720172290594769295756680374928571099138069977179519358166","price":"0.19","size":"804.21","side":"SELL","hash":"d44fcb00bb703551a8a0f429fbc6d07e5eba5716","best_bid":"0.12","best_ask":"0.13"}],"timestamp":"1768250239237","event_type":"price_change"}}
{"schema_version":1,"source":"clob_ws_market","recv_ts_ns":1768250239270786794,"event_type":"price_change","market":"0x2a12fd3d8235c25c062dc9652970ef9f635636c4018df0909e1a51c673e125cb","server_ts_ms":1768250239238,"raw":{"market":"0x2a12fd3d8235c25c062dc9652970ef9f635636c4018df0909e1a51c673e125cb","price_changes":[{"asset_id":"63670753354844494163057275310194312729998307779831462269530137743341854359908","price":"0.92","size":"1556.75","side":"SELL","hash":"d3362beb0030f25e87e0ac8a39840aa76e0dc30f","best_bid":"0.87","best_ask":"0.88"},{"asset_id":"56386988715176239099720172290594769295756680374928571099138069977179519358166","price":"0.08","size":"1556.75","side":"BUY","hash":"84e860ea155df151d7e8b091f3374a3412ac7e10","best_bid":"0.12","best_ask":"0.13"}],"timestamp":"1768250239238","event_type":"price_change"}}
{"schema_version":1,"source":"clob_ws_market","recv_ts_ns":1768250239290956990,"event_type":"price_change","market":"0x2a12fd3d8235c25c062dc9652970ef9f635636c4018df0909e1a51c673e125cb","server_ts_ms":1768250239269,"raw":{"market":"0x2a12fd3d8235c25c062dc9652970ef9f635636c4018df0909e1a51c673e125cb","price_changes":[{"asset_id":"63670753354844494163057275310194312729998307779831462269530137743341854359908","price":"0.88","size":"878.25","side":"SELL","hash":"123d03166d2d9b4ba28ada5673e47b001a62c9dd","best_bid":"0.87","best_ask":"0.88"},{"asset_id":"56386988715176239099720172290594769295756680374928571099138069977179519358166","price":"0.12","size":"878.25","side":"BUY","hash":"46d218e2f3bd85410ed7e230041bd0682b88448e","best_bid":"0.12","best_ask":"0.13"}],"timestamp":"1768250239269","event_type":"price_change"}}
{"schema_version":1,"source":"clob_ws_market","recv_ts_ns":1768250239385834481,"event_type":"best_bid_ask","market":"0x2a12fd3d8235c25c062dc9652970ef9f635636c4018df0909e1a51c673e125cb","server_ts_ms":1768250239366,"raw":{"market":"0x2a12fd3d8235c25c062dc9652970ef9f635636c4018df0909e1a51c673e125cb","asset_id":"56386988715176239099720172290594769295756680374928571099138069977179519358166","best_bid":"0.12","best_ask":"0.13","spread":"0.01","timestamp":"1768250239366","event_type":"best_bid_ask"}}
{"schema_version":1,"source":"clob_ws_market","recv_ts_ns":1768250239390544508,"event_type":"price_change","market":"0x2a12fd3d8235c25c062dc9652970ef9f635636c4018df0909e1a51c673e125cb","server_ts_ms":1768250239364,"raw":{"market":"0x2a12fd3d8235c25c062dc9652970ef9f635636c4018df0909e1a51c673e125cb","price_changes":[{"asset_id":"63670753354844494163057275310194312729998307779831462269530137743341854359908","price":"0.87","size":"393.06","side":"BUY","hash":"e7f0dd9396fe34caa6de6dfb0044467bfb815ee2","best_bid":"0.87","best_ask":"0.88"},{"asset_id":"56386988715176239099720172290594769295756680374928571099138069977179519358166","price":"0.13","size":"393.06","side":"SELL","hash":"dea8e93efba1a64f9821acc0532229368cad69a9","best_bid":"0.12","best_ask":"0.13"}],"timestamp":"1768250239364","event_type":"price_change"}}
{"schema_version":1,"source":"clob_ws_market","recv_ts_ns":1768250239397062004,"event_type":"book","market":"0x2a12fd3d8235c25c062dc9652970ef9f635636c4018df0909e1a51c673e125cb","server_ts_ms":1768250239364,"raw":{"market":"0x2a12fd3d8235c25c062dc9652970ef9f635636c4018df0909e1a51c673e125cb","asset_id":"56386988715176239099720172290594769295756680374928571099138069977179519358166","bids":[{"price":"0.01","size":"10157.67"},{"price":"0.02","size":"6299.77"},{"price":"0.03","size":"5625.94"},{"price":"0.04","size":"5452"},{"price":"0.05","size":"3442"},{"price":"0.06","size":"1492.5"},{"price":"0.07","size":"1416.28"},{"price":"0.08","size":"1556.75"},{"price":"0.09","size":"1382"},{"price":"0.1","size":"3464.5"},{"price":"0.11","size":"1423.5"},{"price":"0.12","size":"878.25"}],"asks":[{"price":"0.99","size":"10178.95"},{"price":"0.98","size":"5982"},{"price":"0.97","size":"5238.94"},{"price":"0.96","size":"5040"},{"price":"0.95","size":"5050"},{"price":"0.94","size":"5005"},{"price":"0.93","size":"5019.28"},{"price":"0.92","size":"5005"},{"price":"0.91","size":"5005"},{"price":"0.9","size":"5030"},{"price":"0.89","size":"5"},{"price":"0.88","size":"5"},{"price":"0.87","size":"5"},{"price":"0.86","size":"5"},{"price":"0.85","size":"10"},{"price":"0.84","size":"5"},{"price":"0.83","size":"5"},{"price":"0.82","size":"5"},{"price":"0.81","size":"5"},{"price":"0.8","size":"5"},{"price":"0.79","size":"5"},{"price":"0.78","size":"5"},{"price":"0.77","size":"5"},{"price":"0.76","size":"5"},{"price":"0.75","size":"10"},{"price":"0.74","size":"5"},{"price":"0.73","size":"5"},{"price":"0.72","size":"5"},{"price":"0.71","size":"15"},{"price":"0.7","size":"10"},{"price":"0.69","size":"5"},{"price":"0.68","size":"5"},{"price":"0.67","size":"5"},{"price":"0.66","size":"505"},{"price":"0.65","size":"510"},{"price":"0.64","size":"510"},{"price":"0.63","size":"505"},{"price":"0.62","size":"505"},{"price":"0.61","size":"755"},{"price":"0.6","size":"760"},{"price":"0.59","size":"916"},{"price":"0.58","size":"671"},{"price":"0.57","size":"827"},{"price":"0.56","size":"827"},{"price":"0.55","size":"817"},{"price":"0.54","size":"872"},{"price":"0.53","size":"839.65"},{"price":"0.52","size":"829"},{"price":"0.51","size":"817"},{"price":"0.5","size":"838.4"},{"price":"0.49","size":"867.58"},{"price":"0.48","size":"817"},{"price":"0.47","size":"827"},{"price":"0.46","size":"847.8"},{"price":"0.45","size":"836.09"},{"price":"0.44","size":"825"},{"price":"0.43","size":"847"},{"price":"0.42","size":"817"},{"price":"0.41","size":"817"},{"price":"0.4","size":"817"},{"price":"0.39","size":"834.5"},{"price":"0.38","size":"817"},{"price":"0.37","size":"497.49"},{"price":"0.36","size":"817"},{"price":"0.35","size":"872"},{"price":"0.34","size":"906.8"},{"price":"0.33","size":"906.8"},{"price":"0.32","size":"902"},{"price":"0.31","size":"1008.96"},{"price":"0.3","size":"911.6"},{"price":"0.29","size":"897"},{"price":"0.28","size":"899.55"},{"price":"0.27","size":"912"},{"price":"0.26","size":"1270.97"},{"price":"0.25","size":"722.5"},{"price":"0.24","size":"912.05"},{"price":"0.23","size":"748.5"},{"price":"0.22","size":"916.9"},{"price":"0.21","size":"969.5"},{"price":"0.2","size":"975.9"},{"price":"0.19","size":"804.21"},{"price":"0.18","size":"761"},{"price":"0.17","size":"669.52"},{"price":"0.16","size":"196"},{"price":"0.15","size":"194.99"},{"price":"0.14","size":"1187.63"},{"price":"0.13","size":"393.06"}],"hash":"dea8e93efba1a64f9821acc0532229368cad69a9","timestamp":"1768250239364","event_type":"book"}}
{"schema_version":1,"source":"clob_ws_market","recv_ts_ns":1768250239420228265,"event_type":"last_trade_price","market":"0x2a12fd3d8235c25c062dc9652970ef9f635636c4018df0909e1a51c673e125cb","server_ts_ms":1768250239394,"raw":{"market":"0x2a12fd3d8235c25c062dc9652970ef9f635636c4018df0909e1a51c673e125cb","asset_id":"56386988715176239099720172290594769295756680374928571099138069977179519358166","price":"0.13","size":"8.461537","fee_rate_bps":"1000","side":"BUY","timestamp":"1768250239394","event_type":"last_trade_price","transaction_hash":"0xef27bb68367525bdfe78ed91fd09b1145e07b4b1b28bb834d7caff73955fb82e"}}
{"schema_version":1,"source":"clob_ws_market","recv_ts_ns":1768250239488860551,"event_type":"price_change","market":"0x2a12fd3d8235c25c062dc9652970ef9f635636c4018df0909e1a51c673e125cb","server_ts_ms":1768250239467,"raw":{"market":"0x2a12fd3d8235c25c062dc9652970ef9f635636c4018df0909e1a51c673e125cb","price_changes":[{"asset_id":"63670753354844494163057275310194312729998307779831462269530137743341854359908","price":"0.83","size":"1369.52","side":"BUY","hash":"eae3d43f12e2dae3712278cdb0c73818f31d9c89","best_bid":"0.87","best_ask":"0.88"},{"asset_id":"56386988715176239099720172290594769295756680374928571099138069977179519358166","price":"0.17","size":"1369.52","side":"SELL","hash":"91183394dbf3b386f9b8f086cbc83a2151932c20","best_bid":"0.12","best_ask":"0.13"}],"timestamp":"1768250239467","event_type":"price_change"}}
{"schema_version":1,"source":"clob_ws_market","recv_ts_ns":1768250239811491781,"event_type":"price_change","market":"0x2a12fd3d8235c25c062dc9652970ef9f635636c4018df0909e1a51c673e125cb","server_ts_ms":1768250239790,"raw":{"market":"0x2a12fd3d8235c25c062dc9652970ef9f635636c4018df0909e1a51c673e125cb","price_changes":[{"asset_id":"63670753354844494163057275310194312729998307779831462269530137743341854359908","price":"0.88","size":"863.25","side":"SELL","hash":"4e83a6aff3db878121c8ac10866c0494e0cb69d5","best_bid":"0.87","best_ask":"0.88"},{"asset_id":"56386988715176239099720172290594769295756680374928571099138069977179519358166","price":"0.12","size":"863.25","side":"BUY","hash":"41779702faa6cb18b4810e9fa65e489c1378c937","best_bid":"0.12","best_ask":"0.13"}],"timestamp":"1768250239790","event_type":"price_change"}}
{"schema_version":1,"source":"clob_ws_market","recv_ts_ns":1768250239838941768,"event_type":"price_change","market":"0x2a12fd3d8235c25c062dc9652970ef9f635636c4018df0909e1a51c673e125cb","server_ts_ms":1768250239816,"raw":{"market":"0x2a12fd3d8235c25c062dc9652970ef9f635636c4018df0909e1a51c673e125cb","price_changes":[{"asset_id":"56386988715176239099720172290594769295756680374928571099138069977179519358166","price":"0.13","size":"398.56","side":"SELL","hash":"554b24bde59550818afa9262660a966376c05ded","best_bid":"0.12","best_ask":"0.13"},{"asset_id":"63670753354844494163057275310194312729998307779831462269530137743341854359908","price":"0.87","size":"398.56","side":"BUY","hash":"ce4620bb17dc184c5a8ab717f53d1c34fd9959f0","best_bid":"0.87","best_ask":"0.88"}],"timestamp":"1768250239816","event_type":"price_change"}}
{"schema_version":1,"source":"clob_ws_market","recv_ts_ns":1768250239846112203,"event_type":"price_change","market":"0x2a12fd3d8235c25c062dc9652970ef9f635636c4018df0909e1a51c673e125cb","server_ts_ms":1768250239820,"raw":{"market":"0x2a12fd3d8235c25c062dc9652970ef9f635636c4018df0909e1a51c673e125cb","price_changes":[{"asset_id":"63670753354844494163057275310194312729998307779831462269530137743341854359908","price":"0.88","size":"857.75","side":"SELL","hash":"f7108ed9b033fef341aac02c970c0541260a6aba","best_bid":"0.87","best_ask":"0.88"},{"asset_id":"56386988715176239099720172290594769295756680374928571099138069977179519358166","price":"0.12","size":"857.75","side":"BUY","hash":"14d31971fd9c9220467a88c8ee0d3e0369e6d613","best_bid":"0.12","best_ask":"0.13"}],"timestamp":"1768250239820","event_type":"price_change"}}
{"schema_version":1,"source":"clob_ws_market","recv_ts_ns":1768250239851962040,"event_type":"price_change","market":"0x2a12fd3d8235c25c062dc9652970ef9f635636c4018df0909e1a51c673e125cb","server_ts_ms":1768250239820,"raw":{"market":"0x2a12fd3d8235c25c062dc9652970ef9f635636c4018df0909e1a51c673e125cb","price_changes":[{"asset_id":"56386988715176239099720172290594769295756680374928571099138069977179519358166","price":"0.13","size":"393.06","side":"SELL","hash":"2bbe47396c4dc871d3acfa3f1b93c0ecc1140108","best_bid":"0.12","best_ask":"0.13"},{"asset_id":"63670753354844494163057275310194312729998307779831462269530137743341854359908","price":"0.87","size":"393.06","side":"BUY","hash":"5c6d9af9f64168a94d9a2f4651209ff2eb21e596","best_bid":"0.87","best_ask":"0.88"}],"timestamp":"1768250239820","event_type":"price_change"}}
{"schema_version":1,"source":"clob_ws_market","recv_ts_ns":1768250239875440599,"event_type":"price_change","market":"0x2a12fd3d8235c25c062dc9652970ef9f635636c4018df0909e1a51c673e125cb","server_ts_ms":1768250239853,"raw":{"market":"0x2a12fd3d8235c25c062dc9652970ef9f635636c4018df0909e1a51c673e125cb","price_changes":[{"asset_id":"63670753354844494163057275310194312729998307779831462269530137743341854359908","price":"0.88","size":"872.75","side":"SELL","hash":"f50eb45612702f376a64dcbbee181ded2a5e9613","best_bid":"0.87","best_ask":"0.88"},{"asset_id":"56386988715176239099720172290594769295756680374928571099138069977179519358166","price":"0.12","size":"872.75","side":"BUY","hash":"5eb8767241b6c0bd87589573554a1d1672c13c36","best_bid":"0.12","best_ask":"0.13"}],"timestamp":"1768250239853","event_type":"price_change"}}
{"schema_version":1,"source":"clob_ws_market","recv_ts_ns":1768250239880869551,"event_type":"price_change","market":"0x2a12fd3d8235c25c062dc9652970ef9f635636c4018df0909e1a51c673e125cb","server_ts_ms":1768250239854,"raw":{"market":"0x2a12fd3d8235c25c062dc9652970ef9f635636c4018df0909e1a51c673e125cb","price_changes":[{"asset_id":"63670753354844494163057275310194312729998307779831462269530137743341854359908","price":"0.88","size":"878.25","side":"SELL","hash":"975581bbe47550786be7fb0bb9d7ee0f1e3c68bf","best_bid":"0.87","best_ask":"0.88"},{"asset_id":"56386988715176239099720172290594769295756680374928571099138069977179519358166","price":"0.12","size":"878.25","side":"BUY","hash":"1f745631648882788dd16ad3bce773118ab9d28a","best_bid":"0.12","best_ask":"0.13"}],"timestamp":"1768250239854","event_type":"price_change"}}
{"schema_version":1,"source":"clob_ws_market","recv_ts_ns":1768250239904227889,"event_type":"price_change","market":"0x2a12fd3d8235c25c062dc9652970ef9f635636c4018df0909e1a51c673e125cb","server_ts_ms":1768250239881,"raw":{"market":"0x2a12fd3d8235c25c062dc9652970ef9f635636c4018df0909e1a51c673e125cb","price_changes":[{"asset_id":"63670753354844494163057275310194312729998307779831462269530137743341854359908","price":"0.81","size":"798.21","side":"BUY","hash":"1e1ed9cdb747fa80e62c7c24796fa97b4aa8f43a","best_bid":"0.87","best_ask":"0.88"},{"asset_id":"56386988715176239099720172290594769295756680374928571099138069977179519358166","price":"0.19","size":"798.21","side":"SELL","hash":"06d804a3d1fd8d4369bd3819488b797842caa889","best_bid":"0.12","best_ask":"0.13"}],"timestamp":"1768250239881","event_type":"price_change"}}
{"schema_version":1,"source":"clob_ws_market","recv_ts_ns":1768250239909548714,"event_type":"price_change","market":"0x2a12fd3d8235c25c062dc9652970ef9f635636c4018df0909e1a51c673e125cb","server_ts_ms":1768250239881,"raw":{"market":"0x2a12fd3d8235c25c062dc9652970ef9f635636c4018df0909e1a51c673e125cb","price_changes":[{"asset_id":"63670753354844494163057275310194312729998307779831462269530137743341854359908","price":"0.92","size":"1551.75","side":"SELL","hash":"1e1ed9cdb747fa80e62c7c24796fa97b4aa8f43a","best_bid":"0.87","best_ask":"0.88"},{"asset_id":"56386988715176239099720172290594769295756680374928571099138069977179519358166","price":"0.08","size":"1551.75","side":"BUY","hash":"06d804a3d1fd8d4369bd3819488b797842caa889","best_bid":"0.12","best_ask":"0.13"}],"timestamp":"1768250239881","event_type":"price_change"}}
{"schema_version":1,"source":"clob_ws_market","recv_ts_ns":1768250239913983568,"event_type":"price_change","market":"0x2a12fd3d8235c25c062dc9652970ef9f635636c4018df0909e1a51c673e125cb","server_ts_ms":1768250239885,"raw":{"market":"0x2a12fd3d8235c25c062dc9652970ef9f635636c4018df0909e1a51c673e125cb","price_changes":[{"asset_id":"56386988715176239099720172290594769295756680374928571099138069977179519358166","price":"0.13","size":"398.56","side":"SELL","hash":"c26dc4fbefba7be62c85726e2298c3de09dfc44c","best_bid":"0.12","best_ask":"0.13"},{"asset_id":"63670753354844494163057275310194312729998307779831462269530137743341854359908","price":"0.87","size":"398.56","side":"BUY","hash":"de50664c3141ba02fa28b6901af10c4420f770b7","best_bid":"0.87","best_ask":"0.88"}],"timestamp":"1768250239885","event_type":"price_change"}}
{"schema_version":1,"source":"clob_ws_market","recv_ts_ns":1768250239931744752,"event_type":"price_change","market":"0x2a12fd3d8235c25c062dc9652970ef9f635636c4018df0909e1a51c673e125cb","server_ts_ms":1768250239909,"raw":{"market":"0x2a12fd3d8235c25c062dc9652970ef9f635636c4018df0909e1a51c673e125cb","price_changes":[{"asset_id":"63670753354844494163057275310194312729998307779831462269530137743341854359908","price":"0.91","size":"1387","side":"SELL","hash":"419ebdf11e0f70c10bd8482fe0cf8ad38b7c57ff","best_bid":"0.87","best_ask":"0.88"},{"asset_id":"56386988715176239099720172290594769295756680374928571099138069977179519358166","price":"0.09","size":"1387","side":"BUY","hash":"b68c88585a80504b17184871f622b922fdc2d1a6","best_bid":"0.12","best_ask":"0.13"}],"timestamp":"1768250239909","event_type":"price_change"}}
{"schema_version":1,"source":"clob_ws_market","recv_ts_ns":1768250239937186007,"event_type":"price_change","market":"0x2a12fd3d8235c25c062dc9652970ef9f635636c4018df0909e1a51c673e125cb","server_ts_ms":1768250239910,"raw":{"market":"0x2a12fd3d8235c25c062dc9652970ef9f635636c4018df0909e1a51c673e125cb","price_changes":[{"asset_id":"63670753354844494163057275310194312729998307779831462269530137743341854359908","price":"0.8","size":"981.9","side":"BUY","hash":"4ccfea386e16144ccf382d1a94a1dd8c32941931","best_bid":"0.87","best_ask":"0.88"},{"asset_id":"56386988715176239099720172290594769295756680374928571099138069977179519358166","price":"0.2","size":"981.9","side":"SELL","hash":"6554fbbfdc8e6c783decaea92269934828e6c2ac","best_bid":"0.12","best_ask":"0.13"}],"timestamp":"1768250239910","event_type":"price_change"}}
{"schema_version":1,"source":"clob_ws_market","recv_ts_ns":1768250240070649048,"event_type":"price_change","market":"0x2a12fd3d8235c25c062dc9652970ef9f635636c4018df0909e1a51c673e125cb","server_ts_ms":1768250240037,"raw":{"market":"0x2a12fd3d8235c25c062dc9652970ef9f635636c4018df0909e1a51c673e125cb","price_changes":[{"asset_id":"63670753354844494163057275310194312729998307779831462269530137743341854359908","price":"0.89","size":"1443.5","side":"SELL","hash":"1129c88b56b5758493aef84fb3f6181491e33358","best_bid":"0.87","best_ask":"0.88"},{"asset_id":"56386988715176239099720172290594769295756680374928571099138069977179519358166","price":"0.11","size":"1443.5","side":"BUY","hash":"b5c141632f8b7787131468458d3a78ab59b7fb4d","best_bid":"0.12","best_ask":"0.13"}],"timestamp":"1768250240037","event_type":"price_change"}}
{"schema_version":1,"source":"clob_ws_market","recv_ts_ns":1768250240132259142,"event_type":"best_bid_ask","market":"0x2a12fd3d8235c25c062dc9652970ef9f635636c4018df0909e1a51c673e125cb","server_ts_ms":1768250240111,"raw":{"market":"0x2a12fd3d8235c25c062dc9652970ef9f635636c4018df0909e1a51c673e125cb","asset_id":"56386988715176239099720172290594769295756680374928571099138069977179519358166","best_bid":"0.12","best_ask":"0.13","spread":"0.01","timestamp":"1768250240111","event_type":"best_bid_ask"}}
{"schema_version":1,"source":"clob_ws_market","recv_ts_ns":1768250240138522110,"event_type":"price_change","market":"0x2a12fd3d8235c25c062dc9652970ef9f635636c4018df0909e1a51c673e125cb","server_ts_ms":1768250240109,"raw":{"market":"0x2a12fd3d8235c25c062dc9652970ef9f635636c4018df0909e1a51c673e125cb","price_changes":[{"asset_id":"63670753354844494163057275310194312729998307779831462269530137743341854359908","price":"0.87","size":"385.23","side":"BUY","hash":"eea1a2da638484d2e7b8efa4898078eccd8ea60d","best_bid":"0.87","best_ask":"0.88"},{"asset_id":"56386988715176239099720172290594769295756680374928571099138069977179519358166","price":"0.13","size":"385.23","side":"SELL","hash":"389c304c14a32abd1c3e8b4e96c2926158a00e5c","best_bid":"0.12","best_ask":"0.13"}],"timestamp":"1768250240109","event_type":"price_change"}}
{"schema_version":1,"source":"clob_ws_market","recv_ts_ns":1768250240144629524,"event_type":"book","market":"0x2a12fd3d8235c25c062dc9652970ef9f635636c4018df0909e1a51c673e125cb","server_ts_ms":1768250240109,"raw":{"market":"0x2a12fd3d8235c25c062dc9652970ef9f635636c4018df0909e1a51c673e125cb","asset_id":"56386988715176239099720172290594769295756680374928571099138069977179519358166","bids":[{"price":"0.01","size":"10157.67"},{"price":"0.02","size":"6299.77"},{"price":"0.03","size":"5625.94"},{"price":"0.04","size":"5452"},{"price":"0.05","size":"3442"},{"price":"0.06","size":"1492.5"},{"price":"0.07","size":"1416.28"},{"price":"0.08","size":"1551.75"},{"price":"0.09","size":"1387"},{"price":"0.1","size":"3464.5"},{"price":"0.11","size":"1443.5"},{"price":"0.12","size":"878.25"}],"asks":[{"price":"0.99","size":"10178.95"},{"price":"0.98","size":"5982"},{"price":"0.97","size":"5238.94"},{"price":"0.96","size":"5040"},{"price":"0.95","size":"5050"},{"price":"0.94","size":"5005"},{"price":"0.93","size":"5019.28"},{"price":"0.92","size":"5005"},{"price":"0.91","size":"5005"},{"price":"0.9","size":"5030"},{"price":"0.89","size":"5"},{"price":"0.88","size":"5"},{"price":"0.87","size":"5"},{"price":"0.86","size":"5"},{"price":"0.85","size":"10"},{"price":"0.84","size":"5"},{"price":"0.83","size":"5"},{"price":"0.82","size":"5"},{"price":"0.81","size":"5"},{"price":"0.8","size":"5"},{"price":"0.79","size":"5"},{"price":"0.78","size":"5"},{"price":"0.77","size":"5"},{"price":"0.76","size":"5"},{"price":"0.75","size":"10"},{"price":"0.74","size":"5"},{"price":"0.73","size":"5"},{"price":"0.72","size":"5"},{"price":"0.71","size":"15"},{"price":"0.7","size":"10"},{"price":"0.69","size":"5"},{"price":"0.68","size":"5"},{"price":"0.67","size":"5"},{"price":"0.66","size":"505"},{"price":"0.65","size":"510"},{"price":"0.64","size":"510"},{"price":"0.63","size":"505"},{"price":"0.62","size":"505"},{"price":"0.61","size":"755"},{"price":"0.6","size":"760"},{"price":"0.59","size":"916"},{"price":"0.58","size":"671"},{"price":"0.57","size":"827"},{"price":"0.56","size":"827"},{"price":"0.55","size":"817"},{"price":"0.54","size":"872"},{"price":"0.53","size":"839.65"},{"price":"0.52","size":"829"},{"price":"0.51","size":"817"},{"price":"0.5","size":"838.4"},{"price":"0.49","size":"867.58"},{"price":"0.48","size":"817"},{"price":"0.47","size":"827"},{"price":"0.46","size":"847.8"},{"price":"0.45","size":"836.09"},{"price":"0.44","size":"825"},{"price":"0.43","size":"847"},{"price":"0.42","size":"817"},{"price":"0.41","size":"817"},{"price":"0.4","size":"817"},{"price":"0.39","size":"834.5"},{"price":"0.38","size":"817"},{"price":"0.37","size":"497.49"},{"price":"0.36","size":"817"},{"price":"0.35","size":"872"},{"price":"0.34","size":"906.8"},{"price":"0.33","size":"906.8"},{"price":"0.32","size":"902"},{"price":"0.31","size":"1008.96"},{"price":"0.3","size":"911.6"},{"price":"0.29","size":"897"},{"price":"0.28","size":"899.55"},{"price":"0.27","size":"912"},{"price":"0.26","size":"1270.97"},{"price":"0.25","size":"722.5"},{"price":"0.24","size":"912.05"},{"price":"0.23","size":"748.5"},{"price":"0.22","size":"916.9"},{"price":"0.21","size":"969.5"},{"price":"0.2","size":"981.9"},{"price":"0.19","size":"798.21"},{"price":"0.18","size":"761"},{"price":"0.17","size":"1369.52"},{"price":"0.16","size":"196"},{"price":"0.15","size":"194.99"},{"price":"0.14","size":"1187.63"},{"price":"0.13","size":"385.23"}],"hash":"389c304c14a32abd1c3e8b4e96c2926158a00e5c","timestamp":"1768250240109","event_type":"book"}}
{"schema_version":1,"source":"clob_ws_market","recv_ts_ns":1768250240177871927,"event_type":"last_trade_price","market":"0x2a12fd3d8235c25c062dc9652970ef9f635636c4018df0909e1a51c673e125cb","server_ts_ms":1768250240138,"raw":{"market":"0x2a12fd3d8235c25c062dc9652970ef9f635636c4018df0909e1a51c673e125cb","asset_id":"56386988715176239099720172290594769295756680374928571099138069977179519358166","price":"0.13","size":"13.33","fee_rate_bps":"1000","side":"BUY","timestamp":"1768250240138","event_type":"last_trade_price","transaction_hash":"0xc8f363fb82066de4cf76fff7083da0d8b4443d32e25d424d760628c1bd42c703"}}
{"schema_version":1,"source":"clob_ws_market","recv_ts_ns":1768250240273306972,"event_type":"price_change","market":"0x2a12fd3d8235c25c062dc9652970ef9f635636c4018df0909e1a51c673e125cb","server_ts_ms":1768250240248,"raw":{"market":"0x2a12fd3d8235c25c062dc9652970ef9f635636c4018df0909e1a51c673e125cb","price_changes":[{"asset_id":"63670753354844494163057275310194312729998307779831462269530137743341854359908","price":"0.74","size":"1221.8","side":"BUY","hash":"eb1b3ed17f13897638473fec15e427038849e343","best_bid":"0.87","best_ask":"0.88"},{"asset_id":"56386988715176239099720172290594769295756680374928571099138069977179519358166","price":"0.26","size":"1221.8","side":"SELL","hash":"726061941197c496c3aece120fcb177cd5bfe4ac","best_bid":"0.12","best_ask":"0.13"}],"timestamp":"1768250240248","event_type":"price_change"}}
{"schema_version":1,"source":"clob_ws_market","recv_ts_ns":1768250240646638836,"event_type":"best_bid_ask","market":"0x2a12fd3d8235c25c062dc9652970ef9f635636c4018df0909e1a51c673e125cb","server_ts_ms":1768250240626,"raw":{"market":"0x2a12fd3d8235c25c062dc9652970ef9f635636c4018df0909e1a51c673e125cb","asset_id":"56386988715176239099720172290594769295756680374928571099138069977179519358166","best_bid":"0.12","best_ask":"0.13","spread":"0.01","timestamp":"1768250240626","event_type":"best_bid_ask"}}
{"schema_version":1,"source":"clob_ws_market","recv_ts_ns":1768250240653301796,"event_type":"price_change","market":"0x2a12fd3d8235c25c062dc9652970ef9f635636c4018df0909e1a51c673e125cb","server_ts_ms":1768250240624,"raw":{"market":"0x2a12fd3d8235c25c062dc9652970ef9f635636c4018df0909e1a51c673e125cb","price_changes":[{"asset_id":"63670753354844494163057275310194312729998307779831462269530137743341854359908","price":"0.87","size":"370.95","side":"BUY","hash":"20fc6d9af2c745f249b723080a47e44a6fee10fc","best_bid":"0.87","best_ask":"0.88"},{"asset_id":"56386988715176239099720172290594769295756680374928571099138069977179519358166","price":"0.13","size":"370.95","side":"SELL","hash":"289ddf87b93501a75ccde6edc1300e5409795df3","best_bid":"0.12","best_ask":"0.13"}],"timestamp":"1768250240624","event_type":"price_change"}}
{"schema_version":1,"source":"clob_ws_market","recv_ts_ns":1768250240660177811,"event_type":"book","market":"0x2a12fd3d8235c25c062dc9652970ef9f635636c4018df0909e1a51c673e125cb","server_ts_ms":1768250240624,"raw":{"market":"0x2a12fd3d8235c25c062dc9652970ef9f635636c4018df0909e1a51c673e125cb","asset_id":"56386988715176239099720172290594769295756680374928571099138069977179519358166","bids":[{"price":"0.01","size":"10157.67"},{"price":"0.02","size":"6299.77"},{"price":"0.03","size":"5625.94"},{"price":"0.04","size":"5452"},{"price":"0.05","size":"3442"},{"price":"0.06","size":"1492.5"},{"price":"0.07","size":"1416.28"},{"price":"0.08","size":"1551.75"},{"price":"0.09","size":"1387"},{"price":"0.1","size":"3464.5"},{"price":"0.11","size":"1443.5"},{"price":"0.12","size":"878.25"}],"asks":[{"price":"0.99","size":"10178.95"},{"price":"0.98","size":"5982"},{"price":"0.97","size":"5238.94"},{"price":"0.96","size":"5040"},{"price":"0.95","size":"5050"},{"price":"0.94","size":"5005"},{"price":"0.93","size":"5019.28"},{"price":"0.92","size":"5005"},{"price":"0.91","size":"5005"},{"price":"0.9","size":"5030"},{"price":"0.89","size":"5"},{"price":"0.88","size":"5"},{"price":"0.87","size":"5"},{"price":"0.86","size":"5"},{"price":"0.85","size":"10"},{"price":"0.84","size":"5"},{"price":"0.83","size":"5"},{"price":"0.82","size":"5"},{"price":"0.81","size":"5"},{"price":"0.8","size":"5"},{"price":"0.79","size":"5"},{"price":"0.78","size":"5"},{"price":"0.77","size":"5"},{"price":"0.76","size":"5"},{"price":"0.75","size":"10"},{"price":"0.74","size":"5"},{"price":"0.73","size":"5"},{"price":"0.72","size":"5"},{"price":"0.71","size":"15"},{"price":"0.7","size":"10"},{"price":"0.69","size":"5"},{"price":"0.68","size":"5"},{"price":"0.67","size":"5"},{"price":"0.66","size":"505"},{"price":"0.65","size":"510"},{"price":"0.64","size":"510"},{"price":"0.63","size":"505"},{"price":"0.62","size":"505"},{"price":"0.61","size":"755"},{"price":"0.6","size":"760"},{"price":"0.59","size":"916"},{"price":"0.58","size":"671"},{"price":"0.57","size":"827"},{"price":"0.56","size":"827"},{"price":"0.55","size":"817"},{"price":"0.54","size":"872"},{"price":"0.53","size":"839.65"},{"price":"0.52","size":"829"},{"price":"0.51","size":"817"},{"price":"0.5","size":"838.4"},{"price":"0.49","size":"867.58"},{"price":"0.48","size":"817"},{"price":"0.47","size":"827"},{"price":"0.46","size":"847.8"},{"price":"0.45","size":"836.09"},{"price":"0.44","size":"825"},{"price":"0.43","size":"847"},{"price":"0.42","size":"817"},{"price":"0.41","size":"817"},{"price":"0.4","size":"817"},{"price":"0.39","size":"834.5"},{"price":"0.38","size":"817"},{"price":"0.37","size":"497.49"},{"price":"0.36","size":"817"},{"price":"0.35","size":"872"},{"price":"0.34","size":"906.8"},{"price":"0.33","size":"906.8"},{"price":"0.32","size":"902"},{"price":"0.31","size":"1008.96"},{"price":"0.3","size":"911.6"},{"price":"0.29","size":"897"},{"price":"0.28","size":"899.55"},{"price":"0.27","size":"912"},{"price":"0.26","size":"1221.8"},{"price":"0.25","size":"722.5"},{"price":"0.24","size":"912.05"},{"price":"0.23","size":"748.5"},{"price":"0.22","size":"916.9"},{"price":"0.21","size":"969.5"},{"price":"0.2","size":"981.9"},{"price":"0.19","size":"798.21"},{"price":"0.18","size":"761"},{"price":"0.17","size":"1369.52"},{"price":"0.16","size":"196"},{"price":"0.15","size":"194.99"},{"price":"0.14","size":"1187.63"},{"price":"0.13","size":"370.95"}],"hash":"289ddf87b93501a75ccde6edc1300e5409795df3","timestamp":"1768250240624","event_type":"book"}}
{"schema_version":1,"source":"clob_ws_market","recv_ts_ns":1768250240671807878,"event_type":"price_change","market":"0x2a12fd3d8235c25c062dc9652970ef9f635636c4018df0909e1a51c673e125cb","server_ts_ms":1768250240649,"raw":{"market":"0x2a12fd3d8235c25c062dc9652970ef9f635636c4018df0909e1a51c673e125cb","price_changes":[{"asset_id":"63670753354844494163057275310194312729998307779831462269530137743341854359908","price":"0.88","size":"863.25","side":"SELL","hash":"2227bca5098814f7b1530ee6550a5fe16705d346","best_bid":"0.87","best_ask":"0.88"},{"asset_id":"56386988715176239099720172290594769295756680374928571099138069977179519358166","price":"0.12","size":"863.25","side":"BUY","hash":"1ff42204804fb142e53afe1527ea15422b72800e","best_bid":"0.12","best_ask":"0.13"}],"timestamp":"1768250240649","event_type":"price_change"}}
{"schema_version":1,"source":"clob_ws_market","recv_ts_ns":1768250240675881628,"event_type":"last_trade_price","market":"0x2a12fd3d8235c25c062dc9652970ef9f635636c4018df0909e1a51c673e125cb","server_ts_ms":1768250240653,"raw":{"market":"0x2a12fd3d8235c25c062dc9652970ef9f635636c4018df0909e1a51c673e125cb","asset_id":"56386988715176239099720172290594769295756680374928571099138069977179519358166","price":"0.13","size":"14.28","fee_rate_bps":"1000","side":"BUY","timestamp":"1768250240653","event_type":"last_trade_price","transaction_hash":"0x45c56600d169696aa556d7c01ef99f69e998688bc82d2f5230ac8ae6cda05e9b"}}
{"schema_version":1,"source":"clob_ws_market","recv_ts_ns":1768250240694384830,"event_type":"price_change","market":"0x2a12fd3d8235c25c062dc9652970ef9f635636c4018df0909e1a51c673e125cb","server_ts_ms":1768250240670,"raw":{"market":"0x2a12fd3d8235c25c062dc9652970ef9f635636c4018df0909e1a51c673e125cb","price_changes":[{"asset_id":"63670753354844494163057275310194312729998307779831462269530137743341854359908","price":"0.88","size":"878.25","side":"SELL","hash":"b04c15bca511856d05146db39cd4a0dd151bac23","best_bid":"0.87","best_ask":"0.88"},{"asset_id":"56386988715176239099720172290594769295756680374928571099138069977179519358166","price":"0.12","size":"878.25","side":"BUY","hash":"027ea72f3e0b24fcc1e30b27fc4a1c0927fb4ea1","best_bid":"0.12","best_ask":"0.13"}],"timestamp":"1768250240670","event_type":"price_change"}}
{"schema_version":1,"source":"clob_ws_market","recv_ts_ns":1768250240740545993,"event_type":"price_change","market":"0x2a12fd3d8235c25c062dc9652970ef9f635636c4018df0909e1a51c673e125cb","server_ts_ms":1768250240719,"raw":{"market":"0x2a12fd3d8235c25c062dc9652970ef9f635636c4018df0909e1a51c673e125cb","price_changes":[{"asset_id":"63670753354844494163057275310194312729998307779831462269530137743341854359908","price":"0.01","size":"10184.18","side":"BUY","hash":"62f338f1c838cf16de404fa55fc39e6c114f24fb","best_bid":"0.87","best_ask":"0.88"},{"asset_id":"56386988715176239099720172290594769295756680374928571099138069977179519358166","price":"0.99","size":"10184.18","side":"SELL","hash":"b73f67bdea03aa3a17cf45389a6e2dceeea5ddb1","best_bid":"0.12","best_ask":"0.13"}],"timestamp":"1768250240719","event_type":"price_change"}}
{"schema_version":1,"source":"clob_ws_market","recv_ts_ns":1768250241019978784,"event_type":"price_change","market":"0x2a12fd3d8235c25c062dc9652970ef9f635636c4018df0909e1a51c673e125cb","server_ts_ms":1768250240996,"raw":{"market":"0x2a12fd3d8235c25c062dc9652970ef9f635636c4018df0909e1a51c673e125cb","price_changes":[{"asset_id":"56386988715176239099720172290594769295756680374928571099138069977179519358166","price":"0.12","size":"883.25","side":"BUY","hash":"ae4c06e4b38abe797fa0459461dfa8d660aa0348","best_bid":"0.12","best_ask":"0.13"},{"asset_id":"63670753354844494163057275310194312729998307779831462269530137743341854359908","price":"0.88","size":"883.25","side":"SELL","hash":"e20922096a0652f5e61d16591454e5bf74941884","best_bid":"0.87","best_ask":"0.88"}],"timestamp":"1768250240996","event_type":"price_change"}}
{"schema_version":1,"source":"clob_ws_market","recv_ts_ns":1768250241088413541,"event_type":"price_change","market":"0x2a12fd3d8235c25c062dc9652970ef9f635636c4018df0909e1a51c673e125cb","server_ts_ms":1768250241049,"raw":{"market":"0x2a12fd3d8235c25c062dc9652970ef9f635636c4018df0909e1a51c673e125cb","price_changes":[{"asset_id":"56386988715176239099720172290594769295756680374928571099138069977179519358166","price":"0.14","size":"1180.13","side":"SELL","hash":"58393533e1c3976f887e11af8622c068bae50db3","best_bid":"0.12","best_ask":"0.13"},{"asset_id":"63670753354844494163057275310194312729998307779831462269530137743341854359908","price":"0.86","size":"1180.13","side":"BUY","hash":"989dcd29a9eacc65ff6bcb8591afb3bfecd4abe7","best_bid":"0.87","best_ask":"0.88"}],"timestamp":"1768250241049","event_type":"price_change"}}
{"schema_version":1,"source":"clob_ws_market","recv_ts_ns":1768250241098871801,"event_type":"price_change","market":"0x2a12fd3d8235c25c062dc9652970ef9f635636c4018df0909e1a51c673e125cb","server_ts_ms":1768250241051,"raw":{"market":"0x2a12fd3d8235c25c062dc9652970ef9f635636c4018df0909e1a51c673e125cb","price_changes":[{"asset_id":"63670753354844494163057275310194312729998307779831462269530137743341854359908","price":"0.86","size":"1172.63","side":"BUY","hash":"55b8f068689c03aeea4a410b6af6c16880a47593","best_bid":"0.87","best_ask":"0.88"},{"asset_id":"56386988715176239099720172290594769295756680374928571099138069977179519358166","price":"0.14","size":"1172.63","side":"SELL","hash":"8918ccf818cf04a046ea59c9f509e0e3b38eb440","best_bid":"0.12","best_ask":"0.13"}],"timestamp":"1768250241051","event_type":"price_change"}}
{"schema_version":1,"source":"clob_ws_market","recv_ts_ns":1768250241123742416,"event_type":"price_change","market":"0x2a12fd3d8235c25c062dc9652970ef9f635636c4018df0909e1a51c673e125cb","server_ts_ms":1768250241057,"raw":{"market":"0x2a12fd3d8235c25c062dc9652970ef9f635636c4018df0909e1a51c673e125cb","price_changes":[{"asset_id":"56386988715176239099720172290594769295756680374928571099138069977179519358166","price":"0.16","size":"186","side":"SELL","hash":"f82844fd2497a4b01f85293a2b7b45bd78ae858d","best_bid":"0.12","best_ask":"0.13"},{"asset_id":"63670753354844494163057275310194312729998307779831462269530137743341854359908","price":"0.84","size":"186","side":"BUY","hash":"de548a91e8265a3eb4a827ba83d0b397f8b5b115","best_bid":"0.87","best_ask":"0.88"}],"timestamp":"1768250241057","event_type":"price_change"}}
{"schema_version":1,"source":"clob_ws_market","recv_ts_ns":1768250241129000625,"event_type":"price_change","market":"0x2a12fd3d8235c25c062dc9652970ef9f635636c4018df0909e1a51c673e125cb","server_ts_ms":1768250241058,"raw":{"market":"0x2a12fd3d8235c25c062dc9652970ef9f635636c4018df0909e1a51c673e125cb","price_changes":[{"asset_id":"63670753354844494163057275310194312729998307779831462269530137743341854359908","price":"0.74","size":"1174.42","side":"BUY","hash":"4f87b417e8f4ced2f2ddd1d4d8cae68f43671f94","best_bid":"0.87","best_ask":"0.88"},{"asset_id":"56386988715176239099720172290594769295756680374928571099138069977179519358166","price":"0.26","size":"1174.42","side":"SELL","hash":"68eb44906cc5430666074451f4d196c5c9d4b1b4","best_bid":"0.12","best_ask":"0.13"}],"timestamp":"1768250241058","event_type":"price_change"}}
{"schema_version":1,"source":"clob_ws_market","recv_ts_ns":1768250241132556777,"event_type":"price_change","market":"0x2a12fd3d8235c25c062dc9652970ef9f635636c4018df0909e1a51c673e125cb","server_ts_ms":1768250241062,"raw":{"market":"0x2a12fd3d8235c25c062dc9652970ef9f635636c4018df0909e1a51c673e125cb","price_changes":[{"asset_id":"56386988715176239099720172290594769295756680374928571099138069977179519358166","price":"0.12","size":"913.25","side":"BUY","hash":"e8ee0a306e18857e1011dd3c6ec1d03cb25277da","best_bid":"0.12","best_ask":"0.13"},{"asset_id":"63670753354844494163057275310194312729998307779831462269530137743341854359908","price":"0.88","size":"913.25","side":"SELL","hash":"27e4f1839e8f5ea3debb1b63c892ef30efa55feb","best_bid":"0.87","best_ask":"0.88"}],"timestamp":"1768250241062","event_type":"price_change"}}
{"schema_version":1,"source":"clob_ws_market","recv_ts_ns":1768250241145078859,"event_type":"price_change","market":"0x2a12fd3d8235c25c062dc9652970ef9f635636c4018df0909e1a51c673e125cb","server_ts_ms":1768250241079,"raw":{"market":"0x2a12fd3d8235c25c062dc9652970ef9f635636c4018df0909e1a51c673e125cb","price_changes":[{"asset_id":"63670753354844494163057275310194312729998307779831462269530137743341854359908","price":"0.67","size":"996.36","side":"BUY","hash":"97aa84cc6206fc218c26de1247a2de0a2628fc92","best_bid":"0.87","best_ask":"0.88"},{"asset_id":"56386988715176239099720172290594769295756680374928571099138069977179519358166","price":"0.33","size":"996.36","side":"SELL","hash":"09a95aa557abf93df98db95f0c32274f04634ef9","best_bid":"0.12","best_ask":"0.13"}],"timestamp":"1768250241079","event_type":"price_change"}}
{"schema_version":1,"source":"clob_ws_market","recv_ts_ns":1768250241147843818,"event_type":"price_change","market":"0x2a12fd3d8235c25c062dc9652970ef9f635636c4018df0909e1a51c673e125cb","server_ts_ms":1768250241080,"raw":{"market":"0x2a12fd3d8235c25c062dc9652970ef9f635636c4018df0909e1a51c673e125cb","price_changes":[{"asset_id":"63670753354844494163057275310194312729998307779831462269530137743341854359908","price":"0.69","size":"922","side":"BUY","hash":"79b18b5e0f94aed0069cf44732c4f4d402a07d92","best_bid":"0.87","best_ask":"0.88"},{"asset_id":"56386988715176239099720172290594769295756680374928571099138069977179519358166","price":"0.31","size":"922","side":"SELL","hash":"0aefeb52bd9092b3b2bd80b23bb11f3e09d4b3c1","best_bid":"0.12","best_ask":"0.13"}],"timestamp":"1768250241080","event_type":"price_change"}}
{"schema_version":1,"source":"clob_ws_market","recv_ts_ns":1768250241150824055,"event_type":"price_change","market":"0x2a12fd3d8235c25c062dc9652970ef9f635636c4018df0909e1a51c673e125cb","server_ts_ms":1768250241082,"raw":{"market":"0x2a12fd3d8235c25c062dc9652970ef9f635636c4018df0909e1a51c673e125cb","price_changes":[{"asset_id":"56386988715176239099720172290594769295756680374928571099138069977179519358166","price":"0.12","size":"918.25","side":"BUY","hash":"a6a6a36964d038699c555da02b34439c4533d89e","best_bid":"0.12","best_ask":"0.13"},{"asset_id":"63670753354844494163057275310194312729998307779831462269530137743341854359908","price":"0.88","size":"918.25","side":"SELL","hash":"b48a8d4723f4a54be82b3cbef62efa069a7991d3","best_bid":"0.87","best_ask":"0.88"}],"timestamp":"1768250241082","event_type":"price_change"}}
{"schema_version":1,"source":"clob_ws_market","recv_ts_ns":1768250241154162778,"event_type":"price_change","market":"0x2a12fd3d8235c25c062dc9652970ef9f635636c4018df0909e1a51c673e125cb","server_ts_ms":1768250241083,"raw":{"market":"0x2a12fd3d8235c25c062dc9652970ef9f635636c4018df0909e1a51c673e125cb","price_changes":[{"asset_id":"56386988715176239099720172290594769295756680374928571099138069977179519358166","price":"0.04","size":"5427","side":"BUY","hash":"542b34f49e3329007b1500602ce5de2a8d377f91","best_bid":"0.12","best_ask":"0.13"},{"asset_id":"63670753354844494163057275310194312729998307779831462269530137743341854359908","price":"0.96","size":"5427","side":"SELL","hash":"6abb5e05c157475babdbad8f9d14d7a05fc8affa","best_bid":"0.87","best_ask":"0.88"}],"timestamp":"1768250241083","event_type":"price_change"}}
{"schema_version":1,"source":"clob_ws_market","recv_ts_ns":1768250241156882871,"event_type":"price_change","market":"0x2a12fd3d8235c25c062dc9652970ef9f635636c4018df0909e1a51c673e125cb","server_ts_ms":1768250241088,"raw":{"market":"0x2a12fd3d8235c25c062dc9652970ef9f635636c4018df0909e1a51c673e125cb","price_changes":[{"asset_id":"56386988715176239099720172290594769295756680374928571099138069977179519358166","price":"0.11","size":"743.5","side":"BUY","hash":"617be3f9b1db64513d6a54ecca00eeb02e22c968","best_bid":"0.12","best_ask":"0.13"},{"asset_id":"63670753354844494163057275310194312729998307779831462269530137743341854359908","price":"0.89","size":"743.5","side":"SELL","hash":"1aae3143fbc82228df3a4d84b191724b6e6fb0e7","best_bid":"0.87","best_ask":"0.88"}],"timestamp":"1768250241088","event_type":"price_change"}}
{"schema_version":1,"source":"clob_ws_market","recv_ts_ns":1768250241166780146,"event_type":"price_change","market":"0x2a12fd3d8235c25c062dc9652970ef9f635636c4018df0909e1a51c673e125cb","server_ts_ms":1768250241091,"raw":{"market":"0x2a12fd3d8235c25c062dc9652970ef9f635636c4018df0909e1a51c673e125cb","price_changes":[{"asset_id":"63670753354844494163057275310194312729998307779831462269530137743341854359908","price":"0.85","size":"189.99","side":"BUY","hash":"6247686a8395fa81f02cde1831b18c46874abdc4","best_bid":"0.87","best_ask":"0.88"},{"asset_id":"56386988715176239099720172290594769295756680374928571099138069977179519358166","price":"0.15","size":"189.99","side":"SELL","hash":"0c62668dd784c6c668f60897bfb28f2c70fac0bb","best_bid":"0.12","best_ask":"0.13"}],"timestamp":"1768250241091","event_type":"price_change"}}
{"schema_version":1,"source":"clob_ws_market","recv_ts_ns":1768250241173536495,"event_type":"price_change","market":"0x2a12fd3d8235c25c062dc9652970ef9f635636c4018df0909e1a51c673e125cb","server_ts_ms":1768250241092,"raw":{"market":"0x2a12fd3d8235c25c062dc9652970ef9f635636c4018df0909e1a51c673e125cb","price_changes":[{"asset_id":"63670753354844494163057275310194312729998307779831462269530137743341854359908","price":"0.86","size":"1167.13","side":"BUY","hash":"42aba30bdaa91aa0fe3846ed52ea35ad842ab8d1","best_bid":"0.87","best_ask":"0.88"},{"asset_id":"56386988715176239099720172290594769295756680374928571099138069977179519358166","price":"0.14","size":"1167.13","side":"SELL","hash":"ac5d7b01a6e2de130325bbd74b449630734b0afc","best_bid":"0.12","best_ask":"0.13"}],"timestamp":"1768250241092","event_type":"price_change"}}
{"schema_version":1,"source":"clob_ws_market","recv_ts_ns":1768250241190426688,"event_type":"price_change","market":"0x2a12fd3d8235c25c062dc9652970ef9f635636c4018df0909e1a51c673e125cb","server_ts_ms":1768250241096,"raw":{"market":"0x2a12fd3d8235c25c062dc9652970ef9f635636c4018df0909e1a51c673e125cb","price_changes":[{"asset_id":"63670753354844494163057275310194312729998307779831462269530137743341854359908","price":"0.87","size":"5.5","side":"BUY","hash":"1d0d1158f411c43eb1ad2220945335dc87cd948f","best_bid":"0.87","best_ask":"0.88"},{"asset_id":"56386988715176239099720172290594769295756680374928571099138069977179519358166","price":"0.13","size":"5.5","side":"SELL","hash":"a687e2a86eced6e8dcc9dddb2f08b9b70c24513d","best_bid":"0.12","best_ask":"0.13"}],"timestamp":"1768250241096","event_type":"price_change"}}
{"schema_version":1,"source":"clob_ws_market","recv_ts_ns":1768250241194964364,"event_type":"price_change","market":"0x2a12fd3d8235c25c062dc9652970ef9f635636c4018df0909e1a51c673e125cb","server_ts_ms":1768250241096,"raw":{"market":"0x2a12fd3d8235c25c062dc9652970ef9f635636c4018df0909e1a51c673e125cb","price_changes":[{"asset_id":"63670753354844494163057275310194312729998307779831462269530137743341854359908","price":"0.89","size":"723.5","side":"SELL","hash":"91d8128ab38bc466bda23dd27ca091f4b7450840","best_bid":"0.87","best_ask":"0.88"},{"asset_id":"56386988715176239099720172290594769295756680374928571099138069977179519358166","price":"0.11","size":"723.5","side":"BUY","hash":"275f6382a254ca443c39e0e3e73962ecf5027f6a","best_bid":"0.12","best_ask":"0.13"}],"timestamp":"1768250241096","event_type":"price_change"}}
{"schema_version":1,"source":"clob_ws_market","recv_ts_ns":1768250241212097988,"event_type":"price_change","market":"0x2a12fd3d8235c25c062dc9652970ef9f635636c4018df0909e1a51c673e125cb","server_ts_ms":1768250241099,"raw":{"market":"0x2a12fd3d8235c25c062dc9652970ef9f635636c4018df0909e1a51c673e125cb","price_changes":[{"asset_id":"56386988715176239099720172290594769295756680374928571099138069977179519358166","price":"0.1","size":"3454.5","side":"BUY","hash":"2a02479a370703af622d9205c63d3a9e42e99a66","best_bid":"0.12","best_ask":"0.13"},{"asset_id":"63670753354844494163057275310194312729998307779831462269530137743341854359908","price":"0.9","size":"3454.5","side":"SELL","hash":"59f85e45bf84ba125cff0c99a2e6dfe6e8253017","best_bid":"0.87","best_ask":"0.88"}],"timestamp":"1768250241099","event_type":"price_change"}}
{"schema_version":1,"source":"clob_ws_market","recv_ts_ns":1768250241219335266,"event_type":"best_bid_ask","market":"0x2a12fd3d8235c25c062dc9652970ef9f635636c4018df0909e1a51c673e125cb","server_ts_ms":1768250241104,"raw":{"market":"0x2a12fd3d8235c25c062dc9652970ef9f635636c4018df0909e1a51c673e125cb","asset_id":"56386988715176239099720172290594769295756680374928571099138069977179519358166","best_bid":"0.12","best_ask":"0.14","spread":"0.02","timestamp":"1768250241104","event_type":"best_bid_ask"}}
{"schema_version":1,"source":"clob_ws_market","recv_ts_ns":1768250241223079307,"event_type":"price_change","market":"0x2a12fd3d8235c25c062dc9652970ef9f635636c4018df0909e1a51c673e125cb","server_ts_ms":1768250241103,"raw":{"market":"0x2a12fd3d8235c25c062dc9652970ef9f635636c4018df0909e1a51c673e125cb","price_changes":[{"asset_id":"56386988715176239099720172290594769295756680374928571099138069977179519358166","price":"0.13","size":"0","side":"SELL","hash":"7769d55a9d558c69f3c4a5220d0e0f2abb59b25d","best_bid":"0.12","best_ask":"0.14"},{"asset_id":"63670753354844494163057275310194312729998307779831462269530137743341854359908","price":"0.87","size":"0","side":"BUY","hash":"0ec7624751a69d858a3cbaf8465e7cafc8903443","best_bid":"0.86","best_ask":"0.88"}],"timestamp":"1768250241103","event_type":"price_change"}}
{"schema_version":1,"source":"clob_ws_market","recv_ts_ns":1768250241227303412,"event_type":"price_change","market":"0x2a12fd3d8235c25c062dc9652970ef9f635636c4018df0909e1a51c673e125cb","server_ts_ms":1768250241104,"raw":{"market":"0x2a12fd3d8235c25c062dc9652970ef9f635636c4018df0909e1a51c673e125cb","price_changes":[{"asset_id":"63670753354844494163057275310194312729998307779831462269530137743341854359908","price":"0.86","size":"1157.13","side":"BUY","hash":"cb84a54630af3e913134fe5c3616a40cc399f375","best_bid":"0.86","best_ask":"0.88"},{"asset_id":"56386988715176239099720172290594769295756680374928571099138069977179519358166","price":"0.14","size":"1157.13","side":"SELL","hash":"43a5093db553d817658614dc9d5e78fae0f8e684","best_bid":"0.12","best_ask":"0.14"}],"timestamp":"1768250241104","event_type":"price_change"}}
{"schema_version":1,"source":"clob_ws_market","recv_ts_ns":1768250241230583743,"event_type":"price_change","market":"0x2a12fd3d8235c25c062dc9652970ef9f635636c4018df0909e1a51c673e125cb","server_ts_ms":1768250241105,"raw":{"market":"0x2a12fd3d8235c25c062dc9652970ef9f635636c4018df0909e1a51c673e125cb","price_changes":[{"asset_id":"56386988715176239099720172290594769295756680374928571099138069977179519358166","price":"0.11","size":"874.5","side":"BUY","hash":"64b64b3c45a9a35d103a8c511a002cfdcdf48308","best_bid":"0.12","best_ask":"0.14"},{"asset_id":"63670753354844494163057275310194312729998307779831462269530137743341854359908","price":"0.89","size":"874.5","side":"SELL","hash":"6ff8fd1ce4ee2d7175b2c9d684796ee386cb545f","best_bid":"0.86","best_ask":"0.88"}],"timestamp":"1768250241105","event_type":"price_change"}}
{"schema_version":1,"source":"clob_ws_market","recv_ts_ns":1768250241241233779,"event_type":"price_change","market":"0x2a12fd3d8235c25c062dc9652970ef9f635636c4018df0909e1a51c673e125cb","server_ts_ms":1768250241106,"raw":{"market":"0x2a12fd3d8235c25c062dc9652970ef9f635636c4018df0909e1a51c673e125cb","price_changes":[{"asset_id":"63670753354844494163057275310194312729998307779831462269530137743341854359908","price":"0.86","size":"1147.13","side":"BUY","hash":"bf88769c8758bc019bccdc5feb7fb977865e5a27","best_bid":"0.86","best_ask":"0.88"},{"asset_id":"56386988715176239099720172290594769295756680374928571099138069977179519358166","price":"0.14","size":"1147.13","side":"SELL","hash":"1e1d26a6bf9eec80d94b09fd310e2ce675364fe6","best_bid":"0.12","best_ask":"0.14"}],"timestamp":"1768250241106","event_type":"price_change"}}
{"schema_version":1,"source":"clob_ws_market","recv_ts_ns":1768250241248066183,"event_type":"price_change","market":"0x2a12fd3d8235c25c062dc9652970ef9f635636c4018df0909e1a51c673e125cb","server_ts_ms":1768250241107,"raw":{"market":"0x2a12fd3d8235c25c062dc9652970ef9f635636c4018df0909e1a51c673e125cb","price_changes":[{"asset_id":"56386988715176239099720172290594769295756680374928571099138069977179519358166","price":"0.08","size":"1541.75","side":"BUY","hash":"0cbe4ee400d0daae55e3da6883414441e12a7fff","best_bid":"0.12","best_ask":"0.14"},{"asset_id":"63670753354844494163057275310194312729998307779831462269530137743341854359908","price":"0.92","size":"1541.75","side":"SELL","hash":"454b56d75b06cae729faadfd6b131fc24d46b3a4","best_bid":"0.86","best_ask":"0.88"}],"timestamp":"1768250241107","event_type":"price_change"}}
{"schema_version":1,"source":"clob_ws_market","recv_ts_ns":1768250241251191933,"event_type":"price_change","market":"0x2a12fd3d8235c25c062dc9652970ef9f635636c4018df0909e1a51c673e125cb","server_ts_ms":1768250241108,"raw":{"market":"0x2a12fd3d8235c25c062dc9652970ef9f635636c4018df0909e1a51c673e125cb","price_changes":[{"asset_id":"63670753354844494163057275310194312729998307779831462269530137743341854359908","price":"0.86","size":"1137.13","side":"BUY","hash":"ddd95a418ac83d71ef0aec07279e8d66daef7814","best_bid":"0.86","best_ask":"0.88"},{"asset_id":"56386988715176239099720172290594769295756680374928571099138069977179519358166","price":"0.14","size":"1137.13","side":"SELL","hash":"85bf7250409a513b1c87741374ae8be02c5b92df","best_bid":"0.12","best_ask":"0.14"}],"timestamp":"1768250241108","event_type":"price_change"}}
{"schema_version":1,"source":"clob_ws_market","recv_ts_ns":1768250241256407010,"event_type":"price_change","market":"0x2a12fd3d8235c25c062dc9652970ef9f635636c4018df0909e1a51c673e125cb","server_ts_ms":1768250241109,"raw":{"market":"0x2a12fd3d8235c25c062dc9652970ef9f635636c4018df0909e1a51c673e125cb","price_changes":[{"asset_id":"56386988715176239099720172290594769295756680374928571099138069977179519358166","price":"0.07","size":"1406.28","side":"BUY","hash":"005076cf0ac4f1796f7440aca29f2ffebc1294e8","best_bid":"0.12","best_ask":"0.14"},{"asset_id":"63670753354844494163057275310194312729998307779831462269530137743341854359908","price":"0.93","size":"1406.28","side":"SELL","hash":"39c042563d3ffef0368b690c0d22b2e56041ddeb","best_bid":"0.86","best_ask":"0.88"}],"timestamp":"1768250241109","event_type":"price_change"}}
{"schema_version":1,"source":"clob_ws_market","recv_ts_ns":1768250241260696692,"event_type":"price_change","market":"0x2a12fd3d8235c25c062dc9652970ef9f635636c4018df0909e1a51c673e125cb","server_ts_ms":1768250241109,"raw":{"market":"0x2a12fd3d8235c25c062dc9652970ef9f635636c4018df0909e1a51c673e125cb","price_changes":[{"asset_id":"56386988715176239099720172290594769295756680374928571099138069977179519358166","price":"0.09","size":"1377","side":"BUY","hash":"754666ee64cdce2050d905f678cd9218fa9008ea","best_bid":"0.12","best_ask":"0.14"},{"asset_id":"63670753354844494163057275310194312729998307779831462269530137743341854359908","price":"0.91","size":"1377","side":"SELL","hash":"b5bb336580d34685eb9a72a5a93d0aa5d0c8ea55","best_bid":"0.86","best_ask":"0.88"}],"timestamp":"1768250241109","event_type":"price_change"}}
{"schema_version":1,"source":"clob_ws_market","recv_ts_ns":1768250241269353673,"event_type":"price_change","market":"0x2a12fd3d8235c25c062dc9652970ef9f635636c4018df0909e1a51c673e125cb","server_ts_ms":1768250241112,"raw":{"market":"0x2a12fd3d8235c25c062dc9652970ef9f635636c4018df0909e1a51c673e125cb","price_changes":[{"asset_id":"56386988715176239099720172290594769295756680374928571099138069977179519358166","price":"0.1","size":"3444.5","side":"BUY","hash":"ec0d66b753df4532d69b5fd184dd894fcdd061ee","best_bid":"0.12","best_ask":"0.14"},{"asset_id":"63670753354844494163057275310194312729998307779831462269530137743341854359908","price":"0.9","size":"3444.5","side":"SELL","hash":"acbc83b3527b551c270c86974c5d2165183dff63","best_bid":"0.86","best_ask":"0.88"}],"timestamp":"1768250241112","event_type":"price_change"}}
{"schema_version":1,"source":"clob_ws_market","recv_ts_ns":1768250241276635789,"event_type":"price_change","market":"0x2a12fd3d8235c25c062dc9652970ef9f635636c4018df0909e1a51c673e125cb","server_ts_ms":1768250241112,"raw":{"market":"0x2a12fd3d8235c25c062dc9652970ef9f635636c4018df0909e1a51c673e125cb","price_changes":[{"asset_id":"63670753354844494163057275310194312729998307779831462269530137743341854359908","price":"0.83","size":"869.52","side":"BUY","hash":"bcd50c10bd479d8798fa70b9da29f3d2c8f40c64","best_bid":"0.86","best_ask":"0.88"},{"asset_id":"56386988715176239099720172290594769295756680374928571099138069977179519358166","price":"0.17","size":"869.52","side":"SELL","hash":"821127917f1dd93acf7f6e5fc9a37af3df6e70e6","best_bid":"0.12","best_ask":"0.14"}],"timestamp":"1768250241112","event_type":"price_change"}}
{"schema_version":1,"source":"clob_ws_market","recv_ts_ns":1768250241280014201,"event_type":"price_change","market":"0x2a12fd3d8235c25c062dc9652970ef9f635636c4018df0909e1a51c673e125cb","server_ts_ms":1768250241113,"raw":{"market":"0x2a12fd3d8235c25c062dc9652970ef9f635636c4018df0909e1a51c673e125cb","price_changes":[{"asset_id":"56386988715176239099720172290594769295756680374928571099138069977179519358166","price":"0.08","size":"1531.75","side":"BUY","hash":"2caa97942d4938cf0831f4db61561dfb33e7b928","best_bid":"0.12","best_ask":"0.14"},{"asset_id":"63670753354844494163057275310194312729998307779831462269530137743341854359908","price":"0.92","size":"1531.75","side":"SELL","hash":"c8595c46a0e795fd1521ca49ab23b12b40ec4bb8","best_bid":"0.86","best_ask":"0.88"}],"timestamp":"1768250241113","event_type":"price_change"}}
{"schema_version":1,"source":"clob_ws_market","recv_ts_ns":1768250241287570472,"event_type":"price_change","market":"0x2a12fd3d8235c25c062dc9652970ef9f635636c4018df0909e1a51c673e125cb","server_ts_ms":1768250241115,"raw":{"market":"0x2a12fd3d8235c25c062dc9652970ef9f635636c4018df0909e1a51c673e125cb","price_changes":[{"asset_id":"63670753354844494163057275310194312729998307779831462269530137743341854359908","price":"0.86","size":"1127.13","side":"BUY","hash":"387aa317afbb9b5acec6fdd6d90f8c217d9a109e","best_bid":"0.86","best_ask":"0.88"},{"asset_id":"56386988715176239099720172290594769295756680374928571099138069977179519358166","price":"0.14","size":"1127.13","side":"SELL","hash":"33c74ef88b5052e4654557380d2cc3d44921f8cd","best_bid":"0.12","best_ask":"0.14"}],"timestamp":"1768250241115","event_type":"price_change"}}
{"schema_version":1,"source":"clob_ws_market","recv_ts_ns":1768250241290780678,"event_type":"price_change","market":"0x2a12fd3d8235c25c062dc9652970ef9f635636c4018df0909e1a51c673e125cb","server_ts_ms":1768250241115,"raw":{"market":"0x2a12fd3d8235c25c062dc9652970ef9f635636c4018df0909e1a51c673e125cb","price_changes":[{"asset_id":"56386988715176239099720172290594769295756680374928571099138069977179519358166","price":"0.1","size":"3434.5","side":"BUY","hash":"b629569545a3bc0321233274d1f0eabc5102fba4","best_bid":"0.12","best_ask":"0.14"},{"asset_id":"63670753354844494163057275310194312729998307779831462269530137743341854359908","price":"0.9","size":"3434.5","side":"SELL","hash":"0fb474f59829ef055320ef65f2a53ce683ab7542","best_bid":"0.86","best_ask":"0.88"}],"timestamp":"1768250241115","event_type":"price_change"}}
{"schema_version":1,"source":"clob_ws_market","recv_ts_ns":1768250241294027441,"event_type":"price_change","market":"0x2a12fd3d8235c25c062dc9652970ef9f635636c4018df0909e1a51c673e125cb","server_ts_ms":1768250241118,"raw":{"market":"0x2a12fd3d8235c25c062dc9652970ef9f635636c4018df0909e1a51c673e125cb","price_changes":[{"asset_id":"56386988715176239099720172290594769295756680374928571099138069977179519358166","price":"0.11","size":"864.5","side":"BUY","hash":"6efa6c5e42a327a3b41364a1e77819be2fa535e2","best_bid":"0.12","best_ask":"0.14"},{"asset_id":"63670753354844494163057275310194312729998307779831462269530137743341854359908","price":"0.89","size":"864.5","side":"SELL","hash":"fee4e286cb73cf080248fe8f1592782d318df3ea","best_bid":"0.86","best_ask":"0.88"}],"timestamp":"1768250241118","event_type":"price_change"}}
{"schema_version":1,"source":"clob_ws_market","recv_ts_ns":1768250241297602234,"event_type":"price_change","market":"0x2a12fd3d8235c25c062dc9652970ef9f635636c4018df0909e1a51c673e125cb","server_ts_ms":1768250241119,"raw":{"market":"0x2a12fd3d8235c25c062dc9652970ef9f635636c4018df0909e1a51c673e125cb","price_changes":[{"asset_id":"56386988715176239099720172290594769295756680374928571099138069977179519358166","price":"0.17","size":"879.52","side":"SELL","hash":"00a79277d795ebf7832d76cf26cdd31473d1f87c","best_bid":"0.12","best_ask":"0.14"},{"asset_id":"63670753354844494163057275310194312729998307779831462269530137743341854359908","price":"0.83","size":"879.52","side":"BUY","hash":"303aba48fe7bf84ce73ac6534b039b6bb4b740df","best_bid":"0.86","best_ask":"0.88"}],"timestamp":"1768250241119","event_type":"price_change"}}
{"schema_version":1,"source":"clob_ws_market","recv_ts_ns":1768250241300926731,"event_type":"price_change","market":"0x2a12fd3d8235c25c062dc9652970ef9f635636c4018df0909e1a51c673e125cb","server_ts_ms":1768250241120,"raw":{"market":"0x2a12fd3d8235c25c062dc9652970ef9f635636c4018df0909e1a51c673e125cb","price_changes":[{"asset_id":"56386988715176239099720172290594769295756680374928571099138069977179519358166","price":"0.05","size":"3462","side":"BUY","hash":"ed127be30498f1704bcab843bc82bbe848fa99c4","best_bid":"0.12","best_ask":"0.14"},{"asset_id":"63670753354844494163057275310194312729998307779831462269530137743341854359908","price":"0.95","size":"3462","side":"SELL","hash":"37d5fe84045d0715eb9af019ba9b0ba0d113b165","best_bid":"0.86","best_ask":"0.88"}],"timestamp":"1768250241120","event_type":"price_change"}}
{"schema_version":1,"source":"clob_ws_market","recv_ts_ns":1768250241307543927,"event_type":"price_change","market":"0x2a12fd3d8235c25c062dc9652970ef9f635636c4018df0909e1a51c673e125cb","server_ts_ms":1768250241122,"raw":{"market":"0x2a12fd3d8235c25c062dc9652970ef9f635636c4018df0909e1a51c673e125cb","price_changes":[{"asset_id":"63670753354844494163057275310194312729998307779831462269530137743341854359908","price":"0.82","size":"261","side":"BUY","hash":"709b5750e284e1199d4608f6eec185d42dbd36ea","best_bid":"0.86","best_ask":"0.88"},{"asset_id":"56386988715176239099720172290594769295756680374928571099138069977179519358166","price":"0.18","size":"261","side":"SELL","hash":"b9f4b198b1fcd82a643d283cd108b753ca526768","best_bid":"0.12","best_ask":"0.14"}],"timestamp":"1768250241122","event_type":"price_change"}}
{"schema_version":1,"source":"clob_ws_market","recv_ts_ns":1768250241315651768,"event_type":"price_change","market":"0x2a12fd3d8235c25c062dc9652970ef9f635636c4018df0909e1a51c673e125cb","server_ts_ms":1768250241131,"raw":{"market":"0x2a12fd3d8235c25c062dc9652970ef9f635636c4018df0909e1a51c673e125cb","price_changes":[{"asset_id":"56386988715176239099720172290594769295756680374928571099138069977179519358166","price":"0.06","size":"1409.5","side":"BUY","hash":"0d9207dbe12be38949d766614c16c877465c7bdc","best_bid":"0.12","best_ask":"0.14"},{"asset_id":"63670753354844494163057275310194312729998307779831462269530137743341854359908","price":"0.94","size":"1409.5","side":"SELL","hash":"3509b6845528fcc795196966d278b06e4d409eab","best_bid":"0.86","best_ask":"0.88"}],"timestamp":"1768250241131","event_type":"price_change"}}
{"schema_version":1,"source":"clob_ws_market","recv_ts_ns":1768250241321886013,"event_type":"price_change","market":"0x2a12fd3d8235c25c062dc9652970ef9f635636c4018df0909e1a51c673e125cb","server_ts_ms":1768250241132,"raw":{"market":"0x2a12fd3d8235c25c062dc9652970ef9f635636c4018df0909e1a51c673e125cb","price_changes":[{"asset_id":"63670753354844494163057275310194312729998307779831462269530137743341854359908","price":"0.8","size":"975.9","side":"BUY","hash":"9ed796c4fc1afbd1cba2fd60ee3b9a038b2f3f66","best_bid":"0.86","best_ask":"0.88"},{"asset_id":"56386988715176239099720172290594769295756680374928571099138069977179519358166","price":"0.2","size":"975.9","side":"SELL","hash":"0e661b71b15ee2f3b95b623e54fdc4d98898b083","best_bid":"0.12","best_ask":"0.14"}],"timestamp":"1768250241132","event_type":"price_change"}}
{"schema_version":1,"source":"clob_ws_market","recv_ts_ns":1768250241324716538,"event_type":"price_change","market":"0x2a12fd3d8235c25c062dc9652970ef9f635636c4018df0909e1a51c673e125cb","server_ts_ms":1768250241132,"raw":{"market":"0x2a12fd3d8235c25c062dc9652970ef9f635636c4018df0909e1a51c673e125cb","price_changes":[{"asset_id":"63670753354844494163057275310194312729998307779831462269530137743341854359908","price":"0.91","size":"1372","side":"SELL","hash":"9ed796c4fc1afbd1cba2fd60ee3b9a038b2f3f66","best_bid":"0.86","best_ask":"0.88"},{"asset_id":"56386988715176239099720172290594769295756680374928571099138069977179519358166","price":"0.09","size":"1372","side":"BUY","hash":"0e661b71b15ee2f3b95b623e54fdc4d98898b083","best_bid":"0.12","best_ask":"0.14"}],"timestamp":"1768250241132","event_type":"price_change"}}
{"schema_version":1,"source":"clob_ws_market","recv_ts_ns":1768250241335099738,"event_type":"price_change","market":"0x2a12fd3d8235c25c062dc9652970ef9f635636c4018df0909e1a51c673e125cb","server_ts_ms":1768250241136,"raw":{"market":"0x2a12fd3d8235c25c062dc9652970ef9f635636c4018df0909e1a51c673e125cb","price_changes":[{"asset_id":"63670753354844494163057275310194312729998307779831462269530137743341854359908","price":"0.86","size":"1117.13","side":"BUY","hash":"cfa7cb4e1a37a9f1e60dd1f0fc69cd2a13d5b4b4","best_bid":"0.86","best_ask":"0.88"},{"asset_id":"56386988715176239099720172290594769295756680374928571099138069977179519358166","price":"0.14","size":"1117.13","side":"SELL","hash":"e9abee2f265beacc2e54e4dbb8b9d5ba0d6d7f09","best_bid":"0.12","best_ask":"0.14"}],"timestamp":"1768250241136","event_type":"price_change"}}
{"schema_version":1,"source":"clob_ws_market","recv_ts_ns":1768250241338285179,"event_type":"price_change","market":"0x2a12fd3d8235c25c062dc9652970ef9f635636c4018df0909e1a51c673e125cb","server_ts_ms":1768250241137,"raw":{"market":"0x2a12fd3d8235c25c062dc9652970ef9f635636c4018df0909e1a51c673e125cb","price_changes":[{"asset_id":"56386988715176239099720172290594769295756680374928571099138069977179519358166","price":"0.12","size":"928.25","side":"BUY","hash":"2e9de20415d8a22922e04ce6d6366200f82d1eec","best_bid":"0.12","best_ask":"0.14"},{"asset_id":"63670753354844494163057275310194312729998307779831462269530137743341854359908","price":"0.88","size":"928.25","side":"SELL","hash":"7ba42ecdb7722100e3a7c2df61be6492aedcfc8d","best_bid":"0.86","best_ask":"0.88"}],"timestamp":"1768250241137","event_type":"price_change"}}
{"schema_version":1,"source":"clob_ws_market","recv_ts_ns":1768250241352139238,"event_type":"price_change","market":"0x2a12fd3d8235c25c062dc9652970ef9f635636c4018df0909e1a51c673e125cb","server_ts_ms":1768250241140,"raw":{"market":"0x2a12fd3d8235c25c062dc9652970ef9f635636c4018df0909e1a51c673e125cb","price_changes":[{"asset_id":"56386988715176239099720172290594769295756680374928571099138069977179519358166","price":"0.14","size":"1122.63","side":"SELL","hash":"f1952e62705664e62c5c6fdfa69242885337e420","best_bid":"0.12","best_ask":"0.14"},{"asset_id":"63670753354844494163057275310194312729998307779831462269530137743341854359908","price":"0.86","size":"1122.63","side":"BUY","hash":"17fd27625cb998dfd8ee49c83e25e7b6eed0773c","best_bid":"0.86","best_ask":"0.88"}],"timestamp":"1768250241140","event_type":"price_change"}}
{"schema_version":1,"source":"clob_ws_market","recv_ts_ns":1768250241364785867,"event_type":"price_change","market":"0x2a12fd3d8235c25c062dc9652970ef9f635636c4018df0909e1a51c673e125cb","server_ts_ms":1768250241144,"raw":{"market":"0x2a12fd3d8235c25c062dc9652970ef9f635636c4018df0909e1a51c673e125cb","price_changes":[{"asset_id":"63670753354844494163057275310194312729998307779831462269530137743341854359908","price":"0.85","size":"199.99","side":"BUY","hash":"ae711e784dc89fa1b633936baaa1fbc77b0d573b","best_bid":"0.86","best_ask":"0.88"},{"asset_id":"56386988715176239099720172290594769295756680374928571099138069977179519358166","price":"0.15","size":"199.99","side":"SELL","hash":"0c2cf82b556d79db88f0a624e3dcc6c85247d130","best_bid":"0.12","best_ask":"0.14"}],"timestamp":"1768250241144","event_type":"price_change"}}
{"schema_version":1,"source":"clob_ws_market","recv_ts_ns":1768250241367824155,"event_type":"price_change","market":"0x2a12fd3d8235c25c062dc9652970ef9f635636c4018df0909e1a51c673e125cb","server_ts_ms":1768250241145,"raw":{"market":"0x2a12fd3d8235c25c062dc9652970ef9f635636c4018df0909e1a51c673e125cb","price_changes":[{"asset_id":"63670753354844494163057275310194312729998307779831462269530137743341854359908","price":"0.85","size":"209.99","side":"BUY","hash":"438a9f55b75832bbaa20f408766ac5a341522305","best_bid":"0.86","best_ask":"0.88"},{"asset_id":"56386988715176239099720172290594769295756680374928571099138069977179519358166","price":"0.15","size":"209.99","side":"SELL","hash":"810efe4a53da51b9a4f8122fe674d8ccf8a65e09","best_bid":"0.12","best_ask":"0.14"}],"timestamp":"1768250241145","event_type":"price_change"}}
{"schema_version":1,"source":"clob_ws_market","recv_ts_ns":1768250241371475078,"event_type":"price_change","market":"0x2a12fd3d8235c25c062dc9652970ef9f635636c4018df0909e1a51c673e125cb","server_ts_ms":1768250241146,"raw":{"market":"0x2a12fd3d8235c25c062dc9652970ef9f635636c4018df0909e1a51c673e125cb","price_changes":[{"asset_id":"56386988715176239099720172290594769295756680374928571099138069977179519358166","price":"0.11","size":"874.5","side":"BUY","hash":"d7b3b115e54b677dd37fbccdb7df640feac4aa13","best_bid":"0.12","best_ask":"0.14"},{"asset_id":"63670753354844494163057275310194312729998307779831462269530137743341854359908","price":"0.89","size":"874.5","side":"SELL","hash":"d2908a0061c6581bbbde7aaf9fbd52531cdeb2b0","best_bid":"0.86","best_ask":"0.88"}],"timestamp":"1768250241146","event_type":"price_change"}}
{"schema_version":1,"source":"clob_ws_market","recv_ts_ns":1768250241374627091,"event_type":"price_change","market":"0x2a12fd3d8235c25c062dc9652970ef9f635636c4018df0909e1a51c673e125cb","server_ts_ms":1768250241147,"raw":{"market":"0x2a12fd3d8235c25c062dc9652970ef9f635636c4018df0909e1a51c673e125cb","price_changes":[{"asset_id":"63670753354844494163057275310194312729998307779831462269530137743341854359908","price":"0.88","size":"943.25","side":"SELL","hash":"cb44b9dd1a39791eb8bb2fbea6d8a042dd296745","best_bid":"0.86","best_ask":"0.88"},{"asset_id":"56386988715176239099720172290594769295756680374928571099138069977179519358166","price":"0.12","size":"943.25","side":"BUY","hash":"cb79862ad3ac6cc07f4886430d1e2ce43c8751c8","best_bid":"0.12","best_ask":"0.14"}],"timestamp":"1768250241147","event_type":"price_change"}}
{"schema_version":1,"source":"clob_ws_market","recv_ts_ns":1768250241377387979,"event_type":"price_change","market":"0x2a12fd3d8235c25c062dc9652970ef9f635636c4018df0909e1a51c673e125cb","server_ts_ms":1768250241147,"raw":{"market":"0x2a12fd3d8235c25c062dc9652970ef9f635636c4018df0909e1a51c673e125cb","price_changes":[{"asset_id":"56386988715176239099720172290594769295756680374928571099138069977179519358166","price":"0.1","size":"3444.5","side":"BUY","hash":"8e7fafa9024a2f1e3b9e1d31828bb984719d9645","best_bid":"0.12","best_ask":"0.14"},{"asset_id":"63670753354844494163057275310194312729998307779831462269530137743341854359908","price":"0.9","size":"3444.5","side":"SELL","hash":"91d65063ddd99754d35bd696e45dae9305204aaa","best_bid":"0.86","best_ask":"0.88"}],"timestamp":"1768250241147","event_type":"price_change"}}
{"schema_version":1,"source":"clob_ws_market","recv_ts_ns":1768250241384429727,"event_type":"price_change","market":"0x2a12fd3d8235c25c062dc9652970ef9f635636c4018df0909e1a51c673e125cb","server_ts_ms":1768250241148,"raw":{"market":"0x2a12fd3d8235c25c062dc9652970ef9f635636c4018df0909e1a51c673e125cb","price_changes":[{"asset_id":"56386988715176239099720172290594769295756680374928571099138069977179519358166","price":"0.09","size":"1382","side":"BUY","hash":"7c83bcb2b40edf5819300831854334dad75d17fc","best_bid":"0.12","best_ask":"0.14"},{"asset_id":"63670753354844494163057275310194312729998307779831462269530137743341854359908","price":"0.91","size":"1382","side":"SELL","hash":"66b064dc7d0ec5259ac88ae4d194a49712d24e70","best_bid":"0.86","best_ask":"0.88"}],"timestamp":"1768250241148","event_type":"price_change"}}
{"schema_version":1,"source":"clob_ws_market","recv_ts_ns":1768250241391084694,"event_type":"price_change","market":"0x2a12fd3d8235c25c062dc9652970ef9f635636c4018df0909e1a51c673e125cb","server_ts_ms":1768250241149,"raw":{"market":"0x2a12fd3d8235c25c062dc9652970ef9f635636c4018df0909e1a51c673e125cb","price_changes":[{"asset_id":"63670753354844494163057275310194312729998307779831462269530137743341854359908","price":"0.85","size":"219.99","side":"BUY","hash":"6f30abbf2e38d763083ccd3e80c20d8bc0a01eae","best_bid":"0.86","best_ask":"0.88"},{"asset_id":"56386988715176239099720172290594769295756680374928571099138069977179519358166","price":"0.15","size":"219.99","side":"SELL","hash":"e38e8f6d5388d36eb631ed8b0527f93ebb5f8f33","best_bid":"0.12","best_ask":"0.14"}],"timestamp":"1768250241149","event_type":"price_change"}}
{"schema_version":1,"source":"clob_ws_market","recv_ts_ns":1768250241394589220,"event_type":"price_change","market":"0x2a12fd3d8235c25c062dc9652970ef9f635636c4018df0909e1a51c673e125cb","server_ts_ms":1768250241150,"raw":{"market":"0x2a12fd3d8235c25c062dc9652970ef9f635636c4018df0909e1a51c673e125cb","price_changes":[{"asset_id":"56386988715176239099720172290594769295756680374928571099138069977179519358166","price":"0.09","size":"1392","side":"BUY","hash":"20c49631d8b1bf61ca2a81aa62308d4d5a4fd1d7","best_bid":"0.12","best_ask":"0.14"},{"asset_id":"63670753354844494163057275310194312729998307779831462269530137743341854359908","price":"0.91","size":"1392","side":"SELL","hash":"66caa61d750cc072a300eb7e5f251565a05cac5a","best_bid":"0.86","best_ask":"0.88"}],"timestamp":"1768250241150","event_type":"price_change"}}
{"schema_version":1,"source":"clob_ws_market","recv_ts_ns":1768250241401079287,"event_type":"price_change","market":"0x2a12fd3d8235c25c062dc9652970ef9f635636c4018df0909e1a51c673e125cb","server_ts_ms":1768250241150,"raw":{"market":"0x2a12fd3d8235c25c062dc9652970ef9f635636c4018df0909e1a51c673e125cb","price_changes":[{"asset_id":"63670753354844494163057275310194312729998307779831462269530137743341854359908","price":"0.85","size":"225.49","side":"BUY","hash":"a015e1f54fccb3a5e3e5cd4fa9ff616c535e78e0","best_bid":"0.86","best_ask":"0.88"},{"asset_id":"56386988715176239099720172290594769295756680374928571099138069977179519358166","price":"0.15","size":"225.49","side":"SELL","hash":"d6b1b0dcd159031749cb371d7f643202aa7f585d","best_bid":"0.12","best_ask":"0.14"}],"timestamp":"1768250241150","event_type":"price_change"}}
{"schema_version":1,"source":"clob_ws_market","recv_ts_ns":1768250241405117504,"event_type":"price_change","market":"0x2a12fd3d8235c25c062dc9652970ef9f635636c4018df0909e1a51c673e125cb","server_ts_ms":1768250241151,"raw":{"market":"0x2a12fd3d8235c25c062dc9652970ef9f635636c4018df0909e1a51c673e125cb","price_changes":[{"asset_id":"56386988715176239099720172290594769295756680374928571099138069977179519358166","price":"0.1","size":"3409.5","side":"BUY","hash":"bacf7c5a0cc1c3063ec8666d103810cc23720df9","best_bid":"0.12","best_ask":"0.14"},{"asset_id":"63670753354844494163057275310194312729998307779831462269530137743341854359908","price":"0.9","size":"3409.5","side":"SELL","hash":"de43beb0edd7be33cff64d7de09a404d475fb2d8","best_bid":"0.86","best_ask":"0.88"}],"timestamp":"1768250241151","event_type":"price_change"}}
{"schema_version":1,"source":"clob_ws_market","recv_ts_ns":1768250241409131158,"event_type":"price_change","market":"0x2a12fd3d8235c25c062dc9652970ef9f635636c4018df0909e1a51c673e125cb","server_ts_ms":1768250241151,"raw":{"market":"0x2a12fd3d8235c25c062dc9652970ef9f635636c4018df0909e1a51c673e125cb","price_changes":[{"asset_id":"56386988715176239099720172290594769295756680374928571099138069977179519358166","price":"0.12","size":"908.25","side":"BUY","hash":"bacf7c5a0cc1c3063ec8666d103810cc23720df9","best_bid":"0.12","best_ask":"0.14"},{"asset_id":"63670753354844494163057275310194312729998307779831462269530137743341854359908","price":"0.88","size":"908.25","side":"SELL","hash":"de43beb0edd7be33cff64d7de09a404d475fb2d8","best_bid":"0.86","best_ask":"0.88"}],"timestamp":"1768250241151","event_type":"price_change"}}
{"schema_version":1,"source":"clob_ws_market","recv_ts_ns":1768250241412066764,"event_type":"price_change","market":"0x2a12fd3d8235c25c062dc9652970ef9f635636c4018df0909e1a51c673e125cb","server_ts_ms":1768250241151,"raw":{"market":"0x2a12fd3d8235c25c062dc9652970ef9f635636c4018df0909e1a51c673e125cb","price_changes":[{"asset_id":"56386988715176239099720172290594769295756680374928571099138069977179519358166","price":"0.08","size":"1496.75","side":"BUY","hash":"bacf7c5a0cc1c3063ec8666d103810cc23720df9","best_bid":"0.12","best_ask":"0.14"},{"asset_id":"63670753354844494163057275310194312729998307779831462269530137743341854359908","price":"0.92","size":"1496.75","side":"SELL","hash":"de43beb0edd7be33cff64d7de09a404d475fb2d8","best_bid":"0.86","best_ask":"0.88"}],"timestamp":"1768250241151","event_type":"price_change"}}
{"schema_version":1,"source":"clob_ws_market","recv_ts_ns":1768250241419165267,"event_type":"price_change","market":"0x2a12fd3d8235c25c062dc9652970ef9f635636c4018df0909e1a51c673e125cb","server_ts_ms":1768250241152,"raw":{"market":"0x2a12fd3d8235c25c062dc9652970ef9f635636c4018df0909e1a51c673e125cb","price_changes":[{"asset_id":"63670753354844494163057275310194312729998307779831462269530137743341854359908","price":"0.89","size":"864.5","side":"SELL","hash":"24f577a46a3fc5394f4b9389be0d11217546679f","best_bid":"0.86","best_ask":"0.88"},{"asset_id":"56386988715176239099720172290594769295756680374928571099138069977179519358166","price":"0.11","size":"864.5","side":"BUY","hash":"0a21f491b79f2ab0f16630fdb32ef20b4f90e8dd","best_bid":"0.12","best_ask":"0.14"}],"timestamp":"1768250241152","event_type":"price_change"}}
{"schema_version":1,"source":"clob_ws_market","recv_ts_ns":1768250241431016567,"event_type":"price_change","market":"0x2a12fd3d8235c25c062dc9652970ef9f635636c4018df0909e1a51c673e125cb","server_ts_ms":1768250241154,"raw":{"market":"0x2a12fd3d8235c25c062dc9652970ef9f635636c4018df0909e1a51c673e125cb","price_changes":[{"asset_id":"63670753354844494163057275310194312729998307779831462269530137743341854359908","price":"0.9","size":"3402","side":"SELL","hash":"f5958b8bbea9786ffe322ace2a18dd1430c6fd72","best_bid":"0.86","best_ask":"0.88"},{"asset_id":"56386988715176239099720172290594769295756680374928571099138069977179519358166","price":"0.1","size":"3402","side":"BUY","hash":"e9ccfcf806cf1eb3206642aca5ac29741d22168c","best_bid":"0.12","best_ask":"0.14"}],"timestamp":"1768250241154","event_type":"price_change"}}
{"schema_version":1,"source":"clob_ws_market","recv_ts_ns":1768250241434709081,"event_type":"price_change","market":"0x2a12fd3d8235c25c062dc9652970ef9f635636c4018df0909e1a51c673e125cb","server_ts_ms":1768250241155,"raw":{"market":"0x2a12fd3d8235c25c062dc9652970ef9f635636c4018df0909e1a51c673e125cb","price_changes":[{"asset_id":"56386988715176239099720172290594769295756680374928571099138069977179519358166","price":"0.11","size":"874.5","side":"BUY","hash":"0030042064c3f1690044e0d19be3339c1cdba1a6","best_bid":"0.12","best_ask":"0.14"},{"asset_id":"63670753354844494163057275310194312729998307779831462269530137743341854359908","price":"0.89","size":"874.5","side":"SELL","hash":"fae307bcf6d403508f9c206abf3cce1c9ee59afb","best_bid":"0.86","best_ask":"0.88"}],"timestamp":"1768250241155","event_type":"price_change"}}
{"schema_version":1,"source":"clob_ws_market","recv_ts_ns":1768250241438750557,"event_type":"best_bid_ask","market":"0x2a12fd3d8235c25c062dc9652970ef9f635636c4018df0909e1a51c673e125cb","server_ts_ms":1768250241156,"raw":{"market":"0x2a12fd3d8235c25c062dc9652970ef9f635636c4018df0909e1a51c673e125cb","asset_id":"56386988715176239099720172290594769295756680374928571099138069977179519358166","best_bid":"0.13","best_ask":"0.14","spread":"0.01","timestamp":"1768250241156","event_type":"best_bid_ask"}}
{"schema_version":1,"source":"clob_ws_market","recv_ts_ns":1768250241442312211,"event_type":"price_change","market":"0x2a12fd3d8235c25c062dc9652970ef9f635636c4018df0909e1a51c673e125cb","server_ts_ms":1768250241156,"raw":{"market":"0x2a12fd3d8235c25c062dc9652970ef9f635636c4018df0909e1a51c673e125cb","price_changes":[{"asset_id":"63670753354844494163057275310194312729998307779831462269530137743341854359908","price":"0.87","size":"7.5","side":"SELL","hash":"5608dfd1bb0c3689c8031181cfcc8e90497fbbd1","best_bid":"0.86","best_ask":"0.87"},{"asset_id":"56386988715176239099720172290594769295756680374928571099138069977179519358166","price":"0.13","size":"7.5","side":"BUY","hash":"89281150fd2a642acd609b0911e080607c0cf54a","best_bid":"0.13","best_ask":"0.14"}],"timestamp":"1768250241156","event_type":"price_change"}}
{"schema_version":1,"source":"clob_ws_market","recv_ts_ns":1768250241456700741,"event_type":"price_change","market":"0x2a12fd3d8235c25c062dc9652970ef9f635636c4018df0909e1a51c673e125cb","server_ts_ms":1768250241158,"raw":{"market":"0x2a12fd3d8235c25c062dc9652970ef9f635636c4018df0909e1a51c673e125cb","price_changes":[{"asset_id":"63670753354844494163057275310194312729998307779831462269530137743341854359908","price":"0.85","size":"235.49","side":"BUY","hash":"5eddb58f0c45fb72e30a9565b50a0896ffb82a19","best_bid":"0.86","best_ask":"0.87"},{"asset_id":"56386988715176239099720172290594769295756680374928571099138069977179519358166","price":"0.15","size":"235.49","side":"SELL","hash":"ac5afc6e31d4c55bf7379c29d68d5da55ca60c50","best_bid":"0.13","best_ask":"0.14"}],"timestamp":"1768250241158","event_type":"price_change"}}
{"schema_version":1,"source":"clob_ws_market","recv_ts_ns":1768250241464219844,"event_type":"price_change","market":"0x2a12fd3d8235c25c062dc9652970ef9f635636c4018df0909e1a51c673e125cb","server_ts_ms":1768250241159,"raw":{"market":"0x2a12fd3d8235c25c062dc9652970ef9f635636c4018df0909e1a51c673e125cb","price_changes":[{"asset_id":"63670753354844494163057275310194312729998307779831462269530137743341854359908","price":"0.79","size":"975.5","side":"BUY","hash":"7bdf93d84bbf03d3dba05c1c96078b14d2f47a85","best_bid":"0.86","best_ask":"0.87"},{"asset_id":"56386988715176239099720172290594769295756680374928571099138069977179519358166","price":"0.21","size":"975.5","side":"SELL","hash":"bb76adca72beb9798fd39d0a2b4eca8f8725f012","best_bid":"0.13","best_ask":"0.14"}],"timestamp":"1768250241159","event_type":"price_change"}}
{"schema_version":1,"source":"clob_ws_market","recv_ts_ns":1768250241472375845,"event_type":"price_change","market":"0x2a12fd3d8235c25c062dc9652970ef9f635636c4018df0909e1a51c673e125cb","server_ts_ms":1768250241160,"raw":{"market":"0x2a12fd3d8235c25c062dc9652970ef9f635636c4018df0909e1a51c673e125cb","price_changes":[{"asset_id":"63670753354844494163057275310194312729998307779831462269530137743341854359908","price":"0.9","size":"3408","side":"SELL","hash":"8abc5d660f932fd6d5c02a0b8155afac75fe1eac","best_bid":"0.86","best_ask":"0.87"},{"asset_id":"56386988715176239099720172290594769295756680374928571099138069977179519358166","price":"0.1","size":"3408","side":"BUY","hash":"7668b9819018c299ccc061979a99f0d4753a552c","best_bid":"0.13","best_ask":"0.14"}],"timestamp":"1768250241160","event_type":"price_change"}}
{"schema_version":1,"source":"clob_ws_market","recv_ts_ns":1768250241480686763,"event_type":"price_change","market":"0x2a12fd3d8235c25c062dc9652970ef9f635636c4018df0909e1a51c673e125cb","server_ts_ms":1768250241161,"raw":{"market":"0x2a12fd3d8235c25c062dc9652970ef9f635636c4018df0909e1a51c673e125cb","price_changes":[{"asset_id":"56386988715176239099720172290594769295756680374928571099138069977179519358166","price":"0.13","size":"168.5","side":"BUY","hash":"bb60c621ba6f6852c8e35d43026205d8a60a15da","best_bid":"0.13","best_ask":"0.14"},{"asset_id":"63670753354844494163057275310194312729998307779831462269530137743341854359908","price":"0.87","size":"168.5","side":"SELL","hash":"c1bf979a0025cdd04f90c713cb7b740204563944","best_bid":"0.86","best_ask":"0.87"}],"timestamp":"1768250241161","event_type":"price_change"}}
{"schema_version":1,"source":"clob_ws_market","recv_ts_ns":1768250241484172572,"event_type":"price_change","market":"0x2a12fd3d8235c25c062dc9652970ef9f635636c4018df0909e1a51c673e125cb","server_ts_ms":1768250241163,"raw":{"market":"0x2a12fd3d8235c25c062dc9652970ef9f635636c4018df0909e1a51c673e125cb","price_changes":[{"asset_id":"63670753354844494163057275310194312729998307779831462269530137743341854359908","price":"0.82","size":"171","side":"BUY","hash":"0ae382448a562858a57f35367352c0441de57972","best_bid":"0.86","best_ask":"0.87"},{"asset_id":"56386988715176239099720172290594769295756680374928571099138069977179519358166","price":"0.18","size":"171","side":"SELL","hash":"19d0ae605592faebb2f9ac8be245ba47900a7f97","best_bid":"0.13","best_ask":"0.14"}],"timestamp":"1768250241163","event_type":"price_change"}}
{"schema_version":1,"source":"clob_ws_market","recv_ts_ns":1768250241490390515,"event_type":"price_change","market":"0x2a12fd3d8235c25c062dc9652970ef9f635636c4018df0909e1a51c673e125cb","server_ts_ms":1768250241167,"raw":{"market":"0x2a12fd3d8235c25c062dc9652970ef9f635636c4018df0909e1a51c673e125cb","price_changes":[{"asset_id":"56386988715176239099720172290594769295756680374928571099138069977179519358166","price":"0.08","size":"1559.75","side":"BUY","hash":"9f9bb7c9f3f3ea37c1bd3fd7f59af8f1a5ed06b1","best_bid":"0.13","best_ask":"0.14"},{"asset_id":"63670753354844494163057275310194312729998307779831462269530137743341854359908","price":"0.92","size":"1559.75","side":"SELL","hash":"9fa33adb11ddc44d85414ac52f9296da5e16a486","best_bid":"0.86","best_ask":"0.87"}],"timestamp":"1768250241167","event_type":"price_change"}}
{"schema_version":1,"source":"clob_ws_market","recv_ts_ns":1768250241502225131,"event_type":"price_change","market":"0x2a12fd3d8235c25c062dc9652970ef9f635636c4018df0909e1a51c673e125cb","server_ts_ms":1768250241171,"raw":{"market":"0x2a12fd3d8235c25c062dc9652970ef9f635636c4018df0909e1a51c673e125cb","price_changes":[{"asset_id":"56386988715176239099720172290594769295756680374928571099138069977179519358166","price":"0.08","size":"1569.75","side":"BUY","hash":"0696205ec67651a1e538ffe2af1e0dbf3202ddd5","best_bid":"0.13","best_ask":"0.14"},{"asset_id":"63670753354844494163057275310194312729998307779831462269530137743341854359908","price":"0.92","size":"1569.75","side":"SELL","hash":"bddf00445df6106f38eae006a57f780d01cdfea3","best_bid":"0.86","best_ask":"0.87"}],"timestamp":"1768250241171","event_type":"price_change"}}
{"schema_version":1,"source":"clob_ws_market","recv_ts_ns":1768250241516254850,"event_type":"price_change","market":"0x2a12fd3d8235c25c062dc9652970ef9f635636c4018df0909e1a51c673e125cb","server_ts_ms":1768250241184,"raw":{"market":"0x2a12fd3d8235c25c062dc9652970ef9f635636c4018df0909e1a51c673e125cb","price_changes":[{"asset_id":"56386988715176239099720172290594769295756680374928571099138069977179519358166","price":"0.12","size":"918.25","side":"BUY","hash":"9b3990d6f7b7c1b5c67825738cec2f6ce9f44f1c","best_bid":"0.13","best_ask":"0.14"},{"asset_id":"63670753354844494163057275310194312729998307779831462269530137743341854359908","price":"0.88","size":"918.25","side":"SELL","hash":"1e854fefef71bfaee2e71b892c5cc7d656c42706","best_bid":"0.86","best_ask":"0.87"}],"timestamp":"1768250241184","event_type":"price_change"}}
{"schema_version":1,"source":"clob_ws_market","recv_ts_ns":1768250241524093130,"event_type":"price_change","market":"0x2a12fd3d8235c25c062dc9652970ef9f635636c4018df0909e1a51c673e125cb","server_ts_ms":1768250241188,"raw":{"market":"0x2a12fd3d8235c25c062dc9652970ef9f635636c4018df0909e1a51c673e125cb","price_changes":[{"asset_id":"63670753354844494163057275310194312729998307779831462269530137743341854359908","price":"0.85","size":"245.49","side":"BUY","hash":"e76659ce087b2efd686200dfd33bab006ab8252e","best_bid":"0.86","best_ask":"0.87"},{"asset_id":"56386988715176239099720172290594769295756680374928571099138069977179519358166","price":"0.15","size":"245.49","side":"SELL","hash":"93d91fc5bcef7ef7de26390caa72a0e49766a2da","best_bid":"0.13","best_ask":"0.14"}],"timestamp":"1768250241188","event_type":"price_change"}}
{"schema_version":1,"source":"clob_ws_market","recv_ts_ns":1768250241529571670,"event_type":"price_change","market":"0x2a12fd3d8235c25c062dc9652970ef9f635636c4018df0909e1a51c673e125cb","server_ts_ms":1768250241190,"raw":{"market":"0x2a12fd3d8235c25c062dc9652970ef9f635636c4018df0909e1a51c673e125cb","price_changes":[{"asset_id":"63670753354844494163057275310194312729998307779831462269530137743341854359908","price":"0.86","size":"1112.63","side":"BUY","hash":"9115c5726d35411cd9ac41c12a9b2703cc58b6c1","best_bid":"0.86","best_ask":"0.87"},{"asset_id":"56386988715176239099720172290594769295756680374928571099138069977179519358166","price":"0.14","size":"1112.63","side":"SELL","hash":"1a05101cff3cdf2b6f2cd56b58ee39eb4fffdcc6","best_bid":"0.13","best_ask":"0.14"}],"timestamp":"1768250241190","event_type":"price_change"}}
{"schema_version":1,"source":"clob_ws_market","recv_ts_ns":1768250241532483813,"event_type":"price_change","market":"0x2a12fd3d8235c25c062dc9652970ef9f635636c4018df0909e1a51c673e125cb","server_ts_ms":1768250241192,"raw":{"market":"0x2a12fd3d8235c25c062dc9652970ef9f635636c4018df0909e1a51c673e125cb","price_changes":[{"asset_id":"63670753354844494163057275310194312729998307779831462269530137743341854359908","price":"0.86","size":"1102.63","side":"BUY","hash":"6b669a2cfed18f0f94d3746324cd78c8d3e4f72f","best_bid":"0.86","best_ask":"0.87"},{"asset_id":"56386988715176239099720172290594769295756680374928571099138069977179519358166","price":"0.14","size":"1102.63","side":"SELL","hash":"38f31ec2189be0afb458bcc91457091d7da3f187","best_bid":"0.13","best_ask":"0.14"}],"timestamp":"1768250241192","event_type":"price_change"}}
{"schema_version":1,"source":"clob_ws_market","recv_ts_ns":1768250241539586379,"event_type":"price_change","market":"0x2a12fd3d8235c25c062dc9652970ef9f635636c4018df0909e1a51c673e125cb","server_ts_ms":1768250241199,"raw":{"market":"0x2a12fd3d8235c25c062dc9652970ef9f635636c4018df0909e1a51c673e125cb","price_changes":[{"asset_id":"63670753354844494163057275310194312729998307779831462269530137743341854359908","price":"0.88","size":"903.25","side":"SELL","hash":"c17a5f2db453cd9fde07c244822890c0c1bd048b","best_bid":"0.86","best_ask":"0.87"},{"asset_id":"56386988715176239099720172290594769295756680374928571099138069977179519358166","price":"0.12","size":"903.25","side":"BUY","hash":"244b28b8ff698176c3f97c126ea3043ac0fa6c24","best_bid":"0.13","best_ask":"0.14"}],"timestamp":"1768250241199","event_type":"price_change"}}
{"schema_version":1,"source":"clob_ws_market","recv_ts_ns":1768250241542713715,"event_type":"price_change","market":"0x2a12fd3d8235c25c062dc9652970ef9f635636c4018df0909e1a51c673e125cb","server_ts_ms":1768250241205,"raw":{"market":"0x2a12fd3d8235c25c062dc9652970ef9f635636c4018df0909e1a51c673e125cb","price_changes":[{"asset_id":"63670753354844494163057275310194312729998307779831462269530137743341854359908","price":"0.87","size":"173.5","side":"SELL","hash":"ab3f6523530915146b17dc9c5c63d69838e7f9d2","best_bid":"0.86","best_ask":"0.87"},{"asset_id":"56386988715176239099720172290594769295756680374928571099138069977179519358166","price":"0.13","size":"173.5","side":"BUY","hash":"d16456135249919220dd9fe145acb7b8c923cf30","best_bid":"0.13","best_ask":"0.14"}],"timestamp":"1768250241205","event_type":"price_change"}}
{"schema_version":1,"source":"clob_ws_market","recv_ts_ns":1768250241546110880,"event_type":"price_change","market":"0x2a12fd3d8235c25c062dc9652970ef9f635636c4018df0909e1a51c673e125cb","server_ts_ms":1768250241212,"raw":{"market":"0x2a12fd3d8235c25c062dc9652970ef9f635636c4018df0909e1a51c673e125cb","price_changes":[{"asset_id":"63670753354844494163057275310194312729998307779831462269530137743341854359908","price":"0.83","size":"1379.52","side":"BUY","hash":"6f0325efcd9a253251caee7c101e6cfdd3d3d1ca","best_bid":"0.86","best_ask":"0.87"},{"asset_id":"56386988715176239099720172290594769295756680374928571099138069977179519358166","price":"0.17","size":"1379.52","side":"SELL","hash":"fd1f97c141c4a006ccb06ace31a6c3f299f0ea1d","best_bid":"0.13","best_ask":"0.14"}],"timestamp":"1768250241212","event_type":"price_change"}}
{"schema_version":1,"source":"clob_ws_market","recv_ts_ns":1768250241549535435,"event_type":"price_change","market":"0x2a12fd3d8235c25c062dc9652970ef9f635636c4018df0909e1a51c673e125cb","server_ts_ms":1768250241213,"raw":{"market":"0x2a12fd3d8235c25c062dc9652970ef9f635636c4018df0909e1a51c673e125cb","price_changes":[{"asset_id":"63670753354844494163057275310194312729998307779831462269530137743341854359908","price":"0.82","size":"671","side":"BUY","hash":"2a849748e4fd1e2eaeaad3ad4b1aa4c3586146a4","best_bid":"0.86","best_ask":"0.87"},{"asset_id":"56386988715176239099720172290594769295756680374928571099138069977179519358166","price":"0.18","size":"671","side":"SELL","hash":"50778b765739d1997daf05b90d65a444aca5c3e4","best_bid":"0.13","best_ask":"0.14"}],"timestamp":"1768250241213","event_type":"price_change"}}
{"schema_version":1,"source":"clob_ws_market","recv_ts_ns":1768250241566272793,"event_type":"price_change","market":"0x2a12fd3d8235c25c062dc9652970ef9f635636c4018df0909e1a51c673e125cb","server_ts_ms":1768250241238,"raw":{"market":"0x2a12fd3d8235c25c062dc9652970ef9f635636c4018df0909e1a51c673e125cb","price_changes":[{"asset_id":"63670753354844494163057275310194312729998307779831462269530137743341854359908","price":"0.87","size":"183.5","side":"SELL","hash":"cf3d9d6ba30e108f5de37a67ce7c1045ad5a33d2","best_bid":"0.86","best_ask":"0.87"},{"asset_id":"56386988715176239099720172290594769295756680374928571099138069977179519358166","price":"0.13","size":"183.5","side":"BUY","hash":"dee0e0d27fe94a1e911a7280ef41067eef832dbe","best_bid":"0.13","best_ask":"0.14"}],"timestamp":"1768250241238","event_type":"price_change"}}
{"schema_version":1,"source":"clob_ws_market","recv_ts_ns":1768250241569334607,"event_type":"price_change","market":"0x2a12fd3d8235c25c062dc9652970ef9f635636c4018df0909e1a51c673e125cb","server_ts_ms":1768250241239,"raw":{"market":"0x2a12fd3d8235c25c062dc9652970ef9f635636c4018df0909e1a51c673e125cb","price_changes":[{"asset_id":"63670753354844494163057275310194312729998307779831462269530137743341854359908","price":"0.85","size":"255.49","side":"BUY","hash":"f44fd5ab7bb382fd5af15e0ed475dea60a47cb62","best_bid":"0.86","best_ask":"0.87"},{"asset_id":"56386988715176239099720172290594769295756680374928571099138069977179519358166","price":"0.15","size":"255.49","side":"SELL","hash":"c309da8029db95d8951c1b879ed7913353a659b7","best_bid":"0.13","best_ask":"0.14"}],"timestamp":"1768250241239","event_type":"price_change"}}
{"schema_version":1,"source":"clob_ws_market","recv_ts_ns":1768250241577385208,"event_type":"price_change","market":"0x2a12fd3d8235c25c062dc9652970ef9f635636c4018df0909e1a51c673e125cb","server_ts_ms":1768250241245,"raw":{"market":"0x2a12fd3d8235c25c062dc9652970ef9f635636c4018df0909e1a51c673e125cb","price_changes":[{"asset_id":"63670753354844494163057275310194312729998307779831462269530137743341854359908","price":"0.88","size":"897.75","side":"SELL","hash":"5ed37503c7698f69dcc8ac19b1d61b24dcb8f25f","best_bid":"0.86","best_ask":"0.87"},{"asset_id":"56386988715176239099720172290594769295756680374928571099138069977179519358166","price":"0.12","size":"897.75","side":"BUY","hash":"53e1ab051e2f2f0c45f72b1c122f17c3e38a4605","best_bid":"0.13","best_ask":"0.14"}],"timestamp":"1768250241245","event_type":"price_change"}}
