{"schema_version":1,"source":"clob_ws_market","recv_ts_ns":1768250241580904508,"event_type":"price_change","market":"0x2a12fd3d8235c25c062dc9652970ef9f635636c4018df0909e1a51c673e125cb","server_ts_ms":1768250241247,"raw":{"market":"0x2a12fd3d8235c25c062dc9652970ef9f635636c4018df0909e1a51c673e125cb","price_changes":[{"asset_id":"63670753354844494163057275310194312729998307779831462269530137743341854359908","price":"0.85","size":"265.49","side":"BUY","hash":"2f365222762b3909a96c7e9ef4b9007caf457c1e","best_bid":"0.86","best_ask":"0.87"},{"asset_id":"56386988715176239099720172290594769295756680374928571099138069977179519358166","price":"0.15","size":"265.49","side":"SELL","hash":"978a7b386e1e24f18418ea6f09d01554fa6e71f6","best_bid":"0.13","best_ask":"0.14"}],"timestamp":"1768250241247","event_type":"price_change"}}
{"schema_version":1,"source":"clob_ws_market","recv_ts_ns":1768250241584145736,"event_type":"price_change","market":"0x2a12fd3d8235c25c062dc9652970ef9f635636c4018df0909e1a51c673e125cb","server_ts_ms":1768250241250,"raw":{"market":"0x2a12fd3d8235c25c062dc9652970ef9f635636c4018df0909e1a51c673e125cb","price_changes":[{"asset_id":"56386988715176239099720172290594769295756680374928571099138069977179519358166","price":"0.12","size":"892.25","side":"BUY","hash":"dc5e32041560002448182e4a6ccb012b9d5e1516","best_bid":"0.13","best_ask":"0.14"},{"asset_id":"63670753354844494163057275310194312729998307779831462269530137743341854359908","price":"0.88","size":"892.25","side":"SELL","hash":"dfb66230a0e65309e12b7b5bdba0535f18cd1963","best_bid":"0.86","best_ask":"0.87"}],"timestamp":"1768250241250","event_type":"price_change"}}
{"schema_version":1,"source":"clob_ws_market","recv_ts_ns":1768250241589964466,"event_type":"price_change","market":"0x2a12fd3d8235c25c062dc9652970ef9f635636c4018df0909e1a51c673e125cb","server_ts_ms":1768250241255,"raw":{"market":"0x2a12fd3d8235c25c062dc9652970ef9f635636c4018df0909e1a51c673e125cb","price_changes":[{"asset_id":"56386988715176239099720172290594769295756680374928571099138069977179519358166","price":"0.12","size":"886.75","side":"BUY","hash":"db515e5834ec19893e7b9dd3d314f7878dd333dd","best_bid":"0.13","best_ask":"0.14"},{"asset_id":"63670753354844494163057275310194312729998307779831462269530137743341854359908","price":"0.88","size":"886.75","side":"SELL","hash":"96d57898a6759244a09a8b2cd7d0ab01e0e6b3f2","best_bid":"0.86","best_ask":"0.87"}],"timestamp":"1768250241255","event_type":"price_change"}}
{"schema_version":1,"source":"clob_ws_market","recv_ts_ns":1768250241594569593,"event_type":"price_change","market":"0x2a12fd3d8235c25c062dc9652970ef9f635636c4018df0909e1a51c673e125cb","server_ts_ms":1768250241263,"raw":{"market":"0x2a12fd3d8235c25c062dc9652970ef9f635636c4018df0909e1a51c673e125cb","price_changes":[{"asset_id":"56386988715176239099720172290594769295756680374928571099138069977179519358166","price":"0.12","size":"881.25","side":"BUY","hash":"da736c9e48ddfebc6fe24684975a8b75e8742c5f","best_bid":"0.13","best_ask":"0.14"},{"asset_id":"63670753354844494163057275310194312729998307779831462269530137743341854359908","price":"0.88","size":"881.25","side":"SELL","hash":"f5d29cdbe776c93edb610aae7398e03449a34c48","best_bid":"0.86","best_ask":"0.87"}],"timestamp":"1768250241263","event_type":"price_change"}}
{"schema_version":1,"source":"clob_ws_market","recv_ts_ns":1768250241598652910,"event_type":"price_change","market":"0x2a12fd3d8235c25c062dc9652970ef9f635636c4018df0909e1a51c673e125cb","server_ts_ms":1768250241265,"raw":{"market":"0x2a12fd3d8235c25c062dc9652970ef9f635636c4018df0909e1a51c673e125cb","price_changes":[{"asset_id":"63670753354844494163057275310194312729998307779831462269530137743341854359908","price":"0.88","size":"866.25","side":"SELL","hash":"ed3b58eaf9ad6c06c21ee7f144b3d53aefa73960","best_bid":"0.86","best_ask":"0.87"},{"asset_id":"56386988715176239099720172290594769295756680374928571099138069977179519358166","price":"0.12","size":"866.25","side":"BUY","hash":"8316d77f9cc9b7c21a353dba5b9c226ea4c246b4","best_bid":"0.13","best_ask":"0.14"}],"timestamp":"1768250241265","event_type":"price_change"}}
{"schema_version":1,"source":"clob_ws_market","recv_ts_ns":1768250241603718892,"event_type":"price_change","market":"0x2a12fd3d8235c25c062dc9652970ef9f635636c4018df0909e1a51c673e125cb","server_ts_ms":1768250241266,"raw":{"market":"0x2a12fd3d8235c25c062dc9652970ef9f635636c4018df0909e1a51c673e125cb","price_changes":[{"asset_id":"56386988715176239099720172290594769295756680374928571099138069977179519358166","price":"0.12","size":"860.75","side":"BUY","hash":"be1467cc1732d53adc00cf882295c344fda96f98","best_bid":"0.13","best_ask":"0.14"},{"asset_id":"63670753354844494163057275310194312729998307779831462269530137743341854359908","price":"0.88","size":"860.75","side":"SELL","hash":"0a4ba44faf3a4dd51febc48d934f689dc6876fed","best_bid":"0.86","best_ask":"0.87"}],"timestamp":"1768250241266","event_type":"price_change"}}
{"schema_version":1,"source":"clob_ws_market","recv_ts_ns":1768250241607695783,"event_type":"price_change","market":"0x2a12fd3d8235c25c062dc9652970ef9f635636c4018df0909e1a51c673e125cb","server_ts_ms":1768250241266,"raw":{"market":"0x2a12fd3d8235c25c062dc9652970ef9f635636c4018df0909e1a51c673e125cb","price_changes":[{"asset_id":"63670753354844494163057275310194312729998307779831462269530137743341854359908","price":"0.83","size":"879.52","side":"BUY","hash":"26fe11d66ca875737dce3e837a708df1fdf102bc","best_bid":"0.86","best_ask":"0.87"},{"asset_id":"56386988715176239099720172290594769295756680374928571099138069977179519358166","price":"0.17","size":"879.52","side":"SELL","hash":"eced95eec7736f8d9862907ec93c0ca028475a23","best_bid":"0.13","best_ask":"0.14"}],"timestamp":"1768250241266","event_type":"price_change"}}
{"schema_version":1,"source":"clob_ws_market","recv_ts_ns":1768250241615911234,"event_type":"price_change","market":"0x2a12fd3d8235c25c062dc9652970ef9f635636c4018df0909e1a51c673e125cb","server_ts_ms":1768250241283,"raw":{"market":"0x2a12fd3d8235c25c062dc9652970ef9f635636c4018df0909e1a51c673e125cb","price_changes":[{"asset_id":"63670753354844494163057275310194312729998307779831462269530137743341854359908","price":"0.87","size":"189","side":"SELL","hash":"00a8fe3d4065e4dd54bafbede3ef60f632bba960","best_bid":"0.86","best_ask":"0.87"},{"asset_id":"56386988715176239099720172290594769295756680374928571099138069977179519358166","price":"0.13","size":"189","side":"BUY","hash":"d4343e8f11d04092f4f3eb97f3830096dfa1105e","best_bid":"0.13","best_ask":"0.14"}],"timestamp":"1768250241283","event_type":"price_change"}}
{"schema_version":1,"source":"clob_ws_market","recv_ts_ns":1768250241619338470,"event_type":"price_change","market":"0x2a12fd3d8235c25c062dc9652970ef9f635636c4018df0909e1a51c673e125cb","server_ts_ms":1768250241286,"raw":{"market":"0x2a12fd3d8235c25c062dc9652970ef9f635636c4018df0909e1a51c673e125cb","price_changes":[{"asset_id":"56386988715176239099720172290594769295756680374928571099138069977179519358166","price":"0.12","size":"850.75","side":"BUY","hash":"4a4a75c6732ec1aebe7e28fa3915208e537f8d22","best_bid":"0.13","best_ask":"0.14"},{"asset_id":"63670753354844494163057275310194312729998307779831462269530137743341854359908","price":"0.88","size":"850.75","side":"SELL","hash":"1e80ca6333e292cb374397d9661cdf67cd550f2f","best_bid":"0.86","best_ask":"0.87"}],"timestamp":"1768250241286","event_type":"price_change"}}
{"schema_version":1,"source":"clob_ws_market","recv_ts_ns":1768250241623577998,"event_type":"price_change","market":"0x2a12fd3d8235c25c062dc9652970ef9f635636c4018df0909e1a51c673e125cb","server_ts_ms":1768250241288,"raw":{"market":"0x2a12fd3d8235c25c062dc9652970ef9f635636c4018df0909e1a51c673e125cb","price_changes":[{"asset_id":"56386988715176239099720172290594769295756680374928571099138069977179519358166","price":"0.13","size":"194.5","side":"BUY","hash":"ae4fd4bee5e9f9cca19df7538f8e9afcc422ca36","best_bid":"0.13","best_ask":"0.14"},{"asset_id":"63670753354844494163057275310194312729998307779831462269530137743341854359908","price":"0.87","size":"194.5","side":"SELL","hash":"6645c252cb368833a1b169df8c9d393b5d0740db","best_bid":"0.86","best_ask":"0.87"}],"timestamp":"1768250241288","event_type":"price_change"}}
{"schema_version":1,"source":"clob_ws_market","recv_ts_ns":1768250241628157343,"event_type":"price_change","market":"0x2a12fd3d8235c25c062dc9652970ef9f635636c4018df0909e1a51c673e125cb","server_ts_ms":1768250241291,"raw":{"market":"0x2a12fd3d8235c25c062dc9652970ef9f635636c4018df0909e1a51c673e125cb","price_changes":[{"asset_id":"56386988715176239099720172290594769295756680374928571099138069977179519358166","price":"0.13","size":"204.5","side":"BUY","hash":"ed6f819c917652571f910cee869a441313577a1a","best_bid":"0.13","best_ask":"0.14"},{"asset_id":"63670753354844494163057275310194312729998307779831462269530137743341854359908","price":"0.87","size":"204.5","side":"SELL","hash":"82d9f7487e4cc08eab528af638f3ab377b72e580","best_bid":"0.86","best_ask":"0.87"}],"timestamp":"1768250241291","event_type":"price_change"}}
{"schema_version":1,"source":"clob_ws_market","recv_ts_ns":1768250241633559570,"event_type":"price_change","market":"0x2a12fd3d8235c25c062dc9652970ef9f635636c4018df0909e1a51c673e125cb","server_ts_ms":1768250241299,"raw":{"market":"0x2a12fd3d8235c25c062dc9652970ef9f635636c4018df0909e1a51c673e125cb","price_changes":[{"asset_id":"63670753354844494163057275310194312729998307779831462269530137743341854359908","price":"0.87","size":"210","side":"SELL","hash":"daf15b8096cc0a7f0b04785d42044e6a165642dd","best_bid":"0.86","best_ask":"0.87"},{"asset_id":"56386988715176239099720172290594769295756680374928571099138069977179519358166","price":"0.13","size":"210","side":"BUY","hash":"d2002a2047d4f0de99fe81828d7165493baeed81","best_bid":"0.13","best_ask":"0.14"}],"timestamp":"1768250241299","event_type":"price_change"}}
{"schema_version":1,"source":"clob_ws_market","recv_ts_ns":1768250241638436541,"event_type":"price_change","market":"0x2a12fd3d8235c25c062dc9652970ef9f635636c4018df0909e1a51c673e125cb","server_ts_ms":1768250241310,"raw":{"market":"0x2a12fd3d8235c25c062dc9652970ef9f635636c4018df0909e1a51c673e125cb","price_changes":[{"asset_id":"56386988715176239099720172290594769295756680374928571099138069977179519358166","price":"0.13","size":"215.5","side":"BUY","hash":"e85e1c3effa18150063b8a5764798ccacc920845","best_bid":"0.13","best_ask":"0.14"},{"asset_id":"63670753354844494163057275310194312729998307779831462269530137743341854359908","price":"0.87","size":"215.5","side":"SELL","hash":"6d2179ee947d0a38c553a3737c0f31ca4c5e3808","best_bid":"0.86","best_ask":"0.87"}],"timestamp":"1768250241310","event_type":"price_change"}}
{"schema_version":1,"source":"clob_ws_market","recv_ts_ns":1768250241643133557,"event_type":"price_change","market":"0x2a12fd3d8235c25c062dc9652970ef9f635636c4018df0909e1a51c673e125cb","server_ts_ms":1768250241313,"raw":{"market":"0x2a12fd3d8235c25c062dc9652970ef9f635636c4018df0909e1a51c673e125cb","price_changes":[{"asset_id":"63670753354844494163057275310194312729998307779831462269530137743341854359908","price":"0.85","size":"275.49","side":"BUY","hash":"862a756e8ce1f0c61f0a6262c97a16c4f48c2852","best_bid":"0.86","best_ask":"0.87"},{"asset_id":"56386988715176239099720172290594769295756680374928571099138069977179519358166","price":"0.15","size":"275.49","side":"SELL","hash":"2bf05915ef346c62fbb0555dfaee07c02d0e4acb","best_bid":"0.13","best_ask":"0.14"}],"timestamp":"1768250241313","event_type":"price_change"}}
{"schema_version":1,"source":"clob_ws_market","recv_ts_ns":1768250241647516595,"event_type":"price_change","market":"0x2a12fd3d8235c25c062dc9652970ef9f635636c4018df0909e1a51c673e125cb","server_ts_ms":1768250241317,"raw":{"market":"0x2a12fd3d8235c25c062dc9652970ef9f635636c4018df0909e1a51c673e125cb","price_changes":[{"asset_id":"63670753354844494163057275310194312729998307779831462269530137743341854359908","price":"0.86","size":"1092.63","side":"BUY","hash":"c6ee8d86da5fae6351e52d8cd6ba966ed8df19de","best_bid":"0.86","best_ask":"0.87"},{"asset_id":"56386988715176239099720172290594769295756680374928571099138069977179519358166","price":"0.14","size":"1092.63","side":"SELL","hash":"7caf08e19a4c4d27df8b4bb557d5e2a99e11012b","best_bid":"0.13","best_ask":"0.14"}],"timestamp":"1768250241317","event_type":"price_change"}}
{"schema_version":1,"source":"clob_ws_market","recv_ts_ns":1768250241651598989,"event_type":"price_change","market":"0x2a12fd3d8235c25c062dc9652970ef9f635636c4018df0909e1a51c673e125cb","server_ts_ms":1768250241321,"raw":{"market":"0x2a12fd3d8235c25c062dc9652970ef9f635636c4018df0909e1a51c673e125cb","price_changes":[{"asset_id":"63670753354844494163057275310194312729998307779831462269530137743341854359908","price":"0.94","size":"1397","side":"SELL","hash":"824a0f7f0d513d9c9caa10bcd759a1fc3851079e","best_bid":"0.86","best_ask":"0.87"},{"asset_id":"56386988715176239099720172290594769295756680374928571099138069977179519358166","price":"0.06","size":"1397","side":"BUY","hash":"43141c46a4755ce4f37c6caa081b8d8b4e6b5205","best_bid":"0.13","best_ask":"0.14"}],"timestamp":"1768250241321","event_type":"price_change"}}
{"schema_version":1,"source":"clob_ws_market","recv_ts_ns":1768250241655464500,"event_type":"price_change","market":"0x2a12fd3d8235c25c062dc9652970ef9f635636c4018df0909e1a51c673e125cb","server_ts_ms":1768250241323,"raw":{"market":"0x2a12fd3d8235c25c062dc9652970ef9f635636c4018df0909e1a51c673e125cb","price_changes":[{"asset_id":"56386988715176239099720172290594769295756680374928571099138069977179519358166","price":"0.11","size":"854.5","side":"BUY","hash":"ba3c3c76939e32590fa1368589fea5d91a99b646","best_bid":"0.13","best_ask":"0.14"},{"asset_id":"63670753354844494163057275310194312729998307779831462269530137743341854359908","price":"0.89","size":"854.5","side":"SELL","hash":"666487d6fb7d51e8cd30f92c0ed24316c5fe2ead","best_bid":"0.86","best_ask":"0.87"}],"timestamp":"1768250241323","event_type":"price_change"}}
{"schema_version":1,"source":"clob_ws_market","recv_ts_ns":1768250241659139838,"event_type":"price_change","market":"0x2a12fd3d8235c25c062dc9652970ef9f635636c4018df0909e1a51c673e125cb","server_ts_ms":1768250241323,"raw":{"market":"0x2a12fd3d8235c25c062dc9652970ef9f635636c4018df0909e1a51c673e125cb","price_changes":[{"asset_id":"63670753354844494163057275310194312729998307779831462269530137743341854359908","price":"0.88","size":"830.75","side":"SELL","hash":"ca82b06976c4efc86402e60050960452f88127ba","best_bid":"0.86","best_ask":"0.87"},{"asset_id":"56386988715176239099720172290594769295756680374928571099138069977179519358166","price":"0.12","size":"830.75","side":"BUY","hash":"7a32cd65c39ac2e68845390418e4df286bea30cc","best_bid":"0.13","best_ask":"0.14"}],"timestamp":"1768250241323","event_type":"price_change"}}
{"schema_version":1,"source":"clob_ws_market","recv_ts_ns":1768250241662355931,"event_type":"price_change","market":"0x2a12fd3d8235c25c062dc9652970ef9f635636c4018df0909e1a51c673e125cb","server_ts_ms":1768250241324,"raw":{"market":"0x2a12fd3d8235c25c062dc9652970ef9f635636c4018df0909e1a51c673e125cb","price_changes":[{"asset_id":"56386988715176239099720172290594769295756680374928571099138069977179519358166","price":"0.12","size":"850.75","side":"BUY","hash":"8f888155766503af9446204b21c1ea63980c1e17","best_bid":"0.13","best_ask":"0.14"},{"asset_id":"63670753354844494163057275310194312729998307779831462269530137743341854359908","price":"0.88","size":"850.75","side":"SELL","hash":"f682cec54678a3a282ec809b97026f70ecbd117b","best_bid":"0.86","best_ask":"0.87"}],"timestamp":"1768250241324","event_type":"price_change"}}
{"schema_version":1,"source":"clob_ws_market","recv_ts_ns":1768250241666004282,"event_type":"price_change","market":"0x2a12fd3d8235c25c062dc9652970ef9f635636c4018df0909e1a51c673e125cb","server_ts_ms":1768250241324,"raw":{"market":"0x2a12fd3d8235c25c062dc9652970ef9f635636c4018df0909e1a51c673e125cb","price_changes":[{"asset_id":"56386988715176239099720172290594769295756680374928571099138069977179519358166","price":"0.13","size":"235.5","side":"BUY","hash":"c85f0eff64255a1b0a5403eb7acd6728688d28fe","best_bid":"0.13","best_ask":"0.14"},{"asset_id":"63670753354844494163057275310194312729998307779831462269530137743341854359908","price":"0.87","size":"235.5","side":"SELL","hash":"eb6581512812451a77dd8fbacc5776d4b18ab799","best_bid":"0.86","best_ask":"0.87"}],"timestamp":"1768250241324","event_type":"price_change"}}
{"schema_version":1,"source":"clob_ws_market","recv_ts_ns":1768250241671682674,"event_type":"price_change","market":"0x2a12fd3d8235c25c062dc9652970ef9f635636c4018df0909e1a51c673e125cb","server_ts_ms":1768250241325,"raw":{"market":"0x2a12fd3d8235c25c062dc9652970ef9f635636c4018df0909e1a51c673e125cb","price_changes":[{"asset_id":"56386988715176239099720172290594769295756680374928571099138069977179519358166","price":"0.11","size":"844.5","side":"BUY","hash":"4d01463a8b4bdc9de6def45c25a8d907965ec396","best_bid":"0.13","best_ask":"0.14"},{"asset_id":"63670753354844494163057275310194312729998307779831462269530137743341854359908","price":"0.89","size":"844.5","side":"SELL","hash":"0c09f00d848628d06c686431e1d607adfffc02b0","best_bid":"0.86","best_ask":"0.87"}],"timestamp":"1768250241325","event_type":"price_change"}}
{"schema_version":1,"source":"clob_ws_market","recv_ts_ns":1768250241675976469,"event_type":"price_change","market":"0x2a12fd3d8235c25c062dc9652970ef9f635636c4018df0909e1a51c673e125cb","server_ts_ms":1768250241325,"raw":{"market":"0x2a12fd3d8235c25c062dc9652970ef9f635636c4018df0909e1a51c673e125cb","price_changes":[{"asset_id":"63670753354844494163057275310194312729998307779831462269530137743341854359908","price":"0.85","size":"265.49","side":"BUY","hash":"13e2948ba21e3d2c9ef4f803d223638fdd9c31e6","best_bid":"0.86","best_ask":"0.87"},{"asset_id":"56386988715176239099720172290594769295756680374928571099138069977179519358166","price":"0.15","size":"265.49","side":"SELL","hash":"6f1bf9f96648d8a59d48773504c9bec73e87e657","best_bid":"0.13","best_ask":"0.14"}],"timestamp":"1768250241325","event_type":"price_change"}}
{"schema_version":1,"source":"clob_ws_market","recv_ts_ns":1768250241680836488,"event_type":"price_change","market":"0x2a12fd3d8235c25c062dc9652970ef9f635636c4018df0909e1a51c673e125cb","server_ts_ms":1768250241326,"raw":{"market":"0x2a12fd3d8235c25c062dc9652970ef9f635636c4018df0909e1a51c673e125cb","price_changes":[{"asset_id":"63670753354844494163057275310194312729998307779831462269530137743341854359908","price":"0.86","size":"1082.63","side":"BUY","hash":"28983f0bc7c833a63e28286524764a1f1af9b0ba","best_bid":"0.86","best_ask":"0.87"},{"asset_id":"56386988715176239099720172290594769295756680374928571099138069977179519358166","price":"0.14","size":"1082.63","side":"SELL","hash":"e97d6500acdfd90a16ee2b4738b96c0826cc68c2","best_bid":"0.13","best_ask":"0.14"}],"timestamp":"1768250241326","event_type":"price_change"}}
{"schema_version":1,"source":"clob_ws_market","recv_ts_ns":1768250241685417989,"event_type":"price_change","market":"0x2a12fd3d8235c25c062dc9652970ef9f635636c4018df0909e1a51c673e125cb","server_ts_ms":1768250241327,"raw":{"market":"0x2a12fd3d8235c25c062dc9652970ef9f635636c4018df0909e1a51c673e125cb","price_changes":[{"asset_id":"63670753354844494163057275310194312729998307779831462269530137743341854359908","price":"0.85","size":"255.49","side":"BUY","hash":"7681f07b77273caeb08c3f9e0af5afadda70dcfe","best_bid":"0.86","best_ask":"0.87"},{"asset_id":"56386988715176239099720172290594769295756680374928571099138069977179519358166","price":"0.15","size":"255.49","side":"SELL","hash":"e99f936b1a9f7d74a3780bb5b9292ee5bef32add","best_bid":"0.13","best_ask":"0.14"}],"timestamp":"1768250241327","event_type":"price_change"}}
{"schema_version":1,"source":"clob_ws_market","recv_ts_ns":1768250241691872168,"event_type":"price_change","market":"0x2a12fd3d8235c25c062dc9652970ef9f635636c4018df0909e1a51c673e125cb","server_ts_ms":1768250241328,"raw":{"market":"0x2a12fd3d8235c25c062dc9652970ef9f635636c4018df0909e1a51c673e125cb","price_changes":[{"asset_id":"63670753354844494163057275310194312729998307779831462269530137743341854359908","price":"0.85","size":"245.49","side":"BUY","hash":"e5429629d79fdaf4ce807a7230aaa03097d5ce86","best_bid":"0.86","best_ask":"0.87"},{"asset_id":"56386988715176239099720172290594769295756680374928571099138069977179519358166","price":"0.15","size":"245.49","side":"SELL","hash":"964aec4241f46c469c3302260ea5d7ebbd794b3c","best_bid":"0.13","best_ask":"0.14"}],"timestamp":"1768250241328","event_type":"price_change"}}
{"schema_version":1,"source":"clob_ws_market","recv_ts_ns":1768250241696899346,"event_type":"price_change","market":"0x2a12fd3d8235c25c062dc9652970ef9f635636c4018df0909e1a51c673e125cb","server_ts_ms":1768250241329,"raw":{"market":"0x2a12fd3d8235c25c062dc9652970ef9f635636c4018df0909e1a51c673e125cb","price_changes":[{"asset_id":"63670753354844494163057275310194312729998307779831462269530137743341854359908","price":"0.87","size":"255.5","side":"SELL","hash":"47299edf4e8b1db1b1b6427ab8309ca30acbae7f","best_bid":"0.86","best_ask":"0.87"},{"asset_id":"56386988715176239099720172290594769295756680374928571099138069977179519358166","price":"0.13","size":"255.5","side":"BUY","hash":"01252c882412c1aab9bedb543ddc42d463708711","best_bid":"0.13","best_ask":"0.14"}],"timestamp":"1768250241329","event_type":"price_change"}}
{"schema_version":1,"source":"clob_ws_market","recv_ts_ns":1768250241700882823,"event_type":"price_change","market":"0x2a12fd3d8235c25c062dc9652970ef9f635636c4018df0909e1a51c673e125cb","server_ts_ms":1768250241330,"raw":{"market":"0x2a12fd3d8235c25c062dc9652970ef9f635636c4018df0909e1a51c673e125cb","price_changes":[{"asset_id":"56386988715176239099720172290594769295756680374928571099138069977179519358166","price":"0.13","size":"261","side":"BUY","hash":"2f82bb27816c33c42f0398ad9de547fc02a3c8cd","best_bid":"0.13","best_ask":"0.14"},{"asset_id":"63670753354844494163057275310194312729998307779831462269530137743341854359908","price":"0.87","size":"261","side":"SELL","hash":"b017fd6a85bf55fe0cfac7299b49bf1c6a49bc42","best_bid":"0.86","best_ask":"0.87"}],"timestamp":"1768250241330","event_type":"price_change"}}
{"schema_version":1,"source":"clob_ws_market","recv_ts_ns":1768250241705706763,"event_type":"price_change","market":"0x2a12fd3d8235c25c062dc9652970ef9f635636c4018df0909e1a51c673e125cb","server_ts_ms":1768250241330,"raw":{"market":"0x2a12fd3d8235c25c062dc9652970ef9f635636c4018df0909e1a51c673e125cb","price_changes":[{"asset_id":"63670753354844494163057275310194312729998307779831462269530137743341854359908","price":"0.85","size":"235.49","side":"BUY","hash":"cdcc9561acc762c9192527d44102a1e0b03db0ce","best_bid":"0.86","best_ask":"0.87"},{"asset_id":"56386988715176239099720172290594769295756680374928571099138069977179519358166","price":"0.15","size":"235.49","side":"SELL","hash":"c8b2aaaabbbf5a940baaf25bdb4b93d8fb0b66b2","best_bid":"0.13","best_ask":"0.14"}],"timestamp":"1768250241330","event_type":"price_change"}}
{"schema_version":1,"source":"clob_ws_market","recv_ts_ns":1768250241709700549,"event_type":"price_change","market":"0x2a12fd3d8235c25c062dc9652970ef9f635636c4018df0909e1a51c673e125cb","server_ts_ms":1768250241331,"raw":{"market":"0x2a12fd3d8235c25c062dc9652970ef9f635636c4018df0909e1a51c673e125cb","price_changes":[{"asset_id":"56386988715176239099720172290594769295756680374928571099138069977179519358166","price":"0.1","size":"3398","side":"BUY","hash":"7740fd74d580e61442021992cbc61817e96b54f0","best_bid":"0.13","best_ask":"0.14"},{"asset_id":"63670753354844494163057275310194312729998307779831462269530137743341854359908","price":"0.9","size":"3398","side":"SELL","hash":"9bcfbeecb95299796700c53b5c757074f34e1af7","best_bid":"0.86","best_ask":"0.87"}],"timestamp":"1768250241331","event_type":"price_change"}}
{"schema_version":1,"source":"clob_ws_market","recv_ts_ns":1768250241713333574,"event_type":"price_change","market":"0x2a12fd3d8235c25c062dc9652970ef9f635636c4018df0909e1a51c673e125cb","server_ts_ms":1768250241331,"raw":{"market":"0x2a12fd3d8235c25c062dc9652970ef9f635636c4018df0909e1a51c673e125cb","price_changes":[{"asset_id":"63670753354844494163057275310194312729998307779831462269530137743341854359908","price":"0.86","size":"1072.63","side":"BUY","hash":"dc8d87f552017cee46827785c706a86bb985ac34","best_bid":"0.86","best_ask":"0.87"},{"asset_id":"56386988715176239099720172290594769295756680374928571099138069977179519358166","price":"0.14","size":"1072.63","side":"SELL","hash":"3b059b930dd8b99dc20ed8bab8f600b2504b48eb","best_bid":"0.13","best_ask":"0.14"}],"timestamp":"1768250241331","event_type":"price_change"}}
{"schema_version":1,"source":"clob_ws_market","recv_ts_ns":1768250241717239663,"event_type":"price_change","market":"0x2a12fd3d8235c25c062dc9652970ef9f635636c4018df0909e1a51c673e125cb","server_ts_ms":1768250241332,"raw":{"market":"0x2a12fd3d8235c25c062dc9652970ef9f635636c4018df0909e1a51c673e125cb","price_changes":[{"asset_id":"56386988715176239099720172290594769295756680374928571099138069977179519358166","price":"0.12","size":"830.75","side":"BUY","hash":"d51193a5d83592bd3d67cded6eabcf6c2c53ef86","best_bid":"0.13","best_ask":"0.14"},{"asset_id":"63670753354844494163057275310194312729998307779831462269530137743341854359908","price":"0.88","size":"830.75","side":"SELL","hash":"d06957fc9f78cb39a958c55c6adec98ea9576fe5","best_bid":"0.86","best_ask":"0.87"}],"timestamp":"1768250241332","event_type":"price_change"}}
{"schema_version":1,"source":"clob_ws_market","recv_ts_ns":1768250241721085841,"event_type":"price_change","market":"0x2a12fd3d8235c25c062dc9652970ef9f635636c4018df0909e1a51c673e125cb","server_ts_ms":1768250241332,"raw":{"market":"0x2a12fd3d8235c25c062dc9652970ef9f635636c4018df0909e1a51c673e125cb","price_changes":[{"asset_id":"56386988715176239099720172290594769295756680374928571099138069977179519358166","price":"0.08","size":"1559.75","side":"BUY","hash":"e275fe5fcfc3652794dd9a6aa57cef3aee2149e4","best_bid":"0.13","best_ask":"0.14"},{"asset_id":"63670753354844494163057275310194312729998307779831462269530137743341854359908","price":"0.92","size":"1559.75","side":"SELL","hash":"3c0d5e5904eae208c9c90266f8b7bddbe396b972","best_bid":"0.86","best_ask":"0.87"}],"timestamp":"1768250241332","event_type":"price_change"}}
{"schema_version":1,"source":"clob_ws_market","recv_ts_ns":1768250241724760006,"event_type":"price_change","market":"0x2a12fd3d8235c25c062dc9652970ef9f635636c4018df0909e1a51c673e125cb","server_ts_ms":1768250241333,"raw":{"market":"0x2a12fd3d8235c25c062dc9652970ef9f635636c4018df0909e1a51c673e125cb","price_changes":[{"asset_id":"63670753354844494163057275310194312729998307779831462269530137743341854359908","price":"0.85","size":"225.49","side":"BUY","hash":"75682cbbfef5ed4109c8123c5933a2dd3468cdb8","best_bid":"0.86","best_ask":"0.87"},{"asset_id":"56386988715176239099720172290594769295756680374928571099138069977179519358166","price":"0.15","size":"225.49","side":"SELL","hash":"3c3d2c5b39c4e6d82d60a88c1407ecdf629d3eb0","best_bid":"0.13","best_ask":"0.14"}],"timestamp":"1768250241333","event_type":"price_change"}}
{"schema_version":1,"source":"clob_ws_market","recv_ts_ns":1768250241728192344,"event_type":"price_change","market":"0x2a12fd3d8235c25c062dc9652970ef9f635636c4018df0909e1a51c673e125cb","server_ts_ms":1768250241336,"raw":{"market":"0x2a12fd3d8235c25c062dc9652970ef9f635636c4018df0909e1a51c673e125cb","price_changes":[{"asset_id":"63670753354844494163057275310194312729998307779831462269530137743341854359908","price":"0.82","size":"171","side":"BUY","hash":"c9e0164a3b744e8eb97c05714d667a75a5ed7b38","best_bid":"0.86","best_ask":"0.87"},{"asset_id":"56386988715176239099720172290594769295756680374928571099138069977179519358166","price":"0.18","size":"171","side":"SELL","hash":"f910b07c84288296636839cb6cc2f8a50d88e8c9","best_bid":"0.13","best_ask":"0.14"}],"timestamp":"1768250241336","event_type":"price_change"}}
{"schema_version":1,"source":"clob_ws_market","recv_ts_ns":1768250241731481440,"event_type":"price_change","market":"0x2a12fd3d8235c25c062dc9652970ef9f635636c4018df0909e1a51c673e125cb","server_ts_ms":1768250241339,"raw":{"market":"0x2a12fd3d8235c25c062dc9652970ef9f635636c4018df0909e1a51c673e125cb","price_changes":[{"asset_id":"63670753354844494163057275310194312729998307779831462269530137743341854359908","price":"0.85","size":"215.49","side":"BUY","hash":"49e3cbd89fcedffaf53c2dd1afe98a4f95e1877b","best_bid":"0.86","best_ask":"0.87"},{"asset_id":"56386988715176239099720172290594769295756680374928571099138069977179519358166","price":"0.15","size":"215.49","side":"SELL","hash":"d6e9d73ef5a421c4a4933152c12a2277eb481ca8","best_bid":"0.13","best_ask":"0.14"}],"timestamp":"1768250241339","event_type":"price_change"}}
{"schema_version":1,"source":"clob_ws_market","recv_ts_ns":1768250241737928770,"event_type":"price_change","market":"0x2a12fd3d8235c25c062dc9652970ef9f635636c4018df0909e1a51c673e125cb","server_ts_ms":1768250241354,"raw":{"market":"0x2a12fd3d8235c25c062dc9652970ef9f635636c4018df0909e1a51c673e125cb","price_changes":[{"asset_id":"63670753354844494163057275310194312729998307779831462269530137743341854359908","price":"0.86","size":"672.63","side":"BUY","hash":"4745de8aecc6ac31526ec4a29aec6029af325b44","best_bid":"0.86","best_ask":"0.87"},{"asset_id":"56386988715176239099720172290594769295756680374928571099138069977179519358166","price":"0.14","size":"672.63","side":"SELL","hash":"f8dfbb03b5f52a996b924d765b8039e9636c7899","best_bid":"0.13","best_ask":"0.14"}],"timestamp":"1768250241354","event_type":"price_change"}}
{"schema_version":1,"source":"clob_ws_market","recv_ts_ns":1768250241740757246,"event_type":"price_change","market":"0x2a12fd3d8235c25c062dc9652970ef9f635636c4018df0909e1a51c673e125cb","server_ts_ms":1768250241355,"raw":{"market":"0x2a12fd3d8235c25c062dc9652970ef9f635636c4018df0909e1a51c673e125cb","price_changes":[{"asset_id":"63670753354844494163057275310194312729998307779831462269530137743341854359908","price":"0.85","size":"225.49","side":"BUY","hash":"c5bbdf1280f8c79c261926bd318bb337023ddfff","best_bid":"0.86","best_ask":"0.87"},{"asset_id":"56386988715176239099720172290594769295756680374928571099138069977179519358166","price":"0.15","size":"225.49","side":"SELL","hash":"84774d5d996f9da9f2b7493f9ee5012ccd45053c","best_bid":"0.13","best_ask":"0.14"}],"timestamp":"1768250241355","event_type":"price_change"}}
{"schema_version":1,"source":"clob_ws_market","recv_ts_ns":1768250241743648105,"event_type":"price_change","market":"0x2a12fd3d8235c25c062dc9652970ef9f635636c4018df0909e1a51c673e125cb","server_ts_ms":1768250241359,"raw":{"market":"0x2a12fd3d8235c25c062dc9652970ef9f635636c4018df0909e1a51c673e125cb","price_changes":[{"asset_id":"63670753354844494163057275310194312729998307779831462269530137743341854359908","price":"0.93","size":"1418.78","side":"SELL","hash":"b84cf2b5f5675b4b528e30b4ed16720f40f20886","best_bid":"0.86","best_ask":"0.87"},{"asset_id":"56386988715176239099720172290594769295756680374928571099138069977179519358166","price":"0.07","size":"1418.78","side":"BUY","hash":"4f35792e9cade2130c2ae5b6f4acafb46b198946","best_bid":"0.13","best_ask":"0.14"}],"timestamp":"1768250241359","event_type":"price_change"}}
{"schema_version":1,"source":"clob_ws_market","recv_ts_ns":1768250241746618040,"event_type":"price_change","market":"0x2a12fd3d8235c25c062dc9652970ef9f635636c4018df0909e1a51c673e125cb","server_ts_ms":1768250241359,"raw":{"market":"0x2a12fd3d8235c25c062dc9652970ef9f635636c4018df0909e1a51c673e125cb","price_changes":[{"asset_id":"63670753354844494163057275310194312729998307779831462269530137743341854359908","price":"0.85","size":"235.49","side":"BUY","hash":"c588c030882f7150a8bd0063270d32e285f925aa","best_bid":"0.86","best_ask":"0.87"},{"asset_id":"56386988715176239099720172290594769295756680374928571099138069977179519358166","price":"0.15","size":"235.49","side":"SELL","hash":"d67d4cfe2277ea55641eb03fbeb4c8d20467baf6","best_bid":"0.13","best_ask":"0.14"}],"timestamp":"1768250241359","event_type":"price_change"}}
{"schema_version":1,"source":"clob_ws_market","recv_ts_ns":1768250241749343848,"event_type":"price_change","market":"0x2a12fd3d8235c25c062dc9652970ef9f635636c4018df0909e1a51c673e125cb","server_ts_ms":1768250241361,"raw":{"market":"0x2a12fd3d8235c25c062dc9652970ef9f635636c4018df0909e1a51c673e125cb","price_changes":[{"asset_id":"63670753354844494163057275310194312729998307779831462269530137743341854359908","price":"0.81","size":"888.21","side":"BUY","hash":"dde1ab1b42fdb0f9ae7da9c2f0b196a17d25b171","best_bid":"0.86","best_ask":"0.87"},{"asset_id":"56386988715176239099720172290594769295756680374928571099138069977179519358166","price":"0.19","size":"888.21","side":"SELL","hash":"e3e8de898a5ef5e7cc695f4e08b00ed9f2bbed80","best_bid":"0.13","best_ask":"0.14"}],"timestamp":"1768250241361","event_type":"price_change"}}
{"schema_version":1,"source":"clob_ws_market","recv_ts_ns":1768250241751797202,"event_type":"price_change","market":"0x2a12fd3d8235c25c062dc9652970ef9f635636c4018df0909e1a51c673e125cb","server_ts_ms":1768250241363,"raw":{"market":"0x2a12fd3d8235c25c062dc9652970ef9f635636c4018df0909e1a51c673e125cb","price_changes":[{"asset_id":"63670753354844494163057275310194312729998307779831462269530137743341854359908","price":"0.86","size":"272.63","side":"BUY","hash":"2ba582d967a9e0bf2203078484a9d7a91ecf9a44","best_bid":"0.86","best_ask":"0.87"},{"asset_id":"56386988715176239099720172290594769295756680374928571099138069977179519358166","price":"0.14","size":"272.63","side":"SELL","hash":"8f462167914d458995f734710b59d6113d89f7db","best_bid":"0.13","best_ask":"0.14"}],"timestamp":"1768250241363","event_type":"price_change"}}
{"schema_version":1,"source":"clob_ws_market","recv_ts_ns":1768250241754387879,"event_type":"price_change","market":"0x2a12fd3d8235c25c062dc9652970ef9f635636c4018df0909e1a51c673e125cb","server_ts_ms":1768250241365,"raw":{"market":"0x2a12fd3d8235c25c062dc9652970ef9f635636c4018df0909e1a51c673e125cb","price_changes":[{"asset_id":"56386988715176239099720172290594769295756680374928571099138069977179519358166","price":"0.08","size":"1569.75","side":"BUY","hash":"3aeb0a490d01d396d26ec25e3b9cdd887984c52c","best_bid":"0.13","best_ask":"0.14"},{"asset_id":"63670753354844494163057275310194312729998307779831462269530137743341854359908","price":"0.92","size":"1569.75","side":"SELL","hash":"b5356fe6383f28354986774d49900b1efc0a8c54","best_bid":"0.86","best_ask":"0.87"}],"timestamp":"1768250241365","event_type":"price_change"}}
{"schema_version":1,"source":"clob_ws_market","recv_ts_ns":1768250241757950629,"event_type":"price_change","market":"0x2a12fd3d8235c25c062dc9652970ef9f635636c4018df0909e1a51c673e125cb","server_ts_ms":1768250241366,"raw":{"market":"0x2a12fd3d8235c25c062dc9652970ef9f635636c4018df0909e1a51c673e125cb","price_changes":[{"asset_id":"63670753354844494163057275310194312729998307779831462269530137743341854359908","price":"0.87","size":"255.5","side":"SELL","hash":"9a2b9cd7b981fb1216f30539c7ab35b0a2df26fe","best_bid":"0.86","best_ask":"0.87"},{"asset_id":"56386988715176239099720172290594769295756680374928571099138069977179519358166","price":"0.13","size":"255.5","side":"BUY","hash":"e44c7c6787b2f8ae7d889100f65071a4afd8c438","best_bid":"0.13","best_ask":"0.14"}],"timestamp":"1768250241366","event_type":"price_change"}}
{"schema_version":1,"source":"clob_ws_market","recv_ts_ns":1768250241761224703,"event_type":"price_change","market":"0x2a12fd3d8235c25c062dc9652970ef9f635636c4018df0909e1a51c673e125cb","server_ts_ms":1768250241368,"raw":{"market":"0x2a12fd3d8235c25c062dc9652970ef9f635636c4018df0909e1a51c673e125cb","price_changes":[{"asset_id":"56386988715176239099720172290594769295756680374928571099138069977179519358166","price":"0.13","size":"250","side":"BUY","hash":"494d400a7143d4538d24bcb14a67a58c97d648f8","best_bid":"0.13","best_ask":"0.14"},{"asset_id":"63670753354844494163057275310194312729998307779831462269530137743341854359908","price":"0.87","size":"250","side":"SELL","hash":"0d0743cc0c8a28614d60752c011bab180fbbb939","best_bid":"0.86","best_ask":"0.87"}],"timestamp":"1768250241368","event_type":"price_change"}}
{"schema_version":1,"source":"clob_ws_market","recv_ts_ns":1768250241764240148,"event_type":"price_change","market":"0x2a12fd3d8235c25c062dc9652970ef9f635636c4018df0909e1a51c673e125cb","server_ts_ms":1768250241369,"raw":{"market":"0x2a12fd3d8235c25c062dc9652970ef9f635636c4018df0909e1a51c673e125cb","price_changes":[{"asset_id":"56386988715176239099720172290594769295756680374928571099138069977179519358166","price":"0.12","size":"1530.75","side":"BUY","hash":"8dd3882fccba50d1c052f6c7f662687d8dbcbf29","best_bid":"0.13","best_ask":"0.14"},{"asset_id":"63670753354844494163057275310194312729998307779831462269530137743341854359908","price":"0.88","size":"1530.75","side":"SELL","hash":"a89eaa076a48350ca55eefa5bb6b390e9c024305","best_bid":"0.86","best_ask":"0.87"}],"timestamp":"1768250241369","event_type":"price_change"}}
{"schema_version":1,"source":"clob_ws_market","recv_ts_ns":1768250241767581431,"event_type":"price_change","market":"0x2a12fd3d8235c25c062dc9652970ef9f635636c4018df0909e1a51c673e125cb","server_ts_ms":1768250241369,"raw":{"market":"0x2a12fd3d8235c25c062dc9652970ef9f635636c4018df0909e1a51c673e125cb","price_changes":[{"asset_id":"63670753354844494163057275310194312729998307779831462269530137743341854359908","price":"0.85","size":"245.49","side":"BUY","hash":"8df4d538d7bbfd026c262b0dfb1d12d418382551","best_bid":"0.86","best_ask":"0.87"},{"asset_id":"56386988715176239099720172290594769295756680374928571099138069977179519358166","price":"0.15","size":"245.49","side":"SELL","hash":"49ee9f218416d6e03d32494f5a8f50b536112154","best_bid":"0.13","best_ask":"0.14"}],"timestamp":"1768250241369","event_type":"price_change"}}
{"schema_version":1,"source":"clob_ws_market","recv_ts_ns":1768250241770458027,"event_type":"price_change","market":"0x2a12fd3d8235c25c062dc9652970ef9f635636c4018df0909e1a51c673e125cb","server_ts_ms":1768250241370,"raw":{"market":"0x2a12fd3d8235c25c062dc9652970ef9f635636c4018df0909e1a51c673e125cb","price_changes":[{"asset_id":"63670753354844494163057275310194312729998307779831462269530137743341854359908","price":"0.85","size":"255.49","side":"BUY","hash":"218e5186577027a9441ae988f41a73090653628f","best_bid":"0.86","best_ask":"0.87"},{"asset_id":"56386988715176239099720172290594769295756680374928571099138069977179519358166","price":"0.15","size":"255.49","side":"SELL","hash":"c52e4712caafad0bdd42d11efa7ea22ebd5c31e3","best_bid":"0.13","best_ask":"0.14"}],"timestamp":"1768250241370","event_type":"price_change"}}
{"schema_version":1,"source":"clob_ws_market","recv_ts_ns":1768250241773229615,"event_type":"price_change","market":"0x2a12fd3d8235c25c062dc9652970ef9f635636c4018df0909e1a51c673e125cb","server_ts_ms":1768250241372,"raw":{"market":"0x2a12fd3d8235c25c062dc9652970ef9f635636c4018df0909e1a51c673e125cb","price_changes":[{"asset_id":"56386988715176239099720172290594769295756680374928571099138069977179519358166","price":"0.1","size":"3408","side":"BUY","hash":"21e227976c301bcf6fc22de9eb3147f3728eb632","best_bid":"0.13","best_ask":"0.14"},{"asset_id":"63670753354844494163057275310194312729998307779831462269530137743341854359908","price":"0.9","size":"3408","side":"SELL","hash":"2fd0fbfd58b330f4f971fba7ca949c93fc496b5c","best_bid":"0.86","best_ask":"0.87"}],"timestamp":"1768250241372","event_type":"price_change"}}
{"schema_version":1,"source":"clob_ws_market","recv_ts_ns":1768250241776272119,"event_type":"price_change","market":"0x2a12fd3d8235c25c062dc9652970ef9f635636c4018df0909e1a51c673e125cb","server_ts_ms":1768250241372,"raw":{"market":"0x2a12fd3d8235c25c062dc9652970ef9f635636c4018df0909e1a51c673e125cb","price_changes":[{"asset_id":"63670753354844494163057275310194312729998307779831462269530137743341854359908","price":"0.85","size":"265.49","side":"BUY","hash":"45ada845f06682f1ec9c4687b8cad8bac88ba8d8","best_bid":"0.86","best_ask":"0.87"},{"asset_id":"56386988715176239099720172290594769295756680374928571099138069977179519358166","price":"0.15","size":"265.49","side":"SELL","hash":"d9a903f69801aa6b43ecfcd697445a740e741742","best_bid":"0.13","best_ask":"0.14"}],"timestamp":"1768250241372","event_type":"price_change"}}
{"schema_version":1,"source":"clob_ws_market","recv_ts_ns":1768250241779419302,"event_type":"price_change","market":"0x2a12fd3d8235c25c062dc9652970ef9f635636c4018df0909e1a51c673e125cb","server_ts_ms":1768250241373,"raw":{"market":"0x2a12fd3d8235c25c062dc9652970ef9f635636c4018df0909e1a51c673e125cb","price_changes":[{"asset_id":"56386988715176239099720172290594769295756680374928571099138069977179519358166","price":"0.13","size":"244.5","side":"BUY","hash":"aceaa9e346991449da2b55c74521bd917c8871a7","best_bid":"0.13","best_ask":"0.14"},{"asset_id":"63670753354844494163057275310194312729998307779831462269530137743341854359908","price":"0.87","size":"244.5","side":"SELL","hash":"8a41923d5454719546fa4312efd3357f7278a5d8","best_bid":"0.86","best_ask":"0.87"}],"timestamp":"1768250241373","event_type":"price_change"}}
{"schema_version":1,"source":"clob_ws_market","recv_ts_ns":1768250241782614450,"event_type":"price_change","market":"0x2a12fd3d8235c25c062dc9652970ef9f635636c4018df0909e1a51c673e125cb","server_ts_ms":1768250241374,"raw":{"market":"0x2a12fd3d8235c25c062dc9652970ef9f635636c4018df0909e1a51c673e125cb","price_changes":[{"asset_id":"56386988715176239099720172290594769295756680374928571099138069977179519358166","price":"0.11","size":"854.5","side":"BUY","hash":"5861f63bec8c358e0ca607d17e7d2fc3bc0023ec","best_bid":"0.13","best_ask":"0.14"},{"asset_id":"63670753354844494163057275310194312729998307779831462269530137743341854359908","price":"0.89","size":"854.5","side":"SELL","hash":"395d7346ce61b2e15983cd9adc0fc7cbd99a957f","best_bid":"0.86","best_ask":"0.87"}],"timestamp":"1768250241374","event_type":"price_change"}}
{"schema_version":1,"source":"clob_ws_market","recv_ts_ns":1768250241786159644,"event_type":"price_change","market":"0x2a12fd3d8235c25c062dc9652970ef9f635636c4018df0909e1a51c673e125cb","server_ts_ms":1768250241374,"raw":{"market":"0x2a12fd3d8235c25c062dc9652970ef9f635636c4018df0909e1a51c673e125cb","price_changes":[{"asset_id":"63670753354844494163057275310194312729998307779831462269530137743341854359908","price":"0.85","size":"275.49","side":"BUY","hash":"506ea308ee9fb07bb4902314369ddba8a31ea205","best_bid":"0.86","best_ask":"0.87"},{"asset_id":"56386988715176239099720172290594769295756680374928571099138069977179519358166","price":"0.15","size":"275.49","side":"SELL","hash":"5bf396ffe5109536879434f15fbd0033e831c536","best_bid":"0.13","best_ask":"0.14"}],"timestamp":"1768250241374","event_type":"price_change"}}
{"schema_version":1,"source":"clob_ws_market","recv_ts_ns":1768250241789754518,"event_type":"price_change","market":"0x2a12fd3d8235c25c062dc9652970ef9f635636c4018df0909e1a51c673e125cb","server_ts_ms":1768250241375,"raw":{"market":"0x2a12fd3d8235c25c062dc9652970ef9f635636c4018df0909e1a51c673e125cb","price_changes":[{"asset_id":"63670753354844494163057275310194312729998307779831462269530137743341854359908","price":"0.83","size":"179.52","side":"BUY","hash":"a220a381c857a17ba6004272250bba491550014d","best_bid":"0.86","best_ask":"0.87"},{"asset_id":"56386988715176239099720172290594769295756680374928571099138069977179519358166","price":"0.17","size":"179.52","side":"SELL","hash":"225ebcb4e9d06f8080ef882c2fd01e657585c059","best_bid":"0.13","best_ask":"0.14"}],"timestamp":"1768250241375","event_type":"price_change"}}
{"schema_version":1,"source":"clob_ws_market","recv_ts_ns":1768250241792987392,"event_type":"price_change","market":"0x2a12fd3d8235c25c062dc9652970ef9f635636c4018df0909e1a51c673e125cb","server_ts_ms":1768250241377,"raw":{"market":"0x2a12fd3d8235c25c062dc9652970ef9f635636c4018df0909e1a51c673e125cb","price_changes":[{"asset_id":"63670753354844494163057275310194312729998307779831462269530137743341854359908","price":"0.85","size":"285.49","side":"BUY","hash":"574106a676ff2b208880e71d6cf4f612dfdd726c","best_bid":"0.86","best_ask":"0.87"},{"asset_id":"56386988715176239099720172290594769295756680374928571099138069977179519358166","price":"0.15","size":"285.49","side":"SELL","hash":"ab5f0a601f5a187f083366599af89b07e8c5ad2f","best_bid":"0.13","best_ask":"0.14"}],"timestamp":"1768250241377","event_type":"price_change"}}
{"schema_version":1,"source":"clob_ws_market","recv_ts_ns":1768250241796008264,"event_type":"price_change","market":"0x2a12fd3d8235c25c062dc9652970ef9f635636c4018df0909e1a51c673e125cb","server_ts_ms":1768250241378,"raw":{"market":"0x2a12fd3d8235c25c062dc9652970ef9f635636c4018df0909e1a51c673e125cb","price_changes":[{"asset_id":"56386988715176239099720172290594769295756680374928571099138069977179519358166","price":"0.13","size":"239","side":"BUY","hash":"c4b4a83b34caa74e035e6e0ca73ead6f400f5099","best_bid":"0.13","best_ask":"0.14"},{"asset_id":"63670753354844494163057275310194312729998307779831462269530137743341854359908","price":"0.87","size":"239","side":"SELL","hash":"b6cd766d8aea72124c12179573a2300a2459d1d3","best_bid":"0.86","best_ask":"0.87"}],"timestamp":"1768250241378","event_type":"price_change"}}
{"schema_version":1,"source":"clob_ws_market","recv_ts_ns":1768250241798825885,"event_type":"price_change","market":"0x2a12fd3d8235c25c062dc9652970ef9f635636c4018df0909e1a51c673e125cb","server_ts_ms":1768250241379,"raw":{"market":"0x2a12fd3d8235c25c062dc9652970ef9f635636c4018df0909e1a51c673e125cb","price_changes":[{"asset_id":"63670753354844494163057275310194312729998307779831462269530137743341854359908","price":"0.87","size":"233.5","side":"SELL","hash":"37a89c55e950ae8c9f17c0e12a6cd3a2610958e2","best_bid":"0.86","best_ask":"0.87"},{"asset_id":"56386988715176239099720172290594769295756680374928571099138069977179519358166","price":"0.13","size":"233.5","side":"BUY","hash":"3aedfe1cee8e86dce58f2d66932ee340a2377e7d","best_bid":"0.13","best_ask":"0.14"}],"timestamp":"1768250241379","event_type":"price_change"}}
{"schema_version":1,"source":"clob_ws_market","recv_ts_ns":1768250241801531700,"event_type":"price_change","market":"0x2a12fd3d8235c25c062dc9652970ef9f635636c4018df0909e1a51c673e125cb","server_ts_ms":1768250241380,"raw":{"market":"0x2a12fd3d8235c25c062dc9652970ef9f635636c4018df0909e1a51c673e125cb","price_changes":[{"asset_id":"63670753354844494163057275310194312729998307779831462269530137743341854359908","price":"0.85","size":"295.49","side":"BUY","hash":"29f4b902787590463885f2aef20ad023b1584e4c","best_bid":"0.86","best_ask":"0.87"},{"asset_id":"56386988715176239099720172290594769295756680374928571099138069977179519358166","price":"0.15","size":"295.49","side":"SELL","hash":"ce571e4398165c1871f730cb4df615faefab1474","best_bid":"0.13","best_ask":"0.14"}],"timestamp":"1768250241380","event_type":"price_change"}}
{"schema_version":1,"source":"clob_ws_market","recv_ts_ns":1768250241804373543,"event_type":"price_change","market":"0x2a12fd3d8235c25c062dc9652970ef9f635636c4018df0909e1a51c673e125cb","server_ts_ms":1768250241397,"raw":{"market":"0x2a12fd3d8235c25c062dc9652970ef9f635636c4018df0909e1a51c673e125cb","price_changes":[{"asset_id":"56386988715176239099720172290594769295756680374928571099138069977179519358166","price":"0.12","size":"1440.75","side":"BUY","hash":"44fcb9a882dffa7277854c9ee1be20b6897f8b8c","best_bid":"0.13","best_ask":"0.14"},{"asset_id":"63670753354844494163057275310194312729998307779831462269530137743341854359908","price":"0.88","size":"1440.75","side":"SELL","hash":"30d2db3b85e09dbf4d478dcafafb40c01afbfe81","best_bid":"0.86","best_ask":"0.87"}],"timestamp":"1768250241397","event_type":"price_change"}}
{"schema_version":1,"source":"clob_ws_market","recv_ts_ns":1768250241811465648,"event_type":"price_change","market":"0x2a12fd3d8235c25c062dc9652970ef9f635636c4018df0909e1a51c673e125cb","server_ts_ms":1768250241405,"raw":{"market":"0x2a12fd3d8235c25c062dc9652970ef9f635636c4018df0909e1a51c673e125cb","price_changes":[{"asset_id":"56386988715176239099720172290594769295756680374928571099138069977179519358166","price":"0.13","size":"239","side":"BUY","hash":"55cf8a7077c6f02811a6c1d917dee04a039d746d","best_bid":"0.13","best_ask":"0.14"},{"asset_id":"63670753354844494163057275310194312729998307779831462269530137743341854359908","price":"0.87","size":"239","side":"SELL","hash":"077e01019b35f520744c33b73093a730367010ce","best_bid":"0.86","best_ask":"0.87"}],"timestamp":"1768250241405","event_type":"price_change"}}
{"schema_version":1,"source":"clob_ws_market","recv_ts_ns":1768250241816735432,"event_type":"price_change","market":"0x2a12fd3d8235c25c062dc9652970ef9f635636c4018df0909e1a51c673e125cb","server_ts_ms":1768250241405,"raw":{"market":"0x2a12fd3d8235c25c062dc9652970ef9f635636c4018df0909e1a51c673e125cb","price_changes":[{"asset_id":"56386988715176239099720172290594769295756680374928571099138069977179519358166","price":"0.13","size":"244.5","side":"BUY","hash":"36b1f9366556c78a097794ef18b947ad35f11184","best_bid":"0.13","best_ask":"0.14"},{"asset_id":"63670753354844494163057275310194312729998307779831462269530137743341854359908","price":"0.87","size":"244.5","side":"SELL","hash":"a600e97f530754f2628d4c9d3e600b0d74cb0df9","best_bid":"0.86","best_ask":"0.87"}],"timestamp":"1768250241405","event_type":"price_change"}}
{"schema_version":1,"source":"clob_ws_market","recv_ts_ns":1768250241821500353,"event_type":"price_change","market":"0x2a12fd3d8235c25c062dc9652970ef9f635636c4018df0909e1a51c673e125cb","server_ts_ms":1768250241410,"raw":{"market":"0x2a12fd3d8235c25c062dc9652970ef9f635636c4018df0909e1a51c673e125cb","price_changes":[{"asset_id":"63670753354844494163057275310194312729998307779831462269530137743341854359908","price":"0.87","size":"250","side":"SELL","hash":"06e3cf4570cd32ac2217c396fdf683726b7291c4","best_bid":"0.86","best_ask":"0.87"},{"asset_id":"56386988715176239099720172290594769295756680374928571099138069977179519358166","price":"0.13","size":"250","side":"BUY","hash":"90f7b4a46ac472d5c84e87b5b249c52c2b4de41b","best_bid":"0.13","best_ask":"0.14"}],"timestamp":"1768250241410","event_type":"price_change"}}
{"schema_version":1,"source":"clob_ws_market","recv_ts_ns":1768250241825237237,"event_type":"price_change","market":"0x2a12fd3d8235c25c062dc9652970ef9f635636c4018df0909e1a51c673e125cb","server_ts_ms":1768250241426,"raw":{"market":"0x2a12fd3d8235c25c062dc9652970ef9f635636c4018df0909e1a51c673e125cb","price_changes":[{"asset_id":"56386988715176239099720172290594769295756680374928571099138069977179519358166","price":"0.13","size":"255.5","side":"BUY","hash":"242aaaeec2cb1589d4988ed6f10fcaa8196f5710","best_bid":"0.13","best_ask":"0.14"},{"asset_id":"63670753354844494163057275310194312729998307779831462269530137743341854359908","price":"0.87","size":"255.5","side":"SELL","hash":"6e750481f894b1bad57d8a0c17d6df6f882fd05d","best_bid":"0.86","best_ask":"0.87"}],"timestamp":"1768250241426","event_type":"price_change"}}
{"schema_version":1,"source":"clob_ws_market","recv_ts_ns":1768250241832907828,"event_type":"price_change","market":"0x2a12fd3d8235c25c062dc9652970ef9f635636c4018df0909e1a51c673e125cb","server_ts_ms":1768250241434,"raw":{"market":"0x2a12fd3d8235c25c062dc9652970ef9f635636c4018df0909e1a51c673e125cb","price_changes":[{"asset_id":"63670753354844494163057275310194312729998307779831462269530137743341854359908","price":"0.82","size":"671","side":"BUY","hash":"4d27b38f694c29be12e3c7b017b174d7f62af263","best_bid":"0.86","best_ask":"0.87"},{"asset_id":"56386988715176239099720172290594769295756680374928571099138069977179519358166","price":"0.18","size":"671","side":"SELL","hash":"745cefe9519a08dee5186dfe6e18d9c60368112a","best_bid":"0.13","best_ask":"0.14"}],"timestamp":"1768250241434","event_type":"price_change"}}
{"schema_version":1,"source":"clob_ws_market","recv_ts_ns":1768250241836132628,"event_type":"price_change","market":"0x2a12fd3d8235c25c062dc9652970ef9f635636c4018df0909e1a51c673e125cb","server_ts_ms":1768250241436,"raw":{"market":"0x2a12fd3d8235c25c062dc9652970ef9f635636c4018df0909e1a51c673e125cb","price_changes":[{"asset_id":"56386988715176239099720172290594769295756680374928571099138069977179519358166","price":"0.08","size":"1506.75","side":"BUY","hash":"1016baaf2d1a22ecc48978db892660e06c173e2b","best_bid":"0.13","best_ask":"0.14"},{"asset_id":"63670753354844494163057275310194312729998307779831462269530137743341854359908","price":"0.92","size":"1506.75","side":"SELL","hash":"0d3079b75dc80c88b213102594a36a8d1412f471","best_bid":"0.86","best_ask":"0.87"}],"timestamp":"1768250241436","event_type":"price_change"}}
{"schema_version":1,"source":"clob_ws_market","recv_ts_ns":1768250241839477376,"event_type":"price_change","market":"0x2a12fd3d8235c25c062dc9652970ef9f635636c4018df0909e1a51c673e125cb","server_ts_ms":1768250241436,"raw":{"market":"0x2a12fd3d8235c25c062dc9652970ef9f635636c4018df0909e1a51c673e125cb","price_changes":[{"asset_id":"63670753354844494163057275310194312729998307779831462269530137743341854359908","price":"0.79","size":"969.5","side":"BUY","hash":"601cbbb5a04118ff50d4e269bc45fe5ede512e79","best_bid":"0.86","best_ask":"0.87"},{"asset_id":"56386988715176239099720172290594769295756680374928571099138069977179519358166","price":"0.21","size":"969.5","side":"SELL","hash":"4e796d20b80b6a419d8abc05914a4831ac6454d0","best_bid":"0.13","best_ask":"0.14"}],"timestamp":"1768250241436","event_type":"price_change"}}
{"schema_version":1,"source":"clob_ws_market","recv_ts_ns":1768250241842849882,"event_type":"price_change","market":"0x2a12fd3d8235c25c062dc9652970ef9f635636c4018df0909e1a51c673e125cb","server_ts_ms":1768250241436,"raw":{"market":"0x2a12fd3d8235c25c062dc9652970ef9f635636c4018df0909e1a51c673e125cb","price_changes":[{"asset_id":"63670753354844494163057275310194312729998307779831462269530137743341854359908","price":"0.9","size":"3402","side":"SELL","hash":"601cbbb5a04118ff50d4e269bc45fe5ede512e79","best_bid":"0.86","best_ask":"0.87"},{"asset_id":"56386988715176239099720172290594769295756680374928571099138069977179519358166","price":"0.1","size":"3402","side":"BUY","hash":"4e796d20b80b6a419d8abc05914a4831ac6454d0","best_bid":"0.13","best_ask":"0.14"}],"timestamp":"1768250241436","event_type":"price_change"}}
{"schema_version":1,"source":"clob_ws_market","recv_ts_ns":1768250241845950188,"event_type":"price_change","market":"0x2a12fd3d8235c25c062dc9652970ef9f635636c4018df0909e1a51c673e125cb","server_ts_ms":1768250241438,"raw":{"market":"0x2a12fd3d8235c25c062dc9652970ef9f635636c4018df0909e1a51c673e125cb","price_changes":[{"asset_id":"63670753354844494163057275310194312729998307779831462269530137743341854359908","price":"0.87","size":"261","side":"SELL","hash":"6e923ab920563813043c6d3a88ddfb6e07e098b0","best_bid":"0.86","best_ask":"0.87"},{"asset_id":"56386988715176239099720172290594769295756680374928571099138069977179519358166","price":"0.13","size":"261","side":"BUY","hash":"4447ab2222f57295d303ab4f60888d56ae2a7320","best_bid":"0.13","best_ask":"0.14"}],"timestamp":"1768250241438","event_type":"price_change"}}
{"schema_version":1,"source":"clob_ws_market","recv_ts_ns":1768250241849439867,"event_type":"price_change","market":"0x2a12fd3d8235c25c062dc9652970ef9f635636c4018df0909e1a51c673e125cb","server_ts_ms":1768250241438,"raw":{"market":"0x2a12fd3d8235c25c062dc9652970ef9f635636c4018df0909e1a51c673e125cb","price_changes":[{"asset_id":"63670753354844494163057275310194312729998307779831462269530137743341854359908","price":"0.85","size":"285.49","side":"BUY","hash":"4a15584b50201ed95f6624bf8cc4527dda531c06","best_bid":"0.86","best_ask":"0.87"},{"asset_id":"56386988715176239099720172290594769295756680374928571099138069977179519358166","price":"0.15","size":"285.49","side":"SELL","hash":"538093220f7655cf2b29607fcf55c7073df9f9a9","best_bid":"0.13","best_ask":"0.14"}],"timestamp":"1768250241438","event_type":"price_change"}}
{"schema_version":1,"source":"clob_ws_market","recv_ts_ns":1768250241852870270,"event_type":"price_change","market":"0x2a12fd3d8235c25c062dc9652970ef9f635636c4018df0909e1a51c673e125cb","server_ts_ms":1768250241442,"raw":{"market":"0x2a12fd3d8235c25c062dc9652970ef9f635636c4018df0909e1a51c673e125cb","price_changes":[{"asset_id":"63670753354844494163057275310194312729998307779831462269530137743341854359908","price":"0.85","size":"275.49","side":"BUY","hash":"97c8fa6316c5541e85535663e1115a3a267efb71","best_bid":"0.86","best_ask":"0.87"},{"asset_id":"56386988715176239099720172290594769295756680374928571099138069977179519358166","price":"0.15","size":"275.49","side":"SELL","hash":"2c5da21572f1e8754bde277308517dbdc0eadea8","best_bid":"0.13","best_ask":"0.14"}],"timestamp":"1768250241442","event_type":"price_change"}}
{"schema_version":1,"source":"clob_ws_market","recv_ts_ns":1768250241856541487,"event_type":"price_change","market":"0x2a12fd3d8235c25c062dc9652970ef9f635636c4018df0909e1a51c673e125cb","server_ts_ms":1768250241443,"raw":{"market":"0x2a12fd3d8235c25c062dc9652970ef9f635636c4018df0909e1a51c673e125cb","price_changes":[{"asset_id":"63670753354844494163057275310194312729998307779831462269530137743341854359908","price":"0.85","size":"265.49","side":"BUY","hash":"767b2c2a0fbb435eac3987c982282a880c67bd63","best_bid":"0.86","best_ask":"0.87"},{"asset_id":"56386988715176239099720172290594769295756680374928571099138069977179519358166","price":"0.15","size":"265.49","side":"SELL","hash":"065209940867fa2f513f468419c72a2866705192","best_bid":"0.13","best_ask":"0.14"}],"timestamp":"1768250241443","event_type":"price_change"}}
{"schema_version":1,"source":"clob_ws_market","recv_ts_ns":1768250241860026461,"event_type":"price_change","market":"0x2a12fd3d8235c25c062dc9652970ef9f635636c4018df0909e1a51c673e125cb","server_ts_ms":1768250241445,"raw":{"market":"0x2a12fd3d8235c25c062dc9652970ef9f635636c4018df0909e1a51c673e125cb","price_changes":[{"asset_id":"63670753354844494163057275310194312729998307779831462269530137743341854359908","price":"0.85","size":"255.49","side":"BUY","hash":"eb33513bdc2cc4e18d9b84858551b10ec7dd4af6","best_bid":"0.86","best_ask":"0.87"},{"asset_id":"56386988715176239099720172290594769295756680374928571099138069977179519358166","price":"0.15","size":"255.49","side":"SELL","hash":"0528257f21159c94de6d867e3a7be3494f518fad","best_bid":"0.13","best_ask":"0.14"}],"timestamp":"1768250241445","event_type":"price_change"}}
{"schema_version":1,"source":"clob_ws_market","recv_ts_ns":1768250241863527941,"event_type":"price_change","market":"0x2a12fd3d8235c25c062dc9652970ef9f635636c4018df0909e1a51c673e125cb","server_ts_ms":1768250241448,"raw":{"market":"0x2a12fd3d8235c25c062dc9652970ef9f635636c4018df0909e1a51c673e125cb","price_changes":[{"asset_id":"56386988715176239099720172290594769295756680374928571099138069977179519358166","price":"0.09","size":"1382","side":"BUY","hash":"432952cbe41679417a485d01c87265cc078f697c","best_bid":"0.13","best_ask":"0.14"},{"asset_id":"63670753354844494163057275310194312729998307779831462269530137743341854359908","price":"0.91","size":"1382","side":"SELL","hash":"e59676318cdc0a6f921613a6d13483fb470f7955","best_bid":"0.86","best_ask":"0.87"}],"timestamp":"1768250241448","event_type":"price_change"}}
{"schema_version":1,"source":"clob_ws_market","recv_ts_ns":1768250241867142021,"event_type":"price_change","market":"0x2a12fd3d8235c25c062dc9652970ef9f635636c4018df0909e1a51c673e125cb","server_ts_ms":1768250241448,"raw":{"market":"0x2a12fd3d8235c25c062dc9652970ef9f635636c4018df0909e1a51c673e125cb","price_changes":[{"asset_id":"56386988715176239099720172290594769295756680374928571099138069977179519358166","price":"0.15","size":"104.49","side":"SELL","hash":"a9588fb8d74a2e52ece1d303f0b8fa18b22d85c1","best_bid":"0.13","best_ask":"0.14"},{"asset_id":"63670753354844494163057275310194312729998307779831462269530137743341854359908","price":"0.85","size":"104.49","side":"BUY","hash":"0d767e7293042b43a78cc8461a81602a92be67af","best_bid":"0.86","best_ask":"0.87"}],"timestamp":"1768250241448","event_type":"price_change"}}
{"schema_version":1,"source":"clob_ws_market","recv_ts_ns":1768250241870574304,"event_type":"price_change","market":"0x2a12fd3d8235c25c062dc9652970ef9f635636c4018df0909e1a51c673e125cb","server_ts_ms":1768250241449,"raw":{"market":"0x2a12fd3d8235c25c062dc9652970ef9f635636c4018df0909e1a51c673e125cb","price_changes":[{"asset_id":"63670753354844494163057275310194312729998307779831462269530137743341854359908","price":"0.85","size":"94.49","side":"BUY","hash":"359b7d636fa56a7c36eb55ed489c07169006a575","best_bid":"0.86","best_ask":"0.87"},{"asset_id":"56386988715176239099720172290594769295756680374928571099138069977179519358166","price":"0.15","size":"94.49","side":"SELL","hash":"a13780d403b27c14f54c9f153ebe9e2bd5b0f5f2","best_bid":"0.13","best_ask":"0.14"}],"timestamp":"1768250241449","event_type":"price_change"}}
{"schema_version":1,"source":"clob_ws_market","recv_ts_ns":1768250241873969076,"event_type":"price_change","market":"0x2a12fd3d8235c25c062dc9652970ef9f635636c4018df0909e1a51c673e125cb","server_ts_ms":1768250241450,"raw":{"market":"0x2a12fd3d8235c25c062dc9652970ef9f635636c4018df0909e1a51c673e125cb","price_changes":[{"asset_id":"63670753354844494163057275310194312729998307779831462269530137743341854359908","price":"0.85","size":"84.49","side":"BUY","hash":"e5e58a3affdfddfc00285db81ae285840c946aa7","best_bid":"0.86","best_ask":"0.87"},{"asset_id":"56386988715176239099720172290594769295756680374928571099138069977179519358166","price":"0.15","size":"84.49","side":"SELL","hash":"984a32bce4d8cb45cda8723362b7ad8a320f65ec","best_bid":"0.13","best_ask":"0.14"}],"timestamp":"1768250241450","event_type":"price_change"}}
{"schema_version":1,"source":"clob_ws_market","recv_ts_ns":1768250241877632662,"event_type":"price_change","market":"0x2a12fd3d8235c25c062dc9652970ef9f635636c4018df0909e1a51c673e125cb","server_ts_ms":1768250241453,"raw":{"market":"0x2a12fd3d8235c25c062dc9652970ef9f635636c4018df0909e1a51c673e125cb","price_changes":[{"asset_id":"63670753354844494163057275310194312729998307779831462269530137743341854359908","price":"0.85","size":"74.49","side":"BUY","hash":"785652e4d25db7c01f1d65239a32e13fb0c39ab3","best_bid":"0.86","best_ask":"0.87"},{"asset_id":"56386988715176239099720172290594769295756680374928571099138069977179519358166","price":"0.15","size":"74.49","side":"SELL","hash":"116bc320afb10f63b2bf7da0872cca4460408380","best_bid":"0.13","best_ask":"0.14"}],"timestamp":"1768250241453","event_type":"price_change"}}
{"schema_version":1,"source":"clob_ws_market","recv_ts_ns":1768250241882019509,"event_type":"price_change","market":"0x2a12fd3d8235c25c062dc9652970ef9f635636c4018df0909e1a51c673e125cb","server_ts_ms":1768250241454,"raw":{"market":"0x2a12fd3d8235c25c062dc9652970ef9f635636c4018df0909e1a51c673e125cb","price_changes":[{"asset_id":"56386988715176239099720172290594769295756680374928571099138069977179519358166","price":"0.1","size":"3392","side":"BUY","hash":"b6a9b828e41a429e0d71bae29bb0a69d8ebb80d1","best_bid":"0.13","best_ask":"0.14"},{"asset_id":"63670753354844494163057275310194312729998307779831462269530137743341854359908","price":"0.9","size":"3392","side":"SELL","hash":"8ce3d0b61ad50319b770cfda8d5a0b971e892f52","best_bid":"0.86","best_ask":"0.87"}],"timestamp":"1768250241454","event_type":"price_change"}}
{"schema_version":1,"source":"clob_ws_market","recv_ts_ns":1768250241887063433,"event_type":"price_change","market":"0x2a12fd3d8235c25c062dc9652970ef9f635636c4018df0909e1a51c673e125cb","server_ts_ms":1768250241454,"raw":{"market":"0x2a12fd3d8235c25c062dc9652970ef9f635636c4018df0909e1a51c673e125cb","price_changes":[{"asset_id":"56386988715176239099720172290594769295756680374928571099138069977179519358166","price":"0.11","size":"844.5","side":"BUY","hash":"8d685c7de2432248fbd300f2f4fd90e503d67e70","best_bid":"0.13","best_ask":"0.14"},{"asset_id":"63670753354844494163057275310194312729998307779831462269530137743341854359908","price":"0.89","size":"844.5","side":"SELL","hash":"b648b5b847dfdfec38b2f7933eabc4f184867dc6","best_bid":"0.86","best_ask":"0.87"}],"timestamp":"1768250241454","event_type":"price_change"}}
{"schema_version":1,"source":"clob_ws_market","recv_ts_ns":1768250241890877585,"event_type":"price_change","market":"0x2a12fd3d8235c25c062dc9652970ef9f635636c4018df0909e1a51c673e125cb","server_ts_ms":1768250241455,"raw":{"market":"0x2a12fd3d8235c25c062dc9652970ef9f635636c4018df0909e1a51c673e125cb","price_changes":[{"asset_id":"63670753354844494163057275310194312729998307779831462269530137743341854359908","price":"0.75","size":"727.5","side":"BUY","hash":"746d711a30dbc22a12ac04771913ddcc3f937bf1","best_bid":"0.86","best_ask":"0.87"},{"asset_id":"56386988715176239099720172290594769295756680374928571099138069977179519358166","price":"0.25","size":"727.5","side":"SELL","hash":"08764ee844065c080f04129eae0af590d65f2215","best_bid":"0.13","best_ask":"0.14"}],"timestamp":"1768250241455","event_type":"price_change"}}
{"schema_version":1,"source":"clob_ws_market","recv_ts_ns":1768250241894575839,"event_type":"price_change","market":"0x2a12fd3d8235c25c062dc9652970ef9f635636c4018df0909e1a51c673e125cb","server_ts_ms":1768250241456,"raw":{"market":"0x2a12fd3d8235c25c062dc9652970ef9f635636c4018df0909e1a51c673e125cb","price_changes":[{"asset_id":"56386988715176239099720172290594769295756680374928571099138069977179519358166","price":"0.13","size":"351","side":"BUY","hash":"d58bb27e9abae62a1f98ad390a6c3f5b68668103","best_bid":"0.13","best_ask":"0.14"},{"asset_id":"63670753354844494163057275310194312729998307779831462269530137743341854359908","price":"0.87","size":"351","side":"SELL","hash":"1926475ae49e1b8e3eb0f32bbe3b74494f9c9d04","best_bid":"0.86","best_ask":"0.87"}],"timestamp":"1768250241456","event_type":"price_change"}}
{"schema_version":1,"source":"clob_ws_market","recv_ts_ns":1768250241898654799,"event_type":"price_change","market":"0x2a12fd3d8235c25c062dc9652970ef9f635636c4018df0909e1a51c673e125cb","server_ts_ms":1768250241463,"raw":{"market":"0x2a12fd3d8235c25c062dc9652970ef9f635636c4018df0909e1a51c673e125cb","price_changes":[{"asset_id":"56386988715176239099720172290594769295756680374928571099138069977179519358166","price":"0.08","size":"1569.75","side":"BUY","hash":"b113c9c4b2502b802afbcd669d59527d995ae2ef","best_bid":"0.13","best_ask":"0.14"},{"asset_id":"63670753354844494163057275310194312729998307779831462269530137743341854359908","price":"0.92","size":"1569.75","side":"SELL","hash":"710c0b7944f94e4278ae206a1fa36d37f4da4cca","best_bid":"0.86","best_ask":"0.87"}],"timestamp":"1768250241463","event_type":"price_change"}}
{"schema_version":1,"source":"clob_ws_market","recv_ts_ns":1768250241901862870,"event_type":"price_change","market":"0x2a12fd3d8235c25c062dc9652970ef9f635636c4018df0909e1a51c673e125cb","server_ts_ms":1768250241464,"raw":{"market":"0x2a12fd3d8235c25c062dc9652970ef9f635636c4018df0909e1a51c673e125cb","price_changes":[{"asset_id":"63670753354844494163057275310194312729998307779831462269530137743341854359908","price":"0.85","size":"64.49","side":"BUY","hash":"f92091716769b46c2b7ac8bb75ec92fa94a47985","best_bid":"0.86","best_ask":"0.87"},{"asset_id":"56386988715176239099720172290594769295756680374928571099138069977179519358166","price":"0.15","size":"64.49","side":"SELL","hash":"46f44a7e126a88ab7a677c6adb3eb471e3fdd0d7","best_bid":"0.13","best_ask":"0.14"}],"timestamp":"1768250241464","event_type":"price_change"}}
{"schema_version":1,"source":"clob_ws_market","recv_ts_ns":1768250241905105334,"event_type":"price_change","market":"0x2a12fd3d8235c25c062dc9652970ef9f635636c4018df0909e1a51c673e125cb","server_ts_ms":1768250241469,"raw":{"market":"0x2a12fd3d8235c25c062dc9652970ef9f635636c4018df0909e1a51c673e125cb","price_changes":[{"asset_id":"63670753354844494163057275310194312729998307779831462269530137743341854359908","price":"0.82","size":"171","side":"BUY","hash":"8b4cdbcc6fb1a02a911c264ddec9b3abc2d8d7ac","best_bid":"0.86","best_ask":"0.87"},{"asset_id":"56386988715176239099720172290594769295756680374928571099138069977179519358166","price":"0.18","size":"171","side":"SELL","hash":"ef03ef0ba040e81c5df0a83269141e3d92532842","best_bid":"0.13","best_ask":"0.14"}],"timestamp":"1768250241469","event_type":"price_change"}}
{"schema_version":1,"source":"clob_ws_market","recv_ts_ns":1768250241909878077,"event_type":"price_change","market":"0x2a12fd3d8235c25c062dc9652970ef9f635636c4018df0909e1a51c673e125cb","server_ts_ms":1768250241470,"raw":{"market":"0x2a12fd3d8235c25c062dc9652970ef9f635636c4018df0909e1a51c673e125cb","price_changes":[{"asset_id":"63670753354844494163057275310194312729998307779831462269530137743341854359908","price":"0.86","size":"267.13","side":"BUY","hash":"e673be659cce546a84c65663dc76e8216bfdce49","best_bid":"0.86","best_ask":"0.87"},{"asset_id":"56386988715176239099720172290594769295756680374928571099138069977179519358166","price":"0.14","size":"267.13","side":"SELL","hash":"b5bcfb65acd46119f87ab636de1975b8ab7e76a2","best_bid":"0.13","best_ask":"0.14"}],"timestamp":"1768250241470","event_type":"price_change"}}
{"schema_version":1,"source":"clob_ws_market","recv_ts_ns":1768250241915289254,"event_type":"price_change","market":"0x2a12fd3d8235c25c062dc9652970ef9f635636c4018df0909e1a51c673e125cb","server_ts_ms":1768250241474,"raw":{"market":"0x2a12fd3d8235c25c062dc9652970ef9f635636c4018df0909e1a51c673e125cb","price_changes":[{"asset_id":"63670753354844494163057275310194312729998307779831462269530137743341854359908","price":"0.8","size":"814.9","side":"BUY","hash":"6c9956d4de56117bd2282c473a87f1064cf3c0a2","best_bid":"0.86","best_ask":"0.87"},{"asset_id":"56386988715176239099720172290594769295756680374928571099138069977179519358166","price":"0.2","size":"814.9","side":"SELL","hash":"3080b7de5c0d14b897f57c3ed56a72e55edf0aef","best_bid":"0.13","best_ask":"0.14"}],"timestamp":"1768250241474","event_type":"price_change"}}
{"schema_version":1,"source":"clob_ws_market","recv_ts_ns":1768250241920711874,"event_type":"price_change","market":"0x2a12fd3d8235c25c062dc9652970ef9f635636c4018df0909e1a51c673e125cb","server_ts_ms":1768250241476,"raw":{"market":"0x2a12fd3d8235c25c062dc9652970ef9f635636c4018df0909e1a51c673e125cb","price_changes":[{"asset_id":"63670753354844494163057275310194312729998307779831462269530137743341854359908","price":"0.9","size":"3398","side":"SELL","hash":"23ac1b7676237f015a030fa4f8ea1db2414a424e","best_bid":"0.86","best_ask":"0.87"},{"asset_id":"56386988715176239099720172290594769295756680374928571099138069977179519358166","price":"0.1","size":"3398","side":"BUY","hash":"9310fa60318a4182a04daa5ab182f82d499d8423","best_bid":"0.13","best_ask":"0.14"}],"timestamp":"1768250241476","event_type":"price_change"}}
{"schema_version":1,"source":"clob_ws_market","recv_ts_ns":1768250241925727861,"event_type":"price_change","market":"0x2a12fd3d8235c25c062dc9652970ef9f635636c4018df0909e1a51c673e125cb","server_ts_ms":1768250241477,"raw":{"market":"0x2a12fd3d8235c25c062dc9652970ef9f635636c4018df0909e1a51c673e125cb","price_changes":[{"asset_id":"63670753354844494163057275310194312729998307779831462269530137743341854359908","price":"0.79","size":"975.5","side":"BUY","hash":"7298dc73d3e181acab511f97008357876219535e","best_bid":"0.86","best_ask":"0.87"},{"asset_id":"56386988715176239099720172290594769295756680374928571099138069977179519358166","price":"0.21","size":"975.5","side":"SELL","hash":"4688db61e9f384d99f55c8b3aacf9bd04b804851","best_bid":"0.13","best_ask":"0.14"}],"timestamp":"1768250241477","event_type":"price_change"}}
{"schema_version":1,"source":"clob_ws_market","recv_ts_ns":1768250241940461771,"event_type":"price_change","market":"0x2a12fd3d8235c25c062dc9652970ef9f635636c4018df0909e1a51c673e125cb","server_ts_ms":1768250241493,"raw":{"market":"0x2a12fd3d8235c25c062dc9652970ef9f635636c4018df0909e1a51c673e125cb","price_changes":[{"asset_id":"63670753354844494163057275310194312729998307779831462269530137743341854359908","price":"0.85","size":"74.49","side":"BUY","hash":"cae46822f5b2cada536aae4e6f3815179fd18eba","best_bid":"0.86","best_ask":"0.87"},{"asset_id":"56386988715176239099720172290594769295756680374928571099138069977179519358166","price":"0.15","size":"74.49","side":"SELL","hash":"d3198ff89cfc71f2b8a6abcabdc1fa8d3d015bb1","best_bid":"0.13","best_ask":"0.14"}],"timestamp":"1768250241493","event_type":"price_change"}}
{"schema_version":1,"source":"clob_ws_market","recv_ts_ns":1768250241945777236,"event_type":"price_change","market":"0x2a12fd3d8235c25c062dc9652970ef9f635636c4018df0909e1a51c673e125cb","server_ts_ms":1768250241494,"raw":{"market":"0x2a12fd3d8235c25c062dc9652970ef9f635636c4018df0909e1a51c673e125cb","price_changes":[{"asset_id":"63670753354844494163057275310194312729998307779831462269530137743341854359908","price":"0.85","size":"84.49","side":"BUY","hash":"b0055df523b3556d2ffd22a3868153f898e00a0b","best_bid":"0.86","best_ask":"0.87"},{"asset_id":"56386988715176239099720172290594769295756680374928571099138069977179519358166","price":"0.15","size":"84.49","side":"SELL","hash":"68ce0f21d5f3612ee3512bb88dc1b747c1b0a5a1","best_bid":"0.13","best_ask":"0.14"}],"timestamp":"1768250241494","event_type":"price_change"}}
{"schema_version":1,"source":"clob_ws_market","recv_ts_ns":1768250241951579729,"event_type":"price_change","market":"0x2a12fd3d8235c25c062dc9652970ef9f635636c4018df0909e1a51c673e125cb","server_ts_ms":1768250241496,"raw":{"market":"0x2a12fd3d8235c25c062dc9652970ef9f635636c4018df0909e1a51c673e125cb","price_changes":[{"asset_id":"63670753354844494163057275310194312729998307779831462269530137743341854359908","price":"0.84","size":"196","side":"BUY","hash":"9e4b418772f82f3624ee7388fc47a9121ef14d50","best_bid":"0.86","best_ask":"0.87"},{"asset_id":"56386988715176239099720172290594769295756680374928571099138069977179519358166","price":"0.16","size":"196","side":"SELL","hash":"4898367981f2a733e9c9695d4902be8d8ddee2db","best_bid":"0.13","best_ask":"0.14"}],"timestamp":"1768250241496","event_type":"price_change"}}
{"schema_version":1,"source":"clob_ws_market","recv_ts_ns":1768250241957247793,"event_type":"price_change","market":"0x2a12fd3d8235c25c062dc9652970ef9f635636c4018df0909e1a51c673e125cb","server_ts_ms":1768250241497,"raw":{"market":"0x2a12fd3d8235c25c062dc9652970ef9f635636c4018df0909e1a51c673e125cb","price_changes":[{"asset_id":"56386988715176239099720172290594769295756680374928571099138069977179519358166","price":"0.11","size":"854.5","side":"BUY","hash":"5b796fe53e3d53f1736215c00b1005db38b003df","best_bid":"0.13","best_ask":"0.14"},{"asset_id":"63670753354844494163057275310194312729998307779831462269530137743341854359908","price":"0.89","size":"854.5","side":"SELL","hash":"30bc0553a513ebe7eb38d97fccca11e074f38171","best_bid":"0.86","best_ask":"0.87"}],"timestamp":"1768250241497","event_type":"price_change"}}
{"schema_version":1,"source":"clob_ws_market","recv_ts_ns":1768250241961923088,"event_type":"price_change","market":"0x2a12fd3d8235c25c062dc9652970ef9f635636c4018df0909e1a51c673e125cb","server_ts_ms":1768250241498,"raw":{"market":"0x2a12fd3d8235c25c062dc9652970ef9f635636c4018df0909e1a51c673e125cb","price_changes":[{"asset_id":"63670753354844494163057275310194312729998307779831462269530137743341854359908","price":"0.85","size":"94.49","side":"BUY","hash":"e29796fd68db16ac2e25d2c0f89dcb1e6603108b","best_bid":"0.86","best_ask":"0.87"},{"asset_id":"56386988715176239099720172290594769295756680374928571099138069977179519358166","price":"0.15","size":"94.49","side":"SELL","hash":"780135cfb094825e17320c50c770dc6479dba436","best_bid":"0.13","best_ask":"0.14"}],"timestamp":"1768250241498","event_type":"price_change"}}
{"schema_version":1,"source":"clob_ws_market","recv_ts_ns":1768250241965585693,"event_type":"price_change","market":"0x2a12fd3d8235c25c062dc9652970ef9f635636c4018df0909e1a51c673e125cb","server_ts_ms":1768250241499,"raw":{"market":"0x2a12fd3d8235c25c062dc9652970ef9f635636c4018df0909e1a51c673e125cb","price_changes":[{"asset_id":"63670753354844494163057275310194312729998307779831462269530137743341854359908","price":"0.85","size":"104.49","side":"BUY","hash":"638249a73e2585e30a9d5f4892e2a4074c6e953d","best_bid":"0.86","best_ask":"0.87"},{"asset_id":"56386988715176239099720172290594769295756680374928571099138069977179519358166","price":"0.15","size":"104.49","side":"SELL","hash":"1b1873534523fd751bbe12e490fe95291eafa722","best_bid":"0.13","best_ask":"0.14"}],"timestamp":"1768250241499","event_type":"price_change"}}
{"schema_version":1,"source":"clob_ws_market","recv_ts_ns":1768250241973202542,"event_type":"price_change","market":"0x2a12fd3d8235c25c062dc9652970ef9f635636c4018df0909e1a51c673e125cb","server_ts_ms":1768250241500,"raw":{"market":"0x2a12fd3d8235c25c062dc9652970ef9f635636c4018df0909e1a51c673e125cb","price_changes":[{"asset_id":"63670753354844494163057275310194312729998307779831462269530137743341854359908","price":"0.85","size":"94.49","side":"BUY","hash":"78c7997127d09c687d0409e0c54f772eda3d95a6","best_bid":"0.86","best_ask":"0.87"},{"asset_id":"56386988715176239099720172290594769295756680374928571099138069977179519358166","price":"0.15","size":"94.49","side":"SELL","hash":"1b0cfe854c6626d48242e5a2c9c0921d63284da1","best_bid":"0.13","best_ask":"0.14"}],"timestamp":"1768250241500","event_type":"price_change"}}
{"schema_version":1,"source":"clob_ws_market","recv_ts_ns":1768250241979195633,"event_type":"price_change","market":"0x2a12fd3d8235c25c062dc9652970ef9f635636c4018df0909e1a51c673e125cb","server_ts_ms":1768250241501,"raw":{"market":"0x2a12fd3d8235c25c062dc9652970ef9f635636c4018df0909e1a51c673e125cb","price_changes":[{"asset_id":"63670753354844494163057275310194312729998307779831462269530137743341854359908","price":"0.85","size":"104.49","side":"BUY","hash":"d8e64dd823b2148f54e7c1f1df1b4819eedcb70c","best_bid":"0.86","best_ask":"0.87"},{"asset_id":"56386988715176239099720172290594769295756680374928571099138069977179519358166","price":"0.15","size":"104.49","side":"SELL","hash":"8d6aa0ed5e499d6a00b4eff3c93575959b986fff","best_bid":"0.13","best_ask":"0.14"}],"timestamp":"1768250241501","event_type":"price_change"}}
{"schema_version":1,"source":"clob_ws_market","recv_ts_ns":1768250241984936149,"event_type":"price_change","market":"0x2a12fd3d8235c25c062dc9652970ef9f635636c4018df0909e1a51c673e125cb","server_ts_ms":1768250241502,"raw":{"market":"0x2a12fd3d8235c25c062dc9652970ef9f635636c4018df0909e1a51c673e125cb","price_changes":[{"asset_id":"63670753354844494163057275310194312729998307779831462269530137743341854359908","price":"0.86","size":"272.63","side":"BUY","hash":"7dce4e1fb00fc7193087018647b08f8fb3c528ed","best_bid":"0.86","best_ask":"0.87"},{"asset_id":"56386988715176239099720172290594769295756680374928571099138069977179519358166","price":"0.14","size":"272.63","side":"SELL","hash":"fef36644c3748f11840be87a6de358c48b96979a","best_bid":"0.13","best_ask":"0.14"}],"timestamp":"1768250241502","event_type":"price_change"}}
{"schema_version":1,"source":"clob_ws_market","recv_ts_ns":1768250241989872275,"event_type":"price_change","market":"0x2a12fd3d8235c25c062dc9652970ef9f635636c4018df0909e1a51c673e125cb","server_ts_ms":1768250241504,"raw":{"market":"0x2a12fd3d8235c25c062dc9652970ef9f635636c4018df0909e1a51c673e125cb","price_changes":[{"asset_id":"63670753354844494163057275310194312729998307779831462269530137743341854359908","price":"0.85","size":"114.49","side":"BUY","hash":"a18f62a5f55fc1f1e2ebd43769a2a88f81483867","best_bid":"0.86","best_ask":"0.87"},{"asset_id":"56386988715176239099720172290594769295756680374928571099138069977179519358166","price":"0.15","size":"114.49","side":"SELL","hash":"59f5833d1497e7a69453fc961086f376ea5e3f85","best_bid":"0.13","best_ask":"0.14"}],"timestamp":"1768250241504","event_type":"price_change"}}
{"schema_version":1,"source":"clob_ws_market","recv_ts_ns":1768250241995189319,"event_type":"price_change","market":"0x2a12fd3d8235c25c062dc9652970ef9f635636c4018df0909e1a51c673e125cb","server_ts_ms":1768250241505,"raw":{"market":"0x2a12fd3d8235c25c062dc9652970ef9f635636c4018df0909e1a51c673e125cb","price_changes":[{"asset_id":"63670753354844494163057275310194312729998307779831462269530137743341854359908","price":"0.85","size":"124.49","side":"BUY","hash":"8a7f9dc92b0e0459f5326e344e0289c2e4e1afb6","best_bid":"0.86","best_ask":"0.87"},{"asset_id":"56386988715176239099720172290594769295756680374928571099138069977179519358166","price":"0.15","size":"124.49","side":"SELL","hash":"e40a59b92d5486d974d297f84bfd959b688c0c64","best_bid":"0.13","best_ask":"0.14"}],"timestamp":"1768250241505","event_type":"price_change"}}
{"schema_version":1,"source":"clob_ws_market","recv_ts_ns":1768250241999737655,"event_type":"price_change","market":"0x2a12fd3d8235c25c062dc9652970ef9f635636c4018df0909e1a51c673e125cb","server_ts_ms":1768250241508,"raw":{"market":"0x2a12fd3d8235c25c062dc9652970ef9f635636c4018df0909e1a51c673e125cb","price_changes":[{"asset_id":"56386988715176239099720172290594769295756680374928571099138069977179519358166","price":"0.1","size":"3408","side":"BUY","hash":"db9b702dcc64202b8cd47d1f82b0234f85044317","best_bid":"0.13","best_ask":"0.14"},{"asset_id":"63670753354844494163057275310194312729998307779831462269530137743341854359908","price":"0.9","size":"3408","side":"SELL","hash":"a27e6b54971cd347adf09c518d9ef287cdd5052b","best_bid":"0.86","best_ask":"0.87"}],"timestamp":"1768250241508","event_type":"price_change"}}
{"schema_version":1,"source":"clob_ws_market","recv_ts_ns":1768250242015150093,"event_type":"price_change","market":"0x2a12fd3d8235c25c062dc9652970ef9f635636c4018df0909e1a51c673e125cb","server_ts_ms":1768250241512,"raw":{"market":"0x2a12fd3d8235c25c062dc9652970ef9f635636c4018df0909e1a51c673e125cb","price_changes":[{"asset_id":"56386988715176239099720172290594769295756680374928571099138069977179519358166","price":"0.1","size":"3418","side":"BUY","hash":"e0398a6613eac8f4d6469d7089833db3ee918564","best_bid":"0.13","best_ask":"0.14"},{"asset_id":"63670753354844494163057275310194312729998307779831462269530137743341854359908","price":"0.9","size":"3418","side":"SELL","hash":"866bf2172d52af45d2daa5f042f288e478395293","best_bid":"0.86","best_ask":"0.87"}],"timestamp":"1768250241512","event_type":"price_change"}}
{"schema_version":1,"source":"clob_ws_market","recv_ts_ns":1768250242042270717,"event_type":"price_change","market":"0x2a12fd3d8235c25c062dc9652970ef9f635636c4018df0909e1a51c673e125cb","server_ts_ms":1768250241547,"raw":{"market":"0x2a12fd3d8235c25c062dc9652970ef9f635636c4018df0909e1a51c673e125cb","price_changes":[{"asset_id":"63670753354844494163057275310194312729998307779831462269530137743341854359908","price":"0.85","size":"134.49","side":"BUY","hash":"b2d49e20960e5ba61366de3d6d5268d6853d9408","best_bid":"0.86","best_ask":"0.87"},{"asset_id":"56386988715176239099720172290594769295756680374928571099138069977179519358166","price":"0.15","size":"134.49","side":"SELL","hash":"2d90c21557cfe21300a1d5862febebbe052a03b3","best_bid":"0.13","best_ask":"0.14"}],"timestamp":"1768250241547","event_type":"price_change"}}
{"schema_version":1,"source":"clob_ws_market","recv_ts_ns":1768250242051618464,"event_type":"price_change","market":"0x2a12fd3d8235c25c062dc9652970ef9f635636c4018df0909e1a51c673e125cb","server_ts_ms":1768250241581,"raw":{"market":"0x2a12fd3d8235c25c062dc9652970ef9f635636c4018df0909e1a51c673e125cb","price_changes":[{"asset_id":"63670753354844494163057275310194312729998307779831462269530137743341854359908","price":"0.82","size":"671","side":"BUY","hash":"0bef969ea386e0f0ebac9d4119d399ea2272fe84","best_bid":"0.86","best_ask":"0.87"},{"asset_id":"56386988715176239099720172290594769295756680374928571099138069977179519358166","price":"0.18","size":"671","side":"SELL","hash":"9acb5fd1903dc1c901d3fe79e90befc10bfff6b5","best_bid":"0.13","best_ask":"0.14"}],"timestamp":"1768250241581","event_type":"price_change"}}
{"schema_version":1,"source":"clob_ws_market","recv_ts_ns":1768250242055621559,"event_type":"price_change","market":"0x2a12fd3d8235c25c062dc9652970ef9f635636c4018df0909e1a51c673e125cb","server_ts_ms":1768250241592,"raw":{"market":"0x2a12fd3d8235c25c062dc9652970ef9f635636c4018df0909e1a51c673e125cb","price_changes":[{"asset_id":"63670753354844494163057275310194312729998307779831462269530137743341854359908","price":"0.86","size":"21","side":"BUY","hash":"76623adab3922202824c811e19fef16611add2bb","best_bid":"0.86","best_ask":"0.87"},{"asset_id":"56386988715176239099720172290594769295756680374928571099138069977179519358166","price":"0.14","size":"21","side":"SELL","hash":"8d99fed5035735c9ee0a6e23f8c11ba15496d82c","best_bid":"0.13","best_ask":"0.14"}],"timestamp":"1768250241592","event_type":"price_change"}}
{"schema_version":1,"source":"clob_ws_market","recv_ts_ns":1768250242063651237,"event_type":"price_change","market":"0x2a12fd3d8235c25c062dc9652970ef9f635636c4018df0909e1a51c673e125cb","server_ts_ms":1768250241606,"raw":{"market":"0x2a12fd3d8235c25c062dc9652970ef9f635636c4018df0909e1a51c673e125cb","price_changes":[{"asset_id":"63670753354844494163057275310194312729998307779831462269530137743341854359908","price":"0.86","size":"15.5","side":"BUY","hash":"1cb71863fa8855b262fc48968821ef9cdb22a12f","best_bid":"0.86","best_ask":"0.87"},{"asset_id":"56386988715176239099720172290594769295756680374928571099138069977179519358166","price":"0.14","size":"15.5","side":"SELL","hash":"52ebdec493bc353a688a281a9fd42b3ada879760","best_bid":"0.13","best_ask":"0.14"}],"timestamp":"1768250241606","event_type":"price_change"}}
{"schema_version":1,"source":"clob_ws_market","recv_ts_ns":1768250242071614409,"event_type":"price_change","market":"0x2a12fd3d8235c25c062dc9652970ef9f635636c4018df0909e1a51c673e125cb","server_ts_ms":1768250241622,"raw":{"market":"0x2a12fd3d8235c25c062dc9652970ef9f635636c4018df0909e1a51c673e125cb","price_changes":[{"asset_id":"56386988715176239099720172290594769295756680374928571099138069977179519358166","price":"0.14","size":"10","side":"SELL","hash":"64f5be2474011fcba9cf3b036a9e9b78c53a309b","best_bid":"0.13","best_ask":"0.14"},{"asset_id":"63670753354844494163057275310194312729998307779831462269530137743341854359908","price":"0.86","size":"10","side":"BUY","hash":"5b4b1731c574c71fb6918dcd109cef8b44fb8898","best_bid":"0.86","best_ask":"0.87"}],"timestamp":"1768250241622","event_type":"price_change"}}
{"schema_version":1,"source":"clob_ws_market","recv_ts_ns":1768250242075992923,"event_type":"price_change","market":"0x2a12fd3d8235c25c062dc9652970ef9f635636c4018df0909e1a51c673e125cb","server_ts_ms":1768250241644,"raw":{"market":"0x2a12fd3d8235c25c062dc9652970ef9f635636c4018df0909e1a51c673e125cb","price_changes":[{"asset_id":"63670753354844494163057275310194312729998307779831462269530137743341854359908","price":"0.87","size":"366","side":"SELL","hash":"342a2bbddbf8369127505d3db589432162934ee4","best_bid":"0.86","best_ask":"0.87"},{"asset_id":"56386988715176239099720172290594769295756680374928571099138069977179519358166","price":"0.13","size":"366","side":"BUY","hash":"d63e65b51cf48535eace7b58c14df2d1f23e0b80","best_bid":"0.13","best_ask":"0.14"}],"timestamp":"1768250241644","event_type":"price_change"}}
{"schema_version":1,"source":"clob_ws_market","recv_ts_ns":1768250242083809567,"event_type":"best_bid_ask","market":"0x2a12fd3d8235c25c062dc9652970ef9f635636c4018df0909e1a51c673e125cb","server_ts_ms":1768250241648,"raw":{"market":"0x2a12fd3d8235c25c062dc9652970ef9f635636c4018df0909e1a51c673e125cb","asset_id":"56386988715176239099720172290594769295756680374928571099138069977179519358166","best_bid":"0.14","best_ask":"0.15","spread":"0.01","timestamp":"1768250241648","event_type":"best_bid_ask"}}
{"schema_version":1,"source":"clob_ws_market","recv_ts_ns":1768250242090119117,"event_type":"price_change","market":"0x2a12fd3d8235c25c062dc9652970ef9f635636c4018df0909e1a51c673e125cb","server_ts_ms":1768250241647,"raw":{"market":"0x2a12fd3d8235c25c062dc9652970ef9f635636c4018df0909e1a51c673e125cb","price_changes":[{"asset_id":"56386988715176239099720172290594769295756680374928571099138069977179519358166","price":"0.14","size":"151","side":"BUY","hash":"5b11a9be70eb02a737c0f732d9337c61897f9044","best_bid":"0.14","best_ask":"0.15"},{"asset_id":"63670753354844494163057275310194312729998307779831462269530137743341854359908","price":"0.86","size":"151","side":"SELL","hash":"f4eb8e608d577ecfc3350db79685ba328f22456a","best_bid":"0.85","best_ask":"0.86"}],"timestamp":"1768250241647","event_type":"price_change"}}
{"schema_version":1,"source":"clob_ws_market","recv_ts_ns":1768250242096700143,"event_type":"book","market":"0x2a12fd3d8235c25c062dc9652970ef9f635636c4018df0909e1a51c673e125cb","server_ts_ms":1768250241647,"raw":{"market":"0x2a12fd3d8235c25c062dc9652970ef9f635636c4018df0909e1a51c673e125cb","asset_id":"56386988715176239099720172290594769295756680374928571099138069977179519358166","bids":[{"price":"0.01","size":"10157.67"},{"price":"0.02","size":"6299.77"},{"price":"0.03","size":"5625.94"},{"price":"0.04","size":"5427"},{"price":"0.05","size":"3462"},{"price":"0.06","size":"1397"},{"price":"0.07","size":"1418.78"},{"price":"0.08","size":"1569.75"},{"price":"0.09","size":"1382"},{"price":"0.1","size":"3418"},{"price":"0.11","size":"854.5"},{"price":"0.12","size":"1440.75"},{"price":"0.13","size":"366"},{"price":"0.14","size":"151"}],"asks":[{"price":"0.99","size":"10184.18"},{"price":"0.98","size":"5982"},{"price":"0.97","size":"5238.94"},{"price":"0.96","size":"5040"},{"price":"0.95","size":"5050"},{"price":"0.94","size":"5005"},{"price":"0.93","size":"5019.28"},{"price":"0.92","size":"5005"},{"price":"0.91","size":"5005"},{"price":"0.9","size":"5030"},{"price":"0.89","size":"5"},{"price":"0.88","size":"5"},{"price":"0.87","size":"5"},{"price":"0.86","size":"5"},{"price":"0.85","size":"10"},{"price":"0.84","size":"5"},{"price":"0.83","size":"5"},{"price":"0.82","size":"5"},{"price":"0.81","size":"5"},{"price":"0.8","size":"5"},{"price":"0.79","size":"5"},{"price":"0.78","size":"5"},{"price":"0.77","size":"5"},{"price":"0.76","size":"5"},{"price":"0.75","size":"10"},{"price":"0.74","size":"5"},{"price":"0.73","size":"5"},{"price":"0.72","size":"5"},{"price":"0.71","size":"15"},{"price":"0.7","size":"10"},{"price":"0.69","size":"5"},{"price":"0.68","size":"5"},{"price":"0.67","size":"5"},{"price":"0.66","size":"505"},{"price":"0.65","size":"510"},{"price":"0.64","size":"510"},{"price":"0.63","size":"505"},{"price":"0.62","size":"505"},{"price":"0.61","size":"755"},{"price":"0.6","size":"760"},{"price":"0.59","size":"916"},{"price":"0.58","size":"671"},{"price":"0.57","size":"827"},{"price":"0.56","size":"827"},{"price":"0.55","size":"817"},{"price":"0.54","size":"872"},{"price":"0.53","size":"839.65"},{"price":"0.52","size":"829"},{"price":"0.51","size":"817"},{"price":"0.5","size":"838.4"},{"price":"0.49","size":"867.58"},{"price":"0.48","size":"817"},{"price":"0.47","size":"827"},{"price":"0.46","size":"847.8"},{"price":"0.45","size":"836.09"},{"price":"0.44","size":"825"},{"price":"0.43","size":"847"},{"price":"0.42","size":"817"},{"price":"0.41","size":"817"},{"price":"0.4","size":"817"},{"price":"0.39","size":"834.5"},{"price":"0.38","size":"817"},{"price":"0.37","size":"497.49"},{"price":"0.36","size":"817"},{"price":"0.35","size":"872"},{"price":"0.34","size":"906.8"},{"price":"0.33","size":"996.36"},{"price":"0.32","size":"902"},{"price":"0.31","size":"922"},{"price":"0.3","size":"911.6"},{"price":"0.29","size":"897"},{"price":"0.28","size":"899.55"},{"price":"0.27","size":"912"},{"price":"0.26","size":"1174.42"},{"price":"0.25","size":"727.5"},{"price":"0.24","size":"912.05"},{"price":"0.23","size":"748.5"},{"price":"0.22","size":"916.9"},{"price":"0.21","size":"975.5"},{"price":"0.2","size":"814.9"},{"price":"0.19","size":"888.21"},{"price":"0.18","size":"671"},{"price":"0.17","size":"179.52"},{"price":"0.16","size":"196"},{"price":"0.15","size":"134.49"}],"hash":"5b11a9be70eb02a737c0f732d9337c61897f9044","timestamp":"1768250241647","event_type":"book"}}
{"schema_version":1,"source":"clob_ws_market","recv_ts_ns":1768250242105674950,"event_type":"price_change","market":"0x2a12fd3d8235c25c062dc9652970ef9f635636c4018df0909e1a51c673e125cb","server_ts_ms":1768250241653,"raw":{"market":"0x2a12fd3d8235c25c062dc9652970ef9f635636c4018df0909e1a51c673e125cb","price_changes":[{"asset_id":"63670753354844494163057275310194312729998307779831462269530137743341854359908","price":"0.85","size":"139.99","side":"BUY","hash":"7d7a1ab5834e48c8a31aa983ae284ced589da902","best_bid":"0.85","best_ask":"0.86"},{"asset_id":"56386988715176239099720172290594769295756680374928571099138069977179519358166","price":"0.15","size":"139.99","side":"SELL","hash":"617a717d141a2bbc3d31d1af3c304bf474e475bd","best_bid":"0.14","best_ask":"0.15"}],"timestamp":"1768250241653","event_type":"price_change"}}
{"schema_version":1,"source":"clob_ws_market","recv_ts_ns":1768250242110468045,"event_type":"price_change","market":"0x2a12fd3d8235c25c062dc9652970ef9f635636c4018df0909e1a51c673e125cb","server_ts_ms":1768250241654,"raw":{"market":"0x2a12fd3d8235c25c062dc9652970ef9f635636c4018df0909e1a51c673e125cb","price_changes":[{"asset_id":"63670753354844494163057275310194312729998307779831462269530137743341854359908","price":"0.82","size":"171","side":"BUY","hash":"29e0c2a5d3808114d84a7765addb35c6630e916e","best_bid":"0.85","best_ask":"0.86"},{"asset_id":"56386988715176239099720172290594769295756680374928571099138069977179519358166","price":"0.18","size":"171","side":"SELL","hash":"8ff149f751d4888a184600eab32c451f38149f8d","best_bid":"0.14","best_ask":"0.15"}],"timestamp":"1768250241654","event_type":"price_change"}}
{"schema_version":1,"source":"clob_ws_market","recv_ts_ns":1768250242114844118,"event_type":"price_change","market":"0x2a12fd3d8235c25c062dc9652970ef9f635636c4018df0909e1a51c673e125cb","server_ts_ms":1768250241655,"raw":{"market":"0x2a12fd3d8235c25c062dc9652970ef9f635636c4018df0909e1a51c673e125cb","price_changes":[{"asset_id":"56386988715176239099720172290594769295756680374928571099138069977179519358166","price":"0.15","size":"145.49","side":"SELL","hash":"a398b4cb5e575f8d020a630203349a13a55c26f2","best_bid":"0.14","best_ask":"0.15"},{"asset_id":"63670753354844494163057275310194312729998307779831462269530137743341854359908","price":"0.85","size":"145.49","side":"BUY","hash":"ffed8d97e2c2e824beb9b283d00f3ab9df85318a","best_bid":"0.85","best_ask":"0.86"}],"timestamp":"1768250241655","event_type":"price_change"}}
{"schema_version":1,"source":"clob_ws_market","recv_ts_ns":1768250242118841351,"event_type":"price_change","market":"0x2a12fd3d8235c25c062dc9652970ef9f635636c4018df0909e1a51c673e125cb","server_ts_ms":1768250241669,"raw":{"market":"0x2a12fd3d8235c25c062dc9652970ef9f635636c4018df0909e1a51c673e125cb","price_changes":[{"asset_id":"63670753354844494163057275310194312729998307779831462269530137743341854359908","price":"0.75","size":"722.5","side":"BUY","hash":"51b60107c51f96ce1037d2d3cd63ba6261735323","best_bid":"0.85","best_ask":"0.86"},{"asset_id":"56386988715176239099720172290594769295756680374928571099138069977179519358166","price":"0.25","size":"722.5","side":"SELL","hash":"8eac43757010fbabd38f2030ab4a4a29d36807e0","best_bid":"0.14","best_ask":"0.15"}],"timestamp":"1768250241669","event_type":"price_change"}}
{"schema_version":1,"source":"clob_ws_market","recv_ts_ns":1768250242124197789,"event_type":"price_change","market":"0x2a12fd3d8235c25c062dc9652970ef9f635636c4018df0909e1a51c673e125cb","server_ts_ms":1768250241672,"raw":{"market":"0x2a12fd3d8235c25c062dc9652970ef9f635636c4018df0909e1a51c673e125cb","price_changes":[{"asset_id":"56386988715176239099720172290594769295756680374928571099138069977179519358166","price":"0.12","size":"1410.75","side":"BUY","hash":"9b24f6652d2695dba63d04d5bb40c7895dfba778","best_bid":"0.14","best_ask":"0.15"},{"asset_id":"63670753354844494163057275310194312729998307779831462269530137743341854359908","price":"0.88","size":"1410.75","side":"SELL","hash":"7ebaa757e7bab2b0c6e60d0ebe107c6b33ead23d","best_bid":"0.85","best_ask":"0.86"}],"timestamp":"1768250241672","event_type":"price_change"}}
{"schema_version":1,"source":"clob_ws_market","recv_ts_ns":1768250242130435833,"event_type":"price_change","market":"0x2a12fd3d8235c25c062dc9652970ef9f635636c4018df0909e1a51c673e125cb","server_ts_ms":1768250241674,"raw":{"market":"0x2a12fd3d8235c25c062dc9652970ef9f635636c4018df0909e1a51c673e125cb","price_changes":[{"asset_id":"56386988715176239099720172290594769295756680374928571099138069977179519358166","price":"0.09","size":"1347","side":"BUY","hash":"04c0fe43b5c229f72d0cc8dc6da77f91ea8423b5","best_bid":"0.14","best_ask":"0.15"},{"asset_id":"63670753354844494163057275310194312729998307779831462269530137743341854359908","price":"0.91","size":"1347","side":"SELL","hash":"c55b30970ee0115dcab2da5ac6eeb9af33171dbb","best_bid":"0.85","best_ask":"0.86"}],"timestamp":"1768250241674","event_type":"price_change"}}
{"schema_version":1,"source":"clob_ws_market","recv_ts_ns":1768250242133967231,"event_type":"price_change","market":"0x2a12fd3d8235c25c062dc9652970ef9f635636c4018df0909e1a51c673e125cb","server_ts_ms":1768250241676,"raw":{"market":"0x2a12fd3d8235c25c062dc9652970ef9f635636c4018df0909e1a51c673e125cb","price_changes":[{"asset_id":"63670753354844494163057275310194312729998307779831462269530137743341854359908","price":"0.85","size":"139.99","side":"BUY","hash":"c5f1eb5319d4c8a37f478dfb43ec5199f5d0bc84","best_bid":"0.85","best_ask":"0.86"},{"asset_id":"56386988715176239099720172290594769295756680374928571099138069977179519358166","price":"0.15","size":"139.99","side":"SELL","hash":"c606cfa275077d98b73a37a05406ca5c217d70dc","best_bid":"0.14","best_ask":"0.15"}],"timestamp":"1768250241676","event_type":"price_change"}}
{"schema_version":1,"source":"clob_ws_market","recv_ts_ns":1768250242138004165,"event_type":"last_trade_price","market":"0x2a12fd3d8235c25c062dc9652970ef9f635636c4018df0909e1a51c673e125cb","server_ts_ms":1768250241679,"raw":{"market":"0x2a12fd3d8235c25c062dc9652970ef9f635636c4018df0909e1a51c673e125cb","asset_id":"56386988715176239099720172290594769295756680374928571099138069977179519358166","price":"0.14","size":"10","fee_rate_bps":"1000","side":"BUY","timestamp":"1768250241679","event_type":"last_trade_price","transaction_hash":"0xf6b775d03a527116a8e18746af988db6b7f085276c14eab015469d373cb46fbe"}}
{"schema_version":1,"source":"clob_ws_market","recv_ts_ns":1768250242140829742,"event_type":"price_change","market":"0x2a12fd3d8235c25c062dc9652970ef9f635636c4018df0909e1a51c673e125cb","server_ts_ms":1768250241681,"raw":{"market":"0x2a12fd3d8235c25c062dc9652970ef9f635636c4018df0909e1a51c673e125cb","price_changes":[{"asset_id":"63670753354844494163057275310194312729998307779831462269530137743341854359908","price":"0.85","size":"134.49","side":"BUY","hash":"fc6ce71c2d597a916faf05b6217f0117d2a3b322","best_bid":"0.85","best_ask":"0.86"},{"asset_id":"56386988715176239099720172290594769295756680374928571099138069977179519358166","price":"0.15","size":"134.49","side":"SELL","hash":"9f5cfdf481e98bad5b5dc890be91c33c6e77e814","best_bid":"0.14","best_ask":"0.15"}],"timestamp":"1768250241681","event_type":"price_change"}}
{"schema_version":1,"source":"clob_ws_market","recv_ts_ns":1768250242144997095,"event_type":"price_change","market":"0x2a12fd3d8235c25c062dc9652970ef9f635636c4018df0909e1a51c673e125cb","server_ts_ms":1768250241682,"raw":{"market":"0x2a12fd3d8235c25c062dc9652970ef9f635636c4018df0909e1a51c673e125cb","price_changes":[{"asset_id":"63670753354844494163057275310194312729998307779831462269530137743341854359908","price":"0.87","size":"356","side":"SELL","hash":"ef7be391644c72c8e75aa1b6f4e00145e75cbb67","best_bid":"0.85","best_ask":"0.86"},{"asset_id":"56386988715176239099720172290594769295756680374928571099138069977179519358166","price":"0.13","size":"356","side":"BUY","hash":"d4c80be8380c71d3b8eb4ce71b541bf72c5da0d0","best_bid":"0.14","best_ask":"0.15"}],"timestamp":"1768250241682","event_type":"price_change"}}
{"schema_version":1,"source":"clob_ws_market","recv_ts_ns":1768250242164411873,"event_type":"price_change","market":"0x2a12fd3d8235c25c062dc9652970ef9f635636c4018df0909e1a51c673e125cb","server_ts_ms":1768250241686,"raw":{"market":"0x2a12fd3d8235c25c062dc9652970ef9f635636c4018df0909e1a51c673e125cb","price_changes":[{"asset_id":"63670753354844494163057275310194312729998307779831462269530137743341854359908","price":"0.86","size":"166","side":"SELL","hash":"c74f840dbada418104e1282f149aa381149b71e7","best_bid":"0.85","best_ask":"0.86"},{"asset_id":"56386988715176239099720172290594769295756680374928571099138069977179519358166","price":"0.14","size":"166","side":"BUY","hash":"2a2ccb16ba418d11254f9396736131b9a2e8bd27","best_bid":"0.14","best_ask":"0.15"}],"timestamp":"1768250241686","event_type":"price_change"}}
{"schema_version":1,"source":"clob_ws_market","recv_ts_ns":1768250242170902350,"event_type":"best_bid_ask","market":"0x2a12fd3d8235c25c062dc9652970ef9f635636c4018df0909e1a51c673e125cb","server_ts_ms":1768250241714,"raw":{"market":"0x2a12fd3d8235c25c062dc9652970ef9f635636c4018df0909e1a51c673e125cb","asset_id":"56386988715176239099720172290594769295756680374928571099138069977179519358166","best_bid":"0.14","best_ask":"0.15","spread":"0.01","timestamp":"1768250241714","event_type":"best_bid_ask"}}
{"schema_version":1,"source":"clob_ws_market","recv_ts_ns":1768250242176431145,"event_type":"price_change","market":"0x2a12fd3d8235c25c062dc9652970ef9f635636c4018df0909e1a51c673e125cb","server_ts_ms":1768250241713,"raw":{"market":"0x2a12fd3d8235c25c062dc9652970ef9f635636c4018df0909e1a51c673e125cb","price_changes":[{"asset_id":"63670753354844494163057275310194312729998307779831462269530137743341854359908","price":"0.86","size":"164.72","side":"SELL","hash":"b50263682c3df0914dcaa3e020292160de36c6e3","best_bid":"0.85","best_ask":"0.86"},{"asset_id":"56386988715176239099720172290594769295756680374928571099138069977179519358166","price":"0.14","size":"164.72","side":"BUY","hash":"3c6244cbb38964933cd622e86d953e478051069a","best_bid":"0.14","best_ask":"0.15"}],"timestamp":"1768250241713","event_type":"price_change"}}
{"schema_version":1,"source":"clob_ws_market","recv_ts_ns":1768250242183356820,"event_type":"book","market":"0x2a12fd3d8235c25c062dc9652970ef9f635636c4018df0909e1a51c673e125cb","server_ts_ms":1768250241713,"raw":{"market":"0x2a12fd3d8235c25c062dc9652970ef9f635636c4018df0909e1a51c673e125cb","asset_id":"56386988715176239099720172290594769295756680374928571099138069977179519358166","bids":[{"price":"0.01","size":"10157.67"},{"price":"0.02","size":"6299.77"},{"price":"0.03","size":"5625.94"},{"price":"0.04","size":"5427"},{"price":"0.05","size":"3462"},{"price":"0.06","size":"1397"},{"price":"0.07","size":"1418.78"},{"price":"0.08","size":"1569.75"},{"price":"0.09","size":"1347"},{"price":"0.1","size":"3418"},{"price":"0.11","size":"854.5"},{"price":"0.12","size":"1410.75"},{"price":"0.13","size":"356"},{"price":"0.14","size":"164.72"}],"asks":[{"price":"0.99","size":"10184.18"},{"price":"0.98","size":"5982"},{"price":"0.97","size":"5238.94"},{"price":"0.96","size":"5040"},{"price":"0.95","size":"5050"},{"price":"0.94","size":"5005"},{"price":"0.93","size":"5019.28"},{"price":"0.92","size":"5005"},{"price":"0.91","size":"5005"},{"price":"0.9","size":"5030"},{"price":"0.89","size":"5"},{"price":"0.88","size":"5"},{"price":"0.87","size":"5"},{"price":"0.86","size":"5"},{"price":"0.85","size":"10"},{"price":"0.84","size":"5"},{"price":"0.83","size":"5"},{"price":"0.82","size":"5"},{"price":"0.81","size":"5"},{"price":"0.8","size":"5"},{"price":"0.79","size":"5"},{"price":"0.78","size":"5"},{"price":"0.77","size":"5"},{"price":"0.76","size":"5"},{"price":"0.75","size":"10"},{"price":"0.74","size":"5"},{"price":"0.73","size":"5"},{"price":"0.72","size":"5"},{"price":"0.71","size":"15"},{"price":"0.7","size":"10"},{"price":"0.69","size":"5"},{"price":"0.68","size":"5"},{"price":"0.67","size":"5"},{"price":"0.66","size":"505"},{"price":"0.65","size":"510"},{"price":"0.64","size":"510"},{"price":"0.63","size":"505"},{"price":"0.62","size":"505"},{"price":"0.61","size":"755"},{"price":"0.6","size":"760"},{"price":"0.59","size":"916"},{"price":"0.58","size":"671"},{"price":"0.57","size":"827"},{"price":"0.56","size":"827"},{"price":"0.55","size":"817"},{"price":"0.54","size":"872"},{"price":"0.53","size":"839.65"},{"price":"0.52","size":"829"},{"price":"0.51","size":"817"},{"price":"0.5","size":"838.4"},{"price":"0.49","size":"867.58"},{"price":"0.48","size":"817"},{"price":"0.47","size":"827"},{"price":"0.46","size":"847.8"},{"price":"0.45","size":"836.09"},{"price":"0.44","size":"825"},{"price":"0.43","size":"847"},{"price":"0.42","size":"817"},{"price":"0.41","size":"817"},{"price":"0.4","size":"817"},{"price":"0.39","size":"834.5"},{"price":"0.38","size":"817"},{"price":"0.37","size":"497.49"},{"price":"0.36","size":"817"},{"price":"0.35","size":"872"},{"price":"0.34","size":"906.8"},{"price":"0.33","size":"996.36"},{"price":"0.32","size":"902"},{"price":"0.31","size":"922"},{"price":"0.3","size":"911.6"},{"price":"0.29","size":"897"},{"price":"0.28","size":"899.55"},{"price":"0.27","size":"912"},{"price":"0.26","size":"1174.42"},{"price":"0.25","size":"722.5"},{"price":"0.24","size":"912.05"},{"price":"0.23","size":"748.5"},{"price":"0.22","size":"916.9"},{"price":"0.21","size":"975.5"},{"price":"0.2","size":"814.9"},{"price":"0.19","size":"888.21"},{"price":"0.18","size":"171"},{"price":"0.17","size":"179.52"},{"price":"0.16","size":"196"},{"price":"0.15","size":"134.49"}],"hash":"3c6244cbb38964933cd622e86d953e478051069a","timestamp":"1768250241713","event_type":"book"}}
{"schema_version":1,"source":"clob_ws_market","recv_ts_ns":1768250242190365341,"event_type":"price_change","market":"0x2a12fd3d8235c25c062dc9652970ef9f635636c4018df0909e1a51c673e125cb","server_ts_ms":1768250241714,"raw":{"market":"0x2a12fd3d8235c25c062dc9652970ef9f635636c4018df0909e1a51c673e125cb","price_changes":[{"asset_id":"56386988715176239099720172290594769295756680374928571099138069977179519358166","price":"0.15","size":"128.99","side":"SELL","hash":"85421240fedbe822524565b34a3c20489e446cd3","best_bid":"0.14","best_ask":"0.15"},{"asset_id":"63670753354844494163057275310194312729998307779831462269530137743341854359908","price":"0.85","size":"128.99","side":"BUY","hash":"8860b30ea2fe3bd7fc4c9ded70471b7614e7060f","best_bid":"0.85","best_ask":"0.86"}],"timestamp":"1768250241714","event_type":"price_change"}}
{"schema_version":1,"source":"clob_ws_market","recv_ts_ns":1768250242193808219,"event_type":"price_change","market":"0x2a12fd3d8235c25c062dc9652970ef9f635636c4018df0909e1a51c673e125cb","server_ts_ms":1768250241715,"raw":{"market":"0x2a12fd3d8235c25c062dc9652970ef9f635636c4018df0909e1a51c673e125cb","price_changes":[{"asset_id":"63670753354844494163057275310194312729998307779831462269530137743341854359908","price":"0.84","size":"201.5","side":"BUY","hash":"8bcbb194b4f3aa9138d32c5a2d555ec788079e40","best_bid":"0.85","best_ask":"0.86"},{"asset_id":"56386988715176239099720172290594769295756680374928571099138069977179519358166","price":"0.16","size":"201.5","side":"SELL","hash":"a3b8c08bab39c77d7096c21b2e8a0b4fed0c15ce","best_bid":"0.14","best_ask":"0.15"}],"timestamp":"1768250241715","event_type":"price_change"}}
{"schema_version":1,"source":"clob_ws_market","recv_ts_ns":1768250242197539757,"event_type":"price_change","market":"0x2a12fd3d8235c25c062dc9652970ef9f635636c4018df0909e1a51c673e125cb","server_ts_ms":1768250241716,"raw":{"market":"0x2a12fd3d8235c25c062dc9652970ef9f635636c4018df0909e1a51c673e125cb","price_changes":[{"asset_id":"63670753354844494163057275310194312729998307779831462269530137743341854359908","price":"0.87","size":"341","side":"SELL","hash":"23f6285dc089b341196a5fe5dcfc6acd35a17a90","best_bid":"0.85","best_ask":"0.86"},{"asset_id":"56386988715176239099720172290594769295756680374928571099138069977179519358166","price":"0.13","size":"341","side":"BUY","hash":"fab9724cab5068833c0d563b236736df751eaaeb","best_bid":"0.14","best_ask":"0.15"}],"timestamp":"1768250241716","event_type":"price_change"}}
{"schema_version":1,"source":"clob_ws_market","recv_ts_ns":1768250242199679768,"event_type":"price_change","market":"0x2a12fd3d8235c25c062dc9652970ef9f635636c4018df0909e1a51c673e125cb","server_ts_ms":1768250241717,"raw":{"market":"0x2a12fd3d8235c25c062dc9652970ef9f635636c4018df0909e1a51c673e125cb","price_changes":[{"asset_id":"63670753354844494163057275310194312729998307779831462269530137743341854359908","price":"0.84","size":"207","side":"BUY","hash":"5ce8bfd1f06d076e90d20974024e5b3b3ba7f61b","best_bid":"0.85","best_ask":"0.86"},{"asset_id":"56386988715176239099720172290594769295756680374928571099138069977179519358166","price":"0.16","size":"207","side":"SELL","hash":"2f30e6e628fe4c7cdd4a47865a045af7cfdc21fc","best_bid":"0.14","best_ask":"0.15"}],"timestamp":"1768250241717","event_type":"price_change"}}
{"schema_version":1,"source":"clob_ws_market","recv_ts_ns":1768250242201502292,"event_type":"price_change","market":"0x2a12fd3d8235c25c062dc9652970ef9f635636c4018df0909e1a51c673e125cb","server_ts_ms":1768250241724,"raw":{"market":"0x2a12fd3d8235c25c062dc9652970ef9f635636c4018df0909e1a51c673e125cb","price_changes":[{"asset_id":"56386988715176239099720172290594769295756680374928571099138069977179519358166","price":"0.09","size":"1337","side":"BUY","hash":"39818c2afefe6029e30e138225b2d719719b29ca","best_bid":"0.14","best_ask":"0.15"},{"asset_id":"63670753354844494163057275310194312729998307779831462269530137743341854359908","price":"0.91","size":"1337","side":"SELL","hash":"797baea526834f8b93e49e91c7f1eea1d0802053","best_bid":"0.85","best_ask":"0.86"}],"timestamp":"1768250241724","event_type":"price_change"}}
{"schema_version":1,"source":"clob_ws_market","recv_ts_ns":1768250242204270080,"event_type":"price_change","market":"0x2a12fd3d8235c25c062dc9652970ef9f635636c4018df0909e1a51c673e125cb","server_ts_ms":1768250241742,"raw":{"market":"0x2a12fd3d8235c25c062dc9652970ef9f635636c4018df0909e1a51c673e125cb","price_changes":[{"asset_id":"56386988715176239099720172290594769295756680374928571099138069977179519358166","price":"0.13","size":"331","side":"BUY","hash":"37a0f204393630c91f7d7c62a426a44893848dce","best_bid":"0.14","best_ask":"0.15"},{"asset_id":"63670753354844494163057275310194312729998307779831462269530137743341854359908","price":"0.87","size":"331","side":"SELL","hash":"519f29e7c6874576d44efa5ec2a7bff4879dfcda","best_bid":"0.85","best_ask":"0.86"}],"timestamp":"1768250241742","event_type":"price_change"}}
{"schema_version":1,"source":"clob_ws_market","recv_ts_ns":1768250242206309481,"event_type":"price_change","market":"0x2a12fd3d8235c25c062dc9652970ef9f635636c4018df0909e1a51c673e125cb","server_ts_ms":1768250241746,"raw":{"market":"0x2a12fd3d8235c25c062dc9652970ef9f635636c4018df0909e1a51c673e125cb","price_changes":[{"asset_id":"63670753354844494163057275310194312729998307779831462269530137743341854359908","price":"0.85","size":"153.99","side":"BUY","hash":"e30d6ec957c994ab53f7fcd28cf9f94d0a8ec751","best_bid":"0.85","best_ask":"0.86"},{"asset_id":"56386988715176239099720172290594769295756680374928571099138069977179519358166","price":"0.15","size":"153.99","side":"SELL","hash":"b38d658b2a2c5711d1496d8466cf623aad113ed7","best_bid":"0.14","best_ask":"0.15"}],"timestamp":"1768250241746","event_type":"price_change"}}
{"schema_version":1,"source":"clob_ws_market","recv_ts_ns":1768250242208553655,"event_type":"price_change","market":"0x2a12fd3d8235c25c062dc9652970ef9f635636c4018df0909e1a51c673e125cb","server_ts_ms":1768250241751,"raw":{"market":"0x2a12fd3d8235c25c062dc9652970ef9f635636c4018df0909e1a51c673e125cb","price_changes":[{"asset_id":"56386988715176239099720172290594769295756680374928571099138069977179519358166","price":"0.16","size":"212.5","side":"SELL","hash":"f71097910b22877a2bfc67e3bbbf2fde43029388","best_bid":"0.14","best_ask":"0.15"},{"asset_id":"63670753354844494163057275310194312729998307779831462269530137743341854359908","price":"0.84","size":"212.5","side":"BUY","hash":"e37a32d2cbf22d1cbea58772e8244ef2f25d7822","best_bid":"0.85","best_ask":"0.86"}],"timestamp":"1768250241751","event_type":"price_change"}}
{"schema_version":1,"source":"clob_ws_market","recv_ts_ns":1768250242210590986,"event_type":"price_change","market":"0x2a12fd3d8235c25c062dc9652970ef9f635636c4018df0909e1a51c673e125cb","server_ts_ms":1768250241756,"raw":{"market":"0x2a12fd3d8235c25c062dc9652970ef9f635636c4018df0909e1a51c673e125cb","price_changes":[{"asset_id":"56386988715176239099720172290594769295756680374928571099138069977179519358166","price":"0.14","size":"174.72","side":"BUY","hash":"a61bea418c4288766e8fc4b7e041eb49af468590","best_bid":"0.14","best_ask":"0.15"},{"asset_id":"63670753354844494163057275310194312729998307779831462269530137743341854359908","price":"0.86","size":"174.72","side":"SELL","hash":"5021573ff2b87c16a752fede963818158628c8b1","best_bid":"0.85","best_ask":"0.86"}],"timestamp":"1768250241756","event_type":"price_change"}}
{"schema_version":1,"source":"clob_ws_market","recv_ts_ns":1768250242212934877,"event_type":"price_change","market":"0x2a12fd3d8235c25c062dc9652970ef9f635636c4018df0909e1a51c673e125cb","server_ts_ms":1768250241810,"raw":{"market":"0x2a12fd3d8235c25c062dc9652970ef9f635636c4018df0909e1a51c673e125cb","price_changes":[{"asset_id":"56386988715176239099720172290594769295756680374928571099138069977179519358166","price":"0.1","size":"3428","side":"BUY","hash":"f9692bc00f913c12e6a9559a1e77ac46ea8b99a3","best_bid":"0.14","best_ask":"0.15"},{"asset_id":"63670753354844494163057275310194312729998307779831462269530137743341854359908","price":"0.9","size":"3428","side":"SELL","hash":"8397cca7ff3170b4b7572302c23bf7bb768d1956","best_bid":"0.85","best_ask":"0.86"}],"timestamp":"1768250241810","event_type":"price_change"}}
{"schema_version":1,"source":"clob_ws_market","recv_ts_ns":1768250242236678892,"event_type":"price_change","market":"0x2a12fd3d8235c25c062dc9652970ef9f635636c4018df0909e1a51c673e125cb","server_ts_ms":1768250241889,"raw":{"market":"0x2a12fd3d8235c25c062dc9652970ef9f635636c4018df0909e1a51c673e125cb","price_changes":[{"asset_id":"63670753354844494163057275310194312729998307779831462269530137743341854359908","price":"0.99","size":"10331.71","side":"SELL","hash":"d9e87cf223841d4bc9b32b93c1a4d58fa3d3cb3a","best_bid":"0.85","best_ask":"0.86"},{"asset_id":"56386988715176239099720172290594769295756680374928571099138069977179519358166","price":"0.01","size":"10331.71","side":"BUY","hash":"7f99542b5a6f117e362a793fc7adc1b37187d54e","best_bid":"0.14","best_ask":"0.15"}],"timestamp":"1768250241889","event_type":"price_change"}}
{"schema_version":1,"source":"clob_ws_market","recv_ts_ns":1768250242253781815,"event_type":"price_change","market":"0x2a12fd3d8235c25c062dc9652970ef9f635636c4018df0909e1a51c673e125cb","server_ts_ms":1768250241927,"raw":{"market":"0x2a12fd3d8235c25c062dc9652970ef9f635636c4018df0909e1a51c673e125cb","price_changes":[{"asset_id":"63670753354844494163057275310194312729998307779831462269530137743341854359908","price":"0.79","size":"814.5","side":"BUY","hash":"473919db5ce11102fee5ed14d56fd0c52f501776","best_bid":"0.85","best_ask":"0.86"},{"asset_id":"56386988715176239099720172290594769295756680374928571099138069977179519358166","price":"0.21","size":"814.5","side":"SELL","hash":"5194062df0dffb30dfaf7aab71cf2b89ef4a0108","best_bid":"0.14","best_ask":"0.15"}],"timestamp":"1768250241927","event_type":"price_change"}}
{"schema_version":1,"source":"clob_ws_market","recv_ts_ns":1768250242267129573,"event_type":"price_change","market":"0x2a12fd3d8235c25c062dc9652970ef9f635636c4018df0909e1a51c673e125cb","server_ts_ms":1768250241981,"raw":{"market":"0x2a12fd3d8235c25c062dc9652970ef9f635636c4018df0909e1a51c673e125cb","price_changes":[{"asset_id":"63670753354844494163057275310194312729998307779831462269530137743341854359908","price":"0.82","size":"671","side":"BUY","hash":"0519942cd577ace9306c9d3543e9be5332358243","best_bid":"0.85","best_ask":"0.86"},{"asset_id":"56386988715176239099720172290594769295756680374928571099138069977179519358166","price":"0.18","size":"671","side":"SELL","hash":"190ac1994a2b30c2969cb14b2a868ab029180d4d","best_bid":"0.14","best_ask":"0.15"}],"timestamp":"1768250241981","event_type":"price_change"}}
{"schema_version":1,"source":"clob_ws_market","recv_ts_ns":1768250242300809876,"event_type":"price_change","market":"0x2a12fd3d8235c25c062dc9652970ef9f635636c4018df0909e1a51c673e125cb","server_ts_ms":1768250242159,"raw":{"market":"0x2a12fd3d8235c25c062dc9652970ef9f635636c4018df0909e1a51c673e125cb","price_changes":[{"asset_id":"56386988715176239099720172290594769295756680374928571099138069977179519358166","price":"0.12","size":"1445.75","side":"BUY","hash":"6b5ff90edd267e4932a01e4926b4bfca893ce20d","best_bid":"0.14","best_ask":"0.15"},{"asset_id":"63670753354844494163057275310194312729998307779831462269530137743341854359908","price":"0.88","size":"1445.75","side":"SELL","hash":"b214305bcaad6b48d03a3107310ac3a13bbfe49c","best_bid":"0.85","best_ask":"0.86"}],"timestamp":"1768250242159","event_type":"price_change"}}
{"schema_version":1,"source":"clob_ws_market","recv_ts_ns":1768250242303877422,"event_type":"price_change","market":"0x2a12fd3d8235c25c062dc9652970ef9f635636c4018df0909e1a51c673e125cb","server_ts_ms":1768250242179,"raw":{"market":"0x2a12fd3d8235c25c062dc9652970ef9f635636c4018df0909e1a51c673e125cb","price_changes":[{"asset_id":"56386988715176239099720172290594769295756680374928571099138069977179519358166","price":"0.1","size":"3463","side":"BUY","hash":"2d7bf8be3c2e50ac5fb53f73e2c9d963e257daa2","best_bid":"0.14","best_ask":"0.15"},{"asset_id":"63670753354844494163057275310194312729998307779831462269530137743341854359908","price":"0.9","size":"3463","side":"SELL","hash":"2de4f6d20cb7c7fad38048f668c84d879088a47b","best_bid":"0.85","best_ask":"0.86"}],"timestamp":"1768250242179","event_type":"price_change"}}
{"schema_version":1,"source":"clob_ws_market","recv_ts_ns":1768250242306701810,"event_type":"price_change","market":"0x2a12fd3d8235c25c062dc9652970ef9f635636c4018df0909e1a51c673e125cb","server_ts_ms":1768250242183,"raw":{"market":"0x2a12fd3d8235c25c062dc9652970ef9f635636c4018df0909e1a51c673e125cb","price_changes":[{"asset_id":"56386988715176239099720172290594769295756680374928571099138069977179519358166","price":"0.11","size":"889.5","side":"BUY","hash":"de6dec5d6c68c03b9df1ed50e1930078e654f091","best_bid":"0.14","best_ask":"0.15"},{"asset_id":"63670753354844494163057275310194312729998307779831462269530137743341854359908","price":"0.89","size":"889.5","side":"SELL","hash":"6246b65da898a5e3c0c6deada5317d2529f7e0cc","best_bid":"0.85","best_ask":"0.86"}],"timestamp":"1768250242183","event_type":"price_change"}}
{"schema_version":1,"source":"clob_ws_market","recv_ts_ns":1768250242309173328,"event_type":"price_change","market":"0x2a12fd3d8235c25c062dc9652970ef9f635636c4018df0909e1a51c673e125cb","server_ts_ms":1768250242189,"raw":{"market":"0x2a12fd3d8235c25c062dc9652970ef9f635636c4018df0909e1a51c673e125cb","price_changes":[{"asset_id":"56386988715176239099720172290594769295756680374928571099138069977179519358166","price":"0.14","size":"209.72","side":"BUY","hash":"c70b597405deb4a087074e86814f5ccd57edf34e","best_bid":"0.14","best_ask":"0.15"},{"asset_id":"63670753354844494163057275310194312729998307779831462269530137743341854359908","price":"0.86","size":"209.72","side":"SELL","hash":"b7f96b0b3ea233fba7b648f0a06912f7145f24ad","best_bid":"0.85","best_ask":"0.86"}],"timestamp":"1768250242189","event_type":"price_change"}}
{"schema_version":1,"source":"clob_ws_market","recv_ts_ns":1768250242324683129,"event_type":"price_change","market":"0x2a12fd3d8235c25c062dc9652970ef9f635636c4018df0909e1a51c673e125cb","server_ts_ms":1768250242217,"raw":{"market":"0x2a12fd3d8235c25c062dc9652970ef9f635636c4018df0909e1a51c673e125cb","price_changes":[{"asset_id":"63670753354844494163057275310194312729998307779831462269530137743341854359908","price":"0.87","size":"341","side":"SELL","hash":"42a022f83e61f0293012190392781b3f7390dfbf","best_bid":"0.85","best_ask":"0.86"},{"asset_id":"56386988715176239099720172290594769295756680374928571099138069977179519358166","price":"0.13","size":"341","side":"BUY","hash":"2411c71cb625ea1d7641a2fd6d344892cda3ff00","best_bid":"0.14","best_ask":"0.15"}],"timestamp":"1768250242217","event_type":"price_change"}}
{"schema_version":1,"source":"clob_ws_market","recv_ts_ns":1768250242358670094,"event_type":"price_change","market":"0x2a12fd3d8235c25c062dc9652970ef9f635636c4018df0909e1a51c673e125cb","server_ts_ms":1768250242338,"raw":{"market":"0x2a12fd3d8235c25c062dc9652970ef9f635636c4018df0909e1a51c673e125cb","price_changes":[{"asset_id":"56386988715176239099720172290594769295756680374928571099138069977179519358166","price":"0.05","size":"3442","side":"BUY","hash":"4c77919d4c3bb289e5af5b2b3150bf109468db40","best_bid":"0.14","best_ask":"0.15"},{"asset_id":"63670753354844494163057275310194312729998307779831462269530137743341854359908","price":"0.95","size":"3442","side":"SELL","hash":"14b25d94f29713536f646247f6da519caa0702fc","best_bid":"0.85","best_ask":"0.86"}],"timestamp":"1768250242338","event_type":"price_change"}}
{"schema_version":1,"source":"clob_ws_market","recv_ts_ns":1768250242371011078,"event_type":"price_change","market":"0x2a12fd3d8235c25c062dc9652970ef9f635636c4018df0909e1a51c673e125cb","server_ts_ms":1768250242348,"raw":{"market":"0x2a12fd3d8235c25c062dc9652970ef9f635636c4018df0909e1a51c673e125cb","price_changes":[{"asset_id":"56386988715176239099720172290594769295756680374928571099138069977179519358166","price":"0.12","size":"1440.75","side":"BUY","hash":"62963dbd67215068a92525cbe79736cebe5d2b1f","best_bid":"0.14","best_ask":"0.15"},{"asset_id":"63670753354844494163057275310194312729998307779831462269530137743341854359908","price":"0.88","size":"1440.75","side":"SELL","hash":"cbf018d9098b6d9246bffbb3a6b051082c85d7b1","best_bid":"0.85","best_ask":"0.86"}],"timestamp":"1768250242348","event_type":"price_change"}}
{"schema_version":1,"source":"clob_ws_market","recv_ts_ns":1768250242396106345,"event_type":"price_change","market":"0x2a12fd3d8235c25c062dc9652970ef9f635636c4018df0909e1a51c673e125cb","server_ts_ms":1768250242373,"raw":{"market":"0x2a12fd3d8235c25c062dc9652970ef9f635636c4018df0909e1a51c673e125cb","price_changes":[{"asset_id":"56386988715176239099720172290594769295756680374928571099138069977179519358166","price":"0.06","size":"1414","side":"BUY","hash":"e4196fe2edc5e4ff681857b3c2190c9ac2f380a1","best_bid":"0.14","best_ask":"0.15"},{"asset_id":"63670753354844494163057275310194312729998307779831462269530137743341854359908","price":"0.94","size":"1414","side":"SELL","hash":"c5911ec082e3853517dbb8a18888e177a05ed7cf","best_bid":"0.85","best_ask":"0.86"}],"timestamp":"1768250242373","event_type":"price_change"}}
{"schema_version":1,"source":"clob_ws_market","recv_ts_ns":1768250242426535694,"event_type":"price_change","market":"0x2a12fd3d8235c25c062dc9652970ef9f635636c4018df0909e1a51c673e125cb","server_ts_ms":1768250242406,"raw":{"market":"0x2a12fd3d8235c25c062dc9652970ef9f635636c4018df0909e1a51c673e125cb","price_changes":[{"asset_id":"56386988715176239099720172290594769295756680374928571099138069977179519358166","price":"0.12","size":"1430.75","side":"BUY","hash":"584907979b491e0f1485b4c418d1959dd95fa26a","best_bid":"0.14","best_ask":"0.15"},{"asset_id":"63670753354844494163057275310194312729998307779831462269530137743341854359908","price":"0.88","size":"1430.75","side":"SELL","hash":"03025dfd1c8f6936d4129d36b3e01ada6f3fc6e4","best_bid":"0.85","best_ask":"0.86"}],"timestamp":"1768250242406","event_type":"price_change"}}
{"schema_version":1,"source":"clob_ws_market","recv_ts_ns":1768250242431414345,"event_type":"price_change","market":"0x2a12fd3d8235c25c062dc9652970ef9f635636c4018df0909e1a51c673e125cb","server_ts_ms":1768250242407,"raw":{"market":"0x2a12fd3d8235c25c062dc9652970ef9f635636c4018df0909e1a51c673e125cb","price_changes":[{"asset_id":"56386988715176239099720172290594769295756680374928571099138069977179519358166","price":"0.11","size":"879.5","side":"BUY","hash":"5f9dd78b30d2df641b9d04d95a40c0b51a3a1f45","best_bid":"0.14","best_ask":"0.15"},{"asset_id":"63670753354844494163057275310194312729998307779831462269530137743341854359908","price":"0.89","size":"879.5","side":"SELL","hash":"8342eea7d49dde60ac6e42cd49059411fa18a7e9","best_bid":"0.85","best_ask":"0.86"}],"timestamp":"1768250242407","event_type":"price_change"}}
{"schema_version":1,"source":"clob_ws_market","recv_ts_ns":1768250242435597794,"event_type":"price_change","market":"0x2a12fd3d8235c25c062dc9652970ef9f635636c4018df0909e1a51c673e125cb","server_ts_ms":1768250242408,"raw":{"market":"0x2a12fd3d8235c25c062dc9652970ef9f635636c4018df0909e1a51c673e125cb","price_changes":[{"asset_id":"56386988715176239099720172290594769295756680374928571099138069977179519358166","price":"0.09","size":"1327","side":"BUY","hash":"a9a347aed85d90a8535d53a72f8a8552176ed6d6","best_bid":"0.14","best_ask":"0.15"},{"asset_id":"63670753354844494163057275310194312729998307779831462269530137743341854359908","price":"0.91","size":"1327","side":"SELL","hash":"7ea4d5becbfde7f29e7f27f3fe3d123c8bc24e70","best_bid":"0.85","best_ask":"0.86"}],"timestamp":"1768250242408","event_type":"price_change"}}
{"schema_version":1,"source":"clob_ws_market","recv_ts_ns":1768250242438922130,"event_type":"price_change","market":"0x2a12fd3d8235c25c062dc9652970ef9f635636c4018df0909e1a51c673e125cb","server_ts_ms":1768250242408,"raw":{"market":"0x2a12fd3d8235c25c062dc9652970ef9f635636c4018df0909e1a51c673e125cb","price_changes":[{"asset_id":"63670753354844494163057275310194312729998307779831462269530137743341854359908","price":"0.85","size":"143.99","side":"BUY","hash":"999e68b3efef966b772e05425accdaf96982f87f","best_bid":"0.85","best_ask":"0.86"},{"asset_id":"56386988715176239099720172290594769295756680374928571099138069977179519358166","price":"0.15","size":"143.99","side":"SELL","hash":"345ebfa43bf4f7d2c3db3afc5f5c9c74cc42547b","best_bid":"0.14","best_ask":"0.15"}],"timestamp":"1768250242408","event_type":"price_change"}}
{"schema_version":1,"source":"clob_ws_market","recv_ts_ns":1768250242442613905,"event_type":"price_change","market":"0x2a12fd3d8235c25c062dc9652970ef9f635636c4018df0909e1a51c673e125cb","server_ts_ms":1768250242410,"raw":{"market":"0x2a12fd3d8235c25c062dc9652970ef9f635636c4018df0909e1a51c673e125cb","price_changes":[{"asset_id":"63670753354844494163057275310194312729998307779831462269530137743341854359908","price":"0.85","size":"133.99","side":"BUY","hash":"189c837a747456ebb72826e946aa6646e66097d4","best_bid":"0.85","best_ask":"0.86"},{"asset_id":"56386988715176239099720172290594769295756680374928571099138069977179519358166","price":"0.15","size":"133.99","side":"SELL","hash":"3adf2482d296959b5f544bdbfb5af5e01704fed0","best_bid":"0.14","best_ask":"0.15"}],"timestamp":"1768250242410","event_type":"price_change"}}
{"schema_version":1,"source":"clob_ws_market","recv_ts_ns":1768250242447463752,"event_type":"price_change","market":"0x2a12fd3d8235c25c062dc9652970ef9f635636c4018df0909e1a51c673e125cb","server_ts_ms":1768250242411,"raw":{"market":"0x2a12fd3d8235c25c062dc9652970ef9f635636c4018df0909e1a51c673e125cb","price_changes":[{"asset_id":"56386988715176239099720172290594769295756680374928571099138069977179519358166","price":"0.1","size":"3453","side":"BUY","hash":"10660b895c7d85ce40ca62428cc5067f4a70d099","best_bid":"0.14","best_ask":"0.15"},{"asset_id":"63670753354844494163057275310194312729998307779831462269530137743341854359908","price":"0.9","size":"3453","side":"SELL","hash":"45d90e2ce8303b11cb2c714b6fdf05d96f35f8cb","best_bid":"0.85","best_ask":"0.86"}],"timestamp":"1768250242411","event_type":"price_change"}}
{"schema_version":1,"source":"clob_ws_market","recv_ts_ns":1768250242452192754,"event_type":"price_change","market":"0x2a12fd3d8235c25c062dc9652970ef9f635636c4018df0909e1a51c673e125cb","server_ts_ms":1768250242411,"raw":{"market":"0x2a12fd3d8235c25c062dc9652970ef9f635636c4018df0909e1a51c673e125cb","price_changes":[{"asset_id":"63670753354844494163057275310194312729998307779831462269530137743341854359908","price":"0.85","size":"123.99","side":"BUY","hash":"9564e4884c94f39032f205ea22eedd4a54c131e4","best_bid":"0.85","best_ask":"0.86"},{"asset_id":"56386988715176239099720172290594769295756680374928571099138069977179519358166","price":"0.15","size":"123.99","side":"SELL","hash":"92fe8b44c625b21c60d8b828b2a9acdba0aff717","best_bid":"0.14","best_ask":"0.15"}],"timestamp":"1768250242411","event_type":"price_change"}}
{"schema_version":1,"source":"clob_ws_market","recv_ts_ns":1768250242458149618,"event_type":"price_change","market":"0x2a12fd3d8235c25c062dc9652970ef9f635636c4018df0909e1a51c673e125cb","server_ts_ms":1768250242412,"raw":{"market":"0x2a12fd3d8235c25c062dc9652970ef9f635636c4018df0909e1a51c673e125cb","price_changes":[{"asset_id":"56386988715176239099720172290594769295756680374928571099138069977179519358166","price":"0.09","size":"1317","side":"BUY","hash":"8519b2da03ccd3157443b703d42791537ba49808","best_bid":"0.14","best_ask":"0.15"},{"asset_id":"63670753354844494163057275310194312729998307779831462269530137743341854359908","price":"0.91","size":"1317","side":"SELL","hash":"dd1fd00938683674e4e880ede960c3c232ee8361","best_bid":"0.85","best_ask":"0.86"}],"timestamp":"1768250242412","event_type":"price_change"}}
{"schema_version":1,"source":"clob_ws_market","recv_ts_ns":1768250242462812621,"event_type":"price_change","market":"0x2a12fd3d8235c25c062dc9652970ef9f635636c4018df0909e1a51c673e125cb","server_ts_ms":1768250242413,"raw":{"market":"0x2a12fd3d8235c25c062dc9652970ef9f635636c4018df0909e1a51c673e125cb","price_changes":[{"asset_id":"63670753354844494163057275310194312729998307779831462269530137743341854359908","price":"0.85","size":"113.99","side":"BUY","hash":"412302a23416ecb25aa15a5a0f1c459cefcb1451","best_bid":"0.85","best_ask":"0.86"},{"asset_id":"56386988715176239099720172290594769295756680374928571099138069977179519358166","price":"0.15","size":"113.99","side":"SELL","hash":"eac10ac1c2d9c98ade95f7f1c416760f2b52ba53","best_bid":"0.14","best_ask":"0.15"}],"timestamp":"1768250242413","event_type":"price_change"}}
{"schema_version":1,"source":"clob_ws_market","recv_ts_ns":1768250242467348495,"event_type":"price_change","market":"0x2a12fd3d8235c25c062dc9652970ef9f635636c4018df0909e1a51c673e125cb","server_ts_ms":1768250242414,"raw":{"market":"0x2a12fd3d8235c25c062dc9652970ef9f635636c4018df0909e1a51c673e125cb","price_changes":[{"asset_id":"56386988715176239099720172290594769295756680374928571099138069977179519358166","price":"0.11","size":"869.5","side":"BUY","hash":"b567b79f1fe096b859545b247fdc1c004bfdc70e","best_bid":"0.14","best_ask":"0.15"},{"asset_id":"63670753354844494163057275310194312729998307779831462269530137743341854359908","price":"0.89","size":"869.5","side":"SELL","hash":"09d7a1664c839e106ddbd351bf8b843a2009abd2","best_bid":"0.85","best_ask":"0.86"}],"timestamp":"1768250242414","event_type":"price_change"}}
{"schema_version":1,"source":"clob_ws_market","recv_ts_ns":1768250242473069275,"event_type":"price_change","market":"0x2a12fd3d8235c25c062dc9652970ef9f635636c4018df0909e1a51c673e125cb","server_ts_ms":1768250242414,"raw":{"market":"0x2a12fd3d8235c25c062dc9652970ef9f635636c4018df0909e1a51c673e125cb","price_changes":[{"asset_id":"56386988715176239099720172290594769295756680374928571099138069977179519358166","price":"0.08","size":"1559.75","side":"BUY","hash":"7b94de08f277215b65865f68122b7faef316bf4f","best_bid":"0.14","best_ask":"0.15"},{"asset_id":"63670753354844494163057275310194312729998307779831462269530137743341854359908","price":"0.92","size":"1559.75","side":"SELL","hash":"eeb07bc0c7ae963cf3921b029357d165fdaa9c5f","best_bid":"0.85","best_ask":"0.86"}],"timestamp":"1768250242414","event_type":"price_change"}}
{"schema_version":1,"source":"clob_ws_market","recv_ts_ns":1768250242479685214,"event_type":"price_change","market":"0x2a12fd3d8235c25c062dc9652970ef9f635636c4018df0909e1a51c673e125cb","server_ts_ms":1768250242415,"raw":{"market":"0x2a12fd3d8235c25c062dc9652970ef9f635636c4018df0909e1a51c673e125cb","price_changes":[{"asset_id":"63670753354844494163057275310194312729998307779831462269530137743341854359908","price":"0.85","size":"103.99","side":"BUY","hash":"27ebc626f8473cb9213ecee3d152cd9f2ed5fb2d","best_bid":"0.85","best_ask":"0.86"},{"asset_id":"56386988715176239099720172290594769295756680374928571099138069977179519358166","price":"0.15","size":"103.99","side":"SELL","hash":"dad8e9bef952ffbad2b325ff85ec5cff191459e8","best_bid":"0.14","best_ask":"0.15"}],"timestamp":"1768250242415","event_type":"price_change"}}
{"schema_version":1,"source":"clob_ws_market","recv_ts_ns":1768250242484134876,"event_type":"price_change","market":"0x2a12fd3d8235c25c062dc9652970ef9f635636c4018df0909e1a51c673e125cb","server_ts_ms":1768250242416,"raw":{"market":"0x2a12fd3d8235c25c062dc9652970ef9f635636c4018df0909e1a51c673e125cb","price_changes":[{"asset_id":"63670753354844494163057275310194312729998307779831462269530137743341854359908","price":"0.85","size":"93.99","side":"BUY","hash":"b2888ce1d40b3c1426d6c63ab44d6bbc95d7ffbd","best_bid":"0.85","best_ask":"0.86"},{"asset_id":"56386988715176239099720172290594769295756680374928571099138069977179519358166","price":"0.15","size":"93.99","side":"SELL","hash":"673185b22c10db8b72a71b5213d15efd5409829a","best_bid":"0.14","best_ask":"0.15"}],"timestamp":"1768250242416","event_type":"price_change"}}
{"schema_version":1,"source":"clob_ws_market","recv_ts_ns":1768250242487251201,"event_type":"price_change","market":"0x2a12fd3d8235c25c062dc9652970ef9f635636c4018df0909e1a51c673e125cb","server_ts_ms":1768250242416,"raw":{"market":"0x2a12fd3d8235c25c062dc9652970ef9f635636c4018df0909e1a51c673e125cb","price_changes":[{"asset_id":"63670753354844494163057275310194312729998307779831462269530137743341854359908","price":"0.85","size":"83.99","side":"BUY","hash":"bf9cc4523812ca4fa5573620ac621627e139b044","best_bid":"0.85","best_ask":"0.86"},{"asset_id":"56386988715176239099720172290594769295756680374928571099138069977179519358166","price":"0.15","size":"83.99","side":"SELL","hash":"b417096e37b8c9c8251fcac6f365d235f9d1a380","best_bid":"0.14","best_ask":"0.15"}],"timestamp":"1768250242416","event_type":"price_change"}}
{"schema_version":1,"source":"clob_ws_market","recv_ts_ns":1768250242491635249,"event_type":"price_change","market":"0x2a12fd3d8235c25c062dc9652970ef9f635636c4018df0909e1a51c673e125cb","server_ts_ms":1768250242418,"raw":{"market":"0x2a12fd3d8235c25c062dc9652970ef9f635636c4018df0909e1a51c673e125cb","price_changes":[{"asset_id":"56386988715176239099720172290594769295756680374928571099138069977179519358166","price":"0.1","size":"3443","side":"BUY","hash":"98af122ea7eb213f1ab26e52947762085fcb8ecc","best_bid":"0.14","best_ask":"0.15"},{"asset_id":"63670753354844494163057275310194312729998307779831462269530137743341854359908","price":"0.9","size":"3443","side":"SELL","hash":"76ad8d026f81d53bd55b73123d1cf8e647957fc1","best_bid":"0.85","best_ask":"0.86"}],"timestamp":"1768250242418","event_type":"price_change"}}
{"schema_version":1,"source":"clob_ws_market","recv_ts_ns":1768250242498879761,"event_type":"price_change","market":"0x2a12fd3d8235c25c062dc9652970ef9f635636c4018df0909e1a51c673e125cb","server_ts_ms":1768250242419,"raw":{"market":"0x2a12fd3d8235c25c062dc9652970ef9f635636c4018df0909e1a51c673e125cb","price_changes":[{"asset_id":"63670753354844494163057275310194312729998307779831462269530137743341854359908","price":"0.85","size":"73.99","side":"BUY","hash":"e274adb65d8142d15c0e4ff96fe3cb27a448b74c","best_bid":"0.85","best_ask":"0.86"},{"asset_id":"56386988715176239099720172290594769295756680374928571099138069977179519358166","price":"0.15","size":"73.99","side":"SELL","hash":"b9f1516e6de50120a7c485ba8e2173ee7cdaf590","best_bid":"0.14","best_ask":"0.15"}],"timestamp":"1768250242419","event_type":"price_change"}}
{"schema_version":1,"source":"clob_ws_market","recv_ts_ns":1768250242501650876,"event_type":"price_change","market":"0x2a12fd3d8235c25c062dc9652970ef9f635636c4018df0909e1a51c673e125cb","server_ts_ms":1768250242421,"raw":{"market":"0x2a12fd3d8235c25c062dc9652970ef9f635636c4018df0909e1a51c673e125cb","price_changes":[{"asset_id":"56386988715176239099720172290594769295756680374928571099138069977179519358166","price":"0.12","size":"1420.75","side":"BUY","hash":"2a6e0e204e3000248980c9267f7364648d5b1247","best_bid":"0.14","best_ask":"0.15"},{"asset_id":"63670753354844494163057275310194312729998307779831462269530137743341854359908","price":"0.88","size":"1420.75","side":"SELL","hash":"1efeb939d97049612a2ac2951d686ab48af0f8ef","best_bid":"0.85","best_ask":"0.86"}],"timestamp":"1768250242421","event_type":"price_change"}}
{"schema_version":1,"source":"clob_ws_market","recv_ts_ns":1768250242505129132,"event_type":"price_change","market":"0x2a12fd3d8235c25c062dc9652970ef9f635636c4018df0909e1a51c673e125cb","server_ts_ms":1768250242422,"raw":{"market":"0x2a12fd3d8235c25c062dc9652970ef9f635636c4018df0909e1a51c673e125cb","price_changes":[{"asset_id":"63670753354844494163057275310194312729998307779831462269530137743341854359908","price":"0.85","size":"63.99","side":"BUY","hash":"674fbfd4b35f8ab9e05fed6d49f5072ea0a98c02","best_bid":"0.85","best_ask":"0.86"},{"asset_id":"56386988715176239099720172290594769295756680374928571099138069977179519358166","price":"0.15","size":"63.99","side":"SELL","hash":"134b577b8db74f55c800b6d4aa1cc18cf5bd03f5","best_bid":"0.14","best_ask":"0.15"}],"timestamp":"1768250242422","event_type":"price_change"}}
{"schema_version":1,"source":"clob_ws_market","recv_ts_ns":1768250242508330011,"event_type":"best_bid_ask","market":"0x2a12fd3d8235c25c062dc9652970ef9f635636c4018df0909e1a51c673e125cb","server_ts_ms":1768250242434,"raw":{"market":"0x2a12fd3d8235c25c062dc9652970ef9f635636c4018df0909e1a51c673e125cb","asset_id":"56386988715176239099720172290594769295756680374928571099138069977179519358166","best_bid":"0.14","best_ask":"0.15","spread":"0.01","timestamp":"1768250242434","event_type":"best_bid_ask"}}
{"schema_version":1,"source":"clob_ws_market","recv_ts_ns":1768250242511665151,"event_type":"price_change","market":"0x2a12fd3d8235c25c062dc9652970ef9f635636c4018df0909e1a51c673e125cb","server_ts_ms":1768250242433,"raw":{"market":"0x2a12fd3d8235c25c062dc9652970ef9f635636c4018df0909e1a51c673e125cb","price_changes":[{"asset_id":"63670753354844494163057275310194312729998307779831462269530137743341854359908","price":"0.86","size":"203.65","side":"SELL","hash":"fb0ab927e0229a3bc7ee0f05ca49cfabdc8cd8ee","best_bid":"0.85","best_ask":"0.86"},{"asset_id":"56386988715176239099720172290594769295756680374928571099138069977179519358166","price":"0.14","size":"203.65","side":"BUY","hash":"0a455d7642dc432f610b0ffe057ceb0708d8f6e7","best_bid":"0.14","best_ask":"0.15"}],"timestamp":"1768250242433","event_type":"price_change"}}
{"schema_version":1,"source":"clob_ws_market","recv_ts_ns":1768250242515650793,"event_type":"book","market":"0x2a12fd3d8235c25c062dc9652970ef9f635636c4018df0909e1a51c673e125cb","server_ts_ms":1768250242433,"raw":{"market":"0x2a12fd3d8235c25c062dc9652970ef9f635636c4018df0909e1a51c673e125cb","asset_id":"56386988715176239099720172290594769295756680374928571099138069977179519358166","bids":[{"price":"0.01","size":"10331.71"},{"price":"0.02","size":"6299.77"},{"price":"0.03","size":"5625.94"},{"price":"0.04","size":"5427"},{"price":"0.05","size":"3442"},{"price":"0.06","size":"1414"},{"price":"0.07","size":"1418.78"},{"price":"0.08","size":"1559.75"},{"price":"0.09","size":"1317"},{"price":"0.1","size":"3443"},{"price":"0.11","size":"869.5"},{"price":"0.12","size":"1420.75"},{"price":"0.13","size":"341"},{"price":"0.14","size":"203.65"}],"asks":[{"price":"0.99","size":"10184.18"},{"price":"0.98","size":"5982"},{"price":"0.97","size":"5238.94"},{"price":"0.96","size":"5040"},{"price":"0.95","size":"5050"},{"price":"0.94","size":"5005"},{"price":"0.93","size":"5019.28"},{"price":"0.92","size":"5005"},{"price":"0.91","size":"5005"},{"price":"0.9","size":"5030"},{"price":"0.89","size":"5"},{"price":"0.88","size":"5"},{"price":"0.87","size":"5"},{"price":"0.86","size":"5"},{"price":"0.85","size":"10"},{"price":"0.84","size":"5"},{"price":"0.83","size":"5"},{"price":"0.82","size":"5"},{"price":"0.81","size":"5"},{"price":"0.8","size":"5"},{"price":"0.79","size":"5"},{"price":"0.78","size":"5"},{"price":"0.77","size":"5"},{"price":"0.76","size":"5"},{"price":"0.75","size":"10"},{"price":"0.74","size":"5"},{"price":"0.73","size":"5"},{"price":"0.72","size":"5"},{"price":"0.71","size":"15"},{"price":"0.7","size":"10"},{"price":"0.69","size":"5"},{"price":"0.68","size":"5"},{"price":"0.67","size":"5"},{"price":"0.66","size":"505"},{"price":"0.65","size":"510"},{"price":"0.64","size":"510"},{"price":"0.63","size":"505"},{"price":"0.62","size":"505"},{"price":"0.61","size":"755"},{"price":"0.6","size":"760"},{"price":"0.59","size":"916"},{"price":"0.58","size":"671"},{"price":"0.57","size":"827"},{"price":"0.56","size":"827"},{"price":"0.55","size":"817"},{"price":"0.54","size":"872"},{"price":"0.53","size":"839.65"},{"price":"0.52","size":"829"},{"price":"0.51","size":"817"},{"price":"0.5","size":"838.4"},{"price":"0.49","size":"867.58"},{"price":"0.48","size":"817"},{"price":"0.47","size":"827"},{"price":"0.46","size":"847.8"},{"price":"0.45","size":"836.09"},{"price":"0.44","size":"825"},{"price":"0.43","size":"847"},{"price":"0.42","size":"817"},{"price":"0.41","size":"817"},{"price":"0.4","size":"817"},{"price":"0.39","size":"834.5"},{"price":"0.38","size":"817"},{"price":"0.37","size":"497.49"},{"price":"0.36","size":"817"},{"price":"0.35","size":"872"},{"price":"0.34","size":"906.8"},{"price":"0.33","size":"996.36"},{"price":"0.32","size":"902"},{"price":"0.31","size":"922"},{"price":"0.3","size":"911.6"},{"price":"0.29","size":"897"},{"price":"0.28","size":"899.55"},{"price":"0.27","size":"912"},{"price":"0.26","size":"1174.42"},{"price":"0.25","size":"722.5"},{"price":"0.24","size":"912.05"},{"price":"0.23","size":"748.5"},{"price":"0.22","size":"916.9"},{"price":"0.21","size":"814.5"},{"price":"0.2","size":"814.9"},{"price":"0.19","size":"888.21"},{"price":"0.18","size":"671"},{"price":"0.17","size":"179.52"},{"price":"0.16","size":"212.5"},{"price":"0.15","size":"63.99"}],"hash":"0a455d7642dc432f610b0ffe057ceb0708d8f6e7","timestamp":"1768250242433","event_type":"book"}}
{"schema_version":1,"source":"clob_ws_market","recv_ts_ns":1768250242677793652,"event_type":"price_change","market":"0x2a12fd3d8235c25c062dc9652970ef9f635636c4018df0909e1a51c673e125cb","server_ts_ms":1768250242651,"raw":{"market":"0x2a12fd3d8235c25c062dc9652970ef9f635636c4018df0909e1a51c673e125cb","price_changes":[{"asset_id":"56386988715176239099720172290594769295756680374928571099138069977179519358166","price":"0.13","size":"351","side":"BUY","hash":"e03de407236dd968506c564effcbe0cc6d869bac","best_bid":"0.14","best_ask":"0.15"},{"asset_id":"63670753354844494163057275310194312729998307779831462269530137743341854359908","price":"0.87","size":"351","side":"SELL","hash":"cc09f3780818f25be25dc746aa6844ac4a83efff","best_bid":"0.85","best_ask":"0.86"}],"timestamp":"1768250242651","event_type":"price_change"}}
{"schema_version":1,"source":"clob_ws_market","recv_ts_ns":1768250242682691524,"event_type":"price_change","market":"0x2a12fd3d8235c25c062dc9652970ef9f635636c4018df0909e1a51c673e125cb","server_ts_ms":1768250242652,"raw":{"market":"0x2a12fd3d8235c25c062dc9652970ef9f635636c4018df0909e1a51c673e125cb","price_changes":[{"asset_id":"56386988715176239099720172290594769295756680374928571099138069977179519358166","price":"0.11","size":"879.5","side":"BUY","hash":"e713d0b501c657a25fb407d757d683e54f3bd80d","best_bid":"0.14","best_ask":"0.15"},{"asset_id":"63670753354844494163057275310194312729998307779831462269530137743341854359908","price":"0.89","size":"879.5","side":"SELL","hash":"8048db51d3020eefabcb2aac68df64079c90349f","best_bid":"0.85","best_ask":"0.86"}],"timestamp":"1768250242652","event_type":"price_change"}}
{"schema_version":1,"source":"clob_ws_market","recv_ts_ns":1768250242687184104,"event_type":"price_change","market":"0x2a12fd3d8235c25c062dc9652970ef9f635636c4018df0909e1a51c673e125cb","server_ts_ms":1768250242656,"raw":{"market":"0x2a12fd3d8235c25c062dc9652970ef9f635636c4018df0909e1a51c673e125cb","price_changes":[{"asset_id":"63670753354844494163057275310194312729998307779831462269530137743341854359908","price":"0.84","size":"222.5","side":"BUY","hash":"b75e9ee3e290e477ef132c342f86ff3950102762","best_bid":"0.85","best_ask":"0.86"},{"asset_id":"56386988715176239099720172290594769295756680374928571099138069977179519358166","price":"0.16","size":"222.5","side":"SELL","hash":"5d43b50dbbbc0618837b4b95b7cde9688e137f66","best_bid":"0.14","best_ask":"0.15"}],"timestamp":"1768250242656","event_type":"price_change"}}
{"schema_version":1,"source":"clob_ws_market","recv_ts_ns":1768250242698132767,"event_type":"price_change","market":"0x2a12fd3d8235c25c062dc9652970ef9f635636c4018df0909e1a51c673e125cb","server_ts_ms":1768250242658,"raw":{"market":"0x2a12fd3d8235c25c062dc9652970ef9f635636c4018df0909e1a51c673e125cb","price_changes":[{"asset_id":"56386988715176239099720172290594769295756680374928571099138069977179519358166","price":"0.11","size":"889.5","side":"BUY","hash":"8e7bdf5b52f50c7889135beca69e7da41dc00e2c","best_bid":"0.14","best_ask":"0.15"},{"asset_id":"63670753354844494163057275310194312729998307779831462269530137743341854359908","price":"0.89","size":"889.5","side":"SELL","hash":"cf57946385320a5e270c83063a3878309c0ba092","best_bid":"0.85","best_ask":"0.86"}],"timestamp":"1768250242658","event_type":"price_change"}}
{"schema_version":1,"source":"clob_ws_market","recv_ts_ns":1768250242702634613,"event_type":"price_change","market":"0x2a12fd3d8235c25c062dc9652970ef9f635636c4018df0909e1a51c673e125cb","server_ts_ms":1768250242658,"raw":{"market":"0x2a12fd3d8235c25c062dc9652970ef9f635636c4018df0909e1a51c673e125cb","price_changes":[{"asset_id":"63670753354844494163057275310194312729998307779831462269530137743341854359908","price":"0.84","size":"232.5","side":"BUY","hash":"27baa69b1b5821b03ca7a12e511987075ed6e87b","best_bid":"0.85","best_ask":"0.86"},{"asset_id":"56386988715176239099720172290594769295756680374928571099138069977179519358166","price":"0.16","size":"232.5","side":"SELL","hash":"37018a218ca72720cda75ccb769d820734c5e85d","best_bid":"0.14","best_ask":"0.15"}],"timestamp":"1768250242658","event_type":"price_change"}}
{"schema_version":1,"source":"clob_ws_market","recv_ts_ns":1768250242705927611,"event_type":"price_change","market":"0x2a12fd3d8235c25c062dc9652970ef9f635636c4018df0909e1a51c673e125cb","server_ts_ms":1768250242660,"raw":{"market":"0x2a12fd3d8235c25c062dc9652970ef9f635636c4018df0909e1a51c673e125cb","price_changes":[{"asset_id":"63670753354844494163057275310194312729998307779831462269530137743341854359908","price":"0.84","size":"242.5","side":"BUY","hash":"21ac65c20a07886d9d2e56edd9c94bedee10bd6b","best_bid":"0.85","best_ask":"0.86"},{"asset_id":"56386988715176239099720172290594769295756680374928571099138069977179519358166","price":"0.16","size":"242.5","side":"SELL","hash":"b035699bbf4c2fc96632f1afb32d1d3ccddc1471","best_bid":"0.14","best_ask":"0.15"}],"timestamp":"1768250242660","event_type":"price_change"}}
{"schema_version":1,"source":"clob_ws_market","recv_ts_ns":1768250242708915079,"event_type":"price_change","market":"0x2a12fd3d8235c25c062dc9652970ef9f635636c4018df0909e1a51c673e125cb","server_ts_ms":1768250242661,"raw":{"market":"0x2a12fd3d8235c25c062dc9652970ef9f635636c4018df0909e1a51c673e125cb","price_changes":[{"asset_id":"56386988715176239099720172290594769295756680374928571099138069977179519358166","price":"0.1","size":"3433","side":"BUY","hash":"b5165debe9179265cdd851552d7df9537b188743","best_bid":"0.14","best_ask":"0.15"},{"asset_id":"63670753354844494163057275310194312729998307779831462269530137743341854359908","price":"0.9","size":"3433","side":"SELL","hash":"9c2c287b45315c6de71c1cd8bd8ed4364f508d20","best_bid":"0.85","best_ask":"0.86"}],"timestamp":"1768250242661","event_type":"price_change"}}
{"schema_version":1,"source":"clob_ws_market","recv_ts_ns":1768250242713393799,"event_type":"price_change","market":"0x2a12fd3d8235c25c062dc9652970ef9f635636c4018df0909e1a51c673e125cb","server_ts_ms":1768250242661,"raw":{"market":"0x2a12fd3d8235c25c062dc9652970ef9f635636c4018df0909e1a51c673e125cb","price_changes":[{"asset_id":"56386988715176239099720172290594769295756680374928571099138069977179519358166","price":"0.12","size":"1430.75","side":"BUY","hash":"ed44ee86415a5d45705142ba65770902a42eec8b","best_bid":"0.14","best_ask":"0.15"},{"asset_id":"63670753354844494163057275310194312729998307779831462269530137743341854359908","price":"0.88","size":"1430.75","side":"SELL","hash":"e151e13f5248886d6e0f4e52c8deea82a27647ca","best_bid":"0.85","best_ask":"0.86"}],"timestamp":"1768250242661","event_type":"price_change"}}
{"schema_version":1,"source":"clob_ws_market","recv_ts_ns":1768250242718021611,"event_type":"price_change","market":"0x2a12fd3d8235c25c062dc9652970ef9f635636c4018df0909e1a51c673e125cb","server_ts_ms":1768250242662,"raw":{"market":"0x2a12fd3d8235c25c062dc9652970ef9f635636c4018df0909e1a51c673e125cb","price_changes":[{"asset_id":"56386988715176239099720172290594769295756680374928571099138069977179519358166","price":"0.11","size":"899.5","side":"BUY","hash":"feb3e5f13387e6bd64f631ebba266aa212f91fec","best_bid":"0.14","best_ask":"0.15"},{"asset_id":"63670753354844494163057275310194312729998307779831462269530137743341854359908","price":"0.89","size":"899.5","side":"SELL","hash":"1fc7e493dbe24f2ebfd92e337c924403cb23e8c7","best_bid":"0.85","best_ask":"0.86"}],"timestamp":"1768250242662","event_type":"price_change"}}
{"schema_version":1,"source":"clob_ws_market","recv_ts_ns":1768250242724134652,"event_type":"price_change","market":"0x2a12fd3d8235c25c062dc9652970ef9f635636c4018df0909e1a51c673e125cb","server_ts_ms":1768250242663,"raw":{"market":"0x2a12fd3d8235c25c062dc9652970ef9f635636c4018df0909e1a51c673e125cb","price_changes":[{"asset_id":"63670753354844494163057275310194312729998307779831462269530137743341854359908","price":"0.84","size":"252.5","side":"BUY","hash":"7a92224233852f634c69d120d9dc49f38d72f4f1","best_bid":"0.85","best_ask":"0.86"},{"asset_id":"56386988715176239099720172290594769295756680374928571099138069977179519358166","price":"0.16","size":"252.5","side":"SELL","hash":"e5d1be3d696c00a127ee2a4ac7db328cb3cd467b","best_bid":"0.14","best_ask":"0.15"}],"timestamp":"1768250242663","event_type":"price_change"}}
{"schema_version":1,"source":"clob_ws_market","recv_ts_ns":1768250242728986599,"event_type":"price_change","market":"0x2a12fd3d8235c25c062dc9652970ef9f635636c4018df0909e1a51c673e125cb","server_ts_ms":1768250242664,"raw":{"market":"0x2a12fd3d8235c25c062dc9652970ef9f635636c4018df0909e1a51c673e125cb","price_changes":[{"asset_id":"56386988715176239099720172290594769295756680374928571099138069977179519358166","price":"0.1","size":"3443","side":"BUY","hash":"0a370cf6f9e222d8b578edfc195d839876ba42d6","best_bid":"0.14","best_ask":"0.15"},{"asset_id":"63670753354844494163057275310194312729998307779831462269530137743341854359908","price":"0.9","size":"3443","side":"SELL","hash":"898e008aceb66b11ad4e7fb46c81f7392daa7432","best_bid":"0.85","best_ask":"0.86"}],"timestamp":"1768250242664","event_type":"price_change"}}
{"schema_version":1,"source":"clob_ws_market","recv_ts_ns":1768250242734197051,"event_type":"price_change","market":"0x2a12fd3d8235c25c062dc9652970ef9f635636c4018df0909e1a51c673e125cb","server_ts_ms":1768250242667,"raw":{"market":"0x2a12fd3d8235c25c062dc9652970ef9f635636c4018df0909e1a51c673e125cb","price_changes":[{"asset_id":"63670753354844494163057275310194312729998307779831462269530137743341854359908","price":"0.84","size":"262.5","side":"BUY","hash":"38795baa69644df99ccd0d1b30b9832dd0af2800","best_bid":"0.85","best_ask":"0.86"},{"asset_id":"56386988715176239099720172290594769295756680374928571099138069977179519358166","price":"0.16","size":"262.5","side":"SELL","hash":"519969ce7d23dfd0898e55f9881ec317b7571f31","best_bid":"0.14","best_ask":"0.15"}],"timestamp":"1768250242667","event_type":"price_change"}}
{"schema_version":1,"source":"clob_ws_market","recv_ts_ns":1768250242739624783,"event_type":"price_change","market":"0x2a12fd3d8235c25c062dc9652970ef9f635636c4018df0909e1a51c673e125cb","server_ts_ms":1768250242668,"raw":{"market":"0x2a12fd3d8235c25c062dc9652970ef9f635636c4018df0909e1a51c673e125cb","price_changes":[{"asset_id":"56386988715176239099720172290594769295756680374928571099138069977179519358166","price":"0.09","size":"1327","side":"BUY","hash":"5a454e8d28b09f0ec8e08c3d8c0a262fa3e1a947","best_bid":"0.14","best_ask":"0.15"},{"asset_id":"63670753354844494163057275310194312729998307779831462269530137743341854359908","price":"0.91","size":"1327","side":"SELL","hash":"a93c6a673236b9e7a9ac4f394d596f2df6ca6303","best_bid":"0.85","best_ask":"0.86"}],"timestamp":"1768250242668","event_type":"price_change"}}
{"schema_version":1,"source":"clob_ws_market","recv_ts_ns":1768250242745150748,"event_type":"price_change","market":"0x2a12fd3d8235c25c062dc9652970ef9f635636c4018df0909e1a51c673e125cb","server_ts_ms":1768250242669,"raw":{"market":"0x2a12fd3d8235c25c062dc9652970ef9f635636c4018df0909e1a51c673e125cb","price_changes":[{"asset_id":"63670753354844494163057275310194312729998307779831462269530137743341854359908","price":"0.84","size":"272.5","side":"BUY","hash":"be401dcf12c425a372228466ac4cd4d45d379ce2","best_bid":"0.85","best_ask":"0.86"},{"asset_id":"56386988715176239099720172290594769295756680374928571099138069977179519358166","price":"0.16","size":"272.5","side":"SELL","hash":"1d2203f6ffe05fbf31767800ed0d3e69c033576b","best_bid":"0.14","best_ask":"0.15"}],"timestamp":"1768250242669","event_type":"price_change"}}
{"schema_version":1,"source":"clob_ws_market","recv_ts_ns":1768250242748888881,"event_type":"price_change","market":"0x2a12fd3d8235c25c062dc9652970ef9f635636c4018df0909e1a51c673e125cb","server_ts_ms":1768250242670,"raw":{"market":"0x2a12fd3d8235c25c062dc9652970ef9f635636c4018df0909e1a51c673e125cb","price_changes":[{"asset_id":"56386988715176239099720172290594769295756680374928571099138069977179519358166","price":"0.14","size":"213.65","side":"BUY","hash":"5425d3fc013372c15d55c2e6033b4b6ba9d26487","best_bid":"0.14","best_ask":"0.15"},{"asset_id":"63670753354844494163057275310194312729998307779831462269530137743341854359908","price":"0.86","size":"213.65","side":"SELL","hash":"0fff4589171380fc6b03f07f954634fe7d7ec51f","best_bid":"0.85","best_ask":"0.86"}],"timestamp":"1768250242670","event_type":"price_change"}}
{"schema_version":1,"source":"clob_ws_market","recv_ts_ns":1768250242758782525,"event_type":"price_change","market":"0x2a12fd3d8235c25c062dc9652970ef9f635636c4018df0909e1a51c673e125cb","server_ts_ms":1768250242687,"raw":{"market":"0x2a12fd3d8235c25c062dc9652970ef9f635636c4018df0909e1a51c673e125cb","price_changes":[{"asset_id":"63670753354844494163057275310194312729998307779831462269530137743341854359908","price":"0.84","size":"282.5","side":"BUY","hash":"ad9a9476895e2671f4ca9353bb89cb63aaa472a0","best_bid":"0.85","best_ask":"0.86"},{"asset_id":"56386988715176239099720172290594769295756680374928571099138069977179519358166","price":"0.16","size":"282.5","side":"SELL","hash":"02ee6f7f96f2e50706e2781ff1082a96b072414c","best_bid":"0.14","best_ask":"0.15"}],"timestamp":"1768250242687","event_type":"price_change"}}
{"schema_version":1,"source":"clob_ws_market","recv_ts_ns":1768250242764495283,"event_type":"price_change","market":"0x2a12fd3d8235c25c062dc9652970ef9f635636c4018df0909e1a51c673e125cb","server_ts_ms":1768250242695,"raw":{"market":"0x2a12fd3d8235c25c062dc9652970ef9f635636c4018df0909e1a51c673e125cb","price_changes":[{"asset_id":"56386988715176239099720172290594769295756680374928571099138069977179519358166","price":"0.12","size":"1435.75","side":"BUY","hash":"9848e0082ce210dff270201f7a03b5f1e984840e","best_bid":"0.14","best_ask":"0.15"},{"asset_id":"63670753354844494163057275310194312729998307779831462269530137743341854359908","price":"0.88","size":"1435.75","side":"SELL","hash":"00f6183fa6f4e2af733e0fb19b186178e9c49eb7","best_bid":"0.85","best_ask":"0.86"}],"timestamp":"1768250242695","event_type":"price_change"}}
{"schema_version":1,"source":"clob_ws_market","recv_ts_ns":1768250242769718452,"event_type":"price_change","market":"0x2a12fd3d8235c25c062dc9652970ef9f635636c4018df0909e1a51c673e125cb","server_ts_ms":1768250242699,"raw":{"market":"0x2a12fd3d8235c25c062dc9652970ef9f635636c4018df0909e1a51c673e125cb","price_changes":[{"asset_id":"56386988715176239099720172290594769295756680374928571099138069977179519358166","price":"0.13","size":"361","side":"BUY","hash":"6795a8a87bfaab3b045a4c28f4a61bd41b739255","best_bid":"0.14","best_ask":"0.15"},{"asset_id":"63670753354844494163057275310194312729998307779831462269530137743341854359908","price":"0.87","size":"361","side":"SELL","hash":"6302b54a8f1e0e0ebf52d2de7cec4e714e265439","best_bid":"0.85","best_ask":"0.86"}],"timestamp":"1768250242699","event_type":"price_change"}}
{"schema_version":1,"source":"clob_ws_market","recv_ts_ns":1768250242775078158,"event_type":"price_change","market":"0x2a12fd3d8235c25c062dc9652970ef9f635636c4018df0909e1a51c673e125cb","server_ts_ms":1768250242703,"raw":{"market":"0x2a12fd3d8235c25c062dc9652970ef9f635636c4018df0909e1a51c673e125cb","price_changes":[{"asset_id":"63670753354844494163057275310194312729998307779831462269530137743341854359908","price":"0.83","size":"189.52","side":"BUY","hash":"a897c90047c88d796220556c66aed7c8aa736549","best_bid":"0.85","best_ask":"0.86"},{"asset_id":"56386988715176239099720172290594769295756680374928571099138069977179519358166","price":"0.17","size":"189.52","side":"SELL","hash":"3dcea2f9b7475a337e6dcce53e7eae1d6d171992","best_bid":"0.14","best_ask":"0.15"}],"timestamp":"1768250242703","event_type":"price_change"}}
{"schema_version":1,"source":"clob_ws_market","recv_ts_ns":1768250242780695157,"event_type":"price_change","market":"0x2a12fd3d8235c25c062dc9652970ef9f635636c4018df0909e1a51c673e125cb","server_ts_ms":1768250242711,"raw":{"market":"0x2a12fd3d8235c25c062dc9652970ef9f635636c4018df0909e1a51c673e125cb","price_changes":[{"asset_id":"63670753354844494163057275310194312729998307779831462269530137743341854359908","price":"0.84","size":"292.5","side":"BUY","hash":"b8d64488d73cafa8b15548ef217a40ae69a4b5af","best_bid":"0.85","best_ask":"0.86"},{"asset_id":"56386988715176239099720172290594769295756680374928571099138069977179519358166","price":"0.16","size":"292.5","side":"SELL","hash":"e2d0509ba83b31ff161ad3fb04ccddab429ba2b9","best_bid":"0.14","best_ask":"0.15"}],"timestamp":"1768250242711","event_type":"price_change"}}
{"schema_version":1,"source":"clob_ws_market","recv_ts_ns":1768250242795964683,"event_type":"price_change","market":"0x2a12fd3d8235c25c062dc9652970ef9f635636c4018df0909e1a51c673e125cb","server_ts_ms":1768250242743,"raw":{"market":"0x2a12fd3d8235c25c062dc9652970ef9f635636c4018df0909e1a51c673e125cb","price_changes":[{"asset_id":"56386988715176239099720172290594769295756680374928571099138069977179519358166","price":"0.14","size":"227.93","side":"BUY","hash":"9f28a33264dfca2e5b3f5054a5062d7a11c58e57","best_bid":"0.14","best_ask":"0.15"},{"asset_id":"63670753354844494163057275310194312729998307779831462269530137743341854359908","price":"0.86","size":"227.93","side":"SELL","hash":"416a21933cd60a5ec7443cba15da6e22ab7eb25c","best_bid":"0.85","best_ask":"0.86"}],"timestamp":"1768250242743","event_type":"price_change"}}
{"schema_version":1,"source":"clob_ws_market","recv_ts_ns":1768250242869784738,"event_type":"price_change","market":"0x2a12fd3d8235c25c062dc9652970ef9f635636c4018df0909e1a51c673e125cb","server_ts_ms":1768250242849,"raw":{"market":"0x2a12fd3d8235c25c062dc9652970ef9f635636c4018df0909e1a51c673e125cb","price_changes":[{"asset_id":"56386988715176239099720172290594769295756680374928571099138069977179519358166","price":"0.11","size":"909.5","side":"BUY","hash":"f761f409358d225dbd7fd3f3b001f84a6015fcf8","best_bid":"0.14","best_ask":"0.15"},{"asset_id":"63670753354844494163057275310194312729998307779831462269530137743341854359908","price":"0.89","size":"909.5","side":"SELL","hash":"70e4f6b20dbdb27ff4de21ebdbf1ccc7cefa85ec","best_bid":"0.85","best_ask":"0.86"}],"timestamp":"1768250242849","event_type":"price_change"}}
{"schema_version":1,"source":"clob_ws_market","recv_ts_ns":1768250242911209548,"event_type":"price_change","market":"0x2a12fd3d8235c25c062dc9652970ef9f635636c4018df0909e1a51c673e125cb","server_ts_ms":1768250242888,"raw":{"market":"0x2a12fd3d8235c25c062dc9652970ef9f635636c4018df0909e1a51c673e125cb","price_changes":[{"asset_id":"63670753354844494163057275310194312729998307779831462269530137743341854359908","price":"0.79","size":"808.5","side":"BUY","hash":"ae2e5e475818bac6e121e7848d2eecfd18636436","best_bid":"0.85","best_ask":"0.86"},{"asset_id":"56386988715176239099720172290594769295756680374928571099138069977179519358166","price":"0.21","size":"808.5","side":"SELL","hash":"8a35e39ebdc739e602026e2aea84597e1d45106c","best_bid":"0.14","best_ask":"0.15"}],"timestamp":"1768250242888","event_type":"price_change"}}
{"schema_version":1,"source":"clob_ws_market","recv_ts_ns":1768250242917180240,"event_type":"price_change","market":"0x2a12fd3d8235c25c062dc9652970ef9f635636c4018df0909e1a51c673e125cb","server_ts_ms":1768250242888,"raw":{"market":"0x2a12fd3d8235c25c062dc9652970ef9f635636c4018df0909e1a51c673e125cb","price_changes":[{"asset_id":"63670753354844494163057275310194312729998307779831462269530137743341854359908","price":"0.9","size":"3437","side":"SELL","hash":"ae2e5e475818bac6e121e7848d2eecfd18636436","best_bid":"0.85","best_ask":"0.86"},{"asset_id":"56386988715176239099720172290594769295756680374928571099138069977179519358166","price":"0.1","size":"3437","side":"BUY","hash":"8a35e39ebdc739e602026e2aea84597e1d45106c","best_bid":"0.14","best_ask":"0.15"}],"timestamp":"1768250242888","event_type":"price_change"}}
{"schema_version":1,"source":"clob_ws_market","recv_ts_ns":1768250242958187902,"event_type":"price_change","market":"0x2a12fd3d8235c25c062dc9652970ef9f635636c4018df0909e1a51c673e125cb","server_ts_ms":1768250242936,"raw":{"market":"0x2a12fd3d8235c25c062dc9652970ef9f635636c4018df0909e1a51c673e125cb","price_changes":[{"asset_id":"63670753354844494163057275310194312729998307779831462269530137743341854359908","price":"0.78","size":"922.9","side":"BUY","hash":"83f5f1caba53d432cd779aad9255e6d5b4d41256","best_bid":"0.85","best_ask":"0.86"},{"asset_id":"56386988715176239099720172290594769295756680374928571099138069977179519358166","price":"0.22","size":"922.9","side":"SELL","hash":"218ec184e67ddb2102f224e1801a4b6a1cb65dcb","best_bid":"0.14","best_ask":"0.15"}],"timestamp":"1768250242936","event_type":"price_change"}}
{"schema_version":1,"source":"clob_ws_market","recv_ts_ns":1768250242963071170,"event_type":"price_change","market":"0x2a12fd3d8235c25c062dc9652970ef9f635636c4018df0909e1a51c673e125cb","server_ts_ms":1768250242937,"raw":{"market":"0x2a12fd3d8235c25c062dc9652970ef9f635636c4018df0909e1a51c673e125cb","price_changes":[{"asset_id":"63670753354844494163057275310194312729998307779831462269530137743341854359908","price":"0.89","size":"915.5","side":"SELL","hash":"af051a7e7d33a0d73dbf6a7effa64a6896f1bfdb","best_bid":"0.85","best_ask":"0.86"},{"asset_id":"56386988715176239099720172290594769295756680374928571099138069977179519358166","price":"0.11","size":"915.5","side":"BUY","hash":"acd0fc8fadc2db811758fd6a0d0b2ae8ce0e4012","best_bid":"0.14","best_ask":"0.15"}],"timestamp":"1768250242937","event_type":"price_change"}}
{"schema_version":1,"source":"clob_ws_market","recv_ts_ns":1768250243062115724,"event_type":"price_change","market":"0x2a12fd3d8235c25c062dc9652970ef9f635636c4018df0909e1a51c673e125cb","server_ts_ms":1768250243037,"raw":{"market":"0x2a12fd3d8235c25c062dc9652970ef9f635636c4018df0909e1a51c673e125cb","price_changes":[{"asset_id":"56386988715176239099720172290594769295756680374928571099138069977179519358166","price":"0.12","size":"1440.75","side":"BUY","hash":"8477791e89e3a2628bb8e4b828fd91f26d909b73","best_bid":"0.14","best_ask":"0.15"},{"asset_id":"63670753354844494163057275310194312729998307779831462269530137743341854359908","price":"0.88","size":"1440.75","side":"SELL","hash":"0e7f23e58a3369a7cd2ba6d4b560e3e2042ceb35","best_bid":"0.85","best_ask":"0.86"}],"timestamp":"1768250243037","event_type":"price_change"}}
{"schema_version":1,"source":"clob_ws_market","recv_ts_ns":1768250243076677115,"event_type":"price_change","market":"0x2a12fd3d8235c25c062dc9652970ef9f635636c4018df0909e1a51c673e125cb","server_ts_ms":1768250243056,"raw":{"market":"0x2a12fd3d8235c25c062dc9652970ef9f635636c4018df0909e1a51c673e125cb","price_changes":[{"asset_id":"56386988715176239099720172290594769295756680374928571099138069977179519358166","price":"0.12","size":"1430.75","side":"BUY","hash":"0797908354a595d579f9b8f903c361c725183885","best_bid":"0.14","best_ask":"0.15"},{"asset_id":"63670753354844494163057275310194312729998307779831462269530137743341854359908","price":"0.88","size":"1430.75","side":"SELL","hash":"a0042f99b5e2c0415687e787cbacd30c55b9b49d","best_bid":"0.85","best_ask":"0.86"}],"timestamp":"1768250243056","event_type":"price_change"}}
{"schema_version":1,"source":"clob_ws_market","recv_ts_ns":1768250243113449399,"event_type":"price_change","market":"0x2a12fd3d8235c25c062dc9652970ef9f635636c4018df0909e1a51c673e125cb","server_ts_ms":1768250243091,"raw":{"market":"0x2a12fd3d8235c25c062dc9652970ef9f635636c4018df0909e1a51c673e125cb","price_changes":[{"asset_id":"63670753354844494163057275310194312729998307779831462269530137743341854359908","price":"0.78","size":"916.9","side":"BUY","hash":"3f718387f6e11942a7a6e38b8b2666a9765d0da5","best_bid":"0.85","best_ask":"0.86"},{"asset_id":"56386988715176239099720172290594769295756680374928571099138069977179519358166","price":"0.22","size":"916.9","side":"SELL","hash":"1d2bfb039be257ea00b7a4cfe38ae5ecb4621b63","best_bid":"0.14","best_ask":"0.15"}],"timestamp":"1768250243091","event_type":"price_change"}}
{"schema_version":1,"source":"clob_ws_market","recv_ts_ns":1768250243118701934,"event_type":"price_change","market":"0x2a12fd3d8235c25c062dc9652970ef9f635636c4018df0909e1a51c673e125cb","server_ts_ms":1768250243091,"raw":{"market":"0x2a12fd3d8235c25c062dc9652970ef9f635636c4018df0909e1a51c673e125cb","price_changes":[{"asset_id":"63670753354844494163057275310194312729998307779831462269530137743341854359908","price":"0.89","size":"909.5","side":"SELL","hash":"3f718387f6e11942a7a6e38b8b2666a9765d0da5","best_bid":"0.85","best_ask":"0.86"},{"asset_id":"56386988715176239099720172290594769295756680374928571099138069977179519358166","price":"0.11","size":"909.5","side":"BUY","hash":"1d2bfb039be257ea00b7a4cfe38ae5ecb4621b63","best_bid":"0.14","best_ask":"0.15"}],"timestamp":"1768250243091","event_type":"price_change"}}
{"schema_version":1,"source":"clob_ws_market","recv_ts_ns":1768250243206839967,"event_type":"price_change","market":"0x2a12fd3d8235c25c062dc9652970ef9f635636c4018df0909e1a51c673e125cb","server_ts_ms":1768250243125,"raw":{"market":"0x2a12fd3d8235c25c062dc9652970ef9f635636c4018df0909e1a51c673e125cb","price_changes":[{"asset_id":"63670753354844494163057275310194312729998307779831462269530137743341854359908","price":"0.9","size":"3443","side":"SELL","hash":"5b3b9c076d2c43a0e6d9459850a5a48c3074242e","best_bid":"0.85","best_ask":"0.86"},{"asset_id":"56386988715176239099720172290594769295756680374928571099138069977179519358166","price":"0.1","size":"3443","side":"BUY","hash":"3120eee3d7f64c183a29dedff030260bf199d95c","best_bid":"0.14","best_ask":"0.15"}],"timestamp":"1768250243125","event_type":"price_change"}}
{"schema_version":1,"source":"clob_ws_market","recv_ts_ns":1768250243212590678,"event_type":"price_change","market":"0x2a12fd3d8235c25c062dc9652970ef9f635636c4018df0909e1a51c673e125cb","server_ts_ms":1768250243126,"raw":{"market":"0x2a12fd3d8235c25c062dc9652970ef9f635636c4018df0909e1a51c673e125cb","price_changes":[{"asset_id":"63670753354844494163057275310194312729998307779831462269530137743341854359908","price":"0.79","size":"814.5","side":"BUY","hash":"f6684800e561ba5022c52f912e75490b5f983aa1","best_bid":"0.85","best_ask":"0.86"},{"asset_id":"56386988715176239099720172290594769295756680374928571099138069977179519358166","price":"0.21","size":"814.5","side":"SELL","hash":"a68953ba359fb3d189c678f3a20dd198ecc62c4a","best_bid":"0.14","best_ask":"0.15"}],"timestamp":"1768250243126","event_type":"price_change"}}
{"schema_version":1,"source":"clob_ws_market","recv_ts_ns":1768250243246413853,"event_type":"price_change","market":"0x2a12fd3d8235c25c062dc9652970ef9f635636c4018df0909e1a51c673e125cb","server_ts_ms":1768250243161,"raw":{"market":"0x2a12fd3d8235c25c062dc9652970ef9f635636c4018df0909e1a51c673e125cb","price_changes":[{"asset_id":"63670753354844494163057275310194312729998307779831462269530137743341854359908","price":"0.84","size":"302.5","side":"BUY","hash":"ccc73ca992a17393aa43834d740521674c3070d8","best_bid":"0.85","best_ask":"0.86"},{"asset_id":"56386988715176239099720172290594769295756680374928571099138069977179519358166","price":"0.16","size":"302.5","side":"SELL","hash":"4e2a05f2b8b82c2ff42b929b2ed635e52b5d167b","best_bid":"0.14","best_ask":"0.15"}],"timestamp":"1768250243161","event_type":"price_change"}}
{"schema_version":1,"source":"clob_ws_market","recv_ts_ns":1768250243277805723,"event_type":"price_change","market":"0x2a12fd3d8235c25c062dc9652970ef9f635636c4018df0909e1a51c673e125cb","server_ts_ms":1768250243234,"raw":{"market":"0x2a12fd3d8235c25c062dc9652970ef9f635636c4018df0909e1a51c673e125cb","price_changes":[{"asset_id":"56386988715176239099720172290594769295756680374928571099138069977179519358166","price":"0.06","size":"1397","side":"BUY","hash":"7dcadb74fd95cd90c46f998c5753ae473d1c68fd","best_bid":"0.14","best_ask":"0.15"},{"asset_id":"63670753354844494163057275310194312729998307779831462269530137743341854359908","price":"0.94","size":"1397","side":"SELL","hash":"011286a35d639e9d81b12699597f3954ccc1c744","best_bid":"0.85","best_ask":"0.86"}],"timestamp":"1768250243234","event_type":"price_change"}}
{"schema_version":1,"source":"clob_ws_market","recv_ts_ns":1768250243295226953,"event_type":"price_change","market":"0x2a12fd3d8235c25c062dc9652970ef9f635636c4018df0909e1a51c673e125cb","server_ts_ms":1768250243270,"raw":{"market":"0x2a12fd3d8235c25c062dc9652970ef9f635636c4018df0909e1a51c673e125cb","price_changes":[{"asset_id":"56386988715176239099720172290594769295756680374928571099138069977179519358166","price":"0.07","size":"1433.78","side":"BUY","hash":"6eec8186706ba8554e623b1a5461cc90c1332144","best_bid":"0.14","best_ask":"0.15"},{"asset_id":"63670753354844494163057275310194312729998307779831462269530137743341854359908","price":"0.93","size":"1433.78","side":"SELL","hash":"6753f2f7ddd2d2e2939793dbb8b4e69890c9233f","best_bid":"0.85","best_ask":"0.86"}],"timestamp":"1768250243270","event_type":"price_change"}}
{"schema_version":1,"source":"clob_ws_market","recv_ts_ns":1768250243312280867,"event_type":"price_change","market":"0x2a12fd3d8235c25c062dc9652970ef9f635636c4018df0909e1a51c673e125cb","server_ts_ms":1768250243290,"raw":{"market":"0x2a12fd3d8235c25c062dc9652970ef9f635636c4018df0909e1a51c673e125cb","price_changes":[{"asset_id":"63670753354844494163057275310194312729998307779831462269530137743341854359908","price":"0.82","size":"171","side":"BUY","hash":"31448e264bf70ceb2d7c8db6bf8bb49d3e2969e3","best_bid":"0.85","best_ask":"0.86"},{"asset_id":"56386988715176239099720172290594769295756680374928571099138069977179519358166","price":"0.18","size":"171","side":"SELL","hash":"bb12dbda49f14efe1c75247492ecfc19d940f391","best_bid":"0.14","best_ask":"0.15"}],"timestamp":"1768250243290","event_type":"price_change"}}
{"schema_version":1,"source":"clob_ws_market","recv_ts_ns":1768250243338721065,"event_type":"price_change","market":"0x2a12fd3d8235c25c062dc9652970ef9f635636c4018df0909e1a51c673e125cb","server_ts_ms":1768250243309,"raw":{"market":"0x2a12fd3d8235c25c062dc9652970ef9f635636c4018df0909e1a51c673e125cb","price_changes":[{"asset_id":"56386988715176239099720172290594769295756680374928571099138069977179519358166","price":"0.11","size":"899.5","side":"BUY","hash":"575f998652341093fd7626c4f15f5eedebd24282","best_bid":"0.14","best_ask":"0.15"},{"asset_id":"63670753354844494163057275310194312729998307779831462269530137743341854359908","price":"0.89","size":"899.5","side":"SELL","hash":"beef52b20a0e16b762b2f21785b05893d81b8329","best_bid":"0.85","best_ask":"0.86"}],"timestamp":"1768250243309","event_type":"price_change"}}
{"schema_version":1,"source":"clob_ws_market","recv_ts_ns":1768250243399894124,"event_type":"best_bid_ask","market":"0x2a12fd3d8235c25c062dc9652970ef9f635636c4018df0909e1a51c673e125cb","server_ts_ms":1768250243380,"raw":{"market":"0x2a12fd3d8235c25c062dc9652970ef9f635636c4018df0909e1a51c673e125cb","asset_id":"56386988715176239099720172290594769295756680374928571099138069977179519358166","best_bid":"0.14","best_ask":"0.15","spread":"0.01","timestamp":"1768250243380","event_type":"best_bid_ask"}}
{"schema_version":1,"source":"clob_ws_market","recv_ts_ns":1768250243405518241,"event_type":"price_change","market":"0x2a12fd3d8235c25c062dc9652970ef9f635636c4018df0909e1a51c673e125cb","server_ts_ms":1768250243378,"raw":{"market":"0x2a12fd3d8235c25c062dc9652970ef9f635636c4018df0909e1a51c673e125cb","price_changes":[{"asset_id":"56386988715176239099720172290594769295756680374928571099138069977179519358166","price":"0.15","size":"56.65","side":"SELL","hash":"2321f0c3ac7cf92c3225c43b5f526ee93e5302d8","best_bid":"0.14","best_ask":"0.15"},{"asset_id":"63670753354844494163057275310194312729998307779831462269530137743341854359908","price":"0.85","size":"56.65","side":"BUY","hash":"3c7046e9b37431f01356c22b5d0de116d0812a36","best_bid":"0.85","best_ask":"0.86"}],"timestamp":"1768250243378","event_type":"price_change"}}
{"schema_version":1,"source":"clob_ws_market","recv_ts_ns":1768250243410496856,"event_type":"price_change","market":"0x2a12fd3d8235c25c062dc9652970ef9f635636c4018df0909e1a51c673e125cb","server_ts_ms":1768250243378,"raw":{"market":"0x2a12fd3d8235c25c062dc9652970ef9f635636c4018df0909e1a51c673e125cb","price_changes":[{"asset_id":"63670753354844494163057275310194312729998307779831462269530137743341854359908","price":"0.85","size":"56.65","side":"BUY","hash":"3c7046e9b37431f01356c22b5d0de116d0812a36","best_bid":"0.85","best_ask":"0.86"},{"asset_id":"56386988715176239099720172290594769295756680374928571099138069977179519358166","price":"0.15","size":"56.65","side":"SELL","hash":"2321f0c3ac7cf92c3225c43b5f526ee93e5302d8","best_bid":"0.14","best_ask":"0.15"}],"timestamp":"1768250243378","event_type":"price_change"}}
