{"schema_version":1,"source":"clob_ws_market","recv_ts_ns":1768250249767727957,"event_type":"price_change","market":"0x2a12fd3d8235c25c062dc9652970ef9f635636c4018df0909e1a51c673e125cb","server_ts_ms":1768250249342,"raw":{"market":"0x2a12fd3d8235c25c062dc9652970ef9f635636c4018df0909e1a51c673e125cb","price_changes":[{"asset_id":"56386988715176239099720172290594769295756680374928571099138069977179519358166","price":"0.1","size":"3417","side":"BUY","hash":"172691802923366a8ddc55ce6ef6c389ec73f107","best_bid":"0.15","best_ask":"0.16"},{"asset_id":"63670753354844494163057275310194312729998307779831462269530137743341854359908","price":"0.9","size":"3417","side":"SELL","hash":"bbdee2273b22850bb97636dd3126061aa70a6a1c","best_bid":"0.84","best_ask":"0.85"}],"timestamp":"1768250249342","event_type":"price_change"}}
{"schema_version":1,"source":"clob_ws_market","recv_ts_ns":1768250249771513454,"event_type":"price_change","market":"0x2a12fd3d8235c25c062dc9652970ef9f635636c4018df0909e1a51c673e125cb","server_ts_ms":1768250249343,"raw":{"market":"0x2a12fd3d8235c25c062dc9652970ef9f635636c4018df0909e1a51c673e125cb","price_changes":[{"asset_id":"63670753354844494163057275310194312729998307779831462269530137743341854359908","price":"0.81","size":"263.21","side":"BUY","hash":"9bc27363ba73a2d60332337b26fd8dd22fa49afa","best_bid":"0.84","best_ask":"0.85"},{"asset_id":"56386988715176239099720172290594769295756680374928571099138069977179519358166","price":"0.19","size":"263.21","side":"SELL","hash":"85d0cee9c7de8bb08ef879fc77132a8f2f99a5b7","best_bid":"0.15","best_ask":"0.16"}],"timestamp":"1768250249343","event_type":"price_change"}}
{"schema_version":1,"source":"clob_ws_market","recv_ts_ns":1768250249774946386,"event_type":"price_change","market":"0x2a12fd3d8235c25c062dc9652970ef9f635636c4018df0909e1a51c673e125cb","server_ts_ms":1768250249344,"raw":{"market":"0x2a12fd3d8235c25c062dc9652970ef9f635636c4018df0909e1a51c673e125cb","price_changes":[{"asset_id":"63670753354844494163057275310194312729998307779831462269530137743341854359908","price":"0.8","size":"314.9","side":"BUY","hash":"f73bbd7742a110bd916e4dc0ab11661962fdad49","best_bid":"0.84","best_ask":"0.85"},{"asset_id":"56386988715176239099720172290594769295756680374928571099138069977179519358166","price":"0.2","size":"314.9","side":"SELL","hash":"a49206cb3929041419570909f45ae5df7606ce11","best_bid":"0.15","best_ask":"0.16"}],"timestamp":"1768250249344","event_type":"price_change"}}
{"schema_version":1,"source":"clob_ws_market","recv_ts_ns":1768250249778703077,"event_type":"price_change","market":"0x2a12fd3d8235c25c062dc9652970ef9f635636c4018df0909e1a51c673e125cb","server_ts_ms":1768250249347,"raw":{"market":"0x2a12fd3d8235c25c062dc9652970ef9f635636c4018df0909e1a51c673e125cb","price_changes":[{"asset_id":"63670753354844494163057275310194312729998307779831462269530137743341854359908","price":"0.87","size":"860.5","side":"SELL","hash":"48421cc09f430eb0fe5a91a2cbd21a9c269c2afa","best_bid":"0.84","best_ask":"0.85"},{"asset_id":"56386988715176239099720172290594769295756680374928571099138069977179519358166","price":"0.13","size":"860.5","side":"BUY","hash":"eae1c194b90618ff55c750916a9d8000d5dd3839","best_bid":"0.15","best_ask":"0.16"}],"timestamp":"1768250249347","event_type":"price_change"}}
{"schema_version":1,"source":"clob_ws_market","recv_ts_ns":1768250249784629840,"event_type":"price_change","market":"0x2a12fd3d8235c25c062dc9652970ef9f635636c4018df0909e1a51c673e125cb","server_ts_ms":1768250249347,"raw":{"market":"0x2a12fd3d8235c25c062dc9652970ef9f635636c4018df0909e1a51c673e125cb","price_changes":[{"asset_id":"63670753354844494163057275310194312729998307779831462269530137743341854359908","price":"0.76","size":"924.85","side":"BUY","hash":"98f79669d63c59aec2d02865cc478268f16fce75","best_bid":"0.84","best_ask":"0.85"},{"asset_id":"56386988715176239099720172290594769295756680374928571099138069977179519358166","price":"0.24","size":"924.85","side":"SELL","hash":"efeda9c5076dfc4bf74dbc96e84bd24206eaf5aa","best_bid":"0.15","best_ask":"0.16"}],"timestamp":"1768250249347","event_type":"price_change"}}
{"schema_version":1,"source":"clob_ws_market","recv_ts_ns":1768250249792059853,"event_type":"price_change","market":"0x2a12fd3d8235c25c062dc9652970ef9f635636c4018df0909e1a51c673e125cb","server_ts_ms":1768250249350,"raw":{"market":"0x2a12fd3d8235c25c062dc9652970ef9f635636c4018df0909e1a51c673e125cb","price_changes":[{"asset_id":"56386988715176239099720172290594769295756680374928571099138069977179519358166","price":"0.15","size":"776.76","side":"BUY","hash":"ceb969732a33929466052321e0f92dc6fbe3e311","best_bid":"0.15","best_ask":"0.16"},{"asset_id":"63670753354844494163057275310194312729998307779831462269530137743341854359908","price":"0.85","size":"776.76","side":"SELL","hash":"174be245b7aa53b325b0fb866d68cffcd1da68e8","best_bid":"0.84","best_ask":"0.85"}],"timestamp":"1768250249350","event_type":"price_change"}}
{"schema_version":1,"source":"clob_ws_market","recv_ts_ns":1768250249795865436,"event_type":"price_change","market":"0x2a12fd3d8235c25c062dc9652970ef9f635636c4018df0909e1a51c673e125cb","server_ts_ms":1768250249351,"raw":{"market":"0x2a12fd3d8235c25c062dc9652970ef9f635636c4018df0909e1a51c673e125cb","price_changes":[{"asset_id":"56386988715176239099720172290594769295756680374928571099138069977179519358166","price":"0.06","size":"1397","side":"BUY","hash":"bb239c84d457cd62ae1e37148458266dda128b16","best_bid":"0.15","best_ask":"0.16"},{"asset_id":"63670753354844494163057275310194312729998307779831462269530137743341854359908","price":"0.94","size":"1397","side":"SELL","hash":"46b9284e550c63e8d0372a9d794f8af2b5419ac6","best_bid":"0.84","best_ask":"0.85"}],"timestamp":"1768250249351","event_type":"price_change"}}
{"schema_version":1,"source":"clob_ws_market","recv_ts_ns":1768250249799715118,"event_type":"price_change","market":"0x2a12fd3d8235c25c062dc9652970ef9f635636c4018df0909e1a51c673e125cb","server_ts_ms":1768250249357,"raw":{"market":"0x2a12fd3d8235c25c062dc9652970ef9f635636c4018df0909e1a51c673e125cb","price_changes":[{"asset_id":"63670753354844494163057275310194312729998307779831462269530137743341854359908","price":"0.81","size":"253.21","side":"BUY","hash":"00717497959df0492c59b770b3dd67bded225332","best_bid":"0.84","best_ask":"0.85"},{"asset_id":"56386988715176239099720172290594769295756680374928571099138069977179519358166","price":"0.19","size":"253.21","side":"SELL","hash":"ba7ae4c43cfcdc579ae667f81cfdc603948a456c","best_bid":"0.15","best_ask":"0.16"}],"timestamp":"1768250249357","event_type":"price_change"}}
{"schema_version":1,"source":"clob_ws_market","recv_ts_ns":1768250249803687048,"event_type":"price_change","market":"0x2a12fd3d8235c25c062dc9652970ef9f635636c4018df0909e1a51c673e125cb","server_ts_ms":1768250249359,"raw":{"market":"0x2a12fd3d8235c25c062dc9652970ef9f635636c4018df0909e1a51c673e125cb","price_changes":[{"asset_id":"56386988715176239099720172290594769295756680374928571099138069977179519358166","price":"0.12","size":"861.75","side":"BUY","hash":"455b40127952720c41271c5c3a75039b3f0a06dc","best_bid":"0.15","best_ask":"0.16"},{"asset_id":"63670753354844494163057275310194312729998307779831462269530137743341854359908","price":"0.88","size":"861.75","side":"SELL","hash":"6171d028bb74f83bc928ed18b474ee7bc674a6eb","best_bid":"0.84","best_ask":"0.85"}],"timestamp":"1768250249359","event_type":"price_change"}}
{"schema_version":1,"source":"clob_ws_market","recv_ts_ns":1768250249816628334,"event_type":"price_change","market":"0x2a12fd3d8235c25c062dc9652970ef9f635636c4018df0909e1a51c673e125cb","server_ts_ms":1768250249366,"raw":{"market":"0x2a12fd3d8235c25c062dc9652970ef9f635636c4018df0909e1a51c673e125cb","price_changes":[{"asset_id":"56386988715176239099720172290594769295756680374928571099138069977179519358166","price":"0.13","size":"870.5","side":"BUY","hash":"126ba57e754f9757d4042ceb0299398059f65358","best_bid":"0.15","best_ask":"0.16"},{"asset_id":"63670753354844494163057275310194312729998307779831462269530137743341854359908","price":"0.87","size":"870.5","side":"SELL","hash":"ccadf76eec651175735dcb9b40a0feb68d7f8fed","best_bid":"0.84","best_ask":"0.85"}],"timestamp":"1768250249366","event_type":"price_change"}}
{"schema_version":1,"source":"clob_ws_market","recv_ts_ns":1768250249822490959,"event_type":"price_change","market":"0x2a12fd3d8235c25c062dc9652970ef9f635636c4018df0909e1a51c673e125cb","server_ts_ms":1768250249367,"raw":{"market":"0x2a12fd3d8235c25c062dc9652970ef9f635636c4018df0909e1a51c673e125cb","price_changes":[{"asset_id":"63670753354844494163057275310194312729998307779831462269530137743341854359908","price":"0.81","size":"263.21","side":"BUY","hash":"0406f0158e79b5bc4a4e2ecdeacb1be8e6b4af4b","best_bid":"0.84","best_ask":"0.85"},{"asset_id":"56386988715176239099720172290594769295756680374928571099138069977179519358166","price":"0.19","size":"263.21","side":"SELL","hash":"47484226421a406203a2e5adc9e2595dc576da88","best_bid":"0.15","best_ask":"0.16"}],"timestamp":"1768250249367","event_type":"price_change"}}
{"schema_version":1,"source":"clob_ws_market","recv_ts_ns":1768250249827403835,"event_type":"price_change","market":"0x2a12fd3d8235c25c062dc9652970ef9f635636c4018df0909e1a51c673e125cb","server_ts_ms":1768250249376,"raw":{"market":"0x2a12fd3d8235c25c062dc9652970ef9f635636c4018df0909e1a51c673e125cb","price_changes":[{"asset_id":"56386988715176239099720172290594769295756680374928571099138069977179519358166","price":"0.13","size":"860.5","side":"BUY","hash":"e05af1a8358abf2ee116a4098eae61c006b75c5e","best_bid":"0.15","best_ask":"0.16"},{"asset_id":"63670753354844494163057275310194312729998307779831462269530137743341854359908","price":"0.87","size":"860.5","side":"SELL","hash":"b0d4dc3bc521650d7890b998d53e9cc9d7da0366","best_bid":"0.84","best_ask":"0.85"}],"timestamp":"1768250249376","event_type":"price_change"}}
{"schema_version":1,"source":"clob_ws_market","recv_ts_ns":1768250249832737005,"event_type":"price_change","market":"0x2a12fd3d8235c25c062dc9652970ef9f635636c4018df0909e1a51c673e125cb","server_ts_ms":1768250249378,"raw":{"market":"0x2a12fd3d8235c25c062dc9652970ef9f635636c4018df0909e1a51c673e125cb","price_changes":[{"asset_id":"63670753354844494163057275310194312729998307779831462269530137743341854359908","price":"0.83","size":"157.02","side":"BUY","hash":"406521628cab866cb34df33d4a604528156283e0","best_bid":"0.84","best_ask":"0.85"},{"asset_id":"56386988715176239099720172290594769295756680374928571099138069977179519358166","price":"0.17","size":"157.02","side":"SELL","hash":"a526376fccb5050596aad21f749629bf401fb0ef","best_bid":"0.15","best_ask":"0.16"}],"timestamp":"1768250249378","event_type":"price_change"}}
{"schema_version":1,"source":"clob_ws_market","recv_ts_ns":1768250249837743623,"event_type":"price_change","market":"0x2a12fd3d8235c25c062dc9652970ef9f635636c4018df0909e1a51c673e125cb","server_ts_ms":1768250249381,"raw":{"market":"0x2a12fd3d8235c25c062dc9652970ef9f635636c4018df0909e1a51c673e125cb","price_changes":[{"asset_id":"63670753354844494163057275310194312729998307779831462269530137743341854359908","price":"0.8","size":"814.9","side":"BUY","hash":"2f87654228eae527d4de8401a8804e0aceb2524b","best_bid":"0.84","best_ask":"0.85"},{"asset_id":"56386988715176239099720172290594769295756680374928571099138069977179519358166","price":"0.2","size":"814.9","side":"SELL","hash":"8910048d3b2ed3d9931149d9d695df56e2bb60e6","best_bid":"0.15","best_ask":"0.16"}],"timestamp":"1768250249381","event_type":"price_change"}}
{"schema_version":1,"source":"clob_ws_market","recv_ts_ns":1768250249842918048,"event_type":"price_change","market":"0x2a12fd3d8235c25c062dc9652970ef9f635636c4018df0909e1a51c673e125cb","server_ts_ms":1768250249386,"raw":{"market":"0x2a12fd3d8235c25c062dc9652970ef9f635636c4018df0909e1a51c673e125cb","price_changes":[{"asset_id":"56386988715176239099720172290594769295756680374928571099138069977179519358166","price":"0.07","size":"1421.28","side":"BUY","hash":"fbd6b83dace9a2eb8e106064ff8059712c1d25d7","best_bid":"0.15","best_ask":"0.16"},{"asset_id":"63670753354844494163057275310194312729998307779831462269530137743341854359908","price":"0.93","size":"1421.28","side":"SELL","hash":"a7eef19476c4fc5a539190fb93a7955823e194b3","best_bid":"0.84","best_ask":"0.85"}],"timestamp":"1768250249386","event_type":"price_change"}}
{"schema_version":1,"source":"clob_ws_market","recv_ts_ns":1768250249847812579,"event_type":"price_change","market":"0x2a12fd3d8235c25c062dc9652970ef9f635636c4018df0909e1a51c673e125cb","server_ts_ms":1768250249387,"raw":{"market":"0x2a12fd3d8235c25c062dc9652970ef9f635636c4018df0909e1a51c673e125cb","price_changes":[{"asset_id":"56386988715176239099720172290594769295756680374928571099138069977179519358166","price":"0.15","size":"796.76","side":"BUY","hash":"25b6e68b4c114a60a5d790b7a2a707aeb0746941","best_bid":"0.15","best_ask":"0.16"},{"asset_id":"63670753354844494163057275310194312729998307779831462269530137743341854359908","price":"0.85","size":"796.76","side":"SELL","hash":"274e4867c571a33e5d313cca388c955cda3aa3e4","best_bid":"0.84","best_ask":"0.85"}],"timestamp":"1768250249387","event_type":"price_change"}}
{"schema_version":1,"source":"clob_ws_market","recv_ts_ns":1768250249852424618,"event_type":"price_change","market":"0x2a12fd3d8235c25c062dc9652970ef9f635636c4018df0909e1a51c673e125cb","server_ts_ms":1768250249387,"raw":{"market":"0x2a12fd3d8235c25c062dc9652970ef9f635636c4018df0909e1a51c673e125cb","price_changes":[{"asset_id":"63670753354844494163057275310194312729998307779831462269530137743341854359908","price":"0.81","size":"273.21","side":"BUY","hash":"3d1dd8050ab5d5e718c9fba7cc129f68c1047411","best_bid":"0.84","best_ask":"0.85"},{"asset_id":"56386988715176239099720172290594769295756680374928571099138069977179519358166","price":"0.19","size":"273.21","side":"SELL","hash":"b6e05e379f9e17619c4f62bf3a366d21b1d3b029","best_bid":"0.15","best_ask":"0.16"}],"timestamp":"1768250249387","event_type":"price_change"}}
{"schema_version":1,"source":"clob_ws_market","recv_ts_ns":1768250249856459062,"event_type":"price_change","market":"0x2a12fd3d8235c25c062dc9652970ef9f635636c4018df0909e1a51c673e125cb","server_ts_ms":1768250249395,"raw":{"market":"0x2a12fd3d8235c25c062dc9652970ef9f635636c4018df0909e1a51c673e125cb","price_changes":[{"asset_id":"56386988715176239099720172290594769295756680374928571099138069977179519358166","price":"0.15","size":"806.76","side":"BUY","hash":"21598ce53561bfabdda3e201d19f334553254793","best_bid":"0.15","best_ask":"0.16"},{"asset_id":"63670753354844494163057275310194312729998307779831462269530137743341854359908","price":"0.85","size":"806.76","side":"SELL","hash":"1e3fc28758bcf9d5081f97fc9d057dee0721c5d3","best_bid":"0.84","best_ask":"0.85"}],"timestamp":"1768250249395","event_type":"price_change"}}
{"schema_version":1,"source":"clob_ws_market","recv_ts_ns":1768250249860517334,"event_type":"price_change","market":"0x2a12fd3d8235c25c062dc9652970ef9f635636c4018df0909e1a51c673e125cb","server_ts_ms":1768250249412,"raw":{"market":"0x2a12fd3d8235c25c062dc9652970ef9f635636c4018df0909e1a51c673e125cb","price_changes":[{"asset_id":"63670753354844494163057275310194312729998307779831462269530137743341854359908","price":"0.8","size":"314.9","side":"BUY","hash":"2f6c745e24a8d85047cdfc31e4624f0746ed8db5","best_bid":"0.84","best_ask":"0.85"},{"asset_id":"56386988715176239099720172290594769295756680374928571099138069977179519358166","price":"0.2","size":"314.9","side":"SELL","hash":"7be4eb54cb4e8f1736b7bb06fdf658953089f30a","best_bid":"0.15","best_ask":"0.16"}],"timestamp":"1768250249412","event_type":"price_change"}}
{"schema_version":1,"source":"clob_ws_market","recv_ts_ns":1768250249866957277,"event_type":"price_change","market":"0x2a12fd3d8235c25c062dc9652970ef9f635636c4018df0909e1a51c673e125cb","server_ts_ms":1768250249444,"raw":{"market":"0x2a12fd3d8235c25c062dc9652970ef9f635636c4018df0909e1a51c673e125cb","price_changes":[{"asset_id":"56386988715176239099720172290594769295756680374928571099138069977179519358166","price":"0.13","size":"870.5","side":"BUY","hash":"cb603464f916fd1297ee3a57fa84e490276c8f71","best_bid":"0.15","best_ask":"0.16"},{"asset_id":"63670753354844494163057275310194312729998307779831462269530137743341854359908","price":"0.87","size":"870.5","side":"SELL","hash":"361fd533fc126a7cdce12fed734cb54c129a68ce","best_bid":"0.84","best_ask":"0.85"}],"timestamp":"1768250249444","event_type":"price_change"}}
{"schema_version":1,"source":"clob_ws_market","recv_ts_ns":1768250249871623892,"event_type":"price_change","market":"0x2a12fd3d8235c25c062dc9652970ef9f635636c4018df0909e1a51c673e125cb","server_ts_ms":1768250249447,"raw":{"market":"0x2a12fd3d8235c25c062dc9652970ef9f635636c4018df0909e1a51c673e125cb","price_changes":[{"asset_id":"63670753354844494163057275310194312729998307779831462269530137743341854359908","price":"0.8","size":"239.9","side":"BUY","hash":"b7fcf1784462ae6b60c3bb8ac210beca616b2dc6","best_bid":"0.84","best_ask":"0.85"},{"asset_id":"56386988715176239099720172290594769295756680374928571099138069977179519358166","price":"0.2","size":"239.9","side":"SELL","hash":"e2e30aecc6b6f49e89f1aa688cf70d5f851b0a7c","best_bid":"0.15","best_ask":"0.16"}],"timestamp":"1768250249447","event_type":"price_change"}}
{"schema_version":1,"source":"clob_ws_market","recv_ts_ns":1768250249875192261,"event_type":"price_change","market":"0x2a12fd3d8235c25c062dc9652970ef9f635636c4018df0909e1a51c673e125cb","server_ts_ms":1768250249447,"raw":{"market":"0x2a12fd3d8235c25c062dc9652970ef9f635636c4018df0909e1a51c673e125cb","price_changes":[{"asset_id":"63670753354844494163057275310194312729998307779831462269530137743341854359908","price":"0.79","size":"733.5","side":"BUY","hash":"b7fcf1784462ae6b60c3bb8ac210beca616b2dc6","best_bid":"0.84","best_ask":"0.85"},{"asset_id":"56386988715176239099720172290594769295756680374928571099138069977179519358166","price":"0.21","size":"733.5","side":"SELL","hash":"e2e30aecc6b6f49e89f1aa688cf70d5f851b0a7c","best_bid":"0.15","best_ask":"0.16"}],"timestamp":"1768250249447","event_type":"price_change"}}
{"schema_version":1,"source":"clob_ws_market","recv_ts_ns":1768250249879507175,"event_type":"price_change","market":"0x2a12fd3d8235c25c062dc9652970ef9f635636c4018df0909e1a51c673e125cb","server_ts_ms":1768250249455,"raw":{"market":"0x2a12fd3d8235c25c062dc9652970ef9f635636c4018df0909e1a51c673e125cb","price_changes":[{"asset_id":"56386988715176239099720172290594769295756680374928571099138069977179519358166","price":"0.15","size":"796.76","side":"BUY","hash":"a013358d8b1d7608a6a16701422b623ee38070af","best_bid":"0.15","best_ask":"0.16"},{"asset_id":"63670753354844494163057275310194312729998307779831462269530137743341854359908","price":"0.85","size":"796.76","side":"SELL","hash":"cc74cb7c6e4827a7695f5690c0b84168ce069ffa","best_bid":"0.84","best_ask":"0.85"}],"timestamp":"1768250249455","event_type":"price_change"}}
{"schema_version":1,"source":"clob_ws_market","recv_ts_ns":1768250249883589078,"event_type":"price_change","market":"0x2a12fd3d8235c25c062dc9652970ef9f635636c4018df0909e1a51c673e125cb","server_ts_ms":1768250249456,"raw":{"market":"0x2a12fd3d8235c25c062dc9652970ef9f635636c4018df0909e1a51c673e125cb","price_changes":[{"asset_id":"56386988715176239099720172290594769295756680374928571099138069977179519358166","price":"0.15","size":"811.76","side":"BUY","hash":"fbc6b818891535ae85a2820fd427ae3f83a0858d","best_bid":"0.15","best_ask":"0.16"},{"asset_id":"63670753354844494163057275310194312729998307779831462269530137743341854359908","price":"0.85","size":"811.76","side":"SELL","hash":"1778c3cf1579bd42647e922422282535138f7a50","best_bid":"0.84","best_ask":"0.85"}],"timestamp":"1768250249456","event_type":"price_change"}}
{"schema_version":1,"source":"clob_ws_market","recv_ts_ns":1768250249903703293,"event_type":"price_change","market":"0x2a12fd3d8235c25c062dc9652970ef9f635636c4018df0909e1a51c673e125cb","server_ts_ms":1768250249565,"raw":{"market":"0x2a12fd3d8235c25c062dc9652970ef9f635636c4018df0909e1a51c673e125cb","price_changes":[{"asset_id":"63670753354844494163057275310194312729998307779831462269530137743341854359908","price":"0.79","size":"823.5","side":"BUY","hash":"c7cfe6a0cc21debde3457bcec1ca9a1cff1c71e0","best_bid":"0.84","best_ask":"0.85"},{"asset_id":"56386988715176239099720172290594769295756680374928571099138069977179519358166","price":"0.21","size":"823.5","side":"SELL","hash":"11e25a51b657b3e767db4477829d9468b11976e7","best_bid":"0.15","best_ask":"0.16"}],"timestamp":"1768250249565","event_type":"price_change"}}
{"schema_version":1,"source":"clob_ws_market","recv_ts_ns":1768250249911048943,"event_type":"price_change","market":"0x2a12fd3d8235c25c062dc9652970ef9f635636c4018df0909e1a51c673e125cb","server_ts_ms":1768250249598,"raw":{"market":"0x2a12fd3d8235c25c062dc9652970ef9f635636c4018df0909e1a51c673e125cb","price_changes":[{"asset_id":"56386988715176239099720172290594769295756680374928571099138069977179519358166","price":"0.14","size":"876.79","side":"BUY","hash":"041777f8cb29d91dc8cf73c89c4652e22957fbaa","best_bid":"0.15","best_ask":"0.16"},{"asset_id":"63670753354844494163057275310194312729998307779831462269530137743341854359908","price":"0.86","size":"876.79","side":"SELL","hash":"85e430072ccd881a0e5c0f0cde1a9c1726e57a6a","best_bid":"0.84","best_ask":"0.85"}],"timestamp":"1768250249598","event_type":"price_change"}}
{"schema_version":1,"source":"clob_ws_market","recv_ts_ns":1768250249914219006,"event_type":"best_bid_ask","market":"0x2a12fd3d8235c25c062dc9652970ef9f635636c4018df0909e1a51c673e125cb","server_ts_ms":1768250249613,"raw":{"market":"0x2a12fd3d8235c25c062dc9652970ef9f635636c4018df0909e1a51c673e125cb","asset_id":"56386988715176239099720172290594769295756680374928571099138069977179519358166","best_bid":"0.15","best_ask":"0.17","spread":"0.02","timestamp":"1768250249613","event_type":"best_bid_ask"}}
{"schema_version":1,"source":"clob_ws_market","recv_ts_ns":1768250249917558196,"event_type":"price_change","market":"0x2a12fd3d8235c25c062dc9652970ef9f635636c4018df0909e1a51c673e125cb","server_ts_ms":1768250249612,"raw":{"market":"0x2a12fd3d8235c25c062dc9652970ef9f635636c4018df0909e1a51c673e125cb","price_changes":[{"asset_id":"63670753354844494163057275310194312729998307779831462269530137743341854359908","price":"0.84","size":"0","side":"BUY","hash":"45d9098dba4c253307914a14c9aa8daabc36845d","best_bid":"0.83","best_ask":"0.85"},{"asset_id":"56386988715176239099720172290594769295756680374928571099138069977179519358166","price":"0.16","size":"0","side":"SELL","hash":"c241185880f39895fb04bb39774d7dfcab734fb7","best_bid":"0.15","best_ask":"0.17"}],"timestamp":"1768250249612","event_type":"price_change"}}
{"schema_version":1,"source":"clob_ws_market","recv_ts_ns":1768250249920808680,"event_type":"price_change","market":"0x2a12fd3d8235c25c062dc9652970ef9f635636c4018df0909e1a51c673e125cb","server_ts_ms":1768250249620,"raw":{"market":"0x2a12fd3d8235c25c062dc9652970ef9f635636c4018df0909e1a51c673e125cb","price_changes":[{"asset_id":"63670753354844494163057275310194312729998307779831462269530137743341854359908","price":"0.77","size":"587.5","side":"BUY","hash":"e98a0b61ecc5f5bb40bfeb98e4ea351b9c20a78f","best_bid":"0.83","best_ask":"0.85"},{"asset_id":"56386988715176239099720172290594769295756680374928571099138069977179519358166","price":"0.23","size":"587.5","side":"SELL","hash":"36cfd41bcf7059823fb80cb6e59b0a04da2ea63c","best_bid":"0.15","best_ask":"0.17"}],"timestamp":"1768250249620","event_type":"price_change"}}
{"schema_version":1,"source":"clob_ws_market","recv_ts_ns":1768250249925236198,"event_type":"price_change","market":"0x2a12fd3d8235c25c062dc9652970ef9f635636c4018df0909e1a51c673e125cb","server_ts_ms":1768250249620,"raw":{"market":"0x2a12fd3d8235c25c062dc9652970ef9f635636c4018df0909e1a51c673e125cb","price_changes":[{"asset_id":"63670753354844494163057275310194312729998307779831462269530137743341854359908","price":"0.78","size":"738.5","side":"BUY","hash":"e98a0b61ecc5f5bb40bfeb98e4ea351b9c20a78f","best_bid":"0.83","best_ask":"0.85"},{"asset_id":"56386988715176239099720172290594769295756680374928571099138069977179519358166","price":"0.22","size":"738.5","side":"SELL","hash":"36cfd41bcf7059823fb80cb6e59b0a04da2ea63c","best_bid":"0.15","best_ask":"0.17"}],"timestamp":"1768250249620","event_type":"price_change"}}
{"schema_version":1,"source":"clob_ws_market","recv_ts_ns":1768250249928893038,"event_type":"best_bid_ask","market":"0x2a12fd3d8235c25c062dc9652970ef9f635636c4018df0909e1a51c673e125cb","server_ts_ms":1768250249622,"raw":{"market":"0x2a12fd3d8235c25c062dc9652970ef9f635636c4018df0909e1a51c673e125cb","asset_id":"56386988715176239099720172290594769295756680374928571099138069977179519358166","best_bid":"0.16","best_ask":"0.17","spread":"0.01","timestamp":"1768250249622","event_type":"best_bid_ask"}}
{"schema_version":1,"source":"clob_ws_market","recv_ts_ns":1768250249933185652,"event_type":"price_change","market":"0x2a12fd3d8235c25c062dc9652970ef9f635636c4018df0909e1a51c673e125cb","server_ts_ms":1768250249621,"raw":{"market":"0x2a12fd3d8235c25c062dc9652970ef9f635636c4018df0909e1a51c673e125cb","price_changes":[{"asset_id":"56386988715176239099720172290594769295756680374928571099138069977179519358166","price":"0.16","size":"10","side":"BUY","hash":"7144cdea30f80e1ac5a3347f38b6017570ced1b6","best_bid":"0.16","best_ask":"0.17"},{"asset_id":"63670753354844494163057275310194312729998307779831462269530137743341854359908","price":"0.84","size":"10","side":"SELL","hash":"41d65337888e7331d31edc3395776d221df0b604","best_bid":"0.83","best_ask":"0.84"}],"timestamp":"1768250249621","event_type":"price_change"}}
{"schema_version":1,"source":"clob_ws_market","recv_ts_ns":1768250249937113955,"event_type":"price_change","market":"0x2a12fd3d8235c25c062dc9652970ef9f635636c4018df0909e1a51c673e125cb","server_ts_ms":1768250249624,"raw":{"market":"0x2a12fd3d8235c25c062dc9652970ef9f635636c4018df0909e1a51c673e125cb","price_changes":[{"asset_id":"63670753354844494163057275310194312729998307779831462269530137743341854359908","price":"0.82","size":"86.5","side":"BUY","hash":"f65e0df4c90ae1d185c9e43fb28b586f3aabc8b8","best_bid":"0.83","best_ask":"0.84"},{"asset_id":"56386988715176239099720172290594769295756680374928571099138069977179519358166","price":"0.18","size":"86.5","side":"SELL","hash":"b1cb01cfe47e85cf0acc60ecf32be28a907057fe","best_bid":"0.16","best_ask":"0.17"}],"timestamp":"1768250249624","event_type":"price_change"}}
{"schema_version":1,"source":"clob_ws_market","recv_ts_ns":1768250249941443559,"event_type":"price_change","market":"0x2a12fd3d8235c25c062dc9652970ef9f635636c4018df0909e1a51c673e125cb","server_ts_ms":1768250249624,"raw":{"market":"0x2a12fd3d8235c25c062dc9652970ef9f635636c4018df0909e1a51c673e125cb","price_changes":[{"asset_id":"63670753354844494163057275310194312729998307779831462269530137743341854359908","price":"0.83","size":"6.02","side":"BUY","hash":"f65e0df4c90ae1d185c9e43fb28b586f3aabc8b8","best_bid":"0.83","best_ask":"0.84"},{"asset_id":"56386988715176239099720172290594769295756680374928571099138069977179519358166","price":"0.17","size":"6.02","side":"SELL","hash":"b1cb01cfe47e85cf0acc60ecf32be28a907057fe","best_bid":"0.16","best_ask":"0.17"}],"timestamp":"1768250249624","event_type":"price_change"}}
{"schema_version":1,"source":"clob_ws_market","recv_ts_ns":1768250249945496754,"event_type":"price_change","market":"0x2a12fd3d8235c25c062dc9652970ef9f635636c4018df0909e1a51c673e125cb","server_ts_ms":1768250249625,"raw":{"market":"0x2a12fd3d8235c25c062dc9652970ef9f635636c4018df0909e1a51c673e125cb","price_changes":[{"asset_id":"56386988715176239099720172290594769295756680374928571099138069977179519358166","price":"0.16","size":"20","side":"BUY","hash":"bf0333fe4af2fd7ce692a613b15efbd29dd73efb","best_bid":"0.16","best_ask":"0.17"},{"asset_id":"63670753354844494163057275310194312729998307779831462269530137743341854359908","price":"0.84","size":"20","side":"SELL","hash":"8ace82bda7b4b832ce6901df376fd77ab346825c","best_bid":"0.83","best_ask":"0.84"}],"timestamp":"1768250249625","event_type":"price_change"}}
{"schema_version":1,"source":"clob_ws_market","recv_ts_ns":1768250249949144073,"event_type":"price_change","market":"0x2a12fd3d8235c25c062dc9652970ef9f635636c4018df0909e1a51c673e125cb","server_ts_ms":1768250249638,"raw":{"market":"0x2a12fd3d8235c25c062dc9652970ef9f635636c4018df0909e1a51c673e125cb","price_changes":[{"asset_id":"63670753354844494163057275310194312729998307779831462269530137743341854359908","price":"0.85","size":"806.26","side":"SELL","hash":"7edfcb7b3173b651a3305eb31a25afa47fe4f4b0","best_bid":"0.83","best_ask":"0.84"},{"asset_id":"56386988715176239099720172290594769295756680374928571099138069977179519358166","price":"0.15","size":"806.26","side":"BUY","hash":"a510e2fcbaec55d247573f809340f968c78f2af8","best_bid":"0.16","best_ask":"0.17"}],"timestamp":"1768250249638","event_type":"price_change"}}
{"schema_version":1,"source":"clob_ws_market","recv_ts_ns":1768250249951805638,"event_type":"price_change","market":"0x2a12fd3d8235c25c062dc9652970ef9f635636c4018df0909e1a51c673e125cb","server_ts_ms":1768250249639,"raw":{"market":"0x2a12fd3d8235c25c062dc9652970ef9f635636c4018df0909e1a51c673e125cb","price_changes":[{"asset_id":"63670753354844494163057275310194312729998307779831462269530137743341854359908","price":"0.85","size":"800.76","side":"SELL","hash":"f408d738c812cf2ed53e019813305751a27a83b9","best_bid":"0.83","best_ask":"0.84"},{"asset_id":"56386988715176239099720172290594769295756680374928571099138069977179519358166","price":"0.15","size":"800.76","side":"BUY","hash":"318f5db1e9ffbda07f805e4719088c3840a94f04","best_bid":"0.16","best_ask":"0.17"}],"timestamp":"1768250249639","event_type":"price_change"}}
{"schema_version":1,"source":"clob_ws_market","recv_ts_ns":1768250249954253114,"event_type":"price_change","market":"0x2a12fd3d8235c25c062dc9652970ef9f635636c4018df0909e1a51c673e125cb","server_ts_ms":1768250249639,"raw":{"market":"0x2a12fd3d8235c25c062dc9652970ef9f635636c4018df0909e1a51c673e125cb","price_changes":[{"asset_id":"56386988715176239099720172290594769295756680374928571099138069977179519358166","price":"0.15","size":"795.26","side":"BUY","hash":"3c10add95169d316d209e3a72357510f33dad650","best_bid":"0.16","best_ask":"0.17"},{"asset_id":"63670753354844494163057275310194312729998307779831462269530137743341854359908","price":"0.85","size":"795.26","side":"SELL","hash":"d6332e9e7c3b2231c5f3cb633f01eec753c47cea","best_bid":"0.83","best_ask":"0.84"}],"timestamp":"1768250249639","event_type":"price_change"}}
{"schema_version":1,"source":"clob_ws_market","recv_ts_ns":1768250249959849986,"event_type":"price_change","market":"0x2a12fd3d8235c25c062dc9652970ef9f635636c4018df0909e1a51c673e125cb","server_ts_ms":1768250249640,"raw":{"market":"0x2a12fd3d8235c25c062dc9652970ef9f635636c4018df0909e1a51c673e125cb","price_changes":[{"asset_id":"63670753354844494163057275310194312729998307779831462269530137743341854359908","price":"0.85","size":"789.76","side":"SELL","hash":"7f7a3319a81ffd956398cbe7da0ee2f275798934","best_bid":"0.83","best_ask":"0.84"},{"asset_id":"56386988715176239099720172290594769295756680374928571099138069977179519358166","price":"0.15","size":"789.76","side":"BUY","hash":"3f6fc6a3331c8d2eb57efe12b10eb8c4173b0e23","best_bid":"0.16","best_ask":"0.17"}],"timestamp":"1768250249640","event_type":"price_change"}}
{"schema_version":1,"source":"clob_ws_market","recv_ts_ns":1768250249962725552,"event_type":"price_change","market":"0x2a12fd3d8235c25c062dc9652970ef9f635636c4018df0909e1a51c673e125cb","server_ts_ms":1768250249641,"raw":{"market":"0x2a12fd3d8235c25c062dc9652970ef9f635636c4018df0909e1a51c673e125cb","price_changes":[{"asset_id":"63670753354844494163057275310194312729998307779831462269530137743341854359908","price":"0.85","size":"784.26","side":"SELL","hash":"fc369ef0fb18704c88a24b809c1fce6c76a547c9","best_bid":"0.83","best_ask":"0.84"},{"asset_id":"56386988715176239099720172290594769295756680374928571099138069977179519358166","price":"0.15","size":"784.26","side":"BUY","hash":"111eca61b9552b79f1ae3d5e3eba8b80c98fc3ce","best_bid":"0.16","best_ask":"0.17"}],"timestamp":"1768250249641","event_type":"price_change"}}
{"schema_version":1,"source":"clob_ws_market","recv_ts_ns":1768250249965359756,"event_type":"price_change","market":"0x2a12fd3d8235c25c062dc9652970ef9f635636c4018df0909e1a51c673e125cb","server_ts_ms":1768250249642,"raw":{"market":"0x2a12fd3d8235c25c062dc9652970ef9f635636c4018df0909e1a51c673e125cb","price_changes":[{"asset_id":"56386988715176239099720172290594769295756680374928571099138069977179519358166","price":"0.15","size":"874.26","side":"BUY","hash":"3beb481622ef247a12650c7832c504a5f4e5f091","best_bid":"0.16","best_ask":"0.17"},{"asset_id":"63670753354844494163057275310194312729998307779831462269530137743341854359908","price":"0.85","size":"874.26","side":"SELL","hash":"abf53db7b3dc3fba3023ced04f15f9a5dadf2e39","best_bid":"0.83","best_ask":"0.84"}],"timestamp":"1768250249642","event_type":"price_change"}}
{"schema_version":1,"source":"clob_ws_market","recv_ts_ns":1768250249968062728,"event_type":"price_change","market":"0x2a12fd3d8235c25c062dc9652970ef9f635636c4018df0909e1a51c673e125cb","server_ts_ms":1768250249645,"raw":{"market":"0x2a12fd3d8235c25c062dc9652970ef9f635636c4018df0909e1a51c673e125cb","price_changes":[{"asset_id":"56386988715176239099720172290594769295756680374928571099138069977179519358166","price":"0.16","size":"27.5","side":"BUY","hash":"469acab817ed0adabc244420177299f88652cc58","best_bid":"0.16","best_ask":"0.17"},{"asset_id":"63670753354844494163057275310194312729998307779831462269530137743341854359908","price":"0.84","size":"27.5","side":"SELL","hash":"29ad8dba7454c1f983d4524e1e4e85fbdad604b0","best_bid":"0.83","best_ask":"0.84"}],"timestamp":"1768250249645","event_type":"price_change"}}
{"schema_version":1,"source":"clob_ws_market","recv_ts_ns":1768250249970693277,"event_type":"price_change","market":"0x2a12fd3d8235c25c062dc9652970ef9f635636c4018df0909e1a51c673e125cb","server_ts_ms":1768250249646,"raw":{"market":"0x2a12fd3d8235c25c062dc9652970ef9f635636c4018df0909e1a51c673e125cb","price_changes":[{"asset_id":"63670753354844494163057275310194312729998307779831462269530137743341854359908","price":"0.84","size":"35","side":"SELL","hash":"b9adce923c9c109a3715e62cb97128aea4797d28","best_bid":"0.83","best_ask":"0.84"},{"asset_id":"56386988715176239099720172290594769295756680374928571099138069977179519358166","price":"0.16","size":"35","side":"BUY","hash":"8637abe325791c632f8e030a17ebba01153127df","best_bid":"0.16","best_ask":"0.17"}],"timestamp":"1768250249646","event_type":"price_change"}}
{"schema_version":1,"source":"clob_ws_market","recv_ts_ns":1768250249973337808,"event_type":"price_change","market":"0x2a12fd3d8235c25c062dc9652970ef9f635636c4018df0909e1a51c673e125cb","server_ts_ms":1768250249650,"raw":{"market":"0x2a12fd3d8235c25c062dc9652970ef9f635636c4018df0909e1a51c673e125cb","price_changes":[{"asset_id":"56386988715176239099720172290594769295756680374928571099138069977179519358166","price":"0.15","size":"866.76","side":"BUY","hash":"fcc40854b80f28dda1aa22a09661f5fb1f1694d5","best_bid":"0.16","best_ask":"0.17"},{"asset_id":"63670753354844494163057275310194312729998307779831462269530137743341854359908","price":"0.85","size":"866.76","side":"SELL","hash":"67debf0f2e221315f987cac7451d2070c7efc43c","best_bid":"0.83","best_ask":"0.84"}],"timestamp":"1768250249650","event_type":"price_change"}}
