{"schema_version":1,"source":"clob_ws_market","recv_ts_ns":1768250238651647401,"event_type":"book","market":"0xe51aa24ab1bbfefce466d642ad98587d13123e4ef95ec9aa73b712e775d4cbba","server_ts_ms":1768250238615,"raw":{"market":"0xe51aa24ab1bbfefce466d642ad98587d13123e4ef95ec9aa73b712e775d4cbba","asset_id":"54232589582260339592359130012520874109228367674780084862642636038394766871668","bids":[{"price":"0.01","size":"21023.9"},{"price":"0.02","size":"6546.25"},{"price":"0.03","size":"2128.6"},{"price":"0.04","size":"506.13"},{"price":"0.05","size":"1324.24"}],"asks":[{"price":"0.99","size":"24290.24"},{"price":"0.98","size":"7594.51"},{"price":"0.97","size":"5964.69"},{"price":"0.96","size":"5411.4"},{"price":"0.95","size":"5356.39"},{"price":"0.94","size":"5328"},{"price":"0.93","size":"5039.28"},{"price":"0.92","size":"5022.7"},{"price":"0.91","size":"5320.9"},{"price":"0.9","size":"5158.44"},{"price":"0.89","size":"18.3"},{"price":"0.88","size":"30.3"},{"price":"0.87","size":"16.5"},{"price":"0.86","size":"15.8"},{"price":"0.85","size":"104.19"},{"price":"0.84","size":"24.69"},{"price":"0.83","size":"14.19"},{"price":"0.82","size":"13.8"},{"price":"0.81","size":"13.4"},{"price":"0.8","size":"38.1"},{"price":"0.79","size":"12.8"},{"price":"0.78","size":"12.6"},{"price":"0.77","size":"12.3"},{"price":"0.76","size":"22.1"},{"price":"0.75","size":"16.9"},{"price":"0.74","size":"21.8"},{"price":"0.73","size":"11.6"},{"price":"0.72","size":"11.4"},{"price":"0.71","size":"61.3"},{"price":"0.7","size":"26.2"},{"price":"0.69","size":"11.1"},{"price":"0.68","size":"11"},{"price":"0.67","size":"110.9"},{"price":"0.66","size":"10.8"},{"price":"0.65","size":"15.7"},{"price":"0.64","size":"10.6"},{"price":"0.63","size":"10.6"},{"price":"0.62","size":"22.5"},{"price":"0.61","size":"10.5"},{"price":"0.6","size":"45.4"},{"price":"0.59","size":"311.4"},{"price":"0.58","size":"820.82"},{"price":"0.57","size":"826.3"},{"price":"0.56","size":"1062.3"},{"price":"0.55","size":"582.3"},{"price":"0.54","size":"626.2"},{"price":"0.53","size":"562.2"},{"price":"0.52","size":"567.2"},{"price":"0.51","size":"573.2"},{"price":"0.5","size":"917.2"},{"price":"0.49","size":"591.2"},{"price":"0.48","size":"596.2"},{"price":"0.47","size":"567.2"},{"price":"0.46","size":"636.61"},{"price":"0.45","size":"362.97"},{"price":"0.44","size":"341.3"},{"price":"0.43","size":"320.62"},{"price":"0.42","size":"567.3"},{"price":"0.41","size":"562.4"},{"price":"0.4","size":"693.02"},{"price":"0.39","size":"593.5"},{"price":"0.38","size":"636.5"},{"price":"0.37","size":"672.32"},{"price":"0.36","size":"680.6"},{"price":"0.35","size":"536.14"},{"price":"0.34","size":"602.8"},{"price":"0.33","size":"572.9"},{"price":"0.32","size":"573"},{"price":"0.31","size":"595.1"},{"price":"0.3","size":"603.2"},{"price":"0.29","size":"1318.72"},{"price":"0.28","size":"1043.04"},{"price":"0.27","size":"663.6"},{"price":"0.26","size":"911.17"},{"price":"0.25","size":"694.3"},{"price":"0.24","size":"717.6"},{"price":"0.23","size":"1183.3"},{"price":"0.22","size":"1526.53"},{"price":"0.21","size":"1178.8"},{"price":"0.2","size":"1445.08"},{"price":"0.19","size":"1229.8"},{"price":"0.18","size":"1467.57"},{"price":"0.17","size":"1520.51"},{"price":"0.16","size":"1967.49"},{"price":"0.15","size":"1810.78"},{"price":"0.14","size":"1506.7"},{"price":"0.13","size":"1588.93"},{"price":"0.12","size":"2555.4"},{"price":"0.11","size":"1792.8"},{"price":"0.1","size":"3402.27"},{"price":"0.09","size":"3012.44"},{"price":"0.08","size":"2724.36"},{"price":"0.07","size":"1556.82"},{"price":"0.06","size":"1413.4"}],"hash":"218016664aa91cb5b5785e55d9d3d03c8f46d94b","timestamp":"1768250238615","event_type":"book"}}
{"schema_version":1,"source":"clob_ws_market","recv_ts_ns":1768250238661453313,"event_type":"price_change","market":"0xe51aa24ab1bbfefce466d642ad98587d13123e4ef95ec9aa73b712e775d4cbba","server_ts_ms":1768250238617,"raw":{"market":"0xe51aa24ab1bbfefce466d642ad98587d13123e4ef95ec9aa73b712e775d4cbba","price_changes":[{"asset_id":"96886111393998001968863279421729456597655847484197549086072988901191634450924","price":"0.94","size":"1397.4","side":"BUY","hash":"6467ceddc662b98d8097ab4edcfb2f20089585a3","best_bid":"0.94","best_ask":"0.95"},{"asset_id":"54232589582260339592359130012520874109228367674780084862642636038394766871668","price":"0.06","size":"1397.4","side":"SELL","hash":"13a819a744f5931070697b62b458b37172db89c8","best_bid":"0.05","best_ask":"0.06"}],"timestamp":"1768250238617","event_type":"price_change"}}
{"schema_version":1,"source":"clob_ws_market","recv_ts_ns":1768250238672838721,"event_type":"price_change","market":"0xe51aa24ab1bbfefce466d642ad98587d13123e4ef95ec9aa73b712e775d4cbba","server_ts_ms":1768250238652,"raw":{"market":"0xe51aa24ab1bbfefce466d642ad98587d13123e4ef95ec9aa73b712e775d4cbba","price_changes":[{"asset_id":"54232589582260339592359130012520874109228367674780084862642636038394766871668","price":"0.02","size":"6562.25","side":"BUY","hash":"71560eef3df23be48bdb84f06b825697678b051a","best_bid":"0.05","best_ask":"0.06"},{"asset_id":"96886111393998001968863279421729456597655847484197549086072988901191634450924","price":"0.98","size":"6562.25","side":"SELL","hash":"3c8b3084942e7fdfbb1f0d7d1bc7581158beb16b","best_bid":"0.94","best_ask":"0.95"}],"timestamp":"1768250238652","event_type":"price_change"}}
{"schema_version":1,"source":"clob_ws_market","recv_ts_ns":1768250238676128380,"event_type":"price_change","market":"0xe51aa24ab1bbfefce466d642ad98587d13123e4ef95ec9aa73b712e775d4cbba","server_ts_ms":1768250238654,"raw":{"market":"0xe51aa24ab1bbfefce466d642ad98587d13123e4ef95ec9aa73b712e775d4cbba","price_changes":[{"asset_id":"96886111393998001968863279421729456597655847484197549086072988901191634450924","price":"0.94","size":"1416.4","side":"BUY","hash":"2343a4664a8d786c546c8e86bf471733ad08c247","best_bid":"0.94","best_ask":"0.95"},{"asset_id":"54232589582260339592359130012520874109228367674780084862642636038394766871668","price":"0.06","size":"1416.4","side":"SELL","hash":"86271a45b186de39d124b0c12aa4c99bd4b6e2a1","best_bid":"0.05","best_ask":"0.06"}],"timestamp":"1768250238654","event_type":"price_change"}}
{"schema_version":1,"source":"clob_ws_market","recv_ts_ns":1768250238697379129,"event_type":"price_change","market":"0xe51aa24ab1bbfefce466d642ad98587d13123e4ef95ec9aa73b712e775d4cbba","server_ts_ms":1768250238676,"raw":{"market":"0xe51aa24ab1bbfefce466d642ad98587d13123e4ef95ec9aa73b712e775d4cbba","price_changes":[{"asset_id":"96886111393998001968863279421729456597655847484197549086072988901191634450924","price":"0.93","size":"1572.82","side":"BUY","hash":"92e4f1b80857708fdd9dc2ec263bb08db1f9b237","best_bid":"0.94","best_ask":"0.95"},{"asset_id":"54232589582260339592359130012520874109228367674780084862642636038394766871668","price":"0.07","size":"1572.82","side":"SELL","hash":"fc9dc2b029248605a7c6eb6b016bda4114c2b572","best_bid":"0.05","best_ask":"0.06"}],"timestamp":"1768250238676","event_type":"price_change"}}
{"schema_version":1,"source":"clob_ws_market","recv_ts_ns":1768250238714210901,"event_type":"price_change","market":"0xe51aa24ab1bbfefce466d642ad98587d13123e4ef95ec9aa73b712e775d4cbba","server_ts_ms":1768250238691,"raw":{"market":"0xe51aa24ab1bbfefce466d642ad98587d13123e4ef95ec9aa73b712e775d4cbba","price_changes":[{"asset_id":"96886111393998001968863279421729456597655847484197549086072988901191634450924","price":"0.94","size":"1404.4","side":"BUY","hash":"43f8b8670fb725b26273fd8324595a318596113d","best_bid":"0.94","best_ask":"0.95"},{"asset_id":"54232589582260339592359130012520874109228367674780084862642636038394766871668","price":"0.06","size":"1404.4","side":"SELL","hash":"65458dd0bd3391f41255f0114eb9a8ee5bbbe083","best_bid":"0.05","best_ask":"0.06"}],"timestamp":"1768250238691","event_type":"price_change"}}
{"schema_version":1,"source":"clob_ws_market","recv_ts_ns":1768250238719717754,"event_type":"price_change","market":"0xe51aa24ab1bbfefce466d642ad98587d13123e4ef95ec9aa73b712e775d4cbba","server_ts_ms":1768250238697,"raw":{"market":"0xe51aa24ab1bbfefce466d642ad98587d13123e4ef95ec9aa73b712e775d4cbba","price_changes":[{"asset_id":"96886111393998001968863279421729456597655847484197549086072988901191634450924","price":"0.94","size":"1388.4","side":"BUY","hash":"7685f33a2a73dc1c8adea35a69edc73aff4f684b","best_bid":"0.94","best_ask":"0.95"},{"asset_id":"54232589582260339592359130012520874109228367674780084862642636038394766871668","price":"0.06","size":"1388.4","side":"SELL","hash":"09d006b1d3f5fc22efae9ceb2ffcb8e360b533c4","best_bid":"0.05","best_ask":"0.06"}],"timestamp":"1768250238697","event_type":"price_change"}}
{"schema_version":1,"source":"clob_ws_market","recv_ts_ns":1768250238723954435,"event_type":"price_change","market":"0xe51aa24ab1bbfefce466d642ad98587d13123e4ef95ec9aa73b712e775d4cbba","server_ts_ms":1768250238698,"raw":{"market":"0xe51aa24ab1bbfefce466d642ad98587d13123e4ef95ec9aa73b712e775d4cbba","price_changes":[{"asset_id":"96886111393998001968863279421729456597655847484197549086072988901191634450924","price":"0.94","size":"1372.4","side":"BUY","hash":"2b44fdb2876d878aae7f7901337672cbee5b91f9","best_bid":"0.94","best_ask":"0.95"},{"asset_id":"54232589582260339592359130012520874109228367674780084862642636038394766871668","price":"0.06","size":"1372.4","side":"SELL","hash":"035ed27b9f4e657fc2f523f0b695c62255715ea7","best_bid":"0.05","best_ask":"0.06"}],"timestamp":"1768250238698","event_type":"price_change"}}
{"schema_version":1,"source":"clob_ws_market","recv_ts_ns":1768250238728507115,"event_type":"price_change","market":"0xe51aa24ab1bbfefce466d642ad98587d13123e4ef95ec9aa73b712e775d4cbba","server_ts_ms":1768250238700,"raw":{"market":"0xe51aa24ab1bbfefce466d642ad98587d13123e4ef95ec9aa73b712e775d4cbba","price_changes":[{"asset_id":"96886111393998001968863279421729456597655847484197549086072988901191634450924","price":"0.93","size":"1622.82","side":"BUY","hash":"1937ebdb4da0edb41c124f94cd33de7c5ef6be74","best_bid":"0.94","best_ask":"0.95"},{"asset_id":"54232589582260339592359130012520874109228367674780084862642636038394766871668","price":"0.07","size":"1622.82","side":"SELL","hash":"381320bd8667b79c47e8c621e7d4e26291603113","best_bid":"0.05","best_ask":"0.06"}],"timestamp":"1768250238700","event_type":"price_change"}}
{"schema_version":1,"source":"clob_ws_market","recv_ts_ns":1768250238736517751,"event_type":"price_change","market":"0xe51aa24ab1bbfefce466d642ad98587d13123e4ef95ec9aa73b712e775d4cbba","server_ts_ms":1768250238713,"raw":{"market":"0xe51aa24ab1bbfefce466d642ad98587d13123e4ef95ec9aa73b712e775d4cbba","price_changes":[{"asset_id":"96886111393998001968863279421729456597655847484197549086072988901191634450924","price":"0.94","size":"1353.4","side":"BUY","hash":"993fd8f992086b9752735ef3834c59b729072285","best_bid":"0.94","best_ask":"0.95"},{"asset_id":"54232589582260339592359130012520874109228367674780084862642636038394766871668","price":"0.06","size":"1353.4","side":"SELL","hash":"3ad659014a8002101276dbbe7518eea30ca962bb","best_bid":"0.05","best_ask":"0.06"}],"timestamp":"1768250238713","event_type":"price_change"}}
{"schema_version":1,"source":"clob_ws_market","recv_ts_ns":1768250238747960616,"event_type":"price_change","market":"0xe51aa24ab1bbfefce466d642ad98587d13123e4ef95ec9aa73b712e775d4cbba","server_ts_ms":1768250238727,"raw":{"market":"0xe51aa24ab1bbfefce466d642ad98587d13123e4ef95ec9aa73b712e775d4cbba","price_changes":[{"asset_id":"54232589582260339592359130012520874109228367674780084862642636038394766871668","price":"0.05","size":"1335.24","side":"BUY","hash":"d538c435a76d6a88accb1e583c2a4be82e9370b1","best_bid":"0.05","best_ask":"0.06"},{"asset_id":"96886111393998001968863279421729456597655847484197549086072988901191634450924","price":"0.95","size":"1335.24","side":"SELL","hash":"d7050cccbfc420bfb6c8d67daabfa70d3476f55d","best_bid":"0.94","best_ask":"0.95"}],"timestamp":"1768250238727","event_type":"price_change"}}
{"schema_version":1,"source":"clob_ws_market","recv_ts_ns":1768250238753349539,"event_type":"price_change","market":"0xe51aa24ab1bbfefce466d642ad98587d13123e4ef95ec9aa73b712e775d4cbba","server_ts_ms":1768250238730,"raw":{"market":"0xe51aa24ab1bbfefce466d642ad98587d13123e4ef95ec9aa73b712e775d4cbba","price_changes":[{"asset_id":"96886111393998001968863279421729456597655847484197549086072988901191634450924","price":"0.95","size":"1347.24","side":"SELL","hash":"791b39747e644efaeffb66de6899cc497cde01ad","best_bid":"0.94","best_ask":"0.95"},{"asset_id":"54232589582260339592359130012520874109228367674780084862642636038394766871668","price":"0.05","size":"1347.24","side":"BUY","hash":"764eeefaa769dd230c9365e6469a755a86294ac8","best_bid":"0.05","best_ask":"0.06"}],"timestamp":"1768250238730","event_type":"price_change"}}
{"schema_version":1,"source":"clob_ws_market","recv_ts_ns":1768250238760238959,"event_type":"price_change","market":"0xe51aa24ab1bbfefce466d642ad98587d13123e4ef95ec9aa73b712e775d4cbba","server_ts_ms":1768250238731,"raw":{"market":"0xe51aa24ab1bbfefce466d642ad98587d13123e4ef95ec9aa73b712e775d4cbba","price_changes":[{"asset_id":"54232589582260339592359130012520874109228367674780084862642636038394766871668","price":"0.03","size":"2112.6","side":"BUY","hash":"6e09eea024a0015bc365c5c8838a4545a71e26bf","best_bid":"0.05","best_ask":"0.06"},{"asset_id":"96886111393998001968863279421729456597655847484197549086072988901191634450924","price":"0.97","size":"2112.6","side":"SELL","hash":"616f0978767d1a11a4e2a07c40ca2bda560b9f4e","best_bid":"0.94","best_ask":"0.95"}],"timestamp":"1768250238731","event_type":"price_change"}}
{"schema_version":1,"source":"clob_ws_market","recv_ts_ns":1768250238773435758,"event_type":"price_change","market":"0xe51aa24ab1bbfefce466d642ad98587d13123e4ef95ec9aa73b712e775d4cbba","server_ts_ms":1768250238738,"raw":{"market":"0xe51aa24ab1bbfefce466d642ad98587d13123e4ef95ec9aa73b712e775d4cbba","price_changes":[{"asset_id":"96886111393998001968863279421729456597655847484197549086072988901191634450924","price":"0.93","size":"1638.82","side":"BUY","hash":"784d4826d8f1e30751dfcce141dc6d48ef839b5b","best_bid":"0.94","best_ask":"0.95"},{"asset_id":"54232589582260339592359130012520874109228367674780084862642636038394766871668","price":"0.07","size":"1638.82","side":"SELL","hash":"4225c8c8db305a3813626ebe63696fb73b8a1e3a","best_bid":"0.05","best_ask":"0.06"}],"timestamp":"1768250238738","event_type":"price_change"}}
{"schema_version":1,"source":"clob_ws_market","recv_ts_ns":1768250238779008366,"event_type":"price_change","market":"0xe51aa24ab1bbfefce466d642ad98587d13123e4ef95ec9aa73b712e775d4cbba","server_ts_ms":1768250238739,"raw":{"market":"0xe51aa24ab1bbfefce466d642ad98587d13123e4ef95ec9aa73b712e775d4cbba","price_changes":[{"asset_id":"96886111393998001968863279421729456597655847484197549086072988901191634450924","price":"0.93","size":"1654.82","side":"BUY","hash":"a22b34bf9e10204848288c8cda661bf32175f0ad","best_bid":"0.94","best_ask":"0.95"},{"asset_id":"54232589582260339592359130012520874109228367674780084862642636038394766871668","price":"0.07","size":"1654.82","side":"SELL","hash":"f9f4456b42cd1cd7c9cd7ed241862470798afcec","best_bid":"0.05","best_ask":"0.06"}],"timestamp":"1768250238739","event_type":"price_change"}}
{"schema_version":1,"source":"clob_ws_market","recv_ts_ns":1768250238783648413,"event_type":"price_change","market":"0xe51aa24ab1bbfefce466d642ad98587d13123e4ef95ec9aa73b712e775d4cbba","server_ts_ms":1768250238741,"raw":{"market":"0xe51aa24ab1bbfefce466d642ad98587d13123e4ef95ec9aa73b712e775d4cbba","price_changes":[{"asset_id":"54232589582260339592359130012520874109228367674780084862642636038394766871668","price":"0.04","size":"530.13","side":"BUY","hash":"9fcb30304ef22859b10d7ea0bdce90e0c1309ace","best_bid":"0.05","best_ask":"0.06"},{"asset_id":"96886111393998001968863279421729456597655847484197549086072988901191634450924","price":"0.96","size":"530.13","side":"SELL","hash":"a7083184c936497d420269481bd7f45158e81115","best_bid":"0.94","best_ask":"0.95"}],"timestamp":"1768250238741","event_type":"price_change"}}
{"schema_version":1,"source":"clob_ws_market","recv_ts_ns":1768250238793244322,"event_type":"price_change","market":"0xe51aa24ab1bbfefce466d642ad98587d13123e4ef95ec9aa73b712e775d4cbba","server_ts_ms":1768250238754,"raw":{"market":"0xe51aa24ab1bbfefce466d642ad98587d13123e4ef95ec9aa73b712e775d4cbba","price_changes":[{"asset_id":"96886111393998001968863279421729456597655847484197549086072988901191634450924","price":"0.96","size":"542.13","side":"SELL","hash":"0b4e0144b19a630c80bcd29fc9db1a0f82e14df0","best_bid":"0.94","best_ask":"0.95"},{"asset_id":"54232589582260339592359130012520874109228367674780084862642636038394766871668","price":"0.04","size":"542.13","side":"BUY","hash":"c9c2a35f18544a2f3e8899d26767801cbd6fc4d4","best_bid":"0.05","best_ask":"0.06"}],"timestamp":"1768250238754","event_type":"price_change"}}
{"schema_version":1,"source":"clob_ws_market","recv_ts_ns":1768250238797367159,"event_type":"price_change","market":"0xe51aa24ab1bbfefce466d642ad98587d13123e4ef95ec9aa73b712e775d4cbba","server_ts_ms":1768250238773,"raw":{"market":"0xe51aa24ab1bbfefce466d642ad98587d13123e4ef95ec9aa73b712e775d4cbba","price_changes":[{"asset_id":"54232589582260339592359130012520874109228367674780084862642636038394766871668","price":"0.1","size":"3416.54","side":"SELL","hash":"d09b219946d04349b17644016f0d277ff1b8cc56","best_bid":"0.05","best_ask":"0.06"},{"asset_id":"96886111393998001968863279421729456597655847484197549086072988901191634450924","price":"0.9","size":"3416.54","side":"BUY","hash":"46f41b53bd763516b0a64184d8bc37b4df0d083c","best_bid":"0.94","best_ask":"0.95"}],"timestamp":"1768250238773","event_type":"price_change"}}
{"schema_version":1,"source":"clob_ws_market","recv_ts_ns":1768250238834975019,"event_type":"price_change","market":"0xe51aa24ab1bbfefce466d642ad98587d13123e4ef95ec9aa73b712e775d4cbba","server_ts_ms":1768250238814,"raw":{"market":"0xe51aa24ab1bbfefce466d642ad98587d13123e4ef95ec9aa73b712e775d4cbba","price_changes":[{"asset_id":"54232589582260339592359130012520874109228367674780084862642636038394766871668","price":"0.04","size":"558.13","side":"BUY","hash":"8a356540bc28182a64f8752b82c62a4342d3e884","best_bid":"0.05","best_ask":"0.06"},{"asset_id":"96886111393998001968863279421729456597655847484197549086072988901191634450924","price":"0.96","size":"558.13","side":"SELL","hash":"6180b7929478c6f3cc6716fba678b98ef6e3fb44","best_bid":"0.94","best_ask":"0.95"}],"timestamp":"1768250238814","event_type":"price_change"}}
{"schema_version":1,"source":"clob_ws_market","recv_ts_ns":1768250238849406337,"event_type":"price_change","market":"0xe51aa24ab1bbfefce466d642ad98587d13123e4ef95ec9aa73b712e775d4cbba","server_ts_ms":1768250238828,"raw":{"market":"0xe51aa24ab1bbfefce466d642ad98587d13123e4ef95ec9aa73b712e775d4cbba","price_changes":[{"asset_id":"54232589582260339592359130012520874109228367674780084862642636038394766871668","price":"0.04","size":"534.13","side":"BUY","hash":"786c50129ca55e259bc4c2c81497a7d9eacdbfef","best_bid":"0.05","best_ask":"0.06"},{"asset_id":"96886111393998001968863279421729456597655847484197549086072988901191634450924","price":"0.96","size":"534.13","side":"SELL","hash":"e5512b78eef2e80ffaeac2726e4b25fdbaf34294","best_bid":"0.94","best_ask":"0.95"}],"timestamp":"1768250238828","event_type":"price_change"}}
{"schema_version":1,"source":"clob_ws_market","recv_ts_ns":1768250238864767701,"event_type":"price_change","market":"0xe51aa24ab1bbfefce466d642ad98587d13123e4ef95ec9aa73b712e775d4cbba","server_ts_ms":1768250238844,"raw":{"market":"0xe51aa24ab1bbfefce466d642ad98587d13123e4ef95ec9aa73b712e775d4cbba","price_changes":[{"asset_id":"54232589582260339592359130012520874109228367674780084862642636038394766871668","price":"0.05","size":"1336.24","side":"BUY","hash":"7586fc85dd778d0e5e581f7ae04695bd3bf39a2c","best_bid":"0.05","best_ask":"0.06"},{"asset_id":"96886111393998001968863279421729456597655847484197549086072988901191634450924","price":"0.95","size":"1336.24","side":"SELL","hash":"1f56b0bd9bc84570c3dfdb58e59fb1ad6aa5d2f4","best_bid":"0.94","best_ask":"0.95"}],"timestamp":"1768250238844","event_type":"price_change"}}
{"schema_version":1,"source":"clob_ws_market","recv_ts_ns":1768250238982282651,"event_type":"price_change","market":"0xe51aa24ab1bbfefce466d642ad98587d13123e4ef95ec9aa73b712e775d4cbba","server_ts_ms":1768250238961,"raw":{"market":"0xe51aa24ab1bbfefce466d642ad98587d13123e4ef95ec9aa73b712e775d4cbba","price_changes":[{"asset_id":"54232589582260339592359130012520874109228367674780084862642636038394766871668","price":"0.02","size":"6534.25","side":"BUY","hash":"20f4e4d8867616f035c5a2b61dbb92142b5ed382","best_bid":"0.05","best_ask":"0.06"},{"asset_id":"96886111393998001968863279421729456597655847484197549086072988901191634450924","price":"0.98","size":"6534.25","side":"SELL","hash":"80d5e0fc8462ed42ee9a5c600819e116ae4439f2","best_bid":"0.94","best_ask":"0.95"}],"timestamp":"1768250238961","event_type":"price_change"}}
{"schema_version":1,"source":"clob_ws_market","recv_ts_ns":1768250239002466015,"event_type":"best_bid_ask","market":"0xe51aa24ab1bbfefce466d642ad98587d13123e4ef95ec9aa73b712e775d4cbba","server_ts_ms":1768250238982,"raw":{"market":"0xe51aa24ab1bbfefce466d642ad98587d13123e4ef95ec9aa73b712e775d4cbba","asset_id":"54232589582260339592359130012520874109228367674780084862642636038394766871668","best_bid":"0.05","best_ask":"0.06","spread":"0.01","timestamp":"1768250238982","event_type":"best_bid_ask"}}
{"schema_version":1,"source":"clob_ws_market","recv_ts_ns":1768250239008786356,"event_type":"price_change","market":"0xe51aa24ab1bbfefce466d642ad98587d13123e4ef95ec9aa73b712e775d4cbba","server_ts_ms":1768250238980,"raw":{"market":"0xe51aa24ab1bbfefce466d642ad98587d13123e4ef95ec9aa73b712e775d4cbba","price_changes":[{"asset_id":"54232589582260339592359130012520874109228367674780084862642636038394766871668","price":"0.05","size":"1325.71","side":"BUY","hash":"cde7b18e37b9666851fab9bc5f8c894663bcfaca","best_bid":"0.05","best_ask":"0.06"},{"asset_id":"96886111393998001968863279421729456597655847484197549086072988901191634450924","price":"0.95","size":"1325.71","side":"SELL","hash":"67d3e182550e28d3111ef9509201140d7fe6e733","best_bid":"0.94","best_ask":"0.95"}],"timestamp":"1768250238980","event_type":"price_change"}}
{"schema_version":1,"source":"clob_ws_market","recv_ts_ns":1768250239014494439,"event_type":"book","market":"0xe51aa24ab1bbfefce466d642ad98587d13123e4ef95ec9aa73b712e775d4cbba","server_ts_ms":1768250238980,"raw":{"market":"0xe51aa24ab1bbfefce466d642ad98587d13123e4ef95ec9aa73b712e775d4cbba","asset_id":"54232589582260339592359130012520874109228367674780084862642636038394766871668","bids":[{"price":"0.01","size":"21023.9"},{"price":"0.02","size":"6534.25"},{"price":"0.03","size":"2112.6"},{"price":"0.04","size":"534.13"},{"price":"0.05","size":"1325.71"}],"asks":[{"price":"0.99","size":"24290.24"},{"price":"0.98","size":"7594.51"},{"price":"0.97","size":"5964.69"},{"price":"0.96","size":"5411.4"},{"price":"0.95","size":"5356.39"},{"price":"0.94","size":"5328"},{"price":"0.93","size":"5039.28"},{"price":"0.92","size":"5022.7"},{"price":"0.91","size":"5320.9"},{"price":"0.9","size":"5158.44"},{"price":"0.89","size":"18.3"},{"price":"0.88","size":"30.3"},{"price":"0.87","size":"16.5"},{"price":"0.86","size":"15.8"},{"price":"0.85","size":"104.19"},{"price":"0.84","size":"24.69"},{"price":"0.83","size":"14.19"},{"price":"0.82","size":"13.8"},{"price":"0.81","size":"13.4"},{"price":"0.8","size":"38.1"},{"price":"0.79","size":"12.8"},{"price":"0.78","size":"12.6"},{"price":"0.77","size":"12.3"},{"price":"0.76","size":"22.1"},{"price":"0.75","size":"16.9"},{"price":"0.74","size":"21.8"},{"price":"0.73","size":"11.6"},{"price":"0.72","size":"11.4"},{"price":"0.71","size":"61.3"},{"price":"0.7","size":"26.2"},{"price":"0.69","size":"11.1"},{"price":"0.68","size":"11"},{"price":"0.67","size":"110.9"},{"price":"0.66","size":"10.8"},{"price":"0.65","size":"15.7"},{"price":"0.64","size":"10.6"},{"price":"0.63","size":"10.6"},{"price":"0.62","size":"22.5"},{"price":"0.61","size":"10.5"},{"price":"0.6","size":"45.4"},{"price":"0.59","size":"311.4"},{"price":"0.58","size":"820.82"},{"price":"0.57","size":"826.3"},{"price":"0.56","size":"1062.3"},{"price":"0.55","size":"582.3"},{"price":"0.54","size":"626.2"},{"price":"0.53","size":"562.2"},{"price":"0.52","size":"567.2"},{"price":"0.51","size":"573.2"},{"price":"0.5","size":"917.2"},{"price":"0.49","size":"591.2"},{"price":"0.48","size":"596.2"},{"price":"0.47","size":"567.2"},{"price":"0.46","size":"636.61"},{"price":"0.45","size":"362.97"},{"price":"0.44","size":"341.3"},{"price":"0.43","size":"320.62"},{"price":"0.42","size":"567.3"},{"price":"0.41","size":"562.4"},{"price":"0.4","size":"693.02"},{"price":"0.39","size":"593.5"},{"price":"0.38","size":"636.5"},{"price":"0.37","size":"672.32"},{"price":"0.36","size":"680.6"},{"price":"0.35","size":"536.14"},{"price":"0.34","size":"602.8"},{"price":"0.33","size":"572.9"},{"price":"0.32","size":"573"},{"price":"0.31","size":"595.1"},{"price":"0.3","size":"603.2"},{"price":"0.29","size":"1318.72"},{"price":"0.28","size":"1043.04"},{"price":"0.27","size":"663.6"},{"price":"0.26","size":"911.17"},{"price":"0.25","size":"694.3"},{"price":"0.24","size":"717.6"},{"price":"0.23","size":"1183.3"},{"price":"0.22","size":"1526.53"},{"price":"0.21","size":"1178.8"},{"price":"0.2","size":"1445.08"},{"price":"0.19","size":"1229.8"},{"price":"0.18","size":"1467.57"},{"price":"0.17","size":"1520.51"},{"price":"0.16","size":"1967.49"},{"price":"0.15","size":"1810.78"},{"price":"0.14","size":"1506.7"},{"price":"0.13","size":"1588.93"},{"price":"0.12","size":"2555.4"},{"price":"0.11","size":"1792.8"},{"price":"0.1","size":"3416.54"},{"price":"0.09","size":"3012.44"},{"price":"0.08","size":"2724.36"},{"price":"0.07","size":"1654.82"},{"price":"0.06","size":"1353.4"}],"hash":"cde7b18e37b9666851fab9bc5f8c894663bcfaca","timestamp":"1768250238980","event_type":"book"}}
{"schema_version":1,"source":"clob_ws_market","recv_ts_ns":1768250239033736273,"event_type":"price_change","market":"0xe51aa24ab1bbfefce466d642ad98587d13123e4ef95ec9aa73b712e775d4cbba","server_ts_ms":1768250239000,"raw":{"market":"0xe51aa24ab1bbfefce466d642ad98587d13123e4ef95ec9aa73b712e775d4cbba","price_changes":[{"asset_id":"54232589582260339592359130012520874109228367674780084862642636038394766871668","price":"0.02","size":"6434.25","side":"BUY","hash":"519584c13a9ba0bdc1123edea43715d79b2fa1a8","best_bid":"0.05","best_ask":"0.06"},{"asset_id":"96886111393998001968863279421729456597655847484197549086072988901191634450924","price":"0.98","size":"6434.25","side":"SELL","hash":"8feb0ec68e03474833f37df11faef5b17860a3bb","best_bid":"0.94","best_ask":"0.95"}],"timestamp":"1768250239000","event_type":"price_change"}}
{"schema_version":1,"source":"clob_ws_market","recv_ts_ns":1768250239047483868,"event_type":"price_change","market":"0xe51aa24ab1bbfefce466d642ad98587d13123e4ef95ec9aa73b712e775d4cbba","server_ts_ms":1768250239008,"raw":{"market":"0xe51aa24ab1bbfefce466d642ad98587d13123e4ef95ec9aa73b712e775d4cbba","price_changes":[{"asset_id":"96886111393998001968863279421729456597655847484197549086072988901191634450924","price":"0.96","size":"522.13","side":"SELL","hash":"7e2624d50d10cb9df9bd14b28cca203b9543f9f4","best_bid":"0.94","best_ask":"0.95"},{"asset_id":"54232589582260339592359130012520874109228367674780084862642636038394766871668","price":"0.04","size":"522.13","side":"BUY","hash":"619caaecc1e6f0c9f5244c19458d761f8e424b24","best_bid":"0.05","best_ask":"0.06"}],"timestamp":"1768250239008","event_type":"price_change"}}
{"schema_version":1,"source":"clob_ws_market","recv_ts_ns":1768250239055483654,"event_type":"price_change","market":"0xe51aa24ab1bbfefce466d642ad98587d13123e4ef95ec9aa73b712e775d4cbba","server_ts_ms":1768250239017,"raw":{"market":"0xe51aa24ab1bbfefce466d642ad98587d13123e4ef95ec9aa73b712e775d4cbba","price_changes":[{"asset_id":"54232589582260339592359130012520874109228367674780084862642636038394766871668","price":"0.02","size":"6462.25","side":"BUY","hash":"095eb3691b0f586c630dfc180fae6cea5d7f346a","best_bid":"0.05","best_ask":"0.06"},{"asset_id":"96886111393998001968863279421729456597655847484197549086072988901191634450924","price":"0.98","size":"6462.25","side":"SELL","hash":"82fa469d055c35ac4a62967ce14eb78bfec08d53","best_bid":"0.94","best_ask":"0.95"}],"timestamp":"1768250239017","event_type":"price_change"}}
{"schema_version":1,"source":"clob_ws_market","recv_ts_ns":1768250239069220984,"event_type":"price_change","market":"0xe51aa24ab1bbfefce466d642ad98587d13123e4ef95ec9aa73b712e775d4cbba","server_ts_ms":1768250239044,"raw":{"market":"0xe51aa24ab1bbfefce466d642ad98587d13123e4ef95ec9aa73b712e775d4cbba","price_changes":[{"asset_id":"96886111393998001968863279421729456597655847484197549086072988901191634450924","price":"0.95","size":"1313.71","side":"SELL","hash":"dfc17527067d53475c9b273d46f39e4df4694002","best_bid":"0.94","best_ask":"0.95"},{"asset_id":"54232589582260339592359130012520874109228367674780084862642636038394766871668","price":"0.05","size":"1313.71","side":"BUY","hash":"6b8762331f0a09a55f9c31b0d73bcb1163b2228d","best_bid":"0.05","best_ask":"0.06"}],"timestamp":"1768250239044","event_type":"price_change"}}
{"schema_version":1,"source":"clob_ws_market","recv_ts_ns":1768250239072475843,"event_type":"price_change","market":"0xe51aa24ab1bbfefce466d642ad98587d13123e4ef95ec9aa73b712e775d4cbba","server_ts_ms":1768250239045,"raw":{"market":"0xe51aa24ab1bbfefce466d642ad98587d13123e4ef95ec9aa73b712e775d4cbba","price_changes":[{"asset_id":"54232589582260339592359130012520874109228367674780084862642636038394766871668","price":"0.02","size":"6562.25","side":"BUY","hash":"2b33b2c9f0aa4fb1a917c8fd6a4594a06a1ab198","best_bid":"0.05","best_ask":"0.06"},{"asset_id":"96886111393998001968863279421729456597655847484197549086072988901191634450924","price":"0.98","size":"6562.25","side":"SELL","hash":"287ddcad207cec4c7b392490a2dc1d76ec32328b","best_bid":"0.94","best_ask":"0.95"}],"timestamp":"1768250239045","event_type":"price_change"}}
{"schema_version":1,"source":"clob_ws_market","recv_ts_ns":1768250239115266193,"event_type":"best_bid_ask","market":"0xe51aa24ab1bbfefce466d642ad98587d13123e4ef95ec9aa73b712e775d4cbba","server_ts_ms":1768250239094,"raw":{"market":"0xe51aa24ab1bbfefce466d642ad98587d13123e4ef95ec9aa73b712e775d4cbba","asset_id":"54232589582260339592359130012520874109228367674780084862642636038394766871668","best_bid":"0.05","best_ask":"0.06","spread":"0.01","timestamp":"1768250239094","event_type":"best_bid_ask"}}
{"schema_version":1,"source":"clob_ws_market","recv_ts_ns":1768250239121718559,"event_type":"price_change","market":"0xe51aa24ab1bbfefce466d642ad98587d13123e4ef95ec9aa73b712e775d4cbba","server_ts_ms":1768250239092,"raw":{"market":"0xe51aa24ab1bbfefce466d642ad98587d13123e4ef95ec9aa73b712e775d4cbba","price_changes":[{"asset_id":"54232589582260339592359130012520874109228367674780084862642636038394766871668","price":"0.05","size":"1297.06","side":"BUY","hash":"6c3251293b97688c33d6f7ff1b63ca4687fb3bb1","best_bid":"0.05","best_ask":"0.06"},{"asset_id":"96886111393998001968863279421729456597655847484197549086072988901191634450924","price":"0.95","size":"1297.06","side":"SELL","hash":"c2f207a0fa6b433731a503370356d507c81b5705","best_bid":"0.94","best_ask":"0.95"}],"timestamp":"1768250239092","event_type":"price_change"}}
{"schema_version":1,"source":"clob_ws_market","recv_ts_ns":1768250239129742531,"event_type":"book","market":"0xe51aa24ab1bbfefce466d642ad98587d13123e4ef95ec9aa73b712e775d4cbba","server_ts_ms":1768250239092,"raw":{"market":"0xe51aa24ab1bbfefce466d642ad98587d13123e4ef95ec9aa73b712e775d4cbba","asset_id":"54232589582260339592359130012520874109228367674780084862642636038394766871668","bids":[{"price":"0.01","size":"21023.9"},{"price":"0.02","size":"6562.25"},{"price":"0.03","size":"2112.6"},{"price":"0.04","size":"522.13"},{"price":"0.05","size":"1297.06"}],"asks":[{"price":"0.99","size":"24290.24"},{"price":"0.98","size":"7594.51"},{"price":"0.97","size":"5964.69"},{"price":"0.96","size":"5411.4"},{"price":"0.95","size":"5356.39"},{"price":"0.94","size":"5328"},{"price":"0.93","size":"5039.28"},{"price":"0.92","size":"5022.7"},{"price":"0.91","size":"5320.9"},{"price":"0.9","size":"5158.44"},{"price":"0.89","size":"18.3"},{"price":"0.88","size":"30.3"},{"price":"0.87","size":"16.5"},{"price":"0.86","size":"15.8"},{"price":"0.85","size":"104.19"},{"price":"0.84","size":"24.69"},{"price":"0.83","size":"14.19"},{"price":"0.82","size":"13.8"},{"price":"0.81","size":"13.4"},{"price":"0.8","size":"38.1"},{"price":"0.79","size":"12.8"},{"price":"0.78","size":"12.6"},{"price":"0.77","size":"12.3"},{"price":"0.76","size":"22.1"},{"price":"0.75","size":"16.9"},{"price":"0.74","size":"21.8"},{"price":"0.73","size":"11.6"},{"price":"0.72","size":"11.4"},{"price":"0.71","size":"61.3"},{"price":"0.7","size":"26.2"},{"price":"0.69","size":"11.1"},{"price":"0.68","size":"11"},{"price":"0.67","size":"110.9"},{"price":"0.66","size":"10.8"},{"price":"0.65","size":"15.7"},{"price":"0.64","size":"10.6"},{"price":"0.63","size":"10.6"},{"price":"0.62","size":"22.5"},{"price":"0.61","size":"10.5"},{"price":"0.6","size":"45.4"},{"price":"0.59","size":"311.4"},{"price":"0.58","size":"820.82"},{"price":"0.57","size":"826.3"},{"price":"0.56","size":"1062.3"},{"price":"0.55","size":"582.3"},{"price":"0.54","size":"626.2"},{"price":"0.53","size":"562.2"},{"price":"0.52","size":"567.2"},{"price":"0.51","size":"573.2"},{"price":"0.5","size":"917.2"},{"price":"0.49","size":"591.2"},{"price":"0.48","size":"596.2"},{"price":"0.47","size":"567.2"},{"price":"0.46","size":"636.61"},{"price":"0.45","size":"362.97"},{"price":"0.44","size":"341.3"},{"price":"0.43","size":"320.62"},{"price":"0.42","size":"567.3"},{"price":"0.41","size":"562.4"},{"price":"0.4","size":"693.02"},{"price":"0.39","size":"593.5"},{"price":"0.38","size":"636.5"},{"price":"0.37","size":"672.32"},{"price":"0.36","size":"680.6"},{"price":"0.35","size":"536.14"},{"price":"0.34","size":"602.8"},{"price":"0.33","size":"572.9"},{"price":"0.32","size":"573"},{"price":"0.31","size":"595.1"},{"price":"0.3","size":"603.2"},{"price":"0.29","size":"1318.72"},{"price":"0.28","size":"1043.04"},{"price":"0.27","size":"663.6"},{"price":"0.26","size":"911.17"},{"price":"0.25","size":"694.3"},{"price":"0.24","size":"717.6"},{"price":"0.23","size":"1183.3"},{"price":"0.22","size":"1526.53"},{"price":"0.21","size":"1178.8"},{"price":"0.2","size":"1445.08"},{"price":"0.19","size":"1229.8"},{"price":"0.18","size":"1467.57"},{"price":"0.17","size":"1520.51"},{"price":"0.16","size":"1967.49"},{"price":"0.15","size":"1810.78"},{"price":"0.14","size":"1506.7"},{"price":"0.13","size":"1588.93"},{"price":"0.12","size":"2555.4"},{"price":"0.11","size":"1792.8"},{"price":"0.1","size":"3416.54"},{"price":"0.09","size":"3012.44"},{"price":"0.08","size":"2724.36"},{"price":"0.07","size":"1654.82"},{"price":"0.06","size":"1353.4"}],"hash":"6c3251293b97688c33d6f7ff1b63ca4687fb3bb1","timestamp":"1768250239092","event_type":"book"}}
{"schema_version":1,"source":"clob_ws_market","recv_ts_ns":1768250239139819589,"event_type":"price_change","market":"0xe51aa24ab1bbfefce466d642ad98587d13123e4ef95ec9aa73b712e775d4cbba","server_ts_ms":1768250239113,"raw":{"market":"0xe51aa24ab1bbfefce466d642ad98587d13123e4ef95ec9aa73b712e775d4cbba","price_changes":[{"asset_id":"96886111393998001968863279421729456597655847484197549086072988901191634450924","price":"0.94","size":"1368.4","side":"BUY","hash":"7d1974c402ef4922e93d19b3beb424616ef088e5","best_bid":"0.94","best_ask":"0.95"},{"asset_id":"54232589582260339592359130012520874109228367674780084862642636038394766871668","price":"0.06","size":"1368.4","side":"SELL","hash":"96fcb491c917b510643a70b80b7d97bd1a7d88d4","best_bid":"0.05","best_ask":"0.06"}],"timestamp":"1768250239113","event_type":"price_change"}}
{"schema_version":1,"source":"clob_ws_market","recv_ts_ns":1768250239144515436,"event_type":"price_change","market":"0xe51aa24ab1bbfefce466d642ad98587d13123e4ef95ec9aa73b712e775d4cbba","server_ts_ms":1768250239115,"raw":{"market":"0xe51aa24ab1bbfefce466d642ad98587d13123e4ef95ec9aa73b712e775d4cbba","price_changes":[{"asset_id":"54232589582260339592359130012520874109228367674780084862642636038394766871668","price":"0.06","size":"1381.4","side":"SELL","hash":"2a60e759b1e88673468eaf9ea08605d3241bc30c","best_bid":"0.05","best_ask":"0.06"},{"asset_id":"96886111393998001968863279421729456597655847484197549086072988901191634450924","price":"0.94","size":"1381.4","side":"BUY","hash":"ddfbfae85bd05978a7efd17cc7a28ea91bec14e5","best_bid":"0.94","best_ask":"0.95"}],"timestamp":"1768250239115","event_type":"price_change"}}
{"schema_version":1,"source":"clob_ws_market","recv_ts_ns":1768250239149380279,"event_type":"price_change","market":"0xe51aa24ab1bbfefce466d642ad98587d13123e4ef95ec9aa73b712e775d4cbba","server_ts_ms":1768250239122,"raw":{"market":"0xe51aa24ab1bbfefce466d642ad98587d13123e4ef95ec9aa73b712e775d4cbba","price_changes":[{"asset_id":"54232589582260339592359130012520874109228367674780084862642636038394766871668","price":"0.02","size":"6534.25","side":"BUY","hash":"91c033646475c0a5095a9e43ac076d376e8abe52","best_bid":"0.05","best_ask":"0.06"},{"asset_id":"96886111393998001968863279421729456597655847484197549086072988901191634450924","price":"0.98","size":"6534.25","side":"SELL","hash":"730b9ca97ffa174edfc32b2e1d2588a3c95b5f35","best_bid":"0.94","best_ask":"0.95"}],"timestamp":"1768250239122","event_type":"price_change"}}
{"schema_version":1,"source":"clob_ws_market","recv_ts_ns":1768250239153765124,"event_type":"last_trade_price","market":"0xe51aa24ab1bbfefce466d642ad98587d13123e4ef95ec9aa73b712e775d4cbba","server_ts_ms":1768250239126,"raw":{"market":"0xe51aa24ab1bbfefce466d642ad98587d13123e4ef95ec9aa73b712e775d4cbba","asset_id":"54232589582260339592359130012520874109228367674780084862642636038394766871668","price":"0.05","size":"16.65","fee_rate_bps":"1000","side":"SELL","timestamp":"1768250239126","event_type":"last_trade_price","transaction_hash":"0x002343572a0fab6f68a152d2395429636fc1c20c7a2a68d0abc46626229a5279"}}
{"schema_version":1,"source":"clob_ws_market","recv_ts_ns":1768250239188294389,"event_type":"price_change","market":"0xe51aa24ab1bbfefce466d642ad98587d13123e4ef95ec9aa73b712e775d4cbba","server_ts_ms":1768250239167,"raw":{"market":"0xe51aa24ab1bbfefce466d642ad98587d13123e4ef95ec9aa73b712e775d4cbba","price_changes":[{"asset_id":"54232589582260339592359130012520874109228367674780084862642636038394766871668","price":"0.02","size":"6562.25","side":"BUY","hash":"1326d3cd3c3ad58a118579df31ccbde493e1f59b","best_bid":"0.05","best_ask":"0.06"},{"asset_id":"96886111393998001968863279421729456597655847484197549086072988901191634450924","price":"0.98","size":"6562.25","side":"SELL","hash":"29d9368b0b87718ac384f765395ce387a362370b","best_bid":"0.94","best_ask":"0.95"}],"timestamp":"1768250239167","event_type":"price_change"}}
{"schema_version":1,"source":"clob_ws_market","recv_ts_ns":1768250239255140988,"event_type":"best_bid_ask","market":"0xe51aa24ab1bbfefce466d642ad98587d13123e4ef95ec9aa73b712e775d4cbba","server_ts_ms":1768250239229,"raw":{"market":"0xe51aa24ab1bbfefce466d642ad98587d13123e4ef95ec9aa73b712e775d4cbba","asset_id":"54232589582260339592359130012520874109228367674780084862642636038394766871668","best_bid":"0.05","best_ask":"0.06","spread":"0.01","timestamp":"1768250239229","event_type":"best_bid_ask"}}
{"schema_version":1,"source":"clob_ws_market","recv_ts_ns":1768250239260264491,"event_type":"price_change","market":"0xe51aa24ab1bbfefce466d642ad98587d13123e4ef95ec9aa73b712e775d4cbba","server_ts_ms":1768250239227,"raw":{"market":"0xe51aa24ab1bbfefce466d642ad98587d13123e4ef95ec9aa73b712e775d4cbba","price_changes":[{"asset_id":"96886111393998001968863279421729456597655847484197549086072988901191634450924","price":"0.94","size":"1324.4","side":"BUY","hash":"a56c884834490c99245a9576e23531a5a77de50b","best_bid":"0.94","best_ask":"0.95"},{"asset_id":"54232589582260339592359130012520874109228367674780084862642636038394766871668","price":"0.06","size":"1324.4","side":"SELL","hash":"f90af06316225ec3b849378cd0666cda6f5ac0e3","best_bid":"0.05","best_ask":"0.06"}],"timestamp":"1768250239227","event_type":"price_change"}}
{"schema_version":1,"source":"clob_ws_market","recv_ts_ns":1768250239264088347,"event_type":"book","market":"0xe51aa24ab1bbfefce466d642ad98587d13123e4ef95ec9aa73b712e775d4cbba","server_ts_ms":1768250239227,"raw":{"market":"0xe51aa24ab1bbfefce466d642ad98587d13123e4ef95ec9aa73b712e775d4cbba","asset_id":"54232589582260339592359130012520874109228367674780084862642636038394766871668","bids":[{"price":"0.01","size":"21023.9"},{"price":"0.02","size":"6562.25"},{"price":"0.03","size":"2112.6"},{"price":"0.04","size":"522.13"},{"price":"0.05","size":"1297.06"}],"asks":[{"price":"0.99","size":"24290.24"},{"price":"0.98","size":"7594.51"},{"price":"0.97","size":"5964.69"},{"price":"0.96","size":"5411.4"},{"price":"0.95","size":"5356.39"},{"price":"0.94","size":"5328"},{"price":"0.93","size":"5039.28"},{"price":"0.92","size":"5022.7"},{"price":"0.91","size":"5320.9"},{"price":"0.9","size":"5158.44"},{"price":"0.89","size":"18.3"},{"price":"0.88","size":"30.3"},{"price":"0.87","size":"16.5"},{"price":"0.86","size":"15.8"},{"price":"0.85","size":"104.19"},{"price":"0.84","size":"24.69"},{"price":"0.83","size":"14.19"},{"price":"0.82","size":"13.8"},{"price":"0.81","size":"13.4"},{"price":"0.8","size":"38.1"},{"price":"0.79","size":"12.8"},{"price":"0.78","size":"12.6"},{"price":"0.77","size":"12.3"},{"price":"0.76","size":"22.1"},{"price":"0.75","size":"16.9"},{"price":"0.74","size":"21.8"},{"price":"0.73","size":"11.6"},{"price":"0.72","size":"11.4"},{"price":"0.71","size":"61.3"},{"price":"0.7","size":"26.2"},{"price":"0.69","size":"11.1"},{"price":"0.68","size":"11"},{"price":"0.67","size":"110.9"},{"price":"0.66","size":"10.8"},{"price":"0.65","size":"15.7"},{"price":"0.64","size":"10.6"},{"price":"0.63","size":"10.6"},{"price":"0.62","size":"22.5"},{"price":"0.61","size":"10.5"},{"price":"0.6","size":"45.4"},{"price":"0.59","size":"311.4"},{"price":"0.58","size":"820.82"},{"price":"0.57","size":"826.3"},{"price":"0.56","size":"1062.3"},{"price":"0.55","size":"582.3"},{"price":"0.54","size":"626.2"},{"price":"0.53","size":"562.2"},{"price":"0.52","size":"567.2"},{"price":"0.51","size":"573.2"},{"price":"0.5","size":"917.2"},{"price":"0.49","size":"591.2"},{"price":"0.48","size":"596.2"},{"price":"0.47","size":"567.2"},{"price":"0.46","size":"636.61"},{"price":"0.45","size":"362.97"},{"price":"0.44","size":"341.3"},{"price":"0.43","size":"320.62"},{"price":"0.42","size":"567.3"},{"price":"0.41","size":"562.4"},{"price":"0.4","size":"693.02"},{"price":"0.39","size":"593.5"},{"price":"0.38","size":"636.5"},{"price":"0.37","size":"672.32"},{"price":"0.36","size":"680.6"},{"price":"0.35","size":"536.14"},{"price":"0.34","size":"602.8"},{"price":"0.33","size":"572.9"},{"price":"0.32","size":"573"},{"price":"0.31","size":"595.1"},{"price":"0.3","size":"603.2"},{"price":"0.29","size":"1318.72"},{"price":"0.28","size":"1043.04"},{"price":"0.27","size":"663.6"},{"price":"0.26","size":"911.17"},{"price":"0.25","size":"694.3"},{"price":"0.24","size":"717.6"},{"price":"0.23","size":"1183.3"},{"price":"0.22","size":"1526.53"},{"price":"0.21","size":"1178.8"},{"price":"0.2","size":"1445.08"},{"price":"0.19","size":"1229.8"},{"price":"0.18","size":"1467.57"},{"price":"0.17","size":"1520.51"},{"price":"0.16","size":"1967.49"},{"price":"0.15","size":"1810.78"},{"price":"0.14","size":"1506.7"},{"price":"0.13","size":"1588.93"},{"price":"0.12","size":"2555.4"},{"price":"0.11","size":"1792.8"},{"price":"0.1","size":"3416.54"},{"price":"0.09","size":"3012.44"},{"price":"0.08","size":"2724.36"},{"price":"0.07","size":"1654.82"},{"price":"0.06","size":"1324.4"}],"hash":"f90af06316225ec3b849378cd0666cda6f5ac0e3","timestamp":"1768250239227","event_type":"book"}}
{"schema_version":1,"source":"clob_ws_market","recv_ts_ns":1768250239300430455,"event_type":"last_trade_price","market":"0xe51aa24ab1bbfefce466d642ad98587d13123e4ef95ec9aa73b712e775d4cbba","server_ts_ms":1768250239256,"raw":{"market":"0xe51aa24ab1bbfefce466d642ad98587d13123e4ef95ec9aa73b712e775d4cbba","asset_id":"54232589582260339592359130012520874109228367674780084862642636038394766871668","price":"0.06","size":"57","fee_rate_bps":"1000","side":"BUY","timestamp":"1768250239256","event_type":"last_trade_price","transaction_hash":"0xf2eb491f1df94c569018dd91a338f2ab89ecaefe532436d2a2ad2529b3684f27"}}
{"schema_version":1,"source":"clob_ws_market","recv_ts_ns":1768250239339887895,"event_type":"price_change","market":"0xe51aa24ab1bbfefce466d642ad98587d13123e4ef95ec9aa73b712e775d4cbba","server_ts_ms":1768250239317,"raw":{"market":"0xe51aa24ab1bbfefce466d642ad98587d13123e4ef95ec9aa73b712e775d4cbba","price_changes":[{"asset_id":"96886111393998001968863279421729456597655847484197549086072988901191634450924","price":"0.61","size":"625.5","side":"BUY","hash":"aaed9a7d0ca298371ad39a4a6fe69e7a640338f6","best_bid":"0.94","best_ask":"0.95"},{"asset_id":"54232589582260339592359130012520874109228367674780084862642636038394766871668","price":"0.39","size":"625.5","side":"SELL","hash":"3a8678bf772ec345e9ceb517e5c9af9902b5e640","best_bid":"0.05","best_ask":"0.06"}],"timestamp":"1768250239317","event_type":"price_change"}}
{"schema_version":1,"source":"clob_ws_market","recv_ts_ns":1768250239408307063,"event_type":"price_change","market":"0xe51aa24ab1bbfefce466d642ad98587d13123e4ef95ec9aa73b712e775d4cbba","server_ts_ms":1768250239382,"raw":{"market":"0xe51aa24ab1bbfefce466d642ad98587d13123e4ef95ec9aa73b712e775d4cbba","price_changes":[{"asset_id":"96886111393998001968863279421729456597655847484197549086072988901191634450924","price":"0.94","size":"1309.4","side":"BUY","hash":"1bb26ea4b55765815c743f59cae3f916116613c9","best_bid":"0.94","best_ask":"0.95"},{"asset_id":"54232589582260339592359130012520874109228367674780084862642636038394766871668","price":"0.06","size":"1309.4","side":"SELL","hash":"7a82d8faf1d47d06e7def4f2b3b6d86ededccc8b","best_bid":"0.05","best_ask":"0.06"}],"timestamp":"1768250239382","event_type":"price_change"}}
{"schema_version":1,"source":"clob_ws_market","recv_ts_ns":1768250239415111469,"event_type":"price_change","market":"0xe51aa24ab1bbfefce466d642ad98587d13123e4ef95ec9aa73b712e775d4cbba","server_ts_ms":1768250239384,"raw":{"market":"0xe51aa24ab1bbfefce466d642ad98587d13123e4ef95ec9aa73b712e775d4cbba","price_changes":[{"asset_id":"54232589582260339592359130012520874109228367674780084862642636038394766871668","price":"0.06","size":"1296.4","side":"SELL","hash":"925b14d5c7ec8539ef39de2ce8ebbe3dad1aa509","best_bid":"0.05","best_ask":"0.06"},{"asset_id":"96886111393998001968863279421729456597655847484197549086072988901191634450924","price":"0.94","size":"1296.4","side":"BUY","hash":"9cc92cc4a2c14045d035bb6cf0c0b137a7174fc9","best_bid":"0.94","best_ask":"0.95"}],"timestamp":"1768250239384","event_type":"price_change"}}
{"schema_version":1,"source":"clob_ws_market","recv_ts_ns":1768250239499278933,"event_type":"price_change","market":"0xe51aa24ab1bbfefce466d642ad98587d13123e4ef95ec9aa73b712e775d4cbba","server_ts_ms":1768250239478,"raw":{"market":"0xe51aa24ab1bbfefce466d642ad98587d13123e4ef95ec9aa73b712e775d4cbba","price_changes":[{"asset_id":"96886111393998001968863279421729456597655847484197549086072988901191634450924","price":"0.99","size":"20993.9","side":"SELL","hash":"9191fabb99066317ec6f26a21bae67cdcf3f1377","best_bid":"0.94","best_ask":"0.95"},{"asset_id":"54232589582260339592359130012520874109228367674780084862642636038394766871668","price":"0.01","size":"20993.9","side":"BUY","hash":"f66822a2fee0a3be7e9509e0d332d6b61f9c563c","best_bid":"0.05","best_ask":"0.06"}],"timestamp":"1768250239478","event_type":"price_change"}}
{"schema_version":1,"source":"clob_ws_market","recv_ts_ns":1768250239522000063,"event_type":"price_change","market":"0xe51aa24ab1bbfefce466d642ad98587d13123e4ef95ec9aa73b712e775d4cbba","server_ts_ms":1768250239500,"raw":{"market":"0xe51aa24ab1bbfefce466d642ad98587d13123e4ef95ec9aa73b712e775d4cbba","price_changes":[{"asset_id":"54232589582260339592359130012520874109228367674780084862642636038394766871668","price":"0.02","size":"6534.25","side":"BUY","hash":"c2ad1d83836be290decc75760f194d24ea1ed0da","best_bid":"0.05","best_ask":"0.06"},{"asset_id":"96886111393998001968863279421729456597655847484197549086072988901191634450924","price":"0.98","size":"6534.25","side":"SELL","hash":"e6cd4f497406df82e9115d6b4c05f0a369b49410","best_bid":"0.94","best_ask":"0.95"}],"timestamp":"1768250239500","event_type":"price_change"}}
{"schema_version":1,"source":"clob_ws_market","recv_ts_ns":1768250239561881639,"event_type":"price_change","market":"0xe51aa24ab1bbfefce466d642ad98587d13123e4ef95ec9aa73b712e775d4cbba","server_ts_ms":1768250239541,"raw":{"market":"0xe51aa24ab1bbfefce466d642ad98587d13123e4ef95ec9aa73b712e775d4cbba","price_changes":[{"asset_id":"54232589582260339592359130012520874109228367674780084862642636038394766871668","price":"0.02","size":"6562.25","side":"BUY","hash":"7c7036c8190d8e65577d06034ad9d365a8bc5722","best_bid":"0.05","best_ask":"0.06"},{"asset_id":"96886111393998001968863279421729456597655847484197549086072988901191634450924","price":"0.98","size":"6562.25","side":"SELL","hash":"cdcab50a901890d05ea11343290d46e0dd039bdf","best_bid":"0.94","best_ask":"0.95"}],"timestamp":"1768250239541","event_type":"price_change"}}
{"schema_version":1,"source":"clob_ws_market","recv_ts_ns":1768250239703679610,"event_type":"price_change","market":"0xe51aa24ab1bbfefce466d642ad98587d13123e4ef95ec9aa73b712e775d4cbba","server_ts_ms":1768250239682,"raw":{"market":"0xe51aa24ab1bbfefce466d642ad98587d13123e4ef95ec9aa73b712e775d4cbba","price_changes":[{"asset_id":"54232589582260339592359130012520874109228367674780084862642636038394766871668","price":"0.02","size":"6534.25","side":"BUY","hash":"d28958af4b1f4fa376cec51bc6edbd505a49ffe6","best_bid":"0.05","best_ask":"0.06"},{"asset_id":"96886111393998001968863279421729456597655847484197549086072988901191634450924","price":"0.98","size":"6534.25","side":"SELL","hash":"d094d09174f291183fd3f92c1570f0ddc26a60de","best_bid":"0.94","best_ask":"0.95"}],"timestamp":"1768250239682","event_type":"price_change"}}
{"schema_version":1,"source":"clob_ws_market","recv_ts_ns":1768250239770722590,"event_type":"price_change","market":"0xe51aa24ab1bbfefce466d642ad98587d13123e4ef95ec9aa73b712e775d4cbba","server_ts_ms":1768250239745,"raw":{"market":"0xe51aa24ab1bbfefce466d642ad98587d13123e4ef95ec9aa73b712e775d4cbba","price_changes":[{"asset_id":"54232589582260339592359130012520874109228367674780084862642636038394766871668","price":"0.02","size":"6562.25","side":"BUY","hash":"dedbbf674d1672fc908c6f8fcb1723903d38bb0c","best_bid":"0.05","best_ask":"0.06"},{"asset_id":"96886111393998001968863279421729456597655847484197549086072988901191634450924","price":"0.98","size":"6562.25","side":"SELL","hash":"2882add0f55036deed776f75e5736d004b1d7b95","best_bid":"0.94","best_ask":"0.95"}],"timestamp":"1768250239745","event_type":"price_change"}}
{"schema_version":1,"source":"clob_ws_market","recv_ts_ns":1768250239779020215,"event_type":"price_change","market":"0xe51aa24ab1bbfefce466d642ad98587d13123e4ef95ec9aa73b712e775d4cbba","server_ts_ms":1768250239758,"raw":{"market":"0xe51aa24ab1bbfefce466d642ad98587d13123e4ef95ec9aa73b712e775d4cbba","price_changes":[{"asset_id":"54232589582260339592359130012520874109228367674780084862642636038394766871668","price":"0.04","size":"558.13","side":"BUY","hash":"e73a204f7982d59a25327d6853b8ae95042c7a97","best_bid":"0.05","best_ask":"0.06"},{"asset_id":"96886111393998001968863279421729456597655847484197549086072988901191634450924","price":"0.96","size":"558.13","side":"SELL","hash":"f6954b92a8740ae3e17794aa9ae59fea7509acaf","best_bid":"0.94","best_ask":"0.95"}],"timestamp":"1768250239758","event_type":"price_change"}}
{"schema_version":1,"source":"clob_ws_market","recv_ts_ns":1768250239785532659,"event_type":"price_change","market":"0xe51aa24ab1bbfefce466d642ad98587d13123e4ef95ec9aa73b712e775d4cbba","server_ts_ms":1768250239762,"raw":{"market":"0xe51aa24ab1bbfefce466d642ad98587d13123e4ef95ec9aa73b712e775d4cbba","price_changes":[{"asset_id":"96886111393998001968863279421729456597655847484197549086072988901191634450924","price":"0.96","size":"587.13","side":"SELL","hash":"1fa24eca8ae8c0f41aa1317d3f9fb770ca9bc47e","best_bid":"0.94","best_ask":"0.95"},{"asset_id":"54232589582260339592359130012520874109228367674780084862642636038394766871668","price":"0.04","size":"587.13","side":"BUY","hash":"3a24a64cdf4cba57fdb846217bfa3291a514f325","best_bid":"0.05","best_ask":"0.06"}],"timestamp":"1768250239762","event_type":"price_change"}}
{"schema_version":1,"source":"clob_ws_market","recv_ts_ns":1768250239790817568,"event_type":"price_change","market":"0xe51aa24ab1bbfefce466d642ad98587d13123e4ef95ec9aa73b712e775d4cbba","server_ts_ms":1768250239765,"raw":{"market":"0xe51aa24ab1bbfefce466d642ad98587d13123e4ef95ec9aa73b712e775d4cbba","price_changes":[{"asset_id":"54232589582260339592359130012520874109228367674780084862642636038394766871668","price":"0.04","size":"599.13","side":"BUY","hash":"fb5998fe57020add712b5e5e0a0a05b25fdc50ab","best_bid":"0.05","best_ask":"0.06"},{"asset_id":"96886111393998001968863279421729456597655847484197549086072988901191634450924","price":"0.96","size":"599.13","side":"SELL","hash":"71e3ec194c0e06d097124c57e1de37001bc775fc","best_bid":"0.94","best_ask":"0.95"}],"timestamp":"1768250239765","event_type":"price_change"}}
{"schema_version":1,"source":"clob_ws_market","recv_ts_ns":1768250239800670640,"event_type":"price_change","market":"0xe51aa24ab1bbfefce466d642ad98587d13123e4ef95ec9aa73b712e775d4cbba","server_ts_ms":1768250239778,"raw":{"market":"0xe51aa24ab1bbfefce466d642ad98587d13123e4ef95ec9aa73b712e775d4cbba","price_changes":[{"asset_id":"96886111393998001968863279421729456597655847484197549086072988901191634450924","price":"0.73","size":"668.6","side":"BUY","hash":"30f776699d61251ed05d64e863cee062d28b0540","best_bid":"0.94","best_ask":"0.95"},{"asset_id":"54232589582260339592359130012520874109228367674780084862642636038394766871668","price":"0.27","size":"668.6","side":"SELL","hash":"6638d7fbc4f58967b36bd1d70e55675bff4f7d62","best_bid":"0.05","best_ask":"0.06"}],"timestamp":"1768250239778","event_type":"price_change"}}
{"schema_version":1,"source":"clob_ws_market","recv_ts_ns":1768250239858072506,"event_type":"price_change","market":"0xe51aa24ab1bbfefce466d642ad98587d13123e4ef95ec9aa73b712e775d4cbba","server_ts_ms":1768250239831,"raw":{"market":"0xe51aa24ab1bbfefce466d642ad98587d13123e4ef95ec9aa73b712e775d4cbba","price_changes":[{"asset_id":"96886111393998001968863279421729456597655847484197549086072988901191634450924","price":"0.95","size":"1372.32","side":"SELL","hash":"0040ea516610f21ec3853c8f39594002e55d26c5","best_bid":"0.94","best_ask":"0.95"},{"asset_id":"54232589582260339592359130012520874109228367674780084862642636038394766871668","price":"0.05","size":"1372.32","side":"BUY","hash":"b08d09069778faf2a3eb57382a3160f2b70f15ce","best_bid":"0.05","best_ask":"0.06"}],"timestamp":"1768250239831","event_type":"price_change"}}
{"schema_version":1,"source":"clob_ws_market","recv_ts_ns":1768250239863411712,"event_type":"price_change","market":"0xe51aa24ab1bbfefce466d642ad98587d13123e4ef95ec9aa73b712e775d4cbba","server_ts_ms":1768250239842,"raw":{"market":"0xe51aa24ab1bbfefce466d642ad98587d13123e4ef95ec9aa73b712e775d4cbba","price_changes":[{"asset_id":"96886111393998001968863279421729456597655847484197549086072988901191634450924","price":"0.94","size":"1286.4","side":"BUY","hash":"950f7c7e1a04852e88592ebee5ff4c796e1ab11d","best_bid":"0.94","best_ask":"0.95"},{"asset_id":"54232589582260339592359130012520874109228367674780084862642636038394766871668","price":"0.06","size":"1286.4","side":"SELL","hash":"28d159eed61431cc299f3bf6c4eb3fb6b5f9e5ff","best_bid":"0.05","best_ask":"0.06"}],"timestamp":"1768250239842","event_type":"price_change"}}
{"schema_version":1,"source":"clob_ws_market","recv_ts_ns":1768250239885647459,"event_type":"price_change","market":"0xe51aa24ab1bbfefce466d642ad98587d13123e4ef95ec9aa73b712e775d4cbba","server_ts_ms":1768250239855,"raw":{"market":"0xe51aa24ab1bbfefce466d642ad98587d13123e4ef95ec9aa73b712e775d4cbba","price_changes":[{"asset_id":"54232589582260339592359130012520874109228367674780084862642636038394766871668","price":"0.04","size":"587.13","side":"BUY","hash":"5f8a16cf1aba99e9b53e10ca3e5598995e828c91","best_bid":"0.05","best_ask":"0.06"},{"asset_id":"96886111393998001968863279421729456597655847484197549086072988901191634450924","price":"0.96","size":"587.13","side":"SELL","hash":"c84eacfea7ccabf175547c50f63e4981f067363f","best_bid":"0.94","best_ask":"0.95"}],"timestamp":"1768250239855","event_type":"price_change"}}
{"schema_version":1,"source":"clob_ws_market","recv_ts_ns":1768250239889701824,"event_type":"price_change","market":"0xe51aa24ab1bbfefce466d642ad98587d13123e4ef95ec9aa73b712e775d4cbba","server_ts_ms":1768250239863,"raw":{"market":"0xe51aa24ab1bbfefce466d642ad98587d13123e4ef95ec9aa73b712e775d4cbba","price_changes":[{"asset_id":"54232589582260339592359130012520874109228367674780084862642636038394766871668","price":"0.16","size":"1718.59","side":"SELL","hash":"3b345d97a630b156fddfeea6bf161a29d6323e62","best_bid":"0.05","best_ask":"0.06"},{"asset_id":"96886111393998001968863279421729456597655847484197549086072988901191634450924","price":"0.84","size":"1718.59","side":"BUY","hash":"f3a39e86c8784af7aab3d407c5f263d036327678","best_bid":"0.94","best_ask":"0.95"}],"timestamp":"1768250239863","event_type":"price_change"}}
{"schema_version":1,"source":"clob_ws_market","recv_ts_ns":1768250239894940815,"event_type":"price_change","market":"0xe51aa24ab1bbfefce466d642ad98587d13123e4ef95ec9aa73b712e775d4cbba","server_ts_ms":1768250239874,"raw":{"market":"0xe51aa24ab1bbfefce466d642ad98587d13123e4ef95ec9aa73b712e775d4cbba","price_changes":[{"asset_id":"54232589582260339592359130012520874109228367674780084862642636038394766871668","price":"0.03","size":"3112.6","side":"BUY","hash":"8ebdf7575617cc07de208b0a293dbb0cab37370b","best_bid":"0.05","best_ask":"0.06"},{"asset_id":"96886111393998001968863279421729456597655847484197549086072988901191634450924","price":"0.97","size":"3112.6","side":"SELL","hash":"ffb66f10368ced29ed598e27b77614748b1513b9","best_bid":"0.94","best_ask":"0.95"}],"timestamp":"1768250239874","event_type":"price_change"}}
{"schema_version":1,"source":"clob_ws_market","recv_ts_ns":1768250239953767292,"event_type":"price_change","market":"0xe51aa24ab1bbfefce466d642ad98587d13123e4ef95ec9aa73b712e775d4cbba","server_ts_ms":1768250239933,"raw":{"market":"0xe51aa24ab1bbfefce466d642ad98587d13123e4ef95ec9aa73b712e775d4cbba","price_changes":[{"asset_id":"54232589582260339592359130012520874109228367674780084862642636038394766871668","price":"0.03","size":"2112.6","side":"BUY","hash":"85cef7945dc76f6a8e50140628b8b3b1cb3db7e9","best_bid":"0.05","best_ask":"0.06"},{"asset_id":"96886111393998001968863279421729456597655847484197549086072988901191634450924","price":"0.97","size":"2112.6","side":"SELL","hash":"03efb547f0ecbc178cbec89dce60d84a54033c0f","best_bid":"0.94","best_ask":"0.95"}],"timestamp":"1768250239933","event_type":"price_change"}}
{"schema_version":1,"source":"clob_ws_market","recv_ts_ns":1768250239966096306,"event_type":"best_bid_ask","market":"0xe51aa24ab1bbfefce466d642ad98587d13123e4ef95ec9aa73b712e775d4cbba","server_ts_ms":1768250239945,"raw":{"market":"0xe51aa24ab1bbfefce466d642ad98587d13123e4ef95ec9aa73b712e775d4cbba","asset_id":"54232589582260339592359130012520874109228367674780084862642636038394766871668","best_bid":"0.05","best_ask":"0.06","spread":"0.01","timestamp":"1768250239945","event_type":"best_bid_ask"}}
{"schema_version":1,"source":"clob_ws_market","recv_ts_ns":1768250239972972944,"event_type":"price_change","market":"0xe51aa24ab1bbfefce466d642ad98587d13123e4ef95ec9aa73b712e775d4cbba","server_ts_ms":1768250239944,"raw":{"market":"0xe51aa24ab1bbfefce466d642ad98587d13123e4ef95ec9aa73b712e775d4cbba","price_changes":[{"asset_id":"96886111393998001968863279421729456597655847484197549086072988901191634450924","price":"0.94","size":"1252.54","side":"BUY","hash":"d786a9cb0ef6e844486cfab37887615ad76a30b0","best_bid":"0.94","best_ask":"0.95"},{"asset_id":"54232589582260339592359130012520874109228367674780084862642636038394766871668","price":"0.06","size":"1252.54","side":"SELL","hash":"70cb4d3a13b9c242668ec057eaad6123e8e01808","best_bid":"0.05","best_ask":"0.06"}],"timestamp":"1768250239944","event_type":"price_change"}}
{"schema_version":1,"source":"clob_ws_market","recv_ts_ns":1768250239979961695,"event_type":"book","market":"0xe51aa24ab1bbfefce466d642ad98587d13123e4ef95ec9aa73b712e775d4cbba","server_ts_ms":1768250239944,"raw":{"market":"0xe51aa24ab1bbfefce466d642ad98587d13123e4ef95ec9aa73b712e775d4cbba","asset_id":"54232589582260339592359130012520874109228367674780084862642636038394766871668","bids":[{"price":"0.01","size":"20993.9"},{"price":"0.02","size":"6562.25"},{"price":"0.03","size":"2112.6"},{"price":"0.04","size":"587.13"},{"price":"0.05","size":"1372.32"}],"asks":[{"price":"0.99","size":"24290.24"},{"price":"0.98","size":"7594.51"},{"price":"0.97","size":"5964.69"},{"price":"0.96","size":"5411.4"},{"price":"0.95","size":"5356.39"},{"price":"0.94","size":"5328"},{"price":"0.93","size":"5039.28"},{"price":"0.92","size":"5022.7"},{"price":"0.91","size":"5320.9"},{"price":"0.9","size":"5158.44"},{"price":"0.89","size":"18.3"},{"price":"0.88","size":"30.3"},{"price":"0.87","size":"16.5"},{"price":"0.86","size":"15.8"},{"price":"0.85","size":"104.19"},{"price":"0.84","size":"24.69"},{"price":"0.83","size":"14.19"},{"price":"0.82","size":"13.8"},{"price":"0.81","size":"13.4"},{"price":"0.8","size":"38.1"},{"price":"0.79","size":"12.8"},{"price":"0.78","size":"12.6"},{"price":"0.77","size":"12.3"},{"price":"0.76","size":"22.1"},{"price":"0.75","size":"16.9"},{"price":"0.74","size":"21.8"},{"price":"0.73","size":"11.6"},{"price":"0.72","size":"11.4"},{"price":"0.71","size":"61.3"},{"price":"0.7","size":"26.2"},{"price":"0.69","size":"11.1"},{"price":"0.68","size":"11"},{"price":"0.67","size":"110.9"},{"price":"0.66","size":"10.8"},{"price":"0.65","size":"15.7"},{"price":"0.64","size":"10.6"},{"price":"0.63","size":"10.6"},{"price":"0.62","size":"22.5"},{"price":"0.61","size":"10.5"},{"price":"0.6","size":"45.4"},{"price":"0.59","size":"311.4"},{"price":"0.58","size":"820.82"},{"price":"0.57","size":"826.3"},{"price":"0.56","size":"1062.3"},{"price":"0.55","size":"582.3"},{"price":"0.54","size":"626.2"},{"price":"0.53","size":"562.2"},{"price":"0.52","size":"567.2"},{"price":"0.51","size":"573.2"},{"price":"0.5","size":"917.2"},{"price":"0.49","size":"591.2"},{"price":"0.48","size":"596.2"},{"price":"0.47","size":"567.2"},{"price":"0.46","size":"636.61"},{"price":"0.45","size":"362.97"},{"price":"0.44","size":"341.3"},{"price":"0.43","size":"320.62"},{"price":"0.42","size":"567.3"},{"price":"0.41","size":"562.4"},{"price":"0.4","size":"693.02"},{"price":"0.39","size":"625.5"},{"price":"0.38","size":"636.5"},{"price":"0.37","size":"672.32"},{"price":"0.36","size":"680.6"},{"price":"0.35","size":"536.14"},{"price":"0.34","size":"602.8"},{"price":"0.33","size":"572.9"},{"price":"0.32","size":"573"},{"price":"0.31","size":"595.1"},{"price":"0.3","size":"603.2"},{"price":"0.29","size":"1318.72"},{"price":"0.28","size":"1043.04"},{"price":"0.27","size":"668.6"},{"price":"0.26","size":"911.17"},{"price":"0.25","size":"694.3"},{"price":"0.24","size":"717.6"},{"price":"0.23","size":"1183.3"},{"price":"0.22","size":"1526.53"},{"price":"0.21","size":"1178.8"},{"price":"0.2","size":"1445.08"},{"price":"0.19","size":"1229.8"},{"price":"0.18","size":"1467.57"},{"price":"0.17","size":"1520.51"},{"price":"0.16","size":"1718.59"},{"price":"0.15","size":"1810.78"},{"price":"0.14","size":"1506.7"},{"price":"0.13","size":"1588.93"},{"price":"0.12","size":"2555.4"},{"price":"0.11","size":"1792.8"},{"price":"0.1","size":"3416.54"},{"price":"0.09","size":"3012.44"},{"price":"0.08","size":"2724.36"},{"price":"0.07","size":"1654.82"},{"price":"0.06","size":"1252.54"}],"hash":"70cb4d3a13b9c242668ec057eaad6123e8e01808","timestamp":"1768250239944","event_type":"book"}}
{"schema_version":1,"source":"clob_ws_market","recv_ts_ns":1768250239989789150,"event_type":"price_change","market":"0xe51aa24ab1bbfefce466d642ad98587d13123e4ef95ec9aa73b712e775d4cbba","server_ts_ms":1768250239949,"raw":{"market":"0xe51aa24ab1bbfefce466d642ad98587d13123e4ef95ec9aa73b712e775d4cbba","price_changes":[{"asset_id":"54232589582260339592359130012520874109228367674780084862642636038394766871668","price":"0.14","size":"1755.6","side":"SELL","hash":"7e05f7e0396664124be696b8b974cbfd61c597b6","best_bid":"0.05","best_ask":"0.06"},{"asset_id":"96886111393998001968863279421729456597655847484197549086072988901191634450924","price":"0.86","size":"1755.6","side":"BUY","hash":"a7b8ee863f26c12c07f040a4a499d1e7d5677f57","best_bid":"0.94","best_ask":"0.95"}],"timestamp":"1768250239949","event_type":"price_change"}}
{"schema_version":1,"source":"clob_ws_market","recv_ts_ns":1768250239999113880,"event_type":"last_trade_price","market":"0xe51aa24ab1bbfefce466d642ad98587d13123e4ef95ec9aa73b712e775d4cbba","server_ts_ms":1768250239976,"raw":{"market":"0xe51aa24ab1bbfefce466d642ad98587d13123e4ef95ec9aa73b712e775d4cbba","asset_id":"54232589582260339592359130012520874109228367674780084862642636038394766871668","price":"0.06","size":"33.86","fee_rate_bps":"1000","side":"BUY","timestamp":"1768250239976","event_type":"last_trade_price","transaction_hash":"0x538227bc2e1163cd689b5b94fafc590453bede26e461ca804ee889560779dc0e"}}
{"schema_version":1,"source":"clob_ws_market","recv_ts_ns":1768250240027507328,"event_type":"price_change","market":"0xe51aa24ab1bbfefce466d642ad98587d13123e4ef95ec9aa73b712e775d4cbba","server_ts_ms":1768250240000,"raw":{"market":"0xe51aa24ab1bbfefce466d642ad98587d13123e4ef95ec9aa73b712e775d4cbba","price_changes":[{"asset_id":"54232589582260339592359130012520874109228367674780084862642636038394766871668","price":"0.02","size":"6462.25","side":"BUY","hash":"7f417d7e4e385b40ed961ecf1fee413f335d5bdb","best_bid":"0.05","best_ask":"0.06"},{"asset_id":"96886111393998001968863279421729456597655847484197549086072988901191634450924","price":"0.98","size":"6462.25","side":"SELL","hash":"93f04a8b61e6f4d41dfe52403db74fb29ad6ded8","best_bid":"0.94","best_ask":"0.95"}],"timestamp":"1768250240000","event_type":"price_change"}}
{"schema_version":1,"source":"clob_ws_market","recv_ts_ns":1768250240076946067,"event_type":"price_change","market":"0xe51aa24ab1bbfefce466d642ad98587d13123e4ef95ec9aa73b712e775d4cbba","server_ts_ms":1768250240037,"raw":{"market":"0xe51aa24ab1bbfefce466d642ad98587d13123e4ef95ec9aa73b712e775d4cbba","price_changes":[{"asset_id":"54232589582260339592359130012520874109228367674780084862642636038394766871668","price":"0.06","size":"1263.54","side":"SELL","hash":"97c1f3d58103171742191a8c7f89ef73bfd213d4","best_bid":"0.05","best_ask":"0.06"},{"asset_id":"96886111393998001968863279421729456597655847484197549086072988901191634450924","price":"0.94","size":"1263.54","side":"BUY","hash":"7a8f5ea4a9f2488a3497adbde474b2ad341e44fc","best_bid":"0.94","best_ask":"0.95"}],"timestamp":"1768250240037","event_type":"price_change"}}
{"schema_version":1,"source":"clob_ws_market","recv_ts_ns":1768250240082976657,"event_type":"price_change","market":"0xe51aa24ab1bbfefce466d642ad98587d13123e4ef95ec9aa73b712e775d4cbba","server_ts_ms":1768250240039,"raw":{"market":"0xe51aa24ab1bbfefce466d642ad98587d13123e4ef95ec9aa73b712e775d4cbba","price_changes":[{"asset_id":"96886111393998001968863279421729456597655847484197549086072988901191634450924","price":"0.94","size":"1275.54","side":"BUY","hash":"2d059e6fc87dc85e75f2e6bf123f86f89a6a2064","best_bid":"0.94","best_ask":"0.95"},{"asset_id":"54232589582260339592359130012520874109228367674780084862642636038394766871668","price":"0.06","size":"1275.54","side":"SELL","hash":"0152c0512b98c21541c1d9b1a0bf81ad34263f0e","best_bid":"0.05","best_ask":"0.06"}],"timestamp":"1768250240039","event_type":"price_change"}}
{"schema_version":1,"source":"clob_ws_market","recv_ts_ns":1768250240097084138,"event_type":"price_change","market":"0xe51aa24ab1bbfefce466d642ad98587d13123e4ef95ec9aa73b712e775d4cbba","server_ts_ms":1768250240072,"raw":{"market":"0xe51aa24ab1bbfefce466d642ad98587d13123e4ef95ec9aa73b712e775d4cbba","price_changes":[{"asset_id":"54232589582260339592359130012520874109228367674780084862642636038394766871668","price":"0.02","size":"6562.25","side":"BUY","hash":"672a9eda49336309f0e5bfd29e210ccff1c6c857","best_bid":"0.05","best_ask":"0.06"},{"asset_id":"96886111393998001968863279421729456597655847484197549086072988901191634450924","price":"0.98","size":"6562.25","side":"SELL","hash":"f4cf128e957b3eb1ab8893d0875c42f23885ba11","best_bid":"0.94","best_ask":"0.95"}],"timestamp":"1768250240072","event_type":"price_change"}}
{"schema_version":1,"source":"clob_ws_market","recv_ts_ns":1768250240155593701,"event_type":"best_bid_ask","market":"0xe51aa24ab1bbfefce466d642ad98587d13123e4ef95ec9aa73b712e775d4cbba","server_ts_ms":1768250240123,"raw":{"market":"0xe51aa24ab1bbfefce466d642ad98587d13123e4ef95ec9aa73b712e775d4cbba","asset_id":"54232589582260339592359130012520874109228367674780084862642636038394766871668","best_bid":"0.05","best_ask":"0.06","spread":"0.01","timestamp":"1768250240123","event_type":"best_bid_ask"}}
{"schema_version":1,"source":"clob_ws_market","recv_ts_ns":1768250240160985878,"event_type":"price_change","market":"0xe51aa24ab1bbfefce466d642ad98587d13123e4ef95ec9aa73b712e775d4cbba","server_ts_ms":1768250240121,"raw":{"market":"0xe51aa24ab1bbfefce466d642ad98587d13123e4ef95ec9aa73b712e775d4cbba","price_changes":[{"asset_id":"96886111393998001968863279421729456597655847484197549086072988901191634450924","price":"0.94","size":"1165.22","side":"BUY","hash":"57a938f6d513522348a321f509d0d6a3ada0a9f2","best_bid":"0.94","best_ask":"0.95"},{"asset_id":"54232589582260339592359130012520874109228367674780084862642636038394766871668","price":"0.06","size":"1165.22","side":"SELL","hash":"55c1b9b646aac13edfd1d351ae57059aa19a4917","best_bid":"0.05","best_ask":"0.06"}],"timestamp":"1768250240121","event_type":"price_change"}}
{"schema_version":1,"source":"clob_ws_market","recv_ts_ns":1768250240168240203,"event_type":"book","market":"0xe51aa24ab1bbfefce466d642ad98587d13123e4ef95ec9aa73b712e775d4cbba","server_ts_ms":1768250240121,"raw":{"market":"0xe51aa24ab1bbfefce466d642ad98587d13123e4ef95ec9aa73b712e775d4cbba","asset_id":"54232589582260339592359130012520874109228367674780084862642636038394766871668","bids":[{"price":"0.01","size":"20993.9"},{"price":"0.02","size":"6562.25"},{"price":"0.03","size":"2112.6"},{"price":"0.04","size":"587.13"},{"price":"0.05","size":"1372.32"}],"asks":[{"price":"0.99","size":"24290.24"},{"price":"0.98","size":"7594.51"},{"price":"0.97","size":"5964.69"},{"price":"0.96","size":"5411.4"},{"price":"0.95","size":"5356.39"},{"price":"0.94","size":"5328"},{"price":"0.93","size":"5039.28"},{"price":"0.92","size":"5022.7"},{"price":"0.91","size":"5320.9"},{"price":"0.9","size":"5158.44"},{"price":"0.89","size":"18.3"},{"price":"0.88","size":"30.3"},{"price":"0.87","size":"16.5"},{"price":"0.86","size":"15.8"},{"price":"0.85","size":"104.19"},{"price":"0.84","size":"24.69"},{"price":"0.83","size":"14.19"},{"price":"0.82","size":"13.8"},{"price":"0.81","size":"13.4"},{"price":"0.8","size":"38.1"},{"price":"0.79","size":"12.8"},{"price":"0.78","size":"12.6"},{"price":"0.77","size":"12.3"},{"price":"0.76","size":"22.1"},{"price":"0.75","size":"16.9"},{"price":"0.74","size":"21.8"},{"price":"0.73","size":"11.6"},{"price":"0.72","size":"11.4"},{"price":"0.71","size":"61.3"},{"price":"0.7","size":"26.2"},{"price":"0.69","size":"11.1"},{"price":"0.68","size":"11"},{"price":"0.67","size":"110.9"},{"price":"0.66","size":"10.8"},{"price":"0.65","size":"15.7"},{"price":"0.64","size":"10.6"},{"price":"0.63","size":"10.6"},{"price":"0.62","size":"22.5"},{"price":"0.61","size":"10.5"},{"price":"0.6","size":"45.4"},{"price":"0.59","size":"311.4"},{"price":"0.58","size":"820.82"},{"price":"0.57","size":"826.3"},{"price":"0.56","size":"1062.3"},{"price":"0.55","size":"582.3"},{"price":"0.54","size":"626.2"},{"price":"0.53","size":"562.2"},{"price":"0.52","size":"567.2"},{"price":"0.51","size":"573.2"},{"price":"0.5","size":"917.2"},{"price":"0.49","size":"591.2"},{"price":"0.48","size":"596.2"},{"price":"0.47","size":"567.2"},{"price":"0.46","size":"636.61"},{"price":"0.45","size":"362.97"},{"price":"0.44","size":"341.3"},{"price":"0.43","size":"320.62"},{"price":"0.42","size":"567.3"},{"price":"0.41","size":"562.4"},{"price":"0.4","size":"693.02"},{"price":"0.39","size":"625.5"},{"price":"0.38","size":"636.5"},{"price":"0.37","size":"672.32"},{"price":"0.36","size":"680.6"},{"price":"0.35","size":"536.14"},{"price":"0.34","size":"602.8"},{"price":"0.33","size":"572.9"},{"price":"0.32","size":"573"},{"price":"0.31","size":"595.1"},{"price":"0.3","size":"603.2"},{"price":"0.29","size":"1318.72"},{"price":"0.28","size":"1043.04"},{"price":"0.27","size":"668.6"},{"price":"0.26","size":"911.17"},{"price":"0.25","size":"694.3"},{"price":"0.24","size":"717.6"},{"price":"0.23","size":"1183.3"},{"price":"0.22","size":"1526.53"},{"price":"0.21","size":"1178.8"},{"price":"0.2","size":"1445.08"},{"price":"0.19","size":"1229.8"},{"price":"0.18","size":"1467.57"},{"price":"0.17","size":"1520.51"},{"price":"0.16","size":"1718.59"},{"price":"0.15","size":"1810.78"},{"price":"0.14","size":"1755.6"},{"price":"0.13","size":"1588.93"},{"price":"0.12","size":"2555.4"},{"price":"0.11","size":"1792.8"},{"price":"0.1","size":"3416.54"},{"price":"0.09","size":"3012.44"},{"price":"0.08","size":"2724.36"},{"price":"0.07","size":"1654.82"},{"price":"0.06","size":"1165.22"}],"hash":"55c1b9b646aac13edfd1d351ae57059aa19a4917","timestamp":"1768250240121","event_type":"book"}}
{"schema_version":1,"source":"clob_ws_market","recv_ts_ns":1768250240187203379,"event_type":"best_bid_ask","market":"0xe51aa24ab1bbfefce466d642ad98587d13123e4ef95ec9aa73b712e775d4cbba","server_ts_ms":1768250240166,"raw":{"market":"0xe51aa24ab1bbfefce466d642ad98587d13123e4ef95ec9aa73b712e775d4cbba","asset_id":"54232589582260339592359130012520874109228367674780084862642636038394766871668","best_bid":"0.05","best_ask":"0.06","spread":"0.01","timestamp":"1768250240166","event_type":"best_bid_ask"}}
{"schema_version":1,"source":"clob_ws_market","recv_ts_ns":1768250240192397354,"event_type":"price_change","market":"0xe51aa24ab1bbfefce466d642ad98587d13123e4ef95ec9aa73b712e775d4cbba","server_ts_ms":1768250240164,"raw":{"market":"0xe51aa24ab1bbfefce466d642ad98587d13123e4ef95ec9aa73b712e775d4cbba","price_changes":[{"asset_id":"54232589582260339592359130012520874109228367674780084862642636038394766871668","price":"0.05","size":"1340.99","side":"BUY","hash":"f019eadec7cc6ac0e97d63279fa9fc4a068ce21e","best_bid":"0.05","best_ask":"0.06"},{"asset_id":"96886111393998001968863279421729456597655847484197549086072988901191634450924","price":"0.95","size":"1340.99","side":"SELL","hash":"0100d866f9cf196df217d610605a7d8fad96f432","best_bid":"0.94","best_ask":"0.95"}],"timestamp":"1768250240164","event_type":"price_change"}}
{"schema_version":1,"source":"clob_ws_market","recv_ts_ns":1768250240197233232,"event_type":"book","market":"0xe51aa24ab1bbfefce466d642ad98587d13123e4ef95ec9aa73b712e775d4cbba","server_ts_ms":1768250240164,"raw":{"market":"0xe51aa24ab1bbfefce466d642ad98587d13123e4ef95ec9aa73b712e775d4cbba","asset_id":"54232589582260339592359130012520874109228367674780084862642636038394766871668","bids":[{"price":"0.01","size":"20993.9"},{"price":"0.02","size":"6562.25"},{"price":"0.03","size":"2112.6"},{"price":"0.04","size":"587.13"},{"price":"0.05","size":"1340.99"}],"asks":[{"price":"0.99","size":"24290.24"},{"price":"0.98","size":"7594.51"},{"price":"0.97","size":"5964.69"},{"price":"0.96","size":"5411.4"},{"price":"0.95","size":"5356.39"},{"price":"0.94","size":"5328"},{"price":"0.93","size":"5039.28"},{"price":"0.92","size":"5022.7"},{"price":"0.91","size":"5320.9"},{"price":"0.9","size":"5158.44"},{"price":"0.89","size":"18.3"},{"price":"0.88","size":"30.3"},{"price":"0.87","size":"16.5"},{"price":"0.86","size":"15.8"},{"price":"0.85","size":"104.19"},{"price":"0.84","size":"24.69"},{"price":"0.83","size":"14.19"},{"price":"0.82","size":"13.8"},{"price":"0.81","size":"13.4"},{"price":"0.8","size":"38.1"},{"price":"0.79","size":"12.8"},{"price":"0.78","size":"12.6"},{"price":"0.77","size":"12.3"},{"price":"0.76","size":"22.1"},{"price":"0.75","size":"16.9"},{"price":"0.74","size":"21.8"},{"price":"0.73","size":"11.6"},{"price":"0.72","size":"11.4"},{"price":"0.71","size":"61.3"},{"price":"0.7","size":"26.2"},{"price":"0.69","size":"11.1"},{"price":"0.68","size":"11"},{"price":"0.67","size":"110.9"},{"price":"0.66","size":"10.8"},{"price":"0.65","size":"15.7"},{"price":"0.64","size":"10.6"},{"price":"0.63","size":"10.6"},{"price":"0.62","size":"22.5"},{"price":"0.61","size":"10.5"},{"price":"0.6","size":"45.4"},{"price":"0.59","size":"311.4"},{"price":"0.58","size":"820.82"},{"price":"0.57","size":"826.3"},{"price":"0.56","size":"1062.3"},{"price":"0.55","size":"582.3"},{"price":"0.54","size":"626.2"},{"price":"0.53","size":"562.2"},{"price":"0.52","size":"567.2"},{"price":"0.51","size":"573.2"},{"price":"0.5","size":"917.2"},{"price":"0.49","size":"591.2"},{"price":"0.48","size":"596.2"},{"price":"0.47","size":"567.2"},{"price":"0.46","size":"636.61"},{"price":"0.45","size":"362.97"},{"price":"0.44","size":"341.3"},{"price":"0.43","size":"320.62"},{"price":"0.42","size":"567.3"},{"price":"0.41","size":"562.4"},{"price":"0.4","size":"693.02"},{"price":"0.39","size":"625.5"},{"price":"0.38","size":"636.5"},{"price":"0.37","size":"672.32"},{"price":"0.36","size":"680.6"},{"price":"0.35","size":"536.14"},{"price":"0.34","size":"602.8"},{"price":"0.33","size":"572.9"},{"price":"0.32","size":"573"},{"price":"0.31","size":"595.1"},{"price":"0.3","size":"603.2"},{"price":"0.29","size":"1318.72"},{"price":"0.28","size":"1043.04"},{"price":"0.27","size":"668.6"},{"price":"0.26","size":"911.17"},{"price":"0.25","size":"694.3"},{"price":"0.24","size":"717.6"},{"price":"0.23","size":"1183.3"},{"price":"0.22","size":"1526.53"},{"price":"0.21","size":"1178.8"},{"price":"0.2","size":"1445.08"},{"price":"0.19","size":"1229.8"},{"price":"0.18","size":"1467.57"},{"price":"0.17","size":"1520.51"},{"price":"0.16","size":"1718.59"},{"price":"0.15","size":"1810.78"},{"price":"0.14","size":"1755.6"},{"price":"0.13","size":"1588.93"},{"price":"0.12","size":"2555.4"},{"price":"0.11","size":"1792.8"},{"price":"0.1","size":"3416.54"},{"price":"0.09","size":"3012.44"},{"price":"0.08","size":"2724.36"},{"price":"0.07","size":"1654.82"},{"price":"0.06","size":"1165.22"}],"hash":"f019eadec7cc6ac0e97d63279fa9fc4a068ce21e","timestamp":"1768250240164","event_type":"book"}}
{"schema_version":1,"source":"clob_ws_market","recv_ts_ns":1768250240206163076,"event_type":"price_change","market":"0xe51aa24ab1bbfefce466d642ad98587d13123e4ef95ec9aa73b712e775d4cbba","server_ts_ms":1768250240173,"raw":{"market":"0xe51aa24ab1bbfefce466d642ad98587d13123e4ef95ec9aa73b712e775d4cbba","price_changes":[{"asset_id":"54232589582260339592359130012520874109228367674780084862642636038394766871668","price":"0.06","size":"1154.22","side":"SELL","hash":"2ac3fa907f422b8749a3e37a4e17ccf5fbb37b00","best_bid":"0.05","best_ask":"0.06"},{"asset_id":"96886111393998001968863279421729456597655847484197549086072988901191634450924","price":"0.94","size":"1154.22","side":"BUY","hash":"c54648ee60d97405683c63652796db5659870dc9","best_bid":"0.94","best_ask":"0.95"}],"timestamp":"1768250240173","event_type":"price_change"}}
{"schema_version":1,"source":"clob_ws_market","recv_ts_ns":1768250240253022209,"event_type":"price_change","market":"0xe51aa24ab1bbfefce466d642ad98587d13123e4ef95ec9aa73b712e775d4cbba","server_ts_ms":1768250240230,"raw":{"market":"0xe51aa24ab1bbfefce466d642ad98587d13123e4ef95ec9aa73b712e775d4cbba","price_changes":[{"asset_id":"96886111393998001968863279421729456597655847484197549086072988901191634450924","price":"0.94","size":"1142.22","side":"BUY","hash":"5001ef3a4f6d5ee4d683505f75561941db9529a4","best_bid":"0.94","best_ask":"0.95"},{"asset_id":"54232589582260339592359130012520874109228367674780084862642636038394766871668","price":"0.06","size":"1142.22","side":"SELL","hash":"6392052547910090563574582b3ab7b5faf53a2a","best_bid":"0.05","best_ask":"0.06"}],"timestamp":"1768250240230","event_type":"price_change"}}
{"schema_version":1,"source":"clob_ws_market","recv_ts_ns":1768250240324201211,"event_type":"price_change","market":"0xe51aa24ab1bbfefce466d642ad98587d13123e4ef95ec9aa73b712e775d4cbba","server_ts_ms":1768250240301,"raw":{"market":"0xe51aa24ab1bbfefce466d642ad98587d13123e4ef95ec9aa73b712e775d4cbba","price_changes":[{"asset_id":"96886111393998001968863279421729456597655847484197549086072988901191634450924","price":"0.73","size":"663.6","side":"BUY","hash":"a49e43b3b0643f002280c248b903fed18e8c5041","best_bid":"0.94","best_ask":"0.95"},{"asset_id":"54232589582260339592359130012520874109228367674780084862642636038394766871668","price":"0.27","size":"663.6","side":"SELL","hash":"d7274aa891cbe1ab01c47bc91c0e4212f6428e6a","best_bid":"0.05","best_ask":"0.06"}],"timestamp":"1768250240301","event_type":"price_change"}}
{"schema_version":1,"source":"clob_ws_market","recv_ts_ns":1768250240422389593,"event_type":"price_change","market":"0xe51aa24ab1bbfefce466d642ad98587d13123e4ef95ec9aa73b712e775d4cbba","server_ts_ms":1768250240396,"raw":{"market":"0xe51aa24ab1bbfefce466d642ad98587d13123e4ef95ec9aa73b712e775d4cbba","price_changes":[{"asset_id":"96886111393998001968863279421729456597655847484197549086072988901191634450924","price":"0.96","size":"558.13","side":"SELL","hash":"0742a4ea40a995b433f6b5dfb58c2c211d55e52c","best_bid":"0.94","best_ask":"0.95"},{"asset_id":"54232589582260339592359130012520874109228367674780084862642636038394766871668","price":"0.04","size":"558.13","side":"BUY","hash":"50547787a026526a0125cc3f8b3bc812f7450729","best_bid":"0.05","best_ask":"0.06"}],"timestamp":"1768250240396","event_type":"price_change"}}
{"schema_version":1,"source":"clob_ws_market","recv_ts_ns":1768250240438832960,"event_type":"price_change","market":"0xe51aa24ab1bbfefce466d642ad98587d13123e4ef95ec9aa73b712e775d4cbba","server_ts_ms":1768250240418,"raw":{"market":"0xe51aa24ab1bbfefce466d642ad98587d13123e4ef95ec9aa73b712e775d4cbba","price_changes":[{"asset_id":"54232589582260339592359130012520874109228367674780084862642636038394766871668","price":"0.02","size":"6534.25","side":"BUY","hash":"47cd7816c87669fde7c70328c671d72ee6d77a30","best_bid":"0.05","best_ask":"0.06"},{"asset_id":"96886111393998001968863279421729456597655847484197549086072988901191634450924","price":"0.98","size":"6534.25","side":"SELL","hash":"8e05fd2bf9dc44dee77b646f4b35e5fd03c10fc8","best_bid":"0.94","best_ask":"0.95"}],"timestamp":"1768250240418","event_type":"price_change"}}
{"schema_version":1,"source":"clob_ws_market","recv_ts_ns":1768250240481281768,"event_type":"price_change","market":"0xe51aa24ab1bbfefce466d642ad98587d13123e4ef95ec9aa73b712e775d4cbba","server_ts_ms":1768250240459,"raw":{"market":"0xe51aa24ab1bbfefce466d642ad98587d13123e4ef95ec9aa73b712e775d4cbba","price_changes":[{"asset_id":"54232589582260339592359130012520874109228367674780084862642636038394766871668","price":"0.02","size":"6563.25","side":"BUY","hash":"a13ec9444f473908c109bdd7bb497c04f804ed71","best_bid":"0.05","best_ask":"0.06"},{"asset_id":"96886111393998001968863279421729456597655847484197549086072988901191634450924","price":"0.98","size":"6563.25","side":"SELL","hash":"a673ddbed9e48d40da24a0dfe4240c50e1eb690c","best_bid":"0.94","best_ask":"0.95"}],"timestamp":"1768250240459","event_type":"price_change"}}
{"schema_version":1,"source":"clob_ws_market","recv_ts_ns":1768250240588881734,"event_type":"best_bid_ask","market":"0xe51aa24ab1bbfefce466d642ad98587d13123e4ef95ec9aa73b712e775d4cbba","server_ts_ms":1768250240568,"raw":{"market":"0xe51aa24ab1bbfefce466d642ad98587d13123e4ef95ec9aa73b712e775d4cbba","asset_id":"54232589582260339592359130012520874109228367674780084862642636038394766871668","best_bid":"0.05","best_ask":"0.06","spread":"0.01","timestamp":"1768250240568","event_type":"best_bid_ask"}}
{"schema_version":1,"source":"clob_ws_market","recv_ts_ns":1768250240596360675,"event_type":"price_change","market":"0xe51aa24ab1bbfefce466d642ad98587d13123e4ef95ec9aa73b712e775d4cbba","server_ts_ms":1768250240566,"raw":{"market":"0xe51aa24ab1bbfefce466d642ad98587d13123e4ef95ec9aa73b712e775d4cbba","price_changes":[{"asset_id":"54232589582260339592359130012520874109228367674780084862642636038394766871668","price":"0.05","size":"1332.99","side":"BUY","hash":"500e50a93496e60e3e3662985938e54d68215975","best_bid":"0.05","best_ask":"0.06"},{"asset_id":"96886111393998001968863279421729456597655847484197549086072988901191634450924","price":"0.95","size":"1332.99","side":"SELL","hash":"0fd2461a058a862998fc86158d0cb14d718c7bb9","best_bid":"0.94","best_ask":"0.95"}],"timestamp":"1768250240566","event_type":"price_change"}}
{"schema_version":1,"source":"clob_ws_market","recv_ts_ns":1768250240602121947,"event_type":"book","market":"0xe51aa24ab1bbfefce466d642ad98587d13123e4ef95ec9aa73b712e775d4cbba","server_ts_ms":1768250240566,"raw":{"market":"0xe51aa24ab1bbfefce466d642ad98587d13123e4ef95ec9aa73b712e775d4cbba","asset_id":"54232589582260339592359130012520874109228367674780084862642636038394766871668","bids":[{"price":"0.01","size":"20993.9"},{"price":"0.02","size":"6563.25"},{"price":"0.03","size":"2112.6"},{"price":"0.04","size":"558.13"},{"price":"0.05","size":"1332.99"}],"asks":[{"price":"0.99","size":"24290.24"},{"price":"0.98","size":"7594.51"},{"price":"0.97","size":"5964.69"},{"price":"0.96","size":"5411.4"},{"price":"0.95","size":"5356.39"},{"price":"0.94","size":"5328"},{"price":"0.93","size":"5039.28"},{"price":"0.92","size":"5022.7"},{"price":"0.91","size":"5320.9"},{"price":"0.9","size":"5158.44"},{"price":"0.89","size":"18.3"},{"price":"0.88","size":"30.3"},{"price":"0.87","size":"16.5"},{"price":"0.86","size":"15.8"},{"price":"0.85","size":"104.19"},{"price":"0.84","size":"24.69"},{"price":"0.83","size":"14.19"},{"price":"0.82","size":"13.8"},{"price":"0.81","size":"13.4"},{"price":"0.8","size":"38.1"},{"price":"0.79","size":"12.8"},{"price":"0.78","size":"12.6"},{"price":"0.77","size":"12.3"},{"price":"0.76","size":"22.1"},{"price":"0.75","size":"16.9"},{"price":"0.74","size":"21.8"},{"price":"0.73","size":"11.6"},{"price":"0.72","size":"11.4"},{"price":"0.71","size":"61.3"},{"price":"0.7","size":"26.2"},{"price":"0.69","size":"11.1"},{"price":"0.68","size":"11"},{"price":"0.67","size":"110.9"},{"price":"0.66","size":"10.8"},{"price":"0.65","size":"15.7"},{"price":"0.64","size":"10.6"},{"price":"0.63","size":"10.6"},{"price":"0.62","size":"22.5"},{"price":"0.61","size":"10.5"},{"price":"0.6","size":"45.4"},{"price":"0.59","size":"311.4"},{"price":"0.58","size":"820.82"},{"price":"0.57","size":"826.3"},{"price":"0.56","size":"1062.3"},{"price":"0.55","size":"582.3"},{"price":"0.54","size":"626.2"},{"price":"0.53","size":"562.2"},{"price":"0.52","size":"567.2"},{"price":"0.51","size":"573.2"},{"price":"0.5","size":"917.2"},{"price":"0.49","size":"591.2"},{"price":"0.48","size":"596.2"},{"price":"0.47","size":"567.2"},{"price":"0.46","size":"636.61"},{"price":"0.45","size":"362.97"},{"price":"0.44","size":"341.3"},{"price":"0.43","size":"320.62"},{"price":"0.42","size":"567.3"},{"price":"0.41","size":"562.4"},{"price":"0.4","size":"693.02"},{"price":"0.39","size":"625.5"},{"price":"0.38","size":"636.5"},{"price":"0.37","size":"672.32"},{"price":"0.36","size":"680.6"},{"price":"0.35","size":"536.14"},{"price":"0.34","size":"602.8"},{"price":"0.33","size":"572.9"},{"price":"0.32","size":"573"},{"price":"0.31","size":"595.1"},{"price":"0.3","size":"603.2"},{"price":"0.29","size":"1318.72"},{"price":"0.28","size":"1043.04"},{"price":"0.27","size":"663.6"},{"price":"0.26","size":"911.17"},{"price":"0.25","size":"694.3"},{"price":"0.24","size":"717.6"},{"price":"0.23","size":"1183.3"},{"price":"0.22","size":"1526.53"},{"price":"0.21","size":"1178.8"},{"price":"0.2","size":"1445.08"},{"price":"0.19","size":"1229.8"},{"price":"0.18","size":"1467.57"},{"price":"0.17","size":"1520.51"},{"price":"0.16","size":"1718.59"},{"price":"0.15","size":"1810.78"},{"price":"0.14","size":"1755.6"},{"price":"0.13","size":"1588.93"},{"price":"0.12","size":"2555.4"},{"price":"0.11","size":"1792.8"},{"price":"0.1","size":"3416.54"},{"price":"0.09","size":"3012.44"},{"price":"0.08","size":"2724.36"},{"price":"0.07","size":"1654.82"},{"price":"0.06","size":"1142.22"}],"hash":"500e50a93496e60e3e3662985938e54d68215975","timestamp":"1768250240566","event_type":"book"}}
{"schema_version":1,"source":"clob_ws_market","recv_ts_ns":1768250240608669545,"event_type":"price_change","market":"0xe51aa24ab1bbfefce466d642ad98587d13123e4ef95ec9aa73b712e775d4cbba","server_ts_ms":1768250240584,"raw":{"market":"0xe51aa24ab1bbfefce466d642ad98587d13123e4ef95ec9aa73b712e775d4cbba","price_changes":[{"asset_id":"54232589582260339592359130012520874109228367674780084862642636038394766871668","price":"0.04","size":"522.13","side":"BUY","hash":"4e001c60dd63bcff62bceec7e058982b58173893","best_bid":"0.05","best_ask":"0.06"},{"asset_id":"96886111393998001968863279421729456597655847484197549086072988901191634450924","price":"0.96","size":"522.13","side":"SELL","hash":"0fc4aaa61a45ccf03f2adaa15e00e06ce2ddc7f8","best_bid":"0.94","best_ask":"0.95"}],"timestamp":"1768250240584","event_type":"price_change"}}
{"schema_version":1,"source":"clob_ws_market","recv_ts_ns":1768250240624601994,"event_type":"price_change","market":"0xe51aa24ab1bbfefce466d642ad98587d13123e4ef95ec9aa73b712e775d4cbba","server_ts_ms":1768250240603,"raw":{"market":"0xe51aa24ab1bbfefce466d642ad98587d13123e4ef95ec9aa73b712e775d4cbba","price_changes":[{"asset_id":"54232589582260339592359130012520874109228367674780084862642636038394766871668","price":"0.02","size":"6534.25","side":"BUY","hash":"eb60c6bc25b3cc2317cd61ac7631b063e43fd1de","best_bid":"0.05","best_ask":"0.06"},{"asset_id":"96886111393998001968863279421729456597655847484197549086072988901191634450924","price":"0.98","size":"6534.25","side":"SELL","hash":"88efae7bc2e7d271aacda31ed2cd877da59a4d5c","best_bid":"0.94","best_ask":"0.95"}],"timestamp":"1768250240603","event_type":"price_change"}}
{"schema_version":1,"source":"clob_ws_market","recv_ts_ns":1768250240668770383,"event_type":"price_change","market":"0xe51aa24ab1bbfefce466d642ad98587d13123e4ef95ec9aa73b712e775d4cbba","server_ts_ms":1768250240645,"raw":{"market":"0xe51aa24ab1bbfefce466d642ad98587d13123e4ef95ec9aa73b712e775d4cbba","price_changes":[{"asset_id":"54232589582260339592359130012520874109228367674780084862642636038394766871668","price":"0.01","size":"21023.9","side":"BUY","hash":"8ef7c3e02df81b61e521dcf94e14224c9878ca2e","best_bid":"0.05","best_ask":"0.06"},{"asset_id":"96886111393998001968863279421729456597655847484197549086072988901191634450924","price":"0.99","size":"21023.9","side":"SELL","hash":"dca1b3eaf8576099daa6f0bd4076a4f698d9ec37","best_bid":"0.94","best_ask":"0.95"}],"timestamp":"1768250240645","event_type":"price_change"}}
{"schema_version":1,"source":"clob_ws_market","recv_ts_ns":1768250240869822150,"event_type":"best_bid_ask","market":"0xe51aa24ab1bbfefce466d642ad98587d13123e4ef95ec9aa73b712e775d4cbba","server_ts_ms":1768250240847,"raw":{"market":"0xe51aa24ab1bbfefce466d642ad98587d13123e4ef95ec9aa73b712e775d4cbba","asset_id":"54232589582260339592359130012520874109228367674780084862642636038394766871668","best_bid":"0.05","best_ask":"0.06","spread":"0.01","timestamp":"1768250240847","event_type":"best_bid_ask"}}
{"schema_version":1,"source":"clob_ws_market","recv_ts_ns":1768250240875396714,"event_type":"price_change","market":"0xe51aa24ab1bbfefce466d642ad98587d13123e4ef95ec9aa73b712e775d4cbba","server_ts_ms":1768250240845,"raw":{"market":"0xe51aa24ab1bbfefce466d642ad98587d13123e4ef95ec9aa73b712e775d4cbba","price_changes":[{"asset_id":"96886111393998001968863279421729456597655847484197549086072988901191634450924","price":"0.94","size":"1137.22","side":"BUY","hash":"da682f676551ab1346202fbbab2f6b09ef1456b4","best_bid":"0.94","best_ask":"0.95"},{"asset_id":"54232589582260339592359130012520874109228367674780084862642636038394766871668","price":"0.06","size":"1137.22","side":"SELL","hash":"c6c71f2bfb89217faa3afcf69e404104c232c79d","best_bid":"0.05","best_ask":"0.06"}],"timestamp":"1768250240845","event_type":"price_change"}}
{"schema_version":1,"source":"clob_ws_market","recv_ts_ns":1768250240881743440,"event_type":"book","market":"0xe51aa24ab1bbfefce466d642ad98587d13123e4ef95ec9aa73b712e775d4cbba","server_ts_ms":1768250240845,"raw":{"market":"0xe51aa24ab1bbfefce466d642ad98587d13123e4ef95ec9aa73b712e775d4cbba","asset_id":"54232589582260339592359130012520874109228367674780084862642636038394766871668","bids":[{"price":"0.01","size":"21023.9"},{"price":"0.02","size":"6534.25"},{"price":"0.03","size":"2112.6"},{"price":"0.04","size":"522.13"},{"price":"0.05","size":"1332.99"}],"asks":[{"price":"0.99","size":"24290.24"},{"price":"0.98","size":"7594.51"},{"price":"0.97","size":"5964.69"},{"price":"0.96","size":"5411.4"},{"price":"0.95","size":"5356.39"},{"price":"0.94","size":"5328"},{"price":"0.93","size":"5039.28"},{"price":"0.92","size":"5022.7"},{"price":"0.91","size":"5320.9"},{"price":"0.9","size":"5158.44"},{"price":"0.89","size":"18.3"},{"price":"0.88","size":"30.3"},{"price":"0.87","size":"16.5"},{"price":"0.86","size":"15.8"},{"price":"0.85","size":"104.19"},{"price":"0.84","size":"24.69"},{"price":"0.83","size":"14.19"},{"price":"0.82","size":"13.8"},{"price":"0.81","size":"13.4"},{"price":"0.8","size":"38.1"},{"price":"0.79","size":"12.8"},{"price":"0.78","size":"12.6"},{"price":"0.77","size":"12.3"},{"price":"0.76","size":"22.1"},{"price":"0.75","size":"16.9"},{"price":"0.74","size":"21.8"},{"price":"0.73","size":"11.6"},{"price":"0.72","size":"11.4"},{"price":"0.71","size":"61.3"},{"price":"0.7","size":"26.2"},{"price":"0.69","size":"11.1"},{"price":"0.68","size":"11"},{"price":"0.67","size":"110.9"},{"price":"0.66","size":"10.8"},{"price":"0.65","size":"15.7"},{"price":"0.64","size":"10.6"},{"price":"0.63","size":"10.6"},{"price":"0.62","size":"22.5"},{"price":"0.61","size":"10.5"},{"price":"0.6","size":"45.4"},{"price":"0.59","size":"311.4"},{"price":"0.58","size":"820.82"},{"price":"0.57","size":"826.3"},{"price":"0.56","size":"1062.3"},{"price":"0.55","size":"582.3"},{"price":"0.54","size":"626.2"},{"price":"0.53","size":"562.2"},{"price":"0.52","size":"567.2"},{"price":"0.51","size":"573.2"},{"price":"0.5","size":"917.2"},{"price":"0.49","size":"591.2"},{"price":"0.48","size":"596.2"},{"price":"0.47","size":"567.2"},{"price":"0.46","size":"636.61"},{"price":"0.45","size":"362.97"},{"price":"0.44","size":"341.3"},{"price":"0.43","size":"320.62"},{"price":"0.42","size":"567.3"},{"price":"0.41","size":"562.4"},{"price":"0.4","size":"693.02"},{"price":"0.39","size":"625.5"},{"price":"0.38","size":"636.5"},{"price":"0.37","size":"672.32"},{"price":"0.36","size":"680.6"},{"price":"0.35","size":"536.14"},{"price":"0.34","size":"602.8"},{"price":"0.33","size":"572.9"},{"price":"0.32","size":"573"},{"price":"0.31","size":"595.1"},{"price":"0.3","size":"603.2"},{"price":"0.29","size":"1318.72"},{"price":"0.28","size":"1043.04"},{"price":"0.27","size":"663.6"},{"price":"0.26","size":"911.17"},{"price":"0.25","size":"694.3"},{"price":"0.24","size":"717.6"},{"price":"0.23","size":"1183.3"},{"price":"0.22","size":"1526.53"},{"price":"0.21","size":"1178.8"},{"price":"0.2","size":"1445.08"},{"price":"0.19","size":"1229.8"},{"price":"0.18","size":"1467.57"},{"price":"0.17","size":"1520.51"},{"price":"0.16","size":"1718.59"},{"price":"0.15","size":"1810.78"},{"price":"0.14","size":"1755.6"},{"price":"0.13","size":"1588.93"},{"price":"0.12","size":"2555.4"},{"price":"0.11","size":"1792.8"},{"price":"0.1","size":"3416.54"},{"price":"0.09","size":"3012.44"},{"price":"0.08","size":"2724.36"},{"price":"0.07","size":"1654.82"},{"price":"0.06","size":"1137.22"}],"hash":"c6c71f2bfb89217faa3afcf69e404104c232c79d","timestamp":"1768250240845","event_type":"book"}}
{"schema_version":1,"source":"clob_ws_market","recv_ts_ns":1768250240891309988,"event_type":"best_bid_ask","market":"0xe51aa24ab1bbfefce466d642ad98587d13123e4ef95ec9aa73b712e775d4cbba","server_ts_ms":1768250240851,"raw":{"market":"0xe51aa24ab1bbfefce466d642ad98587d13123e4ef95ec9aa73b712e775d4cbba","asset_id":"54232589582260339592359130012520874109228367674780084862642636038394766871668","best_bid":"0.05","best_ask":"0.06","spread":"0.01","timestamp":"1768250240851","event_type":"best_bid_ask"}}
{"schema_version":1,"source":"clob_ws_market","recv_ts_ns":1768250240896709763,"event_type":"price_change","market":"0xe51aa24ab1bbfefce466d642ad98587d13123e4ef95ec9aa73b712e775d4cbba","server_ts_ms":1768250240850,"raw":{"market":"0xe51aa24ab1bbfefce466d642ad98587d13123e4ef95ec9aa73b712e775d4cbba","price_changes":[{"asset_id":"54232589582260339592359130012520874109228367674780084862642636038394766871668","price":"0.05","size":"1322.46","side":"BUY","hash":"aa1097abc551957903f1657e632d974200fadf16","best_bid":"0.05","best_ask":"0.06"},{"asset_id":"96886111393998001968863279421729456597655847484197549086072988901191634450924","price":"0.95","size":"1322.46","side":"SELL","hash":"0405abf41a8ea6a4c5cf6f81dfd5f9012d4c563d","best_bid":"0.94","best_ask":"0.95"}],"timestamp":"1768250240850","event_type":"price_change"}}
{"schema_version":1,"source":"clob_ws_market","recv_ts_ns":1768250240903113702,"event_type":"book","market":"0xe51aa24ab1bbfefce466d642ad98587d13123e4ef95ec9aa73b712e775d4cbba","server_ts_ms":1768250240850,"raw":{"market":"0xe51aa24ab1bbfefce466d642ad98587d13123e4ef95ec9aa73b712e775d4cbba","asset_id":"54232589582260339592359130012520874109228367674780084862642636038394766871668","bids":[{"price":"0.01","size":"21023.9"},{"price":"0.02","size":"6534.25"},{"price":"0.03","size":"2112.6"},{"price":"0.04","size":"522.13"},{"price":"0.05","size":"1322.46"}],"asks":[{"price":"0.99","size":"24290.24"},{"price":"0.98","size":"7594.51"},{"price":"0.97","size":"5964.69"},{"price":"0.96","size":"5411.4"},{"price":"0.95","size":"5356.39"},{"price":"0.94","size":"5328"},{"price":"0.93","size":"5039.28"},{"price":"0.92","size":"5022.7"},{"price":"0.91","size":"5320.9"},{"price":"0.9","size":"5158.44"},{"price":"0.89","size":"18.3"},{"price":"0.88","size":"30.3"},{"price":"0.87","size":"16.5"},{"price":"0.86","size":"15.8"},{"price":"0.85","size":"104.19"},{"price":"0.84","size":"24.69"},{"price":"0.83","size":"14.19"},{"price":"0.82","size":"13.8"},{"price":"0.81","size":"13.4"},{"price":"0.8","size":"38.1"},{"price":"0.79","size":"12.8"},{"price":"0.78","size":"12.6"},{"price":"0.77","size":"12.3"},{"price":"0.76","size":"22.1"},{"price":"0.75","size":"16.9"},{"price":"0.74","size":"21.8"},{"price":"0.73","size":"11.6"},{"price":"0.72","size":"11.4"},{"price":"0.71","size":"61.3"},{"price":"0.7","size":"26.2"},{"price":"0.69","size":"11.1"},{"price":"0.68","size":"11"},{"price":"0.67","size":"110.9"},{"price":"0.66","size":"10.8"},{"price":"0.65","size":"15.7"},{"price":"0.64","size":"10.6"},{"price":"0.63","size":"10.6"},{"price":"0.62","size":"22.5"},{"price":"0.61","size":"10.5"},{"price":"0.6","size":"45.4"},{"price":"0.59","size":"311.4"},{"price":"0.58","size":"820.82"},{"price":"0.57","size":"826.3"},{"price":"0.56","size":"1062.3"},{"price":"0.55","size":"582.3"},{"price":"0.54","size":"626.2"},{"price":"0.53","size":"562.2"},{"price":"0.52","size":"567.2"},{"price":"0.51","size":"573.2"},{"price":"0.5","size":"917.2"},{"price":"0.49","size":"591.2"},{"price":"0.48","size":"596.2"},{"price":"0.47","size":"567.2"},{"price":"0.46","size":"636.61"},{"price":"0.45","size":"362.97"},{"price":"0.44","size":"341.3"},{"price":"0.43","size":"320.62"},{"price":"0.42","size":"567.3"},{"price":"0.41","size":"562.4"},{"price":"0.4","size":"693.02"},{"price":"0.39","size":"625.5"},{"price":"0.38","size":"636.5"},{"price":"0.37","size":"672.32"},{"price":"0.36","size":"680.6"},{"price":"0.35","size":"536.14"},{"price":"0.34","size":"602.8"},{"price":"0.33","size":"572.9"},{"price":"0.32","size":"573"},{"price":"0.31","size":"595.1"},{"price":"0.3","size":"603.2"},{"price":"0.29","size":"1318.72"},{"price":"0.28","size":"1043.04"},{"price":"0.27","size":"663.6"},{"price":"0.26","size":"911.17"},{"price":"0.25","size":"694.3"},{"price":"0.24","size":"717.6"},{"price":"0.23","size":"1183.3"},{"price":"0.22","size":"1526.53"},{"price":"0.21","size":"1178.8"},{"price":"0.2","size":"1445.08"},{"price":"0.19","size":"1229.8"},{"price":"0.18","size":"1467.57"},{"price":"0.17","size":"1520.51"},{"price":"0.16","size":"1718.59"},{"price":"0.15","size":"1810.78"},{"price":"0.14","size":"1755.6"},{"price":"0.13","size":"1588.93"},{"price":"0.12","size":"2555.4"},{"price":"0.11","size":"1792.8"},{"price":"0.1","size":"3416.54"},{"price":"0.09","size":"3012.44"},{"price":"0.08","size":"2724.36"},{"price":"0.07","size":"1654.82"},{"price":"0.06","size":"1137.22"}],"hash":"aa1097abc551957903f1657e632d974200fadf16","timestamp":"1768250240850","event_type":"book"}}
{"schema_version":1,"source":"clob_ws_market","recv_ts_ns":1768250240912633732,"event_type":"price_change","market":"0xe51aa24ab1bbfefce466d642ad98587d13123e4ef95ec9aa73b712e775d4cbba","server_ts_ms":1768250240852,"raw":{"market":"0xe51aa24ab1bbfefce466d642ad98587d13123e4ef95ec9aa73b712e775d4cbba","price_changes":[{"asset_id":"54232589582260339592359130012520874109228367674780084862642636038394766871668","price":"0.01","size":"20993.9","side":"BUY","hash":"c59c1fb1fd70d7ca6da135040f610e9c0ceed4ac","best_bid":"0.05","best_ask":"0.06"},{"asset_id":"96886111393998001968863279421729456597655847484197549086072988901191634450924","price":"0.99","size":"20993.9","side":"SELL","hash":"8aca10fac83fbebc120631780a971e453b4f3d4e","best_bid":"0.94","best_ask":"0.95"}],"timestamp":"1768250240852","event_type":"price_change"}}
{"schema_version":1,"source":"clob_ws_market","recv_ts_ns":1768250240917935743,"event_type":"price_change","market":"0xe51aa24ab1bbfefce466d642ad98587d13123e4ef95ec9aa73b712e775d4cbba","server_ts_ms":1768250240880,"raw":{"market":"0xe51aa24ab1bbfefce466d642ad98587d13123e4ef95ec9aa73b712e775d4cbba","price_changes":[{"asset_id":"54232589582260339592359130012520874109228367674780084862642636038394766871668","price":"0.07","size":"1634.82","side":"SELL","hash":"0d0a81406b9a7cdc33d64a7db059315185f7d995","best_bid":"0.05","best_ask":"0.06"},{"asset_id":"96886111393998001968863279421729456597655847484197549086072988901191634450924","price":"0.93","size":"1634.82","side":"BUY","hash":"6a6e816ea8e3f7e39340f6439d38911d2aa0f6b2","best_bid":"0.94","best_ask":"0.95"}],"timestamp":"1768250240880","event_type":"price_change"}}
{"schema_version":1,"source":"clob_ws_market","recv_ts_ns":1768250240928952880,"event_type":"price_change","market":"0xe51aa24ab1bbfefce466d642ad98587d13123e4ef95ec9aa73b712e775d4cbba","server_ts_ms":1768250240890,"raw":{"market":"0xe51aa24ab1bbfefce466d642ad98587d13123e4ef95ec9aa73b712e775d4cbba","price_changes":[{"asset_id":"54232589582260339592359130012520874109228367674780084862642636038394766871668","price":"0.07","size":"1654.82","side":"SELL","hash":"158dfdbd8d686571e4ed4610a08cd5cf3f01a5d3","best_bid":"0.05","best_ask":"0.06"},{"asset_id":"96886111393998001968863279421729456597655847484197549086072988901191634450924","price":"0.93","size":"1654.82","side":"BUY","hash":"0beeed68f9986bfd94583800abedfac5e764eecb","best_bid":"0.94","best_ask":"0.95"}],"timestamp":"1768250240890","event_type":"price_change"}}
{"schema_version":1,"source":"clob_ws_market","recv_ts_ns":1768250240934235502,"event_type":"price_change","market":"0xe51aa24ab1bbfefce466d642ad98587d13123e4ef95ec9aa73b712e775d4cbba","server_ts_ms":1768250240900,"raw":{"market":"0xe51aa24ab1bbfefce466d642ad98587d13123e4ef95ec9aa73b712e775d4cbba","price_changes":[{"asset_id":"54232589582260339592359130012520874109228367674780084862642636038394766871668","price":"0.01","size":"21023.9","side":"BUY","hash":"823a5799c8ea9d2fc9c24ad26dcee235b18d9830","best_bid":"0.05","best_ask":"0.06"},{"asset_id":"96886111393998001968863279421729456597655847484197549086072988901191634450924","price":"0.99","size":"21023.9","side":"SELL","hash":"fd1d4219369b3d65f5d64169c5f18761ef988c23","best_bid":"0.94","best_ask":"0.95"}],"timestamp":"1768250240900","event_type":"price_change"}}
{"schema_version":1,"source":"clob_ws_market","recv_ts_ns":1768250240940564290,"event_type":"price_change","market":"0xe51aa24ab1bbfefce466d642ad98587d13123e4ef95ec9aa73b712e775d4cbba","server_ts_ms":1768250240901,"raw":{"market":"0xe51aa24ab1bbfefce466d642ad98587d13123e4ef95ec9aa73b712e775d4cbba","price_changes":[{"asset_id":"54232589582260339592359130012520874109228367674780084862642636038394766871668","price":"0.04","size":"530.13","side":"BUY","hash":"7ed7e69242a66ff86158f02d504397414e80c6fd","best_bid":"0.05","best_ask":"0.06"},{"asset_id":"96886111393998001968863279421729456597655847484197549086072988901191634450924","price":"0.96","size":"530.13","side":"SELL","hash":"11e99f6cd5472fce51316203bf04ff822e9ad013","best_bid":"0.94","best_ask":"0.95"}],"timestamp":"1768250240901","event_type":"price_change"}}
{"schema_version":1,"source":"clob_ws_market","recv_ts_ns":1768250240945009497,"event_type":"price_change","market":"0xe51aa24ab1bbfefce466d642ad98587d13123e4ef95ec9aa73b712e775d4cbba","server_ts_ms":1768250240902,"raw":{"market":"0xe51aa24ab1bbfefce466d642ad98587d13123e4ef95ec9aa73b712e775d4cbba","price_changes":[{"asset_id":"54232589582260339592359130012520874109228367674780084862642636038394766871668","price":"0.04","size":"566.13","side":"BUY","hash":"959f3615f21f8ddfe5ccddf92763b452dbb01276","best_bid":"0.05","best_ask":"0.06"},{"asset_id":"96886111393998001968863279421729456597655847484197549086072988901191634450924","price":"0.96","size":"566.13","side":"SELL","hash":"11a6470cfd7d7db71bf8b3cb5dee0c07b089ea09","best_bid":"0.94","best_ask":"0.95"}],"timestamp":"1768250240902","event_type":"price_change"}}
{"schema_version":1,"source":"clob_ws_market","recv_ts_ns":1768250240949830457,"event_type":"price_change","market":"0xe51aa24ab1bbfefce466d642ad98587d13123e4ef95ec9aa73b712e775d4cbba","server_ts_ms":1768250240905,"raw":{"market":"0xe51aa24ab1bbfefce466d642ad98587d13123e4ef95ec9aa73b712e775d4cbba","price_changes":[{"asset_id":"96886111393998001968863279421729456597655847484197549086072988901191634450924","price":"0.96","size":"595.13","side":"SELL","hash":"56040c0e9c08825036baaec2c6db3288f7abd52e","best_bid":"0.94","best_ask":"0.95"},{"asset_id":"54232589582260339592359130012520874109228367674780084862642636038394766871668","price":"0.04","size":"595.13","side":"BUY","hash":"5d584b6c6d01921c9f6ab6464c1819add3fe2f97","best_bid":"0.05","best_ask":"0.06"}],"timestamp":"1768250240905","event_type":"price_change"}}
{"schema_version":1,"source":"clob_ws_market","recv_ts_ns":1768250241027099561,"event_type":"price_change","market":"0xe51aa24ab1bbfefce466d642ad98587d13123e4ef95ec9aa73b712e775d4cbba","server_ts_ms":1768250241000,"raw":{"market":"0xe51aa24ab1bbfefce466d642ad98587d13123e4ef95ec9aa73b712e775d4cbba","price_changes":[{"asset_id":"54232589582260339592359130012520874109228367674780084862642636038394766871668","price":"0.02","size":"6434.25","side":"BUY","hash":"ec0bfcbb1491101fbe8c168023a8b68d12d2907b","best_bid":"0.05","best_ask":"0.06"},{"asset_id":"96886111393998001968863279421729456597655847484197549086072988901191634450924","price":"0.98","size":"6434.25","side":"SELL","hash":"429cd309747e9223bfde4afc94b0e57304a39e3a","best_bid":"0.94","best_ask":"0.95"}],"timestamp":"1768250241000","event_type":"price_change"}}
{"schema_version":1,"source":"clob_ws_market","recv_ts_ns":1768250241035934675,"event_type":"price_change","market":"0xe51aa24ab1bbfefce466d642ad98587d13123e4ef95ec9aa73b712e775d4cbba","server_ts_ms":1768250241012,"raw":{"market":"0xe51aa24ab1bbfefce466d642ad98587d13123e4ef95ec9aa73b712e775d4cbba","price_changes":[{"asset_id":"96886111393998001968863279421729456597655847484197549086072988901191634450924","price":"0.94","size":"1887.22","side":"BUY","hash":"9eacbb765124ed1956d187ac1370b0b5f4430ada","best_bid":"0.94","best_ask":"0.95"},{"asset_id":"54232589582260339592359130012520874109228367674780084862642636038394766871668","price":"0.06","size":"1887.22","side":"SELL","hash":"45dbaaf3fe9514f0256c40ab2f45fc15545fc0db","best_bid":"0.05","best_ask":"0.06"}],"timestamp":"1768250241012","event_type":"price_change"}}
{"schema_version":1,"source":"clob_ws_market","recv_ts_ns":1768250241047159167,"event_type":"price_change","market":"0xe51aa24ab1bbfefce466d642ad98587d13123e4ef95ec9aa73b712e775d4cbba","server_ts_ms":1768250241026,"raw":{"market":"0xe51aa24ab1bbfefce466d642ad98587d13123e4ef95ec9aa73b712e775d4cbba","price_changes":[{"asset_id":"54232589582260339592359130012520874109228367674780084862642636038394766871668","price":"0.01","size":"20993.9","side":"BUY","hash":"024d4115db9c3365f2fe5088eab92d2cd7896d3d","best_bid":"0.05","best_ask":"0.06"},{"asset_id":"96886111393998001968863279421729456597655847484197549086072988901191634450924","price":"0.99","size":"20993.9","side":"SELL","hash":"c0239c91601ad88b1dc2a8dc27ddf5b5c425ac2b","best_bid":"0.94","best_ask":"0.95"}],"timestamp":"1768250241026","event_type":"price_change"}}
{"schema_version":1,"source":"clob_ws_market","recv_ts_ns":1768250241050894253,"event_type":"price_change","market":"0xe51aa24ab1bbfefce466d642ad98587d13123e4ef95ec9aa73b712e775d4cbba","server_ts_ms":1768250241030,"raw":{"market":"0xe51aa24ab1bbfefce466d642ad98587d13123e4ef95ec9aa73b712e775d4cbba","price_changes":[{"asset_id":"54232589582260339592359130012520874109228367674780084862642636038394766871668","price":"0.04","size":"587.13","side":"BUY","hash":"6fe6d236f0561e88be77678d7236b88d11f01231","best_bid":"0.05","best_ask":"0.06"},{"asset_id":"96886111393998001968863279421729456597655847484197549086072988901191634450924","price":"0.96","size":"587.13","side":"SELL","hash":"2ad14baeea2147ac2575c83bb46ca26cb5e6aa07","best_bid":"0.94","best_ask":"0.95"}],"timestamp":"1768250241030","event_type":"price_change"}}
{"schema_version":1,"source":"clob_ws_market","recv_ts_ns":1768250241077754176,"event_type":"price_change","market":"0xe51aa24ab1bbfefce466d642ad98587d13123e4ef95ec9aa73b712e775d4cbba","server_ts_ms":1768250241047,"raw":{"market":"0xe51aa24ab1bbfefce466d642ad98587d13123e4ef95ec9aa73b712e775d4cbba","price_changes":[{"asset_id":"54232589582260339592359130012520874109228367674780084862642636038394766871668","price":"0.06","size":"1862.22","side":"SELL","hash":"0e472094987ffa000dad85f5603d92f534644c3b","best_bid":"0.05","best_ask":"0.06"},{"asset_id":"96886111393998001968863279421729456597655847484197549086072988901191634450924","price":"0.94","size":"1862.22","side":"BUY","hash":"801082abc34deef81e02f72c69e2b5049a7e498e","best_bid":"0.94","best_ask":"0.95"}],"timestamp":"1768250241047","event_type":"price_change"}}
{"schema_version":1,"source":"clob_ws_market","recv_ts_ns":1768250241083130248,"event_type":"price_change","market":"0xe51aa24ab1bbfefce466d642ad98587d13123e4ef95ec9aa73b712e775d4cbba","server_ts_ms":1768250241049,"raw":{"market":"0xe51aa24ab1bbfefce466d642ad98587d13123e4ef95ec9aa73b712e775d4cbba","price_changes":[{"asset_id":"54232589582260339592359130012520874109228367674780084862642636038394766871668","price":"0.08","size":"2749.36","side":"SELL","hash":"d4ab7f64a9f6c40b9c4363720e4622c5969cf0aa","best_bid":"0.05","best_ask":"0.06"},{"asset_id":"96886111393998001968863279421729456597655847484197549086072988901191634450924","price":"0.92","size":"2749.36","side":"BUY","hash":"98a560b0576bcaec1ed84970f7e9b4b612fba6c6","best_bid":"0.94","best_ask":"0.95"}],"timestamp":"1768250241049","event_type":"price_change"}}
{"schema_version":1,"source":"clob_ws_market","recv_ts_ns":1768250241093293096,"event_type":"price_change","market":"0xe51aa24ab1bbfefce466d642ad98587d13123e4ef95ec9aa73b712e775d4cbba","server_ts_ms":1768250241051,"raw":{"market":"0xe51aa24ab1bbfefce466d642ad98587d13123e4ef95ec9aa73b712e775d4cbba","price_changes":[{"asset_id":"96886111393998001968863279421729456597655847484197549086072988901191634450924","price":"0.93","size":"1679.82","side":"BUY","hash":"d64110317f8c06d0cb6abca2ecec6510fa53bf7e","best_bid":"0.94","best_ask":"0.95"},{"asset_id":"54232589582260339592359130012520874109228367674780084862642636038394766871668","price":"0.07","size":"1679.82","side":"SELL","hash":"4b9e19a1a46faa450c964c534202a6b8d1f9b5a5","best_bid":"0.05","best_ask":"0.06"}],"timestamp":"1768250241051","event_type":"price_change"}}
{"schema_version":1,"source":"clob_ws_market","recv_ts_ns":1768250241103911714,"event_type":"price_change","market":"0xe51aa24ab1bbfefce466d642ad98587d13123e4ef95ec9aa73b712e775d4cbba","server_ts_ms":1768250241052,"raw":{"market":"0xe51aa24ab1bbfefce466d642ad98587d13123e4ef95ec9aa73b712e775d4cbba","price_changes":[{"asset_id":"96886111393998001968863279421729456597655847484197549086072988901191634450924","price":"0.94","size":"1837.22","side":"BUY","hash":"7ce1141828b665e8998a64fccebee9c4a02837ab","best_bid":"0.94","best_ask":"0.95"},{"asset_id":"54232589582260339592359130012520874109228367674780084862642636038394766871668","price":"0.06","size":"1837.22","side":"SELL","hash":"c06454287ee21fc3c8b0ea306b26e92915675ad5","best_bid":"0.05","best_ask":"0.06"}],"timestamp":"1768250241052","event_type":"price_change"}}
{"schema_version":1,"source":"clob_ws_market","recv_ts_ns":1768250241107987629,"event_type":"price_change","market":"0xe51aa24ab1bbfefce466d642ad98587d13123e4ef95ec9aa73b712e775d4cbba","server_ts_ms":1768250241053,"raw":{"market":"0xe51aa24ab1bbfefce466d642ad98587d13123e4ef95ec9aa73b712e775d4cbba","price_changes":[{"asset_id":"54232589582260339592359130012520874109228367674780084862642636038394766871668","price":"0.05","size":"1432.46","side":"BUY","hash":"13fd48bc985071f922637bd292890e61be88e1a2","best_bid":"0.05","best_ask":"0.06"},{"asset_id":"96886111393998001968863279421729456597655847484197549086072988901191634450924","price":"0.95","size":"1432.46","side":"SELL","hash":"1ef04aa0c765c598c7b6f82aa43486ec61ecedfe","best_bid":"0.94","best_ask":"0.95"}],"timestamp":"1768250241053","event_type":"price_change"}}
{"schema_version":1,"source":"clob_ws_market","recv_ts_ns":1768250241111741953,"event_type":"price_change","market":"0xe51aa24ab1bbfefce466d642ad98587d13123e4ef95ec9aa73b712e775d4cbba","server_ts_ms":1768250241054,"raw":{"market":"0xe51aa24ab1bbfefce466d642ad98587d13123e4ef95ec9aa73b712e775d4cbba","price_changes":[{"asset_id":"96886111393998001968863279421729456597655847484197549086072988901191634450924","price":"0.92","size":"2774.36","side":"BUY","hash":"8ec4ba42c9341f2b81eea8feb9db549bf3a675ff","best_bid":"0.94","best_ask":"0.95"},{"asset_id":"54232589582260339592359130012520874109228367674780084862642636038394766871668","price":"0.08","size":"2774.36","side":"SELL","hash":"8500f6ff719bc130abc9884580ee74e741827f29","best_bid":"0.05","best_ask":"0.06"}],"timestamp":"1768250241054","event_type":"price_change"}}
{"schema_version":1,"source":"clob_ws_market","recv_ts_ns":1768250241115693039,"event_type":"price_change","market":"0xe51aa24ab1bbfefce466d642ad98587d13123e4ef95ec9aa73b712e775d4cbba","server_ts_ms":1768250241055,"raw":{"market":"0xe51aa24ab1bbfefce466d642ad98587d13123e4ef95ec9aa73b712e775d4cbba","price_changes":[{"asset_id":"54232589582260339592359130012520874109228367674780084862642636038394766871668","price":"0.07","size":"1704.82","side":"SELL","hash":"ed95a177defc65880380c0815c867b45e6c00a15","best_bid":"0.05","best_ask":"0.06"},{"asset_id":"96886111393998001968863279421729456597655847484197549086072988901191634450924","price":"0.93","size":"1704.82","side":"BUY","hash":"f4bb0a6b389364d5ae04091fd377ef9e15fa1e88","best_bid":"0.94","best_ask":"0.95"}],"timestamp":"1768250241055","event_type":"price_change"}}
{"schema_version":1,"source":"clob_ws_market","recv_ts_ns":1768250241119474429,"event_type":"price_change","market":"0xe51aa24ab1bbfefce466d642ad98587d13123e4ef95ec9aa73b712e775d4cbba","server_ts_ms":1768250241056,"raw":{"market":"0xe51aa24ab1bbfefce466d642ad98587d13123e4ef95ec9aa73b712e775d4cbba","price_changes":[{"asset_id":"54232589582260339592359130012520874109228367674780084862642636038394766871668","price":"0.07","size":"1679.82","side":"SELL","hash":"0bea033ab9ac3ea275420b91317f21c52652180d","best_bid":"0.05","best_ask":"0.06"},{"asset_id":"96886111393998001968863279421729456597655847484197549086072988901191634450924","price":"0.93","size":"1679.82","side":"BUY","hash":"9e1177fac79bc1b2e7b6e058aa336ab390bc5071","best_bid":"0.94","best_ask":"0.95"}],"timestamp":"1768250241056","event_type":"price_change"}}
{"schema_version":1,"source":"clob_ws_market","recv_ts_ns":1768250241135736042,"event_type":"price_change","market":"0xe51aa24ab1bbfefce466d642ad98587d13123e4ef95ec9aa73b712e775d4cbba","server_ts_ms":1768250241064,"raw":{"market":"0xe51aa24ab1bbfefce466d642ad98587d13123e4ef95ec9aa73b712e775d4cbba","price_changes":[{"asset_id":"54232589582260339592359130012520874109228367674780084862642636038394766871668","price":"0.01","size":"21023.9","side":"BUY","hash":"fdb464527d9aeba178d79ac8db454ad9bcf539c0","best_bid":"0.05","best_ask":"0.06"},{"asset_id":"96886111393998001968863279421729456597655847484197549086072988901191634450924","price":"0.99","size":"21023.9","side":"SELL","hash":"073e4ffa29fe4467ee6dda20e9c63fea03d11ddd","best_bid":"0.94","best_ask":"0.95"}],"timestamp":"1768250241064","event_type":"price_change"}}
{"schema_version":1,"source":"clob_ws_market","recv_ts_ns":1768250241138399239,"event_type":"price_change","market":"0xe51aa24ab1bbfefce466d642ad98587d13123e4ef95ec9aa73b712e775d4cbba","server_ts_ms":1768250241067,"raw":{"market":"0xe51aa24ab1bbfefce466d642ad98587d13123e4ef95ec9aa73b712e775d4cbba","price_changes":[{"asset_id":"96886111393998001968863279421729456597655847484197549086072988901191634450924","price":"0.93","size":"1654.82","side":"BUY","hash":"dfd0c659945424b4fcc620f4b427c6c21c98d961","best_bid":"0.94","best_ask":"0.95"},{"asset_id":"54232589582260339592359130012520874109228367674780084862642636038394766871668","price":"0.07","size":"1654.82","side":"SELL","hash":"a74eff72e33f15b34560a80dfd1bb24b8cb8d276","best_bid":"0.05","best_ask":"0.06"}],"timestamp":"1768250241067","event_type":"price_change"}}
{"schema_version":1,"source":"clob_ws_market","recv_ts_ns":1768250241141943793,"event_type":"price_change","market":"0xe51aa24ab1bbfefce466d642ad98587d13123e4ef95ec9aa73b712e775d4cbba","server_ts_ms":1768250241069,"raw":{"market":"0xe51aa24ab1bbfefce466d642ad98587d13123e4ef95ec9aa73b712e775d4cbba","price_changes":[{"asset_id":"54232589582260339592359130012520874109228367674780084862642636038394766871668","price":"0.02","size":"6534.25","side":"BUY","hash":"5160f406576a81c024adef94c87fbbe68c0984fc","best_bid":"0.05","best_ask":"0.06"},{"asset_id":"96886111393998001968863279421729456597655847484197549086072988901191634450924","price":"0.98","size":"6534.25","side":"SELL","hash":"957b0913bd4c32c9b2a0a2f6846da412754691b3","best_bid":"0.94","best_ask":"0.95"}],"timestamp":"1768250241069","event_type":"price_change"}}
{"schema_version":1,"source":"clob_ws_market","recv_ts_ns":1768250241159969759,"event_type":"price_change","market":"0xe51aa24ab1bbfefce466d642ad98587d13123e4ef95ec9aa73b712e775d4cbba","server_ts_ms":1768250241088,"raw":{"market":"0xe51aa24ab1bbfefce466d642ad98587d13123e4ef95ec9aa73b712e775d4cbba","price_changes":[{"asset_id":"54232589582260339592359130012520874109228367674780084862642636038394766871668","price":"0.04","size":"551.13","side":"BUY","hash":"9fa1985ec9ca5c107cf71e8f890f80cad15bf55d","best_bid":"0.05","best_ask":"0.06"},{"asset_id":"96886111393998001968863279421729456597655847484197549086072988901191634450924","price":"0.96","size":"551.13","side":"SELL","hash":"b94909cd9e291be40de29f534a090ddd69a7716c","best_bid":"0.94","best_ask":"0.95"}],"timestamp":"1768250241088","event_type":"price_change"}}
{"schema_version":1,"source":"clob_ws_market","recv_ts_ns":1768250241163367437,"event_type":"price_change","market":"0xe51aa24ab1bbfefce466d642ad98587d13123e4ef95ec9aa73b712e775d4cbba","server_ts_ms":1768250241090,"raw":{"market":"0xe51aa24ab1bbfefce466d642ad98587d13123e4ef95ec9aa73b712e775d4cbba","price_changes":[{"asset_id":"54232589582260339592359130012520874109228367674780084862642636038394766871668","price":"0.05","size":"1447.46","side":"BUY","hash":"19439d1c23472a707314a8cdd3c676d4923965e0","best_bid":"0.05","best_ask":"0.06"},{"asset_id":"96886111393998001968863279421729456597655847484197549086072988901191634450924","price":"0.95","size":"1447.46","side":"SELL","hash":"eee1376889c6a5333a86c9064a2b85844236bb3d","best_bid":"0.94","best_ask":"0.95"}],"timestamp":"1768250241090","event_type":"price_change"}}
{"schema_version":1,"source":"clob_ws_market","recv_ts_ns":1768250241170080645,"event_type":"price_change","market":"0xe51aa24ab1bbfefce466d642ad98587d13123e4ef95ec9aa73b712e775d4cbba","server_ts_ms":1768250241093,"raw":{"market":"0xe51aa24ab1bbfefce466d642ad98587d13123e4ef95ec9aa73b712e775d4cbba","price_changes":[{"asset_id":"54232589582260339592359130012520874109228367674780084862642636038394766871668","price":"0.03","size":"2363.6","side":"BUY","hash":"4b07e42459da48aec6373db952dff18d37c225c2","best_bid":"0.05","best_ask":"0.06"},{"asset_id":"96886111393998001968863279421729456597655847484197549086072988901191634450924","price":"0.97","size":"2363.6","side":"SELL","hash":"dbe8d48ff8e5a28e6f382b34d5ede3da18ef00d2","best_bid":"0.94","best_ask":"0.95"}],"timestamp":"1768250241093","event_type":"price_change"}}
{"schema_version":1,"source":"clob_ws_market","recv_ts_ns":1768250241177433243,"event_type":"price_change","market":"0xe51aa24ab1bbfefce466d642ad98587d13123e4ef95ec9aa73b712e775d4cbba","server_ts_ms":1768250241093,"raw":{"market":"0xe51aa24ab1bbfefce466d642ad98587d13123e4ef95ec9aa73b712e775d4cbba","price_changes":[{"asset_id":"96886111393998001968863279421729456597655847484197549086072988901191634450924","price":"0.93","size":"1548.82","side":"BUY","hash":"7d1f4e41b4767284ba2cb2ef038b46a7d20825f0","best_bid":"0.94","best_ask":"0.95"},{"asset_id":"54232589582260339592359130012520874109228367674780084862642636038394766871668","price":"0.07","size":"1548.82","side":"SELL","hash":"7ac6d25ec1e632ae69926b9ddd5acdd4cfef551f","best_bid":"0.05","best_ask":"0.06"}],"timestamp":"1768250241093","event_type":"price_change"}}
{"schema_version":1,"source":"clob_ws_market","recv_ts_ns":1768250241181767273,"event_type":"price_change","market":"0xe51aa24ab1bbfefce466d642ad98587d13123e4ef95ec9aa73b712e775d4cbba","server_ts_ms":1768250241093,"raw":{"market":"0xe51aa24ab1bbfefce466d642ad98587d13123e4ef95ec9aa73b712e775d4cbba","price_changes":[{"asset_id":"96886111393998001968863279421729456597655847484197549086072988901191634450924","price":"0.92","size":"2668.36","side":"BUY","hash":"7d1f4e41b4767284ba2cb2ef038b46a7d20825f0","best_bid":"0.94","best_ask":"0.95"},{"asset_id":"54232589582260339592359130012520874109228367674780084862642636038394766871668","price":"0.08","size":"2668.36","side":"SELL","hash":"7ac6d25ec1e632ae69926b9ddd5acdd4cfef551f","best_bid":"0.05","best_ask":"0.06"}],"timestamp":"1768250241093","event_type":"price_change"}}
{"schema_version":1,"source":"clob_ws_market","recv_ts_ns":1768250241186223970,"event_type":"price_change","market":"0xe51aa24ab1bbfefce466d642ad98587d13123e4ef95ec9aa73b712e775d4cbba","server_ts_ms":1768250241095,"raw":{"market":"0xe51aa24ab1bbfefce466d642ad98587d13123e4ef95ec9aa73b712e775d4cbba","price_changes":[{"asset_id":"96886111393998001968863279421729456597655847484197549086072988901191634450924","price":"0.95","size":"1467.46","side":"SELL","hash":"8148b26e2b9dc7884972d9d3d783045a1bbfe418","best_bid":"0.94","best_ask":"0.95"},{"asset_id":"54232589582260339592359130012520874109228367674780084862642636038394766871668","price":"0.05","size":"1467.46","side":"BUY","hash":"4ac3263be1fa35b269994f0628d087b1b4118a36","best_bid":"0.05","best_ask":"0.06"}],"timestamp":"1768250241095","event_type":"price_change"}}
{"schema_version":1,"source":"clob_ws_market","recv_ts_ns":1768250241199662841,"event_type":"price_change","market":"0xe51aa24ab1bbfefce466d642ad98587d13123e4ef95ec9aa73b712e775d4cbba","server_ts_ms":1768250241097,"raw":{"market":"0xe51aa24ab1bbfefce466d642ad98587d13123e4ef95ec9aa73b712e775d4cbba","price_changes":[{"asset_id":"96886111393998001968863279421729456597655847484197549086072988901191634450924","price":"0.96","size":"580.13","side":"SELL","hash":"a216ac5e44b15353544f579b03916614cfffc3f6","best_bid":"0.94","best_ask":"0.95"},{"asset_id":"54232589582260339592359130012520874109228367674780084862642636038394766871668","price":"0.04","size":"580.13","side":"BUY","hash":"02ba0f7ae76d08d91bd9ab8f045022877cf40fab","best_bid":"0.05","best_ask":"0.06"}],"timestamp":"1768250241097","event_type":"price_change"}}
{"schema_version":1,"source":"clob_ws_market","recv_ts_ns":1768250241205157093,"event_type":"price_change","market":"0xe51aa24ab1bbfefce466d642ad98587d13123e4ef95ec9aa73b712e775d4cbba","server_ts_ms":1768250241098,"raw":{"market":"0xe51aa24ab1bbfefce466d642ad98587d13123e4ef95ec9aa73b712e775d4cbba","price_changes":[{"asset_id":"96886111393998001968863279421729456597655847484197549086072988901191634450924","price":"0.94","size":"1821.22","side":"BUY","hash":"7df43db59bd4d548637023842a32cf1d5b99620c","best_bid":"0.94","best_ask":"0.95"},{"asset_id":"54232589582260339592359130012520874109228367674780084862642636038394766871668","price":"0.06","size":"1821.22","side":"SELL","hash":"7d82713135aa394832340bd573fd0b1091d8f932","best_bid":"0.05","best_ask":"0.06"}],"timestamp":"1768250241098","event_type":"price_change"}}
{"schema_version":1,"source":"clob_ws_market","recv_ts_ns":1768250241208712757,"event_type":"price_change","market":"0xe51aa24ab1bbfefce466d642ad98587d13123e4ef95ec9aa73b712e775d4cbba","server_ts_ms":1768250241099,"raw":{"market":"0xe51aa24ab1bbfefce466d642ad98587d13123e4ef95ec9aa73b712e775d4cbba","price_changes":[{"asset_id":"96886111393998001968863279421729456597655847484197549086072988901191634450924","price":"0.96","size":"551.13","side":"SELL","hash":"6b6a841fde1f66eba307848ac1856e11040178bd","best_bid":"0.94","best_ask":"0.95"},{"asset_id":"54232589582260339592359130012520874109228367674780084862642636038394766871668","price":"0.04","size":"551.13","side":"BUY","hash":"b8d72aef56b9e21564189d0d6505937f9ea0cd18","best_bid":"0.05","best_ask":"0.06"}],"timestamp":"1768250241099","event_type":"price_change"}}
{"schema_version":1,"source":"clob_ws_market","recv_ts_ns":1768250241215760957,"event_type":"price_change","market":"0xe51aa24ab1bbfefce466d642ad98587d13123e4ef95ec9aa73b712e775d4cbba","server_ts_ms":1768250241100,"raw":{"market":"0xe51aa24ab1bbfefce466d642ad98587d13123e4ef95ec9aa73b712e775d4cbba","price_changes":[{"asset_id":"96886111393998001968863279421729456597655847484197549086072988901191634450924","price":"0.89","size":"1898.8","side":"BUY","hash":"e93bdde7d17403d1226a2f7aec50dbc2f825ec95","best_bid":"0.94","best_ask":"0.95"},{"asset_id":"54232589582260339592359130012520874109228367674780084862642636038394766871668","price":"0.11","size":"1898.8","side":"SELL","hash":"67794840c27ce3c29aa49a587b159037f19821f7","best_bid":"0.05","best_ask":"0.06"}],"timestamp":"1768250241100","event_type":"price_change"}}
{"schema_version":1,"source":"clob_ws_market","recv_ts_ns":1768250241234163079,"event_type":"price_change","market":"0xe51aa24ab1bbfefce466d642ad98587d13123e4ef95ec9aa73b712e775d4cbba","server_ts_ms":1768250241104,"raw":{"market":"0xe51aa24ab1bbfefce466d642ad98587d13123e4ef95ec9aa73b712e775d4cbba","price_changes":[{"asset_id":"96886111393998001968863279421729456597655847484197549086072988901191634450924","price":"0.94","size":"1805.22","side":"BUY","hash":"b9c71021ce7969434ecdb0fccde3c20450149ae4","best_bid":"0.94","best_ask":"0.95"},{"asset_id":"54232589582260339592359130012520874109228367674780084862642636038394766871668","price":"0.06","size":"1805.22","side":"SELL","hash":"2bed8a72e7b10a637a84f2e81c4e211c46fd77da","best_bid":"0.05","best_ask":"0.06"}],"timestamp":"1768250241104","event_type":"price_change"}}
{"schema_version":1,"source":"clob_ws_market","recv_ts_ns":1768250241237171839,"event_type":"price_change","market":"0xe51aa24ab1bbfefce466d642ad98587d13123e4ef95ec9aa73b712e775d4cbba","server_ts_ms":1768250241106,"raw":{"market":"0xe51aa24ab1bbfefce466d642ad98587d13123e4ef95ec9aa73b712e775d4cbba","price_changes":[{"asset_id":"54232589582260339592359130012520874109228367674780084862642636038394766871668","price":"0.03","size":"2347.6","side":"BUY","hash":"3c8865dcdd3f1a473328aee58942bae14a8265e8","best_bid":"0.05","best_ask":"0.06"},{"asset_id":"96886111393998001968863279421729456597655847484197549086072988901191634450924","price":"0.97","size":"2347.6","side":"SELL","hash":"bd6bf155e06cf3671049ce9593ee2319bb2632b2","best_bid":"0.94","best_ask":"0.95"}],"timestamp":"1768250241106","event_type":"price_change"}}
{"schema_version":1,"source":"clob_ws_market","recv_ts_ns":1768250241244841077,"event_type":"price_change","market":"0xe51aa24ab1bbfefce466d642ad98587d13123e4ef95ec9aa73b712e775d4cbba","server_ts_ms":1768250241107,"raw":{"market":"0xe51aa24ab1bbfefce466d642ad98587d13123e4ef95ec9aa73b712e775d4cbba","price_changes":[{"asset_id":"54232589582260339592359130012520874109228367674780084862642636038394766871668","price":"0.04","size":"535.13","side":"BUY","hash":"31eaeac73877cffa2732efb51ae075a7baa54171","best_bid":"0.05","best_ask":"0.06"},{"asset_id":"96886111393998001968863279421729456597655847484197549086072988901191634450924","price":"0.96","size":"535.13","side":"SELL","hash":"7243335af75a8b4d21077d9232a199871344cab6","best_bid":"0.94","best_ask":"0.95"}],"timestamp":"1768250241107","event_type":"price_change"}}
{"schema_version":1,"source":"clob_ws_market","recv_ts_ns":1768250241265191239,"event_type":"price_change","market":"0xe51aa24ab1bbfefce466d642ad98587d13123e4ef95ec9aa73b712e775d4cbba","server_ts_ms":1768250241111,"raw":{"market":"0xe51aa24ab1bbfefce466d642ad98587d13123e4ef95ec9aa73b712e775d4cbba","price_changes":[{"asset_id":"54232589582260339592359130012520874109228367674780084862642636038394766871668","price":"0.05","size":"1573.46","side":"BUY","hash":"1b335139343d49fb10cd071cdc830d884da8c38b","best_bid":"0.05","best_ask":"0.06"},{"asset_id":"96886111393998001968863279421729456597655847484197549086072988901191634450924","price":"0.95","size":"1573.46","side":"SELL","hash":"f3ee2d07507ea6928eb58c43ae6815b4cf7cbef5","best_bid":"0.94","best_ask":"0.95"}],"timestamp":"1768250241111","event_type":"price_change"}}
{"schema_version":1,"source":"clob_ws_market","recv_ts_ns":1768250241273002443,"event_type":"price_change","market":"0xe51aa24ab1bbfefce466d642ad98587d13123e4ef95ec9aa73b712e775d4cbba","server_ts_ms":1768250241112,"raw":{"market":"0xe51aa24ab1bbfefce466d642ad98587d13123e4ef95ec9aa73b712e775d4cbba","price_changes":[{"asset_id":"54232589582260339592359130012520874109228367674780084862642636038394766871668","price":"0.05","size":"1603.46","side":"BUY","hash":"566889d25253f3b870edd984496a257f14d53fd3","best_bid":"0.05","best_ask":"0.06"},{"asset_id":"96886111393998001968863279421729456597655847484197549086072988901191634450924","price":"0.95","size":"1603.46","side":"SELL","hash":"76f691ed49d360f9a517ca7dae855356bc5ff6bf","best_bid":"0.94","best_ask":"0.95"}],"timestamp":"1768250241112","event_type":"price_change"}}
{"schema_version":1,"source":"clob_ws_market","recv_ts_ns":1768250241283295513,"event_type":"price_change","market":"0xe51aa24ab1bbfefce466d642ad98587d13123e4ef95ec9aa73b712e775d4cbba","server_ts_ms":1768250241115,"raw":{"market":"0xe51aa24ab1bbfefce466d642ad98587d13123e4ef95ec9aa73b712e775d4cbba","price_changes":[{"asset_id":"54232589582260339592359130012520874109228367674780084862642636038394766871668","price":"0.02","size":"6518.25","side":"BUY","hash":"2b1fb2aadd6e9751f0ff6b1a5506c7b7802327a5","best_bid":"0.05","best_ask":"0.06"},{"asset_id":"96886111393998001968863279421729456597655847484197549086072988901191634450924","price":"0.98","size":"6518.25","side":"SELL","hash":"f098a5cec30cc165d180b68913c0a58f8cfe2409","best_bid":"0.94","best_ask":"0.95"}],"timestamp":"1768250241115","event_type":"price_change"}}
{"schema_version":1,"source":"clob_ws_market","recv_ts_ns":1768250241304155247,"event_type":"price_change","market":"0xe51aa24ab1bbfefce466d642ad98587d13123e4ef95ec9aa73b712e775d4cbba","server_ts_ms":1768250241120,"raw":{"market":"0xe51aa24ab1bbfefce466d642ad98587d13123e4ef95ec9aa73b712e775d4cbba","price_changes":[{"asset_id":"54232589582260339592359130012520874109228367674780084862642636038394766871668","price":"0.05","size":"1588.46","side":"BUY","hash":"f2d9215ede83e6c9a348a4d4c516652c853c59e5","best_bid":"0.05","best_ask":"0.06"},{"asset_id":"96886111393998001968863279421729456597655847484197549086072988901191634450924","price":"0.95","size":"1588.46","side":"SELL","hash":"eebbe26e5d7aa8fc79e0c08f96c7bd489fd8dc2e","best_bid":"0.94","best_ask":"0.95"}],"timestamp":"1768250241120","event_type":"price_change"}}
{"schema_version":1,"source":"clob_ws_market","recv_ts_ns":1768250241310081184,"event_type":"price_change","market":"0xe51aa24ab1bbfefce466d642ad98587d13123e4ef95ec9aa73b712e775d4cbba","server_ts_ms":1768250241126,"raw":{"market":"0xe51aa24ab1bbfefce466d642ad98587d13123e4ef95ec9aa73b712e775d4cbba","price_changes":[{"asset_id":"96886111393998001968863279421729456597655847484197549086072988901191634450924","price":"0.95","size":"1568.46","side":"SELL","hash":"a545204869bf5d0bbdd289b2ff4c3d037d1a500e","best_bid":"0.94","best_ask":"0.95"},{"asset_id":"54232589582260339592359130012520874109228367674780084862642636038394766871668","price":"0.05","size":"1568.46","side":"BUY","hash":"e3b79796f48bdd94a823f16b6f895af64af7d09c","best_bid":"0.05","best_ask":"0.06"}],"timestamp":"1768250241126","event_type":"price_change"}}
{"schema_version":1,"source":"clob_ws_market","recv_ts_ns":1768250241312957316,"event_type":"price_change","market":"0xe51aa24ab1bbfefce466d642ad98587d13123e4ef95ec9aa73b712e775d4cbba","server_ts_ms":1768250241126,"raw":{"market":"0xe51aa24ab1bbfefce466d642ad98587d13123e4ef95ec9aa73b712e775d4cbba","price_changes":[{"asset_id":"54232589582260339592359130012520874109228367674780084862642636038394766871668","price":"0.01","size":"20993.9","side":"BUY","hash":"fe302fddb458b72c1a8da4a804faec272b98ef39","best_bid":"0.05","best_ask":"0.06"},{"asset_id":"96886111393998001968863279421729456597655847484197549086072988901191634450924","price":"0.99","size":"20993.9","side":"SELL","hash":"7b80308ac110daf1caff8c38fd4eb022f0aedb29","best_bid":"0.94","best_ask":"0.95"}],"timestamp":"1768250241126","event_type":"price_change"}}
{"schema_version":1,"source":"clob_ws_market","recv_ts_ns":1768250241318714014,"event_type":"price_change","market":"0xe51aa24ab1bbfefce466d642ad98587d13123e4ef95ec9aa73b712e775d4cbba","server_ts_ms":1768250241131,"raw":{"market":"0xe51aa24ab1bbfefce466d642ad98587d13123e4ef95ec9aa73b712e775d4cbba","price_changes":[{"asset_id":"96886111393998001968863279421729456597655847484197549086072988901191634450924","price":"0.93","size":"1523.82","side":"BUY","hash":"dd78d91369268d85b20c0bbc216efffbdce3a286","best_bid":"0.94","best_ask":"0.95"},{"asset_id":"54232589582260339592359130012520874109228367674780084862642636038394766871668","price":"0.07","size":"1523.82","side":"SELL","hash":"c3ba8faad4cef04aa533790cde24564ca0af0873","best_bid":"0.05","best_ask":"0.06"}],"timestamp":"1768250241131","event_type":"price_change"}}
{"schema_version":1,"source":"clob_ws_market","recv_ts_ns":1768250241327924081,"event_type":"price_change","market":"0xe51aa24ab1bbfefce466d642ad98587d13123e4ef95ec9aa73b712e775d4cbba","server_ts_ms":1768250241133,"raw":{"market":"0xe51aa24ab1bbfefce466d642ad98587d13123e4ef95ec9aa73b712e775d4cbba","price_changes":[{"asset_id":"54232589582260339592359130012520874109228367674780084862642636038394766871668","price":"0.06","size":"1830.22","side":"SELL","hash":"b2816c6981fc56e3893d25f812282dd6091d9fce","best_bid":"0.05","best_ask":"0.06"},{"asset_id":"96886111393998001968863279421729456597655847484197549086072988901191634450924","price":"0.94","size":"1830.22","side":"BUY","hash":"fdb4cd69fc9e06a0095a6d2b20926ae8853b0357","best_bid":"0.94","best_ask":"0.95"}],"timestamp":"1768250241133","event_type":"price_change"}}
{"schema_version":1,"source":"clob_ws_market","recv_ts_ns":1768250241330983884,"event_type":"price_change","market":"0xe51aa24ab1bbfefce466d642ad98587d13123e4ef95ec9aa73b712e775d4cbba","server_ts_ms":1768250241135,"raw":{"market":"0xe51aa24ab1bbfefce466d642ad98587d13123e4ef95ec9aa73b712e775d4cbba","price_changes":[{"asset_id":"96886111393998001968863279421729456597655847484197549086072988901191634450924","price":"0.94","size":"1855.22","side":"BUY","hash":"35e191cb3cf0d109b26fe85f694c9e142d1f379e","best_bid":"0.94","best_ask":"0.95"},{"asset_id":"54232589582260339592359130012520874109228367674780084862642636038394766871668","price":"0.06","size":"1855.22","side":"SELL","hash":"2d9da596521d8cbb94152501d56d6668aa446373","best_bid":"0.05","best_ask":"0.06"}],"timestamp":"1768250241135","event_type":"price_change"}}
{"schema_version":1,"source":"clob_ws_market","recv_ts_ns":1768250241341666702,"event_type":"price_change","market":"0xe51aa24ab1bbfefce466d642ad98587d13123e4ef95ec9aa73b712e775d4cbba","server_ts_ms":1768250241136,"raw":{"market":"0xe51aa24ab1bbfefce466d642ad98587d13123e4ef95ec9aa73b712e775d4cbba","price_changes":[{"asset_id":"54232589582260339592359130012520874109228367674780084862642636038394766871668","price":"0.07","size":"1548.82","side":"SELL","hash":"a84be0255209c2aa6b92e50ba99e7f50267d6001","best_bid":"0.05","best_ask":"0.06"},{"asset_id":"96886111393998001968863279421729456597655847484197549086072988901191634450924","price":"0.93","size":"1548.82","side":"BUY","hash":"27a11ad44f507d6300d4d74e15366356e1acbef4","best_bid":"0.94","best_ask":"0.95"}],"timestamp":"1768250241136","event_type":"price_change"}}
{"schema_version":1,"source":"clob_ws_market","recv_ts_ns":1768250241344792484,"event_type":"price_change","market":"0xe51aa24ab1bbfefce466d642ad98587d13123e4ef95ec9aa73b712e775d4cbba","server_ts_ms":1768250241138,"raw":{"market":"0xe51aa24ab1bbfefce466d642ad98587d13123e4ef95ec9aa73b712e775d4cbba","price_changes":[{"asset_id":"96886111393998001968863279421729456597655847484197549086072988901191634450924","price":"0.93","size":"1564.82","side":"BUY","hash":"f0e306dc7ccfd7f06df80fba47c8abdcb6f40c15","best_bid":"0.94","best_ask":"0.95"},{"asset_id":"54232589582260339592359130012520874109228367674780084862642636038394766871668","price":"0.07","size":"1564.82","side":"SELL","hash":"f8328898080ef793a64d4b57baa2a122169be9f5","best_bid":"0.05","best_ask":"0.06"}],"timestamp":"1768250241138","event_type":"price_change"}}
{"schema_version":1,"source":"clob_ws_market","recv_ts_ns":1768250241347999772,"event_type":"price_change","market":"0xe51aa24ab1bbfefce466d642ad98587d13123e4ef95ec9aa73b712e775d4cbba","server_ts_ms":1768250241139,"raw":{"market":"0xe51aa24ab1bbfefce466d642ad98587d13123e4ef95ec9aa73b712e775d4cbba","price_changes":[{"asset_id":"54232589582260339592359130012520874109228367674780084862642636038394766871668","price":"0.07","size":"1539.82","side":"SELL","hash":"eea7e85925b34cef2407e8c8d95dfe6b4a2b34a5","best_bid":"0.05","best_ask":"0.06"},{"asset_id":"96886111393998001968863279421729456597655847484197549086072988901191634450924","price":"0.93","size":"1539.82","side":"BUY","hash":"ba5ec4c6b06f42c892aa4fd151dd5263ad056112","best_bid":"0.94","best_ask":"0.95"}],"timestamp":"1768250241139","event_type":"price_change"}}
{"schema_version":1,"source":"clob_ws_market","recv_ts_ns":1768250241355747658,"event_type":"price_change","market":"0xe51aa24ab1bbfefce466d642ad98587d13123e4ef95ec9aa73b712e775d4cbba","server_ts_ms":1768250241141,"raw":{"market":"0xe51aa24ab1bbfefce466d642ad98587d13123e4ef95ec9aa73b712e775d4cbba","price_changes":[{"asset_id":"54232589582260339592359130012520874109228367674780084862642636038394766871668","price":"0.04","size":"551.13","side":"BUY","hash":"0a8250b830b1825ff0dcbf05fc75fdd870c19a4f","best_bid":"0.05","best_ask":"0.06"},{"asset_id":"96886111393998001968863279421729456597655847484197549086072988901191634450924","price":"0.96","size":"551.13","side":"SELL","hash":"5c8159140833cf7798c331455056870ae37526ee","best_bid":"0.94","best_ask":"0.95"}],"timestamp":"1768250241141","event_type":"price_change"}}
{"schema_version":1,"source":"clob_ws_market","recv_ts_ns":1768250241359237332,"event_type":"price_change","market":"0xe51aa24ab1bbfefce466d642ad98587d13123e4ef95ec9aa73b712e775d4cbba","server_ts_ms":1768250241141,"raw":{"market":"0xe51aa24ab1bbfefce466d642ad98587d13123e4ef95ec9aa73b712e775d4cbba","price_changes":[{"asset_id":"54232589582260339592359130012520874109228367674780084862642636038394766871668","price":"0.05","size":"1584.46","side":"BUY","hash":"42e9924871725fe2c09532ef5922f75dd1ee8625","best_bid":"0.05","best_ask":"0.06"},{"asset_id":"96886111393998001968863279421729456597655847484197549086072988901191634450924","price":"0.95","size":"1584.46","side":"SELL","hash":"994fc263e9a93d56fb677ea9d0b4f2eadb81cf6b","best_bid":"0.94","best_ask":"0.95"}],"timestamp":"1768250241141","event_type":"price_change"}}
{"schema_version":1,"source":"clob_ws_market","recv_ts_ns":1768250241362084490,"event_type":"price_change","market":"0xe51aa24ab1bbfefce466d642ad98587d13123e4ef95ec9aa73b712e775d4cbba","server_ts_ms":1768250241142,"raw":{"market":"0xe51aa24ab1bbfefce466d642ad98587d13123e4ef95ec9aa73b712e775d4cbba","price_changes":[{"asset_id":"96886111393998001968863279421729456597655847484197549086072988901191634450924","price":"0.91","size":"3002.44","side":"BUY","hash":"06f896b69a4976178eb63d30179306dde7931cb6","best_bid":"0.94","best_ask":"0.95"},{"asset_id":"54232589582260339592359130012520874109228367674780084862642636038394766871668","price":"0.09","size":"3002.44","side":"SELL","hash":"1893aceaf573ec606a2a46328d6ecb5f798c3b7b","best_bid":"0.05","best_ask":"0.06"}],"timestamp":"1768250241142","event_type":"price_change"}}
{"schema_version":1,"source":"clob_ws_market","recv_ts_ns":1768250241380762817,"event_type":"price_change","market":"0xe51aa24ab1bbfefce466d642ad98587d13123e4ef95ec9aa73b712e775d4cbba","server_ts_ms":1768250241147,"raw":{"market":"0xe51aa24ab1bbfefce466d642ad98587d13123e4ef95ec9aa73b712e775d4cbba","price_changes":[{"asset_id":"54232589582260339592359130012520874109228367674780084862642636038394766871668","price":"0.03","size":"2447.6","side":"BUY","hash":"4f7f7d7bbb96004b905c5d7c0f5274acf87a7093","best_bid":"0.05","best_ask":"0.06"},{"asset_id":"96886111393998001968863279421729456597655847484197549086072988901191634450924","price":"0.97","size":"2447.6","side":"SELL","hash":"7c2eaf5b657b29ddac2580a8f06d36d48c9a52f1","best_bid":"0.94","best_ask":"0.95"}],"timestamp":"1768250241147","event_type":"price_change"}}
{"schema_version":1,"source":"clob_ws_market","recv_ts_ns":1768250241387918428,"event_type":"price_change","market":"0xe51aa24ab1bbfefce466d642ad98587d13123e4ef95ec9aa73b712e775d4cbba","server_ts_ms":1768250241148,"raw":{"market":"0xe51aa24ab1bbfefce466d642ad98587d13123e4ef95ec9aa73b712e775d4cbba","price_changes":[{"asset_id":"54232589582260339592359130012520874109228367674780084862642636038394766871668","price":"0.02","size":"6418.25","side":"BUY","hash":"19729009fb7c3c1e71cfc5e435cbff6d24983119","best_bid":"0.05","best_ask":"0.06"},{"asset_id":"96886111393998001968863279421729456597655847484197549086072988901191634450924","price":"0.98","size":"6418.25","side":"SELL","hash":"ca920683f6d34cc5c58c9118e9a121c5a3218366","best_bid":"0.94","best_ask":"0.95"}],"timestamp":"1768250241148","event_type":"price_change"}}
{"schema_version":1,"source":"clob_ws_market","recv_ts_ns":1768250241397576308,"event_type":"price_change","market":"0xe51aa24ab1bbfefce466d642ad98587d13123e4ef95ec9aa73b712e775d4cbba","server_ts_ms":1768250241150,"raw":{"market":"0xe51aa24ab1bbfefce466d642ad98587d13123e4ef95ec9aa73b712e775d4cbba","price_changes":[{"asset_id":"54232589582260339592359130012520874109228367674780084862642636038394766871668","price":"0.02","size":"6719.25","side":"BUY","hash":"70e9c83866270204fc9b984b861eb5ba9218e995","best_bid":"0.05","best_ask":"0.06"},{"asset_id":"96886111393998001968863279421729456597655847484197549086072988901191634450924","price":"0.98","size":"6719.25","side":"SELL","hash":"b2a8265ffb0d35a51f420952a7e6f661e1939445","best_bid":"0.94","best_ask":"0.95"}],"timestamp":"1768250241150","event_type":"price_change"}}
{"schema_version":1,"source":"clob_ws_market","recv_ts_ns":1768250241414979748,"event_type":"price_change","market":"0xe51aa24ab1bbfefce466d642ad98587d13123e4ef95ec9aa73b712e775d4cbba","server_ts_ms":1768250241152,"raw":{"market":"0xe51aa24ab1bbfefce466d642ad98587d13123e4ef95ec9aa73b712e775d4cbba","price_changes":[{"asset_id":"54232589582260339592359130012520874109228367674780084862642636038394766871668","price":"0.05","size":"1554.46","side":"BUY","hash":"9f843a1a626b346299f4399fb78434639a26aa00","best_bid":"0.05","best_ask":"0.06"},{"asset_id":"96886111393998001968863279421729456597655847484197549086072988901191634450924","price":"0.95","size":"1554.46","side":"SELL","hash":"2962c6781cd368ccbeefcecf2d7f2a87ba753650","best_bid":"0.94","best_ask":"0.95"}],"timestamp":"1768250241152","event_type":"price_change"}}
{"schema_version":1,"source":"clob_ws_market","recv_ts_ns":1768250241422934659,"event_type":"price_change","market":"0xe51aa24ab1bbfefce466d642ad98587d13123e4ef95ec9aa73b712e775d4cbba","server_ts_ms":1768250241153,"raw":{"market":"0xe51aa24ab1bbfefce466d642ad98587d13123e4ef95ec9aa73b712e775d4cbba","price_changes":[{"asset_id":"96886111393998001968863279421729456597655847484197549086072988901191634450924","price":"0.9","size":"3426.54","side":"BUY","hash":"90570982e2928189f36a79c66ec87a43e58203cb","best_bid":"0.94","best_ask":"0.95"},{"asset_id":"54232589582260339592359130012520874109228367674780084862642636038394766871668","price":"0.1","size":"3426.54","side":"SELL","hash":"4824ce41fb9d1c58c69821769a8bf73996973f31","best_bid":"0.05","best_ask":"0.06"}],"timestamp":"1768250241153","event_type":"price_change"}}
{"schema_version":1,"source":"clob_ws_market","recv_ts_ns":1768250241427560298,"event_type":"price_change","market":"0xe51aa24ab1bbfefce466d642ad98587d13123e4ef95ec9aa73b712e775d4cbba","server_ts_ms":1768250241154,"raw":{"market":"0xe51aa24ab1bbfefce466d642ad98587d13123e4ef95ec9aa73b712e775d4cbba","price_changes":[{"asset_id":"54232589582260339592359130012520874109228367674780084862642636038394766871668","price":"0.08","size":"2643.36","side":"SELL","hash":"0333ff3c72e4d6d5e364ebda728c3dfaadba9880","best_bid":"0.05","best_ask":"0.06"},{"asset_id":"96886111393998001968863279421729456597655847484197549086072988901191634450924","price":"0.92","size":"2643.36","side":"BUY","hash":"084f147d9adb7869fe8ecd45b29fb5a868953f45","best_bid":"0.94","best_ask":"0.95"}],"timestamp":"1768250241154","event_type":"price_change"}}
{"schema_version":1,"source":"clob_ws_market","recv_ts_ns":1768250241446074895,"event_type":"price_change","market":"0xe51aa24ab1bbfefce466d642ad98587d13123e4ef95ec9aa73b712e775d4cbba","server_ts_ms":1768250241156,"raw":{"market":"0xe51aa24ab1bbfefce466d642ad98587d13123e4ef95ec9aa73b712e775d4cbba","price_changes":[{"asset_id":"54232589582260339592359130012520874109228367674780084862642636038394766871668","price":"0.03","size":"2748.6","side":"BUY","hash":"da1ab111480053ef290fc143b4f2128bc2e498e5","best_bid":"0.05","best_ask":"0.06"},{"asset_id":"96886111393998001968863279421729456597655847484197549086072988901191634450924","price":"0.97","size":"2748.6","side":"SELL","hash":"ff70baac21bf5cabd36665bad8c4652b02b50efa","best_bid":"0.94","best_ask":"0.95"}],"timestamp":"1768250241156","event_type":"price_change"}}
{"schema_version":1,"source":"clob_ws_market","recv_ts_ns":1768250241449201482,"event_type":"price_change","market":"0xe51aa24ab1bbfefce466d642ad98587d13123e4ef95ec9aa73b712e775d4cbba","server_ts_ms":1768250241157,"raw":{"market":"0xe51aa24ab1bbfefce466d642ad98587d13123e4ef95ec9aa73b712e775d4cbba","price_changes":[{"asset_id":"54232589582260339592359130012520874109228367674780084862642636038394766871668","price":"0.02","size":"6735.25","side":"BUY","hash":"4678f23004c5cfdba0a51532325f66c36ab80544","best_bid":"0.05","best_ask":"0.06"},{"asset_id":"96886111393998001968863279421729456597655847484197549086072988901191634450924","price":"0.98","size":"6735.25","side":"SELL","hash":"79052e9dab7e66dbe7eac1786f913cec906c9e9e","best_bid":"0.94","best_ask":"0.95"}],"timestamp":"1768250241157","event_type":"price_change"}}
{"schema_version":1,"source":"clob_ws_market","recv_ts_ns":1768250241476609002,"event_type":"price_change","market":"0xe51aa24ab1bbfefce466d642ad98587d13123e4ef95ec9aa73b712e775d4cbba","server_ts_ms":1768250241160,"raw":{"market":"0xe51aa24ab1bbfefce466d642ad98587d13123e4ef95ec9aa73b712e775d4cbba","price_changes":[{"asset_id":"54232589582260339592359130012520874109228367674780084862642636038394766871668","price":"0.06","size":"1830.22","side":"SELL","hash":"6a5b774d7ab4f6bf962e02f9613ed22298294f5b","best_bid":"0.05","best_ask":"0.06"},{"asset_id":"96886111393998001968863279421729456597655847484197549086072988901191634450924","price":"0.94","size":"1830.22","side":"BUY","hash":"41d00af1aab46274be57c350f2787936982a899b","best_bid":"0.94","best_ask":"0.95"}],"timestamp":"1768250241160","event_type":"price_change"}}
{"schema_version":1,"source":"clob_ws_market","recv_ts_ns":1768250241487378902,"event_type":"price_change","market":"0xe51aa24ab1bbfefce466d642ad98587d13123e4ef95ec9aa73b712e775d4cbba","server_ts_ms":1768250241164,"raw":{"market":"0xe51aa24ab1bbfefce466d642ad98587d13123e4ef95ec9aa73b712e775d4cbba","price_changes":[{"asset_id":"54232589582260339592359130012520874109228367674780084862642636038394766871668","price":"0.07","size":"1514.82","side":"SELL","hash":"b02f90a6d5939220afff2660fe090f25fbcaef42","best_bid":"0.05","best_ask":"0.06"},{"asset_id":"96886111393998001968863279421729456597655847484197549086072988901191634450924","price":"0.93","size":"1514.82","side":"BUY","hash":"2359870089919e474bd324ad4c9d2496b8eed2c4","best_bid":"0.94","best_ask":"0.95"}],"timestamp":"1768250241164","event_type":"price_change"}}
{"schema_version":1,"source":"clob_ws_market","recv_ts_ns":1768250241494888796,"event_type":"price_change","market":"0xe51aa24ab1bbfefce466d642ad98587d13123e4ef95ec9aa73b712e775d4cbba","server_ts_ms":1768250241168,"raw":{"market":"0xe51aa24ab1bbfefce466d642ad98587d13123e4ef95ec9aa73b712e775d4cbba","price_changes":[{"asset_id":"96886111393998001968863279421729456597655847484197549086072988901191634450924","price":"0.94","size":"1842.22","side":"BUY","hash":"a4dc4488cdbdfec9368f27040e2c576ee4ced85c","best_bid":"0.94","best_ask":"0.95"},{"asset_id":"54232589582260339592359130012520874109228367674780084862642636038394766871668","price":"0.06","size":"1842.22","side":"SELL","hash":"af12d173776be1ee698d0e692b1e81d0abb27959","best_bid":"0.05","best_ask":"0.06"}],"timestamp":"1768250241168","event_type":"price_change"}}
{"schema_version":1,"source":"clob_ws_market","recv_ts_ns":1768250241498806374,"event_type":"price_change","market":"0xe51aa24ab1bbfefce466d642ad98587d13123e4ef95ec9aa73b712e775d4cbba","server_ts_ms":1768250241170,"raw":{"market":"0xe51aa24ab1bbfefce466d642ad98587d13123e4ef95ec9aa73b712e775d4cbba","price_changes":[{"asset_id":"96886111393998001968863279421729456597655847484197549086072988901191634450924","price":"0.94","size":"1878.22","side":"BUY","hash":"f63f2a1168fa4ac31e3172eceab6233044239c34","best_bid":"0.94","best_ask":"0.95"},{"asset_id":"54232589582260339592359130012520874109228367674780084862642636038394766871668","price":"0.06","size":"1878.22","side":"SELL","hash":"3b56c081d2bde88bbf89124fd7676b486f96b703","best_bid":"0.05","best_ask":"0.06"}],"timestamp":"1768250241170","event_type":"price_change"}}
{"schema_version":1,"source":"clob_ws_market","recv_ts_ns":1768250241505680121,"event_type":"price_change","market":"0xe51aa24ab1bbfefce466d642ad98587d13123e4ef95ec9aa73b712e775d4cbba","server_ts_ms":1768250241171,"raw":{"market":"0xe51aa24ab1bbfefce466d642ad98587d13123e4ef95ec9aa73b712e775d4cbba","price_changes":[{"asset_id":"96886111393998001968863279421729456597655847484197549086072988901191634450924","price":"0.94","size":"1853.22","side":"BUY","hash":"bf7dca28cca79bfd8dbd6926aaa1203a9033403f","best_bid":"0.94","best_ask":"0.95"},{"asset_id":"54232589582260339592359130012520874109228367674780084862642636038394766871668","price":"0.06","size":"1853.22","side":"SELL","hash":"43863466219805a7d25472a0b68347e31188140b","best_bid":"0.05","best_ask":"0.06"}],"timestamp":"1768250241171","event_type":"price_change"}}
{"schema_version":1,"source":"clob_ws_market","recv_ts_ns":1768250241509133779,"event_type":"price_change","market":"0xe51aa24ab1bbfefce466d642ad98587d13123e4ef95ec9aa73b712e775d4cbba","server_ts_ms":1768250241179,"raw":{"market":"0xe51aa24ab1bbfefce466d642ad98587d13123e4ef95ec9aa73b712e775d4cbba","price_changes":[{"asset_id":"96886111393998001968863279421729456597655847484197549086072988901191634450924","price":"0.94","size":"1869.22","side":"BUY","hash":"0ab551a1ebeb66935ed4410bae257d3a8e4d1dd6","best_bid":"0.94","best_ask":"0.95"},{"asset_id":"54232589582260339592359130012520874109228367674780084862642636038394766871668","price":"0.06","size":"1869.22","side":"SELL","hash":"12a6810983f655cf9e53c5ba4015efeedf292602","best_bid":"0.05","best_ask":"0.06"}],"timestamp":"1768250241179","event_type":"price_change"}}
{"schema_version":1,"source":"clob_ws_market","recv_ts_ns":1768250241512608575,"event_type":"price_change","market":"0xe51aa24ab1bbfefce466d642ad98587d13123e4ef95ec9aa73b712e775d4cbba","server_ts_ms":1768250241181,"raw":{"market":"0xe51aa24ab1bbfefce466d642ad98587d13123e4ef95ec9aa73b712e775d4cbba","price_changes":[{"asset_id":"96886111393998001968863279421729456597655847484197549086072988901191634450924","price":"0.96","size":"522.13","side":"SELL","hash":"43c4a1ba50b5d2a75d4ad839d502a97544c99398","best_bid":"0.94","best_ask":"0.95"},{"asset_id":"54232589582260339592359130012520874109228367674780084862642636038394766871668","price":"0.04","size":"522.13","side":"BUY","hash":"7cb4381339c6c4175c287bff5e3371b328e34da4","best_bid":"0.05","best_ask":"0.06"}],"timestamp":"1768250241181","event_type":"price_change"}}
{"schema_version":1,"source":"clob_ws_market","recv_ts_ns":1768250241519586779,"event_type":"price_change","market":"0xe51aa24ab1bbfefce466d642ad98587d13123e4ef95ec9aa73b712e775d4cbba","server_ts_ms":1768250241185,"raw":{"market":"0xe51aa24ab1bbfefce466d642ad98587d13123e4ef95ec9aa73b712e775d4cbba","price_changes":[{"asset_id":"54232589582260339592359130012520874109228367674780084862642636038394766871668","price":"0.03","size":"2648.6","side":"BUY","hash":"bea2bb781fb79bf26a45c7393935a4e17ff19326","best_bid":"0.05","best_ask":"0.06"},{"asset_id":"96886111393998001968863279421729456597655847484197549086072988901191634450924","price":"0.97","size":"2648.6","side":"SELL","hash":"660e8dc89251fb0bc359875ce13f1eae4b337e39","best_bid":"0.94","best_ask":"0.95"}],"timestamp":"1768250241185","event_type":"price_change"}}
{"schema_version":1,"source":"clob_ws_market","recv_ts_ns":1768250241521848738,"event_type":"price_change","market":"0xe51aa24ab1bbfefce466d642ad98587d13123e4ef95ec9aa73b712e775d4cbba","server_ts_ms":1768250241187,"raw":{"market":"0xe51aa24ab1bbfefce466d642ad98587d13123e4ef95ec9aa73b712e775d4cbba","price_changes":[{"asset_id":"96886111393998001968863279421729456597655847484197549086072988901191634450924","price":"0.01","size":"24295.73","side":"BUY","hash":"61a50afc5032c4a6907d4f8cf5b56f21227d414a","best_bid":"0.94","best_ask":"0.95"},{"asset_id":"54232589582260339592359130012520874109228367674780084862642636038394766871668","price":"0.99","size":"24295.73","side":"SELL","hash":"16d0eae0c0500b072ac8466bdaffbe4edec2ceb4","best_bid":"0.05","best_ask":"0.06"}],"timestamp":"1768250241187","event_type":"price_change"}}
{"schema_version":1,"source":"clob_ws_market","recv_ts_ns":1768250241525987015,"event_type":"price_change","market":"0xe51aa24ab1bbfefce466d642ad98587d13123e4ef95ec9aa73b712e775d4cbba","server_ts_ms":1768250241190,"raw":{"market":"0xe51aa24ab1bbfefce466d642ad98587d13123e4ef95ec9aa73b712e775d4cbba","price_changes":[{"asset_id":"54232589582260339592359130012520874109228367674780084862642636038394766871668","price":"0.02","size":"6761.25","side":"BUY","hash":"f600eca7b60c2aeda728c646220f0c1784812f82","best_bid":"0.05","best_ask":"0.06"},{"asset_id":"96886111393998001968863279421729456597655847484197549086072988901191634450924","price":"0.98","size":"6761.25","side":"SELL","hash":"abff18b74507fa104fd319a5c163ad6592850a97","best_bid":"0.94","best_ask":"0.95"}],"timestamp":"1768250241190","event_type":"price_change"}}
{"schema_version":1,"source":"clob_ws_market","recv_ts_ns":1768250241536153887,"event_type":"price_change","market":"0xe51aa24ab1bbfefce466d642ad98587d13123e4ef95ec9aa73b712e775d4cbba","server_ts_ms":1768250241194,"raw":{"market":"0xe51aa24ab1bbfefce466d642ad98587d13123e4ef95ec9aa73b712e775d4cbba","price_changes":[{"asset_id":"96886111393998001968863279421729456597655847484197549086072988901191634450924","price":"0.85","size":"1762.5","side":"BUY","hash":"8252c41d4847ce182a07ee1c547bfcf769c9144d","best_bid":"0.94","best_ask":"0.95"},{"asset_id":"54232589582260339592359130012520874109228367674780084862642636038394766871668","price":"0.15","size":"1762.5","side":"SELL","hash":"57abbfa1eca5e72f89905baec1a5c0554e393e97","best_bid":"0.05","best_ask":"0.06"}],"timestamp":"1768250241194","event_type":"price_change"}}
{"schema_version":1,"source":"clob_ws_market","recv_ts_ns":1768250241553289035,"event_type":"price_change","market":"0xe51aa24ab1bbfefce466d642ad98587d13123e4ef95ec9aa73b712e775d4cbba","server_ts_ms":1768250241214,"raw":{"market":"0xe51aa24ab1bbfefce466d642ad98587d13123e4ef95ec9aa73b712e775d4cbba","price_changes":[{"asset_id":"96886111393998001968863279421729456597655847484197549086072988901191634450924","price":"0.93","size":"1539.82","side":"BUY","hash":"5321b91f39d884a74629d52d51f82d4022f6e9b6","best_bid":"0.94","best_ask":"0.95"},{"asset_id":"54232589582260339592359130012520874109228367674780084862642636038394766871668","price":"0.07","size":"1539.82","side":"SELL","hash":"410bc9e735ba5a36fde2f8b23302806cba5ec08c","best_bid":"0.05","best_ask":"0.06"}],"timestamp":"1768250241214","event_type":"price_change"}}
{"schema_version":1,"source":"clob_ws_market","recv_ts_ns":1768250241556494201,"event_type":"price_change","market":"0xe51aa24ab1bbfefce466d642ad98587d13123e4ef95ec9aa73b712e775d4cbba","server_ts_ms":1768250241220,"raw":{"market":"0xe51aa24ab1bbfefce466d642ad98587d13123e4ef95ec9aa73b712e775d4cbba","price_changes":[{"asset_id":"54232589582260339592359130012520874109228367674780084862642636038394766871668","price":"0.07","size":"1564.82","side":"SELL","hash":"6e0c199df6782c26074a089444665c394072e6d4","best_bid":"0.05","best_ask":"0.06"},{"asset_id":"96886111393998001968863279421729456597655847484197549086072988901191634450924","price":"0.93","size":"1564.82","side":"BUY","hash":"5c63e18e07bd9652cfab516356dacf30a16d8904","best_bid":"0.94","best_ask":"0.95"}],"timestamp":"1768250241220","event_type":"price_change"}}
{"schema_version":1,"source":"clob_ws_market","recv_ts_ns":1768250241559501283,"event_type":"price_change","market":"0xe51aa24ab1bbfefce466d642ad98587d13123e4ef95ec9aa73b712e775d4cbba","server_ts_ms":1768250241231,"raw":{"market":"0xe51aa24ab1bbfefce466d642ad98587d13123e4ef95ec9aa73b712e775d4cbba","price_changes":[{"asset_id":"96886111393998001968863279421729456597655847484197549086072988901191634450924","price":"0.94","size":"1879.22","side":"BUY","hash":"6ba51c0d716aa8cd02e0120c53a71dea6a1ade69","best_bid":"0.94","best_ask":"0.95"},{"asset_id":"54232589582260339592359130012520874109228367674780084862642636038394766871668","price":"0.06","size":"1879.22","side":"SELL","hash":"c262581e9331e028035c41f346be1919f3a15573","best_bid":"0.05","best_ask":"0.06"}],"timestamp":"1768250241231","event_type":"price_change"}}
{"schema_version":1,"source":"clob_ws_market","recv_ts_ns":1768250241562960028,"event_type":"price_change","market":"0xe51aa24ab1bbfefce466d642ad98587d13123e4ef95ec9aa73b712e775d4cbba","server_ts_ms":1768250241233,"raw":{"market":"0xe51aa24ab1bbfefce466d642ad98587d13123e4ef95ec9aa73b712e775d4cbba","price_changes":[{"asset_id":"54232589582260339592359130012520874109228367674780084862642636038394766871668","price":"0.08","size":"2668.36","side":"SELL","hash":"64bb585d83ddc5382a915af2b2ddd451aaa287b9","best_bid":"0.05","best_ask":"0.06"},{"asset_id":"96886111393998001968863279421729456597655847484197549086072988901191634450924","price":"0.92","size":"2668.36","side":"BUY","hash":"77ab91feae8dff9f3cf0d03e30a469c05477b5f3","best_bid":"0.94","best_ask":"0.95"}],"timestamp":"1768250241233","event_type":"price_change"}}
{"schema_version":1,"source":"clob_ws_market","recv_ts_ns":1768250241572131538,"event_type":"price_change","market":"0xe51aa24ab1bbfefce466d642ad98587d13123e4ef95ec9aa73b712e775d4cbba","server_ts_ms":1768250241240,"raw":{"market":"0xe51aa24ab1bbfefce466d642ad98587d13123e4ef95ec9aa73b712e775d4cbba","price_changes":[{"asset_id":"96886111393998001968863279421729456597655847484197549086072988901191634450924","price":"0.01","size":"24290.24","side":"BUY","hash":"7f8c57c552ca5eec6e018e760694278a36f67fbb","best_bid":"0.94","best_ask":"0.95"},{"asset_id":"54232589582260339592359130012520874109228367674780084862642636038394766871668","price":"0.99","size":"24290.24","side":"SELL","hash":"bbf1ec2c806973f6227d720018d7afd882c69e39","best_bid":"0.05","best_ask":"0.06"}],"timestamp":"1768250241240","event_type":"price_change"}}
{"schema_version":1,"source":"clob_ws_market","recv_ts_ns":1768250241574815641,"event_type":"price_change","market":"0xe51aa24ab1bbfefce466d642ad98587d13123e4ef95ec9aa73b712e775d4cbba","server_ts_ms":1768250241242,"raw":{"market":"0xe51aa24ab1bbfefce466d642ad98587d13123e4ef95ec9aa73b712e775d4cbba","price_changes":[{"asset_id":"54232589582260339592359130012520874109228367674780084862642636038394766871668","price":"0.02","size":"6861.25","side":"BUY","hash":"7c33ea5c6c1a8f7a080c5984b7e942e792abf670","best_bid":"0.05","best_ask":"0.06"},{"asset_id":"96886111393998001968863279421729456597655847484197549086072988901191634450924","price":"0.98","size":"6861.25","side":"SELL","hash":"42e6793edc260dc6912a26af6ec376b242d1a01d","best_bid":"0.94","best_ask":"0.95"}],"timestamp":"1768250241242","event_type":"price_change"}}
{"schema_version":1,"source":"clob_ws_market","recv_ts_ns":1768250241611755623,"event_type":"price_change","market":"0xe51aa24ab1bbfefce466d642ad98587d13123e4ef95ec9aa73b712e775d4cbba","server_ts_ms":1768250241277,"raw":{"market":"0xe51aa24ab1bbfefce466d642ad98587d13123e4ef95ec9aa73b712e775d4cbba","price_changes":[{"asset_id":"96886111393998001968863279421729456597655847484197549086072988901191634450924","price":"0.52","size":"590.2","side":"BUY","hash":"854aaef8b3df7ae8c5a92e4d12be06f8247c2da5","best_bid":"0.94","best_ask":"0.95"},{"asset_id":"54232589582260339592359130012520874109228367674780084862642636038394766871668","price":"0.48","size":"590.2","side":"SELL","hash":"3d105e16ea225b001967d17bca7b9a9d5528b2f9","best_bid":"0.05","best_ask":"0.06"}],"timestamp":"1768250241277","event_type":"price_change"}}
{"schema_version":1,"source":"clob_ws_market","recv_ts_ns":1768250241734829372,"event_type":"price_change","market":"0xe51aa24ab1bbfefce466d642ad98587d13123e4ef95ec9aa73b712e775d4cbba","server_ts_ms":1768250241353,"raw":{"market":"0xe51aa24ab1bbfefce466d642ad98587d13123e4ef95ec9aa73b712e775d4cbba","price_changes":[{"asset_id":"96886111393998001968863279421729456597655847484197549086072988901191634450924","price":"0.94","size":"1898.22","side":"BUY","hash":"773833061269f731b82d8b42dec653297b6d4be9","best_bid":"0.94","best_ask":"0.95"},{"asset_id":"54232589582260339592359130012520874109228367674780084862642636038394766871668","price":"0.06","size":"1898.22","side":"SELL","hash":"6ceed05e2adc56207e8ccab0074c648ef4262c4a","best_bid":"0.05","best_ask":"0.06"}],"timestamp":"1768250241353","event_type":"price_change"}}
{"schema_version":1,"source":"clob_ws_market","recv_ts_ns":1768250241829282315,"event_type":"price_change","market":"0xe51aa24ab1bbfefce466d642ad98587d13123e4ef95ec9aa73b712e775d4cbba","server_ts_ms":1768250241428,"raw":{"market":"0xe51aa24ab1bbfefce466d642ad98587d13123e4ef95ec9aa73b712e775d4cbba","price_changes":[{"asset_id":"96886111393998001968863279421729456597655847484197549086072988901191634450924","price":"0.94","size":"1647.22","side":"BUY","hash":"efb9d30138947a31545c06bf844fc6525393b115","best_bid":"0.94","best_ask":"0.95"},{"asset_id":"54232589582260339592359130012520874109228367674780084862642636038394766871668","price":"0.06","size":"1647.22","side":"SELL","hash":"ec775a31eaf8244c8fba2e344d8394fd878bd4fa","best_bid":"0.05","best_ask":"0.06"}],"timestamp":"1768250241428","event_type":"price_change"}}
{"schema_version":1,"source":"clob_ws_market","recv_ts_ns":1768250241930677832,"event_type":"price_change","market":"0xe51aa24ab1bbfefce466d642ad98587d13123e4ef95ec9aa73b712e775d4cbba","server_ts_ms":1768250241480,"raw":{"market":"0xe51aa24ab1bbfefce466d642ad98587d13123e4ef95ec9aa73b712e775d4cbba","price_changes":[{"asset_id":"96886111393998001968863279421729456597655847484197549086072988901191634450924","price":"0.91","size":"2701.44","side":"BUY","hash":"9d75029774fb73b540abf61e234a9e8d1bbb00bd","best_bid":"0.94","best_ask":"0.95"},{"asset_id":"54232589582260339592359130012520874109228367674780084862642636038394766871668","price":"0.09","size":"2701.44","side":"SELL","hash":"e5b1991cb8cec8865fa19041155966a5c2abadff","best_bid":"0.05","best_ask":"0.06"}],"timestamp":"1768250241480","event_type":"price_change"}}
{"schema_version":1,"source":"clob_ws_market","recv_ts_ns":1768250241935364798,"event_type":"price_change","market":"0xe51aa24ab1bbfefce466d642ad98587d13123e4ef95ec9aa73b712e775d4cbba","server_ts_ms":1768250241480,"raw":{"market":"0xe51aa24ab1bbfefce466d642ad98587d13123e4ef95ec9aa73b712e775d4cbba","price_changes":[{"asset_id":"96886111393998001968863279421729456597655847484197549086072988901191634450924","price":"0.92","size":"2367.36","side":"BUY","hash":"9d75029774fb73b540abf61e234a9e8d1bbb00bd","best_bid":"0.94","best_ask":"0.95"},{"asset_id":"54232589582260339592359130012520874109228367674780084862642636038394766871668","price":"0.08","size":"2367.36","side":"SELL","hash":"e5b1991cb8cec8865fa19041155966a5c2abadff","best_bid":"0.05","best_ask":"0.06"}],"timestamp":"1768250241480","event_type":"price_change"}}
{"schema_version":1,"source":"clob_ws_market","recv_ts_ns":1768250242004841166,"event_type":"price_change","market":"0xe51aa24ab1bbfefce466d642ad98587d13123e4ef95ec9aa73b712e775d4cbba","server_ts_ms":1768250241509,"raw":{"market":"0xe51aa24ab1bbfefce466d642ad98587d13123e4ef95ec9aa73b712e775d4cbba","price_changes":[{"asset_id":"54232589582260339592359130012520874109228367674780084862642636038394766871668","price":"0.06","size":"1672.22","side":"SELL","hash":"b3d0d02fc82a7ee28a97c7ee119ba63aa1211f00","best_bid":"0.05","best_ask":"0.06"},{"asset_id":"96886111393998001968863279421729456597655847484197549086072988901191634450924","price":"0.94","size":"1672.22","side":"BUY","hash":"0daa0175826779f7cd01525ccc22bd37ab0e853f","best_bid":"0.94","best_ask":"0.95"}],"timestamp":"1768250241509","event_type":"price_change"}}
{"schema_version":1,"source":"clob_ws_market","recv_ts_ns":1768250242009570394,"event_type":"price_change","market":"0xe51aa24ab1bbfefce466d642ad98587d13123e4ef95ec9aa73b712e775d4cbba","server_ts_ms":1768250241510,"raw":{"market":"0xe51aa24ab1bbfefce466d642ad98587d13123e4ef95ec9aa73b712e775d4cbba","price_changes":[{"asset_id":"54232589582260339592359130012520874109228367674780084862642636038394766871668","price":"0.07","size":"1539.82","side":"SELL","hash":"90f6998a552cab9ed8de1d8282eb1e5881244dcf","best_bid":"0.05","best_ask":"0.06"},{"asset_id":"96886111393998001968863279421729456597655847484197549086072988901191634450924","price":"0.93","size":"1539.82","side":"BUY","hash":"94a1e26c4661eb6c32c183cd12e7ad31c42d8bf5","best_bid":"0.94","best_ask":"0.95"}],"timestamp":"1768250241510","event_type":"price_change"}}
{"schema_version":1,"source":"clob_ws_market","recv_ts_ns":1768250242020229085,"event_type":"best_bid_ask","market":"0xe51aa24ab1bbfefce466d642ad98587d13123e4ef95ec9aa73b712e775d4cbba","server_ts_ms":1768250241516,"raw":{"market":"0xe51aa24ab1bbfefce466d642ad98587d13123e4ef95ec9aa73b712e775d4cbba","asset_id":"54232589582260339592359130012520874109228367674780084862642636038394766871668","best_bid":"0.05","best_ask":"0.06","spread":"0.01","timestamp":"1768250241516","event_type":"best_bid_ask"}}
{"schema_version":1,"source":"clob_ws_market","recv_ts_ns":1768250242025915972,"event_type":"price_change","market":"0xe51aa24ab1bbfefce466d642ad98587d13123e4ef95ec9aa73b712e775d4cbba","server_ts_ms":1768250241515,"raw":{"market":"0xe51aa24ab1bbfefce466d642ad98587d13123e4ef95ec9aa73b712e775d4cbba","price_changes":[{"asset_id":"54232589582260339592359130012520874109228367674780084862642636038394766871668","price":"0.05","size":"1553.41","side":"BUY","hash":"dbca812cf5bf59906196001531c75202796a6783","best_bid":"0.05","best_ask":"0.06"},{"asset_id":"96886111393998001968863279421729456597655847484197549086072988901191634450924","price":"0.95","size":"1553.41","side":"SELL","hash":"b0e8e0a9875d7efa5733ffb104bf4cf4155d1951","best_bid":"0.94","best_ask":"0.95"}],"timestamp":"1768250241515","event_type":"price_change"}}
{"schema_version":1,"source":"clob_ws_market","recv_ts_ns":1768250242033644499,"event_type":"book","market":"0xe51aa24ab1bbfefce466d642ad98587d13123e4ef95ec9aa73b712e775d4cbba","server_ts_ms":1768250241515,"raw":{"market":"0xe51aa24ab1bbfefce466d642ad98587d13123e4ef95ec9aa73b712e775d4cbba","asset_id":"54232589582260339592359130012520874109228367674780084862642636038394766871668","bids":[{"price":"0.01","size":"20993.9"},{"price":"0.02","size":"6861.25"},{"price":"0.03","size":"2648.6"},{"price":"0.04","size":"522.13"},{"price":"0.05","size":"1553.41"}],"asks":[{"price":"0.99","size":"24290.24"},{"price":"0.98","size":"7594.51"},{"price":"0.97","size":"5964.69"},{"price":"0.96","size":"5411.4"},{"price":"0.95","size":"5356.39"},{"price":"0.94","size":"5328"},{"price":"0.93","size":"5039.28"},{"price":"0.92","size":"5022.7"},{"price":"0.91","size":"5320.9"},{"price":"0.9","size":"5158.44"},{"price":"0.89","size":"18.3"},{"price":"0.88","size":"30.3"},{"price":"0.87","size":"16.5"},{"price":"0.86","size":"15.8"},{"price":"0.85","size":"104.19"},{"price":"0.84","size":"24.69"},{"price":"0.83","size":"14.19"},{"price":"0.82","size":"13.8"},{"price":"0.81","size":"13.4"},{"price":"0.8","size":"38.1"},{"price":"0.79","size":"12.8"},{"price":"0.78","size":"12.6"},{"price":"0.77","size":"12.3"},{"price":"0.76","size":"22.1"},{"price":"0.75","size":"16.9"},{"price":"0.74","size":"21.8"},{"price":"0.73","size":"11.6"},{"price":"0.72","size":"11.4"},{"price":"0.71","size":"61.3"},{"price":"0.7","size":"26.2"},{"price":"0.69","size":"11.1"},{"price":"0.68","size":"11"},{"price":"0.67","size":"110.9"},{"price":"0.66","size":"10.8"},{"price":"0.65","size":"15.7"},{"price":"0.64","size":"10.6"},{"price":"0.63","size":"10.6"},{"price":"0.62","size":"22.5"},{"price":"0.61","size":"10.5"},{"price":"0.6","size":"45.4"},{"price":"0.59","size":"311.4"},{"price":"0.58","size":"820.82"},{"price":"0.57","size":"826.3"},{"price":"0.56","size":"1062.3"},{"price":"0.55","size":"582.3"},{"price":"0.54","size":"626.2"},{"price":"0.53","size":"562.2"},{"price":"0.52","size":"567.2"},{"price":"0.51","size":"573.2"},{"price":"0.5","size":"917.2"},{"price":"0.49","size":"591.2"},{"price":"0.48","size":"590.2"},{"price":"0.47","size":"567.2"},{"price":"0.46","size":"636.61"},{"price":"0.45","size":"362.97"},{"price":"0.44","size":"341.3"},{"price":"0.43","size":"320.62"},{"price":"0.42","size":"567.3"},{"price":"0.41","size":"562.4"},{"price":"0.4","size":"693.02"},{"price":"0.39","size":"625.5"},{"price":"0.38","size":"636.5"},{"price":"0.37","size":"672.32"},{"price":"0.36","size":"680.6"},{"price":"0.35","size":"536.14"},{"price":"0.34","size":"602.8"},{"price":"0.33","size":"572.9"},{"price":"0.32","size":"573"},{"price":"0.31","size":"595.1"},{"price":"0.3","size":"603.2"},{"price":"0.29","size":"1318.72"},{"price":"0.28","size":"1043.04"},{"price":"0.27","size":"663.6"},{"price":"0.26","size":"911.17"},{"price":"0.25","size":"694.3"},{"price":"0.24","size":"717.6"},{"price":"0.23","size":"1183.3"},{"price":"0.22","size":"1526.53"},{"price":"0.21","size":"1178.8"},{"price":"0.2","size":"1445.08"},{"price":"0.19","size":"1229.8"},{"price":"0.18","size":"1467.57"},{"price":"0.17","size":"1520.51"},{"price":"0.16","size":"1718.59"},{"price":"0.15","size":"1762.5"},{"price":"0.14","size":"1755.6"},{"price":"0.13","size":"1588.93"},{"price":"0.12","size":"2555.4"},{"price":"0.11","size":"1898.8"},{"price":"0.1","size":"3426.54"},{"price":"0.09","size":"2701.44"},{"price":"0.08","size":"2367.36"},{"price":"0.07","size":"1539.82"},{"price":"0.06","size":"1672.22"}],"hash":"dbca812cf5bf59906196001531c75202796a6783","timestamp":"1768250241515","event_type":"book"}}
{"schema_version":1,"source":"clob_ws_market","recv_ts_ns":1768250242047909313,"event_type":"price_change","market":"0xe51aa24ab1bbfefce466d642ad98587d13123e4ef95ec9aa73b712e775d4cbba","server_ts_ms":1768250241579,"raw":{"market":"0xe51aa24ab1bbfefce466d642ad98587d13123e4ef95ec9aa73b712e775d4cbba","price_changes":[{"asset_id":"96886111393998001968863279421729456597655847484197549086072988901191634450924","price":"0.53","size":"573.2","side":"BUY","hash":"66ea2b5c7e3261117786aaea823b81067cb27b12","best_bid":"0.94","best_ask":"0.95"},{"asset_id":"54232589582260339592359130012520874109228367674780084862642636038394766871668","price":"0.47","size":"573.2","side":"SELL","hash":"274a6276619b13b530a2a88966d84cc20670a266","best_bid":"0.05","best_ask":"0.06"}],"timestamp":"1768250241579","event_type":"price_change"}}
{"schema_version":1,"source":"clob_ws_market","recv_ts_ns":1768250242059430059,"event_type":"price_change","market":"0xe51aa24ab1bbfefce466d642ad98587d13123e4ef95ec9aa73b712e775d4cbba","server_ts_ms":1768250241603,"raw":{"market":"0xe51aa24ab1bbfefce466d642ad98587d13123e4ef95ec9aa73b712e775d4cbba","price_changes":[{"asset_id":"96886111393998001968863279421729456597655847484197549086072988901191634450924","price":"0.94","size":"1697.22","side":"BUY","hash":"13ffab1c41fc643f770fdc8228cb0057fd951fbe","best_bid":"0.94","best_ask":"0.95"},{"asset_id":"54232589582260339592359130012520874109228367674780084862642636038394766871668","price":"0.06","size":"1697.22","side":"SELL","hash":"7e24c455e7fb811e6369725427c2a20e23c750db","best_bid":"0.05","best_ask":"0.06"}],"timestamp":"1768250241603","event_type":"price_change"}}
{"schema_version":1,"source":"clob_ws_market","recv_ts_ns":1768250242067661072,"event_type":"price_change","market":"0xe51aa24ab1bbfefce466d642ad98587d13123e4ef95ec9aa73b712e775d4cbba","server_ts_ms":1768250241619,"raw":{"market":"0xe51aa24ab1bbfefce466d642ad98587d13123e4ef95ec9aa73b712e775d4cbba","price_changes":[{"asset_id":"96886111393998001968863279421729456597655847484197549086072988901191634450924","price":"0.93","size":"1514.82","side":"BUY","hash":"a5320746c8777c8e635415d6aa318cb1ab7550ea","best_bid":"0.94","best_ask":"0.95"},{"asset_id":"54232589582260339592359130012520874109228367674780084862642636038394766871668","price":"0.07","size":"1514.82","side":"SELL","hash":"538d06a30ac0698fb5f752e15d6c8c5bd4dc8565","best_bid":"0.05","best_ask":"0.06"}],"timestamp":"1768250241619","event_type":"price_change"}}
{"schema_version":1,"source":"clob_ws_market","recv_ts_ns":1768250242079785917,"event_type":"price_change","market":"0xe51aa24ab1bbfefce466d642ad98587d13123e4ef95ec9aa73b712e775d4cbba","server_ts_ms":1768250241647,"raw":{"market":"0xe51aa24ab1bbfefce466d642ad98587d13123e4ef95ec9aa73b712e775d4cbba","price_changes":[{"asset_id":"54232589582260339592359130012520874109228367674780084862642636038394766871668","price":"0.02","size":"6811.25","side":"BUY","hash":"d9a5e430c29e9f4ed194dde2cf4ee5dc10e26a62","best_bid":"0.05","best_ask":"0.06"},{"asset_id":"96886111393998001968863279421729456597655847484197549086072988901191634450924","price":"0.98","size":"6811.25","side":"SELL","hash":"d8530f357aa33d89271e090040ae900ab204c13a","best_bid":"0.94","best_ask":"0.95"}],"timestamp":"1768250241647","event_type":"price_change"}}
{"schema_version":1,"source":"clob_ws_market","recv_ts_ns":1768250242121760121,"event_type":"price_change","market":"0xe51aa24ab1bbfefce466d642ad98587d13123e4ef95ec9aa73b712e775d4cbba","server_ts_ms":1768250241672,"raw":{"market":"0xe51aa24ab1bbfefce466d642ad98587d13123e4ef95ec9aa73b712e775d4cbba","price_changes":[{"asset_id":"54232589582260339592359130012520874109228367674780084862642636038394766871668","price":"0.05","size":"1443.41","side":"BUY","hash":"d3cd680964f922b6d1c41fee1ebfdae73d44b296","best_bid":"0.05","best_ask":"0.06"},{"asset_id":"96886111393998001968863279421729456597655847484197549086072988901191634450924","price":"0.95","size":"1443.41","side":"SELL","hash":"db234fec8e30a87b47110a55349966cab7f91504","best_bid":"0.94","best_ask":"0.95"}],"timestamp":"1768250241672","event_type":"price_change"}}
{"schema_version":1,"source":"clob_ws_market","recv_ts_ns":1768250242158147515,"event_type":"price_change","market":"0xe51aa24ab1bbfefce466d642ad98587d13123e4ef95ec9aa73b712e775d4cbba","server_ts_ms":1768250241685,"raw":{"market":"0xe51aa24ab1bbfefce466d642ad98587d13123e4ef95ec9aa73b712e775d4cbba","price_changes":[{"asset_id":"54232589582260339592359130012520874109228367674780084862642636038394766871668","price":"0.03","size":"2682.6","side":"BUY","hash":"3890fb76a580d732fa97b587f9d8dd9fa2a0a85b","best_bid":"0.05","best_ask":"0.06"},{"asset_id":"96886111393998001968863279421729456597655847484197549086072988901191634450924","price":"0.97","size":"2682.6","side":"SELL","hash":"6735b6e1f45803611d21bbcde164c01d8ceac2ee","best_bid":"0.94","best_ask":"0.95"}],"timestamp":"1768250241685","event_type":"price_change"}}
{"schema_version":1,"source":"clob_ws_market","recv_ts_ns":1768250242215495648,"event_type":"price_change","market":"0xe51aa24ab1bbfefce466d642ad98587d13123e4ef95ec9aa73b712e775d4cbba","server_ts_ms":1768250241810,"raw":{"market":"0xe51aa24ab1bbfefce466d642ad98587d13123e4ef95ec9aa73b712e775d4cbba","price_changes":[{"asset_id":"54232589582260339592359130012520874109228367674780084862642636038394766871668","price":"0.02","size":"6785.25","side":"BUY","hash":"c8a7cde8c86162193c404479896aa1e42b80fcfc","best_bid":"0.05","best_ask":"0.06"},{"asset_id":"96886111393998001968863279421729456597655847484197549086072988901191634450924","price":"0.98","size":"6785.25","side":"SELL","hash":"5b9f06115266922729e361d9cde1ff567817a6a1","best_bid":"0.94","best_ask":"0.95"}],"timestamp":"1768250241810","event_type":"price_change"}}
{"schema_version":1,"source":"clob_ws_market","recv_ts_ns":1768250242220380286,"event_type":"price_change","market":"0xe51aa24ab1bbfefce466d642ad98587d13123e4ef95ec9aa73b712e775d4cbba","server_ts_ms":1768250241834,"raw":{"market":"0xe51aa24ab1bbfefce466d642ad98587d13123e4ef95ec9aa73b712e775d4cbba","price_changes":[{"asset_id":"54232589582260339592359130012520874109228367674780084862642636038394766871668","price":"0.08","size":"2342.36","side":"SELL","hash":"b25c643dbbfc57143f256b44831580e7d9cd4815","best_bid":"0.05","best_ask":"0.06"},{"asset_id":"96886111393998001968863279421729456597655847484197549086072988901191634450924","price":"0.92","size":"2342.36","side":"BUY","hash":"a3d8d698070f2262eefbeca3c9d565a0efbd7f95","best_bid":"0.94","best_ask":"0.95"}],"timestamp":"1768250241834","event_type":"price_change"}}
{"schema_version":1,"source":"clob_ws_market","recv_ts_ns":1768250242223393345,"event_type":"price_change","market":"0xe51aa24ab1bbfefce466d642ad98587d13123e4ef95ec9aa73b712e775d4cbba","server_ts_ms":1768250241836,"raw":{"market":"0xe51aa24ab1bbfefce466d642ad98587d13123e4ef95ec9aa73b712e775d4cbba","price_changes":[{"asset_id":"96886111393998001968863279421729456597655847484197549086072988901191634450924","price":"0.92","size":"2317.36","side":"BUY","hash":"abb03feabe437a0443fa19c54a7fa112abad46c1","best_bid":"0.94","best_ask":"0.95"},{"asset_id":"54232589582260339592359130012520874109228367674780084862642636038394766871668","price":"0.08","size":"2317.36","side":"SELL","hash":"a3ad3a768c2e5210fcc3be9e8df57a883cab2220","best_bid":"0.05","best_ask":"0.06"}],"timestamp":"1768250241836","event_type":"price_change"}}
{"schema_version":1,"source":"clob_ws_market","recv_ts_ns":1768250242226814465,"event_type":"price_change","market":"0xe51aa24ab1bbfefce466d642ad98587d13123e4ef95ec9aa73b712e775d4cbba","server_ts_ms":1768250241837,"raw":{"market":"0xe51aa24ab1bbfefce466d642ad98587d13123e4ef95ec9aa73b712e775d4cbba","price_changes":[{"asset_id":"96886111393998001968863279421729456597655847484197549086072988901191634450924","price":"0.93","size":"1539.82","side":"BUY","hash":"f480dca5798557743c7a6596c55eaa97b54a2521","best_bid":"0.94","best_ask":"0.95"},{"asset_id":"54232589582260339592359130012520874109228367674780084862642636038394766871668","price":"0.07","size":"1539.82","side":"SELL","hash":"eb822bd95e5afe58d498d0b1d729ecd196a767a8","best_bid":"0.05","best_ask":"0.06"}],"timestamp":"1768250241837","event_type":"price_change"}}
{"schema_version":1,"source":"clob_ws_market","recv_ts_ns":1768250242229632773,"event_type":"price_change","market":"0xe51aa24ab1bbfefce466d642ad98587d13123e4ef95ec9aa73b712e775d4cbba","server_ts_ms":1768250241839,"raw":{"market":"0xe51aa24ab1bbfefce466d642ad98587d13123e4ef95ec9aa73b712e775d4cbba","price_changes":[{"asset_id":"54232589582260339592359130012520874109228367674780084862642636038394766871668","price":"0.07","size":"1564.82","side":"SELL","hash":"0ea3046aadcb59151fbcd71e471803fba215cbab","best_bid":"0.05","best_ask":"0.06"},{"asset_id":"96886111393998001968863279421729456597655847484197549086072988901191634450924","price":"0.93","size":"1564.82","side":"BUY","hash":"f8af34b624769dabd5e1e72732f24a63e893aaa9","best_bid":"0.94","best_ask":"0.95"}],"timestamp":"1768250241839","event_type":"price_change"}}
{"schema_version":1,"source":"clob_ws_market","recv_ts_ns":1768250242233359837,"event_type":"price_change","market":"0xe51aa24ab1bbfefce466d642ad98587d13123e4ef95ec9aa73b712e775d4cbba","server_ts_ms":1768250241870,"raw":{"market":"0xe51aa24ab1bbfefce466d642ad98587d13123e4ef95ec9aa73b712e775d4cbba","price_changes":[{"asset_id":"54232589582260339592359130012520874109228367674780084862642636038394766871668","price":"0.02","size":"6811.25","side":"BUY","hash":"588a469b32187b595a03bcc2307ec907a431b85d","best_bid":"0.05","best_ask":"0.06"},{"asset_id":"96886111393998001968863279421729456597655847484197549086072988901191634450924","price":"0.98","size":"6811.25","side":"SELL","hash":"ae91c378bf736f992faf27162dc05b21592fe605","best_bid":"0.94","best_ask":"0.95"}],"timestamp":"1768250241870","event_type":"price_change"}}
{"schema_version":1,"source":"clob_ws_market","recv_ts_ns":1768250242239695530,"event_type":"best_bid_ask","market":"0xe51aa24ab1bbfefce466d642ad98587d13123e4ef95ec9aa73b712e775d4cbba","server_ts_ms":1768250241926,"raw":{"market":"0xe51aa24ab1bbfefce466d642ad98587d13123e4ef95ec9aa73b712e775d4cbba","asset_id":"54232589582260339592359130012520874109228367674780084862642636038394766871668","best_bid":"0.05","best_ask":"0.06","spread":"0.01","timestamp":"1768250241926","event_type":"best_bid_ask"}}
{"schema_version":1,"source":"clob_ws_market","recv_ts_ns":1768250242243780141,"event_type":"price_change","market":"0xe51aa24ab1bbfefce466d642ad98587d13123e4ef95ec9aa73b712e775d4cbba","server_ts_ms":1768250241925,"raw":{"market":"0xe51aa24ab1bbfefce466d642ad98587d13123e4ef95ec9aa73b712e775d4cbba","price_changes":[{"asset_id":"96886111393998001968863279421729456597655847484197549086072988901191634450924","price":"0.94","size":"1639.22","side":"BUY","hash":"dd3c10af7dff010c013f3e7d504e399520c6ad0b","best_bid":"0.94","best_ask":"0.95"},{"asset_id":"54232589582260339592359130012520874109228367674780084862642636038394766871668","price":"0.06","size":"1639.22","side":"SELL","hash":"6fb97a560b7b519ceb8b0ed429c8985b945b905b","best_bid":"0.05","best_ask":"0.06"}],"timestamp":"1768250241925","event_type":"price_change"}}
{"schema_version":1,"source":"clob_ws_market","recv_ts_ns":1768250242248300293,"event_type":"book","market":"0xe51aa24ab1bbfefce466d642ad98587d13123e4ef95ec9aa73b712e775d4cbba","server_ts_ms":1768250241925,"raw":{"market":"0xe51aa24ab1bbfefce466d642ad98587d13123e4ef95ec9aa73b712e775d4cbba","asset_id":"54232589582260339592359130012520874109228367674780084862642636038394766871668","bids":[{"price":"0.01","size":"20993.9"},{"price":"0.02","size":"6811.25"},{"price":"0.03","size":"2682.6"},{"price":"0.04","size":"522.13"},{"price":"0.05","size":"1443.41"}],"asks":[{"price":"0.99","size":"24290.24"},{"price":"0.98","size":"7594.51"},{"price":"0.97","size":"5964.69"},{"price":"0.96","size":"5411.4"},{"price":"0.95","size":"5356.39"},{"price":"0.94","size":"5328"},{"price":"0.93","size":"5039.28"},{"price":"0.92","size":"5022.7"},{"price":"0.91","size":"5320.9"},{"price":"0.9","size":"5158.44"},{"price":"0.89","size":"18.3"},{"price":"0.88","size":"30.3"},{"price":"0.87","size":"16.5"},{"price":"0.86","size":"15.8"},{"price":"0.85","size":"104.19"},{"price":"0.84","size":"24.69"},{"price":"0.83","size":"14.19"},{"price":"0.82","size":"13.8"},{"price":"0.81","size":"13.4"},{"price":"0.8","size":"38.1"},{"price":"0.79","size":"12.8"},{"price":"0.78","size":"12.6"},{"price":"0.77","size":"12.3"},{"price":"0.76","size":"22.1"},{"price":"0.75","size":"16.9"},{"price":"0.74","size":"21.8"},{"price":"0.73","size":"11.6"},{"price":"0.72","size":"11.4"},{"price":"0.71","size":"61.3"},{"price":"0.7","size":"26.2"},{"price":"0.69","size":"11.1"},{"price":"0.68","size":"11"},{"price":"0.67","size":"110.9"},{"price":"0.66","size":"10.8"},{"price":"0.65","size":"15.7"},{"price":"0.64","size":"10.6"},{"price":"0.63","size":"10.6"},{"price":"0.62","size":"22.5"},{"price":"0.61","size":"10.5"},{"price":"0.6","size":"45.4"},{"price":"0.59","size":"311.4"},{"price":"0.58","size":"820.82"},{"price":"0.57","size":"826.3"},{"price":"0.56","size":"1062.3"},{"price":"0.55","size":"582.3"},{"price":"0.54","size":"626.2"},{"price":"0.53","size":"562.2"},{"price":"0.52","size":"567.2"},{"price":"0.51","size":"573.2"},{"price":"0.5","size":"917.2"},{"price":"0.49","size":"591.2"},{"price":"0.48","size":"590.2"},{"price":"0.47","size":"573.2"},{"price":"0.46","size":"636.61"},{"price":"0.45","size":"362.97"},{"price":"0.44","size":"341.3"},{"price":"0.43","size":"320.62"},{"price":"0.42","size":"567.3"},{"price":"0.41","size":"562.4"},{"price":"0.4","size":"693.02"},{"price":"0.39","size":"625.5"},{"price":"0.38","size":"636.5"},{"price":"0.37","size":"672.32"},{"price":"0.36","size":"680.6"},{"price":"0.35","size":"536.14"},{"price":"0.34","size":"602.8"},{"price":"0.33","size":"572.9"},{"price":"0.32","size":"573"},{"price":"0.31","size":"595.1"},{"price":"0.3","size":"603.2"},{"price":"0.29","size":"1318.72"},{"price":"0.28","size":"1043.04"},{"price":"0.27","size":"663.6"},{"price":"0.26","size":"911.17"},{"price":"0.25","size":"694.3"},{"price":"0.24","size":"717.6"},{"price":"0.23","size":"1183.3"},{"price":"0.22","size":"1526.53"},{"price":"0.21","size":"1178.8"},{"price":"0.2","size":"1445.08"},{"price":"0.19","size":"1229.8"},{"price":"0.18","size":"1467.57"},{"price":"0.17","size":"1520.51"},{"price":"0.16","size":"1718.59"},{"price":"0.15","size":"1762.5"},{"price":"0.14","size":"1755.6"},{"price":"0.13","size":"1588.93"},{"price":"0.12","size":"2555.4"},{"price":"0.11","size":"1898.8"},{"price":"0.1","size":"3426.54"},{"price":"0.09","size":"2701.44"},{"price":"0.08","size":"2317.36"},{"price":"0.07","size":"1564.82"},{"price":"0.06","size":"1639.22"}],"hash":"6fb97a560b7b519ceb8b0ed429c8985b945b905b","timestamp":"1768250241925","event_type":"book"}}
{"schema_version":1,"source":"clob_ws_market","recv_ts_ns":1768250242256079783,"event_type":"best_bid_ask","market":"0xe51aa24ab1bbfefce466d642ad98587d13123e4ef95ec9aa73b712e775d4cbba","server_ts_ms":1768250241951,"raw":{"market":"0xe51aa24ab1bbfefce466d642ad98587d13123e4ef95ec9aa73b712e775d4cbba","asset_id":"54232589582260339592359130012520874109228367674780084862642636038394766871668","best_bid":"0.05","best_ask":"0.06","spread":"0.01","timestamp":"1768250241951","event_type":"best_bid_ask"}}
{"schema_version":1,"source":"clob_ws_market","recv_ts_ns":1768250242258464220,"event_type":"price_change","market":"0xe51aa24ab1bbfefce466d642ad98587d13123e4ef95ec9aa73b712e775d4cbba","server_ts_ms":1768250241949,"raw":{"market":"0xe51aa24ab1bbfefce466d642ad98587d13123e4ef95ec9aa73b712e775d4cbba","price_changes":[{"asset_id":"54232589582260339592359130012520874109228367674780084862642636038394766871668","price":"0.05","size":"1442.25","side":"BUY","hash":"bb2fddf9567b2fd3ed65d8dd41f54f4e10e9e8cc","best_bid":"0.05","best_ask":"0.06"},{"asset_id":"96886111393998001968863279421729456597655847484197549086072988901191634450924","price":"0.95","size":"1442.25","side":"SELL","hash":"b2fea11e475f3de060b8d1a481d075e2f9959f74","best_bid":"0.94","best_ask":"0.95"}],"timestamp":"1768250241949","event_type":"price_change"}}
