{"schema_version":1,"source":"clob_ws_market","recv_ts_ns":1768250242261159923,"event_type":"book","market":"0xe51aa24ab1bbfefce466d642ad98587d13123e4ef95ec9aa73b712e775d4cbba","server_ts_ms":1768250241949,"raw":{"market":"0xe51aa24ab1bbfefce466d642ad98587d13123e4ef95ec9aa73b712e775d4cbba","asset_id":"54232589582260339592359130012520874109228367674780084862642636038394766871668","bids":[{"price":"0.01","size":"20993.9"},{"price":"0.02","size":"6811.25"},{"price":"0.03","size":"2682.6"},{"price":"0.04","size":"522.13"},{"price":"0.05","size":"1442.25"}],"asks":[{"price":"0.99","size":"24290.24"},{"price":"0.98","size":"7594.51"},{"price":"0.97","size":"5964.69"},{"price":"0.96","size":"5411.4"},{"price":"0.95","size":"5356.39"},{"price":"0.94","size":"5328"},{"price":"0.93","size":"5039.28"},{"price":"0.92","size":"5022.7"},{"price":"0.91","size":"5320.9"},{"price":"0.9","size":"5158.44"},{"price":"0.89","size":"18.3"},{"price":"0.88","size":"30.3"},{"price":"0.87","size":"16.5"},{"price":"0.86","size":"15.8"},{"price":"0.85","size":"104.19"},{"price":"0.84","size":"24.69"},{"price":"0.83","size":"14.19"},{"price":"0.82","size":"13.8"},{"price":"0.81","size":"13.4"},{"price":"0.8","size":"38.1"},{"price":"0.79","size":"12.8"},{"price":"0.78","size":"12.6"},{"price":"0.77","size":"12.3"},{"price":"0.76","size":"22.1"},{"price":"0.75","size":"16.9"},{"price":"0.74","size":"21.8"},{"price":"0.73","size":"11.6"},{"price":"0.72","size":"11.4"},{"price":"0.71","size":"61.3"},{"price":"0.7","size":"26.2"},{"price":"0.69","size":"11.1"},{"price":"0.68","size":"11"},{"price":"0.67","size":"110.9"},{"price":"0.66","size":"10.8"},{"price":"0.65","size":"15.7"},{"price":"0.64","size":"10.6"},{"price":"0.63","size":"10.6"},{"price":"0.62","size":"22.5"},{"price":"0.61","size":"10.5"},{"price":"0.6","size":"45.4"},{"price":"0.59","size":"311.4"},{"price":"0.58","size":"820.82"},{"price":"0.57","size":"826.3"},{"price":"0.56","size":"1062.3"},{"price":"0.55","size":"582.3"},{"price":"0.54","size":"626.2"},{"price":"0.53","size":"562.2"},{"price":"0.52","size":"567.2"},{"price":"0.51","size":"573.2"},{"price":"0.5","size":"917.2"},{"price":"0.49","size":"591.2"},{"price":"0.48","size":"590.2"},{"price":"0.47","size":"573.2"},{"price":"0.46","size":"636.61"},{"price":"0.45","size":"362.97"},{"price":"0.44","size":"341.3"},{"price":"0.43","size":"320.62"},{"price":"0.42","size":"567.3"},{"price":"0.41","size":"562.4"},{"price":"0.4","size":"693.02"},{"price":"0.39","size":"625.5"},{"price":"0.38","size":"636.5"},{"price":"0.37","size":"672.32"},{"price":"0.36","size":"680.6"},{"price":"0.35","size":"536.14"},{"price":"0.34","size":"602.8"},{"price":"0.33","size":"572.9"},{"price":"0.32","size":"573"},{"price":"0.31","size":"595.1"},{"price":"0.3","size":"603.2"},{"price":"0.29","size":"1318.72"},{"price":"0.28","size":"1043.04"},{"price":"0.27","size":"663.6"},{"price":"0.26","size":"911.17"},{"price":"0.25","size":"694.3"},{"price":"0.24","size":"717.6"},{"price":"0.23","size":"1183.3"},{"price":"0.22","size":"1526.53"},{"price":"0.21","size":"1178.8"},{"price":"0.2","size":"1445.08"},{"price":"0.19","size":"1229.8"},{"price":"0.18","size":"1467.57"},{"price":"0.17","size":"1520.51"},{"price":"0.16","size":"1718.59"},{"price":"0.15","size":"1762.5"},{"price":"0.14","size":"1755.6"},{"price":"0.13","size":"1588.93"},{"price":"0.12","size":"2555.4"},{"price":"0.11","size":"1898.8"},{"price":"0.1","size":"3426.54"},{"price":"0.09","size":"2701.44"},{"price":"0.08","size":"2317.36"},{"price":"0.07","size":"1564.82"},{"price":"0.06","size":"1639.22"}],"hash":"bb2fddf9567b2fd3ed65d8dd41f54f4e10e9e8cc","timestamp":"1768250241949","event_type":"book"}}
{"schema_version":1,"source":"clob_ws_market","recv_ts_ns":1768250242264607130,"event_type":"last_trade_price","market":"0xe51aa24ab1bbfefce466d642ad98587d13123e4ef95ec9aa73b712e775d4cbba","server_ts_ms":1768250241953,"raw":{"market":"0xe51aa24ab1bbfefce466d642ad98587d13123e4ef95ec9aa73b712e775d4cbba","asset_id":"54232589582260339592359130012520874109228367674780084862642636038394766871668","price":"0.06","size":"58","fee_rate_bps":"1000","side":"BUY","timestamp":"1768250241953","event_type":"last_trade_price","transaction_hash":"0x1ee43fcefcb1eee95ee3ec2a678c37b20d730b40fcb7deaa083167195e4f617e"}}
{"schema_version":1,"source":"clob_ws_market","recv_ts_ns":1768250242269064622,"event_type":"price_change","market":"0xe51aa24ab1bbfefce466d642ad98587d13123e4ef95ec9aa73b712e775d4cbba","server_ts_ms":1768250241997,"raw":{"market":"0xe51aa24ab1bbfefce466d642ad98587d13123e4ef95ec9aa73b712e775d4cbba","price_changes":[{"asset_id":"96886111393998001968863279421729456597655847484197549086072988901191634450924","price":"0.62","size":"668.5","side":"BUY","hash":"6089226380b9f23f2d352251f484ee05ced587e2","best_bid":"0.94","best_ask":"0.95"},{"asset_id":"54232589582260339592359130012520874109228367674780084862642636038394766871668","price":"0.38","size":"668.5","side":"SELL","hash":"ae0d16654861e0a28802b7ea4425a692c5258d68","best_bid":"0.05","best_ask":"0.06"}],"timestamp":"1768250241997","event_type":"price_change"}}
{"schema_version":1,"source":"clob_ws_market","recv_ts_ns":1768250242271211879,"event_type":"price_change","market":"0xe51aa24ab1bbfefce466d642ad98587d13123e4ef95ec9aa73b712e775d4cbba","server_ts_ms":1768250242000,"raw":{"market":"0xe51aa24ab1bbfefce466d642ad98587d13123e4ef95ec9aa73b712e775d4cbba","price_changes":[{"asset_id":"54232589582260339592359130012520874109228367674780084862642636038394766871668","price":"0.02","size":"6711.25","side":"BUY","hash":"345fed4a6b84bf3b4314b66d5b2f98b0df0c0819","best_bid":"0.05","best_ask":"0.06"},{"asset_id":"96886111393998001968863279421729456597655847484197549086072988901191634450924","price":"0.98","size":"6711.25","side":"SELL","hash":"a6ca1be443b245831b6f01aa30d99b898f8af948","best_bid":"0.94","best_ask":"0.95"}],"timestamp":"1768250242000","event_type":"price_change"}}
{"schema_version":1,"source":"clob_ws_market","recv_ts_ns":1768250242273534509,"event_type":"price_change","market":"0xe51aa24ab1bbfefce466d642ad98587d13123e4ef95ec9aa73b712e775d4cbba","server_ts_ms":1768250242042,"raw":{"market":"0xe51aa24ab1bbfefce466d642ad98587d13123e4ef95ec9aa73b712e775d4cbba","price_changes":[{"asset_id":"54232589582260339592359130012520874109228367674780084862642636038394766871668","price":"0.02","size":"6811.25","side":"BUY","hash":"35e982ac1849222f85b5341883c27c7173d43f03","best_bid":"0.05","best_ask":"0.06"},{"asset_id":"96886111393998001968863279421729456597655847484197549086072988901191634450924","price":"0.98","size":"6811.25","side":"SELL","hash":"e03eca8a749416d1641f897589283837f4fbec86","best_bid":"0.94","best_ask":"0.95"}],"timestamp":"1768250242042","event_type":"price_change"}}
{"schema_version":1,"source":"clob_ws_market","recv_ts_ns":1768250242276476943,"event_type":"price_change","market":"0xe51aa24ab1bbfefce466d642ad98587d13123e4ef95ec9aa73b712e775d4cbba","server_ts_ms":1768250242084,"raw":{"market":"0xe51aa24ab1bbfefce466d642ad98587d13123e4ef95ec9aa73b712e775d4cbba","price_changes":[{"asset_id":"54232589582260339592359130012520874109228367674780084862642636038394766871668","price":"0.04","size":"506.83","side":"BUY","hash":"6b5106bdcb19097a7104f27cfb6e407a7fe22fe3","best_bid":"0.05","best_ask":"0.06"},{"asset_id":"96886111393998001968863279421729456597655847484197549086072988901191634450924","price":"0.96","size":"506.83","side":"SELL","hash":"50237895b3d86b1c1bf9e7d19cb7d8aae33ae728","best_bid":"0.94","best_ask":"0.95"}],"timestamp":"1768250242084","event_type":"price_change"}}
{"schema_version":1,"source":"clob_ws_market","recv_ts_ns":1768250242278772725,"event_type":"price_change","market":"0xe51aa24ab1bbfefce466d642ad98587d13123e4ef95ec9aa73b712e775d4cbba","server_ts_ms":1768250242089,"raw":{"market":"0xe51aa24ab1bbfefce466d642ad98587d13123e4ef95ec9aa73b712e775d4cbba","price_changes":[{"asset_id":"54232589582260339592359130012520874109228367674780084862642636038394766871668","price":"0.04","size":"490.4","side":"BUY","hash":"9897b8bdbd07c6c00f81133f5f8744e2a1f1fc0c","best_bid":"0.05","best_ask":"0.06"},{"asset_id":"96886111393998001968863279421729456597655847484197549086072988901191634450924","price":"0.96","size":"490.4","side":"SELL","hash":"3025a88da83c1145bc1c310a3b142e798610af44","best_bid":"0.94","best_ask":"0.95"}],"timestamp":"1768250242089","event_type":"price_change"}}
{"schema_version":1,"source":"clob_ws_market","recv_ts_ns":1768250242280540428,"event_type":"best_bid_ask","market":"0xe51aa24ab1bbfefce466d642ad98587d13123e4ef95ec9aa73b712e775d4cbba","server_ts_ms":1768250242112,"raw":{"market":"0xe51aa24ab1bbfefce466d642ad98587d13123e4ef95ec9aa73b712e775d4cbba","asset_id":"54232589582260339592359130012520874109228367674780084862642636038394766871668","best_bid":"0.05","best_ask":"0.06","spread":"0.01","timestamp":"1768250242112","event_type":"best_bid_ask"}}
{"schema_version":1,"source":"clob_ws_market","recv_ts_ns":1768250242282846172,"event_type":"price_change","market":"0xe51aa24ab1bbfefce466d642ad98587d13123e4ef95ec9aa73b712e775d4cbba","server_ts_ms":1768250242109,"raw":{"market":"0xe51aa24ab1bbfefce466d642ad98587d13123e4ef95ec9aa73b712e775d4cbba","price_changes":[{"asset_id":"54232589582260339592359130012520874109228367674780084862642636038394766871668","price":"0.05","size":"1436.18","side":"BUY","hash":"4f259d30755f40f955a324c797b5aefbf10c8e4c","best_bid":"0.05","best_ask":"0.06"},{"asset_id":"96886111393998001968863279421729456597655847484197549086072988901191634450924","price":"0.95","size":"1436.18","side":"SELL","hash":"05d6a575dd6976402aa4f1f0614f8095b26197f3","best_bid":"0.94","best_ask":"0.95"}],"timestamp":"1768250242109","event_type":"price_change"}}
{"schema_version":1,"source":"clob_ws_market","recv_ts_ns":1768250242286482653,"event_type":"book","market":"0xe51aa24ab1bbfefce466d642ad98587d13123e4ef95ec9aa73b712e775d4cbba","server_ts_ms":1768250242109,"raw":{"market":"0xe51aa24ab1bbfefce466d642ad98587d13123e4ef95ec9aa73b712e775d4cbba","asset_id":"54232589582260339592359130012520874109228367674780084862642636038394766871668","bids":[{"price":"0.01","size":"20993.9"},{"price":"0.02","size":"6811.25"},{"price":"0.03","size":"2682.6"},{"price":"0.04","size":"490.4"},{"price":"0.05","size":"1436.18"}],"asks":[{"price":"0.99","size":"24290.24"},{"price":"0.98","size":"7594.51"},{"price":"0.97","size":"5964.69"},{"price":"0.96","size":"5411.4"},{"price":"0.95","size":"5356.39"},{"price":"0.94","size":"5328"},{"price":"0.93","size":"5039.28"},{"price":"0.92","size":"5022.7"},{"price":"0.91","size":"5320.9"},{"price":"0.9","size":"5158.44"},{"price":"0.89","size":"18.3"},{"price":"0.88","size":"30.3"},{"price":"0.87","size":"16.5"},{"price":"0.86","size":"15.8"},{"price":"0.85","size":"104.19"},{"price":"0.84","size":"24.69"},{"price":"0.83","size":"14.19"},{"price":"0.82","size":"13.8"},{"price":"0.81","size":"13.4"},{"price":"0.8","size":"38.1"},{"price":"0.79","size":"12.8"},{"price":"0.78","size":"12.6"},{"price":"0.77","size":"12.3"},{"price":"0.76","size":"22.1"},{"price":"0.75","size":"16.9"},{"price":"0.74","size":"21.8"},{"price":"0.73","size":"11.6"},{"price":"0.72","size":"11.4"},{"price":"0.71","size":"61.3"},{"price":"0.7","size":"26.2"},{"price":"0.69","size":"11.1"},{"price":"0.68","size":"11"},{"price":"0.67","size":"110.9"},{"price":"0.66","size":"10.8"},{"price":"0.65","size":"15.7"},{"price":"0.64","size":"10.6"},{"price":"0.63","size":"10.6"},{"price":"0.62","size":"22.5"},{"price":"0.61","size":"10.5"},{"price":"0.6","size":"45.4"},{"price":"0.59","size":"311.4"},{"price":"0.58","size":"820.82"},{"price":"0.57","size":"826.3"},{"price":"0.56","size":"1062.3"},{"price":"0.55","size":"582.3"},{"price":"0.54","size":"626.2"},{"price":"0.53","size":"562.2"},{"price":"0.52","size":"567.2"},{"price":"0.51","size":"573.2"},{"price":"0.5","size":"917.2"},{"price":"0.49","size":"591.2"},{"price":"0.48","size":"590.2"},{"price":"0.47","size":"573.2"},{"price":"0.46","size":"636.61"},{"price":"0.45","size":"362.97"},{"price":"0.44","size":"341.3"},{"price":"0.43","size":"320.62"},{"price":"0.42","size":"567.3"},{"price":"0.41","size":"562.4"},{"price":"0.4","size":"693.02"},{"price":"0.39","size":"625.5"},{"price":"0.38","size":"668.5"},{"price":"0.37","size":"672.32"},{"price":"0.36","size":"680.6"},{"price":"0.35","size":"536.14"},{"price":"0.34","size":"602.8"},{"price":"0.33","size":"572.9"},{"price":"0.32","size":"573"},{"price":"0.31","size":"595.1"},{"price":"0.3","size":"603.2"},{"price":"0.29","size":"1318.72"},{"price":"0.28","size":"1043.04"},{"price":"0.27","size":"663.6"},{"price":"0.26","size":"911.17"},{"price":"0.25","size":"694.3"},{"price":"0.24","size":"717.6"},{"price":"0.23","size":"1183.3"},{"price":"0.22","size":"1526.53"},{"price":"0.21","size":"1178.8"},{"price":"0.2","size":"1445.08"},{"price":"0.19","size":"1229.8"},{"price":"0.18","size":"1467.57"},{"price":"0.17","size":"1520.51"},{"price":"0.16","size":"1718.59"},{"price":"0.15","size":"1762.5"},{"price":"0.14","size":"1755.6"},{"price":"0.13","size":"1588.93"},{"price":"0.12","size":"2555.4"},{"price":"0.11","size":"1898.8"},{"price":"0.1","size":"3426.54"},{"price":"0.09","size":"2701.44"},{"price":"0.08","size":"2317.36"},{"price":"0.07","size":"1564.82"},{"price":"0.06","size":"1639.22"}],"hash":"4f259d30755f40f955a324c797b5aefbf10c8e4c","timestamp":"1768250242109","event_type":"book"}}
{"schema_version":1,"source":"clob_ws_market","recv_ts_ns":1768250242290946063,"event_type":"price_change","market":"0xe51aa24ab1bbfefce466d642ad98587d13123e4ef95ec9aa73b712e775d4cbba","server_ts_ms":1768250242125,"raw":{"market":"0xe51aa24ab1bbfefce466d642ad98587d13123e4ef95ec9aa73b712e775d4cbba","price_changes":[{"asset_id":"54232589582260339592359130012520874109228367674780084862642636038394766871668","price":"0.03","size":"2699.03","side":"BUY","hash":"692bcf3f21443e35d9435c7f13d209f689e4fb95","best_bid":"0.05","best_ask":"0.06"},{"asset_id":"96886111393998001968863279421729456597655847484197549086072988901191634450924","price":"0.97","size":"2699.03","side":"SELL","hash":"91e5d61859faa2531692d832c8940a583829df0a","best_bid":"0.94","best_ask":"0.95"}],"timestamp":"1768250242125","event_type":"price_change"}}
{"schema_version":1,"source":"clob_ws_market","recv_ts_ns":1768250242295340849,"event_type":"price_change","market":"0xe51aa24ab1bbfefce466d642ad98587d13123e4ef95ec9aa73b712e775d4cbba","server_ts_ms":1768250242126,"raw":{"market":"0xe51aa24ab1bbfefce466d642ad98587d13123e4ef95ec9aa73b712e775d4cbba","price_changes":[{"asset_id":"54232589582260339592359130012520874109228367674780084862642636038394766871668","price":"0.03","size":"2714.33","side":"BUY","hash":"d4f97f4a9ba48df79a0596e680d42308afa83fee","best_bid":"0.05","best_ask":"0.06"},{"asset_id":"96886111393998001968863279421729456597655847484197549086072988901191634450924","price":"0.97","size":"2714.33","side":"SELL","hash":"ce935a1f386837815895c30e40c22b6500d5995f","best_bid":"0.94","best_ask":"0.95"}],"timestamp":"1768250242126","event_type":"price_change"}}
{"schema_version":1,"source":"clob_ws_market","recv_ts_ns":1768250242311278318,"event_type":"price_change","market":"0xe51aa24ab1bbfefce466d642ad98587d13123e4ef95ec9aa73b712e775d4cbba","server_ts_ms":1768250242210,"raw":{"market":"0xe51aa24ab1bbfefce466d642ad98587d13123e4ef95ec9aa73b712e775d4cbba","price_changes":[{"asset_id":"54232589582260339592359130012520874109228367674780084862642636038394766871668","price":"0.03","size":"2680.33","side":"BUY","hash":"8925df987ccace8ba24431fdf0f8de17fd9fae0a","best_bid":"0.05","best_ask":"0.06"},{"asset_id":"96886111393998001968863279421729456597655847484197549086072988901191634450924","price":"0.97","size":"2680.33","side":"SELL","hash":"07d12ec9ceb8b288112712e6694f3fae5b647a10","best_bid":"0.94","best_ask":"0.95"}],"timestamp":"1768250242210","event_type":"price_change"}}
{"schema_version":1,"source":"clob_ws_market","recv_ts_ns":1768250242313653422,"event_type":"best_bid_ask","market":"0xe51aa24ab1bbfefce466d642ad98587d13123e4ef95ec9aa73b712e775d4cbba","server_ts_ms":1768250242216,"raw":{"market":"0xe51aa24ab1bbfefce466d642ad98587d13123e4ef95ec9aa73b712e775d4cbba","asset_id":"54232589582260339592359130012520874109228367674780084862642636038394766871668","best_bid":"0.05","best_ask":"0.06","spread":"0.01","timestamp":"1768250242216","event_type":"best_bid_ask"}}
{"schema_version":1,"source":"clob_ws_market","recv_ts_ns":1768250242316606392,"event_type":"price_change","market":"0xe51aa24ab1bbfefce466d642ad98587d13123e4ef95ec9aa73b712e775d4cbba","server_ts_ms":1768250242214,"raw":{"market":"0xe51aa24ab1bbfefce466d642ad98587d13123e4ef95ec9aa73b712e775d4cbba","price_changes":[{"asset_id":"54232589582260339592359130012520874109228367674780084862642636038394766871668","price":"0.05","size":"1288.81","side":"BUY","hash":"32a738af3403f57b7c09905e23893937a8ea9948","best_bid":"0.05","best_ask":"0.06"},{"asset_id":"96886111393998001968863279421729456597655847484197549086072988901191634450924","price":"0.95","size":"1288.81","side":"SELL","hash":"e37c599adaa2914c570031c8f2b07d9b158de73a","best_bid":"0.94","best_ask":"0.95"}],"timestamp":"1768250242214","event_type":"price_change"}}
{"schema_version":1,"source":"clob_ws_market","recv_ts_ns":1768250242320402953,"event_type":"book","market":"0xe51aa24ab1bbfefce466d642ad98587d13123e4ef95ec9aa73b712e775d4cbba","server_ts_ms":1768250242214,"raw":{"market":"0xe51aa24ab1bbfefce466d642ad98587d13123e4ef95ec9aa73b712e775d4cbba","asset_id":"54232589582260339592359130012520874109228367674780084862642636038394766871668","bids":[{"price":"0.01","size":"20993.9"},{"price":"0.02","size":"6811.25"},{"price":"0.03","size":"2680.33"},{"price":"0.04","size":"490.4"},{"price":"0.05","size":"1288.81"}],"asks":[{"price":"0.99","size":"24290.24"},{"price":"0.98","size":"7594.51"},{"price":"0.97","size":"5964.69"},{"price":"0.96","size":"5411.4"},{"price":"0.95","size":"5356.39"},{"price":"0.94","size":"5328"},{"price":"0.93","size":"5039.28"},{"price":"0.92","size":"5022.7"},{"price":"0.91","size":"5320.9"},{"price":"0.9","size":"5158.44"},{"price":"0.89","size":"18.3"},{"price":"0.88","size":"30.3"},{"price":"0.87","size":"16.5"},{"price":"0.86","size":"15.8"},{"price":"0.85","size":"104.19"},{"price":"0.84","size":"24.69"},{"price":"0.83","size":"14.19"},{"price":"0.82","size":"13.8"},{"price":"0.81","size":"13.4"},{"price":"0.8","size":"38.1"},{"price":"0.79","size":"12.8"},{"price":"0.78","size":"12.6"},{"price":"0.77","size":"12.3"},{"price":"0.76","size":"22.1"},{"price":"0.75","size":"16.9"},{"price":"0.74","size":"21.8"},{"price":"0.73","size":"11.6"},{"price":"0.72","size":"11.4"},{"price":"0.71","size":"61.3"},{"price":"0.7","size":"26.2"},{"price":"0.69","size":"11.1"},{"price":"0.68","size":"11"},{"price":"0.67","size":"110.9"},{"price":"0.66","size":"10.8"},{"price":"0.65","size":"15.7"},{"price":"0.64","size":"10.6"},{"price":"0.63","size":"10.6"},{"price":"0.62","size":"22.5"},{"price":"0.61","size":"10.5"},{"price":"0.6","size":"45.4"},{"price":"0.59","size":"311.4"},{"price":"0.58","size":"820.82"},{"price":"0.57","size":"826.3"},{"price":"0.56","size":"1062.3"},{"price":"0.55","size":"582.3"},{"price":"0.54","size":"626.2"},{"price":"0.53","size":"562.2"},{"price":"0.52","size":"567.2"},{"price":"0.51","size":"573.2"},{"price":"0.5","size":"917.2"},{"price":"0.49","size":"591.2"},{"price":"0.48","size":"590.2"},{"price":"0.47","size":"573.2"},{"price":"0.46","size":"636.61"},{"price":"0.45","size":"362.97"},{"price":"0.44","size":"341.3"},{"price":"0.43","size":"320.62"},{"price":"0.42","size":"567.3"},{"price":"0.41","size":"562.4"},{"price":"0.4","size":"693.02"},{"price":"0.39","size":"625.5"},{"price":"0.38","size":"668.5"},{"price":"0.37","size":"672.32"},{"price":"0.36","size":"680.6"},{"price":"0.35","size":"536.14"},{"price":"0.34","size":"602.8"},{"price":"0.33","size":"572.9"},{"price":"0.32","size":"573"},{"price":"0.31","size":"595.1"},{"price":"0.3","size":"603.2"},{"price":"0.29","size":"1318.72"},{"price":"0.28","size":"1043.04"},{"price":"0.27","size":"663.6"},{"price":"0.26","size":"911.17"},{"price":"0.25","size":"694.3"},{"price":"0.24","size":"717.6"},{"price":"0.23","size":"1183.3"},{"price":"0.22","size":"1526.53"},{"price":"0.21","size":"1178.8"},{"price":"0.2","size":"1445.08"},{"price":"0.19","size":"1229.8"},{"price":"0.18","size":"1467.57"},{"price":"0.17","size":"1520.51"},{"price":"0.16","size":"1718.59"},{"price":"0.15","size":"1762.5"},{"price":"0.14","size":"1755.6"},{"price":"0.13","size":"1588.93"},{"price":"0.12","size":"2555.4"},{"price":"0.11","size":"1898.8"},{"price":"0.1","size":"3426.54"},{"price":"0.09","size":"2701.44"},{"price":"0.08","size":"2317.36"},{"price":"0.07","size":"1564.82"},{"price":"0.06","size":"1639.22"}],"hash":"32a738af3403f57b7c09905e23893937a8ea9948","timestamp":"1768250242214","event_type":"book"}}
{"schema_version":1,"source":"clob_ws_market","recv_ts_ns":1768250242329300983,"event_type":"price_change","market":"0xe51aa24ab1bbfefce466d642ad98587d13123e4ef95ec9aa73b712e775d4cbba","server_ts_ms":1768250242259,"raw":{"market":"0xe51aa24ab1bbfefce466d642ad98587d13123e4ef95ec9aa73b712e775d4cbba","price_changes":[{"asset_id":"54232589582260339592359130012520874109228367674780084862642636038394766871668","price":"0.02","size":"6861.25","side":"BUY","hash":"c43b96c4576889e9d7ca8ed9eb7675c32869a63a","best_bid":"0.05","best_ask":"0.06"},{"asset_id":"96886111393998001968863279421729456597655847484197549086072988901191634450924","price":"0.98","size":"6861.25","side":"SELL","hash":"6594b08b3ffde6611b2bff5be86e9458bdc9ae77","best_bid":"0.94","best_ask":"0.95"}],"timestamp":"1768250242259","event_type":"price_change"}}
{"schema_version":1,"source":"clob_ws_market","recv_ts_ns":1768250242331775886,"event_type":"price_change","market":"0xe51aa24ab1bbfefce466d642ad98587d13123e4ef95ec9aa73b712e775d4cbba","server_ts_ms":1768250242301,"raw":{"market":"0xe51aa24ab1bbfefce466d642ad98587d13123e4ef95ec9aa73b712e775d4cbba","price_changes":[{"asset_id":"96886111393998001968863279421729456597655847484197549086072988901191634450924","price":"0.84","size":"1723.59","side":"BUY","hash":"2604d64e0cdfdbbfc3050a77a2b396b96456420d","best_bid":"0.94","best_ask":"0.95"},{"asset_id":"54232589582260339592359130012520874109228367674780084862642636038394766871668","price":"0.16","size":"1723.59","side":"SELL","hash":"d07b919f05829ec5bbd19bb0aef84083ee961903","best_bid":"0.05","best_ask":"0.06"}],"timestamp":"1768250242301","event_type":"price_change"}}
{"schema_version":1,"source":"clob_ws_market","recv_ts_ns":1768250242496058279,"event_type":"price_change","market":"0xe51aa24ab1bbfefce466d642ad98587d13123e4ef95ec9aa73b712e775d4cbba","server_ts_ms":1768250242418,"raw":{"market":"0xe51aa24ab1bbfefce466d642ad98587d13123e4ef95ec9aa73b712e775d4cbba","price_changes":[{"asset_id":"54232589582260339592359130012520874109228367674780084862642636038394766871668","price":"0.02","size":"6835.25","side":"BUY","hash":"faef0246309041cb394df9c430b9c834b3ef0428","best_bid":"0.05","best_ask":"0.06"},{"asset_id":"96886111393998001968863279421729456597655847484197549086072988901191634450924","price":"0.98","size":"6835.25","side":"SELL","hash":"1101c761c6868f4c8286888c7e617b69570db05d","best_bid":"0.94","best_ask":"0.95"}],"timestamp":"1768250242418","event_type":"price_change"}}
{"schema_version":1,"source":"clob_ws_market","recv_ts_ns":1768250242522754641,"event_type":"price_change","market":"0xe51aa24ab1bbfefce466d642ad98587d13123e4ef95ec9aa73b712e775d4cbba","server_ts_ms":1768250242462,"raw":{"market":"0xe51aa24ab1bbfefce466d642ad98587d13123e4ef95ec9aa73b712e775d4cbba","price_changes":[{"asset_id":"54232589582260339592359130012520874109228367674780084862642636038394766871668","price":"0.02","size":"6863.25","side":"BUY","hash":"de906f8f87c8a0407aae17443f359d699ec83a1b","best_bid":"0.05","best_ask":"0.06"},{"asset_id":"96886111393998001968863279421729456597655847484197549086072988901191634450924","price":"0.98","size":"6863.25","side":"SELL","hash":"19609d91d9c6641a0b73c8dacd2bceab0e6eebbd","best_bid":"0.94","best_ask":"0.95"}],"timestamp":"1768250242462","event_type":"price_change"}}
{"schema_version":1,"source":"clob_ws_market","recv_ts_ns":1768250242536255849,"event_type":"price_change","market":"0xe51aa24ab1bbfefce466d642ad98587d13123e4ef95ec9aa73b712e775d4cbba","server_ts_ms":1768250242508,"raw":{"market":"0xe51aa24ab1bbfefce466d642ad98587d13123e4ef95ec9aa73b712e775d4cbba","price_changes":[{"asset_id":"96886111393998001968863279421729456597655847484197549086072988901191634450924","price":"0.84","size":"1718.59","side":"BUY","hash":"5000fa63ffd0642674ea3985bef1568031ec2546","best_bid":"0.94","best_ask":"0.95"},{"asset_id":"54232589582260339592359130012520874109228367674780084862642636038394766871668","price":"0.16","size":"1718.59","side":"SELL","hash":"5c50db75df2f7395aeb822d4adfe6af72209f4c8","best_bid":"0.05","best_ask":"0.06"}],"timestamp":"1768250242508","event_type":"price_change"}}
{"schema_version":1,"source":"clob_ws_market","recv_ts_ns":1768250242650571404,"event_type":"price_change","market":"0xe51aa24ab1bbfefce466d642ad98587d13123e4ef95ec9aa73b712e775d4cbba","server_ts_ms":1768250242624,"raw":{"market":"0xe51aa24ab1bbfefce466d642ad98587d13123e4ef95ec9aa73b712e775d4cbba","price_changes":[{"asset_id":"54232589582260339592359130012520874109228367674780084862642636038394766871668","price":"0.02","size":"6835.25","side":"BUY","hash":"1eb6940c58be9a95b54099b534582e95a7ac9c95","best_bid":"0.05","best_ask":"0.06"},{"asset_id":"96886111393998001968863279421729456597655847484197549086072988901191634450924","price":"0.98","size":"6835.25","side":"SELL","hash":"e0dcfebba23c89baa7d71415ed6c5205c86a5fcc","best_bid":"0.94","best_ask":"0.95"}],"timestamp":"1768250242624","event_type":"price_change"}}
{"schema_version":1,"source":"clob_ws_market","recv_ts_ns":1768250242753488532,"event_type":"price_change","market":"0xe51aa24ab1bbfefce466d642ad98587d13123e4ef95ec9aa73b712e775d4cbba","server_ts_ms":1768250242675,"raw":{"market":"0xe51aa24ab1bbfefce466d642ad98587d13123e4ef95ec9aa73b712e775d4cbba","price_changes":[{"asset_id":"54232589582260339592359130012520874109228367674780084862642636038394766871668","price":"0.02","size":"6863.25","side":"BUY","hash":"d9eb64bbcc88ef304ade9cda6e64ab57f3af557a","best_bid":"0.05","best_ask":"0.06"},{"asset_id":"96886111393998001968863279421729456597655847484197549086072988901191634450924","price":"0.98","size":"6863.25","side":"SELL","hash":"902a889a5dfbed366b90a9e4b9468a3ca261feae","best_bid":"0.94","best_ask":"0.95"}],"timestamp":"1768250242675","event_type":"price_change"}}
{"schema_version":1,"source":"clob_ws_market","recv_ts_ns":1768250242831740252,"event_type":"price_change","market":"0xe51aa24ab1bbfefce466d642ad98587d13123e4ef95ec9aa73b712e775d4cbba","server_ts_ms":1768250242804,"raw":{"market":"0xe51aa24ab1bbfefce466d642ad98587d13123e4ef95ec9aa73b712e775d4cbba","price_changes":[{"asset_id":"54232589582260339592359130012520874109228367674780084862642636038394766871668","price":"0.02","size":"6835.25","side":"BUY","hash":"1236f78921e3151aa50100663b1015fbc270ff35","best_bid":"0.05","best_ask":"0.06"},{"asset_id":"96886111393998001968863279421729456597655847484197549086072988901191634450924","price":"0.98","size":"6835.25","side":"SELL","hash":"066dd427b31b35862ab14096ed661ebb94046ea1","best_bid":"0.94","best_ask":"0.95"}],"timestamp":"1768250242804","event_type":"price_change"}}
{"schema_version":1,"source":"clob_ws_market","recv_ts_ns":1768250242882838447,"event_type":"price_change","market":"0xe51aa24ab1bbfefce466d642ad98587d13123e4ef95ec9aa73b712e775d4cbba","server_ts_ms":1768250242862,"raw":{"market":"0xe51aa24ab1bbfefce466d642ad98587d13123e4ef95ec9aa73b712e775d4cbba","price_changes":[{"asset_id":"54232589582260339592359130012520874109228367674780084862642636038394766871668","price":"0.02","size":"6863.25","side":"BUY","hash":"6bbfe633719b2342e1313f3adae47c6b72e9ec6f","best_bid":"0.05","best_ask":"0.06"},{"asset_id":"96886111393998001968863279421729456597655847484197549086072988901191634450924","price":"0.98","size":"6863.25","side":"SELL","hash":"ced0a8b56c284934fe0162d6662d0a41a0117faa","best_bid":"0.94","best_ask":"0.95"}],"timestamp":"1768250242862","event_type":"price_change"}}
{"schema_version":1,"source":"clob_ws_market","recv_ts_ns":1768250242932128303,"event_type":"price_change","market":"0xe51aa24ab1bbfefce466d642ad98587d13123e4ef95ec9aa73b712e775d4cbba","server_ts_ms":1768250242898,"raw":{"market":"0xe51aa24ab1bbfefce466d642ad98587d13123e4ef95ec9aa73b712e775d4cbba","price_changes":[{"asset_id":"96886111393998001968863279421729456597655847484197549086072988901191634450924","price":"0.94","size":"1620.22","side":"BUY","hash":"552390b24c7e643fc660ebc71350ee5f0a20c350","best_bid":"0.94","best_ask":"0.95"},{"asset_id":"54232589582260339592359130012520874109228367674780084862642636038394766871668","price":"0.06","size":"1620.22","side":"SELL","hash":"dc578e9960b9300ec838685b4c242f9297443183","best_bid":"0.05","best_ask":"0.06"}],"timestamp":"1768250242898","event_type":"price_change"}}
{"schema_version":1,"source":"clob_ws_market","recv_ts_ns":1768250243038865886,"event_type":"price_change","market":"0xe51aa24ab1bbfefce466d642ad98587d13123e4ef95ec9aa73b712e775d4cbba","server_ts_ms":1768250243000,"raw":{"market":"0xe51aa24ab1bbfefce466d642ad98587d13123e4ef95ec9aa73b712e775d4cbba","price_changes":[{"asset_id":"54232589582260339592359130012520874109228367674780084862642636038394766871668","price":"0.02","size":"6763.25","side":"BUY","hash":"2fa8fe057b97720b4991a850da487fdd826161d8","best_bid":"0.05","best_ask":"0.06"},{"asset_id":"96886111393998001968863279421729456597655847484197549086072988901191634450924","price":"0.98","size":"6763.25","side":"SELL","hash":"1784d9e7d63a469070b0951a1a076f43be750a55","best_bid":"0.94","best_ask":"0.95"}],"timestamp":"1768250243000","event_type":"price_change"}}
{"schema_version":1,"source":"clob_ws_market","recv_ts_ns":1768250243043688830,"event_type":"price_change","market":"0xe51aa24ab1bbfefce466d642ad98587d13123e4ef95ec9aa73b712e775d4cbba","server_ts_ms":1768250243016,"raw":{"market":"0xe51aa24ab1bbfefce466d642ad98587d13123e4ef95ec9aa73b712e775d4cbba","price_changes":[{"asset_id":"54232589582260339592359130012520874109228367674780084862642636038394766871668","price":"0.02","size":"6735.25","side":"BUY","hash":"b37e523a5300130143491fd092c8bc4a22266817","best_bid":"0.05","best_ask":"0.06"},{"asset_id":"96886111393998001968863279421729456597655847484197549086072988901191634450924","price":"0.98","size":"6735.25","side":"SELL","hash":"1ce62d5a45f3137373518f64fcd6ab6ef03627b9","best_bid":"0.94","best_ask":"0.95"}],"timestamp":"1768250243016","event_type":"price_change"}}
{"schema_version":1,"source":"clob_ws_market","recv_ts_ns":1768250243083714427,"event_type":"price_change","market":"0xe51aa24ab1bbfefce466d642ad98587d13123e4ef95ec9aa73b712e775d4cbba","server_ts_ms":1768250243063,"raw":{"market":"0xe51aa24ab1bbfefce466d642ad98587d13123e4ef95ec9aa73b712e775d4cbba","price_changes":[{"asset_id":"54232589582260339592359130012520874109228367674780084862642636038394766871668","price":"0.02","size":"6763.25","side":"BUY","hash":"2c36d26f1d257439fc88da2fe6507ba8e47e42cf","best_bid":"0.05","best_ask":"0.06"},{"asset_id":"96886111393998001968863279421729456597655847484197549086072988901191634450924","price":"0.98","size":"6763.25","side":"SELL","hash":"6e643dba67d5e3f97df7766ff59cd00710ac3144","best_bid":"0.94","best_ask":"0.95"}],"timestamp":"1768250243063","event_type":"price_change"}}
{"schema_version":1,"source":"clob_ws_market","recv_ts_ns":1768250243227286336,"event_type":"price_change","market":"0xe51aa24ab1bbfefce466d642ad98587d13123e4ef95ec9aa73b712e775d4cbba","server_ts_ms":1768250243156,"raw":{"market":"0xe51aa24ab1bbfefce466d642ad98587d13123e4ef95ec9aa73b712e775d4cbba","price_changes":[{"asset_id":"96886111393998001968863279421729456597655847484197549086072988901191634450924","price":"0.93","size":"1539.82","side":"BUY","hash":"e49e6516440c5ea0ea7202496aec240437c1e838","best_bid":"0.94","best_ask":"0.95"},{"asset_id":"54232589582260339592359130012520874109228367674780084862642636038394766871668","price":"0.07","size":"1539.82","side":"SELL","hash":"7dcc30537dd2dc472f7cc35b40f4e71e09fc3612","best_bid":"0.05","best_ask":"0.06"}],"timestamp":"1768250243156","event_type":"price_change"}}
{"schema_version":1,"source":"clob_ws_market","recv_ts_ns":1768250243234019244,"event_type":"price_change","market":"0xe51aa24ab1bbfefce466d642ad98587d13123e4ef95ec9aa73b712e775d4cbba","server_ts_ms":1768250243158,"raw":{"market":"0xe51aa24ab1bbfefce466d642ad98587d13123e4ef95ec9aa73b712e775d4cbba","price_changes":[{"asset_id":"54232589582260339592359130012520874109228367674780084862642636038394766871668","price":"0.07","size":"1514.82","side":"SELL","hash":"ced4dbfb1f6afe577674cf6704812aefd95a8fa5","best_bid":"0.05","best_ask":"0.06"},{"asset_id":"96886111393998001968863279421729456597655847484197549086072988901191634450924","price":"0.93","size":"1514.82","side":"BUY","hash":"604158eccf13a5ad4e9a1f3a77cec865c7fb3590","best_bid":"0.94","best_ask":"0.95"}],"timestamp":"1768250243158","event_type":"price_change"}}
{"schema_version":1,"source":"clob_ws_market","recv_ts_ns":1768250243238728545,"event_type":"price_change","market":"0xe51aa24ab1bbfefce466d642ad98587d13123e4ef95ec9aa73b712e775d4cbba","server_ts_ms":1768250243159,"raw":{"market":"0xe51aa24ab1bbfefce466d642ad98587d13123e4ef95ec9aa73b712e775d4cbba","price_changes":[{"asset_id":"54232589582260339592359130012520874109228367674780084862642636038394766871668","price":"0.08","size":"2342.36","side":"SELL","hash":"bc007235b5cd72475f5018e19d7b54e73ba9b818","best_bid":"0.05","best_ask":"0.06"},{"asset_id":"96886111393998001968863279421729456597655847484197549086072988901191634450924","price":"0.92","size":"2342.36","side":"BUY","hash":"18445a014210d3915e6dd8284bf91fff4f629cc3","best_bid":"0.94","best_ask":"0.95"}],"timestamp":"1768250243159","event_type":"price_change"}}
{"schema_version":1,"source":"clob_ws_market","recv_ts_ns":1768250243242559016,"event_type":"price_change","market":"0xe51aa24ab1bbfefce466d642ad98587d13123e4ef95ec9aa73b712e775d4cbba","server_ts_ms":1768250243160,"raw":{"market":"0xe51aa24ab1bbfefce466d642ad98587d13123e4ef95ec9aa73b712e775d4cbba","price_changes":[{"asset_id":"96886111393998001968863279421729456597655847484197549086072988901191634450924","price":"0.94","size":"1595.22","side":"BUY","hash":"3714c64dfeb7f071a57d140d67a2736cddca13fb","best_bid":"0.94","best_ask":"0.95"},{"asset_id":"54232589582260339592359130012520874109228367674780084862642636038394766871668","price":"0.06","size":"1595.22","side":"SELL","hash":"9df6fa74933cf7c5ebcd4567bcf9b3f739dc6d24","best_bid":"0.05","best_ask":"0.06"}],"timestamp":"1768250243160","event_type":"price_change"}}
{"schema_version":1,"source":"clob_ws_market","recv_ts_ns":1768250243250021549,"event_type":"price_change","market":"0xe51aa24ab1bbfefce466d642ad98587d13123e4ef95ec9aa73b712e775d4cbba","server_ts_ms":1768250243162,"raw":{"market":"0xe51aa24ab1bbfefce466d642ad98587d13123e4ef95ec9aa73b712e775d4cbba","price_changes":[{"asset_id":"96886111393998001968863279421729456597655847484197549086072988901191634450924","price":"0.93","size":"1539.82","side":"BUY","hash":"45fc0600c665be816934f35768035ff528807b02","best_bid":"0.94","best_ask":"0.95"},{"asset_id":"54232589582260339592359130012520874109228367674780084862642636038394766871668","price":"0.07","size":"1539.82","side":"SELL","hash":"fb651b2125285e762b4af0a8a976a985b31f96f6","best_bid":"0.05","best_ask":"0.06"}],"timestamp":"1768250243162","event_type":"price_change"}}
{"schema_version":1,"source":"clob_ws_market","recv_ts_ns":1768250243253216399,"event_type":"price_change","market":"0xe51aa24ab1bbfefce466d642ad98587d13123e4ef95ec9aa73b712e775d4cbba","server_ts_ms":1768250243163,"raw":{"market":"0xe51aa24ab1bbfefce466d642ad98587d13123e4ef95ec9aa73b712e775d4cbba","price_changes":[{"asset_id":"54232589582260339592359130012520874109228367674780084862642636038394766871668","price":"0.06","size":"1570.22","side":"SELL","hash":"28206d1ffc38898718c2854edc1dc99181af32d5","best_bid":"0.05","best_ask":"0.06"},{"asset_id":"96886111393998001968863279421729456597655847484197549086072988901191634450924","price":"0.94","size":"1570.22","side":"BUY","hash":"34b5df19ead28610413aa8cca8b69000e0b24b70","best_bid":"0.94","best_ask":"0.95"}],"timestamp":"1768250243163","event_type":"price_change"}}
{"schema_version":1,"source":"clob_ws_market","recv_ts_ns":1768250243256555659,"event_type":"price_change","market":"0xe51aa24ab1bbfefce466d642ad98587d13123e4ef95ec9aa73b712e775d4cbba","server_ts_ms":1768250243164,"raw":{"market":"0xe51aa24ab1bbfefce466d642ad98587d13123e4ef95ec9aa73b712e775d4cbba","price_changes":[{"asset_id":"96886111393998001968863279421729456597655847484197549086072988901191634450924","price":"0.92","size":"2367.36","side":"BUY","hash":"9a70300b6a73b5a243ad4ecc7031468fb7683496","best_bid":"0.94","best_ask":"0.95"},{"asset_id":"54232589582260339592359130012520874109228367674780084862642636038394766871668","price":"0.08","size":"2367.36","side":"SELL","hash":"8abf39ac1443b1c3969490a86a34d17522e146be","best_bid":"0.05","best_ask":"0.06"}],"timestamp":"1768250243164","event_type":"price_change"}}
{"schema_version":1,"source":"clob_ws_market","recv_ts_ns":1768250243259699853,"event_type":"price_change","market":"0xe51aa24ab1bbfefce466d642ad98587d13123e4ef95ec9aa73b712e775d4cbba","server_ts_ms":1768250243167,"raw":{"market":"0xe51aa24ab1bbfefce466d642ad98587d13123e4ef95ec9aa73b712e775d4cbba","price_changes":[{"asset_id":"54232589582260339592359130012520874109228367674780084862642636038394766871668","price":"0.07","size":"1564.82","side":"SELL","hash":"45ba5f5b197f717ce7ab599710707dde1dfa8648","best_bid":"0.05","best_ask":"0.06"},{"asset_id":"96886111393998001968863279421729456597655847484197549086072988901191634450924","price":"0.93","size":"1564.82","side":"BUY","hash":"80984f61b20e4cc5d36482ac51b9a189acfaa974","best_bid":"0.94","best_ask":"0.95"}],"timestamp":"1768250243167","event_type":"price_change"}}
{"schema_version":1,"source":"clob_ws_market","recv_ts_ns":1768250243263535894,"event_type":"price_change","market":"0xe51aa24ab1bbfefce466d642ad98587d13123e4ef95ec9aa73b712e775d4cbba","server_ts_ms":1768250243179,"raw":{"market":"0xe51aa24ab1bbfefce466d642ad98587d13123e4ef95ec9aa73b712e775d4cbba","price_changes":[{"asset_id":"96886111393998001968863279421729456597655847484197549086072988901191634450924","price":"0.94","size":"1534.22","side":"BUY","hash":"bd38a9ce4db34219c3e60380740faa04326d4c85","best_bid":"0.94","best_ask":"0.95"},{"asset_id":"54232589582260339592359130012520874109228367674780084862642636038394766871668","price":"0.06","size":"1534.22","side":"SELL","hash":"bd87caf3aa33ed78080e71a9a762393ab59f5f39","best_bid":"0.05","best_ask":"0.06"}],"timestamp":"1768250243179","event_type":"price_change"}}
{"schema_version":1,"source":"clob_ws_market","recv_ts_ns":1768250243267132291,"event_type":"price_change","market":"0xe51aa24ab1bbfefce466d642ad98587d13123e4ef95ec9aa73b712e775d4cbba","server_ts_ms":1768250243186,"raw":{"market":"0xe51aa24ab1bbfefce466d642ad98587d13123e4ef95ec9aa73b712e775d4cbba","price_changes":[{"asset_id":"96886111393998001968863279421729456597655847484197549086072988901191634450924","price":"0.94","size":"1522.22","side":"BUY","hash":"654191b9a2ec2be067bba487babce64071179b7c","best_bid":"0.94","best_ask":"0.95"},{"asset_id":"54232589582260339592359130012520874109228367674780084862642636038394766871668","price":"0.06","size":"1522.22","side":"SELL","hash":"4d14ef1d76f210d65529f227e3381a6f3e45c661","best_bid":"0.05","best_ask":"0.06"}],"timestamp":"1768250243186","event_type":"price_change"}}
{"schema_version":1,"source":"clob_ws_market","recv_ts_ns":1768250243270393679,"event_type":"price_change","market":"0xe51aa24ab1bbfefce466d642ad98587d13123e4ef95ec9aa73b712e775d4cbba","server_ts_ms":1768250243188,"raw":{"market":"0xe51aa24ab1bbfefce466d642ad98587d13123e4ef95ec9aa73b712e775d4cbba","price_changes":[{"asset_id":"54232589582260339592359130012520874109228367674780084862642636038394766871668","price":"0.02","size":"6735.25","side":"BUY","hash":"a2f4e13f8ea62c8cd007435b711b955178d68651","best_bid":"0.05","best_ask":"0.06"},{"asset_id":"96886111393998001968863279421729456597655847484197549086072988901191634450924","price":"0.98","size":"6735.25","side":"SELL","hash":"3c8745d588f372a4e44fa57a78224461de51774f","best_bid":"0.94","best_ask":"0.95"}],"timestamp":"1768250243188","event_type":"price_change"}}
{"schema_version":1,"source":"clob_ws_market","recv_ts_ns":1768250243273988841,"event_type":"price_change","market":"0xe51aa24ab1bbfefce466d642ad98587d13123e4ef95ec9aa73b712e775d4cbba","server_ts_ms":1768250243203,"raw":{"market":"0xe51aa24ab1bbfefce466d642ad98587d13123e4ef95ec9aa73b712e775d4cbba","price_changes":[{"asset_id":"54232589582260339592359130012520874109228367674780084862642636038394766871668","price":"0.02","size":"6835.25","side":"BUY","hash":"7fc2dc47779f0788a85355c84e10daeb55a7d9f2","best_bid":"0.05","best_ask":"0.06"},{"asset_id":"96886111393998001968863279421729456597655847484197549086072988901191634450924","price":"0.98","size":"6835.25","side":"SELL","hash":"7f76381eeab6655409a89ea9fab11e57ca9d7baf","best_bid":"0.94","best_ask":"0.95"}],"timestamp":"1768250243203","event_type":"price_change"}}
{"schema_version":1,"source":"clob_ws_market","recv_ts_ns":1768250243281416718,"event_type":"price_change","market":"0xe51aa24ab1bbfefce466d642ad98587d13123e4ef95ec9aa73b712e775d4cbba","server_ts_ms":1768250243245,"raw":{"market":"0xe51aa24ab1bbfefce466d642ad98587d13123e4ef95ec9aa73b712e775d4cbba","price_changes":[{"asset_id":"54232589582260339592359130012520874109228367674780084862642636038394766871668","price":"0.02","size":"6863.25","side":"BUY","hash":"2f2c9217c0e4580fc2a2148585055304efbd3b8d","best_bid":"0.05","best_ask":"0.06"},{"asset_id":"96886111393998001968863279421729456597655847484197549086072988901191634450924","price":"0.98","size":"6863.25","side":"SELL","hash":"a26f80dd42e3cce1bcf7237bd68ef0b01efdc1be","best_bid":"0.94","best_ask":"0.95"}],"timestamp":"1768250243245","event_type":"price_change"}}
{"schema_version":1,"source":"clob_ws_market","recv_ts_ns":1768250243290721346,"event_type":"price_change","market":"0xe51aa24ab1bbfefce466d642ad98587d13123e4ef95ec9aa73b712e775d4cbba","server_ts_ms":1768250243268,"raw":{"market":"0xe51aa24ab1bbfefce466d642ad98587d13123e4ef95ec9aa73b712e775d4cbba","price_changes":[{"asset_id":"54232589582260339592359130012520874109228367674780084862642636038394766871668","price":"0.04","size":"502.4","side":"BUY","hash":"1d3f66999becc870f966f664622f38a7ca292917","best_bid":"0.05","best_ask":"0.06"},{"asset_id":"96886111393998001968863279421729456597655847484197549086072988901191634450924","price":"0.96","size":"502.4","side":"SELL","hash":"08455c3530b742005ed286665dee23b7748c40b4","best_bid":"0.94","best_ask":"0.95"}],"timestamp":"1768250243268","event_type":"price_change"}}
{"schema_version":1,"source":"clob_ws_market","recv_ts_ns":1768250243299019652,"event_type":"price_change","market":"0xe51aa24ab1bbfefce466d642ad98587d13123e4ef95ec9aa73b712e775d4cbba","server_ts_ms":1768250243277,"raw":{"market":"0xe51aa24ab1bbfefce466d642ad98587d13123e4ef95ec9aa73b712e775d4cbba","price_changes":[{"asset_id":"96886111393998001968863279421729456597655847484197549086072988901191634450924","price":"0.96","size":"521.4","side":"SELL","hash":"0543a845204f09054732d6704e5940d8a02d2bd1","best_bid":"0.94","best_ask":"0.95"},{"asset_id":"54232589582260339592359130012520874109228367674780084862642636038394766871668","price":"0.04","size":"521.4","side":"BUY","hash":"668ae23297d79169549a3f31436a5a0b49590ac8","best_bid":"0.05","best_ask":"0.06"}],"timestamp":"1768250243277","event_type":"price_change"}}
{"schema_version":1,"source":"clob_ws_market","recv_ts_ns":1768250243423548591,"event_type":"price_change","market":"0xe51aa24ab1bbfefce466d642ad98587d13123e4ef95ec9aa73b712e775d4cbba","server_ts_ms":1768250243398,"raw":{"market":"0xe51aa24ab1bbfefce466d642ad98587d13123e4ef95ec9aa73b712e775d4cbba","price_changes":[{"asset_id":"54232589582260339592359130012520874109228367674780084862642636038394766871668","price":"0.02","size":"6835.25","side":"BUY","hash":"60ee826a6912ba3bd63b3c0f73b8b2890a294c70","best_bid":"0.05","best_ask":"0.06"},{"asset_id":"96886111393998001968863279421729456597655847484197549086072988901191634450924","price":"0.98","size":"6835.25","side":"SELL","hash":"a4e13060d093568642ad66dd473a6a7d66870027","best_bid":"0.94","best_ask":"0.95"}],"timestamp":"1768250243398","event_type":"price_change"}}
{"schema_version":1,"source":"clob_ws_market","recv_ts_ns":1768250243431095254,"event_type":"price_change","market":"0xe51aa24ab1bbfefce466d642ad98587d13123e4ef95ec9aa73b712e775d4cbba","server_ts_ms":1768250243404,"raw":{"market":"0xe51aa24ab1bbfefce466d642ad98587d13123e4ef95ec9aa73b712e775d4cbba","price_changes":[{"asset_id":"54232589582260339592359130012520874109228367674780084862642636038394766871668","price":"0.07","size":"1544.82","side":"SELL","hash":"bbf520ec5b35ee66d7b8ad62d8b771684a6a4c86","best_bid":"0.05","best_ask":"0.06"},{"asset_id":"96886111393998001968863279421729456597655847484197549086072988901191634450924","price":"0.93","size":"1544.82","side":"BUY","hash":"d3cb0d609a1a11bc245cae502788a36683406a2e","best_bid":"0.94","best_ask":"0.95"}],"timestamp":"1768250243404","event_type":"price_change"}}
{"schema_version":1,"source":"clob_ws_market","recv_ts_ns":1768250243437220011,"event_type":"price_change","market":"0xe51aa24ab1bbfefce466d642ad98587d13123e4ef95ec9aa73b712e775d4cbba","server_ts_ms":1768250243406,"raw":{"market":"0xe51aa24ab1bbfefce466d642ad98587d13123e4ef95ec9aa73b712e775d4cbba","price_changes":[{"asset_id":"54232589582260339592359130012520874109228367674780084862642636038394766871668","price":"0.07","size":"1564.82","side":"SELL","hash":"beecb6e277cfb7297905bd7c4adeaf0f1e84f03e","best_bid":"0.05","best_ask":"0.06"},{"asset_id":"96886111393998001968863279421729456597655847484197549086072988901191634450924","price":"0.93","size":"1564.82","side":"BUY","hash":"906f12d5cbb9e1ba23c9034f61cf94277cd6cf26","best_bid":"0.94","best_ask":"0.95"}],"timestamp":"1768250243406","event_type":"price_change"}}
{"schema_version":1,"source":"clob_ws_market","recv_ts_ns":1768250243536453150,"event_type":"price_change","market":"0xe51aa24ab1bbfefce466d642ad98587d13123e4ef95ec9aa73b712e775d4cbba","server_ts_ms":1768250243442,"raw":{"market":"0xe51aa24ab1bbfefce466d642ad98587d13123e4ef95ec9aa73b712e775d4cbba","price_changes":[{"asset_id":"54232589582260339592359130012520874109228367674780084862642636038394766871668","price":"0.02","size":"6863.25","side":"BUY","hash":"7c7c8ec28e376f8261c4b8c692ef48ed270b0811","best_bid":"0.05","best_ask":"0.06"},{"asset_id":"96886111393998001968863279421729456597655847484197549086072988901191634450924","price":"0.98","size":"6863.25","side":"SELL","hash":"ce3a0f644dff9c749608bfcb86106e568db502ba","best_bid":"0.94","best_ask":"0.95"}],"timestamp":"1768250243442","event_type":"price_change"}}
{"schema_version":1,"source":"clob_ws_market","recv_ts_ns":1768250243565891336,"event_type":"price_change","market":"0xe51aa24ab1bbfefce466d642ad98587d13123e4ef95ec9aa73b712e775d4cbba","server_ts_ms":1768250243451,"raw":{"market":"0xe51aa24ab1bbfefce466d642ad98587d13123e4ef95ec9aa73b712e775d4cbba","price_changes":[{"asset_id":"96886111393998001968863279421729456597655847484197549086072988901191634450924","price":"0.72","size":"1048.04","side":"BUY","hash":"5e01b88b1a7f1f46bab0049fd9757ffb4016fbc0","best_bid":"0.94","best_ask":"0.95"},{"asset_id":"54232589582260339592359130012520874109228367674780084862642636038394766871668","price":"0.28","size":"1048.04","side":"SELL","hash":"f8a905b89253b85dd00392ef3b4c4359206a535b","best_bid":"0.05","best_ask":"0.06"}],"timestamp":"1768250243451","event_type":"price_change"}}
{"schema_version":1,"source":"clob_ws_market","recv_ts_ns":1768250243583702083,"event_type":"price_change","market":"0xe51aa24ab1bbfefce466d642ad98587d13123e4ef95ec9aa73b712e775d4cbba","server_ts_ms":1768250243485,"raw":{"market":"0xe51aa24ab1bbfefce466d642ad98587d13123e4ef95ec9aa73b712e775d4cbba","price_changes":[{"asset_id":"54232589582260339592359130012520874109228367674780084862642636038394766871668","price":"0.04","size":"509.4","side":"BUY","hash":"1ceb60d0d51a0c8d8403f0488e44ee1ed665e846","best_bid":"0.05","best_ask":"0.06"},{"asset_id":"96886111393998001968863279421729456597655847484197549086072988901191634450924","price":"0.96","size":"509.4","side":"SELL","hash":"17515166c7210c1231b982daa2c72618b0bb557b","best_bid":"0.94","best_ask":"0.95"}],"timestamp":"1768250243485","event_type":"price_change"}}
{"schema_version":1,"source":"clob_ws_market","recv_ts_ns":1768250243594802060,"event_type":"price_change","market":"0xe51aa24ab1bbfefce466d642ad98587d13123e4ef95ec9aa73b712e775d4cbba","server_ts_ms":1768250243498,"raw":{"market":"0xe51aa24ab1bbfefce466d642ad98587d13123e4ef95ec9aa73b712e775d4cbba","price_changes":[{"asset_id":"96886111393998001968863279421729456597655847484197549086072988901191634450924","price":"0.96","size":"490.4","side":"SELL","hash":"37f078922fc7e478d24b63ed8ca6057fc9c520c0","best_bid":"0.94","best_ask":"0.95"},{"asset_id":"54232589582260339592359130012520874109228367674780084862642636038394766871668","price":"0.04","size":"490.4","side":"BUY","hash":"898d928a5613434b96e471181787063402082c8f","best_bid":"0.05","best_ask":"0.06"}],"timestamp":"1768250243498","event_type":"price_change"}}
{"schema_version":1,"source":"clob_ws_market","recv_ts_ns":1768250243613498158,"event_type":"price_change","market":"0xe51aa24ab1bbfefce466d642ad98587d13123e4ef95ec9aa73b712e775d4cbba","server_ts_ms":1768250243536,"raw":{"market":"0xe51aa24ab1bbfefce466d642ad98587d13123e4ef95ec9aa73b712e775d4cbba","price_changes":[{"asset_id":"54232589582260339592359130012520874109228367674780084862642636038394766871668","price":"0.02","size":"6835.25","side":"BUY","hash":"bf8ce410336bf8413cf67b842d41288d801ff6b2","best_bid":"0.05","best_ask":"0.06"},{"asset_id":"96886111393998001968863279421729456597655847484197549086072988901191634450924","price":"0.98","size":"6835.25","side":"SELL","hash":"270de80cac472a70146040ad8819e5028e208b26","best_bid":"0.94","best_ask":"0.95"}],"timestamp":"1768250243536","event_type":"price_change"}}
{"schema_version":1,"source":"clob_ws_market","recv_ts_ns":1768250243619395136,"event_type":"price_change","market":"0xe51aa24ab1bbfefce466d642ad98587d13123e4ef95ec9aa73b712e775d4cbba","server_ts_ms":1768250243561,"raw":{"market":"0xe51aa24ab1bbfefce466d642ad98587d13123e4ef95ec9aa73b712e775d4cbba","price_changes":[{"asset_id":"96886111393998001968863279421729456597655847484197549086072988901191634450924","price":"0.96","size":"502.4","side":"SELL","hash":"a355a6a0f6ceda8fd8d55b138b6e75befbc2c5f3","best_bid":"0.94","best_ask":"0.95"},{"asset_id":"54232589582260339592359130012520874109228367674780084862642636038394766871668","price":"0.04","size":"502.4","side":"BUY","hash":"91c69cb18a14523ff3e9e66f50d8e5f336d4ffea","best_bid":"0.05","best_ask":"0.06"}],"timestamp":"1768250243561","event_type":"price_change"}}
{"schema_version":1,"source":"clob_ws_market","recv_ts_ns":1768250243624964477,"event_type":"price_change","market":"0xe51aa24ab1bbfefce466d642ad98587d13123e4ef95ec9aa73b712e775d4cbba","server_ts_ms":1768250243564,"raw":{"market":"0xe51aa24ab1bbfefce466d642ad98587d13123e4ef95ec9aa73b712e775d4cbba","price_changes":[{"asset_id":"54232589582260339592359130012520874109228367674780084862642636038394766871668","price":"0.04","size":"526.4","side":"BUY","hash":"ebc0ef853d925f538b5bec4af8290cee1d05df8c","best_bid":"0.05","best_ask":"0.06"},{"asset_id":"96886111393998001968863279421729456597655847484197549086072988901191634450924","price":"0.96","size":"526.4","side":"SELL","hash":"b650025d880d45a706660f8a95fe75f0f74c4987","best_bid":"0.94","best_ask":"0.95"}],"timestamp":"1768250243564","event_type":"price_change"}}
{"schema_version":1,"source":"clob_ws_market","recv_ts_ns":1768250243629520785,"event_type":"price_change","market":"0xe51aa24ab1bbfefce466d642ad98587d13123e4ef95ec9aa73b712e775d4cbba","server_ts_ms":1768250243582,"raw":{"market":"0xe51aa24ab1bbfefce466d642ad98587d13123e4ef95ec9aa73b712e775d4cbba","price_changes":[{"asset_id":"54232589582260339592359130012520874109228367674780084862642636038394766871668","price":"0.02","size":"6863.25","side":"BUY","hash":"345b69f84d956980d90583e3c5cbc2172d7996ca","best_bid":"0.05","best_ask":"0.06"},{"asset_id":"96886111393998001968863279421729456597655847484197549086072988901191634450924","price":"0.98","size":"6863.25","side":"SELL","hash":"350f5785f9e3b0323cb3c95a08aa2700ef9b8b7e","best_bid":"0.94","best_ask":"0.95"}],"timestamp":"1768250243582","event_type":"price_change"}}
{"schema_version":1,"source":"clob_ws_market","recv_ts_ns":1768250243634183612,"event_type":"price_change","market":"0xe51aa24ab1bbfefce466d642ad98587d13123e4ef95ec9aa73b712e775d4cbba","server_ts_ms":1768250243611,"raw":{"market":"0xe51aa24ab1bbfefce466d642ad98587d13123e4ef95ec9aa73b712e775d4cbba","price_changes":[{"asset_id":"96886111393998001968863279421729456597655847484197549086072988901191634450924","price":"0.96","size":"514.4","side":"SELL","hash":"3b2c9ceb92306b3550d11cbb612ee761e5d0bc84","best_bid":"0.94","best_ask":"0.95"},{"asset_id":"54232589582260339592359130012520874109228367674780084862642636038394766871668","price":"0.04","size":"514.4","side":"BUY","hash":"eaed395d6030054e33873bb8bde41bbe438550ee","best_bid":"0.05","best_ask":"0.06"}],"timestamp":"1768250243611","event_type":"price_change"}}
{"schema_version":1,"source":"clob_ws_market","recv_ts_ns":1768250243639367236,"event_type":"price_change","market":"0xe51aa24ab1bbfefce466d642ad98587d13123e4ef95ec9aa73b712e775d4cbba","server_ts_ms":1768250243613,"raw":{"market":"0xe51aa24ab1bbfefce466d642ad98587d13123e4ef95ec9aa73b712e775d4cbba","price_changes":[{"asset_id":"54232589582260339592359130012520874109228367674780084862642636038394766871668","price":"0.04","size":"490.4","side":"BUY","hash":"f7cd1ddbd5197257b23a2bfba655d8817a947073","best_bid":"0.05","best_ask":"0.06"},{"asset_id":"96886111393998001968863279421729456597655847484197549086072988901191634450924","price":"0.96","size":"490.4","side":"SELL","hash":"d607a6bfc33f1b8e765468ad35dd4a699d50ef01","best_bid":"0.94","best_ask":"0.95"}],"timestamp":"1768250243613","event_type":"price_change"}}
{"schema_version":1,"source":"clob_ws_market","recv_ts_ns":1768250243671751878,"event_type":"price_change","market":"0xe51aa24ab1bbfefce466d642ad98587d13123e4ef95ec9aa73b712e775d4cbba","server_ts_ms":1768250243647,"raw":{"market":"0xe51aa24ab1bbfefce466d642ad98587d13123e4ef95ec9aa73b712e775d4cbba","price_changes":[{"asset_id":"96886111393998001968863279421729456597655847484197549086072988901191634450924","price":"0.83","size":"1470.51","side":"BUY","hash":"09283c696bc1304985fac22d13f1dc9caa174520","best_bid":"0.94","best_ask":"0.95"},{"asset_id":"54232589582260339592359130012520874109228367674780084862642636038394766871668","price":"0.17","size":"1470.51","side":"SELL","hash":"8c954d728aa0b22c4a6057a785dac5013170f4fb","best_bid":"0.05","best_ask":"0.06"}],"timestamp":"1768250243647","event_type":"price_change"}}
{"schema_version":1,"source":"clob_ws_market","recv_ts_ns":1768250243871560854,"event_type":"price_change","market":"0xe51aa24ab1bbfefce466d642ad98587d13123e4ef95ec9aa73b712e775d4cbba","server_ts_ms":1768250243749,"raw":{"market":"0xe51aa24ab1bbfefce466d642ad98587d13123e4ef95ec9aa73b712e775d4cbba","price_changes":[{"asset_id":"96886111393998001968863279421729456597655847484197549086072988901191634450924","price":"0.96","size":"502.4","side":"SELL","hash":"f74e4cb822bed52dbeb2f5bd14ad9c3abf3e4721","best_bid":"0.94","best_ask":"0.95"},{"asset_id":"54232589582260339592359130012520874109228367674780084862642636038394766871668","price":"0.04","size":"502.4","side":"BUY","hash":"766a7e3739ee98728bc393c2d2caf0c41eca51f6","best_bid":"0.05","best_ask":"0.06"}],"timestamp":"1768250243749","event_type":"price_change"}}
{"schema_version":1,"source":"clob_ws_market","recv_ts_ns":1768250243874289392,"event_type":"price_change","market":"0xe51aa24ab1bbfefce466d642ad98587d13123e4ef95ec9aa73b712e775d4cbba","server_ts_ms":1768250243750,"raw":{"market":"0xe51aa24ab1bbfefce466d642ad98587d13123e4ef95ec9aa73b712e775d4cbba","price_changes":[{"asset_id":"54232589582260339592359130012520874109228367674780084862642636038394766871668","price":"0.04","size":"514.4","side":"BUY","hash":"613651b812ae33319ff5689873f8b628adb650bf","best_bid":"0.05","best_ask":"0.06"},{"asset_id":"96886111393998001968863279421729456597655847484197549086072988901191634450924","price":"0.96","size":"514.4","side":"SELL","hash":"24712bf9d305005e6d284313d00e0dceb8f4c74f","best_bid":"0.94","best_ask":"0.95"}],"timestamp":"1768250243750","event_type":"price_change"}}
{"schema_version":1,"source":"clob_ws_market","recv_ts_ns":1768250243882127143,"event_type":"price_change","market":"0xe51aa24ab1bbfefce466d642ad98587d13123e4ef95ec9aa73b712e775d4cbba","server_ts_ms":1768250243755,"raw":{"market":"0xe51aa24ab1bbfefce466d642ad98587d13123e4ef95ec9aa73b712e775d4cbba","price_changes":[{"asset_id":"54232589582260339592359130012520874109228367674780084862642636038394766871668","price":"0.04","size":"522.4","side":"BUY","hash":"ab4011a5cd6397c3cf3d5ba528eeb1469a6917e3","best_bid":"0.05","best_ask":"0.06"},{"asset_id":"96886111393998001968863279421729456597655847484197549086072988901191634450924","price":"0.96","size":"522.4","side":"SELL","hash":"7b8808c9224cd14e3989354f2a2d40418c6c1a68","best_bid":"0.94","best_ask":"0.95"}],"timestamp":"1768250243755","event_type":"price_change"}}
{"schema_version":1,"source":"clob_ws_market","recv_ts_ns":1768250243955718263,"event_type":"price_change","market":"0xe51aa24ab1bbfefce466d642ad98587d13123e4ef95ec9aa73b712e775d4cbba","server_ts_ms":1768250243773,"raw":{"market":"0xe51aa24ab1bbfefce466d642ad98587d13123e4ef95ec9aa73b712e775d4cbba","price_changes":[{"asset_id":"54232589582260339592359130012520874109228367674780084862642636038394766871668","price":"0.02","size":"6835.25","side":"BUY","hash":"47b583b82a7f9824fa5af243e8b4b3c5c8d3828b","best_bid":"0.05","best_ask":"0.06"},{"asset_id":"96886111393998001968863279421729456597655847484197549086072988901191634450924","price":"0.98","size":"6835.25","side":"SELL","hash":"7cafe84dddf27b83325154af78c9cbce0e468707","best_bid":"0.94","best_ask":"0.95"}],"timestamp":"1768250243773","event_type":"price_change"}}
{"schema_version":1,"source":"clob_ws_market","recv_ts_ns":1768250244014483219,"event_type":"best_bid_ask","market":"0xe51aa24ab1bbfefce466d642ad98587d13123e4ef95ec9aa73b712e775d4cbba","server_ts_ms":1768250243786,"raw":{"market":"0xe51aa24ab1bbfefce466d642ad98587d13123e4ef95ec9aa73b712e775d4cbba","asset_id":"54232589582260339592359130012520874109228367674780084862642636038394766871668","best_bid":"0.05","best_ask":"0.06","spread":"0.01","timestamp":"1768250243786","event_type":"best_bid_ask"}}
{"schema_version":1,"source":"clob_ws_market","recv_ts_ns":1768250244019164548,"event_type":"price_change","market":"0xe51aa24ab1bbfefce466d642ad98587d13123e4ef95ec9aa73b712e775d4cbba","server_ts_ms":1768250243783,"raw":{"market":"0xe51aa24ab1bbfefce466d642ad98587d13123e4ef95ec9aa73b712e775d4cbba","price_changes":[{"asset_id":"54232589582260339592359130012520874109228367674780084862642636038394766871668","price":"0.05","size":"973.02","side":"BUY","hash":"ccf64c2727e6374fa887fdccc93680dbcd9de5ad","best_bid":"0.05","best_ask":"0.06"},{"asset_id":"96886111393998001968863279421729456597655847484197549086072988901191634450924","price":"0.95","size":"973.02","side":"SELL","hash":"b716dab724b681ef3611b96f384dc26b95f3d9fc","best_bid":"0.94","best_ask":"0.95"}],"timestamp":"1768250243783","event_type":"price_change"}}
{"schema_version":1,"source":"clob_ws_market","recv_ts_ns":1768250244024184125,"event_type":"book","market":"0xe51aa24ab1bbfefce466d642ad98587d13123e4ef95ec9aa73b712e775d4cbba","server_ts_ms":1768250243783,"raw":{"market":"0xe51aa24ab1bbfefce466d642ad98587d13123e4ef95ec9aa73b712e775d4cbba","asset_id":"54232589582260339592359130012520874109228367674780084862642636038394766871668","bids":[{"price":"0.01","size":"20993.9"},{"price":"0.02","size":"6835.25"},{"price":"0.03","size":"2680.33"},{"price":"0.04","size":"522.4"},{"price":"0.05","size":"973.02"}],"asks":[{"price":"0.99","size":"24290.24"},{"price":"0.98","size":"7594.51"},{"price":"0.97","size":"5964.69"},{"price":"0.96","size":"5411.4"},{"price":"0.95","size":"5356.39"},{"price":"0.94","size":"5328"},{"price":"0.93","size":"5039.28"},{"price":"0.92","size":"5022.7"},{"price":"0.91","size":"5320.9"},{"price":"0.9","size":"5158.44"},{"price":"0.89","size":"18.3"},{"price":"0.88","size":"30.3"},{"price":"0.87","size":"16.5"},{"price":"0.86","size":"15.8"},{"price":"0.85","size":"104.19"},{"price":"0.84","size":"24.69"},{"price":"0.83","size":"14.19"},{"price":"0.82","size":"13.8"},{"price":"0.81","size":"13.4"},{"price":"0.8","size":"38.1"},{"price":"0.79","size":"12.8"},{"price":"0.78","size":"12.6"},{"price":"0.77","size":"12.3"},{"price":"0.76","size":"22.1"},{"price":"0.75","size":"16.9"},{"price":"0.74","size":"21.8"},{"price":"0.73","size":"11.6"},{"price":"0.72","size":"11.4"},{"price":"0.71","size":"61.3"},{"price":"0.7","size":"26.2"},{"price":"0.69","size":"11.1"},{"price":"0.68","size":"11"},{"price":"0.67","size":"110.9"},{"price":"0.66","size":"10.8"},{"price":"0.65","size":"15.7"},{"price":"0.64","size":"10.6"},{"price":"0.63","size":"10.6"},{"price":"0.62","size":"22.5"},{"price":"0.61","size":"10.5"},{"price":"0.6","size":"45.4"},{"price":"0.59","size":"311.4"},{"price":"0.58","size":"820.82"},{"price":"0.57","size":"826.3"},{"price":"0.56","size":"1062.3"},{"price":"0.55","size":"582.3"},{"price":"0.54","size":"626.2"},{"price":"0.53","size":"562.2"},{"price":"0.52","size":"567.2"},{"price":"0.51","size":"573.2"},{"price":"0.5","size":"917.2"},{"price":"0.49","size":"591.2"},{"price":"0.48","size":"590.2"},{"price":"0.47","size":"573.2"},{"price":"0.46","size":"636.61"},{"price":"0.45","size":"362.97"},{"price":"0.44","size":"341.3"},{"price":"0.43","size":"320.62"},{"price":"0.42","size":"567.3"},{"price":"0.41","size":"562.4"},{"price":"0.4","size":"693.02"},{"price":"0.39","size":"625.5"},{"price":"0.38","size":"668.5"},{"price":"0.37","size":"672.32"},{"price":"0.36","size":"680.6"},{"price":"0.35","size":"536.14"},{"price":"0.34","size":"602.8"},{"price":"0.33","size":"572.9"},{"price":"0.32","size":"573"},{"price":"0.31","size":"595.1"},{"price":"0.3","size":"603.2"},{"price":"0.29","size":"1318.72"},{"price":"0.28","size":"1048.04"},{"price":"0.27","size":"663.6"},{"price":"0.26","size":"911.17"},{"price":"0.25","size":"694.3"},{"price":"0.24","size":"717.6"},{"price":"0.23","size":"1183.3"},{"price":"0.22","size":"1526.53"},{"price":"0.21","size":"1178.8"},{"price":"0.2","size":"1445.08"},{"price":"0.19","size":"1229.8"},{"price":"0.18","size":"1467.57"},{"price":"0.17","size":"1470.51"},{"price":"0.16","size":"1718.59"},{"price":"0.15","size":"1762.5"},{"price":"0.14","size":"1755.6"},{"price":"0.13","size":"1588.93"},{"price":"0.12","size":"2555.4"},{"price":"0.11","size":"1898.8"},{"price":"0.1","size":"3426.54"},{"price":"0.09","size":"2701.44"},{"price":"0.08","size":"2367.36"},{"price":"0.07","size":"1564.82"},{"price":"0.06","size":"1522.22"}],"hash":"ccf64c2727e6374fa887fdccc93680dbcd9de5ad","timestamp":"1768250243783","event_type":"book"}}
{"schema_version":1,"source":"clob_ws_market","recv_ts_ns":1768250244031935357,"event_type":"price_change","market":"0xe51aa24ab1bbfefce466d642ad98587d13123e4ef95ec9aa73b712e775d4cbba","server_ts_ms":1768250243786,"raw":{"market":"0xe51aa24ab1bbfefce466d642ad98587d13123e4ef95ec9aa73b712e775d4cbba","price_changes":[{"asset_id":"96886111393998001968863279421729456597655847484197549086072988901191634450924","price":"0.94","size":"1512.22","side":"BUY","hash":"ffc858008e28f73fa632be5934a483ca6fa56043","best_bid":"0.94","best_ask":"0.95"},{"asset_id":"54232589582260339592359130012520874109228367674780084862642636038394766871668","price":"0.06","size":"1512.22","side":"SELL","hash":"7beb542675d11b2f7f25e222332c28149ddbd2c3","best_bid":"0.05","best_ask":"0.06"}],"timestamp":"1768250243786","event_type":"price_change"}}
{"schema_version":1,"source":"clob_ws_market","recv_ts_ns":1768250244076140059,"event_type":"price_change","market":"0xe51aa24ab1bbfefce466d642ad98587d13123e4ef95ec9aa73b712e775d4cbba","server_ts_ms":1768250243796,"raw":{"market":"0xe51aa24ab1bbfefce466d642ad98587d13123e4ef95ec9aa73b712e775d4cbba","price_changes":[{"asset_id":"54232589582260339592359130012520874109228367674780084862642636038394766871668","price":"0.04","size":"514.4","side":"BUY","hash":"3ce5b84e974f0a1da83245b3f5a09264f40a70ca","best_bid":"0.05","best_ask":"0.06"},{"asset_id":"96886111393998001968863279421729456597655847484197549086072988901191634450924","price":"0.96","size":"514.4","side":"SELL","hash":"1557bb3836701fb18224d3009086616e6958a322","best_bid":"0.94","best_ask":"0.95"}],"timestamp":"1768250243796","event_type":"price_change"}}
{"schema_version":1,"source":"clob_ws_market","recv_ts_ns":1768250244162479925,"event_type":"price_change","market":"0xe51aa24ab1bbfefce466d642ad98587d13123e4ef95ec9aa73b712e775d4cbba","server_ts_ms":1768250243821,"raw":{"market":"0xe51aa24ab1bbfefce466d642ad98587d13123e4ef95ec9aa73b712e775d4cbba","price_changes":[{"asset_id":"54232589582260339592359130012520874109228367674780084862642636038394766871668","price":"0.04","size":"414.4","side":"BUY","hash":"d7d3cd5cac365f063ff5d319550efbecb4f785a4","best_bid":"0.05","best_ask":"0.06"},{"asset_id":"96886111393998001968863279421729456597655847484197549086072988901191634450924","price":"0.96","size":"414.4","side":"SELL","hash":"69cbf8229a9383bc0625ba1cc5eea24d6906f07b","best_bid":"0.94","best_ask":"0.95"}],"timestamp":"1768250243821","event_type":"price_change"}}
{"schema_version":1,"source":"clob_ws_market","recv_ts_ns":1768250244177221321,"event_type":"price_change","market":"0xe51aa24ab1bbfefce466d642ad98587d13123e4ef95ec9aa73b712e775d4cbba","server_ts_ms":1768250243828,"raw":{"market":"0xe51aa24ab1bbfefce466d642ad98587d13123e4ef95ec9aa73b712e775d4cbba","price_changes":[{"asset_id":"54232589582260339592359130012520874109228367674780084862642636038394766871668","price":"0.02","size":"6863.25","side":"BUY","hash":"a4a9f7d3848100438fcaa6b4850f416d97904101","best_bid":"0.05","best_ask":"0.06"},{"asset_id":"96886111393998001968863279421729456597655847484197549086072988901191634450924","price":"0.98","size":"6863.25","side":"SELL","hash":"85aa9c4918dc3d711fa589efdec0be89c92edee4","best_bid":"0.94","best_ask":"0.95"}],"timestamp":"1768250243828","event_type":"price_change"}}
{"schema_version":1,"source":"clob_ws_market","recv_ts_ns":1768250244269337356,"event_type":"price_change","market":"0xe51aa24ab1bbfefce466d642ad98587d13123e4ef95ec9aa73b712e775d4cbba","server_ts_ms":1768250243867,"raw":{"market":"0xe51aa24ab1bbfefce466d642ad98587d13123e4ef95ec9aa73b712e775d4cbba","price_changes":[{"asset_id":"54232589582260339592359130012520874109228367674780084862642636038394766871668","price":"0.03","size":"2780.33","side":"BUY","hash":"92eba7a85428c3606c3b7acdb4ad059a2b7f64ba","best_bid":"0.05","best_ask":"0.06"},{"asset_id":"96886111393998001968863279421729456597655847484197549086072988901191634450924","price":"0.97","size":"2780.33","side":"SELL","hash":"ccd871d6769c39343b486733cfe2af83c6fc43fe","best_bid":"0.94","best_ask":"0.95"}],"timestamp":"1768250243867","event_type":"price_change"}}
{"schema_version":1,"source":"clob_ws_market","recv_ts_ns":1768250244341832600,"event_type":"price_change","market":"0xe51aa24ab1bbfefce466d642ad98587d13123e4ef95ec9aa73b712e775d4cbba","server_ts_ms":1768250243964,"raw":{"market":"0xe51aa24ab1bbfefce466d642ad98587d13123e4ef95ec9aa73b712e775d4cbba","price_changes":[{"asset_id":"54232589582260339592359130012520874109228367674780084862642636038394766871668","price":"0.04","size":"402.4","side":"BUY","hash":"933fafdc26da27215c2171d1ce6ad1ecd36a0374","best_bid":"0.05","best_ask":"0.06"},{"asset_id":"96886111393998001968863279421729456597655847484197549086072988901191634450924","price":"0.96","size":"402.4","side":"SELL","hash":"57310d314679cd70c151e3936fd4c1686c0b042b","best_bid":"0.94","best_ask":"0.95"}],"timestamp":"1768250243964","event_type":"price_change"}}
{"schema_version":1,"source":"clob_ws_market","recv_ts_ns":1768250244345249289,"event_type":"price_change","market":"0xe51aa24ab1bbfefce466d642ad98587d13123e4ef95ec9aa73b712e775d4cbba","server_ts_ms":1768250243966,"raw":{"market":"0xe51aa24ab1bbfefce466d642ad98587d13123e4ef95ec9aa73b712e775d4cbba","price_changes":[{"asset_id":"96886111393998001968863279421729456597655847484197549086072988901191634450924","price":"0.96","size":"390.4","side":"SELL","hash":"fc675b9d6ad4422395bb66cf609cb47411ffffe3","best_bid":"0.94","best_ask":"0.95"},{"asset_id":"54232589582260339592359130012520874109228367674780084862642636038394766871668","price":"0.04","size":"390.4","side":"BUY","hash":"865dd7984a2434ede07b3dded6f93c5a94e5d88c","best_bid":"0.05","best_ask":"0.06"}],"timestamp":"1768250243966","event_type":"price_change"}}
{"schema_version":1,"source":"clob_ws_market","recv_ts_ns":1768250244348798881,"event_type":"price_change","market":"0xe51aa24ab1bbfefce466d642ad98587d13123e4ef95ec9aa73b712e775d4cbba","server_ts_ms":1768250243977,"raw":{"market":"0xe51aa24ab1bbfefce466d642ad98587d13123e4ef95ec9aa73b712e775d4cbba","price_changes":[{"asset_id":"96886111393998001968863279421729456597655847484197549086072988901191634450924","price":"0.72","size":"1043.04","side":"BUY","hash":"a4e3128000b3544eb153cb10f2505905ee6a6924","best_bid":"0.94","best_ask":"0.95"},{"asset_id":"54232589582260339592359130012520874109228367674780084862642636038394766871668","price":"0.28","size":"1043.04","side":"SELL","hash":"6385125b07d1abe1846cd9b8d4dceedc70e1aae6","best_bid":"0.05","best_ask":"0.06"}],"timestamp":"1768250243977","event_type":"price_change"}}
{"schema_version":1,"source":"clob_ws_market","recv_ts_ns":1768250244352893485,"event_type":"price_change","market":"0xe51aa24ab1bbfefce466d642ad98587d13123e4ef95ec9aa73b712e775d4cbba","server_ts_ms":1768250243983,"raw":{"market":"0xe51aa24ab1bbfefce466d642ad98587d13123e4ef95ec9aa73b712e775d4cbba","price_changes":[{"asset_id":"54232589582260339592359130012520874109228367674780084862642636038394766871668","price":"0.02","size":"6835.25","side":"BUY","hash":"f6cbda267808582188ba4b5b22917b1d76a221ba","best_bid":"0.05","best_ask":"0.06"},{"asset_id":"96886111393998001968863279421729456597655847484197549086072988901191634450924","price":"0.98","size":"6835.25","side":"SELL","hash":"62e32b4344fd00f58e3dcce91f285d1f5892df66","best_bid":"0.94","best_ask":"0.95"}],"timestamp":"1768250243983","event_type":"price_change"}}
{"schema_version":1,"source":"clob_ws_market","recv_ts_ns":1768250244357260625,"event_type":"price_change","market":"0xe51aa24ab1bbfefce466d642ad98587d13123e4ef95ec9aa73b712e775d4cbba","server_ts_ms":1768250244000,"raw":{"market":"0xe51aa24ab1bbfefce466d642ad98587d13123e4ef95ec9aa73b712e775d4cbba","price_changes":[{"asset_id":"54232589582260339592359130012520874109228367674780084862642636038394766871668","price":"0.02","size":"6735.25","side":"BUY","hash":"fbef00c6c1eada79cddfbfe7bc4ef915fc226398","best_bid":"0.05","best_ask":"0.06"},{"asset_id":"96886111393998001968863279421729456597655847484197549086072988901191634450924","price":"0.98","size":"6735.25","side":"SELL","hash":"7a8bb6e02fd6d4b1223ba3a029a5db77809b99a2","best_bid":"0.94","best_ask":"0.95"}],"timestamp":"1768250244000","event_type":"price_change"}}
{"schema_version":1,"source":"clob_ws_market","recv_ts_ns":1768250244360540499,"event_type":"price_change","market":"0xe51aa24ab1bbfefce466d642ad98587d13123e4ef95ec9aa73b712e775d4cbba","server_ts_ms":1768250244011,"raw":{"market":"0xe51aa24ab1bbfefce466d642ad98587d13123e4ef95ec9aa73b712e775d4cbba","price_changes":[{"asset_id":"96886111393998001968863279421729456597655847484197549086072988901191634450924","price":"0.94","size":"1522.22","side":"BUY","hash":"7be799ff84ab567e4523e4f251a91e69b428d279","best_bid":"0.94","best_ask":"0.95"},{"asset_id":"54232589582260339592359130012520874109228367674780084862642636038394766871668","price":"0.06","size":"1522.22","side":"SELL","hash":"6880a83eddcfbe0f2d66438d6ec504e06c84fefe","best_bid":"0.05","best_ask":"0.06"}],"timestamp":"1768250244011","event_type":"price_change"}}
{"schema_version":1,"source":"clob_ws_market","recv_ts_ns":1768250244363694496,"event_type":"price_change","market":"0xe51aa24ab1bbfefce466d642ad98587d13123e4ef95ec9aa73b712e775d4cbba","server_ts_ms":1768250244028,"raw":{"market":"0xe51aa24ab1bbfefce466d642ad98587d13123e4ef95ec9aa73b712e775d4cbba","price_changes":[{"asset_id":"54232589582260339592359130012520874109228367674780084862642636038394766871668","price":"0.02","size":"6763.25","side":"BUY","hash":"5b048f78b11bbeb6e22fcec3b9a3b4292beb3e5e","best_bid":"0.05","best_ask":"0.06"},{"asset_id":"96886111393998001968863279421729456597655847484197549086072988901191634450924","price":"0.98","size":"6763.25","side":"SELL","hash":"42cc52df697114ebfab9ceca9988871a1a4a7492","best_bid":"0.94","best_ask":"0.95"}],"timestamp":"1768250244028","event_type":"price_change"}}
{"schema_version":1,"source":"clob_ws_market","recv_ts_ns":1768250244369823772,"event_type":"price_change","market":"0xe51aa24ab1bbfefce466d642ad98587d13123e4ef95ec9aa73b712e775d4cbba","server_ts_ms":1768250244059,"raw":{"market":"0xe51aa24ab1bbfefce466d642ad98587d13123e4ef95ec9aa73b712e775d4cbba","price_changes":[{"asset_id":"54232589582260339592359130012520874109228367674780084862642636038394766871668","price":"0.02","size":"6863.25","side":"BUY","hash":"0b0b995fe8110d431365be11b1ef0e2a68a5cf35","best_bid":"0.05","best_ask":"0.06"},{"asset_id":"96886111393998001968863279421729456597655847484197549086072988901191634450924","price":"0.98","size":"6863.25","side":"SELL","hash":"a73628da12a45749061a195fd9c9590a5f86d2e1","best_bid":"0.94","best_ask":"0.95"}],"timestamp":"1768250244059","event_type":"price_change"}}
{"schema_version":1,"source":"clob_ws_market","recv_ts_ns":1768250244376351011,"event_type":"price_change","market":"0xe51aa24ab1bbfefce466d642ad98587d13123e4ef95ec9aa73b712e775d4cbba","server_ts_ms":1768250244068,"raw":{"market":"0xe51aa24ab1bbfefce466d642ad98587d13123e4ef95ec9aa73b712e775d4cbba","price_changes":[{"asset_id":"96886111393998001968863279421729456597655847484197549086072988901191634450924","price":"0.93","size":"1574.82","side":"BUY","hash":"2589604b92807149bf106eb3339cd8c11d8fb342","best_bid":"0.94","best_ask":"0.95"},{"asset_id":"54232589582260339592359130012520874109228367674780084862642636038394766871668","price":"0.07","size":"1574.82","side":"SELL","hash":"5056bc759c990ce8663eed1c00a3f0355a4619fb","best_bid":"0.05","best_ask":"0.06"}],"timestamp":"1768250244068","event_type":"price_change"}}
{"schema_version":1,"source":"clob_ws_market","recv_ts_ns":1768250244379130395,"event_type":"best_bid_ask","market":"0xe51aa24ab1bbfefce466d642ad98587d13123e4ef95ec9aa73b712e775d4cbba","server_ts_ms":1768250244183,"raw":{"market":"0xe51aa24ab1bbfefce466d642ad98587d13123e4ef95ec9aa73b712e775d4cbba","asset_id":"54232589582260339592359130012520874109228367674780084862642636038394766871668","best_bid":"0.05","best_ask":"0.06","spread":"0.01","timestamp":"1768250244183","event_type":"best_bid_ask"}}
{"schema_version":1,"source":"clob_ws_market","recv_ts_ns":1768250244382532318,"event_type":"price_change","market":"0xe51aa24ab1bbfefce466d642ad98587d13123e4ef95ec9aa73b712e775d4cbba","server_ts_ms":1768250244181,"raw":{"market":"0xe51aa24ab1bbfefce466d642ad98587d13123e4ef95ec9aa73b712e775d4cbba","price_changes":[{"asset_id":"96886111393998001968863279421729456597655847484197549086072988901191634450924","price":"0.94","size":"1517.22","side":"BUY","hash":"2b697a9ebaf4bfa845f619f346c442fd70679b39","best_bid":"0.94","best_ask":"0.95"},{"asset_id":"54232589582260339592359130012520874109228367674780084862642636038394766871668","price":"0.06","size":"1517.22","side":"SELL","hash":"9ba8961cd035081db4ce59a927828b8b5b33a100","best_bid":"0.05","best_ask":"0.06"}],"timestamp":"1768250244181","event_type":"price_change"}}
{"schema_version":1,"source":"clob_ws_market","recv_ts_ns":1768250244386271198,"event_type":"book","market":"0xe51aa24ab1bbfefce466d642ad98587d13123e4ef95ec9aa73b712e775d4cbba","server_ts_ms":1768250244181,"raw":{"market":"0xe51aa24ab1bbfefce466d642ad98587d13123e4ef95ec9aa73b712e775d4cbba","asset_id":"54232589582260339592359130012520874109228367674780084862642636038394766871668","bids":[{"price":"0.01","size":"20993.9"},{"price":"0.02","size":"6863.25"},{"price":"0.03","size":"2780.33"},{"price":"0.04","size":"390.4"},{"price":"0.05","size":"973.02"}],"asks":[{"price":"0.99","size":"24290.24"},{"price":"0.98","size":"7594.51"},{"price":"0.97","size":"5964.69"},{"price":"0.96","size":"5411.4"},{"price":"0.95","size":"5356.39"},{"price":"0.94","size":"5328"},{"price":"0.93","size":"5039.28"},{"price":"0.92","size":"5022.7"},{"price":"0.91","size":"5320.9"},{"price":"0.9","size":"5158.44"},{"price":"0.89","size":"18.3"},{"price":"0.88","size":"30.3"},{"price":"0.87","size":"16.5"},{"price":"0.86","size":"15.8"},{"price":"0.85","size":"104.19"},{"price":"0.84","size":"24.69"},{"price":"0.83","size":"14.19"},{"price":"0.82","size":"13.8"},{"price":"0.81","size":"13.4"},{"price":"0.8","size":"38.1"},{"price":"0.79","size":"12.8"},{"price":"0.78","size":"12.6"},{"price":"0.77","size":"12.3"},{"price":"0.76","size":"22.1"},{"price":"0.75","size":"16.9"},{"price":"0.74","size":"21.8"},{"price":"0.73","size":"11.6"},{"price":"0.72","size":"11.4"},{"price":"0.71","size":"61.3"},{"price":"0.7","size":"26.2"},{"price":"0.69","size":"11.1"},{"price":"0.68","size":"11"},{"price":"0.67","size":"110.9"},{"price":"0.66","size":"10.8"},{"price":"0.65","size":"15.7"},{"price":"0.64","size":"10.6"},{"price":"0.63","size":"10.6"},{"price":"0.62","size":"22.5"},{"price":"0.61","size":"10.5"},{"price":"0.6","size":"45.4"},{"price":"0.59","size":"311.4"},{"price":"0.58","size":"820.82"},{"price":"0.57","size":"826.3"},{"price":"0.56","size":"1062.3"},{"price":"0.55","size":"582.3"},{"price":"0.54","size":"626.2"},{"price":"0.53","size":"562.2"},{"price":"0.52","size":"567.2"},{"price":"0.51","size":"573.2"},{"price":"0.5","size":"917.2"},{"price":"0.49","size":"591.2"},{"price":"0.48","size":"590.2"},{"price":"0.47","size":"573.2"},{"price":"0.46","size":"636.61"},{"price":"0.45","size":"362.97"},{"price":"0.44","size":"341.3"},{"price":"0.43","size":"320.62"},{"price":"0.42","size":"567.3"},{"price":"0.41","size":"562.4"},{"price":"0.4","size":"693.02"},{"price":"0.39","size":"625.5"},{"price":"0.38","size":"668.5"},{"price":"0.37","size":"672.32"},{"price":"0.36","size":"680.6"},{"price":"0.35","size":"536.14"},{"price":"0.34","size":"602.8"},{"price":"0.33","size":"572.9"},{"price":"0.32","size":"573"},{"price":"0.31","size":"595.1"},{"price":"0.3","size":"603.2"},{"price":"0.29","size":"1318.72"},{"price":"0.28","size":"1043.04"},{"price":"0.27","size":"663.6"},{"price":"0.26","size":"911.17"},{"price":"0.25","size":"694.3"},{"price":"0.24","size":"717.6"},{"price":"0.23","size":"1183.3"},{"price":"0.22","size":"1526.53"},{"price":"0.21","size":"1178.8"},{"price":"0.2","size":"1445.08"},{"price":"0.19","size":"1229.8"},{"price":"0.18","size":"1467.57"},{"price":"0.17","size":"1470.51"},{"price":"0.16","size":"1718.59"},{"price":"0.15","size":"1762.5"},{"price":"0.14","size":"1755.6"},{"price":"0.13","size":"1588.93"},{"price":"0.12","size":"2555.4"},{"price":"0.11","size":"1898.8"},{"price":"0.1","size":"3426.54"},{"price":"0.09","size":"2701.44"},{"price":"0.08","size":"2367.36"},{"price":"0.07","size":"1574.82"},{"price":"0.06","size":"1517.22"}],"hash":"9ba8961cd035081db4ce59a927828b8b5b33a100","timestamp":"1768250244181","event_type":"book"}}
{"schema_version":1,"source":"clob_ws_market","recv_ts_ns":1768250244391892198,"event_type":"price_change","market":"0xe51aa24ab1bbfefce466d642ad98587d13123e4ef95ec9aa73b712e775d4cbba","server_ts_ms":1768250244193,"raw":{"market":"0xe51aa24ab1bbfefce466d642ad98587d13123e4ef95ec9aa73b712e775d4cbba","price_changes":[{"asset_id":"54232589582260339592359130012520874109228367674780084862642636038394766871668","price":"0.02","size":"6835.25","side":"BUY","hash":"a674477d9afeeb1741f948fcb916de8b275b99ca","best_bid":"0.05","best_ask":"0.06"},{"asset_id":"96886111393998001968863279421729456597655847484197549086072988901191634450924","price":"0.98","size":"6835.25","side":"SELL","hash":"0a8c52378c9939c37d878abcefc559de80ba9673","best_bid":"0.94","best_ask":"0.95"}],"timestamp":"1768250244193","event_type":"price_change"}}
{"schema_version":1,"source":"clob_ws_market","recv_ts_ns":1768250244394540189,"event_type":"price_change","market":"0xe51aa24ab1bbfefce466d642ad98587d13123e4ef95ec9aa73b712e775d4cbba","server_ts_ms":1768250244207,"raw":{"market":"0xe51aa24ab1bbfefce466d642ad98587d13123e4ef95ec9aa73b712e775d4cbba","price_changes":[{"asset_id":"96886111393998001968863279421729456597655847484197549086072988901191634450924","price":"0.94","size":"1507.22","side":"BUY","hash":"735f3a301127f4163c107cea683c7ea03201e1a7","best_bid":"0.94","best_ask":"0.95"},{"asset_id":"54232589582260339592359130012520874109228367674780084862642636038394766871668","price":"0.06","size":"1507.22","side":"SELL","hash":"462df72b889a9c56902a9a49c354ed281b3d5e2e","best_bid":"0.05","best_ask":"0.06"}],"timestamp":"1768250244207","event_type":"price_change"}}
{"schema_version":1,"source":"clob_ws_market","recv_ts_ns":1768250244397091652,"event_type":"last_trade_price","market":"0xe51aa24ab1bbfefce466d642ad98587d13123e4ef95ec9aa73b712e775d4cbba","server_ts_ms":1768250244210,"raw":{"market":"0xe51aa24ab1bbfefce466d642ad98587d13123e4ef95ec9aa73b712e775d4cbba","asset_id":"54232589582260339592359130012520874109228367674780084862642636038394766871668","price":"0.06","size":"5","fee_rate_bps":"1000","side":"BUY","timestamp":"1768250244210","event_type":"last_trade_price","transaction_hash":"0x713a4d09580578a2a730f4d13f10f38659daebdee606313c24c2fcf58fa25e5a"}}
{"schema_version":1,"source":"clob_ws_market","recv_ts_ns":1768250244398527843,"event_type":"price_change","market":"0xe51aa24ab1bbfefce466d642ad98587d13123e4ef95ec9aa73b712e775d4cbba","server_ts_ms":1768250244232,"raw":{"market":"0xe51aa24ab1bbfefce466d642ad98587d13123e4ef95ec9aa73b712e775d4cbba","price_changes":[{"asset_id":"54232589582260339592359130012520874109228367674780084862642636038394766871668","price":"0.02","size":"6863.25","side":"BUY","hash":"723ae0cfaef672de70027fa9026b9290adda5b86","best_bid":"0.05","best_ask":"0.06"},{"asset_id":"96886111393998001968863279421729456597655847484197549086072988901191634450924","price":"0.98","size":"6863.25","side":"SELL","hash":"df8063dcd09f654913a74cad97d5fab4f1ab525c","best_bid":"0.94","best_ask":"0.95"}],"timestamp":"1768250244232","event_type":"price_change"}}
{"schema_version":1,"source":"clob_ws_market","recv_ts_ns":1768250244457440905,"event_type":"price_change","market":"0xe51aa24ab1bbfefce466d642ad98587d13123e4ef95ec9aa73b712e775d4cbba","server_ts_ms":1768250244296,"raw":{"market":"0xe51aa24ab1bbfefce466d642ad98587d13123e4ef95ec9aa73b712e775d4cbba","price_changes":[{"asset_id":"54232589582260339592359130012520874109228367674780084862642636038394766871668","price":"0.05","size":"988.02","side":"BUY","hash":"1b76a1722269008eb1e6119b9165ba46fe23a86e","best_bid":"0.05","best_ask":"0.06"},{"asset_id":"96886111393998001968863279421729456597655847484197549086072988901191634450924","price":"0.95","size":"988.02","side":"SELL","hash":"01c3867b318d1f96fc230821feb0ded79c19d2d3","best_bid":"0.94","best_ask":"0.95"}],"timestamp":"1768250244296","event_type":"price_change"}}
{"schema_version":1,"source":"clob_ws_market","recv_ts_ns":1768250244482725268,"event_type":"price_change","market":"0xe51aa24ab1bbfefce466d642ad98587d13123e4ef95ec9aa73b712e775d4cbba","server_ts_ms":1768250244302,"raw":{"market":"0xe51aa24ab1bbfefce466d642ad98587d13123e4ef95ec9aa73b712e775d4cbba","price_changes":[{"asset_id":"96886111393998001968863279421729456597655847484197549086072988901191634450924","price":"0.95","size":"1003.02","side":"SELL","hash":"4f3a55040c106cf5b778a08572666ba058522ef4","best_bid":"0.94","best_ask":"0.95"},{"asset_id":"54232589582260339592359130012520874109228367674780084862642636038394766871668","price":"0.05","size":"1003.02","side":"BUY","hash":"a0c34acd2b0453ca586671aa993234ed9f5364b1","best_bid":"0.05","best_ask":"0.06"}],"timestamp":"1768250244302","event_type":"price_change"}}
{"schema_version":1,"source":"clob_ws_market","recv_ts_ns":1768250244486831677,"event_type":"price_change","market":"0xe51aa24ab1bbfefce466d642ad98587d13123e4ef95ec9aa73b712e775d4cbba","server_ts_ms":1768250244302,"raw":{"market":"0xe51aa24ab1bbfefce466d642ad98587d13123e4ef95ec9aa73b712e775d4cbba","price_changes":[{"asset_id":"54232589582260339592359130012520874109228367674780084862642636038394766871668","price":"0.04","size":"426.4","side":"BUY","hash":"7a7e89862c36ce61f7738c2be766b42ea8313e4a","best_bid":"0.05","best_ask":"0.06"},{"asset_id":"96886111393998001968863279421729456597655847484197549086072988901191634450924","price":"0.96","size":"426.4","side":"SELL","hash":"13f8f02f93053fdc70fa095140b1c787b3681550","best_bid":"0.94","best_ask":"0.95"}],"timestamp":"1768250244302","event_type":"price_change"}}
{"schema_version":1,"source":"clob_ws_market","recv_ts_ns":1768250244491254624,"event_type":"price_change","market":"0xe51aa24ab1bbfefce466d642ad98587d13123e4ef95ec9aa73b712e775d4cbba","server_ts_ms":1768250244303,"raw":{"market":"0xe51aa24ab1bbfefce466d642ad98587d13123e4ef95ec9aa73b712e775d4cbba","price_changes":[{"asset_id":"96886111393998001968863279421729456597655847484197549086072988901191634450924","price":"0.96","size":"445.4","side":"SELL","hash":"8704d38cb94ced4cc8d88290952736021b3309f5","best_bid":"0.94","best_ask":"0.95"},{"asset_id":"54232589582260339592359130012520874109228367674780084862642636038394766871668","price":"0.04","size":"445.4","side":"BUY","hash":"62cce32117df4de4ceeb74422f561d311b9da617","best_bid":"0.05","best_ask":"0.06"}],"timestamp":"1768250244303","event_type":"price_change"}}
{"schema_version":1,"source":"clob_ws_market","recv_ts_ns":1768250244541355125,"event_type":"price_change","market":"0xe51aa24ab1bbfefce466d642ad98587d13123e4ef95ec9aa73b712e775d4cbba","server_ts_ms":1768250244308,"raw":{"market":"0xe51aa24ab1bbfefce466d642ad98587d13123e4ef95ec9aa73b712e775d4cbba","price_changes":[{"asset_id":"54232589582260339592359130012520874109228367674780084862642636038394766871668","price":"0.05","size":"963.6","side":"BUY","hash":"6c1845619b9987fe88578f7615e9e0b552c2e65a","best_bid":"0.05","best_ask":"0.06"},{"asset_id":"96886111393998001968863279421729456597655847484197549086072988901191634450924","price":"0.95","size":"963.6","side":"SELL","hash":"6b1f44a5b416b7352aff2bac7a276b09556eff5e","best_bid":"0.94","best_ask":"0.95"}],"timestamp":"1768250244308","event_type":"price_change"}}
{"schema_version":1,"source":"clob_ws_market","recv_ts_ns":1768250244545263917,"event_type":"best_bid_ask","market":"0xe51aa24ab1bbfefce466d642ad98587d13123e4ef95ec9aa73b712e775d4cbba","server_ts_ms":1768250244310,"raw":{"market":"0xe51aa24ab1bbfefce466d642ad98587d13123e4ef95ec9aa73b712e775d4cbba","asset_id":"54232589582260339592359130012520874109228367674780084862642636038394766871668","best_bid":"0.05","best_ask":"0.06","spread":"0.01","timestamp":"1768250244310","event_type":"best_bid_ask"}}
{"schema_version":1,"source":"clob_ws_market","recv_ts_ns":1768250244551016152,"event_type":"book","market":"0xe51aa24ab1bbfefce466d642ad98587d13123e4ef95ec9aa73b712e775d4cbba","server_ts_ms":1768250244308,"raw":{"market":"0xe51aa24ab1bbfefce466d642ad98587d13123e4ef95ec9aa73b712e775d4cbba","asset_id":"54232589582260339592359130012520874109228367674780084862642636038394766871668","bids":[{"price":"0.01","size":"20993.9"},{"price":"0.02","size":"6863.25"},{"price":"0.03","size":"2780.33"},{"price":"0.04","size":"445.4"},{"price":"0.05","size":"963.6"}],"asks":[{"price":"0.99","size":"24290.24"},{"price":"0.98","size":"7594.51"},{"price":"0.97","size":"5964.69"},{"price":"0.96","size":"5411.4"},{"price":"0.95","size":"5356.39"},{"price":"0.94","size":"5328"},{"price":"0.93","size":"5039.28"},{"price":"0.92","size":"5022.7"},{"price":"0.91","size":"5320.9"},{"price":"0.9","size":"5158.44"},{"price":"0.89","size":"18.3"},{"price":"0.88","size":"30.3"},{"price":"0.87","size":"16.5"},{"price":"0.86","size":"15.8"},{"price":"0.85","size":"104.19"},{"price":"0.84","size":"24.69"},{"price":"0.83","size":"14.19"},{"price":"0.82","size":"13.8"},{"price":"0.81","size":"13.4"},{"price":"0.8","size":"38.1"},{"price":"0.79","size":"12.8"},{"price":"0.78","size":"12.6"},{"price":"0.77","size":"12.3"},{"price":"0.76","size":"22.1"},{"price":"0.75","size":"16.9"},{"price":"0.74","size":"21.8"},{"price":"0.73","size":"11.6"},{"price":"0.72","size":"11.4"},{"price":"0.71","size":"61.3"},{"price":"0.7","size":"26.2"},{"price":"0.69","size":"11.1"},{"price":"0.68","size":"11"},{"price":"0.67","size":"110.9"},{"price":"0.66","size":"10.8"},{"price":"0.65","size":"15.7"},{"price":"0.64","size":"10.6"},{"price":"0.63","size":"10.6"},{"price":"0.62","size":"22.5"},{"price":"0.61","size":"10.5"},{"price":"0.6","size":"45.4"},{"price":"0.59","size":"311.4"},{"price":"0.58","size":"820.82"},{"price":"0.57","size":"826.3"},{"price":"0.56","size":"1062.3"},{"price":"0.55","size":"582.3"},{"price":"0.54","size":"626.2"},{"price":"0.53","size":"562.2"},{"price":"0.52","size":"567.2"},{"price":"0.51","size":"573.2"},{"price":"0.5","size":"917.2"},{"price":"0.49","size":"591.2"},{"price":"0.48","size":"590.2"},{"price":"0.47","size":"573.2"},{"price":"0.46","size":"636.61"},{"price":"0.45","size":"362.97"},{"price":"0.44","size":"341.3"},{"price":"0.43","size":"320.62"},{"price":"0.42","size":"567.3"},{"price":"0.41","size":"562.4"},{"price":"0.4","size":"693.02"},{"price":"0.39","size":"625.5"},{"price":"0.38","size":"668.5"},{"price":"0.37","size":"672.32"},{"price":"0.36","size":"680.6"},{"price":"0.35","size":"536.14"},{"price":"0.34","size":"602.8"},{"price":"0.33","size":"572.9"},{"price":"0.32","size":"573"},{"price":"0.31","size":"595.1"},{"price":"0.3","size":"603.2"},{"price":"0.29","size":"1318.72"},{"price":"0.28","size":"1043.04"},{"price":"0.27","size":"663.6"},{"price":"0.26","size":"911.17"},{"price":"0.25","size":"694.3"},{"price":"0.24","size":"717.6"},{"price":"0.23","size":"1183.3"},{"price":"0.22","size":"1526.53"},{"price":"0.21","size":"1178.8"},{"price":"0.2","size":"1445.08"},{"price":"0.19","size":"1229.8"},{"price":"0.18","size":"1467.57"},{"price":"0.17","size":"1470.51"},{"price":"0.16","size":"1718.59"},{"price":"0.15","size":"1762.5"},{"price":"0.14","size":"1755.6"},{"price":"0.13","size":"1588.93"},{"price":"0.12","size":"2555.4"},{"price":"0.11","size":"1898.8"},{"price":"0.1","size":"3426.54"},{"price":"0.09","size":"2701.44"},{"price":"0.08","size":"2367.36"},{"price":"0.07","size":"1574.82"},{"price":"0.06","size":"1507.22"}],"hash":"6c1845619b9987fe88578f7615e9e0b552c2e65a","timestamp":"1768250244308","event_type":"book"}}
{"schema_version":1,"source":"clob_ws_market","recv_ts_ns":1768250244559092313,"event_type":"price_change","market":"0xe51aa24ab1bbfefce466d642ad98587d13123e4ef95ec9aa73b712e775d4cbba","server_ts_ms":1768250244311,"raw":{"market":"0xe51aa24ab1bbfefce466d642ad98587d13123e4ef95ec9aa73b712e775d4cbba","price_changes":[{"asset_id":"54232589582260339592359130012520874109228367674780084862642636038394766871668","price":"0.05","size":"993.6","side":"BUY","hash":"032f472ab20693abac96bf7ab6a1cfe48897a9b3","best_bid":"0.05","best_ask":"0.06"},{"asset_id":"96886111393998001968863279421729456597655847484197549086072988901191634450924","price":"0.95","size":"993.6","side":"SELL","hash":"9ae043240a1bbd4fc6a1488df2810071621d6077","best_bid":"0.94","best_ask":"0.95"}],"timestamp":"1768250244311","event_type":"price_change"}}
{"schema_version":1,"source":"clob_ws_market","recv_ts_ns":1768250244571800898,"event_type":"price_change","market":"0xe51aa24ab1bbfefce466d642ad98587d13123e4ef95ec9aa73b712e775d4cbba","server_ts_ms":1768250244311,"raw":{"market":"0xe51aa24ab1bbfefce466d642ad98587d13123e4ef95ec9aa73b712e775d4cbba","price_changes":[{"asset_id":"54232589582260339592359130012520874109228367674780084862642636038394766871668","price":"0.04","size":"457.4","side":"BUY","hash":"0522d38ddfd8ccb37e76bd2e509d39b55fa733cf","best_bid":"0.05","best_ask":"0.06"},{"asset_id":"96886111393998001968863279421729456597655847484197549086072988901191634450924","price":"0.96","size":"457.4","side":"SELL","hash":"338fb9aca4acc28d3b6c57408ff13520fa9f1326","best_bid":"0.94","best_ask":"0.95"}],"timestamp":"1768250244311","event_type":"price_change"}}
{"schema_version":1,"source":"clob_ws_market","recv_ts_ns":1768250244582450204,"event_type":"price_change","market":"0xe51aa24ab1bbfefce466d642ad98587d13123e4ef95ec9aa73b712e775d4cbba","server_ts_ms":1768250244318,"raw":{"market":"0xe51aa24ab1bbfefce466d642ad98587d13123e4ef95ec9aa73b712e775d4cbba","price_changes":[{"asset_id":"96886111393998001968863279421729456597655847484197549086072988901191634450924","price":"0.94","size":"757.22","side":"BUY","hash":"1e8591f4d621caf9169c8e5ca833ad5ec0f6fd1c","best_bid":"0.94","best_ask":"0.95"},{"asset_id":"54232589582260339592359130012520874109228367674780084862642636038394766871668","price":"0.06","size":"757.22","side":"SELL","hash":"bdaee9c8a55ff7523b85f6d73e575cc656f94981","best_bid":"0.05","best_ask":"0.06"}],"timestamp":"1768250244318","event_type":"price_change"}}
{"schema_version":1,"source":"clob_ws_market","recv_ts_ns":1768250244603765983,"event_type":"best_bid_ask","market":"0xe51aa24ab1bbfefce466d642ad98587d13123e4ef95ec9aa73b712e775d4cbba","server_ts_ms":1768250244340,"raw":{"market":"0xe51aa24ab1bbfefce466d642ad98587d13123e4ef95ec9aa73b712e775d4cbba","asset_id":"54232589582260339592359130012520874109228367674780084862642636038394766871668","best_bid":"0.05","best_ask":"0.06","spread":"0.01","timestamp":"1768250244340","event_type":"best_bid_ask"}}
{"schema_version":1,"source":"clob_ws_market","recv_ts_ns":1768250244610916852,"event_type":"price_change","market":"0xe51aa24ab1bbfefce466d642ad98587d13123e4ef95ec9aa73b712e775d4cbba","server_ts_ms":1768250244339,"raw":{"market":"0xe51aa24ab1bbfefce466d642ad98587d13123e4ef95ec9aa73b712e775d4cbba","price_changes":[{"asset_id":"54232589582260339592359130012520874109228367674780084862642636038394766871668","price":"0.05","size":"988.6","side":"BUY","hash":"a56fd81caee07f5546f0daea7da5b69b9d1726c2","best_bid":"0.05","best_ask":"0.06"},{"asset_id":"96886111393998001968863279421729456597655847484197549086072988901191634450924","price":"0.95","size":"988.6","side":"SELL","hash":"d518f3bfe7392012f022342b5f59d87334c7b3b2","best_bid":"0.94","best_ask":"0.95"}],"timestamp":"1768250244339","event_type":"price_change"}}
{"schema_version":1,"source":"clob_ws_market","recv_ts_ns":1768250244617646099,"event_type":"book","market":"0xe51aa24ab1bbfefce466d642ad98587d13123e4ef95ec9aa73b712e775d4cbba","server_ts_ms":1768250244339,"raw":{"market":"0xe51aa24ab1bbfefce466d642ad98587d13123e4ef95ec9aa73b712e775d4cbba","asset_id":"54232589582260339592359130012520874109228367674780084862642636038394766871668","bids":[{"price":"0.01","size":"20993.9"},{"price":"0.02","size":"6863.25"},{"price":"0.03","size":"2780.33"},{"price":"0.04","size":"457.4"},{"price":"0.05","size":"988.6"}],"asks":[{"price":"0.99","size":"24290.24"},{"price":"0.98","size":"7594.51"},{"price":"0.97","size":"5964.69"},{"price":"0.96","size":"5411.4"},{"price":"0.95","size":"5356.39"},{"price":"0.94","size":"5328"},{"price":"0.93","size":"5039.28"},{"price":"0.92","size":"5022.7"},{"price":"0.91","size":"5320.9"},{"price":"0.9","size":"5158.44"},{"price":"0.89","size":"18.3"},{"price":"0.88","size":"30.3"},{"price":"0.87","size":"16.5"},{"price":"0.86","size":"15.8"},{"price":"0.85","size":"104.19"},{"price":"0.84","size":"24.69"},{"price":"0.83","size":"14.19"},{"price":"0.82","size":"13.8"},{"price":"0.81","size":"13.4"},{"price":"0.8","size":"38.1"},{"price":"0.79","size":"12.8"},{"price":"0.78","size":"12.6"},{"price":"0.77","size":"12.3"},{"price":"0.76","size":"22.1"},{"price":"0.75","size":"16.9"},{"price":"0.74","size":"21.8"},{"price":"0.73","size":"11.6"},{"price":"0.72","size":"11.4"},{"price":"0.71","size":"61.3"},{"price":"0.7","size":"26.2"},{"price":"0.69","size":"11.1"},{"price":"0.68","size":"11"},{"price":"0.67","size":"110.9"},{"price":"0.66","size":"10.8"},{"price":"0.65","size":"15.7"},{"price":"0.64","size":"10.6"},{"price":"0.63","size":"10.6"},{"price":"0.62","size":"22.5"},{"price":"0.61","size":"10.5"},{"price":"0.6","size":"45.4"},{"price":"0.59","size":"311.4"},{"price":"0.58","size":"820.82"},{"price":"0.57","size":"826.3"},{"price":"0.56","size":"1062.3"},{"price":"0.55","size":"582.3"},{"price":"0.54","size":"626.2"},{"price":"0.53","size":"562.2"},{"price":"0.52","size":"567.2"},{"price":"0.51","size":"573.2"},{"price":"0.5","size":"917.2"},{"price":"0.49","size":"591.2"},{"price":"0.48","size":"590.2"},{"price":"0.47","size":"573.2"},{"price":"0.46","size":"636.61"},{"price":"0.45","size":"362.97"},{"price":"0.44","size":"341.3"},{"price":"0.43","size":"320.62"},{"price":"0.42","size":"567.3"},{"price":"0.41","size":"562.4"},{"price":"0.4","size":"693.02"},{"price":"0.39","size":"625.5"},{"price":"0.38","size":"668.5"},{"price":"0.37","size":"672.32"},{"price":"0.36","size":"680.6"},{"price":"0.35","size":"536.14"},{"price":"0.34","size":"602.8"},{"price":"0.33","size":"572.9"},{"price":"0.32","size":"573"},{"price":"0.31","size":"595.1"},{"price":"0.3","size":"603.2"},{"price":"0.29","size":"1318.72"},{"price":"0.28","size":"1043.04"},{"price":"0.27","size":"663.6"},{"price":"0.26","size":"911.17"},{"price":"0.25","size":"694.3"},{"price":"0.24","size":"717.6"},{"price":"0.23","size":"1183.3"},{"price":"0.22","size":"1526.53"},{"price":"0.21","size":"1178.8"},{"price":"0.2","size":"1445.08"},{"price":"0.19","size":"1229.8"},{"price":"0.18","size":"1467.57"},{"price":"0.17","size":"1470.51"},{"price":"0.16","size":"1718.59"},{"price":"0.15","size":"1762.5"},{"price":"0.14","size":"1755.6"},{"price":"0.13","size":"1588.93"},{"price":"0.12","size":"2555.4"},{"price":"0.11","size":"1898.8"},{"price":"0.1","size":"3426.54"},{"price":"0.09","size":"2701.44"},{"price":"0.08","size":"2367.36"},{"price":"0.07","size":"1574.82"},{"price":"0.06","size":"757.22"}],"hash":"a56fd81caee07f5546f0daea7da5b69b9d1726c2","timestamp":"1768250244339","event_type":"book"}}
{"schema_version":1,"source":"clob_ws_market","recv_ts_ns":1768250244723327012,"event_type":"price_change","market":"0xe51aa24ab1bbfefce466d642ad98587d13123e4ef95ec9aa73b712e775d4cbba","server_ts_ms":1768250244426,"raw":{"market":"0xe51aa24ab1bbfefce466d642ad98587d13123e4ef95ec9aa73b712e775d4cbba","price_changes":[{"asset_id":"54232589582260339592359130012520874109228367674780084862642636038394766871668","price":"0.04","size":"445.4","side":"BUY","hash":"4c56e9ff4a6732367064f28112b87ae382055f91","best_bid":"0.05","best_ask":"0.06"},{"asset_id":"96886111393998001968863279421729456597655847484197549086072988901191634450924","price":"0.96","size":"445.4","side":"SELL","hash":"d04899b6c52fa4625f0f9f18ddcad02e978b2874","best_bid":"0.94","best_ask":"0.95"}],"timestamp":"1768250244426","event_type":"price_change"}}
{"schema_version":1,"source":"clob_ws_market","recv_ts_ns":1768250244811707714,"event_type":"price_change","market":"0xe51aa24ab1bbfefce466d642ad98587d13123e4ef95ec9aa73b712e775d4cbba","server_ts_ms":1768250244448,"raw":{"market":"0xe51aa24ab1bbfefce466d642ad98587d13123e4ef95ec9aa73b712e775d4cbba","price_changes":[{"asset_id":"96886111393998001968863279421729456597655847484197549086072988901191634450924","price":"0.9","size":"3455.34","side":"BUY","hash":"615d8b4da029277aba56578bebad8a7b2194fdac","best_bid":"0.94","best_ask":"0.95"},{"asset_id":"54232589582260339592359130012520874109228367674780084862642636038394766871668","price":"0.1","size":"3455.34","side":"SELL","hash":"66d7fcf98c000c95fbb095da931b02102ef0606a","best_bid":"0.05","best_ask":"0.06"}],"timestamp":"1768250244448","event_type":"price_change"}}
{"schema_version":1,"source":"clob_ws_market","recv_ts_ns":1768250244880108868,"event_type":"price_change","market":"0xe51aa24ab1bbfefce466d642ad98587d13123e4ef95ec9aa73b712e775d4cbba","server_ts_ms":1768250244476,"raw":{"market":"0xe51aa24ab1bbfefce466d642ad98587d13123e4ef95ec9aa73b712e775d4cbba","price_changes":[{"asset_id":"96886111393998001968863279421729456597655847484197549086072988901191634450924","price":"0.94","size":"1507.22","side":"BUY","hash":"7794ce727c8a079e8030fa4a65fac07a221a3da6","best_bid":"0.94","best_ask":"0.95"},{"asset_id":"54232589582260339592359130012520874109228367674780084862642636038394766871668","price":"0.06","size":"1507.22","side":"SELL","hash":"d254a4c472edeaf6bf4ae815f1ae332eea88380d","best_bid":"0.05","best_ask":"0.06"}],"timestamp":"1768250244476","event_type":"price_change"}}
{"schema_version":1,"source":"clob_ws_market","recv_ts_ns":1768250244900982825,"event_type":"price_change","market":"0xe51aa24ab1bbfefce466d642ad98587d13123e4ef95ec9aa73b712e775d4cbba","server_ts_ms":1768250244479,"raw":{"market":"0xe51aa24ab1bbfefce466d642ad98587d13123e4ef95ec9aa73b712e775d4cbba","price_changes":[{"asset_id":"96886111393998001968863279421729456597655847484197549086072988901191634450924","price":"0.95","size":"973.6","side":"SELL","hash":"550d2cba565e58b89e3fc849c4735bc6f14a331e","best_bid":"0.94","best_ask":"0.95"},{"asset_id":"54232589582260339592359130012520874109228367674780084862642636038394766871668","price":"0.05","size":"973.6","side":"BUY","hash":"453f7d04ba53ad7503b50a06b17971e741cd0c89","best_bid":"0.05","best_ask":"0.06"}],"timestamp":"1768250244479","event_type":"price_change"}}
{"schema_version":1,"source":"clob_ws_market","recv_ts_ns":1768250244906190978,"event_type":"price_change","market":"0xe51aa24ab1bbfefce466d642ad98587d13123e4ef95ec9aa73b712e775d4cbba","server_ts_ms":1768250244483,"raw":{"market":"0xe51aa24ab1bbfefce466d642ad98587d13123e4ef95ec9aa73b712e775d4cbba","price_changes":[{"asset_id":"54232589582260339592359130012520874109228367674780084862642636038394766871668","price":"0.05","size":"958.6","side":"BUY","hash":"180a094fd91cfd6d4a8145cd513b63ae167ed33f","best_bid":"0.05","best_ask":"0.06"},{"asset_id":"96886111393998001968863279421729456597655847484197549086072988901191634450924","price":"0.95","size":"958.6","side":"SELL","hash":"6fa03dbd6401cac96fc9ca3ba8587de594b795cd","best_bid":"0.94","best_ask":"0.95"}],"timestamp":"1768250244483","event_type":"price_change"}}
{"schema_version":1,"source":"clob_ws_market","recv_ts_ns":1768250244911960819,"event_type":"price_change","market":"0xe51aa24ab1bbfefce466d642ad98587d13123e4ef95ec9aa73b712e775d4cbba","server_ts_ms":1768250244484,"raw":{"market":"0xe51aa24ab1bbfefce466d642ad98587d13123e4ef95ec9aa73b712e775d4cbba","price_changes":[{"asset_id":"54232589582260339592359130012520874109228367674780084862642636038394766871668","price":"0.05","size":"928.6","side":"BUY","hash":"846e586bef994e2520c58145ccea13b5d09f532b","best_bid":"0.05","best_ask":"0.06"},{"asset_id":"96886111393998001968863279421729456597655847484197549086072988901191634450924","price":"0.95","size":"928.6","side":"SELL","hash":"ddaff2a29429a9788031c041e13a926e8899c82b","best_bid":"0.94","best_ask":"0.95"}],"timestamp":"1768250244484","event_type":"price_change"}}
{"schema_version":1,"source":"clob_ws_market","recv_ts_ns":1768250244929198066,"event_type":"price_change","market":"0xe51aa24ab1bbfefce466d642ad98587d13123e4ef95ec9aa73b712e775d4cbba","server_ts_ms":1768250244536,"raw":{"market":"0xe51aa24ab1bbfefce466d642ad98587d13123e4ef95ec9aa73b712e775d4cbba","price_changes":[{"asset_id":"96886111393998001968863279421729456597655847484197549086072988901191634450924","price":"0.96","size":"426.4","side":"SELL","hash":"fd8235e2ace95a4276cf0748d75c441658aa0ada","best_bid":"0.94","best_ask":"0.95"},{"asset_id":"54232589582260339592359130012520874109228367674780084862642636038394766871668","price":"0.04","size":"426.4","side":"BUY","hash":"d2b84afde8a3b4d3768b585b70b1e7e0ec60cedb","best_bid":"0.05","best_ask":"0.06"}],"timestamp":"1768250244536","event_type":"price_change"}}
{"schema_version":1,"source":"clob_ws_market","recv_ts_ns":1768250244932413855,"event_type":"price_change","market":"0xe51aa24ab1bbfefce466d642ad98587d13123e4ef95ec9aa73b712e775d4cbba","server_ts_ms":1768250244542,"raw":{"market":"0xe51aa24ab1bbfefce466d642ad98587d13123e4ef95ec9aa73b712e775d4cbba","price_changes":[{"asset_id":"54232589582260339592359130012520874109228367674780084862642636038394766871668","price":"0.04","size":"390.4","side":"BUY","hash":"1353bbb3c68e84655e51944344f183193fb51520","best_bid":"0.05","best_ask":"0.06"},{"asset_id":"96886111393998001968863279421729456597655847484197549086072988901191634450924","price":"0.96","size":"390.4","side":"SELL","hash":"ebf809ecd88055b4a8e0432411887194a20c3689","best_bid":"0.94","best_ask":"0.95"}],"timestamp":"1768250244542","event_type":"price_change"}}
{"schema_version":1,"source":"clob_ws_market","recv_ts_ns":1768250244935502550,"event_type":"last_trade_price","market":"0xe51aa24ab1bbfefce466d642ad98587d13123e4ef95ec9aa73b712e775d4cbba","server_ts_ms":1768250244638,"raw":{"market":"0xe51aa24ab1bbfefce466d642ad98587d13123e4ef95ec9aa73b712e775d4cbba","asset_id":"54232589582260339592359130012520874109228367674780084862642636038394766871668","price":"0.06","size":"58","fee_rate_bps":"1000","side":"BUY","timestamp":"1768250244638","event_type":"last_trade_price","transaction_hash":"0xe900fc85d98b13024b3fd45b1de1dd436f9420bd92ecfd9fdcf0c2c7ff057299"}}
{"schema_version":1,"source":"clob_ws_market","recv_ts_ns":1768250244938931261,"event_type":"best_bid_ask","market":"0xe51aa24ab1bbfefce466d642ad98587d13123e4ef95ec9aa73b712e775d4cbba","server_ts_ms":1768250244612,"raw":{"market":"0xe51aa24ab1bbfefce466d642ad98587d13123e4ef95ec9aa73b712e775d4cbba","asset_id":"54232589582260339592359130012520874109228367674780084862642636038394766871668","best_bid":"0.05","best_ask":"0.06","spread":"0.01","timestamp":"1768250244612","event_type":"best_bid_ask"}}
{"schema_version":1,"source":"clob_ws_market","recv_ts_ns":1768250244942591300,"event_type":"price_change","market":"0xe51aa24ab1bbfefce466d642ad98587d13123e4ef95ec9aa73b712e775d4cbba","server_ts_ms":1768250244609,"raw":{"market":"0xe51aa24ab1bbfefce466d642ad98587d13123e4ef95ec9aa73b712e775d4cbba","price_changes":[{"asset_id":"96886111393998001968863279421729456597655847484197549086072988901191634450924","price":"0.94","size":"1449.22","side":"BUY","hash":"747f143f5aea790c721f791aa38fc707fa4eed47","best_bid":"0.94","best_ask":"0.95"},{"asset_id":"54232589582260339592359130012520874109228367674780084862642636038394766871668","price":"0.06","size":"1449.22","side":"SELL","hash":"93fa3d4b509ee5658270a7622dc85d7be78d69ff","best_bid":"0.05","best_ask":"0.06"}],"timestamp":"1768250244609","event_type":"price_change"}}
{"schema_version":1,"source":"clob_ws_market","recv_ts_ns":1768250244948547102,"event_type":"book","market":"0xe51aa24ab1bbfefce466d642ad98587d13123e4ef95ec9aa73b712e775d4cbba","server_ts_ms":1768250244609,"raw":{"market":"0xe51aa24ab1bbfefce466d642ad98587d13123e4ef95ec9aa73b712e775d4cbba","asset_id":"54232589582260339592359130012520874109228367674780084862642636038394766871668","bids":[{"price":"0.01","size":"20993.9"},{"price":"0.02","size":"6863.25"},{"price":"0.03","size":"2780.33"},{"price":"0.04","size":"390.4"},{"price":"0.05","size":"928.6"}],"asks":[{"price":"0.99","size":"24290.24"},{"price":"0.98","size":"7594.51"},{"price":"0.97","size":"5964.69"},{"price":"0.96","size":"5411.4"},{"price":"0.95","size":"5356.39"},{"price":"0.94","size":"5328"},{"price":"0.93","size":"5039.28"},{"price":"0.92","size":"5022.7"},{"price":"0.91","size":"5320.9"},{"price":"0.9","size":"5158.44"},{"price":"0.89","size":"18.3"},{"price":"0.88","size":"30.3"},{"price":"0.87","size":"16.5"},{"price":"0.86","size":"15.8"},{"price":"0.85","size":"104.19"},{"price":"0.84","size":"24.69"},{"price":"0.83","size":"14.19"},{"price":"0.82","size":"13.8"},{"price":"0.81","size":"13.4"},{"price":"0.8","size":"38.1"},{"price":"0.79","size":"12.8"},{"price":"0.78","size":"12.6"},{"price":"0.77","size":"12.3"},{"price":"0.76","size":"22.1"},{"price":"0.75","size":"16.9"},{"price":"0.74","size":"21.8"},{"price":"0.73","size":"11.6"},{"price":"0.72","size":"11.4"},{"price":"0.71","size":"61.3"},{"price":"0.7","size":"26.2"},{"price":"0.69","size":"11.1"},{"price":"0.68","size":"11"},{"price":"0.67","size":"110.9"},{"price":"0.66","size":"10.8"},{"price":"0.65","size":"15.7"},{"price":"0.64","size":"10.6"},{"price":"0.63","size":"10.6"},{"price":"0.62","size":"22.5"},{"price":"0.61","size":"10.5"},{"price":"0.6","size":"45.4"},{"price":"0.59","size":"311.4"},{"price":"0.58","size":"820.82"},{"price":"0.57","size":"826.3"},{"price":"0.56","size":"1062.3"},{"price":"0.55","size":"582.3"},{"price":"0.54","size":"626.2"},{"price":"0.53","size":"562.2"},{"price":"0.52","size":"567.2"},{"price":"0.51","size":"573.2"},{"price":"0.5","size":"917.2"},{"price":"0.49","size":"591.2"},{"price":"0.48","size":"590.2"},{"price":"0.47","size":"573.2"},{"price":"0.46","size":"636.61"},{"price":"0.45","size":"362.97"},{"price":"0.44","size":"341.3"},{"price":"0.43","size":"320.62"},{"price":"0.42","size":"567.3"},{"price":"0.41","size":"562.4"},{"price":"0.4","size":"693.02"},{"price":"0.39","size":"625.5"},{"price":"0.38","size":"668.5"},{"price":"0.37","size":"672.32"},{"price":"0.36","size":"680.6"},{"price":"0.35","size":"536.14"},{"price":"0.34","size":"602.8"},{"price":"0.33","size":"572.9"},{"price":"0.32","size":"573"},{"price":"0.31","size":"595.1"},{"price":"0.3","size":"603.2"},{"price":"0.29","size":"1318.72"},{"price":"0.28","size":"1043.04"},{"price":"0.27","size":"663.6"},{"price":"0.26","size":"911.17"},{"price":"0.25","size":"694.3"},{"price":"0.24","size":"717.6"},{"price":"0.23","size":"1183.3"},{"price":"0.22","size":"1526.53"},{"price":"0.21","size":"1178.8"},{"price":"0.2","size":"1445.08"},{"price":"0.19","size":"1229.8"},{"price":"0.18","size":"1467.57"},{"price":"0.17","size":"1470.51"},{"price":"0.16","size":"1718.59"},{"price":"0.15","size":"1762.5"},{"price":"0.14","size":"1755.6"},{"price":"0.13","size":"1588.93"},{"price":"0.12","size":"2555.4"},{"price":"0.11","size":"1898.8"},{"price":"0.1","size":"3455.34"},{"price":"0.09","size":"2701.44"},{"price":"0.08","size":"2367.36"},{"price":"0.07","size":"1574.82"},{"price":"0.06","size":"1449.22"}],"hash":"93fa3d4b509ee5658270a7622dc85d7be78d69ff","timestamp":"1768250244609","event_type":"book"}}
{"schema_version":1,"source":"clob_ws_market","recv_ts_ns":1768250244957826768,"event_type":"best_bid_ask","market":"0xe51aa24ab1bbfefce466d642ad98587d13123e4ef95ec9aa73b712e775d4cbba","server_ts_ms":1768250244617,"raw":{"market":"0xe51aa24ab1bbfefce466d642ad98587d13123e4ef95ec9aa73b712e775d4cbba","asset_id":"54232589582260339592359130012520874109228367674780084862642636038394766871668","best_bid":"0.05","best_ask":"0.06","spread":"0.01","timestamp":"1768250244617","event_type":"best_bid_ask"}}
{"schema_version":1,"source":"clob_ws_market","recv_ts_ns":1768250244963670484,"event_type":"price_change","market":"0xe51aa24ab1bbfefce466d642ad98587d13123e4ef95ec9aa73b712e775d4cbba","server_ts_ms":1768250244615,"raw":{"market":"0xe51aa24ab1bbfefce466d642ad98587d13123e4ef95ec9aa73b712e775d4cbba","price_changes":[{"asset_id":"54232589582260339592359130012520874109228367674780084862642636038394766871668","price":"0.05","size":"886.6","side":"BUY","hash":"16d67d8b50fdc2ade9e6bfb11ab0fbd3ee68fa82","best_bid":"0.05","best_ask":"0.06"},{"asset_id":"96886111393998001968863279421729456597655847484197549086072988901191634450924","price":"0.95","size":"886.6","side":"SELL","hash":"1146bd70ab3ee6f54206407b721db6d7343585b8","best_bid":"0.94","best_ask":"0.95"}],"timestamp":"1768250244615","event_type":"price_change"}}
{"schema_version":1,"source":"clob_ws_market","recv_ts_ns":1768250244970690743,"event_type":"book","market":"0xe51aa24ab1bbfefce466d642ad98587d13123e4ef95ec9aa73b712e775d4cbba","server_ts_ms":1768250244615,"raw":{"market":"0xe51aa24ab1bbfefce466d642ad98587d13123e4ef95ec9aa73b712e775d4cbba","asset_id":"54232589582260339592359130012520874109228367674780084862642636038394766871668","bids":[{"price":"0.01","size":"20993.9"},{"price":"0.02","size":"6863.25"},{"price":"0.03","size":"2780.33"},{"price":"0.04","size":"390.4"},{"price":"0.05","size":"886.6"}],"asks":[{"price":"0.99","size":"24290.24"},{"price":"0.98","size":"7594.51"},{"price":"0.97","size":"5964.69"},{"price":"0.96","size":"5411.4"},{"price":"0.95","size":"5356.39"},{"price":"0.94","size":"5328"},{"price":"0.93","size":"5039.28"},{"price":"0.92","size":"5022.7"},{"price":"0.91","size":"5320.9"},{"price":"0.9","size":"5158.44"},{"price":"0.89","size":"18.3"},{"price":"0.88","size":"30.3"},{"price":"0.87","size":"16.5"},{"price":"0.86","size":"15.8"},{"price":"0.85","size":"104.19"},{"price":"0.84","size":"24.69"},{"price":"0.83","size":"14.19"},{"price":"0.82","size":"13.8"},{"price":"0.81","size":"13.4"},{"price":"0.8","size":"38.1"},{"price":"0.79","size":"12.8"},{"price":"0.78","size":"12.6"},{"price":"0.77","size":"12.3"},{"price":"0.76","size":"22.1"},{"price":"0.75","size":"16.9"},{"price":"0.74","size":"21.8"},{"price":"0.73","size":"11.6"},{"price":"0.72","size":"11.4"},{"price":"0.71","size":"61.3"},{"price":"0.7","size":"26.2"},{"price":"0.69","size":"11.1"},{"price":"0.68","size":"11"},{"price":"0.67","size":"110.9"},{"price":"0.66","size":"10.8"},{"price":"0.65","size":"15.7"},{"price":"0.64","size":"10.6"},{"price":"0.63","size":"10.6"},{"price":"0.62","size":"22.5"},{"price":"0.61","size":"10.5"},{"price":"0.6","size":"45.4"},{"price":"0.59","size":"311.4"},{"price":"0.58","size":"820.82"},{"price":"0.57","size":"826.3"},{"price":"0.56","size":"1062.3"},{"price":"0.55","size":"582.3"},{"price":"0.54","size":"626.2"},{"price":"0.53","size":"562.2"},{"price":"0.52","size":"567.2"},{"price":"0.51","size":"573.2"},{"price":"0.5","size":"917.2"},{"price":"0.49","size":"591.2"},{"price":"0.48","size":"590.2"},{"price":"0.47","size":"573.2"},{"price":"0.46","size":"636.61"},{"price":"0.45","size":"362.97"},{"price":"0.44","size":"341.3"},{"price":"0.43","size":"320.62"},{"price":"0.42","size":"567.3"},{"price":"0.41","size":"562.4"},{"price":"0.4","size":"693.02"},{"price":"0.39","size":"625.5"},{"price":"0.38","size":"668.5"},{"price":"0.37","size":"672.32"},{"price":"0.36","size":"680.6"},{"price":"0.35","size":"536.14"},{"price":"0.34","size":"602.8"},{"price":"0.33","size":"572.9"},{"price":"0.32","size":"573"},{"price":"0.31","size":"595.1"},{"price":"0.3","size":"603.2"},{"price":"0.29","size":"1318.72"},{"price":"0.28","size":"1043.04"},{"price":"0.27","size":"663.6"},{"price":"0.26","size":"911.17"},{"price":"0.25","size":"694.3"},{"price":"0.24","size":"717.6"},{"price":"0.23","size":"1183.3"},{"price":"0.22","size":"1526.53"},{"price":"0.21","size":"1178.8"},{"price":"0.2","size":"1445.08"},{"price":"0.19","size":"1229.8"},{"price":"0.18","size":"1467.57"},{"price":"0.17","size":"1470.51"},{"price":"0.16","size":"1718.59"},{"price":"0.15","size":"1762.5"},{"price":"0.14","size":"1755.6"},{"price":"0.13","size":"1588.93"},{"price":"0.12","size":"2555.4"},{"price":"0.11","size":"1898.8"},{"price":"0.1","size":"3455.34"},{"price":"0.09","size":"2701.44"},{"price":"0.08","size":"2367.36"},{"price":"0.07","size":"1574.82"},{"price":"0.06","size":"1449.22"}],"hash":"16d67d8b50fdc2ade9e6bfb11ab0fbd3ee68fa82","timestamp":"1768250244615","event_type":"book"}}
{"schema_version":1,"source":"clob_ws_market","recv_ts_ns":1768250244978758048,"event_type":"price_change","market":"0xe51aa24ab1bbfefce466d642ad98587d13123e4ef95ec9aa73b712e775d4cbba","server_ts_ms":1768250244626,"raw":{"market":"0xe51aa24ab1bbfefce466d642ad98587d13123e4ef95ec9aa73b712e775d4cbba","price_changes":[{"asset_id":"96886111393998001968863279421729456597655847484197549086072988901191634450924","price":"0.95","size":"811.34","side":"SELL","hash":"778f00998b048fbabe7e32963d67fbc7344f23cd","best_bid":"0.94","best_ask":"0.95"},{"asset_id":"54232589582260339592359130012520874109228367674780084862642636038394766871668","price":"0.05","size":"811.34","side":"BUY","hash":"6224bba78a96a56610fd9b654a2f88203ce8a85d","best_bid":"0.05","best_ask":"0.06"}],"timestamp":"1768250244626","event_type":"price_change"}}
{"schema_version":1,"source":"clob_ws_market","recv_ts_ns":1768250245003739122,"event_type":"price_change","market":"0xe51aa24ab1bbfefce466d642ad98587d13123e4ef95ec9aa73b712e775d4cbba","server_ts_ms":1768250244663,"raw":{"market":"0xe51aa24ab1bbfefce466d642ad98587d13123e4ef95ec9aa73b712e775d4cbba","price_changes":[{"asset_id":"96886111393998001968863279421729456597655847484197549086072988901191634450924","price":"0.92","size":"2342.36","side":"BUY","hash":"43a880725a7363d20ed6b8d436a094693602f59c","best_bid":"0.94","best_ask":"0.95"},{"asset_id":"54232589582260339592359130012520874109228367674780084862642636038394766871668","price":"0.08","size":"2342.36","side":"SELL","hash":"4352e401ef611e6627c75b97b09bf5d1c2a2be31","best_bid":"0.05","best_ask":"0.06"}],"timestamp":"1768250244663","event_type":"price_change"}}
{"schema_version":1,"source":"clob_ws_market","recv_ts_ns":1768250245009020200,"event_type":"price_change","market":"0xe51aa24ab1bbfefce466d642ad98587d13123e4ef95ec9aa73b712e775d4cbba","server_ts_ms":1768250244665,"raw":{"market":"0xe51aa24ab1bbfefce466d642ad98587d13123e4ef95ec9aa73b712e775d4cbba","price_changes":[{"asset_id":"54232589582260339592359130012520874109228367674780084862642636038394766871668","price":"0.06","size":"1474.22","side":"SELL","hash":"2934d29e53af8f2e35d00bdb9559642f81288d81","best_bid":"0.05","best_ask":"0.06"},{"asset_id":"96886111393998001968863279421729456597655847484197549086072988901191634450924","price":"0.94","size":"1474.22","side":"BUY","hash":"83e8fc10f66daa7ad90a291e586fce44a4228980","best_bid":"0.94","best_ask":"0.95"}],"timestamp":"1768250244665","event_type":"price_change"}}
{"schema_version":1,"source":"clob_ws_market","recv_ts_ns":1768250245013446709,"event_type":"price_change","market":"0xe51aa24ab1bbfefce466d642ad98587d13123e4ef95ec9aa73b712e775d4cbba","server_ts_ms":1768250244667,"raw":{"market":"0xe51aa24ab1bbfefce466d642ad98587d13123e4ef95ec9aa73b712e775d4cbba","price_changes":[{"asset_id":"96886111393998001968863279421729456597655847484197549086072988901191634450924","price":"0.94","size":"1499.22","side":"BUY","hash":"0a2b394beb6bfc8c601e0f089c6ea7294f16a18d","best_bid":"0.94","best_ask":"0.95"},{"asset_id":"54232589582260339592359130012520874109228367674780084862642636038394766871668","price":"0.06","size":"1499.22","side":"SELL","hash":"0b10dd482e069ef13dd712688c61504e499ec874","best_bid":"0.05","best_ask":"0.06"}],"timestamp":"1768250244667","event_type":"price_change"}}
{"schema_version":1,"source":"clob_ws_market","recv_ts_ns":1768250245017001595,"event_type":"price_change","market":"0xe51aa24ab1bbfefce466d642ad98587d13123e4ef95ec9aa73b712e775d4cbba","server_ts_ms":1768250244668,"raw":{"market":"0xe51aa24ab1bbfefce466d642ad98587d13123e4ef95ec9aa73b712e775d4cbba","price_changes":[{"asset_id":"96886111393998001968863279421729456597655847484197549086072988901191634450924","price":"0.93","size":"1549.82","side":"BUY","hash":"038d263f044deede3085a3895f68a58027e8ed55","best_bid":"0.94","best_ask":"0.95"},{"asset_id":"54232589582260339592359130012520874109228367674780084862642636038394766871668","price":"0.07","size":"1549.82","side":"SELL","hash":"8ac3b961df7e32f0869ca068ac1b4c4392831d24","best_bid":"0.05","best_ask":"0.06"}],"timestamp":"1768250244668","event_type":"price_change"}}
{"schema_version":1,"source":"clob_ws_market","recv_ts_ns":1768250245020925563,"event_type":"price_change","market":"0xe51aa24ab1bbfefce466d642ad98587d13123e4ef95ec9aa73b712e775d4cbba","server_ts_ms":1768250244669,"raw":{"market":"0xe51aa24ab1bbfefce466d642ad98587d13123e4ef95ec9aa73b712e775d4cbba","price_changes":[{"asset_id":"54232589582260339592359130012520874109228367674780084862642636038394766871668","price":"0.07","size":"1574.82","side":"SELL","hash":"20db8e966c9a968124cbb93db330a1a92c009e1b","best_bid":"0.05","best_ask":"0.06"},{"asset_id":"96886111393998001968863279421729456597655847484197549086072988901191634450924","price":"0.93","size":"1574.82","side":"BUY","hash":"1ff5a96804c97688e839838d02db9af9ebc60970","best_bid":"0.94","best_ask":"0.95"}],"timestamp":"1768250244669","event_type":"price_change"}}
{"schema_version":1,"source":"clob_ws_market","recv_ts_ns":1768250245024245254,"event_type":"price_change","market":"0xe51aa24ab1bbfefce466d642ad98587d13123e4ef95ec9aa73b712e775d4cbba","server_ts_ms":1768250244670,"raw":{"market":"0xe51aa24ab1bbfefce466d642ad98587d13123e4ef95ec9aa73b712e775d4cbba","price_changes":[{"asset_id":"54232589582260339592359130012520874109228367674780084862642636038394766871668","price":"0.02","size":"6835.25","side":"BUY","hash":"d83451aaaf196c722c78946fc599eca860961358","best_bid":"0.05","best_ask":"0.06"},{"asset_id":"96886111393998001968863279421729456597655847484197549086072988901191634450924","price":"0.98","size":"6835.25","side":"SELL","hash":"73aa631172f305bd983c8fb5aad3f5b1c817a20f","best_bid":"0.94","best_ask":"0.95"}],"timestamp":"1768250244670","event_type":"price_change"}}
{"schema_version":1,"source":"clob_ws_market","recv_ts_ns":1768250245030749878,"event_type":"price_change","market":"0xe51aa24ab1bbfefce466d642ad98587d13123e4ef95ec9aa73b712e775d4cbba","server_ts_ms":1768250244671,"raw":{"market":"0xe51aa24ab1bbfefce466d642ad98587d13123e4ef95ec9aa73b712e775d4cbba","price_changes":[{"asset_id":"96886111393998001968863279421729456597655847484197549086072988901191634450924","price":"0.93","size":"1599.82","side":"BUY","hash":"ee383b19dc9660719f6d3709a6741314a164f92c","best_bid":"0.94","best_ask":"0.95"},{"asset_id":"54232589582260339592359130012520874109228367674780084862642636038394766871668","price":"0.07","size":"1599.82","side":"SELL","hash":"ee52eb1d332b9309d40cae99b63f032b0d9ca6a5","best_bid":"0.05","best_ask":"0.06"}],"timestamp":"1768250244671","event_type":"price_change"}}
{"schema_version":1,"source":"clob_ws_market","recv_ts_ns":1768250245035255154,"event_type":"price_change","market":"0xe51aa24ab1bbfefce466d642ad98587d13123e4ef95ec9aa73b712e775d4cbba","server_ts_ms":1768250244673,"raw":{"market":"0xe51aa24ab1bbfefce466d642ad98587d13123e4ef95ec9aa73b712e775d4cbba","price_changes":[{"asset_id":"54232589582260339592359130012520874109228367674780084862642636038394766871668","price":"0.07","size":"1574.82","side":"SELL","hash":"21cc6a22292269abcbf5af0de171293d73bdc69b","best_bid":"0.05","best_ask":"0.06"},{"asset_id":"96886111393998001968863279421729456597655847484197549086072988901191634450924","price":"0.93","size":"1574.82","side":"BUY","hash":"87d3bb8c1020abdae9407f9bd347c7b81779991b","best_bid":"0.94","best_ask":"0.95"}],"timestamp":"1768250244673","event_type":"price_change"}}
{"schema_version":1,"source":"clob_ws_market","recv_ts_ns":1768250245053908654,"event_type":"price_change","market":"0xe51aa24ab1bbfefce466d642ad98587d13123e4ef95ec9aa73b712e775d4cbba","server_ts_ms":1768250244674,"raw":{"market":"0xe51aa24ab1bbfefce466d642ad98587d13123e4ef95ec9aa73b712e775d4cbba","price_changes":[{"asset_id":"54232589582260339592359130012520874109228367674780084862642636038394766871668","price":"0.08","size":"2317.36","side":"SELL","hash":"b2946dfe924f369165b5f8b3b41a6baed8588951","best_bid":"0.05","best_ask":"0.06"},{"asset_id":"96886111393998001968863279421729456597655847484197549086072988901191634450924","price":"0.92","size":"2317.36","side":"BUY","hash":"1a1325d03a8b10c09f3afe49e48d479b51e8f4fc","best_bid":"0.94","best_ask":"0.95"}],"timestamp":"1768250244674","event_type":"price_change"}}
{"schema_version":1,"source":"clob_ws_market","recv_ts_ns":1768250245059020548,"event_type":"price_change","market":"0xe51aa24ab1bbfefce466d642ad98587d13123e4ef95ec9aa73b712e775d4cbba","server_ts_ms":1768250244677,"raw":{"market":"0xe51aa24ab1bbfefce466d642ad98587d13123e4ef95ec9aa73b712e775d4cbba","price_changes":[{"asset_id":"96886111393998001968863279421729456597655847484197549086072988901191634450924","price":"0.62","size":"700.5","side":"BUY","hash":"c30462e81c213d9e33d4e46b24554d54e9e7a78a","best_bid":"0.94","best_ask":"0.95"},{"asset_id":"54232589582260339592359130012520874109228367674780084862642636038394766871668","price":"0.38","size":"700.5","side":"SELL","hash":"e99aa79b0247e18c37cb2d916b3e2491996b62ea","best_bid":"0.05","best_ask":"0.06"}],"timestamp":"1768250244677","event_type":"price_change"}}
{"schema_version":1,"source":"clob_ws_market","recv_ts_ns":1768250245063539240,"event_type":"price_change","market":"0xe51aa24ab1bbfefce466d642ad98587d13123e4ef95ec9aa73b712e775d4cbba","server_ts_ms":1768250244697,"raw":{"market":"0xe51aa24ab1bbfefce466d642ad98587d13123e4ef95ec9aa73b712e775d4cbba","price_changes":[{"asset_id":"96886111393998001968863279421729456597655847484197549086072988901191634450924","price":"0.94","size":"1511.22","side":"BUY","hash":"e2d598a59c884107e31094f97750489d5e6cf9fa","best_bid":"0.94","best_ask":"0.95"},{"asset_id":"54232589582260339592359130012520874109228367674780084862642636038394766871668","price":"0.06","size":"1511.22","side":"SELL","hash":"8311a4818d1973897573bd0dfcc3d10ffa5de4d2","best_bid":"0.05","best_ask":"0.06"}],"timestamp":"1768250244697","event_type":"price_change"}}
{"schema_version":1,"source":"clob_ws_market","recv_ts_ns":1768250245086825792,"event_type":"price_change","market":"0xe51aa24ab1bbfefce466d642ad98587d13123e4ef95ec9aa73b712e775d4cbba","server_ts_ms":1768250244729,"raw":{"market":"0xe51aa24ab1bbfefce466d642ad98587d13123e4ef95ec9aa73b712e775d4cbba","price_changes":[{"asset_id":"54232589582260339592359130012520874109228367674780084862642636038394766871668","price":"0.02","size":"6863.25","side":"BUY","hash":"7d1005b7085427a62c52be892d43ae86d78f4f2b","best_bid":"0.05","best_ask":"0.06"},{"asset_id":"96886111393998001968863279421729456597655847484197549086072988901191634450924","price":"0.98","size":"6863.25","side":"SELL","hash":"451c536839c86cd1ae6c5ba4dda81f61d8b20d20","best_bid":"0.94","best_ask":"0.95"}],"timestamp":"1768250244729","event_type":"price_change"}}
{"schema_version":1,"source":"clob_ws_market","recv_ts_ns":1768250245108466465,"event_type":"price_change","market":"0xe51aa24ab1bbfefce466d642ad98587d13123e4ef95ec9aa73b712e775d4cbba","server_ts_ms":1768250244767,"raw":{"market":"0xe51aa24ab1bbfefce466d642ad98587d13123e4ef95ec9aa73b712e775d4cbba","price_changes":[{"asset_id":"96886111393998001968863279421729456597655847484197549086072988901191634450924","price":"0.94","size":"1523.22","side":"BUY","hash":"85e1ea9a0821223d56c04e862c5e47d22ac6c285","best_bid":"0.94","best_ask":"0.95"},{"asset_id":"54232589582260339592359130012520874109228367674780084862642636038394766871668","price":"0.06","size":"1523.22","side":"SELL","hash":"c4a99b498e08cbf6b8bcb8ec6fe4107118f6d024","best_bid":"0.05","best_ask":"0.06"}],"timestamp":"1768250244767","event_type":"price_change"}}
{"schema_version":1,"source":"clob_ws_market","recv_ts_ns":1768250245111592609,"event_type":"price_change","market":"0xe51aa24ab1bbfefce466d642ad98587d13123e4ef95ec9aa73b712e775d4cbba","server_ts_ms":1768250244775,"raw":{"market":"0xe51aa24ab1bbfefce466d642ad98587d13123e4ef95ec9aa73b712e775d4cbba","price_changes":[{"asset_id":"96886111393998001968863279421729456597655847484197549086072988901191634450924","price":"0.94","size":"1535.22","side":"BUY","hash":"5d5e9eced36191f4ed9092cc5326608b3975a0eb","best_bid":"0.94","best_ask":"0.95"},{"asset_id":"54232589582260339592359130012520874109228367674780084862642636038394766871668","price":"0.06","size":"1535.22","side":"SELL","hash":"062dc9c7ba6b5465253a3081a726ff7bd6c65ca4","best_bid":"0.05","best_ask":"0.06"}],"timestamp":"1768250244775","event_type":"price_change"}}
{"schema_version":1,"source":"clob_ws_market","recv_ts_ns":1768250245121856282,"event_type":"price_change","market":"0xe51aa24ab1bbfefce466d642ad98587d13123e4ef95ec9aa73b712e775d4cbba","server_ts_ms":1768250244798,"raw":{"market":"0xe51aa24ab1bbfefce466d642ad98587d13123e4ef95ec9aa73b712e775d4cbba","price_changes":[{"asset_id":"96886111393998001968863279421729456597655847484197549086072988901191634450924","price":"0.94","size":"1547.22","side":"BUY","hash":"fbe26691bda625f84dcd14c4827d0e9349f07b01","best_bid":"0.94","best_ask":"0.95"},{"asset_id":"54232589582260339592359130012520874109228367674780084862642636038394766871668","price":"0.06","size":"1547.22","side":"SELL","hash":"b1f86cc8a33e9a7a2a614487a4137f50cbc8208b","best_bid":"0.05","best_ask":"0.06"}],"timestamp":"1768250244798","event_type":"price_change"}}
{"schema_version":1,"source":"clob_ws_market","recv_ts_ns":1768250245127899976,"event_type":"price_change","market":"0xe51aa24ab1bbfefce466d642ad98587d13123e4ef95ec9aa73b712e775d4cbba","server_ts_ms":1768250244805,"raw":{"market":"0xe51aa24ab1bbfefce466d642ad98587d13123e4ef95ec9aa73b712e775d4cbba","price_changes":[{"asset_id":"54232589582260339592359130012520874109228367674780084862642636038394766871668","price":"0.06","size":"1560.22","side":"SELL","hash":"54b408119135223c3c332768afeefb526131bdb9","best_bid":"0.05","best_ask":"0.06"},{"asset_id":"96886111393998001968863279421729456597655847484197549086072988901191634450924","price":"0.94","size":"1560.22","side":"BUY","hash":"a7c1bea46934b7a332c5f996cfd4a2c5a7cd1f44","best_bid":"0.94","best_ask":"0.95"}],"timestamp":"1768250244805","event_type":"price_change"}}
{"schema_version":1,"source":"clob_ws_market","recv_ts_ns":1768250245131905405,"event_type":"price_change","market":"0xe51aa24ab1bbfefce466d642ad98587d13123e4ef95ec9aa73b712e775d4cbba","server_ts_ms":1768250244816,"raw":{"market":"0xe51aa24ab1bbfefce466d642ad98587d13123e4ef95ec9aa73b712e775d4cbba","price_changes":[{"asset_id":"54232589582260339592359130012520874109228367674780084862642636038394766871668","price":"0.05","size":"795.34","side":"BUY","hash":"af7b8ef7f3e9e0ae867a25349fa5baa67e666056","best_bid":"0.05","best_ask":"0.06"},{"asset_id":"96886111393998001968863279421729456597655847484197549086072988901191634450924","price":"0.95","size":"795.34","side":"SELL","hash":"7d87b6011c9304a94afc66668e14c6f59f1c0442","best_bid":"0.94","best_ask":"0.95"}],"timestamp":"1768250244816","event_type":"price_change"}}
{"schema_version":1,"source":"clob_ws_market","recv_ts_ns":1768250245159099896,"event_type":"price_change","market":"0xe51aa24ab1bbfefce466d642ad98587d13123e4ef95ec9aa73b712e775d4cbba","server_ts_ms":1768250244830,"raw":{"market":"0xe51aa24ab1bbfefce466d642ad98587d13123e4ef95ec9aa73b712e775d4cbba","price_changes":[{"asset_id":"96886111393998001968863279421729456597655847484197549086072988901191634450924","price":"0.93","size":"1558.82","side":"BUY","hash":"4ca4fa87df7348d94f8e62d902db4fa0532dac80","best_bid":"0.94","best_ask":"0.95"},{"asset_id":"54232589582260339592359130012520874109228367674780084862642636038394766871668","price":"0.07","size":"1558.82","side":"SELL","hash":"a5a85835362adfad2f49c01f4186370a81de91f3","best_bid":"0.05","best_ask":"0.06"}],"timestamp":"1768250244830","event_type":"price_change"}}
{"schema_version":1,"source":"clob_ws_market","recv_ts_ns":1768250245196289607,"event_type":"price_change","market":"0xe51aa24ab1bbfefce466d642ad98587d13123e4ef95ec9aa73b712e775d4cbba","server_ts_ms":1768250244853,"raw":{"market":"0xe51aa24ab1bbfefce466d642ad98587d13123e4ef95ec9aa73b712e775d4cbba","price_changes":[{"asset_id":"96886111393998001968863279421729456597655847484197549086072988901191634450924","price":"0.94","size":"1570.22","side":"BUY","hash":"566f37733c0fd93df8338c4ca0d77a92f744256d","best_bid":"0.94","best_ask":"0.95"},{"asset_id":"54232589582260339592359130012520874109228367674780084862642636038394766871668","price":"0.06","size":"1570.22","side":"SELL","hash":"d7db42ec7b8398776cde93ca188899548314f4fd","best_bid":"0.05","best_ask":"0.06"}],"timestamp":"1768250244853","event_type":"price_change"}}
{"schema_version":1,"source":"clob_ws_market","recv_ts_ns":1768250245237162576,"event_type":"price_change","market":"0xe51aa24ab1bbfefce466d642ad98587d13123e4ef95ec9aa73b712e775d4cbba","server_ts_ms":1768250244863,"raw":{"market":"0xe51aa24ab1bbfefce466d642ad98587d13123e4ef95ec9aa73b712e775d4cbba","price_changes":[{"asset_id":"54232589582260339592359130012520874109228367674780084862642636038394766871668","price":"0.04","size":"406.4","side":"BUY","hash":"8d86ecc145b11e89074a32c4713385398f1b3a46","best_bid":"0.05","best_ask":"0.06"},{"asset_id":"96886111393998001968863279421729456597655847484197549086072988901191634450924","price":"0.96","size":"406.4","side":"SELL","hash":"4d11c998770314d16f116981280641f3e9e8f5b0","best_bid":"0.94","best_ask":"0.95"}],"timestamp":"1768250244863","event_type":"price_change"}}
{"schema_version":1,"source":"clob_ws_market","recv_ts_ns":1768250245243082942,"event_type":"best_bid_ask","market":"0xe51aa24ab1bbfefce466d642ad98587d13123e4ef95ec9aa73b712e775d4cbba","server_ts_ms":1768250244869,"raw":{"market":"0xe51aa24ab1bbfefce466d642ad98587d13123e4ef95ec9aa73b712e775d4cbba","asset_id":"54232589582260339592359130012520874109228367674780084862642636038394766871668","best_bid":"0.05","best_ask":"0.06","spread":"0.01","timestamp":"1768250244869","event_type":"best_bid_ask"}}
{"schema_version":1,"source":"clob_ws_market","recv_ts_ns":1768250245245754772,"event_type":"price_change","market":"0xe51aa24ab1bbfefce466d642ad98587d13123e4ef95ec9aa73b712e775d4cbba","server_ts_ms":1768250244867,"raw":{"market":"0xe51aa24ab1bbfefce466d642ad98587d13123e4ef95ec9aa73b712e775d4cbba","price_changes":[{"asset_id":"96886111393998001968863279421729456597655847484197549086072988901191634450924","price":"0.94","size":"1503.55","side":"BUY","hash":"c375f73783433176a89e538899fd2fee5f474f5d","best_bid":"0.94","best_ask":"0.95"},{"asset_id":"54232589582260339592359130012520874109228367674780084862642636038394766871668","price":"0.06","size":"1503.55","side":"SELL","hash":"5bab8324bd453cefa90115d514814de0f37867a6","best_bid":"0.05","best_ask":"0.06"}],"timestamp":"1768250244867","event_type":"price_change"}}
{"schema_version":1,"source":"clob_ws_market","recv_ts_ns":1768250245248365960,"event_type":"book","market":"0xe51aa24ab1bbfefce466d642ad98587d13123e4ef95ec9aa73b712e775d4cbba","server_ts_ms":1768250244867,"raw":{"market":"0xe51aa24ab1bbfefce466d642ad98587d13123e4ef95ec9aa73b712e775d4cbba","asset_id":"54232589582260339592359130012520874109228367674780084862642636038394766871668","bids":[{"price":"0.01","size":"20993.9"},{"price":"0.02","size":"6863.25"},{"price":"0.03","size":"2780.33"},{"price":"0.04","size":"406.4"},{"price":"0.05","size":"795.34"}],"asks":[{"price":"0.99","size":"24290.24"},{"price":"0.98","size":"7594.51"},{"price":"0.97","size":"5964.69"},{"price":"0.96","size":"5411.4"},{"price":"0.95","size":"5356.39"},{"price":"0.94","size":"5328"},{"price":"0.93","size":"5039.28"},{"price":"0.92","size":"5022.7"},{"price":"0.91","size":"5320.9"},{"price":"0.9","size":"5158.44"},{"price":"0.89","size":"18.3"},{"price":"0.88","size":"30.3"},{"price":"0.87","size":"16.5"},{"price":"0.86","size":"15.8"},{"price":"0.85","size":"104.19"},{"price":"0.84","size":"24.69"},{"price":"0.83","size":"14.19"},{"price":"0.82","size":"13.8"},{"price":"0.81","size":"13.4"},{"price":"0.8","size":"38.1"},{"price":"0.79","size":"12.8"},{"price":"0.78","size":"12.6"},{"price":"0.77","size":"12.3"},{"price":"0.76","size":"22.1"},{"price":"0.75","size":"16.9"},{"price":"0.74","size":"21.8"},{"price":"0.73","size":"11.6"},{"price":"0.72","size":"11.4"},{"price":"0.71","size":"61.3"},{"price":"0.7","size":"26.2"},{"price":"0.69","size":"11.1"},{"price":"0.68","size":"11"},{"price":"0.67","size":"110.9"},{"price":"0.66","size":"10.8"},{"price":"0.65","size":"15.7"},{"price":"0.64","size":"10.6"},{"price":"0.63","size":"10.6"},{"price":"0.62","size":"22.5"},{"price":"0.61","size":"10.5"},{"price":"0.6","size":"45.4"},{"price":"0.59","size":"311.4"},{"price":"0.58","size":"820.82"},{"price":"0.57","size":"826.3"},{"price":"0.56","size":"1062.3"},{"price":"0.55","size":"582.3"},{"price":"0.54","size":"626.2"},{"price":"0.53","size":"562.2"},{"price":"0.52","size":"567.2"},{"price":"0.51","size":"573.2"},{"price":"0.5","size":"917.2"},{"price":"0.49","size":"591.2"},{"price":"0.48","size":"590.2"},{"price":"0.47","size":"573.2"},{"price":"0.46","size":"636.61"},{"price":"0.45","size":"362.97"},{"price":"0.44","size":"341.3"},{"price":"0.43","size":"320.62"},{"price":"0.42","size":"567.3"},{"price":"0.41","size":"562.4"},{"price":"0.4","size":"693.02"},{"price":"0.39","size":"625.5"},{"price":"0.38","size":"700.5"},{"price":"0.37","size":"672.32"},{"price":"0.36","size":"680.6"},{"price":"0.35","size":"536.14"},{"price":"0.34","size":"602.8"},{"price":"0.33","size":"572.9"},{"price":"0.32","size":"573"},{"price":"0.31","size":"595.1"},{"price":"0.3","size":"603.2"},{"price":"0.29","size":"1318.72"},{"price":"0.28","size":"1043.04"},{"price":"0.27","size":"663.6"},{"price":"0.26","size":"911.17"},{"price":"0.25","size":"694.3"},{"price":"0.24","size":"717.6"},{"price":"0.23","size":"1183.3"},{"price":"0.22","size":"1526.53"},{"price":"0.21","size":"1178.8"},{"price":"0.2","size":"1445.08"},{"price":"0.19","size":"1229.8"},{"price":"0.18","size":"1467.57"},{"price":"0.17","size":"1470.51"},{"price":"0.16","size":"1718.59"},{"price":"0.15","size":"1762.5"},{"price":"0.14","size":"1755.6"},{"price":"0.13","size":"1588.93"},{"price":"0.12","size":"2555.4"},{"price":"0.11","size":"1898.8"},{"price":"0.1","size":"3455.34"},{"price":"0.09","size":"2701.44"},{"price":"0.08","size":"2317.36"},{"price":"0.07","size":"1558.82"},{"price":"0.06","size":"1503.55"}],"hash":"5bab8324bd453cefa90115d514814de0f37867a6","timestamp":"1768250244867","event_type":"book"}}
{"schema_version":1,"source":"clob_ws_market","recv_ts_ns":1768250245262575113,"event_type":"price_change","market":"0xe51aa24ab1bbfefce466d642ad98587d13123e4ef95ec9aa73b712e775d4cbba","server_ts_ms":1768250244883,"raw":{"market":"0xe51aa24ab1bbfefce466d642ad98587d13123e4ef95ec9aa73b712e775d4cbba","price_changes":[{"asset_id":"96886111393998001968863279421729456597655847484197549086072988901191634450924","price":"0.94","size":"1519.55","side":"BUY","hash":"c3f1845c0af990624da8bd22f09217342a95040d","best_bid":"0.94","best_ask":"0.95"},{"asset_id":"54232589582260339592359130012520874109228367674780084862642636038394766871668","price":"0.06","size":"1519.55","side":"SELL","hash":"e00755377e1c58aee71091d318c8cb28c94c2e4d","best_bid":"0.05","best_ask":"0.06"}],"timestamp":"1768250244883","event_type":"price_change"}}
{"schema_version":1,"source":"clob_ws_market","recv_ts_ns":1768250245279617286,"event_type":"last_trade_price","market":"0xe51aa24ab1bbfefce466d642ad98587d13123e4ef95ec9aa73b712e775d4cbba","server_ts_ms":1768250244907,"raw":{"market":"0xe51aa24ab1bbfefce466d642ad98587d13123e4ef95ec9aa73b712e775d4cbba","asset_id":"54232589582260339592359130012520874109228367674780084862642636038394766871668","price":"0.06","size":"66.666665","fee_rate_bps":"1000","side":"BUY","timestamp":"1768250244907","event_type":"last_trade_price","transaction_hash":"0xbb217c311e88ff2205e2e079771e48aab4af1423df765b2360a7aeb8cf3a4b54"}}
{"schema_version":1,"source":"clob_ws_market","recv_ts_ns":1768250245282557675,"event_type":"price_change","market":"0xe51aa24ab1bbfefce466d642ad98587d13123e4ef95ec9aa73b712e775d4cbba","server_ts_ms":1768250244919,"raw":{"market":"0xe51aa24ab1bbfefce466d642ad98587d13123e4ef95ec9aa73b712e775d4cbba","price_changes":[{"asset_id":"54232589582260339592359130012520874109228367674780084862642636038394766871668","price":"0.02","size":"6813.25","side":"BUY","hash":"78b53ef46df01286f3405d9574af93680c018961","best_bid":"0.05","best_ask":"0.06"},{"asset_id":"96886111393998001968863279421729456597655847484197549086072988901191634450924","price":"0.98","size":"6813.25","side":"SELL","hash":"2b4b905b5a6b68ffd71b09004e5b93d36484d984","best_bid":"0.94","best_ask":"0.95"}],"timestamp":"1768250244919","event_type":"price_change"}}
{"schema_version":1,"source":"clob_ws_market","recv_ts_ns":1768250245287917047,"event_type":"price_change","market":"0xe51aa24ab1bbfefce466d642ad98587d13123e4ef95ec9aa73b712e775d4cbba","server_ts_ms":1768250244926,"raw":{"market":"0xe51aa24ab1bbfefce466d642ad98587d13123e4ef95ec9aa73b712e775d4cbba","price_changes":[{"asset_id":"54232589582260339592359130012520874109228367674780084862642636038394766871668","price":"0.05","size":"1530.34","side":"BUY","hash":"783aba1b239dd1d04818b8742dd1a3c04447a4d5","best_bid":"0.05","best_ask":"0.06"},{"asset_id":"96886111393998001968863279421729456597655847484197549086072988901191634450924","price":"0.95","size":"1530.34","side":"SELL","hash":"bb1f0a03d9d8319ece811403c344cb40f8d75a45","best_bid":"0.94","best_ask":"0.95"}],"timestamp":"1768250244926","event_type":"price_change"}}
{"schema_version":1,"source":"clob_ws_market","recv_ts_ns":1768250245340910661,"event_type":"price_change","market":"0xe51aa24ab1bbfefce466d642ad98587d13123e4ef95ec9aa73b712e775d4cbba","server_ts_ms":1768250244986,"raw":{"market":"0xe51aa24ab1bbfefce466d642ad98587d13123e4ef95ec9aa73b712e775d4cbba","price_changes":[{"asset_id":"54232589582260339592359130012520874109228367674780084862642636038394766871668","price":"0.04","size":"356.4","side":"BUY","hash":"4ca75cd91ba53e1988c271d1d3d4c6f403756ac4","best_bid":"0.05","best_ask":"0.06"},{"asset_id":"96886111393998001968863279421729456597655847484197549086072988901191634450924","price":"0.96","size":"356.4","side":"SELL","hash":"0200ec273fee48252181f00632328e33f9b048b9","best_bid":"0.94","best_ask":"0.95"}],"timestamp":"1768250244986","event_type":"price_change"}}
{"schema_version":1,"source":"clob_ws_market","recv_ts_ns":1768250245348857727,"event_type":"price_change","market":"0xe51aa24ab1bbfefce466d642ad98587d13123e4ef95ec9aa73b712e775d4cbba","server_ts_ms":1768250244988,"raw":{"market":"0xe51aa24ab1bbfefce466d642ad98587d13123e4ef95ec9aa73b712e775d4cbba","price_changes":[{"asset_id":"96886111393998001968863279421729456597655847484197549086072988901191634450924","price":"0.53","size":"567.2","side":"BUY","hash":"32776d929433987d20718fa6c6e9ef9d6a6a588e","best_bid":"0.94","best_ask":"0.95"},{"asset_id":"54232589582260339592359130012520874109228367674780084862642636038394766871668","price":"0.47","size":"567.2","side":"SELL","hash":"431b7c4520dc6487c2c61068fb3ec35a5ff6ebb7","best_bid":"0.05","best_ask":"0.06"}],"timestamp":"1768250244988","event_type":"price_change"}}
{"schema_version":1,"source":"clob_ws_market","recv_ts_ns":1768250245352838586,"event_type":"price_change","market":"0xe51aa24ab1bbfefce466d642ad98587d13123e4ef95ec9aa73b712e775d4cbba","server_ts_ms":1768250245000,"raw":{"market":"0xe51aa24ab1bbfefce466d642ad98587d13123e4ef95ec9aa73b712e775d4cbba","price_changes":[{"asset_id":"54232589582260339592359130012520874109228367674780084862642636038394766871668","price":"0.02","size":"6713.25","side":"BUY","hash":"7887cb34d0e61837c7fc6f313a93c992fa08ad99","best_bid":"0.05","best_ask":"0.06"},{"asset_id":"96886111393998001968863279421729456597655847484197549086072988901191634450924","price":"0.98","size":"6713.25","side":"SELL","hash":"c6ab2fad0d0203d18ac42183cd487aadda288d04","best_bid":"0.94","best_ask":"0.95"}],"timestamp":"1768250245000","event_type":"price_change"}}
{"schema_version":1,"source":"clob_ws_market","recv_ts_ns":1768250245361104026,"event_type":"price_change","market":"0xe51aa24ab1bbfefce466d642ad98587d13123e4ef95ec9aa73b712e775d4cbba","server_ts_ms":1768250245030,"raw":{"market":"0xe51aa24ab1bbfefce466d642ad98587d13123e4ef95ec9aa73b712e775d4cbba","price_changes":[{"asset_id":"54232589582260339592359130012520874109228367674780084862642636038394766871668","price":"0.02","size":"6763.25","side":"BUY","hash":"1f5b71471b81dd9327afd348cf92b5b66421cfb8","best_bid":"0.05","best_ask":"0.06"},{"asset_id":"96886111393998001968863279421729456597655847484197549086072988901191634450924","price":"0.98","size":"6763.25","side":"SELL","hash":"2d7e4170d149b1083861120ae4d385fd0f506814","best_bid":"0.94","best_ask":"0.95"}],"timestamp":"1768250245030","event_type":"price_change"}}
{"schema_version":1,"source":"clob_ws_market","recv_ts_ns":1768250245365901719,"event_type":"price_change","market":"0xe51aa24ab1bbfefce466d642ad98587d13123e4ef95ec9aa73b712e775d4cbba","server_ts_ms":1768250245037,"raw":{"market":"0xe51aa24ab1bbfefce466d642ad98587d13123e4ef95ec9aa73b712e775d4cbba","price_changes":[{"asset_id":"96886111393998001968863279421729456597655847484197549086072988901191634450924","price":"0.94","size":"1569.55","side":"BUY","hash":"82c165f8a3d3892e07430c296f00ce9b21049889","best_bid":"0.94","best_ask":"0.95"},{"asset_id":"54232589582260339592359130012520874109228367674780084862642636038394766871668","price":"0.06","size":"1569.55","side":"SELL","hash":"e261d959aa8f607a53c924ed8230ef9f74460ea2","best_bid":"0.05","best_ask":"0.06"}],"timestamp":"1768250245037","event_type":"price_change"}}
{"schema_version":1,"source":"clob_ws_market","recv_ts_ns":1768250245370601918,"event_type":"price_change","market":"0xe51aa24ab1bbfefce466d642ad98587d13123e4ef95ec9aa73b712e775d4cbba","server_ts_ms":1768250245040,"raw":{"market":"0xe51aa24ab1bbfefce466d642ad98587d13123e4ef95ec9aa73b712e775d4cbba","price_changes":[{"asset_id":"54232589582260339592359130012520874109228367674780084862642636038394766871668","price":"0.02","size":"6863.25","side":"BUY","hash":"dbc688ff3e7e07e150a2a23f4184272665e7216b","best_bid":"0.05","best_ask":"0.06"},{"asset_id":"96886111393998001968863279421729456597655847484197549086072988901191634450924","price":"0.98","size":"6863.25","side":"SELL","hash":"fd37da4e0d8dc3240827e9c01ba23302cd6ee17a","best_bid":"0.94","best_ask":"0.95"}],"timestamp":"1768250245040","event_type":"price_change"}}
{"schema_version":1,"source":"clob_ws_market","recv_ts_ns":1768250245375129672,"event_type":"price_change","market":"0xe51aa24ab1bbfefce466d642ad98587d13123e4ef95ec9aa73b712e775d4cbba","server_ts_ms":1768250245053,"raw":{"market":"0xe51aa24ab1bbfefce466d642ad98587d13123e4ef95ec9aa73b712e775d4cbba","price_changes":[{"asset_id":"54232589582260339592359130012520874109228367674780084862642636038394766871668","price":"0.04","size":"340.4","side":"BUY","hash":"55e9449f222111d75c7719a4f684fe7b1319d8e9","best_bid":"0.05","best_ask":"0.06"},{"asset_id":"96886111393998001968863279421729456597655847484197549086072988901191634450924","price":"0.96","size":"340.4","side":"SELL","hash":"b3d5f936b5ec7be3e1878179ba5effcee8a4fcd3","best_bid":"0.94","best_ask":"0.95"}],"timestamp":"1768250245053","event_type":"price_change"}}
{"schema_version":1,"source":"clob_ws_market","recv_ts_ns":1768250245379455132,"event_type":"price_change","market":"0xe51aa24ab1bbfefce466d642ad98587d13123e4ef95ec9aa73b712e775d4cbba","server_ts_ms":1768250245058,"raw":{"market":"0xe51aa24ab1bbfefce466d642ad98587d13123e4ef95ec9aa73b712e775d4cbba","price_changes":[{"asset_id":"96886111393998001968863279421729456597655847484197549086072988901191634450924","price":"0.93","size":"1542.82","side":"BUY","hash":"c46da456681afc69ea8ff91555418754d012a603","best_bid":"0.94","best_ask":"0.95"},{"asset_id":"54232589582260339592359130012520874109228367674780084862642636038394766871668","price":"0.07","size":"1542.82","side":"SELL","hash":"2b345a5c61d0246265e29e8aed4d04d50a1f99f9","best_bid":"0.05","best_ask":"0.06"}],"timestamp":"1768250245058","event_type":"price_change"}}
{"schema_version":1,"source":"clob_ws_market","recv_ts_ns":1768250245383913945,"event_type":"price_change","market":"0xe51aa24ab1bbfefce466d642ad98587d13123e4ef95ec9aa73b712e775d4cbba","server_ts_ms":1768250245060,"raw":{"market":"0xe51aa24ab1bbfefce466d642ad98587d13123e4ef95ec9aa73b712e775d4cbba","price_changes":[{"asset_id":"54232589582260339592359130012520874109228367674780084862642636038394766871668","price":"0.04","size":"324.4","side":"BUY","hash":"130af297f2ba574711ce334695a25791b777ec89","best_bid":"0.05","best_ask":"0.06"},{"asset_id":"96886111393998001968863279421729456597655847484197549086072988901191634450924","price":"0.96","size":"324.4","side":"SELL","hash":"fb53d1c37be44cb2706b48b592c2032b83d7942d","best_bid":"0.94","best_ask":"0.95"}],"timestamp":"1768250245060","event_type":"price_change"}}
{"schema_version":1,"source":"clob_ws_market","recv_ts_ns":1768250245397161261,"event_type":"price_change","market":"0xe51aa24ab1bbfefce466d642ad98587d13123e4ef95ec9aa73b712e775d4cbba","server_ts_ms":1768250245065,"raw":{"market":"0xe51aa24ab1bbfefce466d642ad98587d13123e4ef95ec9aa73b712e775d4cbba","price_changes":[{"asset_id":"54232589582260339592359130012520874109228367674780084862642636038394766871668","price":"0.04","size":"308.4","side":"BUY","hash":"ca22d18b9bb3b374b37157d318a53a63d06434ec","best_bid":"0.05","best_ask":"0.06"},{"asset_id":"96886111393998001968863279421729456597655847484197549086072988901191634450924","price":"0.96","size":"308.4","side":"SELL","hash":"430fcfe88b109fa7fd1ae7c7c2585439cd22c9af","best_bid":"0.94","best_ask":"0.95"}],"timestamp":"1768250245065","event_type":"price_change"}}
{"schema_version":1,"source":"clob_ws_market","recv_ts_ns":1768250245400863805,"event_type":"price_change","market":"0xe51aa24ab1bbfefce466d642ad98587d13123e4ef95ec9aa73b712e775d4cbba","server_ts_ms":1768250245068,"raw":{"market":"0xe51aa24ab1bbfefce466d642ad98587d13123e4ef95ec9aa73b712e775d4cbba","price_changes":[{"asset_id":"54232589582260339592359130012520874109228367674780084862642636038394766871668","price":"0.02","size":"6847.25","side":"BUY","hash":"b46e40853b7503d60d97b31f8e54a6e27c684b74","best_bid":"0.05","best_ask":"0.06"},{"asset_id":"96886111393998001968863279421729456597655847484197549086072988901191634450924","price":"0.98","size":"6847.25","side":"SELL","hash":"2c3e581fe34e01c34ab564a60024808ed1c98c68","best_bid":"0.94","best_ask":"0.95"}],"timestamp":"1768250245068","event_type":"price_change"}}
{"schema_version":1,"source":"clob_ws_market","recv_ts_ns":1768250245404305750,"event_type":"price_change","market":"0xe51aa24ab1bbfefce466d642ad98587d13123e4ef95ec9aa73b712e775d4cbba","server_ts_ms":1768250245069,"raw":{"market":"0xe51aa24ab1bbfefce466d642ad98587d13123e4ef95ec9aa73b712e775d4cbba","price_changes":[{"asset_id":"54232589582260339592359130012520874109228367674780084862642636038394766871668","price":"0.04","size":"292.4","side":"BUY","hash":"263110e40e80e7994a554355e371f320b6b42e08","best_bid":"0.05","best_ask":"0.06"},{"asset_id":"96886111393998001968863279421729456597655847484197549086072988901191634450924","price":"0.96","size":"292.4","side":"SELL","hash":"e3e984882b0923a928ba1efbc80fc800c21cca21","best_bid":"0.94","best_ask":"0.95"}],"timestamp":"1768250245069","event_type":"price_change"}}
{"schema_version":1,"source":"clob_ws_market","recv_ts_ns":1768250245407697420,"event_type":"price_change","market":"0xe51aa24ab1bbfefce466d642ad98587d13123e4ef95ec9aa73b712e775d4cbba","server_ts_ms":1768250245080,"raw":{"market":"0xe51aa24ab1bbfefce466d642ad98587d13123e4ef95ec9aa73b712e775d4cbba","price_changes":[{"asset_id":"96886111393998001968863279421729456597655847484197549086072988901191634450924","price":"0.93","size":"1526.82","side":"BUY","hash":"80fae91abb244e36255de404190651e1d21eca7b","best_bid":"0.94","best_ask":"0.95"},{"asset_id":"54232589582260339592359130012520874109228367674780084862642636038394766871668","price":"0.07","size":"1526.82","side":"SELL","hash":"742e9b6c17790338f9763cb7e2643a9c1cd53061","best_bid":"0.05","best_ask":"0.06"}],"timestamp":"1768250245080","event_type":"price_change"}}
{"schema_version":1,"source":"clob_ws_market","recv_ts_ns":1768250245412078751,"event_type":"price_change","market":"0xe51aa24ab1bbfefce466d642ad98587d13123e4ef95ec9aa73b712e775d4cbba","server_ts_ms":1768250245088,"raw":{"market":"0xe51aa24ab1bbfefce466d642ad98587d13123e4ef95ec9aa73b712e775d4cbba","price_changes":[{"asset_id":"96886111393998001968863279421729456597655847484197549086072988901191634450924","price":"0.93","size":"1510.82","side":"BUY","hash":"92fa466c2f4f99ca50bf1a9efaaef87a8b573182","best_bid":"0.94","best_ask":"0.95"},{"asset_id":"54232589582260339592359130012520874109228367674780084862642636038394766871668","price":"0.07","size":"1510.82","side":"SELL","hash":"3617442b256a0cb54d5fe27ef692ee1533e91bd4","best_bid":"0.05","best_ask":"0.06"}],"timestamp":"1768250245088","event_type":"price_change"}}
{"schema_version":1,"source":"clob_ws_market","recv_ts_ns":1768250245427811090,"event_type":"price_change","market":"0xe51aa24ab1bbfefce466d642ad98587d13123e4ef95ec9aa73b712e775d4cbba","server_ts_ms":1768250245099,"raw":{"market":"0xe51aa24ab1bbfefce466d642ad98587d13123e4ef95ec9aa73b712e775d4cbba","price_changes":[{"asset_id":"54232589582260339592359130012520874109228367674780084862642636038394766871668","price":"0.03","size":"2796.33","side":"BUY","hash":"7100b89d44d3c05160da9de3f50c5b68553b2442","best_bid":"0.05","best_ask":"0.06"},{"asset_id":"96886111393998001968863279421729456597655847484197549086072988901191634450924","price":"0.97","size":"2796.33","side":"SELL","hash":"6a13e89b9e64c9d775debc9897580216a86ab85d","best_bid":"0.94","best_ask":"0.95"}],"timestamp":"1768250245099","event_type":"price_change"}}
{"schema_version":1,"source":"clob_ws_market","recv_ts_ns":1768250245432090174,"event_type":"price_change","market":"0xe51aa24ab1bbfefce466d642ad98587d13123e4ef95ec9aa73b712e775d4cbba","server_ts_ms":1768250245103,"raw":{"market":"0xe51aa24ab1bbfefce466d642ad98587d13123e4ef95ec9aa73b712e775d4cbba","price_changes":[{"asset_id":"96886111393998001968863279421729456597655847484197549086072988901191634450924","price":"0.94","size":"1585.55","side":"BUY","hash":"85f8211a3daa59e481dfa36db7412a36fdfbc3c1","best_bid":"0.94","best_ask":"0.95"},{"asset_id":"54232589582260339592359130012520874109228367674780084862642636038394766871668","price":"0.06","size":"1585.55","side":"SELL","hash":"9a330b776b1d5a810bea0637a7e0cc42cdf76081","best_bid":"0.05","best_ask":"0.06"}],"timestamp":"1768250245103","event_type":"price_change"}}
{"schema_version":1,"source":"clob_ws_market","recv_ts_ns":1768250245435948801,"event_type":"price_change","market":"0xe51aa24ab1bbfefce466d642ad98587d13123e4ef95ec9aa73b712e775d4cbba","server_ts_ms":1768250245105,"raw":{"market":"0xe51aa24ab1bbfefce466d642ad98587d13123e4ef95ec9aa73b712e775d4cbba","price_changes":[{"asset_id":"54232589582260339592359130012520874109228367674780084862642636038394766871668","price":"0.03","size":"2812.33","side":"BUY","hash":"b6f48af27a713086d5a26c7986e6fb47d0af0c91","best_bid":"0.05","best_ask":"0.06"},{"asset_id":"96886111393998001968863279421729456597655847484197549086072988901191634450924","price":"0.97","size":"2812.33","side":"SELL","hash":"0cfe4e3b91ec5c0f1a8876cd7ee949e1ad13537e","best_bid":"0.94","best_ask":"0.95"}],"timestamp":"1768250245105","event_type":"price_change"}}
{"schema_version":1,"source":"clob_ws_market","recv_ts_ns":1768250245439442643,"event_type":"price_change","market":"0xe51aa24ab1bbfefce466d642ad98587d13123e4ef95ec9aa73b712e775d4cbba","server_ts_ms":1768250245107,"raw":{"market":"0xe51aa24ab1bbfefce466d642ad98587d13123e4ef95ec9aa73b712e775d4cbba","price_changes":[{"asset_id":"54232589582260339592359130012520874109228367674780084862642636038394766871668","price":"0.01","size":"21009.9","side":"BUY","hash":"d7be85f980cb0993dc355c289bc3c22cd6fce609","best_bid":"0.05","best_ask":"0.06"},{"asset_id":"96886111393998001968863279421729456597655847484197549086072988901191634450924","price":"0.99","size":"21009.9","side":"SELL","hash":"3cd2fda295f0d91846a9e001e939e83b799895ba","best_bid":"0.94","best_ask":"0.95"}],"timestamp":"1768250245107","event_type":"price_change"}}
{"schema_version":1,"source":"clob_ws_market","recv_ts_ns":1768250245442507520,"event_type":"best_bid_ask","market":"0xe51aa24ab1bbfefce466d642ad98587d13123e4ef95ec9aa73b712e775d4cbba","server_ts_ms":1768250245111,"raw":{"market":"0xe51aa24ab1bbfefce466d642ad98587d13123e4ef95ec9aa73b712e775d4cbba","asset_id":"54232589582260339592359130012520874109228367674780084862642636038394766871668","best_bid":"0.05","best_ask":"0.06","spread":"0.01","timestamp":"1768250245111","event_type":"best_bid_ask"}}
{"schema_version":1,"source":"clob_ws_market","recv_ts_ns":1768250245445636598,"event_type":"price_change","market":"0xe51aa24ab1bbfefce466d642ad98587d13123e4ef95ec9aa73b712e775d4cbba","server_ts_ms":1768250245110,"raw":{"market":"0xe51aa24ab1bbfefce466d642ad98587d13123e4ef95ec9aa73b712e775d4cbba","price_changes":[{"asset_id":"54232589582260339592359130012520874109228367674780084862642636038394766871668","price":"0.05","size":"1525.34","side":"BUY","hash":"85a2fb185ae7cfd857eec14dff0544b0208a2756","best_bid":"0.05","best_ask":"0.06"},{"asset_id":"96886111393998001968863279421729456597655847484197549086072988901191634450924","price":"0.95","size":"1525.34","side":"SELL","hash":"6f0a8a5e89128dd55e703c67ef14891fd0a066bf","best_bid":"0.94","best_ask":"0.95"}],"timestamp":"1768250245110","event_type":"price_change"}}
{"schema_version":1,"source":"clob_ws_market","recv_ts_ns":1768250245451739152,"event_type":"book","market":"0xe51aa24ab1bbfefce466d642ad98587d13123e4ef95ec9aa73b712e775d4cbba","server_ts_ms":1768250245110,"raw":{"market":"0xe51aa24ab1bbfefce466d642ad98587d13123e4ef95ec9aa73b712e775d4cbba","asset_id":"54232589582260339592359130012520874109228367674780084862642636038394766871668","bids":[{"price":"0.01","size":"21009.9"},{"price":"0.02","size":"6847.25"},{"price":"0.03","size":"2812.33"},{"price":"0.04","size":"292.4"},{"price":"0.05","size":"1525.34"}],"asks":[{"price":"0.99","size":"24290.24"},{"price":"0.98","size":"7594.51"},{"price":"0.97","size":"5964.69"},{"price":"0.96","size":"5411.4"},{"price":"0.95","size":"5356.39"},{"price":"0.94","size":"5328"},{"price":"0.93","size":"5039.28"},{"price":"0.92","size":"5022.7"},{"price":"0.91","size":"5320.9"},{"price":"0.9","size":"5158.44"},{"price":"0.89","size":"18.3"},{"price":"0.88","size":"30.3"},{"price":"0.87","size":"16.5"},{"price":"0.86","size":"15.8"},{"price":"0.85","size":"104.19"},{"price":"0.84","size":"24.69"},{"price":"0.83","size":"14.19"},{"price":"0.82","size":"13.8"},{"price":"0.81","size":"13.4"},{"price":"0.8","size":"38.1"},{"price":"0.79","size":"12.8"},{"price":"0.78","size":"12.6"},{"price":"0.77","size":"12.3"},{"price":"0.76","size":"22.1"},{"price":"0.75","size":"16.9"},{"price":"0.74","size":"21.8"},{"price":"0.73","size":"11.6"},{"price":"0.72","size":"11.4"},{"price":"0.71","size":"61.3"},{"price":"0.7","size":"26.2"},{"price":"0.69","size":"11.1"},{"price":"0.68","size":"11"},{"price":"0.67","size":"110.9"},{"price":"0.66","size":"10.8"},{"price":"0.65","size":"15.7"},{"price":"0.64","size":"10.6"},{"price":"0.63","size":"10.6"},{"price":"0.62","size":"22.5"},{"price":"0.61","size":"10.5"},{"price":"0.6","size":"45.4"},{"price":"0.59","size":"311.4"},{"price":"0.58","size":"820.82"},{"price":"0.57","size":"826.3"},{"price":"0.56","size":"1062.3"},{"price":"0.55","size":"582.3"},{"price":"0.54","size":"626.2"},{"price":"0.53","size":"562.2"},{"price":"0.52","size":"567.2"},{"price":"0.51","size":"573.2"},{"price":"0.5","size":"917.2"},{"price":"0.49","size":"591.2"},{"price":"0.48","size":"590.2"},{"price":"0.47","size":"567.2"},{"price":"0.46","size":"636.61"},{"price":"0.45","size":"362.97"},{"price":"0.44","size":"341.3"},{"price":"0.43","size":"320.62"},{"price":"0.42","size":"567.3"},{"price":"0.41","size":"562.4"},{"price":"0.4","size":"693.02"},{"price":"0.39","size":"625.5"},{"price":"0.38","size":"700.5"},{"price":"0.37","size":"672.32"},{"price":"0.36","size":"680.6"},{"price":"0.35","size":"536.14"},{"price":"0.34","size":"602.8"},{"price":"0.33","size":"572.9"},{"price":"0.32","size":"573"},{"price":"0.31","size":"595.1"},{"price":"0.3","size":"603.2"},{"price":"0.29","size":"1318.72"},{"price":"0.28","size":"1043.04"},{"price":"0.27","size":"663.6"},{"price":"0.26","size":"911.17"},{"price":"0.25","size":"694.3"},{"price":"0.24","size":"717.6"},{"price":"0.23","size":"1183.3"},{"price":"0.22","size":"1526.53"},{"price":"0.21","size":"1178.8"},{"price":"0.2","size":"1445.08"},{"price":"0.19","size":"1229.8"},{"price":"0.18","size":"1467.57"},{"price":"0.17","size":"1470.51"},{"price":"0.16","size":"1718.59"},{"price":"0.15","size":"1762.5"},{"price":"0.14","size":"1755.6"},{"price":"0.13","size":"1588.93"},{"price":"0.12","size":"2555.4"},{"price":"0.11","size":"1898.8"},{"price":"0.1","size":"3455.34"},{"price":"0.09","size":"2701.44"},{"price":"0.08","size":"2317.36"},{"price":"0.07","size":"1510.82"},{"price":"0.06","size":"1585.55"}],"hash":"85a2fb185ae7cfd857eec14dff0544b0208a2756","timestamp":"1768250245110","event_type":"book"}}
{"schema_version":1,"source":"clob_ws_market","recv_ts_ns":1768250245459262991,"event_type":"price_change","market":"0xe51aa24ab1bbfefce466d642ad98587d13123e4ef95ec9aa73b712e775d4cbba","server_ts_ms":1768250245112,"raw":{"market":"0xe51aa24ab1bbfefce466d642ad98587d13123e4ef95ec9aa73b712e775d4cbba","price_changes":[{"asset_id":"96886111393998001968863279421729456597655847484197549086072988901191634450924","price":"0.93","size":"1494.82","side":"BUY","hash":"1af0a852dd6ff17e1cee23d64b82dc186ccd5ee4","best_bid":"0.94","best_ask":"0.95"},{"asset_id":"54232589582260339592359130012520874109228367674780084862642636038394766871668","price":"0.07","size":"1494.82","side":"SELL","hash":"b605e48ecfee49e3a1f2ede48bca4ae8fe755cc6","best_bid":"0.05","best_ask":"0.06"}],"timestamp":"1768250245112","event_type":"price_change"}}
{"schema_version":1,"source":"clob_ws_market","recv_ts_ns":1768250245462882856,"event_type":"price_change","market":"0xe51aa24ab1bbfefce466d642ad98587d13123e4ef95ec9aa73b712e775d4cbba","server_ts_ms":1768250245113,"raw":{"market":"0xe51aa24ab1bbfefce466d642ad98587d13123e4ef95ec9aa73b712e775d4cbba","price_changes":[{"asset_id":"54232589582260339592359130012520874109228367674780084862642636038394766871668","price":"0.03","size":"2828.33","side":"BUY","hash":"7fa2d44f224bd744271e36880f49232b52911308","best_bid":"0.05","best_ask":"0.06"},{"asset_id":"96886111393998001968863279421729456597655847484197549086072988901191634450924","price":"0.97","size":"2828.33","side":"SELL","hash":"d87681d0b2ccfb869e7c8397e2ee3337e175279b","best_bid":"0.94","best_ask":"0.95"}],"timestamp":"1768250245113","event_type":"price_change"}}
{"schema_version":1,"source":"clob_ws_market","recv_ts_ns":1768250245466538459,"event_type":"price_change","market":"0xe51aa24ab1bbfefce466d642ad98587d13123e4ef95ec9aa73b712e775d4cbba","server_ts_ms":1768250245128,"raw":{"market":"0xe51aa24ab1bbfefce466d642ad98587d13123e4ef95ec9aa73b712e775d4cbba","price_changes":[{"asset_id":"54232589582260339592359130012520874109228367674780084862642636038394766871668","price":"0.03","size":"2844.33","side":"BUY","hash":"f9fbc049c8c6fd66077f91e7d821036662a747a7","best_bid":"0.05","best_ask":"0.06"},{"asset_id":"96886111393998001968863279421729456597655847484197549086072988901191634450924","price":"0.97","size":"2844.33","side":"SELL","hash":"55bfccb1f5397b8cfe9673cd1cb1a9d4f523bd91","best_bid":"0.94","best_ask":"0.95"}],"timestamp":"1768250245128","event_type":"price_change"}}
{"schema_version":1,"source":"clob_ws_market","recv_ts_ns":1768250245469356637,"event_type":"price_change","market":"0xe51aa24ab1bbfefce466d642ad98587d13123e4ef95ec9aa73b712e775d4cbba","server_ts_ms":1768250245130,"raw":{"market":"0xe51aa24ab1bbfefce466d642ad98587d13123e4ef95ec9aa73b712e775d4cbba","price_changes":[{"asset_id":"54232589582260339592359130012520874109228367674780084862642636038394766871668","price":"0.06","size":"1572.55","side":"SELL","hash":"7d52d31c4c38331f49e30eaffe7b17c2c49d40dd","best_bid":"0.05","best_ask":"0.06"},{"asset_id":"96886111393998001968863279421729456597655847484197549086072988901191634450924","price":"0.94","size":"1572.55","side":"BUY","hash":"0077fe0a3537eac6ec429b45c199aab9dd8bfdca","best_bid":"0.94","best_ask":"0.95"}],"timestamp":"1768250245130","event_type":"price_change"}}
{"schema_version":1,"source":"clob_ws_market","recv_ts_ns":1768250245478117195,"event_type":"price_change","market":"0xe51aa24ab1bbfefce466d642ad98587d13123e4ef95ec9aa73b712e775d4cbba","server_ts_ms":1768250245147,"raw":{"market":"0xe51aa24ab1bbfefce466d642ad98587d13123e4ef95ec9aa73b712e775d4cbba","price_changes":[{"asset_id":"96886111393998001968863279421729456597655847484197549086072988901191634450924","price":"0.93","size":"1510.82","side":"BUY","hash":"ddefc4299e87233462f2b2f6006f3246e04cccdb","best_bid":"0.94","best_ask":"0.95"},{"asset_id":"54232589582260339592359130012520874109228367674780084862642636038394766871668","price":"0.07","size":"1510.82","side":"SELL","hash":"954abe706a719b5f1def31f4f00bec15d7304189","best_bid":"0.05","best_ask":"0.06"}],"timestamp":"1768250245147","event_type":"price_change"}}
{"schema_version":1,"source":"clob_ws_market","recv_ts_ns":1768250245489614764,"event_type":"price_change","market":"0xe51aa24ab1bbfefce466d642ad98587d13123e4ef95ec9aa73b712e775d4cbba","server_ts_ms":1768250245155,"raw":{"market":"0xe51aa24ab1bbfefce466d642ad98587d13123e4ef95ec9aa73b712e775d4cbba","price_changes":[{"asset_id":"96886111393998001968863279421729456597655847484197549086072988901191634450924","price":"0.93","size":"1526.82","side":"BUY","hash":"095b2333effcc493df6a2ba39340232d86ed2961","best_bid":"0.94","best_ask":"0.95"},{"asset_id":"54232589582260339592359130012520874109228367674780084862642636038394766871668","price":"0.07","size":"1526.82","side":"SELL","hash":"255ba74f8b1f25545b445f61be425b37d7bf73b1","best_bid":"0.05","best_ask":"0.06"}],"timestamp":"1768250245155","event_type":"price_change"}}
{"schema_version":1,"source":"clob_ws_market","recv_ts_ns":1768250245558003549,"event_type":"price_change","market":"0xe51aa24ab1bbfefce466d642ad98587d13123e4ef95ec9aa73b712e775d4cbba","server_ts_ms":1768250245256,"raw":{"market":"0xe51aa24ab1bbfefce466d642ad98587d13123e4ef95ec9aa73b712e775d4cbba","price_changes":[{"asset_id":"96886111393998001968863279421729456597655847484197549086072988901191634450924","price":"0.94","size":"1588.55","side":"BUY","hash":"1f03b62372778929a4bc097e46dfc9287447c1a8","best_bid":"0.94","best_ask":"0.95"},{"asset_id":"54232589582260339592359130012520874109228367674780084862642636038394766871668","price":"0.06","size":"1588.55","side":"SELL","hash":"58c4ef27793c04f7aebea538318b5c51b7c2a8ad","best_bid":"0.05","best_ask":"0.06"}],"timestamp":"1768250245256","event_type":"price_change"}}
{"schema_version":1,"source":"clob_ws_market","recv_ts_ns":1768250245585710417,"event_type":"price_change","market":"0xe51aa24ab1bbfefce466d642ad98587d13123e4ef95ec9aa73b712e775d4cbba","server_ts_ms":1768250245301,"raw":{"market":"0xe51aa24ab1bbfefce466d642ad98587d13123e4ef95ec9aa73b712e775d4cbba","price_changes":[{"asset_id":"54232589582260339592359130012520874109228367674780084862642636038394766871668","price":"0.02","size":"6819.25","side":"BUY","hash":"78f0536e4c5a10c006110fa5ed10bc25b398097a","best_bid":"0.05","best_ask":"0.06"},{"asset_id":"96886111393998001968863279421729456597655847484197549086072988901191634450924","price":"0.98","size":"6819.25","side":"SELL","hash":"0a60d70758c7f07ec964fdbab07da1c8e46be64f","best_bid":"0.94","best_ask":"0.95"}],"timestamp":"1768250245301","event_type":"price_change"}}
{"schema_version":1,"source":"clob_ws_market","recv_ts_ns":1768250245608882277,"event_type":"price_change","market":"0xe51aa24ab1bbfefce466d642ad98587d13123e4ef95ec9aa73b712e775d4cbba","server_ts_ms":1768250245358,"raw":{"market":"0xe51aa24ab1bbfefce466d642ad98587d13123e4ef95ec9aa73b712e775d4cbba","price_changes":[{"asset_id":"54232589582260339592359130012520874109228367674780084862642636038394766871668","price":"0.02","size":"6847.25","side":"BUY","hash":"5ed2b95817f68abd6dc75e1ea6a7d6c0a19500ae","best_bid":"0.05","best_ask":"0.06"},{"asset_id":"96886111393998001968863279421729456597655847484197549086072988901191634450924","price":"0.98","size":"6847.25","side":"SELL","hash":"36019259cd8a59de5848a4178809ce9d0e2c3293","best_bid":"0.94","best_ask":"0.95"}],"timestamp":"1768250245358","event_type":"price_change"}}
{"schema_version":1,"source":"clob_ws_market","recv_ts_ns":1768250245614862583,"event_type":"price_change","market":"0xe51aa24ab1bbfefce466d642ad98587d13123e4ef95ec9aa73b712e775d4cbba","server_ts_ms":1768250245361,"raw":{"market":"0xe51aa24ab1bbfefce466d642ad98587d13123e4ef95ec9aa73b712e775d4cbba","price_changes":[{"asset_id":"96886111393998001968863279421729456597655847484197549086072988901191634450924","price":"0.54","size":"642.61","side":"BUY","hash":"6ecfb0b4002d3ae8ef5840fa73ee432edb9c69b8","best_bid":"0.94","best_ask":"0.95"},{"asset_id":"54232589582260339592359130012520874109228367674780084862642636038394766871668","price":"0.46","size":"642.61","side":"SELL","hash":"db6adcc669c340fb80992e6904b29bf74fb42c6b","best_bid":"0.05","best_ask":"0.06"}],"timestamp":"1768250245361","event_type":"price_change"}}
{"schema_version":1,"source":"clob_ws_market","recv_ts_ns":1768250245649294288,"event_type":"price_change","market":"0xe51aa24ab1bbfefce466d642ad98587d13123e4ef95ec9aa73b712e775d4cbba","server_ts_ms":1768250245407,"raw":{"market":"0xe51aa24ab1bbfefce466d642ad98587d13123e4ef95ec9aa73b712e775d4cbba","price_changes":[{"asset_id":"54232589582260339592359130012520874109228367674780084862642636038394766871668","price":"0.03","size":"1844.33","side":"BUY","hash":"22b48d50d948821fcab2e830bebe89682dc4fe77","best_bid":"0.05","best_ask":"0.06"},{"asset_id":"96886111393998001968863279421729456597655847484197549086072988901191634450924","price":"0.97","size":"1844.33","side":"SELL","hash":"149484b5803b99d94368980c87e1ad61c792e86b","best_bid":"0.94","best_ask":"0.95"}],"timestamp":"1768250245407","event_type":"price_change"}}
{"schema_version":1,"source":"clob_ws_market","recv_ts_ns":1768250245669964968,"event_type":"price_change","market":"0xe51aa24ab1bbfefce466d642ad98587d13123e4ef95ec9aa73b712e775d4cbba","server_ts_ms":1768250245524,"raw":{"market":"0xe51aa24ab1bbfefce466d642ad98587d13123e4ef95ec9aa73b712e775d4cbba","price_changes":[{"asset_id":"54232589582260339592359130012520874109228367674780084862642636038394766871668","price":"0.02","size":"6819.25","side":"BUY","hash":"e59b8117e499c5543cfae6f78fabe525390d86cb","best_bid":"0.05","best_ask":"0.06"},{"asset_id":"96886111393998001968863279421729456597655847484197549086072988901191634450924","price":"0.98","size":"6819.25","side":"SELL","hash":"9b3438a538ba251e9085bed9b9e77b51ada887b7","best_bid":"0.94","best_ask":"0.95"}],"timestamp":"1768250245524","event_type":"price_change"}}
{"schema_version":1,"source":"clob_ws_market","recv_ts_ns":1768250245689286164,"event_type":"price_change","market":"0xe51aa24ab1bbfefce466d642ad98587d13123e4ef95ec9aa73b712e775d4cbba","server_ts_ms":1768250245565,"raw":{"market":"0xe51aa24ab1bbfefce466d642ad98587d13123e4ef95ec9aa73b712e775d4cbba","price_changes":[{"asset_id":"54232589582260339592359130012520874109228367674780084862642636038394766871668","price":"0.02","size":"6847.25","side":"BUY","hash":"751e83cc404923d6ca2a1a83f67ab5349dd0d7be","best_bid":"0.05","best_ask":"0.06"},{"asset_id":"96886111393998001968863279421729456597655847484197549086072988901191634450924","price":"0.98","size":"6847.25","side":"SELL","hash":"91eb6cadf10cbb11c734819ae54ce5cf768d73e3","best_bid":"0.94","best_ask":"0.95"}],"timestamp":"1768250245565","event_type":"price_change"}}
{"schema_version":1,"source":"clob_ws_market","recv_ts_ns":1768250245693078778,"event_type":"best_bid_ask","market":"0xe51aa24ab1bbfefce466d642ad98587d13123e4ef95ec9aa73b712e775d4cbba","server_ts_ms":1768250245587,"raw":{"market":"0xe51aa24ab1bbfefce466d642ad98587d13123e4ef95ec9aa73b712e775d4cbba","asset_id":"54232589582260339592359130012520874109228367674780084862642636038394766871668","best_bid":"0.05","best_ask":"0.06","spread":"0.01","timestamp":"1768250245587","event_type":"best_bid_ask"}}
{"schema_version":1,"source":"clob_ws_market","recv_ts_ns":1768250245697980964,"event_type":"price_change","market":"0xe51aa24ab1bbfefce466d642ad98587d13123e4ef95ec9aa73b712e775d4cbba","server_ts_ms":1768250245585,"raw":{"market":"0xe51aa24ab1bbfefce466d642ad98587d13123e4ef95ec9aa73b712e775d4cbba","price_changes":[{"asset_id":"54232589582260339592359130012520874109228367674780084862642636038394766871668","price":"0.05","size":"1499.79","side":"BUY","hash":"df79b9306eb841c47f444e82a9b4d73af6338ff7","best_bid":"0.05","best_ask":"0.06"},{"asset_id":"96886111393998001968863279421729456597655847484197549086072988901191634450924","price":"0.95","size":"1499.79","side":"SELL","hash":"f39e92ff1a8db5306d732f0351d3133bc8d70103","best_bid":"0.94","best_ask":"0.95"}],"timestamp":"1768250245585","event_type":"price_change"}}
