{"schema_version":1,"source":"clob_ws_market","recv_ts_ns":1768250236212098409,"event_type":"price_change","market":"0xe51aa24ab1bbfefce466d642ad98587d13123e4ef95ec9aa73b712e775d4cbba","server_ts_ms":1768250236164,"raw":{"market":"0xe51aa24ab1bbfefce466d642ad98587d13123e4ef95ec9aa73b712e775d4cbba","price_changes":[{"asset_id":"54232589582260339592359130012520874109228367674780084862642636038394766871668","price":"0.04","size":"425.9","side":"BUY","hash":"6fe6ed50b5071b49c9807f862eed7d11a1364130","best_bid":"0.05","best_ask":"0.06"},{"asset_id":"96886111393998001968863279421729456597655847484197549086072988901191634450924","price":"0.96","size":"425.9","side":"SELL","hash":"7a7b6a142ac307a0181c3ec669b8e93a688df16d","best_bid":"0.94","best_ask":"0.95"}],"timestamp":"1768250236164","event_type":"price_change"}}
{"schema_version":1,"source":"clob_ws_market","recv_ts_ns":1768250236229552110,"event_type":"price_change","market":"0xe51aa24ab1bbfefce466d642ad98587d13123e4ef95ec9aa73b712e775d4cbba","server_ts_ms":1768250236174,"raw":{"market":"0xe51aa24ab1bbfefce466d642ad98587d13123e4ef95ec9aa73b712e775d4cbba","price_changes":[{"asset_id":"96886111393998001968863279421729456597655847484197549086072988901191634450924","price":"0.95","size":"1647.07","side":"SELL","hash":"4bf46b0081d02aa299131f11620237a2b06a9bba","best_bid":"0.94","best_ask":"0.95"},{"asset_id":"54232589582260339592359130012520874109228367674780084862642636038394766871668","price":"0.05","size":"1647.07","side":"BUY","hash":"3ed9c3f7c4d2d6af42c61b368f894f23b4092c3b","best_bid":"0.05","best_ask":"0.06"}],"timestamp":"1768250236174","event_type":"price_change"}}
{"schema_version":1,"source":"clob_ws_market","recv_ts_ns":1768250236244384142,"event_type":"price_change","market":"0xe51aa24ab1bbfefce466d642ad98587d13123e4ef95ec9aa73b712e775d4cbba","server_ts_ms":1768250236175,"raw":{"market":"0xe51aa24ab1bbfefce466d642ad98587d13123e4ef95ec9aa73b712e775d4cbba","price_changes":[{"asset_id":"54232589582260339592359130012520874109228367674780084862642636038394766871668","price":"0.04","size":"401.9","side":"BUY","hash":"205eac9e99d1dbc7bb6ecd88d7110d4fdf6f5a9f","best_bid":"0.05","best_ask":"0.06"},{"asset_id":"96886111393998001968863279421729456597655847484197549086072988901191634450924","price":"0.96","size":"401.9","side":"SELL","hash":"1ec88e207cf3efec89afc71783ac30cdb4ffb5f5","best_bid":"0.94","best_ask":"0.95"}],"timestamp":"1768250236175","event_type":"price_change"}}
{"schema_version":1,"source":"clob_ws_market","recv_ts_ns":1768250236249777239,"event_type":"price_change","market":"0xe51aa24ab1bbfefce466d642ad98587d13123e4ef95ec9aa73b712e775d4cbba","server_ts_ms":1768250236175,"raw":{"market":"0xe51aa24ab1bbfefce466d642ad98587d13123e4ef95ec9aa73b712e775d4cbba","price_changes":[{"asset_id":"96886111393998001968863279421729456597655847484197549086072988901191634450924","price":"0.96","size":"389.9","side":"SELL","hash":"c882bd8313e75282c0dbb6d7e1dc9c0d90350706","best_bid":"0.94","best_ask":"0.95"},{"asset_id":"54232589582260339592359130012520874109228367674780084862642636038394766871668","price":"0.04","size":"389.9","side":"BUY","hash":"1e92c60ff4607d228d6e6aa725e4a7fbb871f017","best_bid":"0.05","best_ask":"0.06"}],"timestamp":"1768250236175","event_type":"price_change"}}
{"schema_version":1,"source":"clob_ws_market","recv_ts_ns":1768250236256672984,"event_type":"price_change","market":"0xe51aa24ab1bbfefce466d642ad98587d13123e4ef95ec9aa73b712e775d4cbba","server_ts_ms":1768250236176,"raw":{"market":"0xe51aa24ab1bbfefce466d642ad98587d13123e4ef95ec9aa73b712e775d4cbba","price_changes":[{"asset_id":"54232589582260339592359130012520874109228367674780084862642636038394766871668","price":"0.04","size":"373.9","side":"BUY","hash":"d5c1b20ca5f6cae68a45b3000f4594acea6bc0c7","best_bid":"0.05","best_ask":"0.06"},{"asset_id":"96886111393998001968863279421729456597655847484197549086072988901191634450924","price":"0.96","size":"373.9","side":"SELL","hash":"26c521336fe37e8e03448a8ee19aa839f2842582","best_bid":"0.94","best_ask":"0.95"}],"timestamp":"1768250236176","event_type":"price_change"}}
{"schema_version":1,"source":"clob_ws_market","recv_ts_ns":1768250236263989007,"event_type":"price_change","market":"0xe51aa24ab1bbfefce466d642ad98587d13123e4ef95ec9aa73b712e775d4cbba","server_ts_ms":1768250236177,"raw":{"market":"0xe51aa24ab1bbfefce466d642ad98587d13123e4ef95ec9aa73b712e775d4cbba","price_changes":[{"asset_id":"96886111393998001968863279421729456597655847484197549086072988901191634450924","price":"0.93","size":"1604.82","side":"BUY","hash":"0e04c31353c58869aa3e0834c4025ada5138f028","best_bid":"0.94","best_ask":"0.95"},{"asset_id":"54232589582260339592359130012520874109228367674780084862642636038394766871668","price":"0.07","size":"1604.82","side":"SELL","hash":"4f39560ea45c1b9eb571bdb0dadaa677ab2b974e","best_bid":"0.05","best_ask":"0.06"}],"timestamp":"1768250236177","event_type":"price_change"}}
{"schema_version":1,"source":"clob_ws_market","recv_ts_ns":1768250236266438197,"event_type":"price_change","market":"0xe51aa24ab1bbfefce466d642ad98587d13123e4ef95ec9aa73b712e775d4cbba","server_ts_ms":1768250236179,"raw":{"market":"0xe51aa24ab1bbfefce466d642ad98587d13123e4ef95ec9aa73b712e775d4cbba","price_changes":[{"asset_id":"54232589582260339592359130012520874109228367674780084862642636038394766871668","price":"0.05","size":"1632.07","side":"BUY","hash":"6e20b70291ec21bfbd181201a75522fa39e62a13","best_bid":"0.05","best_ask":"0.06"},{"asset_id":"96886111393998001968863279421729456597655847484197549086072988901191634450924","price":"0.95","size":"1632.07","side":"SELL","hash":"10e7a638c5bc70c4f03775619313ac6da175eb7e","best_bid":"0.94","best_ask":"0.95"}],"timestamp":"1768250236179","event_type":"price_change"}}
{"schema_version":1,"source":"clob_ws_market","recv_ts_ns":1768250236268413001,"event_type":"price_change","market":"0xe51aa24ab1bbfefce466d642ad98587d13123e4ef95ec9aa73b712e775d4cbba","server_ts_ms":1768250236179,"raw":{"market":"0xe51aa24ab1bbfefce466d642ad98587d13123e4ef95ec9aa73b712e775d4cbba","price_changes":[{"asset_id":"96886111393998001968863279421729456597655847484197549086072988901191634450924","price":"0.01","size":"24280.24","side":"BUY","hash":"0734530ed2cbd11849d910b33fda3e742945e4a1","best_bid":"0.94","best_ask":"0.95"},{"asset_id":"54232589582260339592359130012520874109228367674780084862642636038394766871668","price":"0.99","size":"24280.24","side":"SELL","hash":"3c18a084b21d6b1f0fd454600522ae839d2561dd","best_bid":"0.05","best_ask":"0.06"}],"timestamp":"1768250236179","event_type":"price_change"}}
{"schema_version":1,"source":"clob_ws_market","recv_ts_ns":1768250236270110651,"event_type":"price_change","market":"0xe51aa24ab1bbfefce466d642ad98587d13123e4ef95ec9aa73b712e775d4cbba","server_ts_ms":1768250236180,"raw":{"market":"0xe51aa24ab1bbfefce466d642ad98587d13123e4ef95ec9aa73b712e775d4cbba","price_changes":[{"asset_id":"54232589582260339592359130012520874109228367674780084862642636038394766871668","price":"0.04","size":"357.9","side":"BUY","hash":"99626d1092c7c115d05ae59c997f41b30779ace4","best_bid":"0.05","best_ask":"0.06"},{"asset_id":"96886111393998001968863279421729456597655847484197549086072988901191634450924","price":"0.96","size":"357.9","side":"SELL","hash":"5793b24c60fb4b4c805ff65b16f948c335ce0d7a","best_bid":"0.94","best_ask":"0.95"}],"timestamp":"1768250236180","event_type":"price_change"}}
{"schema_version":1,"source":"clob_ws_market","recv_ts_ns":1768250236271958668,"event_type":"price_change","market":"0xe51aa24ab1bbfefce466d642ad98587d13123e4ef95ec9aa73b712e775d4cbba","server_ts_ms":1768250236180,"raw":{"market":"0xe51aa24ab1bbfefce466d642ad98587d13123e4ef95ec9aa73b712e775d4cbba","price_changes":[{"asset_id":"54232589582260339592359130012520874109228367674780084862642636038394766871668","price":"0.05","size":"1602.07","side":"BUY","hash":"4f62ae73f7fa195bfd6d76af1c1ffbd062879ab2","best_bid":"0.05","best_ask":"0.06"},{"asset_id":"96886111393998001968863279421729456597655847484197549086072988901191634450924","price":"0.95","size":"1602.07","side":"SELL","hash":"f8f7c0db0e33ea425c8f252cd7510bda0c3b23ad","best_bid":"0.94","best_ask":"0.95"}],"timestamp":"1768250236180","event_type":"price_change"}}
{"schema_version":1,"source":"clob_ws_market","recv_ts_ns":1768250236275988280,"event_type":"price_change","market":"0xe51aa24ab1bbfefce466d642ad98587d13123e4ef95ec9aa73b712e775d4cbba","server_ts_ms":1768250236182,"raw":{"market":"0xe51aa24ab1bbfefce466d642ad98587d13123e4ef95ec9aa73b712e775d4cbba","price_changes":[{"asset_id":"96886111393998001968863279421729456597655847484197549086072988901191634450924","price":"0.93","size":"1588.82","side":"BUY","hash":"617b024c1205651dacf24b422cc7da15c3467ff9","best_bid":"0.94","best_ask":"0.95"},{"asset_id":"54232589582260339592359130012520874109228367674780084862642636038394766871668","price":"0.07","size":"1588.82","side":"SELL","hash":"d606483b8136446da593c12f83f6f0bc00ab4623","best_bid":"0.05","best_ask":"0.06"}],"timestamp":"1768250236182","event_type":"price_change"}}
{"schema_version":1,"source":"clob_ws_market","recv_ts_ns":1768250236278306496,"event_type":"price_change","market":"0xe51aa24ab1bbfefce466d642ad98587d13123e4ef95ec9aa73b712e775d4cbba","server_ts_ms":1768250236184,"raw":{"market":"0xe51aa24ab1bbfefce466d642ad98587d13123e4ef95ec9aa73b712e775d4cbba","price_changes":[{"asset_id":"96886111393998001968863279421729456597655847484197549086072988901191634450924","price":"0.93","size":"1572.82","side":"BUY","hash":"3a4b53a8eb3519e968d41098d85bfe84549e27c7","best_bid":"0.94","best_ask":"0.95"},{"asset_id":"54232589582260339592359130012520874109228367674780084862642636038394766871668","price":"0.07","size":"1572.82","side":"SELL","hash":"d94fde296c7b81cbe3d48dbd55fa0222f2c52cc8","best_bid":"0.05","best_ask":"0.06"}],"timestamp":"1768250236184","event_type":"price_change"}}
{"schema_version":1,"source":"clob_ws_market","recv_ts_ns":1768250236280632664,"event_type":"price_change","market":"0xe51aa24ab1bbfefce466d642ad98587d13123e4ef95ec9aa73b712e775d4cbba","server_ts_ms":1768250236188,"raw":{"market":"0xe51aa24ab1bbfefce466d642ad98587d13123e4ef95ec9aa73b712e775d4cbba","price_changes":[{"asset_id":"54232589582260339592359130012520874109228367674780084862642636038394766871668","price":"0.02","size":"6845.25","side":"BUY","hash":"67cbee46a54a44d6f1081ad989a371e1b0682e96","best_bid":"0.05","best_ask":"0.06"},{"asset_id":"96886111393998001968863279421729456597655847484197549086072988901191634450924","price":"0.98","size":"6845.25","side":"SELL","hash":"990945511446435c2161eff015ea5780878872f5","best_bid":"0.94","best_ask":"0.95"}],"timestamp":"1768250236188","event_type":"price_change"}}
{"schema_version":1,"source":"clob_ws_market","recv_ts_ns":1768250236283147511,"event_type":"price_change","market":"0xe51aa24ab1bbfefce466d642ad98587d13123e4ef95ec9aa73b712e775d4cbba","server_ts_ms":1768250236189,"raw":{"market":"0xe51aa24ab1bbfefce466d642ad98587d13123e4ef95ec9aa73b712e775d4cbba","price_changes":[{"asset_id":"54232589582260339592359130012520874109228367674780084862642636038394766871668","price":"0.04","size":"341.9","side":"BUY","hash":"8a2fe5ad71c0f1447418856fe2f6cba0e7b214b1","best_bid":"0.05","best_ask":"0.06"},{"asset_id":"96886111393998001968863279421729456597655847484197549086072988901191634450924","price":"0.96","size":"341.9","side":"SELL","hash":"a2496a7427d74d524580f1d3f5da1dd24b9364d9","best_bid":"0.94","best_ask":"0.95"}],"timestamp":"1768250236189","event_type":"price_change"}}
{"schema_version":1,"source":"clob_ws_market","recv_ts_ns":1768250236285451349,"event_type":"price_change","market":"0xe51aa24ab1bbfefce466d642ad98587d13123e4ef95ec9aa73b712e775d4cbba","server_ts_ms":1768250236192,"raw":{"market":"0xe51aa24ab1bbfefce466d642ad98587d13123e4ef95ec9aa73b712e775d4cbba","price_changes":[{"asset_id":"96886111393998001968863279421729456597655847484197549086072988901191634450924","price":"0.94","size":"1068.88","side":"BUY","hash":"264bcf463508eaa4225339cb12761f222c645b11","best_bid":"0.94","best_ask":"0.95"},{"asset_id":"54232589582260339592359130012520874109228367674780084862642636038394766871668","price":"0.06","size":"1068.88","side":"SELL","hash":"597ee8b9f6c376a93462853e968b5d3680571cd2","best_bid":"0.05","best_ask":"0.06"}],"timestamp":"1768250236192","event_type":"price_change"}}
{"schema_version":1,"source":"clob_ws_market","recv_ts_ns":1768250236298022557,"event_type":"price_change","market":"0xe51aa24ab1bbfefce466d642ad98587d13123e4ef95ec9aa73b712e775d4cbba","server_ts_ms":1768250236197,"raw":{"market":"0xe51aa24ab1bbfefce466d642ad98587d13123e4ef95ec9aa73b712e775d4cbba","price_changes":[{"asset_id":"96886111393998001968863279421729456597655847484197549086072988901191634450924","price":"0.78","size":"1526.53","side":"BUY","hash":"8774afe02e7afbbce78730929efa01674691f532","best_bid":"0.94","best_ask":"0.95"},{"asset_id":"54232589582260339592359130012520874109228367674780084862642636038394766871668","price":"0.22","size":"1526.53","side":"SELL","hash":"6cf15d73c8d1d5a0044d07187556c5476763db0e","best_bid":"0.05","best_ask":"0.06"}],"timestamp":"1768250236197","event_type":"price_change"}}
{"schema_version":1,"source":"clob_ws_market","recv_ts_ns":1768250236303197284,"event_type":"price_change","market":"0xe51aa24ab1bbfefce466d642ad98587d13123e4ef95ec9aa73b712e775d4cbba","server_ts_ms":1768250236200,"raw":{"market":"0xe51aa24ab1bbfefce466d642ad98587d13123e4ef95ec9aa73b712e775d4cbba","price_changes":[{"asset_id":"96886111393998001968863279421729456597655847484197549086072988901191634450924","price":"0.77","size":"1183.3","side":"BUY","hash":"d641a9914764e85c7120f25b16c78142773aea65","best_bid":"0.94","best_ask":"0.95"},{"asset_id":"54232589582260339592359130012520874109228367674780084862642636038394766871668","price":"0.23","size":"1183.3","side":"SELL","hash":"fabd6e587c5b33f0e674c823508b96488824596a","best_bid":"0.05","best_ask":"0.06"}],"timestamp":"1768250236200","event_type":"price_change"}}
{"schema_version":1,"source":"clob_ws_market","recv_ts_ns":1768250236311304949,"event_type":"price_change","market":"0xe51aa24ab1bbfefce466d642ad98587d13123e4ef95ec9aa73b712e775d4cbba","server_ts_ms":1768250236201,"raw":{"market":"0xe51aa24ab1bbfefce466d642ad98587d13123e4ef95ec9aa73b712e775d4cbba","price_changes":[{"asset_id":"96886111393998001968863279421729456597655847484197549086072988901191634450924","price":"0.9","size":"3396.27","side":"BUY","hash":"5249f37ca2b79c0050bdea3812df7233c574aab7","best_bid":"0.94","best_ask":"0.95"},{"asset_id":"54232589582260339592359130012520874109228367674780084862642636038394766871668","price":"0.1","size":"3396.27","side":"SELL","hash":"5ca3ef8f23f259cae6ecc20f1bcac3600add4ddc","best_bid":"0.05","best_ask":"0.06"}],"timestamp":"1768250236201","event_type":"price_change"}}
{"schema_version":1,"source":"clob_ws_market","recv_ts_ns":1768250236321330834,"event_type":"price_change","market":"0xe51aa24ab1bbfefce466d642ad98587d13123e4ef95ec9aa73b712e775d4cbba","server_ts_ms":1768250236201,"raw":{"market":"0xe51aa24ab1bbfefce466d642ad98587d13123e4ef95ec9aa73b712e775d4cbba","price_changes":[{"asset_id":"96886111393998001968863279421729456597655847484197549086072988901191634450924","price":"0.99","size":"21003.91","side":"SELL","hash":"5249f37ca2b79c0050bdea3812df7233c574aab7","best_bid":"0.94","best_ask":"0.95"},{"asset_id":"54232589582260339592359130012520874109228367674780084862642636038394766871668","price":"0.01","size":"21003.91","side":"BUY","hash":"5ca3ef8f23f259cae6ecc20f1bcac3600add4ddc","best_bid":"0.05","best_ask":"0.06"}],"timestamp":"1768250236201","event_type":"price_change"}}
{"schema_version":1,"source":"clob_ws_market","recv_ts_ns":1768250236327507812,"event_type":"price_change","market":"0xe51aa24ab1bbfefce466d642ad98587d13123e4ef95ec9aa73b712e775d4cbba","server_ts_ms":1768250236210,"raw":{"market":"0xe51aa24ab1bbfefce466d642ad98587d13123e4ef95ec9aa73b712e775d4cbba","price_changes":[{"asset_id":"54232589582260339592359130012520874109228367674780084862642636038394766871668","price":"0.03","size":"2347.6","side":"BUY","hash":"46e96ddac6871d4a56b85b5495499a014eede6b9","best_bid":"0.05","best_ask":"0.06"},{"asset_id":"96886111393998001968863279421729456597655847484197549086072988901191634450924","price":"0.97","size":"2347.6","side":"SELL","hash":"ca65d21a9cb5d62555a6a08166501584d0f9fedd","best_bid":"0.94","best_ask":"0.95"}],"timestamp":"1768250236210","event_type":"price_change"}}
{"schema_version":1,"source":"clob_ws_market","recv_ts_ns":1768250236331991096,"event_type":"price_change","market":"0xe51aa24ab1bbfefce466d642ad98587d13123e4ef95ec9aa73b712e775d4cbba","server_ts_ms":1768250236212,"raw":{"market":"0xe51aa24ab1bbfefce466d642ad98587d13123e4ef95ec9aa73b712e775d4cbba","price_changes":[{"asset_id":"96886111393998001968863279421729456597655847484197549086072988901191634450924","price":"0.94","size":"1084.88","side":"BUY","hash":"a9492768afa4bf2c12a2541fc1b31b9029894d3d","best_bid":"0.94","best_ask":"0.95"},{"asset_id":"54232589582260339592359130012520874109228367674780084862642636038394766871668","price":"0.06","size":"1084.88","side":"SELL","hash":"d9c56526649fa9d19b47f8bcce416405d5682d3e","best_bid":"0.05","best_ask":"0.06"}],"timestamp":"1768250236212","event_type":"price_change"}}
{"schema_version":1,"source":"clob_ws_market","recv_ts_ns":1768250236336234076,"event_type":"price_change","market":"0xe51aa24ab1bbfefce466d642ad98587d13123e4ef95ec9aa73b712e775d4cbba","server_ts_ms":1768250236214,"raw":{"market":"0xe51aa24ab1bbfefce466d642ad98587d13123e4ef95ec9aa73b712e775d4cbba","price_changes":[{"asset_id":"96886111393998001968863279421729456597655847484197549086072988901191634450924","price":"0.94","size":"1100.88","side":"BUY","hash":"cdddcd485d0c2988ea4df209dd03b633588f3ec1","best_bid":"0.94","best_ask":"0.95"},{"asset_id":"54232589582260339592359130012520874109228367674780084862642636038394766871668","price":"0.06","size":"1100.88","side":"SELL","hash":"89c1dda366401258efdef09a45909f14f6a995b1","best_bid":"0.05","best_ask":"0.06"}],"timestamp":"1768250236214","event_type":"price_change"}}
{"schema_version":1,"source":"clob_ws_market","recv_ts_ns":1768250236340499535,"event_type":"price_change","market":"0xe51aa24ab1bbfefce466d642ad98587d13123e4ef95ec9aa73b712e775d4cbba","server_ts_ms":1768250236228,"raw":{"market":"0xe51aa24ab1bbfefce466d642ad98587d13123e4ef95ec9aa73b712e775d4cbba","price_changes":[{"asset_id":"96886111393998001968863279421729456597655847484197549086072988901191634450924","price":"0.94","size":"1116.88","side":"BUY","hash":"85329f853114a75413731b3c6be5c78defaabbe1","best_bid":"0.94","best_ask":"0.95"},{"asset_id":"54232589582260339592359130012520874109228367674780084862642636038394766871668","price":"0.06","size":"1116.88","side":"SELL","hash":"2062d0be829a13a86e34d7d947060f733a2557dc","best_bid":"0.05","best_ask":"0.06"}],"timestamp":"1768250236228","event_type":"price_change"}}
{"schema_version":1,"source":"clob_ws_market","recv_ts_ns":1768250236348666242,"event_type":"price_change","market":"0xe51aa24ab1bbfefce466d642ad98587d13123e4ef95ec9aa73b712e775d4cbba","server_ts_ms":1768250236233,"raw":{"market":"0xe51aa24ab1bbfefce466d642ad98587d13123e4ef95ec9aa73b712e775d4cbba","price_changes":[{"asset_id":"54232589582260339592359130012520874109228367674780084862642636038394766871668","price":"0.03","size":"2363.6","side":"BUY","hash":"7947b292abfdd488fe035c5e10de0a2d99a97d81","best_bid":"0.05","best_ask":"0.06"},{"asset_id":"96886111393998001968863279421729456597655847484197549086072988901191634450924","price":"0.97","size":"2363.6","side":"SELL","hash":"fbc59f29f7ca46c72fad9a8ce32e32d7b5e0836c","best_bid":"0.94","best_ask":"0.95"}],"timestamp":"1768250236233","event_type":"price_change"}}
{"schema_version":1,"source":"clob_ws_market","recv_ts_ns":1768250236353539402,"event_type":"price_change","market":"0xe51aa24ab1bbfefce466d642ad98587d13123e4ef95ec9aa73b712e775d4cbba","server_ts_ms":1768250236233,"raw":{"market":"0xe51aa24ab1bbfefce466d642ad98587d13123e4ef95ec9aa73b712e775d4cbba","price_changes":[{"asset_id":"54232589582260339592359130012520874109228367674780084862642636038394766871668","price":"0.01","size":"21019.91","side":"BUY","hash":"3cad1468f4c81cc29e1a05a0f5f53869c84e248e","best_bid":"0.05","best_ask":"0.06"},{"asset_id":"96886111393998001968863279421729456597655847484197549086072988901191634450924","price":"0.99","size":"21019.91","side":"SELL","hash":"2f215ff5f2d020c216ad97cd9472ba5ed8927131","best_bid":"0.94","best_ask":"0.95"}],"timestamp":"1768250236233","event_type":"price_change"}}
{"schema_version":1,"source":"clob_ws_market","recv_ts_ns":1768250236359006084,"event_type":"price_change","market":"0xe51aa24ab1bbfefce466d642ad98587d13123e4ef95ec9aa73b712e775d4cbba","server_ts_ms":1768250236237,"raw":{"market":"0xe51aa24ab1bbfefce466d642ad98587d13123e4ef95ec9aa73b712e775d4cbba","price_changes":[{"asset_id":"96886111393998001968863279421729456597655847484197549086072988901191634450924","price":"0.91","size":"3017.44","side":"BUY","hash":"d485b53d4c69a0e69cb4f87e924339ab5a64bdb4","best_bid":"0.94","best_ask":"0.95"},{"asset_id":"54232589582260339592359130012520874109228367674780084862642636038394766871668","price":"0.09","size":"3017.44","side":"SELL","hash":"325206b7ee0dc93e35eec71393ea326075e9e83a","best_bid":"0.05","best_ask":"0.06"}],"timestamp":"1768250236237","event_type":"price_change"}}
{"schema_version":1,"source":"clob_ws_market","recv_ts_ns":1768250236363648858,"event_type":"price_change","market":"0xe51aa24ab1bbfefce466d642ad98587d13123e4ef95ec9aa73b712e775d4cbba","server_ts_ms":1768250236239,"raw":{"market":"0xe51aa24ab1bbfefce466d642ad98587d13123e4ef95ec9aa73b712e775d4cbba","price_changes":[{"asset_id":"96886111393998001968863279421729456597655847484197549086072988901191634450924","price":"0.99","size":"21024.91","side":"SELL","hash":"c6562dce81cdb0afa3dc086e2ad9a7d617c5f263","best_bid":"0.94","best_ask":"0.95"},{"asset_id":"54232589582260339592359130012520874109228367674780084862642636038394766871668","price":"0.01","size":"21024.91","side":"BUY","hash":"edc029022682006fdc8b67483530f7659715519f","best_bid":"0.05","best_ask":"0.06"}],"timestamp":"1768250236239","event_type":"price_change"}}
{"schema_version":1,"source":"clob_ws_market","recv_ts_ns":1768250236368664267,"event_type":"price_change","market":"0xe51aa24ab1bbfefce466d642ad98587d13123e4ef95ec9aa73b712e775d4cbba","server_ts_ms":1768250236239,"raw":{"market":"0xe51aa24ab1bbfefce466d642ad98587d13123e4ef95ec9aa73b712e775d4cbba","price_changes":[{"asset_id":"54232589582260339592359130012520874109228367674780084862642636038394766871668","price":"0.03","size":"2379.6","side":"BUY","hash":"7e0fde285d7febd037cde4cf7277a9685424daaa","best_bid":"0.05","best_ask":"0.06"},{"asset_id":"96886111393998001968863279421729456597655847484197549086072988901191634450924","price":"0.97","size":"2379.6","side":"SELL","hash":"83533b8592b0c10b6adcfe9eb9613b5c60cf3592","best_bid":"0.94","best_ask":"0.95"}],"timestamp":"1768250236239","event_type":"price_change"}}
{"schema_version":1,"source":"clob_ws_market","recv_ts_ns":1768250236373797171,"event_type":"price_change","market":"0xe51aa24ab1bbfefce466d642ad98587d13123e4ef95ec9aa73b712e775d4cbba","server_ts_ms":1768250236240,"raw":{"market":"0xe51aa24ab1bbfefce466d642ad98587d13123e4ef95ec9aa73b712e775d4cbba","price_changes":[{"asset_id":"96886111393998001968863279421729456597655847484197549086072988901191634450924","price":"0.92","size":"2448.36","side":"BUY","hash":"48bbded9baf9a897905f2891d6eb5fe56ff37b0b","best_bid":"0.94","best_ask":"0.95"},{"asset_id":"54232589582260339592359130012520874109228367674780084862642636038394766871668","price":"0.08","size":"2448.36","side":"SELL","hash":"c7d874f69bdb0d2e39bf0be04f16222af736e058","best_bid":"0.05","best_ask":"0.06"}],"timestamp":"1768250236240","event_type":"price_change"}}
{"schema_version":1,"source":"clob_ws_market","recv_ts_ns":1768250236379145701,"event_type":"price_change","market":"0xe51aa24ab1bbfefce466d642ad98587d13123e4ef95ec9aa73b712e775d4cbba","server_ts_ms":1768250236241,"raw":{"market":"0xe51aa24ab1bbfefce466d642ad98587d13123e4ef95ec9aa73b712e775d4cbba","price_changes":[{"asset_id":"54232589582260339592359130012520874109228367674780084862642636038394766871668","price":"0.07","size":"1547.82","side":"SELL","hash":"72eed0fc5f4e6440f38a06e1d7c7cf1a86188dc7","best_bid":"0.05","best_ask":"0.06"},{"asset_id":"96886111393998001968863279421729456597655847484197549086072988901191634450924","price":"0.93","size":"1547.82","side":"BUY","hash":"0adc5b97b1970ff967c629c31d138fea6b2dcede","best_bid":"0.94","best_ask":"0.95"}],"timestamp":"1768250236241","event_type":"price_change"}}
{"schema_version":1,"source":"clob_ws_market","recv_ts_ns":1768250236386302801,"event_type":"price_change","market":"0xe51aa24ab1bbfefce466d642ad98587d13123e4ef95ec9aa73b712e775d4cbba","server_ts_ms":1768250236242,"raw":{"market":"0xe51aa24ab1bbfefce466d642ad98587d13123e4ef95ec9aa73b712e775d4cbba","price_changes":[{"asset_id":"54232589582260339592359130012520874109228367674780084862642636038394766871668","price":"0.08","size":"2423.36","side":"SELL","hash":"c7f44b17a8de4c10ab26bcce4667301ec52b1b2a","best_bid":"0.05","best_ask":"0.06"},{"asset_id":"96886111393998001968863279421729456597655847484197549086072988901191634450924","price":"0.92","size":"2423.36","side":"BUY","hash":"113a532baae1892988268b101a9e91b3b13f2463","best_bid":"0.94","best_ask":"0.95"}],"timestamp":"1768250236242","event_type":"price_change"}}
{"schema_version":1,"source":"clob_ws_market","recv_ts_ns":1768250236391408581,"event_type":"price_change","market":"0xe51aa24ab1bbfefce466d642ad98587d13123e4ef95ec9aa73b712e775d4cbba","server_ts_ms":1768250236244,"raw":{"market":"0xe51aa24ab1bbfefce466d642ad98587d13123e4ef95ec9aa73b712e775d4cbba","price_changes":[{"asset_id":"96886111393998001968863279421729456597655847484197549086072988901191634450924","price":"0.94","size":"1141.88","side":"BUY","hash":"7a135be859e700d6acb481fda250a9e0cd8b740c","best_bid":"0.94","best_ask":"0.95"},{"asset_id":"54232589582260339592359130012520874109228367674780084862642636038394766871668","price":"0.06","size":"1141.88","side":"SELL","hash":"4e1f08f3df28ca3d677a390afd7e3e8c1b939c41","best_bid":"0.05","best_ask":"0.06"}],"timestamp":"1768250236244","event_type":"price_change"}}
{"schema_version":1,"source":"clob_ws_market","recv_ts_ns":1768250236396479142,"event_type":"price_change","market":"0xe51aa24ab1bbfefce466d642ad98587d13123e4ef95ec9aa73b712e775d4cbba","server_ts_ms":1768250236245,"raw":{"market":"0xe51aa24ab1bbfefce466d642ad98587d13123e4ef95ec9aa73b712e775d4cbba","price_changes":[{"asset_id":"96886111393998001968863279421729456597655847484197549086072988901191634450924","price":"0.93","size":"1522.82","side":"BUY","hash":"5d1389ce73591303d9e5e4a9e83a57047116dfdd","best_bid":"0.94","best_ask":"0.95"},{"asset_id":"54232589582260339592359130012520874109228367674780084862642636038394766871668","price":"0.07","size":"1522.82","side":"SELL","hash":"9505a3b70de46dddf5839de65f61f671bfbcf5c4","best_bid":"0.05","best_ask":"0.06"}],"timestamp":"1768250236245","event_type":"price_change"}}
{"schema_version":1,"source":"clob_ws_market","recv_ts_ns":1768250236400465697,"event_type":"price_change","market":"0xe51aa24ab1bbfefce466d642ad98587d13123e4ef95ec9aa73b712e775d4cbba","server_ts_ms":1768250236246,"raw":{"market":"0xe51aa24ab1bbfefce466d642ad98587d13123e4ef95ec9aa73b712e775d4cbba","price_changes":[{"asset_id":"54232589582260339592359130012520874109228367674780084862642636038394766871668","price":"0.06","size":"1166.88","side":"SELL","hash":"5e7c47a519b31f0a6dc40118f92af3752cb5f7eb","best_bid":"0.05","best_ask":"0.06"},{"asset_id":"96886111393998001968863279421729456597655847484197549086072988901191634450924","price":"0.94","size":"1166.88","side":"BUY","hash":"e6c34b7b4853187280ea85fb8fce811a32609b48","best_bid":"0.94","best_ask":"0.95"}],"timestamp":"1768250236246","event_type":"price_change"}}
{"schema_version":1,"source":"clob_ws_market","recv_ts_ns":1768250236404017057,"event_type":"price_change","market":"0xe51aa24ab1bbfefce466d642ad98587d13123e4ef95ec9aa73b712e775d4cbba","server_ts_ms":1768250236248,"raw":{"market":"0xe51aa24ab1bbfefce466d642ad98587d13123e4ef95ec9aa73b712e775d4cbba","price_changes":[{"asset_id":"54232589582260339592359130012520874109228367674780084862642636038394766871668","price":"0.07","size":"1547.82","side":"SELL","hash":"a5c4ac84dd9a4f3f103860727eca84bced6e0da2","best_bid":"0.05","best_ask":"0.06"},{"asset_id":"96886111393998001968863279421729456597655847484197549086072988901191634450924","price":"0.93","size":"1547.82","side":"BUY","hash":"f82beb36afb365a06314969f4d55da66a5d63d45","best_bid":"0.94","best_ask":"0.95"}],"timestamp":"1768250236248","event_type":"price_change"}}
{"schema_version":1,"source":"clob_ws_market","recv_ts_ns":1768250236407923938,"event_type":"price_change","market":"0xe51aa24ab1bbfefce466d642ad98587d13123e4ef95ec9aa73b712e775d4cbba","server_ts_ms":1768250236249,"raw":{"market":"0xe51aa24ab1bbfefce466d642ad98587d13123e4ef95ec9aa73b712e775d4cbba","price_changes":[{"asset_id":"96886111393998001968863279421729456597655847484197549086072988901191634450924","price":"0.93","size":"1572.82","side":"BUY","hash":"94a78a709be11aa37a077bee70643f5f2a40048d","best_bid":"0.94","best_ask":"0.95"},{"asset_id":"54232589582260339592359130012520874109228367674780084862642636038394766871668","price":"0.07","size":"1572.82","side":"SELL","hash":"fbde8e1c3bff152d151408367def658cf9472985","best_bid":"0.05","best_ask":"0.06"}],"timestamp":"1768250236249","event_type":"price_change"}}
{"schema_version":1,"source":"clob_ws_market","recv_ts_ns":1768250236411425782,"event_type":"price_change","market":"0xe51aa24ab1bbfefce466d642ad98587d13123e4ef95ec9aa73b712e775d4cbba","server_ts_ms":1768250236263,"raw":{"market":"0xe51aa24ab1bbfefce466d642ad98587d13123e4ef95ec9aa73b712e775d4cbba","price_changes":[{"asset_id":"96886111393998001968863279421729456597655847484197549086072988901191634450924","price":"0.93","size":"1556.82","side":"BUY","hash":"75c5fa1bc51fdb61fd8372e0455d613cf5aea9bc","best_bid":"0.94","best_ask":"0.95"},{"asset_id":"54232589582260339592359130012520874109228367674780084862642636038394766871668","price":"0.07","size":"1556.82","side":"SELL","hash":"519212a1a0f7c8639d7faeff8ab22beee66d7e2a","best_bid":"0.05","best_ask":"0.06"}],"timestamp":"1768250236263","event_type":"price_change"}}
{"schema_version":1,"source":"clob_ws_market","recv_ts_ns":1768250236414215423,"event_type":"price_change","market":"0xe51aa24ab1bbfefce466d642ad98587d13123e4ef95ec9aa73b712e775d4cbba","server_ts_ms":1768250236270,"raw":{"market":"0xe51aa24ab1bbfefce466d642ad98587d13123e4ef95ec9aa73b712e775d4cbba","price_changes":[{"asset_id":"96886111393998001968863279421729456597655847484197549086072988901191634450924","price":"0.94","size":"1141.88","side":"BUY","hash":"d8b39a0c1e2f192b863d145186bfb52063fb890c","best_bid":"0.94","best_ask":"0.95"},{"asset_id":"54232589582260339592359130012520874109228367674780084862642636038394766871668","price":"0.06","size":"1141.88","side":"SELL","hash":"0a69c77bee017d067a3c3c99a28843de98551f96","best_bid":"0.05","best_ask":"0.06"}],"timestamp":"1768250236270","event_type":"price_change"}}
{"schema_version":1,"source":"clob_ws_market","recv_ts_ns":1768250236417855728,"event_type":"price_change","market":"0xe51aa24ab1bbfefce466d642ad98587d13123e4ef95ec9aa73b712e775d4cbba","server_ts_ms":1768250236273,"raw":{"market":"0xe51aa24ab1bbfefce466d642ad98587d13123e4ef95ec9aa73b712e775d4cbba","price_changes":[{"asset_id":"54232589582260339592359130012520874109228367674780084862642636038394766871668","price":"0.06","size":"1116.88","side":"SELL","hash":"b221ff62c7ce495c22e2e8edece49d40a8360681","best_bid":"0.05","best_ask":"0.06"},{"asset_id":"96886111393998001968863279421729456597655847484197549086072988901191634450924","price":"0.94","size":"1116.88","side":"BUY","hash":"f654ac059630e86288d7c9c10bc214c8808da4b0","best_bid":"0.94","best_ask":"0.95"}],"timestamp":"1768250236273","event_type":"price_change"}}
{"schema_version":1,"source":"clob_ws_market","recv_ts_ns":1768250236421466942,"event_type":"price_change","market":"0xe51aa24ab1bbfefce466d642ad98587d13123e4ef95ec9aa73b712e775d4cbba","server_ts_ms":1768250236275,"raw":{"market":"0xe51aa24ab1bbfefce466d642ad98587d13123e4ef95ec9aa73b712e775d4cbba","price_changes":[{"asset_id":"96886111393998001968863279421729456597655847484197549086072988901191634450924","price":"0.93","size":"1531.82","side":"BUY","hash":"4299eaa7d6f8ed40aea87041f82b34b633141ffb","best_bid":"0.94","best_ask":"0.95"},{"asset_id":"54232589582260339592359130012520874109228367674780084862642636038394766871668","price":"0.07","size":"1531.82","side":"SELL","hash":"e70ffd739c4d811046010c9088e1c90916457248","best_bid":"0.05","best_ask":"0.06"}],"timestamp":"1768250236275","event_type":"price_change"}}
{"schema_version":1,"source":"clob_ws_market","recv_ts_ns":1768250236424727491,"event_type":"price_change","market":"0xe51aa24ab1bbfefce466d642ad98587d13123e4ef95ec9aa73b712e775d4cbba","server_ts_ms":1768250236276,"raw":{"market":"0xe51aa24ab1bbfefce466d642ad98587d13123e4ef95ec9aa73b712e775d4cbba","price_changes":[{"asset_id":"96886111393998001968863279421729456597655847484197549086072988901191634450924","price":"0.94","size":"1152.88","side":"BUY","hash":"a756141751ed60955e86f93eaa28da7dad16fcf7","best_bid":"0.94","best_ask":"0.95"},{"asset_id":"54232589582260339592359130012520874109228367674780084862642636038394766871668","price":"0.06","size":"1152.88","side":"SELL","hash":"e30aecad1ded8f45bc0d742b3e6716ae659c4b8e","best_bid":"0.05","best_ask":"0.06"}],"timestamp":"1768250236276","event_type":"price_change"}}
{"schema_version":1,"source":"clob_ws_market","recv_ts_ns":1768250236428260900,"event_type":"price_change","market":"0xe51aa24ab1bbfefce466d642ad98587d13123e4ef95ec9aa73b712e775d4cbba","server_ts_ms":1768250236279,"raw":{"market":"0xe51aa24ab1bbfefce466d642ad98587d13123e4ef95ec9aa73b712e775d4cbba","price_changes":[{"asset_id":"96886111393998001968863279421729456597655847484197549086072988901191634450924","price":"0.93","size":"1515.82","side":"BUY","hash":"640b98d06f83bce548233b7f94812d7008a153d4","best_bid":"0.94","best_ask":"0.95"},{"asset_id":"54232589582260339592359130012520874109228367674780084862642636038394766871668","price":"0.07","size":"1515.82","side":"SELL","hash":"d58b4eaac49cee5664b691cfc69c36510ead9c7a","best_bid":"0.05","best_ask":"0.06"}],"timestamp":"1768250236279","event_type":"price_change"}}
{"schema_version":1,"source":"clob_ws_market","recv_ts_ns":1768250236432567522,"event_type":"price_change","market":"0xe51aa24ab1bbfefce466d642ad98587d13123e4ef95ec9aa73b712e775d4cbba","server_ts_ms":1768250236280,"raw":{"market":"0xe51aa24ab1bbfefce466d642ad98587d13123e4ef95ec9aa73b712e775d4cbba","price_changes":[{"asset_id":"54232589582260339592359130012520874109228367674780084862642636038394766871668","price":"0.01","size":"21008.91","side":"BUY","hash":"4473280b6e02d4d7e47e3b8cb41a97b44e43badb","best_bid":"0.05","best_ask":"0.06"},{"asset_id":"96886111393998001968863279421729456597655847484197549086072988901191634450924","price":"0.99","size":"21008.91","side":"SELL","hash":"ac05fa48c9e2c932be91cde57f5b47348f621314","best_bid":"0.94","best_ask":"0.95"}],"timestamp":"1768250236280","event_type":"price_change"}}
{"schema_version":1,"source":"clob_ws_market","recv_ts_ns":1768250236435440502,"event_type":"price_change","market":"0xe51aa24ab1bbfefce466d642ad98587d13123e4ef95ec9aa73b712e775d4cbba","server_ts_ms":1768250236281,"raw":{"market":"0xe51aa24ab1bbfefce466d642ad98587d13123e4ef95ec9aa73b712e775d4cbba","price_changes":[{"asset_id":"54232589582260339592359130012520874109228367674780084862642636038394766871668","price":"0.07","size":"1490.82","side":"SELL","hash":"82324a9f5aefcc396b30224032cc2a3356f84a8b","best_bid":"0.05","best_ask":"0.06"},{"asset_id":"96886111393998001968863279421729456597655847484197549086072988901191634450924","price":"0.93","size":"1490.82","side":"BUY","hash":"33a9dd0134920c606c2ebde8022c9701e6389008","best_bid":"0.94","best_ask":"0.95"}],"timestamp":"1768250236281","event_type":"price_change"}}
{"schema_version":1,"source":"clob_ws_market","recv_ts_ns":1768250236438796144,"event_type":"price_change","market":"0xe51aa24ab1bbfefce466d642ad98587d13123e4ef95ec9aa73b712e775d4cbba","server_ts_ms":1768250236282,"raw":{"market":"0xe51aa24ab1bbfefce466d642ad98587d13123e4ef95ec9aa73b712e775d4cbba","price_changes":[{"asset_id":"96886111393998001968863279421729456597655847484197549086072988901191634450924","price":"0.93","size":"1474.82","side":"BUY","hash":"5da5811b1200c69170f867b7cbbfc897bba252dd","best_bid":"0.94","best_ask":"0.95"},{"asset_id":"54232589582260339592359130012520874109228367674780084862642636038394766871668","price":"0.07","size":"1474.82","side":"SELL","hash":"273a175b28dee0a40fecd16dc0a46174283bdf1b","best_bid":"0.05","best_ask":"0.06"}],"timestamp":"1768250236282","event_type":"price_change"}}
{"schema_version":1,"source":"clob_ws_market","recv_ts_ns":1768250236442413555,"event_type":"price_change","market":"0xe51aa24ab1bbfefce466d642ad98587d13123e4ef95ec9aa73b712e775d4cbba","server_ts_ms":1768250236283,"raw":{"market":"0xe51aa24ab1bbfefce466d642ad98587d13123e4ef95ec9aa73b712e775d4cbba","price_changes":[{"asset_id":"96886111393998001968863279421729456597655847484197549086072988901191634450924","price":"0.94","size":"1164.88","side":"BUY","hash":"25c9cb704fed12bd03f663e526a2a72202ff6728","best_bid":"0.94","best_ask":"0.95"},{"asset_id":"54232589582260339592359130012520874109228367674780084862642636038394766871668","price":"0.06","size":"1164.88","side":"SELL","hash":"6b4fe34824915784cc49f8e3395c213dee92ddde","best_bid":"0.05","best_ask":"0.06"}],"timestamp":"1768250236283","event_type":"price_change"}}
{"schema_version":1,"source":"clob_ws_market","recv_ts_ns":1768250236445495039,"event_type":"price_change","market":"0xe51aa24ab1bbfefce466d642ad98587d13123e4ef95ec9aa73b712e775d4cbba","server_ts_ms":1768250236284,"raw":{"market":"0xe51aa24ab1bbfefce466d642ad98587d13123e4ef95ec9aa73b712e775d4cbba","price_changes":[{"asset_id":"54232589582260339592359130012520874109228367674780084862642636038394766871668","price":"0.04","size":"325.9","side":"BUY","hash":"d29fdb2758c4ba14efbacde93dc1e51d1ee406ab","best_bid":"0.05","best_ask":"0.06"},{"asset_id":"96886111393998001968863279421729456597655847484197549086072988901191634450924","price":"0.96","size":"325.9","side":"SELL","hash":"2e01383b78e0fdef7cf1a39956449792831f39e1","best_bid":"0.94","best_ask":"0.95"}],"timestamp":"1768250236284","event_type":"price_change"}}
{"schema_version":1,"source":"clob_ws_market","recv_ts_ns":1768250236448858191,"event_type":"price_change","market":"0xe51aa24ab1bbfefce466d642ad98587d13123e4ef95ec9aa73b712e775d4cbba","server_ts_ms":1768250236285,"raw":{"market":"0xe51aa24ab1bbfefce466d642ad98587d13123e4ef95ec9aa73b712e775d4cbba","price_changes":[{"asset_id":"96886111393998001968863279421729456597655847484197549086072988901191634450924","price":"0.93","size":"1458.82","side":"BUY","hash":"7f95603e818a16515ac85c2c528087ce6000c0de","best_bid":"0.94","best_ask":"0.95"},{"asset_id":"54232589582260339592359130012520874109228367674780084862642636038394766871668","price":"0.07","size":"1458.82","side":"SELL","hash":"304e4a7f2da22c3104ae026cd2c4ea5ae7159f71","best_bid":"0.05","best_ask":"0.06"}],"timestamp":"1768250236285","event_type":"price_change"}}
{"schema_version":1,"source":"clob_ws_market","recv_ts_ns":1768250236452645869,"event_type":"price_change","market":"0xe51aa24ab1bbfefce466d642ad98587d13123e4ef95ec9aa73b712e775d4cbba","server_ts_ms":1768250236286,"raw":{"market":"0xe51aa24ab1bbfefce466d642ad98587d13123e4ef95ec9aa73b712e775d4cbba","price_changes":[{"asset_id":"54232589582260339592359130012520874109228367674780084862642636038394766871668","price":"0.04","size":"309.9","side":"BUY","hash":"051e7a95125a18ba8dc992a338c0aa2f32180efc","best_bid":"0.05","best_ask":"0.06"},{"asset_id":"96886111393998001968863279421729456597655847484197549086072988901191634450924","price":"0.96","size":"309.9","side":"SELL","hash":"5e28eff1e9cb68714e896aac45c451f695ebc68c","best_bid":"0.94","best_ask":"0.95"}],"timestamp":"1768250236286","event_type":"price_change"}}
{"schema_version":1,"source":"clob_ws_market","recv_ts_ns":1768250236456845383,"event_type":"price_change","market":"0xe51aa24ab1bbfefce466d642ad98587d13123e4ef95ec9aa73b712e775d4cbba","server_ts_ms":1768250236286,"raw":{"market":"0xe51aa24ab1bbfefce466d642ad98587d13123e4ef95ec9aa73b712e775d4cbba","price_changes":[{"asset_id":"96886111393998001968863279421729456597655847484197549086072988901191634450924","price":"0.93","size":"1442.82","side":"BUY","hash":"e248ce6a7e82f757693d392fe8facf5c03aaeaf1","best_bid":"0.94","best_ask":"0.95"},{"asset_id":"54232589582260339592359130012520874109228367674780084862642636038394766871668","price":"0.07","size":"1442.82","side":"SELL","hash":"9d1f1463cbd2211b68c6c84853d796a090a0c547","best_bid":"0.05","best_ask":"0.06"}],"timestamp":"1768250236286","event_type":"price_change"}}
{"schema_version":1,"source":"clob_ws_market","recv_ts_ns":1768250236461631482,"event_type":"price_change","market":"0xe51aa24ab1bbfefce466d642ad98587d13123e4ef95ec9aa73b712e775d4cbba","server_ts_ms":1768250236291,"raw":{"market":"0xe51aa24ab1bbfefce466d642ad98587d13123e4ef95ec9aa73b712e775d4cbba","price_changes":[{"asset_id":"96886111393998001968863279421729456597655847484197549086072988901191634450924","price":"0.94","size":"1183.88","side":"BUY","hash":"d45425ddd4a6a2569fb14c77b0a11973e45aa959","best_bid":"0.94","best_ask":"0.95"},{"asset_id":"54232589582260339592359130012520874109228367674780084862642636038394766871668","price":"0.06","size":"1183.88","side":"SELL","hash":"9ee15d331dd1d243b92a51f11ba733920848b64b","best_bid":"0.05","best_ask":"0.06"}],"timestamp":"1768250236291","event_type":"price_change"}}
{"schema_version":1,"source":"clob_ws_market","recv_ts_ns":1768250236466166001,"event_type":"price_change","market":"0xe51aa24ab1bbfefce466d642ad98587d13123e4ef95ec9aa73b712e775d4cbba","server_ts_ms":1768250236294,"raw":{"market":"0xe51aa24ab1bbfefce466d642ad98587d13123e4ef95ec9aa73b712e775d4cbba","price_changes":[{"asset_id":"96886111393998001968863279421729456597655847484197549086072988901191634450924","price":"0.94","size":"1199.88","side":"BUY","hash":"eea9ad9a3425d15e564fbb8f19280c55b176c8bf","best_bid":"0.94","best_ask":"0.95"},{"asset_id":"54232589582260339592359130012520874109228367674780084862642636038394766871668","price":"0.06","size":"1199.88","side":"SELL","hash":"ed60886933b2d33df5b84e39558552b23c580701","best_bid":"0.05","best_ask":"0.06"}],"timestamp":"1768250236294","event_type":"price_change"}}
{"schema_version":1,"source":"clob_ws_market","recv_ts_ns":1768250236471738781,"event_type":"price_change","market":"0xe51aa24ab1bbfefce466d642ad98587d13123e4ef95ec9aa73b712e775d4cbba","server_ts_ms":1768250236315,"raw":{"market":"0xe51aa24ab1bbfefce466d642ad98587d13123e4ef95ec9aa73b712e775d4cbba","price_changes":[{"asset_id":"96886111393998001968863279421729456597655847484197549086072988901191634450924","price":"0.94","size":"1215.88","side":"BUY","hash":"012a6afe38900da180d5286f15379b5cd8444b81","best_bid":"0.94","best_ask":"0.95"},{"asset_id":"54232589582260339592359130012520874109228367674780084862642636038394766871668","price":"0.06","size":"1215.88","side":"SELL","hash":"6d5114e09c1102f401440786b8758324becbad37","best_bid":"0.05","best_ask":"0.06"}],"timestamp":"1768250236315","event_type":"price_change"}}
{"schema_version":1,"source":"clob_ws_market","recv_ts_ns":1768250236475499381,"event_type":"price_change","market":"0xe51aa24ab1bbfefce466d642ad98587d13123e4ef95ec9aa73b712e775d4cbba","server_ts_ms":1768250236316,"raw":{"market":"0xe51aa24ab1bbfefce466d642ad98587d13123e4ef95ec9aa73b712e775d4cbba","price_changes":[{"asset_id":"54232589582260339592359130012520874109228367674780084862642636038394766871668","price":"0.03","size":"2395.6","side":"BUY","hash":"4b13868704709c3b8f2af9e9b2cba692ac4f2db5","best_bid":"0.05","best_ask":"0.06"},{"asset_id":"96886111393998001968863279421729456597655847484197549086072988901191634450924","price":"0.97","size":"2395.6","side":"SELL","hash":"0d1c5ec41ecbd2dd80c93f582b53350f37e6ee3b","best_bid":"0.94","best_ask":"0.95"}],"timestamp":"1768250236316","event_type":"price_change"}}
{"schema_version":1,"source":"clob_ws_market","recv_ts_ns":1768250236479068017,"event_type":"price_change","market":"0xe51aa24ab1bbfefce466d642ad98587d13123e4ef95ec9aa73b712e775d4cbba","server_ts_ms":1768250236318,"raw":{"market":"0xe51aa24ab1bbfefce466d642ad98587d13123e4ef95ec9aa73b712e775d4cbba","price_changes":[{"asset_id":"54232589582260339592359130012520874109228367674780084862642636038394766871668","price":"0.03","size":"2411.6","side":"BUY","hash":"332db10ebf0ba69de2e614730518ec57492d5853","best_bid":"0.05","best_ask":"0.06"},{"asset_id":"96886111393998001968863279421729456597655847484197549086072988901191634450924","price":"0.97","size":"2411.6","side":"SELL","hash":"24c687ca36ca42bb0101a4ad8674f885cb0bec35","best_bid":"0.94","best_ask":"0.95"}],"timestamp":"1768250236318","event_type":"price_change"}}
{"schema_version":1,"source":"clob_ws_market","recv_ts_ns":1768250236482908699,"event_type":"price_change","market":"0xe51aa24ab1bbfefce466d642ad98587d13123e4ef95ec9aa73b712e775d4cbba","server_ts_ms":1768250236320,"raw":{"market":"0xe51aa24ab1bbfefce466d642ad98587d13123e4ef95ec9aa73b712e775d4cbba","price_changes":[{"asset_id":"96886111393998001968863279421729456597655847484197549086072988901191634450924","price":"0.94","size":"1231.88","side":"BUY","hash":"57af15580464ab8572f716c12d5d6b4332ef5967","best_bid":"0.94","best_ask":"0.95"},{"asset_id":"54232589582260339592359130012520874109228367674780084862642636038394766871668","price":"0.06","size":"1231.88","side":"SELL","hash":"407c91a61ef2f0c42e0bd903b5cd8fa35bff8f22","best_bid":"0.05","best_ask":"0.06"}],"timestamp":"1768250236320","event_type":"price_change"}}
{"schema_version":1,"source":"clob_ws_market","recv_ts_ns":1768250236486702001,"event_type":"price_change","market":"0xe51aa24ab1bbfefce466d642ad98587d13123e4ef95ec9aa73b712e775d4cbba","server_ts_ms":1768250236322,"raw":{"market":"0xe51aa24ab1bbfefce466d642ad98587d13123e4ef95ec9aa73b712e775d4cbba","price_changes":[{"asset_id":"54232589582260339592359130012520874109228367674780084862642636038394766871668","price":"0.08","size":"2448.36","side":"SELL","hash":"f8200ed9531522d51ca61ee06569d967e03f3251","best_bid":"0.05","best_ask":"0.06"},{"asset_id":"96886111393998001968863279421729456597655847484197549086072988901191634450924","price":"0.92","size":"2448.36","side":"BUY","hash":"af8294d990a2ea358a3e85b577c3369c21a5c701","best_bid":"0.94","best_ask":"0.95"}],"timestamp":"1768250236322","event_type":"price_change"}}
{"schema_version":1,"source":"clob_ws_market","recv_ts_ns":1768250236490804969,"event_type":"price_change","market":"0xe51aa24ab1bbfefce466d642ad98587d13123e4ef95ec9aa73b712e775d4cbba","server_ts_ms":1768250236323,"raw":{"market":"0xe51aa24ab1bbfefce466d642ad98587d13123e4ef95ec9aa73b712e775d4cbba","price_changes":[{"asset_id":"96886111393998001968863279421729456597655847484197549086072988901191634450924","price":"0.94","size":"1247.88","side":"BUY","hash":"af945320099a16d5f1b0832108d83e8c91e9da00","best_bid":"0.94","best_ask":"0.95"},{"asset_id":"54232589582260339592359130012520874109228367674780084862642636038394766871668","price":"0.06","size":"1247.88","side":"SELL","hash":"c27146c1b1177605d7afbd018489c750f6d51cd6","best_bid":"0.05","best_ask":"0.06"}],"timestamp":"1768250236323","event_type":"price_change"}}
{"schema_version":1,"source":"clob_ws_market","recv_ts_ns":1768250236494308530,"event_type":"price_change","market":"0xe51aa24ab1bbfefce466d642ad98587d13123e4ef95ec9aa73b712e775d4cbba","server_ts_ms":1768250236327,"raw":{"market":"0xe51aa24ab1bbfefce466d642ad98587d13123e4ef95ec9aa73b712e775d4cbba","price_changes":[{"asset_id":"96886111393998001968863279421729456597655847484197549086072988901191634450924","price":"0.94","size":"1263.88","side":"BUY","hash":"8794083fbfbe94ebcba030898854f8288f875c77","best_bid":"0.94","best_ask":"0.95"},{"asset_id":"54232589582260339592359130012520874109228367674780084862642636038394766871668","price":"0.06","size":"1263.88","side":"SELL","hash":"458fe1ea9d7817414cb22555505abfbb22b67dd4","best_bid":"0.05","best_ask":"0.06"}],"timestamp":"1768250236327","event_type":"price_change"}}
{"schema_version":1,"source":"clob_ws_market","recv_ts_ns":1768250236497528440,"event_type":"price_change","market":"0xe51aa24ab1bbfefce466d642ad98587d13123e4ef95ec9aa73b712e775d4cbba","server_ts_ms":1768250236334,"raw":{"market":"0xe51aa24ab1bbfefce466d642ad98587d13123e4ef95ec9aa73b712e775d4cbba","price_changes":[{"asset_id":"96886111393998001968863279421729456597655847484197549086072988901191634450924","price":"0.92","size":"2473.36","side":"BUY","hash":"c8642b02b51bfefad0cb47db2545c0ea6d44d96a","best_bid":"0.94","best_ask":"0.95"},{"asset_id":"54232589582260339592359130012520874109228367674780084862642636038394766871668","price":"0.08","size":"2473.36","side":"SELL","hash":"9ad791657f4d1968b0db89a7cb6f2473344016ef","best_bid":"0.05","best_ask":"0.06"}],"timestamp":"1768250236334","event_type":"price_change"}}
{"schema_version":1,"source":"clob_ws_market","recv_ts_ns":1768250236501456000,"event_type":"price_change","market":"0xe51aa24ab1bbfefce466d642ad98587d13123e4ef95ec9aa73b712e775d4cbba","server_ts_ms":1768250236341,"raw":{"market":"0xe51aa24ab1bbfefce466d642ad98587d13123e4ef95ec9aa73b712e775d4cbba","price_changes":[{"asset_id":"96886111393998001968863279421729456597655847484197549086072988901191634450924","price":"0.93","size":"1467.82","side":"BUY","hash":"61209e8b5f0bd4e8a5e6db3e18838b662f58c16a","best_bid":"0.94","best_ask":"0.95"},{"asset_id":"54232589582260339592359130012520874109228367674780084862642636038394766871668","price":"0.07","size":"1467.82","side":"SELL","hash":"121f4fa3ebb9fc74cadd16ab6f1bdf3da4d4cc89","best_bid":"0.05","best_ask":"0.06"}],"timestamp":"1768250236341","event_type":"price_change"}}
{"schema_version":1,"source":"clob_ws_market","recv_ts_ns":1768250236509354165,"event_type":"price_change","market":"0xe51aa24ab1bbfefce466d642ad98587d13123e4ef95ec9aa73b712e775d4cbba","server_ts_ms":1768250236348,"raw":{"market":"0xe51aa24ab1bbfefce466d642ad98587d13123e4ef95ec9aa73b712e775d4cbba","price_changes":[{"asset_id":"96886111393998001968863279421729456597655847484197549086072988901191634450924","price":"0.94","size":"1273.88","side":"BUY","hash":"2922e15927894e11e8a083f0d57ce696175ef821","best_bid":"0.94","best_ask":"0.95"},{"asset_id":"54232589582260339592359130012520874109228367674780084862642636038394766871668","price":"0.06","size":"1273.88","side":"SELL","hash":"ec944c579b54f06d4cef9ddb8549f48bafc37146","best_bid":"0.05","best_ask":"0.06"}],"timestamp":"1768250236348","event_type":"price_change"}}
{"schema_version":1,"source":"clob_ws_market","recv_ts_ns":1768250236515802730,"event_type":"price_change","market":"0xe51aa24ab1bbfefce466d642ad98587d13123e4ef95ec9aa73b712e775d4cbba","server_ts_ms":1768250236350,"raw":{"market":"0xe51aa24ab1bbfefce466d642ad98587d13123e4ef95ec9aa73b712e775d4cbba","price_changes":[{"asset_id":"54232589582260339592359130012520874109228367674780084862642636038394766871668","price":"0.06","size":"1298.88","side":"SELL","hash":"21f412f2898949d7ffda7e6f4fd45017b5d62f14","best_bid":"0.05","best_ask":"0.06"},{"asset_id":"96886111393998001968863279421729456597655847484197549086072988901191634450924","price":"0.94","size":"1298.88","side":"BUY","hash":"5b7e3062a3cd40abe5449f0318ea903c89f68619","best_bid":"0.94","best_ask":"0.95"}],"timestamp":"1768250236350","event_type":"price_change"}}
{"schema_version":1,"source":"clob_ws_market","recv_ts_ns":1768250236541135595,"event_type":"best_bid_ask","market":"0xe51aa24ab1bbfefce466d642ad98587d13123e4ef95ec9aa73b712e775d4cbba","server_ts_ms":1768250236361,"raw":{"market":"0xe51aa24ab1bbfefce466d642ad98587d13123e4ef95ec9aa73b712e775d4cbba","asset_id":"54232589582260339592359130012520874109228367674780084862642636038394766871668","best_bid":"0.05","best_ask":"0.06","spread":"0.01","timestamp":"1768250236361","event_type":"best_bid_ask"}}
{"schema_version":1,"source":"clob_ws_market","recv_ts_ns":1768250236546219030,"event_type":"price_change","market":"0xe51aa24ab1bbfefce466d642ad98587d13123e4ef95ec9aa73b712e775d4cbba","server_ts_ms":1768250236360,"raw":{"market":"0xe51aa24ab1bbfefce466d642ad98587d13123e4ef95ec9aa73b712e775d4cbba","price_changes":[{"asset_id":"54232589582260339592359130012520874109228367674780084862642636038394766871668","price":"0.05","size":"1598.07","side":"BUY","hash":"acb2ff8b41b198823509837bc517e50483303d20","best_bid":"0.05","best_ask":"0.06"},{"asset_id":"96886111393998001968863279421729456597655847484197549086072988901191634450924","price":"0.95","size":"1598.07","side":"SELL","hash":"8381eef8d23b12c9fdb02c71b5a105b9d31c2833","best_bid":"0.94","best_ask":"0.95"}],"timestamp":"1768250236360","event_type":"price_change"}}
{"schema_version":1,"source":"clob_ws_market","recv_ts_ns":1768250236552767691,"event_type":"book","market":"0xe51aa24ab1bbfefce466d642ad98587d13123e4ef95ec9aa73b712e775d4cbba","server_ts_ms":1768250236360,"raw":{"market":"0xe51aa24ab1bbfefce466d642ad98587d13123e4ef95ec9aa73b712e775d4cbba","asset_id":"54232589582260339592359130012520874109228367674780084862642636038394766871668","bids":[{"price":"0.01","size":"21008.91"},{"price":"0.02","size":"6845.25"},{"price":"0.03","size":"2411.6"},{"price":"0.04","size":"309.9"},{"price":"0.05","size":"1598.07"}],"asks":[{"price":"0.99","size":"24280.24"},{"price":"0.98","size":"7594.51"},{"price":"0.97","size":"5964.69"},{"price":"0.96","size":"5411.4"},{"price":"0.95","size":"5356.39"},{"price":"0.94","size":"5328"},{"price":"0.93","size":"5039.28"},{"price":"0.92","size":"5022.7"},{"price":"0.91","size":"5320.9"},{"price":"0.9","size":"5158.44"},{"price":"0.89","size":"18.3"},{"price":"0.88","size":"30.3"},{"price":"0.87","size":"16.5"},{"price":"0.86","size":"15.8"},{"price":"0.85","size":"104.19"},{"price":"0.84","size":"24.69"},{"price":"0.83","size":"14.19"},{"price":"0.82","size":"13.8"},{"price":"0.81","size":"13.4"},{"price":"0.8","size":"38.1"},{"price":"0.79","size":"12.8"},{"price":"0.78","size":"12.6"},{"price":"0.77","size":"12.3"},{"price":"0.76","size":"22.1"},{"price":"0.75","size":"16.9"},{"price":"0.74","size":"21.8"},{"price":"0.73","size":"11.6"},{"price":"0.72","size":"11.4"},{"price":"0.71","size":"61.3"},{"price":"0.7","size":"26.2"},{"price":"0.69","size":"11.1"},{"price":"0.68","size":"11"},{"price":"0.67","size":"110.9"},{"price":"0.66","size":"10.8"},{"price":"0.65","size":"15.7"},{"price":"0.64","size":"10.6"},{"price":"0.63","size":"10.6"},{"price":"0.62","size":"22.5"},{"price":"0.61","size":"10.5"},{"price":"0.6","size":"45.4"},{"price":"0.59","size":"311.4"},{"price":"0.58","size":"820.82"},{"price":"0.57","size":"826.3"},{"price":"0.56","size":"1062.3"},{"price":"0.55","size":"582.3"},{"price":"0.54","size":"626.2"},{"price":"0.53","size":"562.2"},{"price":"0.52","size":"567.2"},{"price":"0.51","size":"573.2"},{"price":"0.5","size":"917.2"},{"price":"0.49","size":"597.2"},{"price":"0.48","size":"590.2"},{"price":"0.47","size":"567.2"},{"price":"0.46","size":"636.61"},{"price":"0.45","size":"362.97"},{"price":"0.44","size":"341.3"},{"price":"0.43","size":"320.62"},{"price":"0.42","size":"567.3"},{"price":"0.41","size":"562.4"},{"price":"0.4","size":"693.02"},{"price":"0.39","size":"593.5"},{"price":"0.38","size":"604.5"},{"price":"0.37","size":"672.32"},{"price":"0.36","size":"680.6"},{"price":"0.35","size":"536.14"},{"price":"0.34","size":"602.8"},{"price":"0.33","size":"572.9"},{"price":"0.32","size":"573"},{"price":"0.31","size":"595.1"},{"price":"0.3","size":"603.2"},{"price":"0.29","size":"1318.72"},{"price":"0.28","size":"1043.04"},{"price":"0.27","size":"663.6"},{"price":"0.26","size":"911.17"},{"price":"0.25","size":"694.3"},{"price":"0.24","size":"717.6"},{"price":"0.23","size":"1183.3"},{"price":"0.22","size":"1526.53"},{"price":"0.21","size":"1178.8"},{"price":"0.2","size":"1445.08"},{"price":"0.19","size":"1229.8"},{"price":"0.18","size":"1467.57"},{"price":"0.17","size":"1672.41"},{"price":"0.16","size":"1815.59"},{"price":"0.15","size":"1810.78"},{"price":"0.14","size":"1506.7"},{"price":"0.13","size":"1788.93"},{"price":"0.12","size":"2355.4"},{"price":"0.11","size":"1792.8"},{"price":"0.1","size":"3396.27"},{"price":"0.09","size":"3017.44"},{"price":"0.08","size":"2473.36"},{"price":"0.07","size":"1467.82"},{"price":"0.06","size":"1298.88"}],"hash":"acb2ff8b41b198823509837bc517e50483303d20","timestamp":"1768250236360","event_type":"book"}}
{"schema_version":1,"source":"clob_ws_market","recv_ts_ns":1768250236561686757,"event_type":"price_change","market":"0xe51aa24ab1bbfefce466d642ad98587d13123e4ef95ec9aa73b712e775d4cbba","server_ts_ms":1768250236367,"raw":{"market":"0xe51aa24ab1bbfefce466d642ad98587d13123e4ef95ec9aa73b712e775d4cbba","price_changes":[{"asset_id":"96886111393998001968863279421729456597655847484197549086072988901191634450924","price":"0.95","size":"1618.07","side":"SELL","hash":"bfedaf077907c9dd35311553742a26ed18245f2c","best_bid":"0.94","best_ask":"0.95"},{"asset_id":"54232589582260339592359130012520874109228367674780084862642636038394766871668","price":"0.05","size":"1618.07","side":"BUY","hash":"0943859f7325a564e4d7b3c52798767597515a8b","best_bid":"0.05","best_ask":"0.06"}],"timestamp":"1768250236367","event_type":"price_change"}}
{"schema_version":1,"source":"clob_ws_market","recv_ts_ns":1768250236608631556,"event_type":"price_change","market":"0xe51aa24ab1bbfefce466d642ad98587d13123e4ef95ec9aa73b712e775d4cbba","server_ts_ms":1768250236424,"raw":{"market":"0xe51aa24ab1bbfefce466d642ad98587d13123e4ef95ec9aa73b712e775d4cbba","price_changes":[{"asset_id":"96886111393998001968863279421729456597655847484197549086072988901191634450924","price":"0.94","size":"1286.88","side":"BUY","hash":"2b1e49317cf73127fe0ef77ccf0db426acec5156","best_bid":"0.94","best_ask":"0.95"},{"asset_id":"54232589582260339592359130012520874109228367674780084862642636038394766871668","price":"0.06","size":"1286.88","side":"SELL","hash":"851ad47b3cff19bf4de74f5576449543c4c4f613","best_bid":"0.05","best_ask":"0.06"}],"timestamp":"1768250236424","event_type":"price_change"}}
{"schema_version":1,"source":"clob_ws_market","recv_ts_ns":1768250236612342624,"event_type":"price_change","market":"0xe51aa24ab1bbfefce466d642ad98587d13123e4ef95ec9aa73b712e775d4cbba","server_ts_ms":1768250236442,"raw":{"market":"0xe51aa24ab1bbfefce466d642ad98587d13123e4ef95ec9aa73b712e775d4cbba","price_changes":[{"asset_id":"96886111393998001968863279421729456597655847484197549086072988901191634450924","price":"0.73","size":"668.6","side":"BUY","hash":"8779ff23ba7dea3450de3666a3083a4bdc7b560c","best_bid":"0.94","best_ask":"0.95"},{"asset_id":"54232589582260339592359130012520874109228367674780084862642636038394766871668","price":"0.27","size":"668.6","side":"SELL","hash":"2f533b4fa521fe35126b09aafadd5922dc272d2a","best_bid":"0.05","best_ask":"0.06"}],"timestamp":"1768250236442","event_type":"price_change"}}
{"schema_version":1,"source":"clob_ws_market","recv_ts_ns":1768250236615980636,"event_type":"price_change","market":"0xe51aa24ab1bbfefce466d642ad98587d13123e4ef95ec9aa73b712e775d4cbba","server_ts_ms":1768250236475,"raw":{"market":"0xe51aa24ab1bbfefce466d642ad98587d13123e4ef95ec9aa73b712e775d4cbba","price_changes":[{"asset_id":"96886111393998001968863279421729456597655847484197549086072988901191634450924","price":"0.92","size":"2448.36","side":"BUY","hash":"da6e202b5ddb34d87837d37e502f0fe5d30b057c","best_bid":"0.94","best_ask":"0.95"},{"asset_id":"54232589582260339592359130012520874109228367674780084862642636038394766871668","price":"0.08","size":"2448.36","side":"SELL","hash":"35d7d3e9c5b537901fa7655373c90842c7ec005d","best_bid":"0.05","best_ask":"0.06"}],"timestamp":"1768250236475","event_type":"price_change"}}
{"schema_version":1,"source":"clob_ws_market","recv_ts_ns":1768250236619525723,"event_type":"price_change","market":"0xe51aa24ab1bbfefce466d642ad98587d13123e4ef95ec9aa73b712e775d4cbba","server_ts_ms":1768250236476,"raw":{"market":"0xe51aa24ab1bbfefce466d642ad98587d13123e4ef95ec9aa73b712e775d4cbba","price_changes":[{"asset_id":"96886111393998001968863279421729456597655847484197549086072988901191634450924","price":"0.93","size":"1442.82","side":"BUY","hash":"99990587ff91a5cb7ee690391a42addf25dbca2d","best_bid":"0.94","best_ask":"0.95"},{"asset_id":"54232589582260339592359130012520874109228367674780084862642636038394766871668","price":"0.07","size":"1442.82","side":"SELL","hash":"093497883a04884798209fae01b2c1dab2547112","best_bid":"0.05","best_ask":"0.06"}],"timestamp":"1768250236476","event_type":"price_change"}}
{"schema_version":1,"source":"clob_ws_market","recv_ts_ns":1768250236623199565,"event_type":"price_change","market":"0xe51aa24ab1bbfefce466d642ad98587d13123e4ef95ec9aa73b712e775d4cbba","server_ts_ms":1768250236478,"raw":{"market":"0xe51aa24ab1bbfefce466d642ad98587d13123e4ef95ec9aa73b712e775d4cbba","price_changes":[{"asset_id":"54232589582260339592359130012520874109228367674780084862642636038394766871668","price":"0.08","size":"2423.36","side":"SELL","hash":"a504b82255fa6b1d66fcb209600ce52f389f92c3","best_bid":"0.05","best_ask":"0.06"},{"asset_id":"96886111393998001968863279421729456597655847484197549086072988901191634450924","price":"0.92","size":"2423.36","side":"BUY","hash":"ac80152a77703f6fbb10eb34e3e6085860d85292","best_bid":"0.94","best_ask":"0.95"}],"timestamp":"1768250236478","event_type":"price_change"}}
{"schema_version":1,"source":"clob_ws_market","recv_ts_ns":1768250236628042567,"event_type":"price_change","market":"0xe51aa24ab1bbfefce466d642ad98587d13123e4ef95ec9aa73b712e775d4cbba","server_ts_ms":1768250236479,"raw":{"market":"0xe51aa24ab1bbfefce466d642ad98587d13123e4ef95ec9aa73b712e775d4cbba","price_changes":[{"asset_id":"54232589582260339592359130012520874109228367674780084862642636038394766871668","price":"0.07","size":"1467.82","side":"SELL","hash":"8d14614798fab2ee307ad2dd6d846bbafd87cdbd","best_bid":"0.05","best_ask":"0.06"},{"asset_id":"96886111393998001968863279421729456597655847484197549086072988901191634450924","price":"0.93","size":"1467.82","side":"BUY","hash":"862a982aeef3a6de2acebce53e89a6036d421e54","best_bid":"0.94","best_ask":"0.95"}],"timestamp":"1768250236479","event_type":"price_change"}}
{"schema_version":1,"source":"clob_ws_market","recv_ts_ns":1768250236632456650,"event_type":"price_change","market":"0xe51aa24ab1bbfefce466d642ad98587d13123e4ef95ec9aa73b712e775d4cbba","server_ts_ms":1768250236481,"raw":{"market":"0xe51aa24ab1bbfefce466d642ad98587d13123e4ef95ec9aa73b712e775d4cbba","price_changes":[{"asset_id":"96886111393998001968863279421729456597655847484197549086072988901191634450924","price":"0.93","size":"1492.82","side":"BUY","hash":"b61a1c33932f37ee34cbdb86a96e3bd02fb4c25a","best_bid":"0.94","best_ask":"0.95"},{"asset_id":"54232589582260339592359130012520874109228367674780084862642636038394766871668","price":"0.07","size":"1492.82","side":"SELL","hash":"79f5af7617876e15292dde5e8f8a031043e203cf","best_bid":"0.05","best_ask":"0.06"}],"timestamp":"1768250236481","event_type":"price_change"}}
{"schema_version":1,"source":"clob_ws_market","recv_ts_ns":1768250236635727933,"event_type":"price_change","market":"0xe51aa24ab1bbfefce466d642ad98587d13123e4ef95ec9aa73b712e775d4cbba","server_ts_ms":1768250236482,"raw":{"market":"0xe51aa24ab1bbfefce466d642ad98587d13123e4ef95ec9aa73b712e775d4cbba","price_changes":[{"asset_id":"96886111393998001968863279421729456597655847484197549086072988901191634450924","price":"0.94","size":"1311.88","side":"BUY","hash":"271bbf8c9c1bb1c917f058618cda51d2735dd3b4","best_bid":"0.94","best_ask":"0.95"},{"asset_id":"54232589582260339592359130012520874109228367674780084862642636038394766871668","price":"0.06","size":"1311.88","side":"SELL","hash":"e45260d11623f6b91b7283e5f20e5e63fc21e39d","best_bid":"0.05","best_ask":"0.06"}],"timestamp":"1768250236482","event_type":"price_change"}}
{"schema_version":1,"source":"clob_ws_market","recv_ts_ns":1768250236638918837,"event_type":"price_change","market":"0xe51aa24ab1bbfefce466d642ad98587d13123e4ef95ec9aa73b712e775d4cbba","server_ts_ms":1768250236491,"raw":{"market":"0xe51aa24ab1bbfefce466d642ad98587d13123e4ef95ec9aa73b712e775d4cbba","price_changes":[{"asset_id":"96886111393998001968863279421729456597655847484197549086072988901191634450924","price":"0.98","size":"6820.25","side":"SELL","hash":"77dbd1a12a43209bb501d2834916a116d842146d","best_bid":"0.94","best_ask":"0.95"},{"asset_id":"54232589582260339592359130012520874109228367674780084862642636038394766871668","price":"0.02","size":"6820.25","side":"BUY","hash":"419533e4e47cf319f09babf4342836bc9c5e862d","best_bid":"0.05","best_ask":"0.06"}],"timestamp":"1768250236491","event_type":"price_change"}}
{"schema_version":1,"source":"clob_ws_market","recv_ts_ns":1768250236647558782,"event_type":"price_change","market":"0xe51aa24ab1bbfefce466d642ad98587d13123e4ef95ec9aa73b712e775d4cbba","server_ts_ms":1768250236492,"raw":{"market":"0xe51aa24ab1bbfefce466d642ad98587d13123e4ef95ec9aa73b712e775d4cbba","price_changes":[{"asset_id":"96886111393998001968863279421729456597655847484197549086072988901191634450924","price":"0.99","size":"21033.91","side":"SELL","hash":"d95ccf2176d9bf462567786927ed3446246ddcbc","best_bid":"0.94","best_ask":"0.95"},{"asset_id":"54232589582260339592359130012520874109228367674780084862642636038394766871668","price":"0.01","size":"21033.91","side":"BUY","hash":"0cfcab5a60996757ce2210cc01e496a6780e117b","best_bid":"0.05","best_ask":"0.06"}],"timestamp":"1768250236492","event_type":"price_change"}}
{"schema_version":1,"source":"clob_ws_market","recv_ts_ns":1768250236657798307,"event_type":"price_change","market":"0xe51aa24ab1bbfefce466d642ad98587d13123e4ef95ec9aa73b712e775d4cbba","server_ts_ms":1768250236514,"raw":{"market":"0xe51aa24ab1bbfefce466d642ad98587d13123e4ef95ec9aa73b712e775d4cbba","price_changes":[{"asset_id":"96886111393998001968863279421729456597655847484197549086072988901191634450924","price":"0.94","size":"1341.88","side":"BUY","hash":"f7b3430ab4cb8e578e4e9bab697368d5a55ff427","best_bid":"0.94","best_ask":"0.95"},{"asset_id":"54232589582260339592359130012520874109228367674780084862642636038394766871668","price":"0.06","size":"1341.88","side":"SELL","hash":"f7937155b4e8fdb89a4ca78c0dca52c065a85a44","best_bid":"0.05","best_ask":"0.06"}],"timestamp":"1768250236514","event_type":"price_change"}}
{"schema_version":1,"source":"clob_ws_market","recv_ts_ns":1768250236661745634,"event_type":"price_change","market":"0xe51aa24ab1bbfefce466d642ad98587d13123e4ef95ec9aa73b712e775d4cbba","server_ts_ms":1768250236515,"raw":{"market":"0xe51aa24ab1bbfefce466d642ad98587d13123e4ef95ec9aa73b712e775d4cbba","price_changes":[{"asset_id":"54232589582260339592359130012520874109228367674780084862642636038394766871668","price":"0.06","size":"1352.88","side":"SELL","hash":"dde9b9a399fbb94aeba60b38e9a3e9431a6becb9","best_bid":"0.05","best_ask":"0.06"},{"asset_id":"96886111393998001968863279421729456597655847484197549086072988901191634450924","price":"0.94","size":"1352.88","side":"BUY","hash":"b73a9400d35d867a5aca6818ffb6f754ed6a23f0","best_bid":"0.94","best_ask":"0.95"}],"timestamp":"1768250236515","event_type":"price_change"}}
{"schema_version":1,"source":"clob_ws_market","recv_ts_ns":1768250236665978008,"event_type":"price_change","market":"0xe51aa24ab1bbfefce466d642ad98587d13123e4ef95ec9aa73b712e775d4cbba","server_ts_ms":1768250236516,"raw":{"market":"0xe51aa24ab1bbfefce466d642ad98587d13123e4ef95ec9aa73b712e775d4cbba","price_changes":[{"asset_id":"96886111393998001968863279421729456597655847484197549086072988901191634450924","price":"0.94","size":"1367.88","side":"BUY","hash":"827f761a7a1a967819031d0ba711c0b68455bb26","best_bid":"0.94","best_ask":"0.95"},{"asset_id":"54232589582260339592359130012520874109228367674780084862642636038394766871668","price":"0.06","size":"1367.88","side":"SELL","hash":"a95670878fd66ae8b2dfc45fc5d4c28411ae81a7","best_bid":"0.05","best_ask":"0.06"}],"timestamp":"1768250236516","event_type":"price_change"}}
{"schema_version":1,"source":"clob_ws_market","recv_ts_ns":1768250236670368342,"event_type":"price_change","market":"0xe51aa24ab1bbfefce466d642ad98587d13123e4ef95ec9aa73b712e775d4cbba","server_ts_ms":1768250236518,"raw":{"market":"0xe51aa24ab1bbfefce466d642ad98587d13123e4ef95ec9aa73b712e775d4cbba","price_changes":[{"asset_id":"96886111393998001968863279421729456597655847484197549086072988901191634450924","price":"0.94","size":"1618.88","side":"BUY","hash":"832e902ea8e9b780aef1fbbd55ac666996d9111b","best_bid":"0.94","best_ask":"0.95"},{"asset_id":"54232589582260339592359130012520874109228367674780084862642636038394766871668","price":"0.06","size":"1618.88","side":"SELL","hash":"62deeeb98d7eb026ef54b2b7fd3bfd236f5546bc","best_bid":"0.05","best_ask":"0.06"}],"timestamp":"1768250236518","event_type":"price_change"}}
{"schema_version":1,"source":"clob_ws_market","recv_ts_ns":1768250236775179251,"event_type":"best_bid_ask","market":"0xe51aa24ab1bbfefce466d642ad98587d13123e4ef95ec9aa73b712e775d4cbba","server_ts_ms":1768250236571,"raw":{"market":"0xe51aa24ab1bbfefce466d642ad98587d13123e4ef95ec9aa73b712e775d4cbba","asset_id":"54232589582260339592359130012520874109228367674780084862642636038394766871668","best_bid":"0.05","best_ask":"0.06","spread":"0.01","timestamp":"1768250236571","event_type":"best_bid_ask"}}
{"schema_version":1,"source":"clob_ws_market","recv_ts_ns":1768250236779572832,"event_type":"price_change","market":"0xe51aa24ab1bbfefce466d642ad98587d13123e4ef95ec9aa73b712e775d4cbba","server_ts_ms":1768250236570,"raw":{"market":"0xe51aa24ab1bbfefce466d642ad98587d13123e4ef95ec9aa73b712e775d4cbba","price_changes":[{"asset_id":"96886111393998001968863279421729456597655847484197549086072988901191634450924","price":"0.94","size":"1560.88","side":"BUY","hash":"674ddab6248e1e7cd9d0aafb7f8a917627606803","best_bid":"0.94","best_ask":"0.95"},{"asset_id":"54232589582260339592359130012520874109228367674780084862642636038394766871668","price":"0.06","size":"1560.88","side":"SELL","hash":"647e63e8bbeea3e4227368f76970a9ba181b6481","best_bid":"0.05","best_ask":"0.06"}],"timestamp":"1768250236570","event_type":"price_change"}}
{"schema_version":1,"source":"clob_ws_market","recv_ts_ns":1768250236784954236,"event_type":"book","market":"0xe51aa24ab1bbfefce466d642ad98587d13123e4ef95ec9aa73b712e775d4cbba","server_ts_ms":1768250236570,"raw":{"market":"0xe51aa24ab1bbfefce466d642ad98587d13123e4ef95ec9aa73b712e775d4cbba","asset_id":"54232589582260339592359130012520874109228367674780084862642636038394766871668","bids":[{"price":"0.01","size":"21033.91"},{"price":"0.02","size":"6820.25"},{"price":"0.03","size":"2411.6"},{"price":"0.04","size":"309.9"},{"price":"0.05","size":"1618.07"}],"asks":[{"price":"0.99","size":"24280.24"},{"price":"0.98","size":"7594.51"},{"price":"0.97","size":"5964.69"},{"price":"0.96","size":"5411.4"},{"price":"0.95","size":"5356.39"},{"price":"0.94","size":"5328"},{"price":"0.93","size":"5039.28"},{"price":"0.92","size":"5022.7"},{"price":"0.91","size":"5320.9"},{"price":"0.9","size":"5158.44"},{"price":"0.89","size":"18.3"},{"price":"0.88","size":"30.3"},{"price":"0.87","size":"16.5"},{"price":"0.86","size":"15.8"},{"price":"0.85","size":"104.19"},{"price":"0.84","size":"24.69"},{"price":"0.83","size":"14.19"},{"price":"0.82","size":"13.8"},{"price":"0.81","size":"13.4"},{"price":"0.8","size":"38.1"},{"price":"0.79","size":"12.8"},{"price":"0.78","size":"12.6"},{"price":"0.77","size":"12.3"},{"price":"0.76","size":"22.1"},{"price":"0.75","size":"16.9"},{"price":"0.74","size":"21.8"},{"price":"0.73","size":"11.6"},{"price":"0.72","size":"11.4"},{"price":"0.71","size":"61.3"},{"price":"0.7","size":"26.2"},{"price":"0.69","size":"11.1"},{"price":"0.68","size":"11"},{"price":"0.67","size":"110.9"},{"price":"0.66","size":"10.8"},{"price":"0.65","size":"15.7"},{"price":"0.64","size":"10.6"},{"price":"0.63","size":"10.6"},{"price":"0.62","size":"22.5"},{"price":"0.61","size":"10.5"},{"price":"0.6","size":"45.4"},{"price":"0.59","size":"311.4"},{"price":"0.58","size":"820.82"},{"price":"0.57","size":"826.3"},{"price":"0.56","size":"1062.3"},{"price":"0.55","size":"582.3"},{"price":"0.54","size":"626.2"},{"price":"0.53","size":"562.2"},{"price":"0.52","size":"567.2"},{"price":"0.51","size":"573.2"},{"price":"0.5","size":"917.2"},{"price":"0.49","size":"597.2"},{"price":"0.48","size":"590.2"},{"price":"0.47","size":"567.2"},{"price":"0.46","size":"636.61"},{"price":"0.45","size":"362.97"},{"price":"0.44","size":"341.3"},{"price":"0.43","size":"320.62"},{"price":"0.42","size":"567.3"},{"price":"0.41","size":"562.4"},{"price":"0.4","size":"693.02"},{"price":"0.39","size":"593.5"},{"price":"0.38","size":"604.5"},{"price":"0.37","size":"672.32"},{"price":"0.36","size":"680.6"},{"price":"0.35","size":"536.14"},{"price":"0.34","size":"602.8"},{"price":"0.33","size":"572.9"},{"price":"0.32","size":"573"},{"price":"0.31","size":"595.1"},{"price":"0.3","size":"603.2"},{"price":"0.29","size":"1318.72"},{"price":"0.28","size":"1043.04"},{"price":"0.27","size":"668.6"},{"price":"0.26","size":"911.17"},{"price":"0.25","size":"694.3"},{"price":"0.24","size":"717.6"},{"price":"0.23","size":"1183.3"},{"price":"0.22","size":"1526.53"},{"price":"0.21","size":"1178.8"},{"price":"0.2","size":"1445.08"},{"price":"0.19","size":"1229.8"},{"price":"0.18","size":"1467.57"},{"price":"0.17","size":"1672.41"},{"price":"0.16","size":"1815.59"},{"price":"0.15","size":"1810.78"},{"price":"0.14","size":"1506.7"},{"price":"0.13","size":"1788.93"},{"price":"0.12","size":"2355.4"},{"price":"0.11","size":"1792.8"},{"price":"0.1","size":"3396.27"},{"price":"0.09","size":"3017.44"},{"price":"0.08","size":"2423.36"},{"price":"0.07","size":"1492.82"},{"price":"0.06","size":"1560.88"}],"hash":"647e63e8bbeea3e4227368f76970a9ba181b6481","timestamp":"1768250236570","event_type":"book"}}
{"schema_version":1,"source":"clob_ws_market","recv_ts_ns":1768250236794761394,"event_type":"price_change","market":"0xe51aa24ab1bbfefce466d642ad98587d13123e4ef95ec9aa73b712e775d4cbba","server_ts_ms":1768250236572,"raw":{"market":"0xe51aa24ab1bbfefce466d642ad98587d13123e4ef95ec9aa73b712e775d4cbba","price_changes":[{"asset_id":"96886111393998001968863279421729456597655847484197549086072988901191634450924","price":"0.92","size":"2724.36","side":"BUY","hash":"8a2f22a1f5454893f3dd0b7eb7d553f24808be56","best_bid":"0.94","best_ask":"0.95"},{"asset_id":"54232589582260339592359130012520874109228367674780084862642636038394766871668","price":"0.08","size":"2724.36","side":"SELL","hash":"b6766c2baa0ad154e6fb12399ab760c0347a0d98","best_bid":"0.05","best_ask":"0.06"}],"timestamp":"1768250236572","event_type":"price_change"}}
{"schema_version":1,"source":"clob_ws_market","recv_ts_ns":1768250236799097031,"event_type":"price_change","market":"0xe51aa24ab1bbfefce466d642ad98587d13123e4ef95ec9aa73b712e775d4cbba","server_ts_ms":1768250236573,"raw":{"market":"0xe51aa24ab1bbfefce466d642ad98587d13123e4ef95ec9aa73b712e775d4cbba","price_changes":[{"asset_id":"96886111393998001968863279421729456597655847484197549086072988901191634450924","price":"0.94","size":"1544.88","side":"BUY","hash":"58bd322a4e4a0ccf7897ce6c1f01582cdbcb0e53","best_bid":"0.94","best_ask":"0.95"},{"asset_id":"54232589582260339592359130012520874109228367674780084862642636038394766871668","price":"0.06","size":"1544.88","side":"SELL","hash":"cd83e6c9b91e45c1b64faf149f821c40a45ccb4b","best_bid":"0.05","best_ask":"0.06"}],"timestamp":"1768250236573","event_type":"price_change"}}
{"schema_version":1,"source":"clob_ws_market","recv_ts_ns":1768250236803524369,"event_type":"price_change","market":"0xe51aa24ab1bbfefce466d642ad98587d13123e4ef95ec9aa73b712e775d4cbba","server_ts_ms":1768250236574,"raw":{"market":"0xe51aa24ab1bbfefce466d642ad98587d13123e4ef95ec9aa73b712e775d4cbba","price_changes":[{"asset_id":"96886111393998001968863279421729456597655847484197549086072988901191634450924","price":"0.94","size":"1508.88","side":"BUY","hash":"3b6241b992c9109de7b5e3e1159e6d80660db092","best_bid":"0.94","best_ask":"0.95"},{"asset_id":"54232589582260339592359130012520874109228367674780084862642636038394766871668","price":"0.06","size":"1508.88","side":"SELL","hash":"d5ecb1b0393acb2fc2cdbe9b7655139cc7565ff9","best_bid":"0.05","best_ask":"0.06"}],"timestamp":"1768250236574","event_type":"price_change"}}
{"schema_version":1,"source":"clob_ws_market","recv_ts_ns":1768250236807675506,"event_type":"price_change","market":"0xe51aa24ab1bbfefce466d642ad98587d13123e4ef95ec9aa73b712e775d4cbba","server_ts_ms":1768250236575,"raw":{"market":"0xe51aa24ab1bbfefce466d642ad98587d13123e4ef95ec9aa73b712e775d4cbba","price_changes":[{"asset_id":"96886111393998001968863279421729456597655847484197549086072988901191634450924","price":"0.94","size":"1538.88","side":"BUY","hash":"ca941859dab88623541e41001d1aefb8024540d9","best_bid":"0.94","best_ask":"0.95"},{"asset_id":"54232589582260339592359130012520874109228367674780084862642636038394766871668","price":"0.06","size":"1538.88","side":"SELL","hash":"7cde499508d815aa8f76216ebe45e020ce1abbb2","best_bid":"0.05","best_ask":"0.06"}],"timestamp":"1768250236575","event_type":"price_change"}}
{"schema_version":1,"source":"clob_ws_market","recv_ts_ns":1768250236812096456,"event_type":"price_change","market":"0xe51aa24ab1bbfefce466d642ad98587d13123e4ef95ec9aa73b712e775d4cbba","server_ts_ms":1768250236577,"raw":{"market":"0xe51aa24ab1bbfefce466d642ad98587d13123e4ef95ec9aa73b712e775d4cbba","price_changes":[{"asset_id":"96886111393998001968863279421729456597655847484197549086072988901191634450924","price":"0.95","size":"1612.57","side":"SELL","hash":"4cc8a3b6f6719d003885eb8a43162acac77ebefb","best_bid":"0.94","best_ask":"0.95"},{"asset_id":"54232589582260339592359130012520874109228367674780084862642636038394766871668","price":"0.05","size":"1612.57","side":"BUY","hash":"64db6d98a258f723670608ef17ee3f8f75a3eaa6","best_bid":"0.05","best_ask":"0.06"}],"timestamp":"1768250236577","event_type":"price_change"}}
{"schema_version":1,"source":"clob_ws_market","recv_ts_ns":1768250236815895787,"event_type":"price_change","market":"0xe51aa24ab1bbfefce466d642ad98587d13123e4ef95ec9aa73b712e775d4cbba","server_ts_ms":1768250236577,"raw":{"market":"0xe51aa24ab1bbfefce466d642ad98587d13123e4ef95ec9aa73b712e775d4cbba","price_changes":[{"asset_id":"54232589582260339592359130012520874109228367674780084862642636038394766871668","price":"0.03","size":"2395.6","side":"BUY","hash":"29a4a0335165621cb2979f6261a2e2f3aaf51bb2","best_bid":"0.05","best_ask":"0.06"},{"asset_id":"96886111393998001968863279421729456597655847484197549086072988901191634450924","price":"0.97","size":"2395.6","side":"SELL","hash":"035f4514dfb0e0db88d1a4e9c78ec53512f3b58b","best_bid":"0.94","best_ask":"0.95"}],"timestamp":"1768250236577","event_type":"price_change"}}
{"schema_version":1,"source":"clob_ws_market","recv_ts_ns":1768250236824710969,"event_type":"best_bid_ask","market":"0xe51aa24ab1bbfefce466d642ad98587d13123e4ef95ec9aa73b712e775d4cbba","server_ts_ms":1768250236583,"raw":{"market":"0xe51aa24ab1bbfefce466d642ad98587d13123e4ef95ec9aa73b712e775d4cbba","asset_id":"54232589582260339592359130012520874109228367674780084862642636038394766871668","best_bid":"0.05","best_ask":"0.06","spread":"0.01","timestamp":"1768250236583","event_type":"best_bid_ask"}}
{"schema_version":1,"source":"clob_ws_market","recv_ts_ns":1768250236829548062,"event_type":"price_change","market":"0xe51aa24ab1bbfefce466d642ad98587d13123e4ef95ec9aa73b712e775d4cbba","server_ts_ms":1768250236582,"raw":{"market":"0xe51aa24ab1bbfefce466d642ad98587d13123e4ef95ec9aa73b712e775d4cbba","price_changes":[{"asset_id":"54232589582260339592359130012520874109228367674780084862642636038394766871668","price":"0.05","size":"1583.57","side":"BUY","hash":"7488a47533dd0ac419d4d138f34e43d1cab89f05","best_bid":"0.05","best_ask":"0.06"},{"asset_id":"96886111393998001968863279421729456597655847484197549086072988901191634450924","price":"0.95","size":"1583.57","side":"SELL","hash":"6137644e8535d439d6675026caecc3621a1b98fa","best_bid":"0.94","best_ask":"0.95"}],"timestamp":"1768250236582","event_type":"price_change"}}
{"schema_version":1,"source":"clob_ws_market","recv_ts_ns":1768250236833928924,"event_type":"price_change","market":"0xe51aa24ab1bbfefce466d642ad98587d13123e4ef95ec9aa73b712e775d4cbba","server_ts_ms":1768250236582,"raw":{"market":"0xe51aa24ab1bbfefce466d642ad98587d13123e4ef95ec9aa73b712e775d4cbba","price_changes":[{"asset_id":"96886111393998001968863279421729456597655847484197549086072988901191634450924","price":"0.95","size":"1583.57","side":"SELL","hash":"6137644e8535d439d6675026caecc3621a1b98fa","best_bid":"0.94","best_ask":"0.95"},{"asset_id":"54232589582260339592359130012520874109228367674780084862642636038394766871668","price":"0.05","size":"1583.57","side":"BUY","hash":"7488a47533dd0ac419d4d138f34e43d1cab89f05","best_bid":"0.05","best_ask":"0.06"}],"timestamp":"1768250236582","event_type":"price_change"}}
{"schema_version":1,"source":"clob_ws_market","recv_ts_ns":1768250236840981601,"event_type":"book","market":"0xe51aa24ab1bbfefce466d642ad98587d13123e4ef95ec9aa73b712e775d4cbba","server_ts_ms":1768250236582,"raw":{"market":"0xe51aa24ab1bbfefce466d642ad98587d13123e4ef95ec9aa73b712e775d4cbba","asset_id":"54232589582260339592359130012520874109228367674780084862642636038394766871668","bids":[{"price":"0.01","size":"21033.91"},{"price":"0.02","size":"6820.25"},{"price":"0.03","size":"2395.6"},{"price":"0.04","size":"309.9"},{"price":"0.05","size":"1583.57"}],"asks":[{"price":"0.99","size":"24280.24"},{"price":"0.98","size":"7594.51"},{"price":"0.97","size":"5964.69"},{"price":"0.96","size":"5411.4"},{"price":"0.95","size":"5356.39"},{"price":"0.94","size":"5328"},{"price":"0.93","size":"5039.28"},{"price":"0.92","size":"5022.7"},{"price":"0.91","size":"5320.9"},{"price":"0.9","size":"5158.44"},{"price":"0.89","size":"18.3"},{"price":"0.88","size":"30.3"},{"price":"0.87","size":"16.5"},{"price":"0.86","size":"15.8"},{"price":"0.85","size":"104.19"},{"price":"0.84","size":"24.69"},{"price":"0.83","size":"14.19"},{"price":"0.82","size":"13.8"},{"price":"0.81","size":"13.4"},{"price":"0.8","size":"38.1"},{"price":"0.79","size":"12.8"},{"price":"0.78","size":"12.6"},{"price":"0.77","size":"12.3"},{"price":"0.76","size":"22.1"},{"price":"0.75","size":"16.9"},{"price":"0.74","size":"21.8"},{"price":"0.73","size":"11.6"},{"price":"0.72","size":"11.4"},{"price":"0.71","size":"61.3"},{"price":"0.7","size":"26.2"},{"price":"0.69","size":"11.1"},{"price":"0.68","size":"11"},{"price":"0.67","size":"110.9"},{"price":"0.66","size":"10.8"},{"price":"0.65","size":"15.7"},{"price":"0.64","size":"10.6"},{"price":"0.63","size":"10.6"},{"price":"0.62","size":"22.5"},{"price":"0.61","size":"10.5"},{"price":"0.6","size":"45.4"},{"price":"0.59","size":"311.4"},{"price":"0.58","size":"820.82"},{"price":"0.57","size":"826.3"},{"price":"0.56","size":"1062.3"},{"price":"0.55","size":"582.3"},{"price":"0.54","size":"626.2"},{"price":"0.53","size":"562.2"},{"price":"0.52","size":"567.2"},{"price":"0.51","size":"573.2"},{"price":"0.5","size":"917.2"},{"price":"0.49","size":"597.2"},{"price":"0.48","size":"590.2"},{"price":"0.47","size":"567.2"},{"price":"0.46","size":"636.61"},{"price":"0.45","size":"362.97"},{"price":"0.44","size":"341.3"},{"price":"0.43","size":"320.62"},{"price":"0.42","size":"567.3"},{"price":"0.41","size":"562.4"},{"price":"0.4","size":"693.02"},{"price":"0.39","size":"593.5"},{"price":"0.38","size":"604.5"},{"price":"0.37","size":"672.32"},{"price":"0.36","size":"680.6"},{"price":"0.35","size":"536.14"},{"price":"0.34","size":"602.8"},{"price":"0.33","size":"572.9"},{"price":"0.32","size":"573"},{"price":"0.31","size":"595.1"},{"price":"0.3","size":"603.2"},{"price":"0.29","size":"1318.72"},{"price":"0.28","size":"1043.04"},{"price":"0.27","size":"668.6"},{"price":"0.26","size":"911.17"},{"price":"0.25","size":"694.3"},{"price":"0.24","size":"717.6"},{"price":"0.23","size":"1183.3"},{"price":"0.22","size":"1526.53"},{"price":"0.21","size":"1178.8"},{"price":"0.2","size":"1445.08"},{"price":"0.19","size":"1229.8"},{"price":"0.18","size":"1467.57"},{"price":"0.17","size":"1672.41"},{"price":"0.16","size":"1815.59"},{"price":"0.15","size":"1810.78"},{"price":"0.14","size":"1506.7"},{"price":"0.13","size":"1788.93"},{"price":"0.12","size":"2355.4"},{"price":"0.11","size":"1792.8"},{"price":"0.1","size":"3396.27"},{"price":"0.09","size":"3017.44"},{"price":"0.08","size":"2724.36"},{"price":"0.07","size":"1492.82"},{"price":"0.06","size":"1538.88"}],"hash":"7488a47533dd0ac419d4d138f34e43d1cab89f05","timestamp":"1768250236582","event_type":"book"}}
{"schema_version":1,"source":"clob_ws_market","recv_ts_ns":1768250236852564600,"event_type":"price_change","market":"0xe51aa24ab1bbfefce466d642ad98587d13123e4ef95ec9aa73b712e775d4cbba","server_ts_ms":1768250236584,"raw":{"market":"0xe51aa24ab1bbfefce466d642ad98587d13123e4ef95ec9aa73b712e775d4cbba","price_changes":[{"asset_id":"96886111393998001968863279421729456597655847484197549086072988901191634450924","price":"0.94","size":"1550.88","side":"BUY","hash":"ee7ff813919b40b9ecd5a71c5bce298b1c252e0b","best_bid":"0.94","best_ask":"0.95"},{"asset_id":"54232589582260339592359130012520874109228367674780084862642636038394766871668","price":"0.06","size":"1550.88","side":"SELL","hash":"de92250440a26ce19d6d55f924f9aff9e536d28d","best_bid":"0.05","best_ask":"0.06"}],"timestamp":"1768250236584","event_type":"price_change"}}
{"schema_version":1,"source":"clob_ws_market","recv_ts_ns":1768250236857223174,"event_type":"price_change","market":"0xe51aa24ab1bbfefce466d642ad98587d13123e4ef95ec9aa73b712e775d4cbba","server_ts_ms":1768250236585,"raw":{"market":"0xe51aa24ab1bbfefce466d642ad98587d13123e4ef95ec9aa73b712e775d4cbba","price_changes":[{"asset_id":"96886111393998001968863279421729456597655847484197549086072988901191634450924","price":"0.98","size":"6845.25","side":"SELL","hash":"f5f94e92fd72335aa8d9bdef990dc1ca47474097","best_bid":"0.94","best_ask":"0.95"},{"asset_id":"54232589582260339592359130012520874109228367674780084862642636038394766871668","price":"0.02","size":"6845.25","side":"BUY","hash":"04dab2a828899df792e89cbf421bbab0d59dc3ae","best_bid":"0.05","best_ask":"0.06"}],"timestamp":"1768250236585","event_type":"price_change"}}
{"schema_version":1,"source":"clob_ws_market","recv_ts_ns":1768250236861738845,"event_type":"price_change","market":"0xe51aa24ab1bbfefce466d642ad98587d13123e4ef95ec9aa73b712e775d4cbba","server_ts_ms":1768250236586,"raw":{"market":"0xe51aa24ab1bbfefce466d642ad98587d13123e4ef95ec9aa73b712e775d4cbba","price_changes":[{"asset_id":"54232589582260339592359130012520874109228367674780084862642636038394766871668","price":"0.01","size":"21038.91","side":"BUY","hash":"bba77ebf55f4850ea49416f9966205d53de032af","best_bid":"0.05","best_ask":"0.06"},{"asset_id":"96886111393998001968863279421729456597655847484197549086072988901191634450924","price":"0.99","size":"21038.91","side":"SELL","hash":"be2ed9c396bf75f940ca490e7ff73af94cb09a30","best_bid":"0.94","best_ask":"0.95"}],"timestamp":"1768250236586","event_type":"price_change"}}
{"schema_version":1,"source":"clob_ws_market","recv_ts_ns":1768250236866026401,"event_type":"price_change","market":"0xe51aa24ab1bbfefce466d642ad98587d13123e4ef95ec9aa73b712e775d4cbba","server_ts_ms":1768250236586,"raw":{"market":"0xe51aa24ab1bbfefce466d642ad98587d13123e4ef95ec9aa73b712e775d4cbba","price_changes":[{"asset_id":"54232589582260339592359130012520874109228367674780084862642636038394766871668","price":"0.01","size":"21138.91","side":"BUY","hash":"2dda99c77847534f4fa47a6720977165a688dc37","best_bid":"0.05","best_ask":"0.06"},{"asset_id":"96886111393998001968863279421729456597655847484197549086072988901191634450924","price":"0.99","size":"21138.91","side":"SELL","hash":"5ca62362d10461f575c3c49a82af81c2e3b36f7b","best_bid":"0.94","best_ask":"0.95"}],"timestamp":"1768250236586","event_type":"price_change"}}
{"schema_version":1,"source":"clob_ws_market","recv_ts_ns":1768250236870561023,"event_type":"price_change","market":"0xe51aa24ab1bbfefce466d642ad98587d13123e4ef95ec9aa73b712e775d4cbba","server_ts_ms":1768250236587,"raw":{"market":"0xe51aa24ab1bbfefce466d642ad98587d13123e4ef95ec9aa73b712e775d4cbba","price_changes":[{"asset_id":"96886111393998001968863279421729456597655847484197549086072988901191634450924","price":"0.99","size":"21113.91","side":"SELL","hash":"b0e45b2b0e0fb8103f46d45a1aeac0f4e4d5afdf","best_bid":"0.94","best_ask":"0.95"},{"asset_id":"54232589582260339592359130012520874109228367674780084862642636038394766871668","price":"0.01","size":"21113.91","side":"BUY","hash":"775f3ac689a7426154143f5c87688a7e6558fb71","best_bid":"0.05","best_ask":"0.06"}],"timestamp":"1768250236587","event_type":"price_change"}}
{"schema_version":1,"source":"clob_ws_market","recv_ts_ns":1768250236875235090,"event_type":"price_change","market":"0xe51aa24ab1bbfefce466d642ad98587d13123e4ef95ec9aa73b712e775d4cbba","server_ts_ms":1768250236587,"raw":{"market":"0xe51aa24ab1bbfefce466d642ad98587d13123e4ef95ec9aa73b712e775d4cbba","price_changes":[{"asset_id":"54232589582260339592359130012520874109228367674780084862642636038394766871668","price":"0.02","size":"6745.25","side":"BUY","hash":"51640b3d7b1837f0a92a72b56ff4166d1e820eac","best_bid":"0.05","best_ask":"0.06"},{"asset_id":"96886111393998001968863279421729456597655847484197549086072988901191634450924","price":"0.98","size":"6745.25","side":"SELL","hash":"69f5a0393b7b303850f2acda020295dbd14f93a0","best_bid":"0.94","best_ask":"0.95"}],"timestamp":"1768250236587","event_type":"price_change"}}
{"schema_version":1,"source":"clob_ws_market","recv_ts_ns":1768250236891136455,"event_type":"price_change","market":"0xe51aa24ab1bbfefce466d642ad98587d13123e4ef95ec9aa73b712e775d4cbba","server_ts_ms":1768250236596,"raw":{"market":"0xe51aa24ab1bbfefce466d642ad98587d13123e4ef95ec9aa73b712e775d4cbba","price_changes":[{"asset_id":"96886111393998001968863279421729456597655847484197549086072988901191634450924","price":"0.94","size":"1520.88","side":"BUY","hash":"7f04cd58470c2186bb0e1a595e1d7eac040b5589","best_bid":"0.94","best_ask":"0.95"},{"asset_id":"54232589582260339592359130012520874109228367674780084862642636038394766871668","price":"0.06","size":"1520.88","side":"SELL","hash":"4db833cb1800c96e9465213cdb70431c95f163b7","best_bid":"0.05","best_ask":"0.06"}],"timestamp":"1768250236596","event_type":"price_change"}}
{"schema_version":1,"source":"clob_ws_market","recv_ts_ns":1768250236895753900,"event_type":"price_change","market":"0xe51aa24ab1bbfefce466d642ad98587d13123e4ef95ec9aa73b712e775d4cbba","server_ts_ms":1768250236598,"raw":{"market":"0xe51aa24ab1bbfefce466d642ad98587d13123e4ef95ec9aa73b712e775d4cbba","price_changes":[{"asset_id":"96886111393998001968863279421729456597655847484197549086072988901191634450924","price":"0.94","size":"1508.88","side":"BUY","hash":"ffcd45e3b4f5a98b4ebaf015eccc4b7b3fb4310a","best_bid":"0.94","best_ask":"0.95"},{"asset_id":"54232589582260339592359130012520874109228367674780084862642636038394766871668","price":"0.06","size":"1508.88","side":"SELL","hash":"033f3291c582a250b7f16819aee45d958739efdb","best_bid":"0.05","best_ask":"0.06"}],"timestamp":"1768250236598","event_type":"price_change"}}
{"schema_version":1,"source":"clob_ws_market","recv_ts_ns":1768250236908396991,"event_type":"price_change","market":"0xe51aa24ab1bbfefce466d642ad98587d13123e4ef95ec9aa73b712e775d4cbba","server_ts_ms":1768250236605,"raw":{"market":"0xe51aa24ab1bbfefce466d642ad98587d13123e4ef95ec9aa73b712e775d4cbba","price_changes":[{"asset_id":"54232589582260339592359130012520874109228367674780084862642636038394766871668","price":"0.03","size":"1395.6","side":"BUY","hash":"911f572d3996120761fcb4c21e14609564cdbc1a","best_bid":"0.05","best_ask":"0.06"},{"asset_id":"96886111393998001968863279421729456597655847484197549086072988901191634450924","price":"0.97","size":"1395.6","side":"SELL","hash":"fc012f935cc858c5833c6cb73a05a00e12c58969","best_bid":"0.94","best_ask":"0.95"}],"timestamp":"1768250236605","event_type":"price_change"}}
{"schema_version":1,"source":"clob_ws_market","recv_ts_ns":1768250236920792145,"event_type":"last_trade_price","market":"0xe51aa24ab1bbfefce466d642ad98587d13123e4ef95ec9aa73b712e775d4cbba","server_ts_ms":1768250236608,"raw":{"market":"0xe51aa24ab1bbfefce466d642ad98587d13123e4ef95ec9aa73b712e775d4cbba","asset_id":"54232589582260339592359130012520874109228367674780084862642636038394766871668","price":"0.06","size":"58","fee_rate_bps":"1000","side":"BUY","timestamp":"1768250236608","event_type":"last_trade_price","transaction_hash":"0xbb700651b91c759e99e120ba22a0881a6400b424e3a72e4763c5ffe36db35581"}}
{"schema_version":1,"source":"clob_ws_market","recv_ts_ns":1768250236922333127,"event_type":"price_change","market":"0xe51aa24ab1bbfefce466d642ad98587d13123e4ef95ec9aa73b712e775d4cbba","server_ts_ms":1768250236607,"raw":{"market":"0xe51aa24ab1bbfefce466d642ad98587d13123e4ef95ec9aa73b712e775d4cbba","price_changes":[{"asset_id":"96886111393998001968863279421729456597655847484197549086072988901191634450924","price":"0.91","size":"3012.44","side":"BUY","hash":"6dbd74e7de22a2e9df7a8026e375bd9eed5f3c0a","best_bid":"0.94","best_ask":"0.95"},{"asset_id":"54232589582260339592359130012520874109228367674780084862642636038394766871668","price":"0.09","size":"3012.44","side":"SELL","hash":"67f1d3c3d05215b6968dfaee7f00f619f752fda9","best_bid":"0.05","best_ask":"0.06"}],"timestamp":"1768250236607","event_type":"price_change"}}
{"schema_version":1,"source":"clob_ws_market","recv_ts_ns":1768250236927006173,"event_type":"price_change","market":"0xe51aa24ab1bbfefce466d642ad98587d13123e4ef95ec9aa73b712e775d4cbba","server_ts_ms":1768250236607,"raw":{"market":"0xe51aa24ab1bbfefce466d642ad98587d13123e4ef95ec9aa73b712e775d4cbba","price_changes":[{"asset_id":"96886111393998001968863279421729456597655847484197549086072988901191634450924","price":"0.99","size":"21108.91","side":"SELL","hash":"6dbd74e7de22a2e9df7a8026e375bd9eed5f3c0a","best_bid":"0.94","best_ask":"0.95"},{"asset_id":"54232589582260339592359130012520874109228367674780084862642636038394766871668","price":"0.01","size":"21108.91","side":"BUY","hash":"67f1d3c3d05215b6968dfaee7f00f619f752fda9","best_bid":"0.05","best_ask":"0.06"}],"timestamp":"1768250236607","event_type":"price_change"}}
{"schema_version":1,"source":"clob_ws_market","recv_ts_ns":1768250236935526556,"event_type":"price_change","market":"0xe51aa24ab1bbfefce466d642ad98587d13123e4ef95ec9aa73b712e775d4cbba","server_ts_ms":1768250236632,"raw":{"market":"0xe51aa24ab1bbfefce466d642ad98587d13123e4ef95ec9aa73b712e775d4cbba","price_changes":[{"asset_id":"54232589582260339592359130012520874109228367674780084862642636038394766871668","price":"0.02","size":"6761.25","side":"BUY","hash":"25a7802486d6f3ba14310c0df6bf6779dc3ec22e","best_bid":"0.05","best_ask":"0.06"},{"asset_id":"96886111393998001968863279421729456597655847484197549086072988901191634450924","price":"0.98","size":"6761.25","side":"SELL","hash":"e46985293f0ed02369ac11320af39a58b2ba26c7","best_bid":"0.94","best_ask":"0.95"}],"timestamp":"1768250236632","event_type":"price_change"}}
{"schema_version":1,"source":"clob_ws_market","recv_ts_ns":1768250236939559158,"event_type":"price_change","market":"0xe51aa24ab1bbfefce466d642ad98587d13123e4ef95ec9aa73b712e775d4cbba","server_ts_ms":1768250236633,"raw":{"market":"0xe51aa24ab1bbfefce466d642ad98587d13123e4ef95ec9aa73b712e775d4cbba","price_changes":[{"asset_id":"54232589582260339592359130012520874109228367674780084862642636038394766871668","price":"0.05","size":"1578.07","side":"BUY","hash":"421f5c79a3da4dd611a00b19bcc9a76c1b962627","best_bid":"0.05","best_ask":"0.06"},{"asset_id":"96886111393998001968863279421729456597655847484197549086072988901191634450924","price":"0.95","size":"1578.07","side":"SELL","hash":"afda6a0316b2ca3a863405d8539d06baccf49e6d","best_bid":"0.94","best_ask":"0.95"}],"timestamp":"1768250236633","event_type":"price_change"}}
{"schema_version":1,"source":"clob_ws_market","recv_ts_ns":1768250236943602240,"event_type":"price_change","market":"0xe51aa24ab1bbfefce466d642ad98587d13123e4ef95ec9aa73b712e775d4cbba","server_ts_ms":1768250236636,"raw":{"market":"0xe51aa24ab1bbfefce466d642ad98587d13123e4ef95ec9aa73b712e775d4cbba","price_changes":[{"asset_id":"96886111393998001968863279421729456597655847484197549086072988901191634450924","price":"0.95","size":"1572.57","side":"SELL","hash":"671a60c3b1444dd78ca412435b427731efdaf83b","best_bid":"0.94","best_ask":"0.95"},{"asset_id":"54232589582260339592359130012520874109228367674780084862642636038394766871668","price":"0.05","size":"1572.57","side":"BUY","hash":"aa8bfebc6953371b16520f26da4994ccc41583f0","best_bid":"0.05","best_ask":"0.06"}],"timestamp":"1768250236636","event_type":"price_change"}}
{"schema_version":1,"source":"clob_ws_market","recv_ts_ns":1768250236947291035,"event_type":"price_change","market":"0xe51aa24ab1bbfefce466d642ad98587d13123e4ef95ec9aa73b712e775d4cbba","server_ts_ms":1768250236639,"raw":{"market":"0xe51aa24ab1bbfefce466d642ad98587d13123e4ef95ec9aa73b712e775d4cbba","price_changes":[{"asset_id":"96886111393998001968863279421729456597655847484197549086072988901191634450924","price":"0.95","size":"1567.07","side":"SELL","hash":"7e77c33e0fda0ed24c556e953139209f721e8cdd","best_bid":"0.94","best_ask":"0.95"},{"asset_id":"54232589582260339592359130012520874109228367674780084862642636038394766871668","price":"0.05","size":"1567.07","side":"BUY","hash":"acd572bf1668db13763de003ceae2d03b64de84c","best_bid":"0.05","best_ask":"0.06"}],"timestamp":"1768250236639","event_type":"price_change"}}
{"schema_version":1,"source":"clob_ws_market","recv_ts_ns":1768250236950621565,"event_type":"price_change","market":"0xe51aa24ab1bbfefce466d642ad98587d13123e4ef95ec9aa73b712e775d4cbba","server_ts_ms":1768250236643,"raw":{"market":"0xe51aa24ab1bbfefce466d642ad98587d13123e4ef95ec9aa73b712e775d4cbba","price_changes":[{"asset_id":"96886111393998001968863279421729456597655847484197549086072988901191634450924","price":"0.62","size":"636.5","side":"BUY","hash":"4f57d0b52f30a0cea09e95d939f4ef9fcd2658b4","best_bid":"0.94","best_ask":"0.95"},{"asset_id":"54232589582260339592359130012520874109228367674780084862642636038394766871668","price":"0.38","size":"636.5","side":"SELL","hash":"a8f339f6c17254fc0759bbaff6f1151dc4277d09","best_bid":"0.05","best_ask":"0.06"}],"timestamp":"1768250236643","event_type":"price_change"}}
{"schema_version":1,"source":"clob_ws_market","recv_ts_ns":1768250236953974111,"event_type":"price_change","market":"0xe51aa24ab1bbfefce466d642ad98587d13123e4ef95ec9aa73b712e775d4cbba","server_ts_ms":1768250236644,"raw":{"market":"0xe51aa24ab1bbfefce466d642ad98587d13123e4ef95ec9aa73b712e775d4cbba","price_changes":[{"asset_id":"54232589582260339592359130012520874109228367674780084862642636038394766871668","price":"0.01","size":"21092.91","side":"BUY","hash":"9a795e6e4f7c4676bb16e29a6597f4f7d0bdf617","best_bid":"0.05","best_ask":"0.06"},{"asset_id":"96886111393998001968863279421729456597655847484197549086072988901191634450924","price":"0.99","size":"21092.91","side":"SELL","hash":"9638e9cb8fa17130002ff2ce6f1c3b5308894ea5","best_bid":"0.94","best_ask":"0.95"}],"timestamp":"1768250236644","event_type":"price_change"}}
{"schema_version":1,"source":"clob_ws_market","recv_ts_ns":1768250236957349128,"event_type":"price_change","market":"0xe51aa24ab1bbfefce466d642ad98587d13123e4ef95ec9aa73b712e775d4cbba","server_ts_ms":1768250236645,"raw":{"market":"0xe51aa24ab1bbfefce466d642ad98587d13123e4ef95ec9aa73b712e775d4cbba","price_changes":[{"asset_id":"54232589582260339592359130012520874109228367674780084862642636038394766871668","price":"0.04","size":"293.9","side":"BUY","hash":"2bbf6f8c73024d75704a76297874f9339de95606","best_bid":"0.05","best_ask":"0.06"},{"asset_id":"96886111393998001968863279421729456597655847484197549086072988901191634450924","price":"0.96","size":"293.9","side":"SELL","hash":"9fccf6aa1ea150ea9d2e7773d2c0b948c16901ec","best_bid":"0.94","best_ask":"0.95"}],"timestamp":"1768250236645","event_type":"price_change"}}
{"schema_version":1,"source":"clob_ws_market","recv_ts_ns":1768250236961610684,"event_type":"price_change","market":"0xe51aa24ab1bbfefce466d642ad98587d13123e4ef95ec9aa73b712e775d4cbba","server_ts_ms":1768250236645,"raw":{"market":"0xe51aa24ab1bbfefce466d642ad98587d13123e4ef95ec9aa73b712e775d4cbba","price_changes":[{"asset_id":"54232589582260339592359130012520874109228367674780084862642636038394766871668","price":"0.02","size":"6745.25","side":"BUY","hash":"a194dee97f87899834f2051ffcbc08e7b1a0cb52","best_bid":"0.05","best_ask":"0.06"},{"asset_id":"96886111393998001968863279421729456597655847484197549086072988901191634450924","price":"0.98","size":"6745.25","side":"SELL","hash":"29f3d93a410f8da27975d4edddbf81f1f080a105","best_bid":"0.94","best_ask":"0.95"}],"timestamp":"1768250236645","event_type":"price_change"}}
{"schema_version":1,"source":"clob_ws_market","recv_ts_ns":1768250236964753707,"event_type":"price_change","market":"0xe51aa24ab1bbfefce466d642ad98587d13123e4ef95ec9aa73b712e775d4cbba","server_ts_ms":1768250236651,"raw":{"market":"0xe51aa24ab1bbfefce466d642ad98587d13123e4ef95ec9aa73b712e775d4cbba","price_changes":[{"asset_id":"96886111393998001968863279421729456597655847484197549086072988901191634450924","price":"0.9","size":"3402.27","side":"BUY","hash":"4a0423578a58461e8c2154ede22ff329d7678623","best_bid":"0.94","best_ask":"0.95"},{"asset_id":"54232589582260339592359130012520874109228367674780084862642636038394766871668","price":"0.1","size":"3402.27","side":"SELL","hash":"07efef7f5797eddf247cbad77425f412fddc921d","best_bid":"0.05","best_ask":"0.06"}],"timestamp":"1768250236651","event_type":"price_change"}}
{"schema_version":1,"source":"clob_ws_market","recv_ts_ns":1768250236968251733,"event_type":"price_change","market":"0xe51aa24ab1bbfefce466d642ad98587d13123e4ef95ec9aa73b712e775d4cbba","server_ts_ms":1768250236652,"raw":{"market":"0xe51aa24ab1bbfefce466d642ad98587d13123e4ef95ec9aa73b712e775d4cbba","price_changes":[{"asset_id":"96886111393998001968863279421729456597655847484197549086072988901191634450924","price":"0.99","size":"21097.91","side":"SELL","hash":"95a7308dd98dfe4795d31169a4889b13fc5bd3ed","best_bid":"0.94","best_ask":"0.95"},{"asset_id":"54232589582260339592359130012520874109228367674780084862642636038394766871668","price":"0.01","size":"21097.91","side":"BUY","hash":"c8aa172bfbedbf6da50c4273e6a3bb1f71073a12","best_bid":"0.05","best_ask":"0.06"}],"timestamp":"1768250236652","event_type":"price_change"}}
{"schema_version":1,"source":"clob_ws_market","recv_ts_ns":1768250236971479345,"event_type":"price_change","market":"0xe51aa24ab1bbfefce466d642ad98587d13123e4ef95ec9aa73b712e775d4cbba","server_ts_ms":1768250236653,"raw":{"market":"0xe51aa24ab1bbfefce466d642ad98587d13123e4ef95ec9aa73b712e775d4cbba","price_changes":[{"asset_id":"96886111393998001968863279421729456597655847484197549086072988901191634450924","price":"0.94","size":"1513.88","side":"BUY","hash":"a6688c290dda6aaa3bdaaa834a9155c93bb68a40","best_bid":"0.94","best_ask":"0.95"},{"asset_id":"54232589582260339592359130012520874109228367674780084862642636038394766871668","price":"0.06","size":"1513.88","side":"SELL","hash":"81c8aa67cbcdaf765b827e2ae288c0118cb3dce9","best_bid":"0.05","best_ask":"0.06"}],"timestamp":"1768250236653","event_type":"price_change"}}
{"schema_version":1,"source":"clob_ws_market","recv_ts_ns":1768250236979942740,"event_type":"price_change","market":"0xe51aa24ab1bbfefce466d642ad98587d13123e4ef95ec9aa73b712e775d4cbba","server_ts_ms":1768250236657,"raw":{"market":"0xe51aa24ab1bbfefce466d642ad98587d13123e4ef95ec9aa73b712e775d4cbba","price_changes":[{"asset_id":"96886111393998001968863279421729456597655847484197549086072988901191634450924","price":"0.94","size":"1533.88","side":"BUY","hash":"544a12a6f7ea01d39402bac1b4ebbd3969c65cef","best_bid":"0.94","best_ask":"0.95"},{"asset_id":"54232589582260339592359130012520874109228367674780084862642636038394766871668","price":"0.06","size":"1533.88","side":"SELL","hash":"bee002f9ff3f9add04207385076436f331e8ef88","best_bid":"0.05","best_ask":"0.06"}],"timestamp":"1768250236657","event_type":"price_change"}}
{"schema_version":1,"source":"clob_ws_market","recv_ts_ns":1768250236984560781,"event_type":"price_change","market":"0xe51aa24ab1bbfefce466d642ad98587d13123e4ef95ec9aa73b712e775d4cbba","server_ts_ms":1768250236663,"raw":{"market":"0xe51aa24ab1bbfefce466d642ad98587d13123e4ef95ec9aa73b712e775d4cbba","price_changes":[{"asset_id":"54232589582260339592359130012520874109228367674780084862642636038394766871668","price":"0.01","size":"20997.91","side":"BUY","hash":"57af862140c08ec7e9c3d2ed180bb1d406e09f70","best_bid":"0.05","best_ask":"0.06"},{"asset_id":"96886111393998001968863279421729456597655847484197549086072988901191634450924","price":"0.99","size":"20997.91","side":"SELL","hash":"fb97b96cb512179821ff3d3720b1fa464aa89380","best_bid":"0.94","best_ask":"0.95"}],"timestamp":"1768250236663","event_type":"price_change"}}
{"schema_version":1,"source":"clob_ws_market","recv_ts_ns":1768250236988954495,"event_type":"price_change","market":"0xe51aa24ab1bbfefce466d642ad98587d13123e4ef95ec9aa73b712e775d4cbba","server_ts_ms":1768250236665,"raw":{"market":"0xe51aa24ab1bbfefce466d642ad98587d13123e4ef95ec9aa73b712e775d4cbba","price_changes":[{"asset_id":"54232589582260339592359130012520874109228367674780084862642636038394766871668","price":"0.02","size":"6845.25","side":"BUY","hash":"96300eca71aa0f4f9c058681298ba0e017ac0c00","best_bid":"0.05","best_ask":"0.06"},{"asset_id":"96886111393998001968863279421729456597655847484197549086072988901191634450924","price":"0.98","size":"6845.25","side":"SELL","hash":"a19da1b4ad2afdd1ebe8e40246fe7adbd1072f1a","best_bid":"0.94","best_ask":"0.95"}],"timestamp":"1768250236665","event_type":"price_change"}}
{"schema_version":1,"source":"clob_ws_market","recv_ts_ns":1768250236996981605,"event_type":"price_change","market":"0xe51aa24ab1bbfefce466d642ad98587d13123e4ef95ec9aa73b712e775d4cbba","server_ts_ms":1768250236671,"raw":{"market":"0xe51aa24ab1bbfefce466d642ad98587d13123e4ef95ec9aa73b712e775d4cbba","price_changes":[{"asset_id":"96886111393998001968863279421729456597655847484197549086072988901191634450924","price":"0.96","size":"299.4","side":"SELL","hash":"d442de6c5012530a815197e60045ec0400846858","best_bid":"0.94","best_ask":"0.95"},{"asset_id":"54232589582260339592359130012520874109228367674780084862642636038394766871668","price":"0.04","size":"299.4","side":"BUY","hash":"64875612d316eb28d3de067fa2fdb84d746cbe09","best_bid":"0.05","best_ask":"0.06"}],"timestamp":"1768250236671","event_type":"price_change"}}
{"schema_version":1,"source":"clob_ws_market","recv_ts_ns":1768250237000946918,"event_type":"price_change","market":"0xe51aa24ab1bbfefce466d642ad98587d13123e4ef95ec9aa73b712e775d4cbba","server_ts_ms":1768250236709,"raw":{"market":"0xe51aa24ab1bbfefce466d642ad98587d13123e4ef95ec9aa73b712e775d4cbba","price_changes":[{"asset_id":"54232589582260339592359130012520874109228367674780084862642636038394766871668","price":"0.03","size":"1411.6","side":"BUY","hash":"885a892f8db8b88bdcd3ac39c25cc9441949c7e4","best_bid":"0.05","best_ask":"0.06"},{"asset_id":"96886111393998001968863279421729456597655847484197549086072988901191634450924","price":"0.97","size":"1411.6","side":"SELL","hash":"d1b0ccaec1b48b41129efd93234d5c064bf5a855","best_bid":"0.94","best_ask":"0.95"}],"timestamp":"1768250236709","event_type":"price_change"}}
{"schema_version":1,"source":"clob_ws_market","recv_ts_ns":1768250237004310814,"event_type":"price_change","market":"0xe51aa24ab1bbfefce466d642ad98587d13123e4ef95ec9aa73b712e775d4cbba","server_ts_ms":1768250236711,"raw":{"market":"0xe51aa24ab1bbfefce466d642ad98587d13123e4ef95ec9aa73b712e775d4cbba","price_changes":[{"asset_id":"54232589582260339592359130012520874109228367674780084862642636038394766871668","price":"0.01","size":"21013.91","side":"BUY","hash":"16b32068ee556cca6a4f230cd7627ac519a78cd0","best_bid":"0.05","best_ask":"0.06"},{"asset_id":"96886111393998001968863279421729456597655847484197549086072988901191634450924","price":"0.99","size":"21013.91","side":"SELL","hash":"a8f3f0a19d79c7a2027ed49e4cd7026aaa5baaac","best_bid":"0.94","best_ask":"0.95"}],"timestamp":"1768250236711","event_type":"price_change"}}
{"schema_version":1,"source":"clob_ws_market","recv_ts_ns":1768250237008110732,"event_type":"price_change","market":"0xe51aa24ab1bbfefce466d642ad98587d13123e4ef95ec9aa73b712e775d4cbba","server_ts_ms":1768250236711,"raw":{"market":"0xe51aa24ab1bbfefce466d642ad98587d13123e4ef95ec9aa73b712e775d4cbba","price_changes":[{"asset_id":"54232589582260339592359130012520874109228367674780084862642636038394766871668","price":"0.17","size":"1520.51","side":"SELL","hash":"1cc22669688de231bed31d1b4645828d978bee84","best_bid":"0.05","best_ask":"0.06"},{"asset_id":"96886111393998001968863279421729456597655847484197549086072988901191634450924","price":"0.83","size":"1520.51","side":"BUY","hash":"b4e89878d4e422307fa400a59b39099d0017ddb2","best_bid":"0.94","best_ask":"0.95"}],"timestamp":"1768250236711","event_type":"price_change"}}
{"schema_version":1,"source":"clob_ws_market","recv_ts_ns":1768250237018902941,"event_type":"price_change","market":"0xe51aa24ab1bbfefce466d642ad98587d13123e4ef95ec9aa73b712e775d4cbba","server_ts_ms":1768250236772,"raw":{"market":"0xe51aa24ab1bbfefce466d642ad98587d13123e4ef95ec9aa73b712e775d4cbba","price_changes":[{"asset_id":"54232589582260339592359130012520874109228367674780084862642636038394766871668","price":"0.16","size":"1967.49","side":"SELL","hash":"335620b6bb8982853d3473a331d336c4dd9d366f","best_bid":"0.05","best_ask":"0.06"},{"asset_id":"96886111393998001968863279421729456597655847484197549086072988901191634450924","price":"0.84","size":"1967.49","side":"BUY","hash":"767d0404dec3dec4c0fa1bfe36dd1f134284294e","best_bid":"0.94","best_ask":"0.95"}],"timestamp":"1768250236772","event_type":"price_change"}}
{"schema_version":1,"source":"clob_ws_market","recv_ts_ns":1768250237025151857,"event_type":"price_change","market":"0xe51aa24ab1bbfefce466d642ad98587d13123e4ef95ec9aa73b712e775d4cbba","server_ts_ms":1768250236779,"raw":{"market":"0xe51aa24ab1bbfefce466d642ad98587d13123e4ef95ec9aa73b712e775d4cbba","price_changes":[{"asset_id":"54232589582260339592359130012520874109228367674780084862642636038394766871668","price":"0.01","size":"21029.91","side":"BUY","hash":"1480c5b82d6593a0c6a73ea82ac5967357b5f384","best_bid":"0.05","best_ask":"0.06"},{"asset_id":"96886111393998001968863279421729456597655847484197549086072988901191634450924","price":"0.99","size":"21029.91","side":"SELL","hash":"e2daab3584f9eaf8af064d7c324c3b16bdcffc20","best_bid":"0.94","best_ask":"0.95"}],"timestamp":"1768250236779","event_type":"price_change"}}
{"schema_version":1,"source":"clob_ws_market","recv_ts_ns":1768250237057366164,"event_type":"price_change","market":"0xe51aa24ab1bbfefce466d642ad98587d13123e4ef95ec9aa73b712e775d4cbba","server_ts_ms":1768250236856,"raw":{"market":"0xe51aa24ab1bbfefce466d642ad98587d13123e4ef95ec9aa73b712e775d4cbba","price_changes":[{"asset_id":"54232589582260339592359130012520874109228367674780084862642636038394766871668","price":"0.02","size":"6544.25","side":"BUY","hash":"375d3dd37fe26825dc000df7d7005593ede823be","best_bid":"0.05","best_ask":"0.06"},{"asset_id":"96886111393998001968863279421729456597655847484197549086072988901191634450924","price":"0.98","size":"6544.25","side":"SELL","hash":"3bbc6662598f48a229a20ede263ceb79651c0c48","best_bid":"0.94","best_ask":"0.95"}],"timestamp":"1768250236856","event_type":"price_change"}}
{"schema_version":1,"source":"clob_ws_market","recv_ts_ns":1768250237062015296,"event_type":"price_change","market":"0xe51aa24ab1bbfefce466d642ad98587d13123e4ef95ec9aa73b712e775d4cbba","server_ts_ms":1768250236857,"raw":{"market":"0xe51aa24ab1bbfefce466d642ad98587d13123e4ef95ec9aa73b712e775d4cbba","price_changes":[{"asset_id":"54232589582260339592359130012520874109228367674780084862642636038394766871668","price":"0.03","size":"1160.6","side":"BUY","hash":"0d027da3d1a0c1b5499c9bcdce0008e942699881","best_bid":"0.05","best_ask":"0.06"},{"asset_id":"96886111393998001968863279421729456597655847484197549086072988901191634450924","price":"0.97","size":"1160.6","side":"SELL","hash":"18ae66cc12a54271bb3e95f4c9fe435decf2ed01","best_bid":"0.94","best_ask":"0.95"}],"timestamp":"1768250236857","event_type":"price_change"}}
{"schema_version":1,"source":"clob_ws_market","recv_ts_ns":1768250237066984861,"event_type":"price_change","market":"0xe51aa24ab1bbfefce466d642ad98587d13123e4ef95ec9aa73b712e775d4cbba","server_ts_ms":1768250236879,"raw":{"market":"0xe51aa24ab1bbfefce466d642ad98587d13123e4ef95ec9aa73b712e775d4cbba","price_changes":[{"asset_id":"96886111393998001968863279421729456597655847484197549086072988901191634450924","price":"0.73","size":"663.6","side":"BUY","hash":"b38c2916aeef870a737b7e9d11e2011b6310af51","best_bid":"0.94","best_ask":"0.95"},{"asset_id":"54232589582260339592359130012520874109228367674780084862642636038394766871668","price":"0.27","size":"663.6","side":"SELL","hash":"95b97069c01fa325c22a6554073a9fe4d4ce8fb6","best_bid":"0.05","best_ask":"0.06"}],"timestamp":"1768250236879","event_type":"price_change"}}
{"schema_version":1,"source":"clob_ws_market","recv_ts_ns":1768250237076561134,"event_type":"price_change","market":"0xe51aa24ab1bbfefce466d642ad98587d13123e4ef95ec9aa73b712e775d4cbba","server_ts_ms":1768250236998,"raw":{"market":"0xe51aa24ab1bbfefce466d642ad98587d13123e4ef95ec9aa73b712e775d4cbba","price_changes":[{"asset_id":"54232589582260339592359130012520874109228367674780084862642636038394766871668","price":"0.02","size":"6518.25","side":"BUY","hash":"4b9e4e984339d422353e27a5ae59e94e898a053b","best_bid":"0.05","best_ask":"0.06"},{"asset_id":"96886111393998001968863279421729456597655847484197549086072988901191634450924","price":"0.98","size":"6518.25","side":"SELL","hash":"aa320c94a756109e964a9d2725a26f8b5e9f3aa9","best_bid":"0.94","best_ask":"0.95"}],"timestamp":"1768250236998","event_type":"price_change"}}
{"schema_version":1,"source":"clob_ws_market","recv_ts_ns":1768250237081269481,"event_type":"best_bid_ask","market":"0xe51aa24ab1bbfefce466d642ad98587d13123e4ef95ec9aa73b712e775d4cbba","server_ts_ms":1768250237046,"raw":{"market":"0xe51aa24ab1bbfefce466d642ad98587d13123e4ef95ec9aa73b712e775d4cbba","asset_id":"54232589582260339592359130012520874109228367674780084862642636038394766871668","best_bid":"0.05","best_ask":"0.06","spread":"0.01","timestamp":"1768250237046","event_type":"best_bid_ask"}}
{"schema_version":1,"source":"clob_ws_market","recv_ts_ns":1768250237086580597,"event_type":"price_change","market":"0xe51aa24ab1bbfefce466d642ad98587d13123e4ef95ec9aa73b712e775d4cbba","server_ts_ms":1768250237044,"raw":{"market":"0xe51aa24ab1bbfefce466d642ad98587d13123e4ef95ec9aa73b712e775d4cbba","price_changes":[{"asset_id":"96886111393998001968863279421729456597655847484197549086072988901191634450924","price":"0.94","size":"1528.88","side":"BUY","hash":"ddb05f45e5e789189807cf78611881e089f843eb","best_bid":"0.94","best_ask":"0.95"},{"asset_id":"54232589582260339592359130012520874109228367674780084862642636038394766871668","price":"0.06","size":"1528.88","side":"SELL","hash":"644cf490b1b9a7ca51a8f6d8e7d5145f6ee09e62","best_bid":"0.05","best_ask":"0.06"}],"timestamp":"1768250237044","event_type":"price_change"}}
{"schema_version":1,"source":"clob_ws_market","recv_ts_ns":1768250237091122254,"event_type":"book","market":"0xe51aa24ab1bbfefce466d642ad98587d13123e4ef95ec9aa73b712e775d4cbba","server_ts_ms":1768250237044,"raw":{"market":"0xe51aa24ab1bbfefce466d642ad98587d13123e4ef95ec9aa73b712e775d4cbba","asset_id":"54232589582260339592359130012520874109228367674780084862642636038394766871668","bids":[{"price":"0.01","size":"21029.91"},{"price":"0.02","size":"6518.25"},{"price":"0.03","size":"1160.6"},{"price":"0.04","size":"299.4"},{"price":"0.05","size":"1567.07"}],"asks":[{"price":"0.99","size":"24280.24"},{"price":"0.98","size":"7594.51"},{"price":"0.97","size":"5964.69"},{"price":"0.96","size":"5411.4"},{"price":"0.95","size":"5356.39"},{"price":"0.94","size":"5328"},{"price":"0.93","size":"5039.28"},{"price":"0.92","size":"5022.7"},{"price":"0.91","size":"5320.9"},{"price":"0.9","size":"5158.44"},{"price":"0.89","size":"18.3"},{"price":"0.88","size":"30.3"},{"price":"0.87","size":"16.5"},{"price":"0.86","size":"15.8"},{"price":"0.85","size":"104.19"},{"price":"0.84","size":"24.69"},{"price":"0.83","size":"14.19"},{"price":"0.82","size":"13.8"},{"price":"0.81","size":"13.4"},{"price":"0.8","size":"38.1"},{"price":"0.79","size":"12.8"},{"price":"0.78","size":"12.6"},{"price":"0.77","size":"12.3"},{"price":"0.76","size":"22.1"},{"price":"0.75","size":"16.9"},{"price":"0.74","size":"21.8"},{"price":"0.73","size":"11.6"},{"price":"0.72","size":"11.4"},{"price":"0.71","size":"61.3"},{"price":"0.7","size":"26.2"},{"price":"0.69","size":"11.1"},{"price":"0.68","size":"11"},{"price":"0.67","size":"110.9"},{"price":"0.66","size":"10.8"},{"price":"0.65","size":"15.7"},{"price":"0.64","size":"10.6"},{"price":"0.63","size":"10.6"},{"price":"0.62","size":"22.5"},{"price":"0.61","size":"10.5"},{"price":"0.6","size":"45.4"},{"price":"0.59","size":"311.4"},{"price":"0.58","size":"820.82"},{"price":"0.57","size":"826.3"},{"price":"0.56","size":"1062.3"},{"price":"0.55","size":"582.3"},{"price":"0.54","size":"626.2"},{"price":"0.53","size":"562.2"},{"price":"0.52","size":"567.2"},{"price":"0.51","size":"573.2"},{"price":"0.5","size":"917.2"},{"price":"0.49","size":"597.2"},{"price":"0.48","size":"590.2"},{"price":"0.47","size":"567.2"},{"price":"0.46","size":"636.61"},{"price":"0.45","size":"362.97"},{"price":"0.44","size":"341.3"},{"price":"0.43","size":"320.62"},{"price":"0.42","size":"567.3"},{"price":"0.41","size":"562.4"},{"price":"0.4","size":"693.02"},{"price":"0.39","size":"593.5"},{"price":"0.38","size":"636.5"},{"price":"0.37","size":"672.32"},{"price":"0.36","size":"680.6"},{"price":"0.35","size":"536.14"},{"price":"0.34","size":"602.8"},{"price":"0.33","size":"572.9"},{"price":"0.32","size":"573"},{"price":"0.31","size":"595.1"},{"price":"0.3","size":"603.2"},{"price":"0.29","size":"1318.72"},{"price":"0.28","size":"1043.04"},{"price":"0.27","size":"663.6"},{"price":"0.26","size":"911.17"},{"price":"0.25","size":"694.3"},{"price":"0.24","size":"717.6"},{"price":"0.23","size":"1183.3"},{"price":"0.22","size":"1526.53"},{"price":"0.21","size":"1178.8"},{"price":"0.2","size":"1445.08"},{"price":"0.19","size":"1229.8"},{"price":"0.18","size":"1467.57"},{"price":"0.17","size":"1520.51"},{"price":"0.16","size":"1967.49"},{"price":"0.15","size":"1810.78"},{"price":"0.14","size":"1506.7"},{"price":"0.13","size":"1788.93"},{"price":"0.12","size":"2355.4"},{"price":"0.11","size":"1792.8"},{"price":"0.1","size":"3402.27"},{"price":"0.09","size":"3012.44"},{"price":"0.08","size":"2724.36"},{"price":"0.07","size":"1492.82"},{"price":"0.06","size":"1528.88"}],"hash":"644cf490b1b9a7ca51a8f6d8e7d5145f6ee09e62","timestamp":"1768250237044","event_type":"book"}}
{"schema_version":1,"source":"clob_ws_market","recv_ts_ns":1768250237097196912,"event_type":"price_change","market":"0xe51aa24ab1bbfefce466d642ad98587d13123e4ef95ec9aa73b712e775d4cbba","server_ts_ms":1768250237047,"raw":{"market":"0xe51aa24ab1bbfefce466d642ad98587d13123e4ef95ec9aa73b712e775d4cbba","price_changes":[{"asset_id":"54232589582260339592359130012520874109228367674780084862642636038394766871668","price":"0.02","size":"6546.25","side":"BUY","hash":"5871a41b4b607551cf20f4a62d1469cc95943705","best_bid":"0.05","best_ask":"0.06"},{"asset_id":"96886111393998001968863279421729456597655847484197549086072988901191634450924","price":"0.98","size":"6546.25","side":"SELL","hash":"45b53d9dca33cdf22beabd915517f84e44eee84f","best_bid":"0.94","best_ask":"0.95"}],"timestamp":"1768250237047","event_type":"price_change"}}
{"schema_version":1,"source":"clob_ws_market","recv_ts_ns":1768250237118199724,"event_type":"last_trade_price","market":"0xe51aa24ab1bbfefce466d642ad98587d13123e4ef95ec9aa73b712e775d4cbba","server_ts_ms":1768250237076,"raw":{"market":"0xe51aa24ab1bbfefce466d642ad98587d13123e4ef95ec9aa73b712e775d4cbba","asset_id":"54232589582260339592359130012520874109228367674780084862642636038394766871668","price":"0.06","size":"5","fee_rate_bps":"1000","side":"BUY","timestamp":"1768250237076","event_type":"last_trade_price","transaction_hash":"0xfc3303e8bb302844626f45571657a527084482a23b969805e13d41bdaa6ace83"}}
{"schema_version":1,"source":"clob_ws_market","recv_ts_ns":1768250237164758725,"event_type":"price_change","market":"0xe51aa24ab1bbfefce466d642ad98587d13123e4ef95ec9aa73b712e775d4cbba","server_ts_ms":1768250237137,"raw":{"market":"0xe51aa24ab1bbfefce466d642ad98587d13123e4ef95ec9aa73b712e775d4cbba","price_changes":[{"asset_id":"54232589582260339592359130012520874109228367674780084862642636038394766871668","price":"0.06","size":"1517.88","side":"SELL","hash":"19efcefb01ee4a9285d775175b6102ff29eec25e","best_bid":"0.05","best_ask":"0.06"},{"asset_id":"96886111393998001968863279421729456597655847484197549086072988901191634450924","price":"0.94","size":"1517.88","side":"BUY","hash":"5ae3c575de220cccd5eb3835ab0e00cfeb3ecd94","best_bid":"0.94","best_ask":"0.95"}],"timestamp":"1768250237137","event_type":"price_change"}}
{"schema_version":1,"source":"clob_ws_market","recv_ts_ns":1768250237177396168,"event_type":"price_change","market":"0xe51aa24ab1bbfefce466d642ad98587d13123e4ef95ec9aa73b712e775d4cbba","server_ts_ms":1768250237150,"raw":{"market":"0xe51aa24ab1bbfefce466d642ad98587d13123e4ef95ec9aa73b712e775d4cbba","price_changes":[{"asset_id":"96886111393998001968863279421729456597655847484197549086072988901191634450924","price":"0.94","size":"1533.88","side":"BUY","hash":"0db46787b3c479f281fb51ee9f0295c037eae182","best_bid":"0.94","best_ask":"0.95"},{"asset_id":"54232589582260339592359130012520874109228367674780084862642636038394766871668","price":"0.06","size":"1533.88","side":"SELL","hash":"b121c164b4359a32ca6c25fb21ee796bfb7b7961","best_bid":"0.05","best_ask":"0.06"}],"timestamp":"1768250237150","event_type":"price_change"}}
{"schema_version":1,"source":"clob_ws_market","recv_ts_ns":1768250237182638477,"event_type":"price_change","market":"0xe51aa24ab1bbfefce466d642ad98587d13123e4ef95ec9aa73b712e775d4cbba","server_ts_ms":1768250237151,"raw":{"market":"0xe51aa24ab1bbfefce466d642ad98587d13123e4ef95ec9aa73b712e775d4cbba","price_changes":[{"asset_id":"96886111393998001968863279421729456597655847484197549086072988901191634450924","price":"0.94","size":"1521.88","side":"BUY","hash":"d48c1a560c7522f44de6cf3bc3de8f8abbfbd4b6","best_bid":"0.94","best_ask":"0.95"},{"asset_id":"54232589582260339592359130012520874109228367674780084862642636038394766871668","price":"0.06","size":"1521.88","side":"SELL","hash":"1ff089d910c2992f2b0c8da04173446d26bde16d","best_bid":"0.05","best_ask":"0.06"}],"timestamp":"1768250237151","event_type":"price_change"}}
{"schema_version":1,"source":"clob_ws_market","recv_ts_ns":1768250237188912827,"event_type":"price_change","market":"0xe51aa24ab1bbfefce466d642ad98587d13123e4ef95ec9aa73b712e775d4cbba","server_ts_ms":1768250237160,"raw":{"market":"0xe51aa24ab1bbfefce466d642ad98587d13123e4ef95ec9aa73b712e775d4cbba","price_changes":[{"asset_id":"96886111393998001968863279421729456597655847484197549086072988901191634450924","price":"0.94","size":"1491.88","side":"BUY","hash":"8d08cbff1f7935f8f51e044c98e3b647dbf30f2b","best_bid":"0.94","best_ask":"0.95"},{"asset_id":"54232589582260339592359130012520874109228367674780084862642636038394766871668","price":"0.06","size":"1491.88","side":"SELL","hash":"3c278efa46656c19cbaf4fa9671e147ab714aa34","best_bid":"0.05","best_ask":"0.06"}],"timestamp":"1768250237160","event_type":"price_change"}}
{"schema_version":1,"source":"clob_ws_market","recv_ts_ns":1768250237211228698,"event_type":"price_change","market":"0xe51aa24ab1bbfefce466d642ad98587d13123e4ef95ec9aa73b712e775d4cbba","server_ts_ms":1768250237176,"raw":{"market":"0xe51aa24ab1bbfefce466d642ad98587d13123e4ef95ec9aa73b712e775d4cbba","price_changes":[{"asset_id":"54232589582260339592359130012520874109228367674780084862642636038394766871668","price":"0.03","size":"2160.6","side":"BUY","hash":"22666d6064d0a7bed38e63e4cb7b70d46c3b17a8","best_bid":"0.05","best_ask":"0.06"},{"asset_id":"96886111393998001968863279421729456597655847484197549086072988901191634450924","price":"0.97","size":"2160.6","side":"SELL","hash":"adfad09cdec3e6cbbc7d27a4b6e4a37a1d20022d","best_bid":"0.94","best_ask":"0.95"}],"timestamp":"1768250237176","event_type":"price_change"}}
{"schema_version":1,"source":"clob_ws_market","recv_ts_ns":1768250237218659440,"event_type":"price_change","market":"0xe51aa24ab1bbfefce466d642ad98587d13123e4ef95ec9aa73b712e775d4cbba","server_ts_ms":1768250237188,"raw":{"market":"0xe51aa24ab1bbfefce466d642ad98587d13123e4ef95ec9aa73b712e775d4cbba","price_changes":[{"asset_id":"96886111393998001968863279421729456597655847484197549086072988901191634450924","price":"0.99","size":"21039.9","side":"SELL","hash":"1d4059b1b28530f89a8d2f17c27fb83f88192e0e","best_bid":"0.94","best_ask":"0.95"},{"asset_id":"54232589582260339592359130012520874109228367674780084862642636038394766871668","price":"0.01","size":"21039.9","side":"BUY","hash":"705c0cb532769339e52883a1daf029623e4fb0d4","best_bid":"0.05","best_ask":"0.06"}],"timestamp":"1768250237188","event_type":"price_change"}}
{"schema_version":1,"source":"clob_ws_market","recv_ts_ns":1768250237410910280,"event_type":"best_bid_ask","market":"0xe51aa24ab1bbfefce466d642ad98587d13123e4ef95ec9aa73b712e775d4cbba","server_ts_ms":1768250237246,"raw":{"market":"0xe51aa24ab1bbfefce466d642ad98587d13123e4ef95ec9aa73b712e775d4cbba","asset_id":"54232589582260339592359130012520874109228367674780084862642636038394766871668","best_bid":"0.05","best_ask":"0.06","spread":"0.01","timestamp":"1768250237246","event_type":"best_bid_ask"}}
{"schema_version":1,"source":"clob_ws_market","recv_ts_ns":1768250237416544393,"event_type":"price_change","market":"0xe51aa24ab1bbfefce466d642ad98587d13123e4ef95ec9aa73b712e775d4cbba","server_ts_ms":1768250237243,"raw":{"market":"0xe51aa24ab1bbfefce466d642ad98587d13123e4ef95ec9aa73b712e775d4cbba","price_changes":[{"asset_id":"54232589582260339592359130012520874109228367674780084862642636038394766871668","price":"0.05","size":"1556.54","side":"BUY","hash":"f0848a181f8d7d77ffb2b331f9e8ed9fc7e4bceb","best_bid":"0.05","best_ask":"0.06"},{"asset_id":"96886111393998001968863279421729456597655847484197549086072988901191634450924","price":"0.95","size":"1556.54","side":"SELL","hash":"b38b51434291d7f0da0476fc9d67194ce02f37b2","best_bid":"0.94","best_ask":"0.95"}],"timestamp":"1768250237243","event_type":"price_change"}}
{"schema_version":1,"source":"clob_ws_market","recv_ts_ns":1768250237421608661,"event_type":"book","market":"0xe51aa24ab1bbfefce466d642ad98587d13123e4ef95ec9aa73b712e775d4cbba","server_ts_ms":1768250237243,"raw":{"market":"0xe51aa24ab1bbfefce466d642ad98587d13123e4ef95ec9aa73b712e775d4cbba","asset_id":"54232589582260339592359130012520874109228367674780084862642636038394766871668","bids":[{"price":"0.01","size":"21039.9"},{"price":"0.02","size":"6546.25"},{"price":"0.03","size":"2160.6"},{"price":"0.04","size":"299.4"},{"price":"0.05","size":"1556.54"}],"asks":[{"price":"0.99","size":"24280.24"},{"price":"0.98","size":"7594.51"},{"price":"0.97","size":"5964.69"},{"price":"0.96","size":"5411.4"},{"price":"0.95","size":"5356.39"},{"price":"0.94","size":"5328"},{"price":"0.93","size":"5039.28"},{"price":"0.92","size":"5022.7"},{"price":"0.91","size":"5320.9"},{"price":"0.9","size":"5158.44"},{"price":"0.89","size":"18.3"},{"price":"0.88","size":"30.3"},{"price":"0.87","size":"16.5"},{"price":"0.86","size":"15.8"},{"price":"0.85","size":"104.19"},{"price":"0.84","size":"24.69"},{"price":"0.83","size":"14.19"},{"price":"0.82","size":"13.8"},{"price":"0.81","size":"13.4"},{"price":"0.8","size":"38.1"},{"price":"0.79","size":"12.8"},{"price":"0.78","size":"12.6"},{"price":"0.77","size":"12.3"},{"price":"0.76","size":"22.1"},{"price":"0.75","size":"16.9"},{"price":"0.74","size":"21.8"},{"price":"0.73","size":"11.6"},{"price":"0.72","size":"11.4"},{"price":"0.71","size":"61.3"},{"price":"0.7","size":"26.2"},{"price":"0.69","size":"11.1"},{"price":"0.68","size":"11"},{"price":"0.67","size":"110.9"},{"price":"0.66","size":"10.8"},{"price":"0.65","size":"15.7"},{"price":"0.64","size":"10.6"},{"price":"0.63","size":"10.6"},{"price":"0.62","size":"22.5"},{"price":"0.61","size":"10.5"},{"price":"0.6","size":"45.4"},{"price":"0.59","size":"311.4"},{"price":"0.58","size":"820.82"},{"price":"0.57","size":"826.3"},{"price":"0.56","size":"1062.3"},{"price":"0.55","size":"582.3"},{"price":"0.54","size":"626.2"},{"price":"0.53","size":"562.2"},{"price":"0.52","size":"567.2"},{"price":"0.51","size":"573.2"},{"price":"0.5","size":"917.2"},{"price":"0.49","size":"597.2"},{"price":"0.48","size":"590.2"},{"price":"0.47","size":"567.2"},{"price":"0.46","size":"636.61"},{"price":"0.45","size":"362.97"},{"price":"0.44","size":"341.3"},{"price":"0.43","size":"320.62"},{"price":"0.42","size":"567.3"},{"price":"0.41","size":"562.4"},{"price":"0.4","size":"693.02"},{"price":"0.39","size":"593.5"},{"price":"0.38","size":"636.5"},{"price":"0.37","size":"672.32"},{"price":"0.36","size":"680.6"},{"price":"0.35","size":"536.14"},{"price":"0.34","size":"602.8"},{"price":"0.33","size":"572.9"},{"price":"0.32","size":"573"},{"price":"0.31","size":"595.1"},{"price":"0.3","size":"603.2"},{"price":"0.29","size":"1318.72"},{"price":"0.28","size":"1043.04"},{"price":"0.27","size":"663.6"},{"price":"0.26","size":"911.17"},{"price":"0.25","size":"694.3"},{"price":"0.24","size":"717.6"},{"price":"0.23","size":"1183.3"},{"price":"0.22","size":"1526.53"},{"price":"0.21","size":"1178.8"},{"price":"0.2","size":"1445.08"},{"price":"0.19","size":"1229.8"},{"price":"0.18","size":"1467.57"},{"price":"0.17","size":"1520.51"},{"price":"0.16","size":"1967.49"},{"price":"0.15","size":"1810.78"},{"price":"0.14","size":"1506.7"},{"price":"0.13","size":"1788.93"},{"price":"0.12","size":"2355.4"},{"price":"0.11","size":"1792.8"},{"price":"0.1","size":"3402.27"},{"price":"0.09","size":"3012.44"},{"price":"0.08","size":"2724.36"},{"price":"0.07","size":"1492.82"},{"price":"0.06","size":"1491.88"}],"hash":"f0848a181f8d7d77ffb2b331f9e8ed9fc7e4bceb","timestamp":"1768250237243","event_type":"book"}}
{"schema_version":1,"source":"clob_ws_market","recv_ts_ns":1768250237447850157,"event_type":"price_change","market":"0xe51aa24ab1bbfefce466d642ad98587d13123e4ef95ec9aa73b712e775d4cbba","server_ts_ms":1768250237252,"raw":{"market":"0xe51aa24ab1bbfefce466d642ad98587d13123e4ef95ec9aa73b712e775d4cbba","price_changes":[{"asset_id":"54232589582260339592359130012520874109228367674780084862642636038394766871668","price":"0.99","size":"24290.24","side":"SELL","hash":"7a5b49de4a2aaceb1aa76b50a0d76bb8e5cfb0b8","best_bid":"0.05","best_ask":"0.06"},{"asset_id":"96886111393998001968863279421729456597655847484197549086072988901191634450924","price":"0.01","size":"24290.24","side":"BUY","hash":"7ad620dd4803c5127744d4fd58bb855ddad46b57","best_bid":"0.94","best_ask":"0.95"}],"timestamp":"1768250237252","event_type":"price_change"}}
{"schema_version":1,"source":"clob_ws_market","recv_ts_ns":1768250237542120567,"event_type":"price_change","market":"0xe51aa24ab1bbfefce466d642ad98587d13123e4ef95ec9aa73b712e775d4cbba","server_ts_ms":1768250237411,"raw":{"market":"0xe51aa24ab1bbfefce466d642ad98587d13123e4ef95ec9aa73b712e775d4cbba","price_changes":[{"asset_id":"54232589582260339592359130012520874109228367674780084862642636038394766871668","price":"0.02","size":"6518.25","side":"BUY","hash":"89e77939ce25159fc7a588275ba23d48f8bece73","best_bid":"0.05","best_ask":"0.06"},{"asset_id":"96886111393998001968863279421729456597655847484197549086072988901191634450924","price":"0.98","size":"6518.25","side":"SELL","hash":"10e6422e3ca8f93e44ebc8bc4d1a6bd8de27fb02","best_bid":"0.94","best_ask":"0.95"}],"timestamp":"1768250237411","event_type":"price_change"}}
{"schema_version":1,"source":"clob_ws_market","recv_ts_ns":1768250237584591086,"event_type":"price_change","market":"0xe51aa24ab1bbfefce466d642ad98587d13123e4ef95ec9aa73b712e775d4cbba","server_ts_ms":1768250237505,"raw":{"market":"0xe51aa24ab1bbfefce466d642ad98587d13123e4ef95ec9aa73b712e775d4cbba","price_changes":[{"asset_id":"54232589582260339592359130012520874109228367674780084862642636038394766871668","price":"0.01","size":"21023.9","side":"BUY","hash":"2b418b94a25b43fcadd151743997beef0aa2bab9","best_bid":"0.05","best_ask":"0.06"},{"asset_id":"96886111393998001968863279421729456597655847484197549086072988901191634450924","price":"0.99","size":"21023.9","side":"SELL","hash":"8e3f0a8a22dd674d89fc38d9662d9c2730da33dd","best_bid":"0.94","best_ask":"0.95"}],"timestamp":"1768250237505","event_type":"price_change"}}
{"schema_version":1,"source":"clob_ws_market","recv_ts_ns":1768250237641376916,"event_type":"price_change","market":"0xe51aa24ab1bbfefce466d642ad98587d13123e4ef95ec9aa73b712e775d4cbba","server_ts_ms":1768250237571,"raw":{"market":"0xe51aa24ab1bbfefce466d642ad98587d13123e4ef95ec9aa73b712e775d4cbba","price_changes":[{"asset_id":"96886111393998001968863279421729456597655847484197549086072988901191634450924","price":"0.51","size":"591.2","side":"BUY","hash":"f30e6ceae46975bf6d04a43fd8f39d61718f041c","best_bid":"0.94","best_ask":"0.95"},{"asset_id":"54232589582260339592359130012520874109228367674780084862642636038394766871668","price":"0.49","size":"591.2","side":"SELL","hash":"6fdff00640a922b33d2d454806d8d6af1f195bb2","best_bid":"0.05","best_ask":"0.06"}],"timestamp":"1768250237571","event_type":"price_change"}}
{"schema_version":1,"source":"clob_ws_market","recv_ts_ns":1768250237645817888,"event_type":"price_change","market":"0xe51aa24ab1bbfefce466d642ad98587d13123e4ef95ec9aa73b712e775d4cbba","server_ts_ms":1768250237594,"raw":{"market":"0xe51aa24ab1bbfefce466d642ad98587d13123e4ef95ec9aa73b712e775d4cbba","price_changes":[{"asset_id":"54232589582260339592359130012520874109228367674780084862642636038394766871668","price":"0.02","size":"6546.25","side":"BUY","hash":"32bdde27a137e51a53b9d3aed3388ab440c54fe6","best_bid":"0.05","best_ask":"0.06"},{"asset_id":"96886111393998001968863279421729456597655847484197549086072988901191634450924","price":"0.98","size":"6546.25","side":"SELL","hash":"44f243362488e4f02a37c0714f1730232f256f39","best_bid":"0.94","best_ask":"0.95"}],"timestamp":"1768250237594","event_type":"price_change"}}
{"schema_version":1,"source":"clob_ws_market","recv_ts_ns":1768250237650681398,"event_type":"price_change","market":"0xe51aa24ab1bbfefce466d642ad98587d13123e4ef95ec9aa73b712e775d4cbba","server_ts_ms":1768250237602,"raw":{"market":"0xe51aa24ab1bbfefce466d642ad98587d13123e4ef95ec9aa73b712e775d4cbba","price_changes":[{"asset_id":"96886111393998001968863279421729456597655847484197549086072988901191634450924","price":"0.94","size":"1472.88","side":"BUY","hash":"b2f4f91d0e86e780c531329517a4d57205eead58","best_bid":"0.94","best_ask":"0.95"},{"asset_id":"54232589582260339592359130012520874109228367674780084862642636038394766871668","price":"0.06","size":"1472.88","side":"SELL","hash":"003b30c0fcd7c6ad07a42558da7e7990abe28016","best_bid":"0.05","best_ask":"0.06"}],"timestamp":"1768250237602","event_type":"price_change"}}
{"schema_version":1,"source":"clob_ws_market","recv_ts_ns":1768250237655377254,"event_type":"price_change","market":"0xe51aa24ab1bbfefce466d642ad98587d13123e4ef95ec9aa73b712e775d4cbba","server_ts_ms":1768250237603,"raw":{"market":"0xe51aa24ab1bbfefce466d642ad98587d13123e4ef95ec9aa73b712e775d4cbba","price_changes":[{"asset_id":"96886111393998001968863279421729456597655847484197549086072988901191634450924","price":"0.94","size":"1456.88","side":"BUY","hash":"5d4e054c6240f2cae5f54bd61962d7dc6e64047f","best_bid":"0.94","best_ask":"0.95"},{"asset_id":"54232589582260339592359130012520874109228367674780084862642636038394766871668","price":"0.06","size":"1456.88","side":"SELL","hash":"ad96349d637b5f92ca49e1b8cd2eca93415674ec","best_bid":"0.05","best_ask":"0.06"}],"timestamp":"1768250237603","event_type":"price_change"}}
{"schema_version":1,"source":"clob_ws_market","recv_ts_ns":1768250237660002102,"event_type":"price_change","market":"0xe51aa24ab1bbfefce466d642ad98587d13123e4ef95ec9aa73b712e775d4cbba","server_ts_ms":1768250237605,"raw":{"market":"0xe51aa24ab1bbfefce466d642ad98587d13123e4ef95ec9aa73b712e775d4cbba","price_changes":[{"asset_id":"54232589582260339592359130012520874109228367674780084862642636038394766871668","price":"0.02","size":"6562.25","side":"BUY","hash":"6b66d93c7529afa9017cec31d3d39c1cbe0d286b","best_bid":"0.05","best_ask":"0.06"},{"asset_id":"96886111393998001968863279421729456597655847484197549086072988901191634450924","price":"0.98","size":"6562.25","side":"SELL","hash":"5eed8d723e1842f7ac1bfd004a691df1a14da35b","best_bid":"0.94","best_ask":"0.95"}],"timestamp":"1768250237605","event_type":"price_change"}}
{"schema_version":1,"source":"clob_ws_market","recv_ts_ns":1768250237666392803,"event_type":"price_change","market":"0xe51aa24ab1bbfefce466d642ad98587d13123e4ef95ec9aa73b712e775d4cbba","server_ts_ms":1768250237608,"raw":{"market":"0xe51aa24ab1bbfefce466d642ad98587d13123e4ef95ec9aa73b712e775d4cbba","price_changes":[{"asset_id":"54232589582260339592359130012520874109228367674780084862642636038394766871668","price":"0.03","size":"2144.6","side":"BUY","hash":"4409c29c8f1ce0b492b782a391f679fd492bdc71","best_bid":"0.05","best_ask":"0.06"},{"asset_id":"96886111393998001968863279421729456597655847484197549086072988901191634450924","price":"0.97","size":"2144.6","side":"SELL","hash":"cd1ce61deff06d76375969220c786c59a14ff9b4","best_bid":"0.94","best_ask":"0.95"}],"timestamp":"1768250237608","event_type":"price_change"}}
{"schema_version":1,"source":"clob_ws_market","recv_ts_ns":1768250237671886736,"event_type":"price_change","market":"0xe51aa24ab1bbfefce466d642ad98587d13123e4ef95ec9aa73b712e775d4cbba","server_ts_ms":1768250237622,"raw":{"market":"0xe51aa24ab1bbfefce466d642ad98587d13123e4ef95ec9aa73b712e775d4cbba","price_changes":[{"asset_id":"54232589582260339592359130012520874109228367674780084862642636038394766871668","price":"0.02","size":"6534.25","side":"BUY","hash":"0c8a22d8d02a79d725580f181d7bd1e1ebb7278d","best_bid":"0.05","best_ask":"0.06"},{"asset_id":"96886111393998001968863279421729456597655847484197549086072988901191634450924","price":"0.98","size":"6534.25","side":"SELL","hash":"4361166dc23a9f6be12071e4f902d023e623143f","best_bid":"0.94","best_ask":"0.95"}],"timestamp":"1768250237622","event_type":"price_change"}}
{"schema_version":1,"source":"clob_ws_market","recv_ts_ns":1768250237678723851,"event_type":"price_change","market":"0xe51aa24ab1bbfefce466d642ad98587d13123e4ef95ec9aa73b712e775d4cbba","server_ts_ms":1768250237649,"raw":{"market":"0xe51aa24ab1bbfefce466d642ad98587d13123e4ef95ec9aa73b712e775d4cbba","price_changes":[{"asset_id":"54232589582260339592359130012520874109228367674780084862642636038394766871668","price":"0.04","size":"426.4","side":"BUY","hash":"0f4f500c28d69c1d5ca7156e8dad8497edb62308","best_bid":"0.05","best_ask":"0.06"},{"asset_id":"96886111393998001968863279421729456597655847484197549086072988901191634450924","price":"0.96","size":"426.4","side":"SELL","hash":"a65408c270357ac4e65dac18f37e41ff4985a954","best_bid":"0.94","best_ask":"0.95"}],"timestamp":"1768250237649","event_type":"price_change"}}
{"schema_version":1,"source":"clob_ws_market","recv_ts_ns":1768250237684556190,"event_type":"price_change","market":"0xe51aa24ab1bbfefce466d642ad98587d13123e4ef95ec9aa73b712e775d4cbba","server_ts_ms":1768250237651,"raw":{"market":"0xe51aa24ab1bbfefce466d642ad98587d13123e4ef95ec9aa73b712e775d4cbba","price_changes":[{"asset_id":"96886111393998001968863279421729456597655847484197549086072988901191634450924","price":"0.87","size":"1588.93","side":"BUY","hash":"47821b55787576d0e0d163a537c90151b698c2c1","best_bid":"0.94","best_ask":"0.95"},{"asset_id":"54232589582260339592359130012520874109228367674780084862642636038394766871668","price":"0.13","size":"1588.93","side":"SELL","hash":"2f6fdc932fee8dd00ca1a76cc98ac6555bbc2c1e","best_bid":"0.05","best_ask":"0.06"}],"timestamp":"1768250237651","event_type":"price_change"}}
{"schema_version":1,"source":"clob_ws_market","recv_ts_ns":1768250237690247285,"event_type":"price_change","market":"0xe51aa24ab1bbfefce466d642ad98587d13123e4ef95ec9aa73b712e775d4cbba","server_ts_ms":1768250237652,"raw":{"market":"0xe51aa24ab1bbfefce466d642ad98587d13123e4ef95ec9aa73b712e775d4cbba","price_changes":[{"asset_id":"54232589582260339592359130012520874109228367674780084862642636038394766871668","price":"0.05","size":"1561.54","side":"BUY","hash":"d830f4c919efea707818c18bb77c138022248155","best_bid":"0.05","best_ask":"0.06"},{"asset_id":"96886111393998001968863279421729456597655847484197549086072988901191634450924","price":"0.95","size":"1561.54","side":"SELL","hash":"56c5b3a5c7105a02fe9ff1756077bc0ead4f22be","best_bid":"0.94","best_ask":"0.95"}],"timestamp":"1768250237652","event_type":"price_change"}}
{"schema_version":1,"source":"clob_ws_market","recv_ts_ns":1768250237695985336,"event_type":"price_change","market":"0xe51aa24ab1bbfefce466d642ad98587d13123e4ef95ec9aa73b712e775d4cbba","server_ts_ms":1768250237654,"raw":{"market":"0xe51aa24ab1bbfefce466d642ad98587d13123e4ef95ec9aa73b712e775d4cbba","price_changes":[{"asset_id":"54232589582260339592359130012520874109228367674780084862642636038394766871668","price":"0.05","size":"1532.52","side":"BUY","hash":"329ae68a5368df9918fe3c5474a8aeb283503449","best_bid":"0.05","best_ask":"0.06"},{"asset_id":"96886111393998001968863279421729456597655847484197549086072988901191634450924","price":"0.95","size":"1532.52","side":"SELL","hash":"bcbab1c8cb7965ae4ced2a6929145650d2534e13","best_bid":"0.94","best_ask":"0.95"}],"timestamp":"1768250237654","event_type":"price_change"}}
{"schema_version":1,"source":"clob_ws_market","recv_ts_ns":1768250237701468593,"event_type":"price_change","market":"0xe51aa24ab1bbfefce466d642ad98587d13123e4ef95ec9aa73b712e775d4cbba","server_ts_ms":1768250237664,"raw":{"market":"0xe51aa24ab1bbfefce466d642ad98587d13123e4ef95ec9aa73b712e775d4cbba","price_changes":[{"asset_id":"96886111393998001968863279421729456597655847484197549086072988901191634450924","price":"0.88","size":"2555.4","side":"BUY","hash":"2d8dcbfedc1d017c5f94091aecb8090a56281bc0","best_bid":"0.94","best_ask":"0.95"},{"asset_id":"54232589582260339592359130012520874109228367674780084862642636038394766871668","price":"0.12","size":"2555.4","side":"SELL","hash":"48b477750c88960ffb48fb05bb40cd94f809cb0b","best_bid":"0.05","best_ask":"0.06"}],"timestamp":"1768250237664","event_type":"price_change"}}
{"schema_version":1,"source":"clob_ws_market","recv_ts_ns":1768250237706414371,"event_type":"price_change","market":"0xe51aa24ab1bbfefce466d642ad98587d13123e4ef95ec9aa73b712e775d4cbba","server_ts_ms":1768250237668,"raw":{"market":"0xe51aa24ab1bbfefce466d642ad98587d13123e4ef95ec9aa73b712e775d4cbba","price_changes":[{"asset_id":"96886111393998001968863279421729456597655847484197549086072988901191634450924","price":"0.94","size":"1440.88","side":"BUY","hash":"b9e88f75dd20875fcece17385f4b3487cc63bee6","best_bid":"0.94","best_ask":"0.95"},{"asset_id":"54232589582260339592359130012520874109228367674780084862642636038394766871668","price":"0.06","size":"1440.88","side":"SELL","hash":"2fe0a2d0c7b9d5e825a935c76a9e07b59d2cf76e","best_bid":"0.05","best_ask":"0.06"}],"timestamp":"1768250237668","event_type":"price_change"}}
{"schema_version":1,"source":"clob_ws_market","recv_ts_ns":1768250237710704332,"event_type":"price_change","market":"0xe51aa24ab1bbfefce466d642ad98587d13123e4ef95ec9aa73b712e775d4cbba","server_ts_ms":1768250237671,"raw":{"market":"0xe51aa24ab1bbfefce466d642ad98587d13123e4ef95ec9aa73b712e775d4cbba","price_changes":[{"asset_id":"54232589582260339592359130012520874109228367674780084862642636038394766871668","price":"0.04","size":"442.4","side":"BUY","hash":"9c8bf9727d1659f45a74d3acf315ec1757ba3b42","best_bid":"0.05","best_ask":"0.06"},{"asset_id":"96886111393998001968863279421729456597655847484197549086072988901191634450924","price":"0.96","size":"442.4","side":"SELL","hash":"b144b03e2518005363901e420d6875cfa3c45133","best_bid":"0.94","best_ask":"0.95"}],"timestamp":"1768250237671","event_type":"price_change"}}
{"schema_version":1,"source":"clob_ws_market","recv_ts_ns":1768250237714623801,"event_type":"price_change","market":"0xe51aa24ab1bbfefce466d642ad98587d13123e4ef95ec9aa73b712e775d4cbba","server_ts_ms":1768250237673,"raw":{"market":"0xe51aa24ab1bbfefce466d642ad98587d13123e4ef95ec9aa73b712e775d4cbba","price_changes":[{"asset_id":"96886111393998001968863279421729456597655847484197549086072988901191634450924","price":"0.93","size":"1508.82","side":"BUY","hash":"96d37736157fb21553909fc4d6108b747650f730","best_bid":"0.94","best_ask":"0.95"},{"asset_id":"54232589582260339592359130012520874109228367674780084862642636038394766871668","price":"0.07","size":"1508.82","side":"SELL","hash":"add6dc81c4e3b5c060580db76742b42892761258","best_bid":"0.05","best_ask":"0.06"}],"timestamp":"1768250237673","event_type":"price_change"}}
{"schema_version":1,"source":"clob_ws_market","recv_ts_ns":1768250237719377244,"event_type":"price_change","market":"0xe51aa24ab1bbfefce466d642ad98587d13123e4ef95ec9aa73b712e775d4cbba","server_ts_ms":1768250237677,"raw":{"market":"0xe51aa24ab1bbfefce466d642ad98587d13123e4ef95ec9aa73b712e775d4cbba","price_changes":[{"asset_id":"96886111393998001968863279421729456597655847484197549086072988901191634450924","price":"0.94","size":"1424.88","side":"BUY","hash":"5187b2712501cce81b76824f200bd056648cda8a","best_bid":"0.94","best_ask":"0.95"},{"asset_id":"54232589582260339592359130012520874109228367674780084862642636038394766871668","price":"0.06","size":"1424.88","side":"SELL","hash":"aff3a96c602f1cb5e06e854e0244c439ef1a93c6","best_bid":"0.05","best_ask":"0.06"}],"timestamp":"1768250237677","event_type":"price_change"}}
{"schema_version":1,"source":"clob_ws_market","recv_ts_ns":1768250237722782030,"event_type":"price_change","market":"0xe51aa24ab1bbfefce466d642ad98587d13123e4ef95ec9aa73b712e775d4cbba","server_ts_ms":1768250237687,"raw":{"market":"0xe51aa24ab1bbfefce466d642ad98587d13123e4ef95ec9aa73b712e775d4cbba","price_changes":[{"asset_id":"54232589582260339592359130012520874109228367674780084862642636038394766871668","price":"0.02","size":"6562.25","side":"BUY","hash":"b397b87bbaaec742b62e83a73cd1484cb1f24fa8","best_bid":"0.05","best_ask":"0.06"},{"asset_id":"96886111393998001968863279421729456597655847484197549086072988901191634450924","price":"0.98","size":"6562.25","side":"SELL","hash":"6f115dea3d5433c6566ca7233c28658960f29299","best_bid":"0.94","best_ask":"0.95"}],"timestamp":"1768250237687","event_type":"price_change"}}
{"schema_version":1,"source":"clob_ws_market","recv_ts_ns":1768250237826491915,"event_type":"price_change","market":"0xe51aa24ab1bbfefce466d642ad98587d13123e4ef95ec9aa73b712e775d4cbba","server_ts_ms":1768250237804,"raw":{"market":"0xe51aa24ab1bbfefce466d642ad98587d13123e4ef95ec9aa73b712e775d4cbba","price_changes":[{"asset_id":"54232589582260339592359130012520874109228367674780084862642636038394766871668","price":"0.02","size":"6534.25","side":"BUY","hash":"1ff32dce0cf161eb7f760e2b136d2d28a6450d92","best_bid":"0.05","best_ask":"0.06"},{"asset_id":"96886111393998001968863279421729456597655847484197549086072988901191634450924","price":"0.98","size":"6534.25","side":"SELL","hash":"2c43b0ea8eff2e369728303c31428c376ad2d54c","best_bid":"0.94","best_ask":"0.95"}],"timestamp":"1768250237804","event_type":"price_change"}}
{"schema_version":1,"source":"clob_ws_market","recv_ts_ns":1768250237885685198,"event_type":"price_change","market":"0xe51aa24ab1bbfefce466d642ad98587d13123e4ef95ec9aa73b712e775d4cbba","server_ts_ms":1768250237852,"raw":{"market":"0xe51aa24ab1bbfefce466d642ad98587d13123e4ef95ec9aa73b712e775d4cbba","price_changes":[{"asset_id":"54232589582260339592359130012520874109228367674780084862642636038394766871668","price":"0.02","size":"6562.25","side":"BUY","hash":"5b93dad933562b6e25e115b3eea02100b803ef62","best_bid":"0.05","best_ask":"0.06"},{"asset_id":"96886111393998001968863279421729456597655847484197549086072988901191634450924","price":"0.98","size":"6562.25","side":"SELL","hash":"998032e51e9be1c86a764aa6dc9985beee5f1e43","best_bid":"0.94","best_ask":"0.95"}],"timestamp":"1768250237852","event_type":"price_change"}}
{"schema_version":1,"source":"clob_ws_market","recv_ts_ns":1768250237931336229,"event_type":"price_change","market":"0xe51aa24ab1bbfefce466d642ad98587d13123e4ef95ec9aa73b712e775d4cbba","server_ts_ms":1768250237873,"raw":{"market":"0xe51aa24ab1bbfefce466d642ad98587d13123e4ef95ec9aa73b712e775d4cbba","price_changes":[{"asset_id":"96886111393998001968863279421729456597655847484197549086072988901191634450924","price":"0.52","size":"596.2","side":"BUY","hash":"6ef64f668b7b2869f83295ffda404ac480acf731","best_bid":"0.94","best_ask":"0.95"},{"asset_id":"54232589582260339592359130012520874109228367674780084862642636038394766871668","price":"0.48","size":"596.2","side":"SELL","hash":"d779df5a879edbc0208e3b42d7626264e0add447","best_bid":"0.05","best_ask":"0.06"}],"timestamp":"1768250237873","event_type":"price_change"}}
{"schema_version":1,"source":"clob_ws_market","recv_ts_ns":1768250238104252511,"event_type":"price_change","market":"0xe51aa24ab1bbfefce466d642ad98587d13123e4ef95ec9aa73b712e775d4cbba","server_ts_ms":1768250237990,"raw":{"market":"0xe51aa24ab1bbfefce466d642ad98587d13123e4ef95ec9aa73b712e775d4cbba","price_changes":[{"asset_id":"54232589582260339592359130012520874109228367674780084862642636038394766871668","price":"0.02","size":"6534.25","side":"BUY","hash":"4052c7690edf025cd04d37020345ef99282ec18c","best_bid":"0.05","best_ask":"0.06"},{"asset_id":"96886111393998001968863279421729456597655847484197549086072988901191634450924","price":"0.98","size":"6534.25","side":"SELL","hash":"832b54e6db32a91c6e8bee0528d24ccdd90d551b","best_bid":"0.94","best_ask":"0.95"}],"timestamp":"1768250237990","event_type":"price_change"}}
{"schema_version":1,"source":"clob_ws_market","recv_ts_ns":1768250238115938614,"event_type":"price_change","market":"0xe51aa24ab1bbfefce466d642ad98587d13123e4ef95ec9aa73b712e775d4cbba","server_ts_ms":1768250238000,"raw":{"market":"0xe51aa24ab1bbfefce466d642ad98587d13123e4ef95ec9aa73b712e775d4cbba","price_changes":[{"asset_id":"54232589582260339592359130012520874109228367674780084862642636038394766871668","price":"0.02","size":"6434.25","side":"BUY","hash":"b5b58fbaf1f9b01409b36c0586a4327c8e50b383","best_bid":"0.05","best_ask":"0.06"},{"asset_id":"96886111393998001968863279421729456597655847484197549086072988901191634450924","price":"0.98","size":"6434.25","side":"SELL","hash":"cbc89224ad2b9113533dcea369e1d167c35a2c4d","best_bid":"0.94","best_ask":"0.95"}],"timestamp":"1768250238000","event_type":"price_change"}}
{"schema_version":1,"source":"clob_ws_market","recv_ts_ns":1768250238140012648,"event_type":"price_change","market":"0xe51aa24ab1bbfefce466d642ad98587d13123e4ef95ec9aa73b712e775d4cbba","server_ts_ms":1768250238035,"raw":{"market":"0xe51aa24ab1bbfefce466d642ad98587d13123e4ef95ec9aa73b712e775d4cbba","price_changes":[{"asset_id":"96886111393998001968863279421729456597655847484197549086072988901191634450924","price":"0.93","size":"1524.82","side":"BUY","hash":"67024da0d242e4bfcd533f601b6f9acfe89f7959","best_bid":"0.94","best_ask":"0.95"},{"asset_id":"54232589582260339592359130012520874109228367674780084862642636038394766871668","price":"0.07","size":"1524.82","side":"SELL","hash":"9d3cd431794f0faf08e7ac500715851756ddf91c","best_bid":"0.05","best_ask":"0.06"}],"timestamp":"1768250238035","event_type":"price_change"}}
{"schema_version":1,"source":"clob_ws_market","recv_ts_ns":1768250238145201137,"event_type":"price_change","market":"0xe51aa24ab1bbfefce466d642ad98587d13123e4ef95ec9aa73b712e775d4cbba","server_ts_ms":1768250238038,"raw":{"market":"0xe51aa24ab1bbfefce466d642ad98587d13123e4ef95ec9aa73b712e775d4cbba","price_changes":[{"asset_id":"96886111393998001968863279421729456597655847484197549086072988901191634450924","price":"0.93","size":"1540.82","side":"BUY","hash":"00db6740973a668a17cca08489e963e2f1f05126","best_bid":"0.94","best_ask":"0.95"},{"asset_id":"54232589582260339592359130012520874109228367674780084862642636038394766871668","price":"0.07","size":"1540.82","side":"SELL","hash":"857b74adfbff55fa47aaa939c91f559eff723c35","best_bid":"0.05","best_ask":"0.06"}],"timestamp":"1768250238038","event_type":"price_change"}}
{"schema_version":1,"source":"clob_ws_market","recv_ts_ns":1768250238150243272,"event_type":"price_change","market":"0xe51aa24ab1bbfefce466d642ad98587d13123e4ef95ec9aa73b712e775d4cbba","server_ts_ms":1768250238067,"raw":{"market":"0xe51aa24ab1bbfefce466d642ad98587d13123e4ef95ec9aa73b712e775d4cbba","price_changes":[{"asset_id":"54232589582260339592359130012520874109228367674780084862642636038394766871668","price":"0.02","size":"6462.25","side":"BUY","hash":"a99406924a405eb5acf4225a247c28431e0210b6","best_bid":"0.05","best_ask":"0.06"},{"asset_id":"96886111393998001968863279421729456597655847484197549086072988901191634450924","price":"0.98","size":"6462.25","side":"SELL","hash":"689bb7f6b8242c5a8120d0c3c236dcac44a09709","best_bid":"0.94","best_ask":"0.95"}],"timestamp":"1768250238067","event_type":"price_change"}}
{"schema_version":1,"source":"clob_ws_market","recv_ts_ns":1768250238155087794,"event_type":"price_change","market":"0xe51aa24ab1bbfefce466d642ad98587d13123e4ef95ec9aa73b712e775d4cbba","server_ts_ms":1768250238073,"raw":{"market":"0xe51aa24ab1bbfefce466d642ad98587d13123e4ef95ec9aa73b712e775d4cbba","price_changes":[{"asset_id":"96886111393998001968863279421729456597655847484197549086072988901191634450924","price":"0.94","size":"1448.88","side":"BUY","hash":"34c9f66f18d53a917552b282da45c8cbf078ccae","best_bid":"0.94","best_ask":"0.95"},{"asset_id":"54232589582260339592359130012520874109228367674780084862642636038394766871668","price":"0.06","size":"1448.88","side":"SELL","hash":"5d53bca4569b9d2a7c17c2b3b715a20648c4fdfc","best_bid":"0.05","best_ask":"0.06"}],"timestamp":"1768250238073","event_type":"price_change"}}
{"schema_version":1,"source":"clob_ws_market","recv_ts_ns":1768250238159860763,"event_type":"price_change","market":"0xe51aa24ab1bbfefce466d642ad98587d13123e4ef95ec9aa73b712e775d4cbba","server_ts_ms":1768250238075,"raw":{"market":"0xe51aa24ab1bbfefce466d642ad98587d13123e4ef95ec9aa73b712e775d4cbba","price_changes":[{"asset_id":"54232589582260339592359130012520874109228367674780084862642636038394766871668","price":"0.02","size":"6562.25","side":"BUY","hash":"fc2bef850d8509972fb02f0dd101295d492a6a37","best_bid":"0.05","best_ask":"0.06"},{"asset_id":"96886111393998001968863279421729456597655847484197549086072988901191634450924","price":"0.98","size":"6562.25","side":"SELL","hash":"8cb009be1d1c6bfa247f594245e352e4685987b7","best_bid":"0.94","best_ask":"0.95"}],"timestamp":"1768250238075","event_type":"price_change"}}
{"schema_version":1,"source":"clob_ws_market","recv_ts_ns":1768250238211156258,"event_type":"price_change","market":"0xe51aa24ab1bbfefce466d642ad98587d13123e4ef95ec9aa73b712e775d4cbba","server_ts_ms":1768250238190,"raw":{"market":"0xe51aa24ab1bbfefce466d642ad98587d13123e4ef95ec9aa73b712e775d4cbba","price_changes":[{"asset_id":"54232589582260339592359130012520874109228367674780084862642636038394766871668","price":"0.02","size":"6534.25","side":"BUY","hash":"93cd7ea2f23cb48407168d24a41c3c331e0e9265","best_bid":"0.05","best_ask":"0.06"},{"asset_id":"96886111393998001968863279421729456597655847484197549086072988901191634450924","price":"0.98","size":"6534.25","side":"SELL","hash":"fdf0849d7d9d440c801ad0ce5dfdd6a30a091528","best_bid":"0.94","best_ask":"0.95"}],"timestamp":"1768250238190","event_type":"price_change"}}
{"schema_version":1,"source":"clob_ws_market","recv_ts_ns":1768250238254200884,"event_type":"price_change","market":"0xe51aa24ab1bbfefce466d642ad98587d13123e4ef95ec9aa73b712e775d4cbba","server_ts_ms":1768250238233,"raw":{"market":"0xe51aa24ab1bbfefce466d642ad98587d13123e4ef95ec9aa73b712e775d4cbba","price_changes":[{"asset_id":"54232589582260339592359130012520874109228367674780084862642636038394766871668","price":"0.02","size":"6562.25","side":"BUY","hash":"e2654b3660201f600eeaf4c2023a155c9559e93c","best_bid":"0.05","best_ask":"0.06"},{"asset_id":"96886111393998001968863279421729456597655847484197549086072988901191634450924","price":"0.98","size":"6562.25","side":"SELL","hash":"2c092080fea3efa05dd5d890684272fbf101a3a8","best_bid":"0.94","best_ask":"0.95"}],"timestamp":"1768250238233","event_type":"price_change"}}
{"schema_version":1,"source":"clob_ws_market","recv_ts_ns":1768250238260155213,"event_type":"price_change","market":"0xe51aa24ab1bbfefce466d642ad98587d13123e4ef95ec9aa73b712e775d4cbba","server_ts_ms":1768250238234,"raw":{"market":"0xe51aa24ab1bbfefce466d642ad98587d13123e4ef95ec9aa73b712e775d4cbba","price_changes":[{"asset_id":"54232589582260339592359130012520874109228367674780084862642636038394766871668","price":"0.04","size":"458.83","side":"BUY","hash":"8bf07773cb4815c5ca9f29cf2fb482e3a134cfbd","best_bid":"0.05","best_ask":"0.06"},{"asset_id":"96886111393998001968863279421729456597655847484197549086072988901191634450924","price":"0.96","size":"458.83","side":"SELL","hash":"4eb5cb17d439c3087803bf9262224c4a4f204571","best_bid":"0.94","best_ask":"0.95"}],"timestamp":"1768250238234","event_type":"price_change"}}
{"schema_version":1,"source":"clob_ws_market","recv_ts_ns":1768250238383158575,"event_type":"price_change","market":"0xe51aa24ab1bbfefce466d642ad98587d13123e4ef95ec9aa73b712e775d4cbba","server_ts_ms":1768250238360,"raw":{"market":"0xe51aa24ab1bbfefce466d642ad98587d13123e4ef95ec9aa73b712e775d4cbba","price_changes":[{"asset_id":"54232589582260339592359130012520874109228367674780084862642636038394766871668","price":"0.07","size":"1520.82","side":"SELL","hash":"94ddc4e690ee944f0f5d0cf2c6f7ca9a79c76125","best_bid":"0.05","best_ask":"0.06"},{"asset_id":"96886111393998001968863279421729456597655847484197549086072988901191634450924","price":"0.93","size":"1520.82","side":"BUY","hash":"8057749cd9cc4aed29ccfdfabbdc10d0d3a41329","best_bid":"0.94","best_ask":"0.95"}],"timestamp":"1768250238360","event_type":"price_change"}}
{"schema_version":1,"source":"clob_ws_market","recv_ts_ns":1768250238393026909,"event_type":"price_change","market":"0xe51aa24ab1bbfefce466d642ad98587d13123e4ef95ec9aa73b712e775d4cbba","server_ts_ms":1768250238363,"raw":{"market":"0xe51aa24ab1bbfefce466d642ad98587d13123e4ef95ec9aa73b712e775d4cbba","price_changes":[{"asset_id":"54232589582260339592359130012520874109228367674780084862642636038394766871668","price":"0.07","size":"1540.82","side":"SELL","hash":"62d2d3ae6b16d5e382e6770a618d735ec2c28c4e","best_bid":"0.05","best_ask":"0.06"},{"asset_id":"96886111393998001968863279421729456597655847484197549086072988901191634450924","price":"0.93","size":"1540.82","side":"BUY","hash":"0a744d162362066994f6463d7c4f889e2861c787","best_bid":"0.94","best_ask":"0.95"}],"timestamp":"1768250238363","event_type":"price_change"}}
{"schema_version":1,"source":"clob_ws_market","recv_ts_ns":1768250238399194792,"event_type":"price_change","market":"0xe51aa24ab1bbfefce466d642ad98587d13123e4ef95ec9aa73b712e775d4cbba","server_ts_ms":1768250238368,"raw":{"market":"0xe51aa24ab1bbfefce466d642ad98587d13123e4ef95ec9aa73b712e775d4cbba","price_changes":[{"asset_id":"54232589582260339592359130012520874109228367674780084862642636038394766871668","price":"0.02","size":"6534.25","side":"BUY","hash":"064c35eaf714b0347d59d4d12a7d8bf6ab274956","best_bid":"0.05","best_ask":"0.06"},{"asset_id":"96886111393998001968863279421729456597655847484197549086072988901191634450924","price":"0.98","size":"6534.25","side":"SELL","hash":"2e54853feae16b73231207911bc54e4c26d44ecc","best_bid":"0.94","best_ask":"0.95"}],"timestamp":"1768250238368","event_type":"price_change"}}
{"schema_version":1,"source":"clob_ws_market","recv_ts_ns":1768250238404609014,"event_type":"best_bid_ask","market":"0xe51aa24ab1bbfefce466d642ad98587d13123e4ef95ec9aa73b712e775d4cbba","server_ts_ms":1768250238373,"raw":{"market":"0xe51aa24ab1bbfefce466d642ad98587d13123e4ef95ec9aa73b712e775d4cbba","asset_id":"54232589582260339592359130012520874109228367674780084862642636038394766871668","best_bid":"0.05","best_ask":"0.06","spread":"0.01","timestamp":"1768250238373","event_type":"best_bid_ask"}}
{"schema_version":1,"source":"clob_ws_market","recv_ts_ns":1768250238408844131,"event_type":"price_change","market":"0xe51aa24ab1bbfefce466d642ad98587d13123e4ef95ec9aa73b712e775d4cbba","server_ts_ms":1768250238372,"raw":{"market":"0xe51aa24ab1bbfefce466d642ad98587d13123e4ef95ec9aa73b712e775d4cbba","price_changes":[{"asset_id":"54232589582260339592359130012520874109228367674780084862642636038394766871668","price":"0.05","size":"1513.52","side":"BUY","hash":"e7912b2e966d0e0b48f2ad58045b74940d5e8e77","best_bid":"0.05","best_ask":"0.06"},{"asset_id":"96886111393998001968863279421729456597655847484197549086072988901191634450924","price":"0.95","size":"1513.52","side":"SELL","hash":"657409440ebf9839565245a7c6c90ff5adf4f1b1","best_bid":"0.94","best_ask":"0.95"}],"timestamp":"1768250238372","event_type":"price_change"}}
{"schema_version":1,"source":"clob_ws_market","recv_ts_ns":1768250238415173418,"event_type":"book","market":"0xe51aa24ab1bbfefce466d642ad98587d13123e4ef95ec9aa73b712e775d4cbba","server_ts_ms":1768250238372,"raw":{"market":"0xe51aa24ab1bbfefce466d642ad98587d13123e4ef95ec9aa73b712e775d4cbba","asset_id":"54232589582260339592359130012520874109228367674780084862642636038394766871668","bids":[{"price":"0.01","size":"21023.9"},{"price":"0.02","size":"6534.25"},{"price":"0.03","size":"2144.6"},{"price":"0.04","size":"458.83"},{"price":"0.05","size":"1513.52"}],"asks":[{"price":"0.99","size":"24290.24"},{"price":"0.98","size":"7594.51"},{"price":"0.97","size":"5964.69"},{"price":"0.96","size":"5411.4"},{"price":"0.95","size":"5356.39"},{"price":"0.94","size":"5328"},{"price":"0.93","size":"5039.28"},{"price":"0.92","size":"5022.7"},{"price":"0.91","size":"5320.9"},{"price":"0.9","size":"5158.44"},{"price":"0.89","size":"18.3"},{"price":"0.88","size":"30.3"},{"price":"0.87","size":"16.5"},{"price":"0.86","size":"15.8"},{"price":"0.85","size":"104.19"},{"price":"0.84","size":"24.69"},{"price":"0.83","size":"14.19"},{"price":"0.82","size":"13.8"},{"price":"0.81","size":"13.4"},{"price":"0.8","size":"38.1"},{"price":"0.79","size":"12.8"},{"price":"0.78","size":"12.6"},{"price":"0.77","size":"12.3"},{"price":"0.76","size":"22.1"},{"price":"0.75","size":"16.9"},{"price":"0.74","size":"21.8"},{"price":"0.73","size":"11.6"},{"price":"0.72","size":"11.4"},{"price":"0.71","size":"61.3"},{"price":"0.7","size":"26.2"},{"price":"0.69","size":"11.1"},{"price":"0.68","size":"11"},{"price":"0.67","size":"110.9"},{"price":"0.66","size":"10.8"},{"price":"0.65","size":"15.7"},{"price":"0.64","size":"10.6"},{"price":"0.63","size":"10.6"},{"price":"0.62","size":"22.5"},{"price":"0.61","size":"10.5"},{"price":"0.6","size":"45.4"},{"price":"0.59","size":"311.4"},{"price":"0.58","size":"820.82"},{"price":"0.57","size":"826.3"},{"price":"0.56","size":"1062.3"},{"price":"0.55","size":"582.3"},{"price":"0.54","size":"626.2"},{"price":"0.53","size":"562.2"},{"price":"0.52","size":"567.2"},{"price":"0.51","size":"573.2"},{"price":"0.5","size":"917.2"},{"price":"0.49","size":"591.2"},{"price":"0.48","size":"596.2"},{"price":"0.47","size":"567.2"},{"price":"0.46","size":"636.61"},{"price":"0.45","size":"362.97"},{"price":"0.44","size":"341.3"},{"price":"0.43","size":"320.62"},{"price":"0.42","size":"567.3"},{"price":"0.41","size":"562.4"},{"price":"0.4","size":"693.02"},{"price":"0.39","size":"593.5"},{"price":"0.38","size":"636.5"},{"price":"0.37","size":"672.32"},{"price":"0.36","size":"680.6"},{"price":"0.35","size":"536.14"},{"price":"0.34","size":"602.8"},{"price":"0.33","size":"572.9"},{"price":"0.32","size":"573"},{"price":"0.31","size":"595.1"},{"price":"0.3","size":"603.2"},{"price":"0.29","size":"1318.72"},{"price":"0.28","size":"1043.04"},{"price":"0.27","size":"663.6"},{"price":"0.26","size":"911.17"},{"price":"0.25","size":"694.3"},{"price":"0.24","size":"717.6"},{"price":"0.23","size":"1183.3"},{"price":"0.22","size":"1526.53"},{"price":"0.21","size":"1178.8"},{"price":"0.2","size":"1445.08"},{"price":"0.19","size":"1229.8"},{"price":"0.18","size":"1467.57"},{"price":"0.17","size":"1520.51"},{"price":"0.16","size":"1967.49"},{"price":"0.15","size":"1810.78"},{"price":"0.14","size":"1506.7"},{"price":"0.13","size":"1588.93"},{"price":"0.12","size":"2555.4"},{"price":"0.11","size":"1792.8"},{"price":"0.1","size":"3402.27"},{"price":"0.09","size":"3012.44"},{"price":"0.08","size":"2724.36"},{"price":"0.07","size":"1540.82"},{"price":"0.06","size":"1448.88"}],"hash":"e7912b2e966d0e0b48f2ad58045b74940d5e8e77","timestamp":"1768250238372","event_type":"book"}}
{"schema_version":1,"source":"clob_ws_market","recv_ts_ns":1768250238431850041,"event_type":"best_bid_ask","market":"0xe51aa24ab1bbfefce466d642ad98587d13123e4ef95ec9aa73b712e775d4cbba","server_ts_ms":1768250238411,"raw":{"market":"0xe51aa24ab1bbfefce466d642ad98587d13123e4ef95ec9aa73b712e775d4cbba","asset_id":"54232589582260339592359130012520874109228367674780084862642636038394766871668","best_bid":"0.05","best_ask":"0.06","spread":"0.01","timestamp":"1768250238411","event_type":"best_bid_ask"}}
{"schema_version":1,"source":"clob_ws_market","recv_ts_ns":1768250238437244919,"event_type":"price_change","market":"0xe51aa24ab1bbfefce466d642ad98587d13123e4ef95ec9aa73b712e775d4cbba","server_ts_ms":1768250238409,"raw":{"market":"0xe51aa24ab1bbfefce466d642ad98587d13123e4ef95ec9aa73b712e775d4cbba","price_changes":[{"asset_id":"54232589582260339592359130012520874109228367674780084862642636038394766871668","price":"0.05","size":"1512.38","side":"BUY","hash":"fb4710bea7a720b1b1446a93cd1991b90027839c","best_bid":"0.05","best_ask":"0.06"},{"asset_id":"96886111393998001968863279421729456597655847484197549086072988901191634450924","price":"0.95","size":"1512.38","side":"SELL","hash":"24c87e8e354b83a01d1977075376ee7d8f451d52","best_bid":"0.94","best_ask":"0.95"}],"timestamp":"1768250238409","event_type":"price_change"}}
{"schema_version":1,"source":"clob_ws_market","recv_ts_ns":1768250238444786348,"event_type":"book","market":"0xe51aa24ab1bbfefce466d642ad98587d13123e4ef95ec9aa73b712e775d4cbba","server_ts_ms":1768250238409,"raw":{"market":"0xe51aa24ab1bbfefce466d642ad98587d13123e4ef95ec9aa73b712e775d4cbba","asset_id":"54232589582260339592359130012520874109228367674780084862642636038394766871668","bids":[{"price":"0.01","size":"21023.9"},{"price":"0.02","size":"6534.25"},{"price":"0.03","size":"2144.6"},{"price":"0.04","size":"458.83"},{"price":"0.05","size":"1512.38"}],"asks":[{"price":"0.99","size":"24290.24"},{"price":"0.98","size":"7594.51"},{"price":"0.97","size":"5964.69"},{"price":"0.96","size":"5411.4"},{"price":"0.95","size":"5356.39"},{"price":"0.94","size":"5328"},{"price":"0.93","size":"5039.28"},{"price":"0.92","size":"5022.7"},{"price":"0.91","size":"5320.9"},{"price":"0.9","size":"5158.44"},{"price":"0.89","size":"18.3"},{"price":"0.88","size":"30.3"},{"price":"0.87","size":"16.5"},{"price":"0.86","size":"15.8"},{"price":"0.85","size":"104.19"},{"price":"0.84","size":"24.69"},{"price":"0.83","size":"14.19"},{"price":"0.82","size":"13.8"},{"price":"0.81","size":"13.4"},{"price":"0.8","size":"38.1"},{"price":"0.79","size":"12.8"},{"price":"0.78","size":"12.6"},{"price":"0.77","size":"12.3"},{"price":"0.76","size":"22.1"},{"price":"0.75","size":"16.9"},{"price":"0.74","size":"21.8"},{"price":"0.73","size":"11.6"},{"price":"0.72","size":"11.4"},{"price":"0.71","size":"61.3"},{"price":"0.7","size":"26.2"},{"price":"0.69","size":"11.1"},{"price":"0.68","size":"11"},{"price":"0.67","size":"110.9"},{"price":"0.66","size":"10.8"},{"price":"0.65","size":"15.7"},{"price":"0.64","size":"10.6"},{"price":"0.63","size":"10.6"},{"price":"0.62","size":"22.5"},{"price":"0.61","size":"10.5"},{"price":"0.6","size":"45.4"},{"price":"0.59","size":"311.4"},{"price":"0.58","size":"820.82"},{"price":"0.57","size":"826.3"},{"price":"0.56","size":"1062.3"},{"price":"0.55","size":"582.3"},{"price":"0.54","size":"626.2"},{"price":"0.53","size":"562.2"},{"price":"0.52","size":"567.2"},{"price":"0.51","size":"573.2"},{"price":"0.5","size":"917.2"},{"price":"0.49","size":"591.2"},{"price":"0.48","size":"596.2"},{"price":"0.47","size":"567.2"},{"price":"0.46","size":"636.61"},{"price":"0.45","size":"362.97"},{"price":"0.44","size":"341.3"},{"price":"0.43","size":"320.62"},{"price":"0.42","size":"567.3"},{"price":"0.41","size":"562.4"},{"price":"0.4","size":"693.02"},{"price":"0.39","size":"593.5"},{"price":"0.38","size":"636.5"},{"price":"0.37","size":"672.32"},{"price":"0.36","size":"680.6"},{"price":"0.35","size":"536.14"},{"price":"0.34","size":"602.8"},{"price":"0.33","size":"572.9"},{"price":"0.32","size":"573"},{"price":"0.31","size":"595.1"},{"price":"0.3","size":"603.2"},{"price":"0.29","size":"1318.72"},{"price":"0.28","size":"1043.04"},{"price":"0.27","size":"663.6"},{"price":"0.26","size":"911.17"},{"price":"0.25","size":"694.3"},{"price":"0.24","size":"717.6"},{"price":"0.23","size":"1183.3"},{"price":"0.22","size":"1526.53"},{"price":"0.21","size":"1178.8"},{"price":"0.2","size":"1445.08"},{"price":"0.19","size":"1229.8"},{"price":"0.18","size":"1467.57"},{"price":"0.17","size":"1520.51"},{"price":"0.16","size":"1967.49"},{"price":"0.15","size":"1810.78"},{"price":"0.14","size":"1506.7"},{"price":"0.13","size":"1588.93"},{"price":"0.12","size":"2555.4"},{"price":"0.11","size":"1792.8"},{"price":"0.1","size":"3402.27"},{"price":"0.09","size":"3012.44"},{"price":"0.08","size":"2724.36"},{"price":"0.07","size":"1540.82"},{"price":"0.06","size":"1448.88"}],"hash":"fb4710bea7a720b1b1446a93cd1991b90027839c","timestamp":"1768250238409","event_type":"book"}}
{"schema_version":1,"source":"clob_ws_market","recv_ts_ns":1768250238457838356,"event_type":"price_change","market":"0xe51aa24ab1bbfefce466d642ad98587d13123e4ef95ec9aa73b712e775d4cbba","server_ts_ms":1768250238425,"raw":{"market":"0xe51aa24ab1bbfefce466d642ad98587d13123e4ef95ec9aa73b712e775d4cbba","price_changes":[{"asset_id":"54232589582260339592359130012520874109228367674780084862642636038394766871668","price":"0.02","size":"6562.25","side":"BUY","hash":"a5ed92338e6795c1cfd187aa8a37421b10481098","best_bid":"0.05","best_ask":"0.06"},{"asset_id":"96886111393998001968863279421729456597655847484197549086072988901191634450924","price":"0.98","size":"6562.25","side":"SELL","hash":"0cf43ad9b75ab72f973a9c542e659197267c11ab","best_bid":"0.94","best_ask":"0.95"}],"timestamp":"1768250238425","event_type":"price_change"}}
{"schema_version":1,"source":"clob_ws_market","recv_ts_ns":1768250238481682607,"event_type":"price_change","market":"0xe51aa24ab1bbfefce466d642ad98587d13123e4ef95ec9aa73b712e775d4cbba","server_ts_ms":1768250238453,"raw":{"market":"0xe51aa24ab1bbfefce466d642ad98587d13123e4ef95ec9aa73b712e775d4cbba","price_changes":[{"asset_id":"54232589582260339592359130012520874109228367674780084862642636038394766871668","price":"0.03","size":"2128.6","side":"BUY","hash":"11b3fcea165196a08fd034ffa0457c2a89802c7d","best_bid":"0.05","best_ask":"0.06"},{"asset_id":"96886111393998001968863279421729456597655847484197549086072988901191634450924","price":"0.97","size":"2128.6","side":"SELL","hash":"e05df46e2cfb7af7c54155a77d3666656f6fbdf7","best_bid":"0.94","best_ask":"0.95"}],"timestamp":"1768250238453","event_type":"price_change"}}
{"schema_version":1,"source":"clob_ws_market","recv_ts_ns":1768250238486382789,"event_type":"price_change","market":"0xe51aa24ab1bbfefce466d642ad98587d13123e4ef95ec9aa73b712e775d4cbba","server_ts_ms":1768250238459,"raw":{"market":"0xe51aa24ab1bbfefce466d642ad98587d13123e4ef95ec9aa73b712e775d4cbba","price_changes":[{"asset_id":"54232589582260339592359130012520874109228367674780084862642636038394766871668","price":"0.04","size":"474.13","side":"BUY","hash":"6592272993aacd73e70d332e07b7521ce49aa873","best_bid":"0.05","best_ask":"0.06"},{"asset_id":"96886111393998001968863279421729456597655847484197549086072988901191634450924","price":"0.96","size":"474.13","side":"SELL","hash":"4efcd35468a2af0e7515c0e686e0fa01a2d2c67c","best_bid":"0.94","best_ask":"0.95"}],"timestamp":"1768250238459","event_type":"price_change"}}
{"schema_version":1,"source":"clob_ws_market","recv_ts_ns":1768250238490978140,"event_type":"price_change","market":"0xe51aa24ab1bbfefce466d642ad98587d13123e4ef95ec9aa73b712e775d4cbba","server_ts_ms":1768250238460,"raw":{"market":"0xe51aa24ab1bbfefce466d642ad98587d13123e4ef95ec9aa73b712e775d4cbba","price_changes":[{"asset_id":"54232589582260339592359130012520874109228367674780084862642636038394766871668","price":"0.01","size":"21039.9","side":"BUY","hash":"70078c528ea28e350d13eb06bc8a36e730c13ddb","best_bid":"0.05","best_ask":"0.06"},{"asset_id":"96886111393998001968863279421729456597655847484197549086072988901191634450924","price":"0.99","size":"21039.9","side":"SELL","hash":"a0b284d327322468bbc95c04fefafc0a7c7aa9f2","best_bid":"0.94","best_ask":"0.95"}],"timestamp":"1768250238460","event_type":"price_change"}}
{"schema_version":1,"source":"clob_ws_market","recv_ts_ns":1768250238495551109,"event_type":"price_change","market":"0xe51aa24ab1bbfefce466d642ad98587d13123e4ef95ec9aa73b712e775d4cbba","server_ts_ms":1768250238461,"raw":{"market":"0xe51aa24ab1bbfefce466d642ad98587d13123e4ef95ec9aa73b712e775d4cbba","price_changes":[{"asset_id":"54232589582260339592359130012520874109228367674780084862642636038394766871668","price":"0.03","size":"2112.6","side":"BUY","hash":"b1375abbdcccec94356e84c5074e457ca4e537d5","best_bid":"0.05","best_ask":"0.06"},{"asset_id":"96886111393998001968863279421729456597655847484197549086072988901191634450924","price":"0.97","size":"2112.6","side":"SELL","hash":"6879745a1816921b3fcdc764716ea946dcba6ee6","best_bid":"0.94","best_ask":"0.95"}],"timestamp":"1768250238461","event_type":"price_change"}}
{"schema_version":1,"source":"clob_ws_market","recv_ts_ns":1768250238508361386,"event_type":"best_bid_ask","market":"0xe51aa24ab1bbfefce466d642ad98587d13123e4ef95ec9aa73b712e775d4cbba","server_ts_ms":1768250238486,"raw":{"market":"0xe51aa24ab1bbfefce466d642ad98587d13123e4ef95ec9aa73b712e775d4cbba","asset_id":"54232589582260339592359130012520874109228367674780084862642636038394766871668","best_bid":"0.05","best_ask":"0.06","spread":"0.01","timestamp":"1768250238486","event_type":"best_bid_ask"}}
{"schema_version":1,"source":"clob_ws_market","recv_ts_ns":1768250238513791705,"event_type":"price_change","market":"0xe51aa24ab1bbfefce466d642ad98587d13123e4ef95ec9aa73b712e775d4cbba","server_ts_ms":1768250238484,"raw":{"market":"0xe51aa24ab1bbfefce466d642ad98587d13123e4ef95ec9aa73b712e775d4cbba","price_changes":[{"asset_id":"54232589582260339592359130012520874109228367674780084862642636038394766871668","price":"0.05","size":"1511.24","side":"BUY","hash":"c7d25a56574ae4b3b1bece110a23064c87e4bd05","best_bid":"0.05","best_ask":"0.06"},{"asset_id":"96886111393998001968863279421729456597655847484197549086072988901191634450924","price":"0.95","size":"1511.24","side":"SELL","hash":"5cd43bc41f2b43c0a88d899efab3592a4510e4d0","best_bid":"0.94","best_ask":"0.95"}],"timestamp":"1768250238484","event_type":"price_change"}}
{"schema_version":1,"source":"clob_ws_market","recv_ts_ns":1768250238519868429,"event_type":"book","market":"0xe51aa24ab1bbfefce466d642ad98587d13123e4ef95ec9aa73b712e775d4cbba","server_ts_ms":1768250238484,"raw":{"market":"0xe51aa24ab1bbfefce466d642ad98587d13123e4ef95ec9aa73b712e775d4cbba","asset_id":"54232589582260339592359130012520874109228367674780084862642636038394766871668","bids":[{"price":"0.01","size":"21039.9"},{"price":"0.02","size":"6562.25"},{"price":"0.03","size":"2112.6"},{"price":"0.04","size":"474.13"},{"price":"0.05","size":"1511.24"}],"asks":[{"price":"0.99","size":"24290.24"},{"price":"0.98","size":"7594.51"},{"price":"0.97","size":"5964.69"},{"price":"0.96","size":"5411.4"},{"price":"0.95","size":"5356.39"},{"price":"0.94","size":"5328"},{"price":"0.93","size":"5039.28"},{"price":"0.92","size":"5022.7"},{"price":"0.91","size":"5320.9"},{"price":"0.9","size":"5158.44"},{"price":"0.89","size":"18.3"},{"price":"0.88","size":"30.3"},{"price":"0.87","size":"16.5"},{"price":"0.86","size":"15.8"},{"price":"0.85","size":"104.19"},{"price":"0.84","size":"24.69"},{"price":"0.83","size":"14.19"},{"price":"0.82","size":"13.8"},{"price":"0.81","size":"13.4"},{"price":"0.8","size":"38.1"},{"price":"0.79","size":"12.8"},{"price":"0.78","size":"12.6"},{"price":"0.77","size":"12.3"},{"price":"0.76","size":"22.1"},{"price":"0.75","size":"16.9"},{"price":"0.74","size":"21.8"},{"price":"0.73","size":"11.6"},{"price":"0.72","size":"11.4"},{"price":"0.71","size":"61.3"},{"price":"0.7","size":"26.2"},{"price":"0.69","size":"11.1"},{"price":"0.68","size":"11"},{"price":"0.67","size":"110.9"},{"price":"0.66","size":"10.8"},{"price":"0.65","size":"15.7"},{"price":"0.64","size":"10.6"},{"price":"0.63","size":"10.6"},{"price":"0.62","size":"22.5"},{"price":"0.61","size":"10.5"},{"price":"0.6","size":"45.4"},{"price":"0.59","size":"311.4"},{"price":"0.58","size":"820.82"},{"price":"0.57","size":"826.3"},{"price":"0.56","size":"1062.3"},{"price":"0.55","size":"582.3"},{"price":"0.54","size":"626.2"},{"price":"0.53","size":"562.2"},{"price":"0.52","size":"567.2"},{"price":"0.51","size":"573.2"},{"price":"0.5","size":"917.2"},{"price":"0.49","size":"591.2"},{"price":"0.48","size":"596.2"},{"price":"0.47","size":"567.2"},{"price":"0.46","size":"636.61"},{"price":"0.45","size":"362.97"},{"price":"0.44","size":"341.3"},{"price":"0.43","size":"320.62"},{"price":"0.42","size":"567.3"},{"price":"0.41","size":"562.4"},{"price":"0.4","size":"693.02"},{"price":"0.39","size":"593.5"},{"price":"0.38","size":"636.5"},{"price":"0.37","size":"672.32"},{"price":"0.36","size":"680.6"},{"price":"0.35","size":"536.14"},{"price":"0.34","size":"602.8"},{"price":"0.33","size":"572.9"},{"price":"0.32","size":"573"},{"price":"0.31","size":"595.1"},{"price":"0.3","size":"603.2"},{"price":"0.29","size":"1318.72"},{"price":"0.28","size":"1043.04"},{"price":"0.27","size":"663.6"},{"price":"0.26","size":"911.17"},{"price":"0.25","size":"694.3"},{"price":"0.24","size":"717.6"},{"price":"0.23","size":"1183.3"},{"price":"0.22","size":"1526.53"},{"price":"0.21","size":"1178.8"},{"price":"0.2","size":"1445.08"},{"price":"0.19","size":"1229.8"},{"price":"0.18","size":"1467.57"},{"price":"0.17","size":"1520.51"},{"price":"0.16","size":"1967.49"},{"price":"0.15","size":"1810.78"},{"price":"0.14","size":"1506.7"},{"price":"0.13","size":"1588.93"},{"price":"0.12","size":"2555.4"},{"price":"0.11","size":"1792.8"},{"price":"0.1","size":"3402.27"},{"price":"0.09","size":"3012.44"},{"price":"0.08","size":"2724.36"},{"price":"0.07","size":"1540.82"},{"price":"0.06","size":"1448.88"}],"hash":"c7d25a56574ae4b3b1bece110a23064c87e4bd05","timestamp":"1768250238484","event_type":"book"}}
{"schema_version":1,"source":"clob_ws_market","recv_ts_ns":1768250238528601127,"event_type":"price_change","market":"0xe51aa24ab1bbfefce466d642ad98587d13123e4ef95ec9aa73b712e775d4cbba","server_ts_ms":1768250238488,"raw":{"market":"0xe51aa24ab1bbfefce466d642ad98587d13123e4ef95ec9aa73b712e775d4cbba","price_changes":[{"asset_id":"96886111393998001968863279421729456597655847484197549086072988901191634450924","price":"0.94","size":"1433.88","side":"BUY","hash":"3e0449bddcfa4748dcf60597dd89b23612baa836","best_bid":"0.94","best_ask":"0.95"},{"asset_id":"54232589582260339592359130012520874109228367674780084862642636038394766871668","price":"0.06","size":"1433.88","side":"SELL","hash":"783332fccde895f1409343c1439f784f1b7857b5","best_bid":"0.05","best_ask":"0.06"}],"timestamp":"1768250238488","event_type":"price_change"}}
{"schema_version":1,"source":"clob_ws_market","recv_ts_ns":1768250238532991351,"event_type":"price_change","market":"0xe51aa24ab1bbfefce466d642ad98587d13123e4ef95ec9aa73b712e775d4cbba","server_ts_ms":1768250238490,"raw":{"market":"0xe51aa24ab1bbfefce466d642ad98587d13123e4ef95ec9aa73b712e775d4cbba","price_changes":[{"asset_id":"96886111393998001968863279421729456597655847484197549086072988901191634450924","price":"0.94","size":"1409.88","side":"BUY","hash":"88d97a80e92d51644c9cd9c4668b8d17d097f390","best_bid":"0.94","best_ask":"0.95"},{"asset_id":"54232589582260339592359130012520874109228367674780084862642636038394766871668","price":"0.06","size":"1409.88","side":"SELL","hash":"6ce71d8474b66c2fd775c99b4b36ef6b420609db","best_bid":"0.05","best_ask":"0.06"}],"timestamp":"1768250238490","event_type":"price_change"}}
{"schema_version":1,"source":"clob_ws_market","recv_ts_ns":1768250238537095003,"event_type":"price_change","market":"0xe51aa24ab1bbfefce466d642ad98587d13123e4ef95ec9aa73b712e775d4cbba","server_ts_ms":1768250238494,"raw":{"market":"0xe51aa24ab1bbfefce466d642ad98587d13123e4ef95ec9aa73b712e775d4cbba","price_changes":[{"asset_id":"96886111393998001968863279421729456597655847484197549086072988901191634450924","price":"0.94","size":"1417.4","side":"BUY","hash":"462a8bedd746f134aedc3f5c781d965b2f404e8d","best_bid":"0.94","best_ask":"0.95"},{"asset_id":"54232589582260339592359130012520874109228367674780084862642636038394766871668","price":"0.06","size":"1417.4","side":"SELL","hash":"1a9c52a897a578656fbb9e2813034ff1b0c62a75","best_bid":"0.05","best_ask":"0.06"}],"timestamp":"1768250238494","event_type":"price_change"}}
{"schema_version":1,"source":"clob_ws_market","recv_ts_ns":1768250238542306476,"event_type":"price_change","market":"0xe51aa24ab1bbfefce466d642ad98587d13123e4ef95ec9aa73b712e775d4cbba","server_ts_ms":1768250238497,"raw":{"market":"0xe51aa24ab1bbfefce466d642ad98587d13123e4ef95ec9aa73b712e775d4cbba","price_changes":[{"asset_id":"54232589582260339592359130012520874109228367674780084862642636038394766871668","price":"0.02","size":"6546.25","side":"BUY","hash":"4313b65ff699a1ef8017ae4acaa17f00012c1568","best_bid":"0.05","best_ask":"0.06"},{"asset_id":"96886111393998001968863279421729456597655847484197549086072988901191634450924","price":"0.98","size":"6546.25","side":"SELL","hash":"9b51a2720d9baac8046bc236a1d14cf22e95b5af","best_bid":"0.94","best_ask":"0.95"}],"timestamp":"1768250238497","event_type":"price_change"}}
{"schema_version":1,"source":"clob_ws_market","recv_ts_ns":1768250238546948967,"event_type":"price_change","market":"0xe51aa24ab1bbfefce466d642ad98587d13123e4ef95ec9aa73b712e775d4cbba","server_ts_ms":1768250238504,"raw":{"market":"0xe51aa24ab1bbfefce466d642ad98587d13123e4ef95ec9aa73b712e775d4cbba","price_changes":[{"asset_id":"54232589582260339592359130012520874109228367674780084862642636038394766871668","price":"0.04","size":"490.13","side":"BUY","hash":"379e002994872b94fef1b8037207bbb1dff6f2fb","best_bid":"0.05","best_ask":"0.06"},{"asset_id":"96886111393998001968863279421729456597655847484197549086072988901191634450924","price":"0.96","size":"490.13","side":"SELL","hash":"a39835498796a8231f741599cd928a0bdd7ffae9","best_bid":"0.94","best_ask":"0.95"}],"timestamp":"1768250238504","event_type":"price_change"}}
{"schema_version":1,"source":"clob_ws_market","recv_ts_ns":1768250238552473236,"event_type":"price_change","market":"0xe51aa24ab1bbfefce466d642ad98587d13123e4ef95ec9aa73b712e775d4cbba","server_ts_ms":1768250238506,"raw":{"market":"0xe51aa24ab1bbfefce466d642ad98587d13123e4ef95ec9aa73b712e775d4cbba","price_changes":[{"asset_id":"96886111393998001968863279421729456597655847484197549086072988901191634450924","price":"0.94","size":"1401.4","side":"BUY","hash":"0182f33b62f327f1f37e895d24867e1ba7d47673","best_bid":"0.94","best_ask":"0.95"},{"asset_id":"54232589582260339592359130012520874109228367674780084862642636038394766871668","price":"0.06","size":"1401.4","side":"SELL","hash":"c605d7109a8578f46e5f8906cae7b7b32cb35ca0","best_bid":"0.05","best_ask":"0.06"}],"timestamp":"1768250238506","event_type":"price_change"}}
{"schema_version":1,"source":"clob_ws_market","recv_ts_ns":1768250238557738992,"event_type":"price_change","market":"0xe51aa24ab1bbfefce466d642ad98587d13123e4ef95ec9aa73b712e775d4cbba","server_ts_ms":1768250238508,"raw":{"market":"0xe51aa24ab1bbfefce466d642ad98587d13123e4ef95ec9aa73b712e775d4cbba","price_changes":[{"asset_id":"54232589582260339592359130012520874109228367674780084862642636038394766871668","price":"0.04","size":"506.13","side":"BUY","hash":"b0ae28b3f72f638bf1f667b7442a085554af2831","best_bid":"0.05","best_ask":"0.06"},{"asset_id":"96886111393998001968863279421729456597655847484197549086072988901191634450924","price":"0.96","size":"506.13","side":"SELL","hash":"6f523e3f73c134c4d7b092aba2c9adf909984347","best_bid":"0.94","best_ask":"0.95"}],"timestamp":"1768250238508","event_type":"price_change"}}
{"schema_version":1,"source":"clob_ws_market","recv_ts_ns":1768250238565590297,"event_type":"price_change","market":"0xe51aa24ab1bbfefce466d642ad98587d13123e4ef95ec9aa73b712e775d4cbba","server_ts_ms":1768250238533,"raw":{"market":"0xe51aa24ab1bbfefce466d642ad98587d13123e4ef95ec9aa73b712e775d4cbba","price_changes":[{"asset_id":"54232589582260339592359130012520874109228367674780084862642636038394766871668","price":"0.03","size":"2128.6","side":"BUY","hash":"1953883ebd7da69c820862a03cb36e0c8195b96b","best_bid":"0.05","best_ask":"0.06"},{"asset_id":"96886111393998001968863279421729456597655847484197549086072988901191634450924","price":"0.97","size":"2128.6","side":"SELL","hash":"860415a594f0b5ba9de809ff0a67b64bbfa12cfd","best_bid":"0.94","best_ask":"0.95"}],"timestamp":"1768250238533","event_type":"price_change"}}
{"schema_version":1,"source":"clob_ws_market","recv_ts_ns":1768250238571157490,"event_type":"price_change","market":"0xe51aa24ab1bbfefce466d642ad98587d13123e4ef95ec9aa73b712e775d4cbba","server_ts_ms":1768250238541,"raw":{"market":"0xe51aa24ab1bbfefce466d642ad98587d13123e4ef95ec9aa73b712e775d4cbba","price_changes":[{"asset_id":"96886111393998001968863279421729456597655847484197549086072988901191634450924","price":"0.93","size":"1556.82","side":"BUY","hash":"0038d4ddee4bb821b4b27968805577a7fd19a6d0","best_bid":"0.94","best_ask":"0.95"},{"asset_id":"54232589582260339592359130012520874109228367674780084862642636038394766871668","price":"0.07","size":"1556.82","side":"SELL","hash":"3495b682d209cf075ebe8be58a3916aa51fbb4dd","best_bid":"0.05","best_ask":"0.06"}],"timestamp":"1768250238541","event_type":"price_change"}}
{"schema_version":1,"source":"clob_ws_market","recv_ts_ns":1768250238615393508,"event_type":"price_change","market":"0xe51aa24ab1bbfefce466d642ad98587d13123e4ef95ec9aa73b712e775d4cbba","server_ts_ms":1768250238574,"raw":{"market":"0xe51aa24ab1bbfefce466d642ad98587d13123e4ef95ec9aa73b712e775d4cbba","price_changes":[{"asset_id":"96886111393998001968863279421729456597655847484197549086072988901191634450924","price":"0.94","size":"1413.4","side":"BUY","hash":"73ca4723207a62cfdc3cb6071157816f186ee176","best_bid":"0.94","best_ask":"0.95"},{"asset_id":"54232589582260339592359130012520874109228367674780084862642636038394766871668","price":"0.06","size":"1413.4","side":"SELL","hash":"28818bccf86287a85a743bed96fa1cda4e1c52df","best_bid":"0.05","best_ask":"0.06"}],"timestamp":"1768250238574","event_type":"price_change"}}
{"schema_version":1,"source":"clob_ws_market","recv_ts_ns":1768250238619009938,"event_type":"price_change","market":"0xe51aa24ab1bbfefce466d642ad98587d13123e4ef95ec9aa73b712e775d4cbba","server_ts_ms":1768250238594,"raw":{"market":"0xe51aa24ab1bbfefce466d642ad98587d13123e4ef95ec9aa73b712e775d4cbba","price_changes":[{"asset_id":"54232589582260339592359130012520874109228367674780084862642636038394766871668","price":"0.01","size":"21023.9","side":"BUY","hash":"fb851f13da7480383bf857de8c0020f9b4555fc6","best_bid":"0.05","best_ask":"0.06"},{"asset_id":"96886111393998001968863279421729456597655847484197549086072988901191634450924","price":"0.99","size":"21023.9","side":"SELL","hash":"51060d692341abd289de7cd10018c44fa2cf6957","best_bid":"0.94","best_ask":"0.95"}],"timestamp":"1768250238594","event_type":"price_change"}}
{"schema_version":1,"source":"clob_ws_market","recv_ts_ns":1768250238637961788,"event_type":"best_bid_ask","market":"0xe51aa24ab1bbfefce466d642ad98587d13123e4ef95ec9aa73b712e775d4cbba","server_ts_ms":1768250238617,"raw":{"market":"0xe51aa24ab1bbfefce466d642ad98587d13123e4ef95ec9aa73b712e775d4cbba","asset_id":"54232589582260339592359130012520874109228367674780084862642636038394766871668","best_bid":"0.05","best_ask":"0.06","spread":"0.01","timestamp":"1768250238617","event_type":"best_bid_ask"}}
{"schema_version":1,"source":"clob_ws_market","recv_ts_ns":1768250238643488192,"event_type":"price_change","market":"0xe51aa24ab1bbfefce466d642ad98587d13123e4ef95ec9aa73b712e775d4cbba","server_ts_ms":1768250238615,"raw":{"market":"0xe51aa24ab1bbfefce466d642ad98587d13123e4ef95ec9aa73b712e775d4cbba","price_changes":[{"asset_id":"54232589582260339592359130012520874109228367674780084862642636038394766871668","price":"0.05","size":"1324.24","side":"BUY","hash":"218016664aa91cb5b5785e55d9d3d03c8f46d94b","best_bid":"0.05","best_ask":"0.06"},{"asset_id":"96886111393998001968863279421729456597655847484197549086072988901191634450924","price":"0.95","size":"1324.24","side":"SELL","hash":"763ea5362b11e44c654bebb699097dcdd07166ac","best_bid":"0.94","best_ask":"0.95"}],"timestamp":"1768250238615","event_type":"price_change"}}
