{"schema_version":1,"source":"clob_ws_market","recv_ts_ns":1768250246671856443,"event_type":"book","market":"0x2a12fd3d8235c25c062dc9652970ef9f635636c4018df0909e1a51c673e125cb","server_ts_ms":1768250246439,"raw":{"market":"0x2a12fd3d8235c25c062dc9652970ef9f635636c4018df0909e1a51c673e125cb","asset_id":"63670753354844494163057275310194312729998307779831462269530137743341854359908","bids":[{"price":"0.01","size":"10189.41"},{"price":"0.02","size":"5982"},{"price":"0.03","size":"5238.94"},{"price":"0.04","size":"5040"},{"price":"0.05","size":"5050"},{"price":"0.06","size":"5005"},{"price":"0.07","size":"5019.28"},{"price":"0.08","size":"5005"},{"price":"0.09","size":"5005"},{"price":"0.1","size":"5030"},{"price":"0.11","size":"5"},{"price":"0.12","size":"5"},{"price":"0.13","size":"5"},{"price":"0.14","size":"5"},{"price":"0.15","size":"10"},{"price":"0.16","size":"5"},{"price":"0.17","size":"5"},{"price":"0.18","size":"5"},{"price":"0.19","size":"5"},{"price":"0.2","size":"5"},{"price":"0.21","size":"5"},{"price":"0.22","size":"5"},{"price":"0.23","size":"5"},{"price":"0.24","size":"5"},{"price":"0.25","size":"10"},{"price":"0.26","size":"5"},{"price":"0.27","size":"5"},{"price":"0.28","size":"5"},{"price":"0.29","size":"15"},{"price":"0.3","size":"10"},{"price":"0.31","size":"5"},{"price":"0.32","size":"5"},{"price":"0.33","size":"5"},{"price":"0.34","size":"505"},{"price":"0.35","size":"510"},{"price":"0.36","size":"510"},{"price":"0.37","size":"505"},{"price":"0.38","size":"505"},{"price":"0.39","size":"755"},{"price":"0.4","size":"760"},{"price":"0.41","size":"916"},{"price":"0.42","size":"671"},{"price":"0.43","size":"827"},{"price":"0.44","size":"827"},{"price":"0.45","size":"817"},{"price":"0.46","size":"872"},{"price":"0.47","size":"839.65"},{"price":"0.48","size":"829"},{"price":"0.49","size":"817"},{"price":"0.5","size":"838.4"},{"price":"0.51","size":"867.58"},{"price":"0.52","size":"817"},{"price":"0.53","size":"827"},{"price":"0.54","size":"847.8"},{"price":"0.55","size":"836.09"},{"price":"0.56","size":"825"},{"price":"0.57","size":"847"},{"price":"0.58","size":"817"},{"price":"0.59","size":"817"},{"price":"0.6","size":"817"},{"price":"0.61","size":"834.5"},{"price":"0.62","size":"817"},{"price":"0.63","size":"497.49"},{"price":"0.64","size":"817"},{"price":"0.65","size":"872"},{"price":"0.66","size":"997.71"},{"price":"0.67","size":"906.8"},{"price":"0.68","size":"902"},{"price":"0.69","size":"922"},{"price":"0.7","size":"911.6"},{"price":"0.71","size":"897"},{"price":"0.72","size":"899.55"},{"price":"0.73","size":"912"},{"price":"0.74","size":"1087.3"},{"price":"0.75","size":"722.5"},{"price":"0.76","size":"924.25"},{"price":"0.77","size":"762.5"},{"price":"0.78","size":"899.5"},{"price":"0.79","size":"808.5"},{"price":"0.8","size":"814.9"},{"price":"0.81","size":"813.21"},{"price":"0.82","size":"1381"},{"price":"0.83","size":"200.52"},{"price":"0.84","size":"244.37"}],"asks":[{"price":"0.99","size":"10331.71"},{"price":"0.98","size":"6299.77"},{"price":"0.97","size":"5625.94"},{"price":"0.96","size":"5427"},{"price":"0.95","size":"3442"},{"price":"0.94","size":"1397"},{"price":"0.93","size":"1433.78"},{"price":"0.92","size":"1546.75"},{"price":"0.91","size":"1373"},{"price":"0.9","size":"3447"},{"price":"0.89","size":"924.5"},{"price":"0.88","size":"887.75"},{"price":"0.87","size":"743.5"},{"price":"0.86","size":"823.29"},{"price":"0.85","size":"550.76"}],"hash":"579dee2b52f1f4f1382f7e5124f791248926b055","timestamp":"1768250246439","event_type":"book"}}
{"schema_version":1,"source":"clob_ws_market","recv_ts_ns":1768250246733301741,"event_type":"price_change","market":"0x2a12fd3d8235c25c062dc9652970ef9f635636c4018df0909e1a51c673e125cb","server_ts_ms":1768250246647,"raw":{"market":"0x2a12fd3d8235c25c062dc9652970ef9f635636c4018df0909e1a51c673e125cb","price_changes":[{"asset_id":"63670753354844494163057275310194312729998307779831462269530137743341854359908","price":"0.84","size":"644.37","side":"BUY","hash":"bc13971fa7eea8b79c2e98a41a0f640d6bb60731","best_bid":"0.84","best_ask":"0.85"},{"asset_id":"56386988715176239099720172290594769295756680374928571099138069977179519358166","price":"0.16","size":"644.37","side":"SELL","hash":"b43d053f976854bd3ba940e5a1f03676027ad582","best_bid":"0.15","best_ask":"0.16"}],"timestamp":"1768250246647","event_type":"price_change"}}
{"schema_version":1,"source":"clob_ws_market","recv_ts_ns":1768250246771684351,"event_type":"price_change","market":"0x2a12fd3d8235c25c062dc9652970ef9f635636c4018df0909e1a51c673e125cb","server_ts_ms":1768250246734,"raw":{"market":"0x2a12fd3d8235c25c062dc9652970ef9f635636c4018df0909e1a51c673e125cb","price_changes":[{"asset_id":"56386988715176239099720172290594769295756680374928571099138069977179519358166","price":"0.07","size":"1418.78","side":"BUY","hash":"c9a75afed50710e3a4f26bb3034447841bb65135","best_bid":"0.15","best_ask":"0.16"},{"asset_id":"63670753354844494163057275310194312729998307779831462269530137743341854359908","price":"0.93","size":"1418.78","side":"SELL","hash":"8b5097f0df33e9b10c49b826997738977e5aa5ae","best_bid":"0.84","best_ask":"0.85"}],"timestamp":"1768250246734","event_type":"price_change"}}
{"schema_version":1,"source":"clob_ws_market","recv_ts_ns":1768250246798364417,"event_type":"price_change","market":"0x2a12fd3d8235c25c062dc9652970ef9f635636c4018df0909e1a51c673e125cb","server_ts_ms":1768250246777,"raw":{"market":"0x2a12fd3d8235c25c062dc9652970ef9f635636c4018df0909e1a51c673e125cb","price_changes":[{"asset_id":"56386988715176239099720172290594769295756680374928571099138069977179519358166","price":"0.06","size":"1414","side":"BUY","hash":"c1872c9aeeb73eda4143ccf4c69ed3ab355cd891","best_bid":"0.15","best_ask":"0.16"},{"asset_id":"63670753354844494163057275310194312729998307779831462269530137743341854359908","price":"0.94","size":"1414","side":"SELL","hash":"806d2af310bdb41d7353963d0e4403e95d51beff","best_bid":"0.84","best_ask":"0.85"}],"timestamp":"1768250246777","event_type":"price_change"}}
{"schema_version":1,"source":"clob_ws_market","recv_ts_ns":1768250246958586358,"event_type":"price_change","market":"0x2a12fd3d8235c25c062dc9652970ef9f635636c4018df0909e1a51c673e125cb","server_ts_ms":1768250246933,"raw":{"market":"0x2a12fd3d8235c25c062dc9652970ef9f635636c4018df0909e1a51c673e125cb","price_changes":[{"asset_id":"56386988715176239099720172290594769295756680374928571099138069977179519358166","price":"0.14","size":"828.29","side":"BUY","hash":"fa018a4d0a61d0dacaac26cd3017fa8d88a3cb71","best_bid":"0.15","best_ask":"0.16"},{"asset_id":"63670753354844494163057275310194312729998307779831462269530137743341854359908","price":"0.86","size":"828.29","side":"SELL","hash":"36f5da867d70f641e4b2c4d07673c2ede4428c81","best_bid":"0.84","best_ask":"0.85"}],"timestamp":"1768250246933","event_type":"price_change"}}
{"schema_version":1,"source":"clob_ws_market","recv_ts_ns":1768250246963280373,"event_type":"price_change","market":"0x2a12fd3d8235c25c062dc9652970ef9f635636c4018df0909e1a51c673e125cb","server_ts_ms":1768250246938,"raw":{"market":"0x2a12fd3d8235c25c062dc9652970ef9f635636c4018df0909e1a51c673e125cb","price_changes":[{"asset_id":"63670753354844494163057275310194312729998307779831462269530137743341854359908","price":"0.83","size":"700.52","side":"BUY","hash":"5c5d26db8468c73fd9da6ef3abffc6a0b1b929a9","best_bid":"0.84","best_ask":"0.85"},{"asset_id":"56386988715176239099720172290594769295756680374928571099138069977179519358166","price":"0.17","size":"700.52","side":"SELL","hash":"72a067f367e0cc0f4df68b2e010ce5dc1fc5591d","best_bid":"0.15","best_ask":"0.16"}],"timestamp":"1768250246938","event_type":"price_change"}}
{"schema_version":1,"source":"clob_ws_market","recv_ts_ns":1768250247022484507,"event_type":"price_change","market":"0x2a12fd3d8235c25c062dc9652970ef9f635636c4018df0909e1a51c673e125cb","server_ts_ms":1768250246996,"raw":{"market":"0x2a12fd3d8235c25c062dc9652970ef9f635636c4018df0909e1a51c673e125cb","price_changes":[{"asset_id":"56386988715176239099720172290594769295756680374928571099138069977179519358166","price":"0.12","size":"736.75","side":"BUY","hash":"4498eca8914858122254f4f62348cd156e5bbdf1","best_bid":"0.15","best_ask":"0.16"},{"asset_id":"63670753354844494163057275310194312729998307779831462269530137743341854359908","price":"0.88","size":"736.75","side":"SELL","hash":"dc8678ae77cc3cfe0f7fa6e94cad94b78605feb7","best_bid":"0.84","best_ask":"0.85"}],"timestamp":"1768250246996","event_type":"price_change"}}
{"schema_version":1,"source":"clob_ws_market","recv_ts_ns":1768250247070960802,"event_type":"price_change","market":"0x2a12fd3d8235c25c062dc9652970ef9f635636c4018df0909e1a51c673e125cb","server_ts_ms":1768250247049,"raw":{"market":"0x2a12fd3d8235c25c062dc9652970ef9f635636c4018df0909e1a51c673e125cb","price_changes":[{"asset_id":"63670753354844494163057275310194312729998307779831462269530137743341854359908","price":"0.83","size":"200.52","side":"BUY","hash":"18ca204465439ceaaf274ec1f5de2a43e1f86cab","best_bid":"0.84","best_ask":"0.85"},{"asset_id":"56386988715176239099720172290594769295756680374928571099138069977179519358166","price":"0.17","size":"200.52","side":"SELL","hash":"eb72ec44d88e83b327aaab347d184f9c6e76ed64","best_bid":"0.15","best_ask":"0.16"}],"timestamp":"1768250247049","event_type":"price_change"}}
{"schema_version":1,"source":"clob_ws_market","recv_ts_ns":1768250247203523277,"event_type":"price_change","market":"0x2a12fd3d8235c25c062dc9652970ef9f635636c4018df0909e1a51c673e125cb","server_ts_ms":1768250247169,"raw":{"market":"0x2a12fd3d8235c25c062dc9652970ef9f635636c4018df0909e1a51c673e125cb","price_changes":[{"asset_id":"63670753354844494163057275310194312729998307779831462269530137743341854359908","price":"0.77","size":"756.5","side":"BUY","hash":"c6e6512ddbdfa639e30ce95eae507274a47489af","best_bid":"0.84","best_ask":"0.85"},{"asset_id":"56386988715176239099720172290594769295756680374928571099138069977179519358166","price":"0.23","size":"756.5","side":"SELL","hash":"2ac8ed893a16541a9165e94f2b355eb859d2051b","best_bid":"0.15","best_ask":"0.16"}],"timestamp":"1768250247169","event_type":"price_change"}}
{"schema_version":1,"source":"clob_ws_market","recv_ts_ns":1768250247208607225,"event_type":"price_change","market":"0x2a12fd3d8235c25c062dc9652970ef9f635636c4018df0909e1a51c673e125cb","server_ts_ms":1768250247169,"raw":{"market":"0x2a12fd3d8235c25c062dc9652970ef9f635636c4018df0909e1a51c673e125cb","price_changes":[{"asset_id":"63670753354844494163057275310194312729998307779831462269530137743341854359908","price":"0.88","size":"730.75","side":"SELL","hash":"c6e6512ddbdfa639e30ce95eae507274a47489af","best_bid":"0.84","best_ask":"0.85"},{"asset_id":"56386988715176239099720172290594769295756680374928571099138069977179519358166","price":"0.12","size":"730.75","side":"BUY","hash":"2ac8ed893a16541a9165e94f2b355eb859d2051b","best_bid":"0.15","best_ask":"0.16"}],"timestamp":"1768250247169","event_type":"price_change"}}
{"schema_version":1,"source":"clob_ws_market","recv_ts_ns":1768250247214257865,"event_type":"price_change","market":"0x2a12fd3d8235c25c062dc9652970ef9f635636c4018df0909e1a51c673e125cb","server_ts_ms":1768250247176,"raw":{"market":"0x2a12fd3d8235c25c062dc9652970ef9f635636c4018df0909e1a51c673e125cb","price_changes":[{"asset_id":"56386988715176239099720172290594769295756680374928571099138069977179519358166","price":"0.09","size":"1317","side":"BUY","hash":"0eec5f1f8352a34865778de2ef66856df820978c","best_bid":"0.15","best_ask":"0.16"},{"asset_id":"63670753354844494163057275310194312729998307779831462269530137743341854359908","price":"0.91","size":"1317","side":"SELL","hash":"69b7b3852b9d2156fbfa185a6a9d2cd9173eb388","best_bid":"0.84","best_ask":"0.85"}],"timestamp":"1768250247176","event_type":"price_change"}}
{"schema_version":1,"source":"clob_ws_market","recv_ts_ns":1768250247223710937,"event_type":"price_change","market":"0x2a12fd3d8235c25c062dc9652970ef9f635636c4018df0909e1a51c673e125cb","server_ts_ms":1768250247201,"raw":{"market":"0x2a12fd3d8235c25c062dc9652970ef9f635636c4018df0909e1a51c673e125cb","price_changes":[{"asset_id":"63670753354844494163057275310194312729998307779831462269530137743341854359908","price":"0.87","size":"749.5","side":"SELL","hash":"a2a3144c13dae4db959c481182d3875b72da71c0","best_bid":"0.84","best_ask":"0.85"},{"asset_id":"56386988715176239099720172290594769295756680374928571099138069977179519358166","price":"0.13","size":"749.5","side":"BUY","hash":"18a508c1d39faddd2a732d9a3d68d90face031d7","best_bid":"0.15","best_ask":"0.16"}],"timestamp":"1768250247201","event_type":"price_change"}}
{"schema_version":1,"source":"clob_ws_market","recv_ts_ns":1768250247230559195,"event_type":"price_change","market":"0x2a12fd3d8235c25c062dc9652970ef9f635636c4018df0909e1a51c673e125cb","server_ts_ms":1768250247202,"raw":{"market":"0x2a12fd3d8235c25c062dc9652970ef9f635636c4018df0909e1a51c673e125cb","price_changes":[{"asset_id":"63670753354844494163057275310194312729998307779831462269530137743341854359908","price":"0.76","size":"931.25","side":"BUY","hash":"33224c1cbb0c0989ac1a7c1129076034993ec628","best_bid":"0.84","best_ask":"0.85"},{"asset_id":"56386988715176239099720172290594769295756680374928571099138069977179519358166","price":"0.24","size":"931.25","side":"SELL","hash":"b33be8cc9fd4cce8a92ec9a499f544967fe023de","best_bid":"0.15","best_ask":"0.16"}],"timestamp":"1768250247202","event_type":"price_change"}}
{"schema_version":1,"source":"clob_ws_market","recv_ts_ns":1768250247235741838,"event_type":"price_change","market":"0x2a12fd3d8235c25c062dc9652970ef9f635636c4018df0909e1a51c673e125cb","server_ts_ms":1768250247203,"raw":{"market":"0x2a12fd3d8235c25c062dc9652970ef9f635636c4018df0909e1a51c673e125cb","price_changes":[{"asset_id":"56386988715176239099720172290594769295756680374928571099138069977179519358166","price":"0.1","size":"3497","side":"BUY","hash":"e96b716e13e2d83400e0ab6b9824f2655aee34aa","best_bid":"0.15","best_ask":"0.16"},{"asset_id":"63670753354844494163057275310194312729998307779831462269530137743341854359908","price":"0.9","size":"3497","side":"SELL","hash":"01af7a615383342012d3e15cdb91417fa8e7437a","best_bid":"0.84","best_ask":"0.85"}],"timestamp":"1768250247203","event_type":"price_change"}}
{"schema_version":1,"source":"clob_ws_market","recv_ts_ns":1768250247788484641,"event_type":"best_bid_ask","market":"0x2a12fd3d8235c25c062dc9652970ef9f635636c4018df0909e1a51c673e125cb","server_ts_ms":1768250247764,"raw":{"market":"0x2a12fd3d8235c25c062dc9652970ef9f635636c4018df0909e1a51c673e125cb","asset_id":"63670753354844494163057275310194312729998307779831462269530137743341854359908","best_bid":"0.84","best_ask":"0.85","spread":"0.01","timestamp":"1768250247764","event_type":"best_bid_ask"}}
{"schema_version":1,"source":"clob_ws_market","recv_ts_ns":1768250247791206541,"event_type":"price_change","market":"0x2a12fd3d8235c25c062dc9652970ef9f635636c4018df0909e1a51c673e125cb","server_ts_ms":1768250247761,"raw":{"market":"0x2a12fd3d8235c25c062dc9652970ef9f635636c4018df0909e1a51c673e125cb","price_changes":[{"asset_id":"63670753354844494163057275310194312729998307779831462269530137743341854359908","price":"0.84","size":"637.49","side":"BUY","hash":"834f355304403244dd07840f6c504302c626b779","best_bid":"0.84","best_ask":"0.85"},{"asset_id":"56386988715176239099720172290594769295756680374928571099138069977179519358166","price":"0.16","size":"637.49","side":"SELL","hash":"3cafa4c545e7cd37d14891d687123febf9d17585","best_bid":"0.15","best_ask":"0.16"}],"timestamp":"1768250247761","event_type":"price_change"}}
{"schema_version":1,"source":"clob_ws_market","recv_ts_ns":1768250247801813411,"event_type":"book","market":"0x2a12fd3d8235c25c062dc9652970ef9f635636c4018df0909e1a51c673e125cb","server_ts_ms":1768250247761,"raw":{"market":"0x2a12fd3d8235c25c062dc9652970ef9f635636c4018df0909e1a51c673e125cb","asset_id":"63670753354844494163057275310194312729998307779831462269530137743341854359908","bids":[{"price":"0.01","size":"10189.41"},{"price":"0.02","size":"5982"},{"price":"0.03","size":"5238.94"},{"price":"0.04","size":"5040"},{"price":"0.05","size":"5050"},{"price":"0.06","size":"5005"},{"price":"0.07","size":"5019.28"},{"price":"0.08","size":"5005"},{"price":"0.09","size":"5005"},{"price":"0.1","size":"5030"},{"price":"0.11","size":"5"},{"price":"0.12","size":"5"},{"price":"0.13","size":"5"},{"price":"0.14","size":"5"},{"price":"0.15","size":"10"},{"price":"0.16","size":"5"},{"price":"0.17","size":"5"},{"price":"0.18","size":"5"},{"price":"0.19","size":"5"},{"price":"0.2","size":"5"},{"price":"0.21","size":"5"},{"price":"0.22","size":"5"},{"price":"0.23","size":"5"},{"price":"0.24","size":"5"},{"price":"0.25","size":"10"},{"price":"0.26","size":"5"},{"price":"0.27","size":"5"},{"price":"0.28","size":"5"},{"price":"0.29","size":"15"},{"price":"0.3","size":"10"},{"price":"0.31","size":"5"},{"price":"0.32","size":"5"},{"price":"0.33","size":"5"},{"price":"0.34","size":"505"},{"price":"0.35","size":"510"},{"price":"0.36","size":"510"},{"price":"0.37","size":"505"},{"price":"0.38","size":"505"},{"price":"0.39","size":"755"},{"price":"0.4","size":"760"},{"price":"0.41","size":"916"},{"price":"0.42","size":"671"},{"price":"0.43","size":"827"},{"price":"0.44","size":"827"},{"price":"0.45","size":"817"},{"price":"0.46","size":"872"},{"price":"0.47","size":"839.65"},{"price":"0.48","size":"829"},{"price":"0.49","size":"817"},{"price":"0.5","size":"838.4"},{"price":"0.51","size":"867.58"},{"price":"0.52","size":"817"},{"price":"0.53","size":"827"},{"price":"0.54","size":"847.8"},{"price":"0.55","size":"836.09"},{"price":"0.56","size":"825"},{"price":"0.57","size":"847"},{"price":"0.58","size":"817"},{"price":"0.59","size":"817"},{"price":"0.6","size":"817"},{"price":"0.61","size":"834.5"},{"price":"0.62","size":"817"},{"price":"0.63","size":"497.49"},{"price":"0.64","size":"817"},{"price":"0.65","size":"872"},{"price":"0.66","size":"997.71"},{"price":"0.67","size":"906.8"},{"price":"0.68","size":"902"},{"price":"0.69","size":"922"},{"price":"0.7","size":"911.6"},{"price":"0.71","size":"897"},{"price":"0.72","size":"899.55"},{"price":"0.73","size":"912"},{"price":"0.74","size":"1087.3"},{"price":"0.75","size":"722.5"},{"price":"0.76","size":"931.25"},{"price":"0.77","size":"756.5"},{"price":"0.78","size":"899.5"},{"price":"0.79","size":"808.5"},{"price":"0.8","size":"814.9"},{"price":"0.81","size":"813.21"},{"price":"0.82","size":"1381"},{"price":"0.83","size":"200.52"},{"price":"0.84","size":"637.49"}],"asks":[{"price":"0.99","size":"10331.71"},{"price":"0.98","size":"6299.77"},{"price":"0.97","size":"5625.94"},{"price":"0.96","size":"5427"},{"price":"0.95","size":"3442"},{"price":"0.94","size":"1414"},{"price":"0.93","size":"1418.78"},{"price":"0.92","size":"1546.75"},{"price":"0.91","size":"1317"},{"price":"0.9","size":"3497"},{"price":"0.89","size":"924.5"},{"price":"0.88","size":"730.75"},{"price":"0.87","size":"749.5"},{"price":"0.86","size":"828.29"},{"price":"0.85","size":"550.76"}],"hash":"834f355304403244dd07840f6c504302c626b779","timestamp":"1768250247761","event_type":"book"}}
{"schema_version":1,"source":"clob_ws_market","recv_ts_ns":1768250247804411372,"event_type":"price_change","market":"0x2a12fd3d8235c25c062dc9652970ef9f635636c4018df0909e1a51c673e125cb","server_ts_ms":1768250247764,"raw":{"market":"0x2a12fd3d8235c25c062dc9652970ef9f635636c4018df0909e1a51c673e125cb","price_changes":[{"asset_id":"56386988715176239099720172290594769295756680374928571099138069977179519358166","price":"0.13","size":"1449.5","side":"BUY","hash":"7c5dab328ae6a205aa5a7a5cd2b6b871da4adf3d","best_bid":"0.15","best_ask":"0.16"},{"asset_id":"63670753354844494163057275310194312729998307779831462269530137743341854359908","price":"0.87","size":"1449.5","side":"SELL","hash":"fc784aa451e3b7abb9d60ae969403720f4721628","best_bid":"0.84","best_ask":"0.85"}],"timestamp":"1768250247764","event_type":"price_change"}}
{"schema_version":1,"source":"clob_ws_market","recv_ts_ns":1768250247943434890,"event_type":"price_change","market":"0x2a12fd3d8235c25c062dc9652970ef9f635636c4018df0909e1a51c673e125cb","server_ts_ms":1768250247907,"raw":{"market":"0x2a12fd3d8235c25c062dc9652970ef9f635636c4018df0909e1a51c673e125cb","price_changes":[{"asset_id":"56386988715176239099720172290594769295756680374928571099138069977179519358166","price":"0.1","size":"3447","side":"BUY","hash":"9875d9901df03b4af071121e7ff29bb1ea48e5df","best_bid":"0.15","best_ask":"0.16"},{"asset_id":"63670753354844494163057275310194312729998307779831462269530137743341854359908","price":"0.9","size":"3447","side":"SELL","hash":"4e26120747d6e64b08e9f82a4d09b20dd7a88680","best_bid":"0.84","best_ask":"0.85"}],"timestamp":"1768250247907","event_type":"price_change"}}
{"schema_version":1,"source":"clob_ws_market","recv_ts_ns":1768250247958567412,"event_type":"price_change","market":"0x2a12fd3d8235c25c062dc9652970ef9f635636c4018df0909e1a51c673e125cb","server_ts_ms":1768250247908,"raw":{"market":"0x2a12fd3d8235c25c062dc9652970ef9f635636c4018df0909e1a51c673e125cb","price_changes":[{"asset_id":"63670753354844494163057275310194312729998307779831462269530137743341854359908","price":"0.76","size":"924.25","side":"BUY","hash":"14e505e9711e2d3e87e6ef15d606bcfd0e47385b","best_bid":"0.84","best_ask":"0.85"},{"asset_id":"56386988715176239099720172290594769295756680374928571099138069977179519358166","price":"0.24","size":"924.25","side":"SELL","hash":"d4c843ec2cd8f94581f55c94cb6e2c0318a8c9f0","best_bid":"0.15","best_ask":"0.16"}],"timestamp":"1768250247908","event_type":"price_change"}}
{"schema_version":1,"source":"clob_ws_market","recv_ts_ns":1768250247962859417,"event_type":"price_change","market":"0x2a12fd3d8235c25c062dc9652970ef9f635636c4018df0909e1a51c673e125cb","server_ts_ms":1768250247908,"raw":{"market":"0x2a12fd3d8235c25c062dc9652970ef9f635636c4018df0909e1a51c673e125cb","price_changes":[{"asset_id":"63670753354844494163057275310194312729998307779831462269530137743341854359908","price":"0.87","size":"1443.5","side":"SELL","hash":"14e505e9711e2d3e87e6ef15d606bcfd0e47385b","best_bid":"0.84","best_ask":"0.85"},{"asset_id":"56386988715176239099720172290594769295756680374928571099138069977179519358166","price":"0.13","size":"1443.5","side":"BUY","hash":"d4c843ec2cd8f94581f55c94cb6e2c0318a8c9f0","best_bid":"0.15","best_ask":"0.16"}],"timestamp":"1768250247908","event_type":"price_change"}}
{"schema_version":1,"source":"clob_ws_market","recv_ts_ns":1768250247990056390,"event_type":"price_change","market":"0x2a12fd3d8235c25c062dc9652970ef9f635636c4018df0909e1a51c673e125cb","server_ts_ms":1768250247945,"raw":{"market":"0x2a12fd3d8235c25c062dc9652970ef9f635636c4018df0909e1a51c673e125cb","price_changes":[{"asset_id":"63670753354844494163057275310194312729998307779831462269530137743341854359908","price":"0.86","size":"820.79","side":"SELL","hash":"1b3fc53221f1b6e81c14e7481fa02f199a0c36a3","best_bid":"0.84","best_ask":"0.85"},{"asset_id":"56386988715176239099720172290594769295756680374928571099138069977179519358166","price":"0.14","size":"820.79","side":"BUY","hash":"892a71a829e68507695fbdfc297ea34b5ca6d598","best_bid":"0.15","best_ask":"0.16"}],"timestamp":"1768250247945","event_type":"price_change"}}
{"schema_version":1,"source":"clob_ws_market","recv_ts_ns":1768250247993170936,"event_type":"price_change","market":"0x2a12fd3d8235c25c062dc9652970ef9f635636c4018df0909e1a51c673e125cb","server_ts_ms":1768250247952,"raw":{"market":"0x2a12fd3d8235c25c062dc9652970ef9f635636c4018df0909e1a51c673e125cb","price_changes":[{"asset_id":"63670753354844494163057275310194312729998307779831462269530137743341854359908","price":"0.78","size":"905.5","side":"BUY","hash":"c221bbaa4b90301d3f005f1fcc40a8eec8ad19a9","best_bid":"0.84","best_ask":"0.85"},{"asset_id":"56386988715176239099720172290594769295756680374928571099138069977179519358166","price":"0.22","size":"905.5","side":"SELL","hash":"a16c2b164f89fad782af788e0d35a42a9c3f1af9","best_bid":"0.15","best_ask":"0.16"}],"timestamp":"1768250247952","event_type":"price_change"}}
{"schema_version":1,"source":"clob_ws_market","recv_ts_ns":1768250247997233206,"event_type":"price_change","market":"0x2a12fd3d8235c25c062dc9652970ef9f635636c4018df0909e1a51c673e125cb","server_ts_ms":1768250247953,"raw":{"market":"0x2a12fd3d8235c25c062dc9652970ef9f635636c4018df0909e1a51c673e125cb","price_changes":[{"asset_id":"63670753354844494163057275310194312729998307779831462269530137743341854359908","price":"0.89","size":"930.5","side":"SELL","hash":"57a53494172ee56058342a1fb90819ec2a9908c7","best_bid":"0.84","best_ask":"0.85"},{"asset_id":"56386988715176239099720172290594769295756680374928571099138069977179519358166","price":"0.11","size":"930.5","side":"BUY","hash":"66773bf86bd8398ed7b3dd2d7326993f9ecb46fc","best_bid":"0.15","best_ask":"0.16"}],"timestamp":"1768250247953","event_type":"price_change"}}
{"schema_version":1,"source":"clob_ws_market","recv_ts_ns":1768250248000512115,"event_type":"price_change","market":"0x2a12fd3d8235c25c062dc9652970ef9f635636c4018df0909e1a51c673e125cb","server_ts_ms":1768250247960,"raw":{"market":"0x2a12fd3d8235c25c062dc9652970ef9f635636c4018df0909e1a51c673e125cb","price_changes":[{"asset_id":"56386988715176239099720172290594769295756680374928571099138069977179519358166","price":"0.08","size":"1609.75","side":"BUY","hash":"a27f30d98c1e81e361efd89bff5736d9cc1c2052","best_bid":"0.15","best_ask":"0.16"},{"asset_id":"63670753354844494163057275310194312729998307779831462269530137743341854359908","price":"0.92","size":"1609.75","side":"SELL","hash":"d30abdf1f27f40d221e770e72c163d4208a9e049","best_bid":"0.84","best_ask":"0.85"}],"timestamp":"1768250247960","event_type":"price_change"}}
{"schema_version":1,"source":"clob_ws_market","recv_ts_ns":1768250248063352574,"event_type":"price_change","market":"0x2a12fd3d8235c25c062dc9652970ef9f635636c4018df0909e1a51c673e125cb","server_ts_ms":1768250248031,"raw":{"market":"0x2a12fd3d8235c25c062dc9652970ef9f635636c4018df0909e1a51c673e125cb","price_changes":[{"asset_id":"63670753354844494163057275310194312729998307779831462269530137743341854359908","price":"0.86","size":"828.29","side":"SELL","hash":"3f3d4d97d8b2443c9083af6855015d260f116683","best_bid":"0.84","best_ask":"0.85"},{"asset_id":"56386988715176239099720172290594769295756680374928571099138069977179519358166","price":"0.14","size":"828.29","side":"BUY","hash":"a9df1eca689e3e8c52fcd27c3eee01fbd96aff7e","best_bid":"0.15","best_ask":"0.16"}],"timestamp":"1768250248031","event_type":"price_change"}}
{"schema_version":1,"source":"clob_ws_market","recv_ts_ns":1768250248067516001,"event_type":"price_change","market":"0x2a12fd3d8235c25c062dc9652970ef9f635636c4018df0909e1a51c673e125cb","server_ts_ms":1768250248042,"raw":{"market":"0x2a12fd3d8235c25c062dc9652970ef9f635636c4018df0909e1a51c673e125cb","price_changes":[{"asset_id":"56386988715176239099720172290594769295756680374928571099138069977179519358166","price":"0.13","size":"1433.5","side":"BUY","hash":"ff49799e84756a03c6ee48d83966eb8d33d5d051","best_bid":"0.15","best_ask":"0.16"},{"asset_id":"63670753354844494163057275310194312729998307779831462269530137743341854359908","price":"0.87","size":"1433.5","side":"SELL","hash":"95e467a100e4bca55e071efe0c3e938efda9c369","best_bid":"0.84","best_ask":"0.85"}],"timestamp":"1768250248042","event_type":"price_change"}}
{"schema_version":1,"source":"clob_ws_market","recv_ts_ns":1768250248157125896,"event_type":"price_change","market":"0x2a12fd3d8235c25c062dc9652970ef9f635636c4018df0909e1a51c673e125cb","server_ts_ms":1768250248134,"raw":{"market":"0x2a12fd3d8235c25c062dc9652970ef9f635636c4018df0909e1a51c673e125cb","price_changes":[{"asset_id":"56386988715176239099720172290594769295756680374928571099138069977179519358166","price":"0.06","size":"1397","side":"BUY","hash":"56528c7a6afcad387309a42c1c5182d6a0f40660","best_bid":"0.15","best_ask":"0.16"},{"asset_id":"63670753354844494163057275310194312729998307779831462269530137743341854359908","price":"0.94","size":"1397","side":"SELL","hash":"35ad643db33aa57ece1ea6b2e949c5ae5acb2bc8","best_bid":"0.84","best_ask":"0.85"}],"timestamp":"1768250248134","event_type":"price_change"}}
{"schema_version":1,"source":"clob_ws_market","recv_ts_ns":1768250248192737711,"event_type":"price_change","market":"0x2a12fd3d8235c25c062dc9652970ef9f635636c4018df0909e1a51c673e125cb","server_ts_ms":1768250248172,"raw":{"market":"0x2a12fd3d8235c25c062dc9652970ef9f635636c4018df0909e1a51c673e125cb","price_changes":[{"asset_id":"56386988715176239099720172290594769295756680374928571099138069977179519358166","price":"0.05","size":"3462","side":"BUY","hash":"d1f28ef4adc074203528787fdf687a7f0c35b6de","best_bid":"0.15","best_ask":"0.16"},{"asset_id":"63670753354844494163057275310194312729998307779831462269530137743341854359908","price":"0.95","size":"3462","side":"SELL","hash":"5f7bdcc77968afc6926f61f602e98776ad71080f","best_bid":"0.84","best_ask":"0.85"}],"timestamp":"1768250248172","event_type":"price_change"}}
{"schema_version":1,"source":"clob_ws_market","recv_ts_ns":1768250248362561059,"event_type":"price_change","market":"0x2a12fd3d8235c25c062dc9652970ef9f635636c4018df0909e1a51c673e125cb","server_ts_ms":1768250248334,"raw":{"market":"0x2a12fd3d8235c25c062dc9652970ef9f635636c4018df0909e1a51c673e125cb","price_changes":[{"asset_id":"63670753354844494163057275310194312729998307779831462269530137743341854359908","price":"0.74","size":"1092.3","side":"BUY","hash":"9dc31058f7215ab06f78da090165662e998dd5ac","best_bid":"0.84","best_ask":"0.85"},{"asset_id":"56386988715176239099720172290594769295756680374928571099138069977179519358166","price":"0.26","size":"1092.3","side":"SELL","hash":"47cbc222dbcffff01cc1bcafa9cc6bd1dcb8b784","best_bid":"0.15","best_ask":"0.16"}],"timestamp":"1768250248334","event_type":"price_change"}}
{"schema_version":1,"source":"clob_ws_market","recv_ts_ns":1768250248403823698,"event_type":"price_change","market":"0x2a12fd3d8235c25c062dc9652970ef9f635636c4018df0909e1a51c673e125cb","server_ts_ms":1768250248367,"raw":{"market":"0x2a12fd3d8235c25c062dc9652970ef9f635636c4018df0909e1a51c673e125cb","price_changes":[{"asset_id":"63670753354844494163057275310194312729998307779831462269530137743341854359908","price":"0.86","size":"820.79","side":"SELL","hash":"623376de0ce668a35a07da50d4f2669999095039","best_bid":"0.84","best_ask":"0.85"},{"asset_id":"56386988715176239099720172290594769295756680374928571099138069977179519358166","price":"0.14","size":"820.79","side":"BUY","hash":"542e053c6eae894768cb9903ee7d031eed4ca5f3","best_bid":"0.15","best_ask":"0.16"}],"timestamp":"1768250248367","event_type":"price_change"}}
{"schema_version":1,"source":"clob_ws_market","recv_ts_ns":1768250248443861821,"event_type":"price_change","market":"0x2a12fd3d8235c25c062dc9652970ef9f635636c4018df0909e1a51c673e125cb","server_ts_ms":1768250248411,"raw":{"market":"0x2a12fd3d8235c25c062dc9652970ef9f635636c4018df0909e1a51c673e125cb","price_changes":[{"asset_id":"56386988715176239099720172290594769295756680374928571099138069977179519358166","price":"0.14","size":"825.79","side":"BUY","hash":"f381d6a576ddd5576292d3e0fd3a91f4a5da2ddc","best_bid":"0.15","best_ask":"0.16"},{"asset_id":"63670753354844494163057275310194312729998307779831462269530137743341854359908","price":"0.86","size":"825.79","side":"SELL","hash":"5ef6e50043613f5cd232fe87bd85b418d2e5ed79","best_bid":"0.84","best_ask":"0.85"}],"timestamp":"1768250248411","event_type":"price_change"}}
{"schema_version":1,"source":"clob_ws_market","recv_ts_ns":1768250248567263991,"event_type":"price_change","market":"0x2a12fd3d8235c25c062dc9652970ef9f635636c4018df0909e1a51c673e125cb","server_ts_ms":1768250248537,"raw":{"market":"0x2a12fd3d8235c25c062dc9652970ef9f635636c4018df0909e1a51c673e125cb","price_changes":[{"asset_id":"56386988715176239099720172290594769295756680374928571099138069977179519358166","price":"0.12","size":"710.75","side":"BUY","hash":"45b0a0af2551f58306a85b5ce0367fae86451f4c","best_bid":"0.15","best_ask":"0.16"},{"asset_id":"63670753354844494163057275310194312729998307779831462269530137743341854359908","price":"0.88","size":"710.75","side":"SELL","hash":"4715dc8bba9488e02715ce2caf1a87f944a08abf","best_bid":"0.84","best_ask":"0.85"}],"timestamp":"1768250248537","event_type":"price_change"}}
{"schema_version":1,"source":"clob_ws_market","recv_ts_ns":1768250248574903195,"event_type":"price_change","market":"0x2a12fd3d8235c25c062dc9652970ef9f635636c4018df0909e1a51c673e125cb","server_ts_ms":1768250248537,"raw":{"market":"0x2a12fd3d8235c25c062dc9652970ef9f635636c4018df0909e1a51c673e125cb","price_changes":[{"asset_id":"56386988715176239099720172290594769295756680374928571099138069977179519358166","price":"0.13","size":"1413.5","side":"BUY","hash":"e30ef0ce7e6b3ccdff8d26ca246959731a61d582","best_bid":"0.15","best_ask":"0.16"},{"asset_id":"63670753354844494163057275310194312729998307779831462269530137743341854359908","price":"0.87","size":"1413.5","side":"SELL","hash":"0d6672ddc9a0c0820b92618a18c899eb28166e6d","best_bid":"0.84","best_ask":"0.85"}],"timestamp":"1768250248537","event_type":"price_change"}}
{"schema_version":1,"source":"clob_ws_market","recv_ts_ns":1768250248580576414,"event_type":"price_change","market":"0x2a12fd3d8235c25c062dc9652970ef9f635636c4018df0909e1a51c673e125cb","server_ts_ms":1768250248538,"raw":{"market":"0x2a12fd3d8235c25c062dc9652970ef9f635636c4018df0909e1a51c673e125cb","price_changes":[{"asset_id":"56386988715176239099720172290594769295756680374928571099138069977179519358166","price":"0.13","size":"1433.5","side":"BUY","hash":"ccb85b74a3adeea1d0c6018d4d8b676d90d5efa5","best_bid":"0.15","best_ask":"0.16"},{"asset_id":"63670753354844494163057275310194312729998307779831462269530137743341854359908","price":"0.87","size":"1433.5","side":"SELL","hash":"f8a2d5120bb99da6f03cf103d148cdb6fd35ee55","best_bid":"0.84","best_ask":"0.85"}],"timestamp":"1768250248538","event_type":"price_change"}}
{"schema_version":1,"source":"clob_ws_market","recv_ts_ns":1768250248585963108,"event_type":"price_change","market":"0x2a12fd3d8235c25c062dc9652970ef9f635636c4018df0909e1a51c673e125cb","server_ts_ms":1768250248539,"raw":{"market":"0x2a12fd3d8235c25c062dc9652970ef9f635636c4018df0909e1a51c673e125cb","price_changes":[{"asset_id":"63670753354844494163057275310194312729998307779831462269530137743341854359908","price":"0.87","size":"1413.5","side":"SELL","hash":"deee3541545a7c0997a73c933c137a5b7522805e","best_bid":"0.84","best_ask":"0.85"},{"asset_id":"56386988715176239099720172290594769295756680374928571099138069977179519358166","price":"0.13","size":"1413.5","side":"BUY","hash":"0e2d0bd59dc7cfbe60e410f220c794cdb403cee0","best_bid":"0.15","best_ask":"0.16"}],"timestamp":"1768250248539","event_type":"price_change"}}
{"schema_version":1,"source":"clob_ws_market","recv_ts_ns":1768250248592026053,"event_type":"price_change","market":"0x2a12fd3d8235c25c062dc9652970ef9f635636c4018df0909e1a51c673e125cb","server_ts_ms":1768250248540,"raw":{"market":"0x2a12fd3d8235c25c062dc9652970ef9f635636c4018df0909e1a51c673e125cb","price_changes":[{"asset_id":"56386988715176239099720172290594769295756680374928571099138069977179519358166","price":"0.14","size":"845.79","side":"BUY","hash":"1380821defca0f3bd8172f17b92fb000dd18c251","best_bid":"0.15","best_ask":"0.16"},{"asset_id":"63670753354844494163057275310194312729998307779831462269530137743341854359908","price":"0.86","size":"845.79","side":"SELL","hash":"7a413a307cfadcae18b6a311ac618af9e3d9e7e8","best_bid":"0.84","best_ask":"0.85"}],"timestamp":"1768250248540","event_type":"price_change"}}
{"schema_version":1,"source":"clob_ws_market","recv_ts_ns":1768250248597352412,"event_type":"price_change","market":"0x2a12fd3d8235c25c062dc9652970ef9f635636c4018df0909e1a51c673e125cb","server_ts_ms":1768250248541,"raw":{"market":"0x2a12fd3d8235c25c062dc9652970ef9f635636c4018df0909e1a51c673e125cb","price_changes":[{"asset_id":"63670753354844494163057275310194312729998307779831462269530137743341854359908","price":"0.86","size":"865.79","side":"SELL","hash":"69a575c1de4b2d79a96858225db856d6f46eab0a","best_bid":"0.84","best_ask":"0.85"},{"asset_id":"56386988715176239099720172290594769295756680374928571099138069977179519358166","price":"0.14","size":"865.79","side":"BUY","hash":"5acb4c9a95656278cdefad435d2576b33f30b22c","best_bid":"0.15","best_ask":"0.16"}],"timestamp":"1768250248541","event_type":"price_change"}}
{"schema_version":1,"source":"clob_ws_market","recv_ts_ns":1768250248603489582,"event_type":"price_change","market":"0x2a12fd3d8235c25c062dc9652970ef9f635636c4018df0909e1a51c673e125cb","server_ts_ms":1768250248551,"raw":{"market":"0x2a12fd3d8235c25c062dc9652970ef9f635636c4018df0909e1a51c673e125cb","price_changes":[{"asset_id":"63670753354844494163057275310194312729998307779831462269530137743341854359908","price":"0.74","size":"1087.3","side":"BUY","hash":"d8a8f8426247f4a1830156c4ae783a1897844ea5","best_bid":"0.84","best_ask":"0.85"},{"asset_id":"56386988715176239099720172290594769295756680374928571099138069977179519358166","price":"0.26","size":"1087.3","side":"SELL","hash":"efa663bebff59e71f4b9a0dcc50f4d990fde3ed3","best_bid":"0.15","best_ask":"0.16"}],"timestamp":"1768250248551","event_type":"price_change"}}
{"schema_version":1,"source":"clob_ws_market","recv_ts_ns":1768250248608680950,"event_type":"price_change","market":"0x2a12fd3d8235c25c062dc9652970ef9f635636c4018df0909e1a51c673e125cb","server_ts_ms":1768250248558,"raw":{"market":"0x2a12fd3d8235c25c062dc9652970ef9f635636c4018df0909e1a51c673e125cb","price_changes":[{"asset_id":"63670753354844494163057275310194312729998307779831462269530137743341854359908","price":"0.86","size":"873.29","side":"SELL","hash":"a20dec09e843dac30339c3a14498c5de76c43cad","best_bid":"0.84","best_ask":"0.85"},{"asset_id":"56386988715176239099720172290594769295756680374928571099138069977179519358166","price":"0.14","size":"873.29","side":"BUY","hash":"466d0a4f6c00d989a7dc24a83a46d2570323ae1e","best_bid":"0.15","best_ask":"0.16"}],"timestamp":"1768250248558","event_type":"price_change"}}
{"schema_version":1,"source":"clob_ws_market","recv_ts_ns":1768250248619886391,"event_type":"price_change","market":"0x2a12fd3d8235c25c062dc9652970ef9f635636c4018df0909e1a51c673e125cb","server_ts_ms":1768250248580,"raw":{"market":"0x2a12fd3d8235c25c062dc9652970ef9f635636c4018df0909e1a51c673e125cb","price_changes":[{"asset_id":"63670753354844494163057275310194312729998307779831462269530137743341854359908","price":"0.84","size":"627.49","side":"BUY","hash":"028a0894783e68c04f1dd7513f997eb8ee086031","best_bid":"0.84","best_ask":"0.85"},{"asset_id":"56386988715176239099720172290594769295756680374928571099138069977179519358166","price":"0.16","size":"627.49","side":"SELL","hash":"2c8a82643ac55eb8be49a641badbe783fb75ae5d","best_bid":"0.15","best_ask":"0.16"}],"timestamp":"1768250248580","event_type":"price_change"}}
{"schema_version":1,"source":"clob_ws_market","recv_ts_ns":1768250248625882539,"event_type":"price_change","market":"0x2a12fd3d8235c25c062dc9652970ef9f635636c4018df0909e1a51c673e125cb","server_ts_ms":1768250248583,"raw":{"market":"0x2a12fd3d8235c25c062dc9652970ef9f635636c4018df0909e1a51c673e125cb","price_changes":[{"asset_id":"63670753354844494163057275310194312729998307779831462269530137743341854359908","price":"0.78","size":"899.5","side":"BUY","hash":"35aa28ddc113749c3e577702f3541fda04b316e7","best_bid":"0.84","best_ask":"0.85"},{"asset_id":"56386988715176239099720172290594769295756680374928571099138069977179519358166","price":"0.22","size":"899.5","side":"SELL","hash":"a9a7772f097cfeb89ce5ed173eb9c8078daea04f","best_bid":"0.15","best_ask":"0.16"}],"timestamp":"1768250248583","event_type":"price_change"}}
{"schema_version":1,"source":"clob_ws_market","recv_ts_ns":1768250248633312548,"event_type":"price_change","market":"0x2a12fd3d8235c25c062dc9652970ef9f635636c4018df0909e1a51c673e125cb","server_ts_ms":1768250248583,"raw":{"market":"0x2a12fd3d8235c25c062dc9652970ef9f635636c4018df0909e1a51c673e125cb","price_changes":[{"asset_id":"63670753354844494163057275310194312729998307779831462269530137743341854359908","price":"0.89","size":"924.5","side":"SELL","hash":"35aa28ddc113749c3e577702f3541fda04b316e7","best_bid":"0.84","best_ask":"0.85"},{"asset_id":"56386988715176239099720172290594769295756680374928571099138069977179519358166","price":"0.11","size":"924.5","side":"BUY","hash":"a9a7772f097cfeb89ce5ed173eb9c8078daea04f","best_bid":"0.15","best_ask":"0.16"}],"timestamp":"1768250248583","event_type":"price_change"}}
{"schema_version":1,"source":"clob_ws_market","recv_ts_ns":1768250248638013920,"event_type":"price_change","market":"0x2a12fd3d8235c25c062dc9652970ef9f635636c4018df0909e1a51c673e125cb","server_ts_ms":1768250248584,"raw":{"market":"0x2a12fd3d8235c25c062dc9652970ef9f635636c4018df0909e1a51c673e125cb","price_changes":[{"asset_id":"56386988715176239099720172290594769295756680374928571099138069977179519358166","price":"0.11","size":"914.5","side":"BUY","hash":"58644d7aa94d5ab7e7cbf8f9ec4981940381f130","best_bid":"0.15","best_ask":"0.16"},{"asset_id":"63670753354844494163057275310194312729998307779831462269530137743341854359908","price":"0.89","size":"914.5","side":"SELL","hash":"df5e42e938c7ccd2200b9ed543ad37f51947d5c1","best_bid":"0.84","best_ask":"0.85"}],"timestamp":"1768250248584","event_type":"price_change"}}
{"schema_version":1,"source":"clob_ws_market","recv_ts_ns":1768250248641425990,"event_type":"price_change","market":"0x2a12fd3d8235c25c062dc9652970ef9f635636c4018df0909e1a51c673e125cb","server_ts_ms":1768250248586,"raw":{"market":"0x2a12fd3d8235c25c062dc9652970ef9f635636c4018df0909e1a51c673e125cb","price_changes":[{"asset_id":"56386988715176239099720172290594769295756680374928571099138069977179519358166","price":"0.11","size":"904.5","side":"BUY","hash":"4ba0c752d0241d767221d0e08443f72304c1d20d","best_bid":"0.15","best_ask":"0.16"},{"asset_id":"63670753354844494163057275310194312729998307779831462269530137743341854359908","price":"0.89","size":"904.5","side":"SELL","hash":"0b50563e7fdf13aab2c38154038b2985fcbb1095","best_bid":"0.84","best_ask":"0.85"}],"timestamp":"1768250248586","event_type":"price_change"}}
{"schema_version":1,"source":"clob_ws_market","recv_ts_ns":1768250248647718198,"event_type":"price_change","market":"0x2a12fd3d8235c25c062dc9652970ef9f635636c4018df0909e1a51c673e125cb","server_ts_ms":1768250248586,"raw":{"market":"0x2a12fd3d8235c25c062dc9652970ef9f635636c4018df0909e1a51c673e125cb","price_changes":[{"asset_id":"56386988715176239099720172290594769295756680374928571099138069977179519358166","price":"0.08","size":"1546.75","side":"BUY","hash":"4b389cd8fbf84e9c44ffe950b5755130a45c2943","best_bid":"0.15","best_ask":"0.16"},{"asset_id":"63670753354844494163057275310194312729998307779831462269530137743341854359908","price":"0.92","size":"1546.75","side":"SELL","hash":"4ea7bac88fb1c0807688c11aa47bbfc25350b617","best_bid":"0.84","best_ask":"0.85"}],"timestamp":"1768250248586","event_type":"price_change"}}
{"schema_version":1,"source":"clob_ws_market","recv_ts_ns":1768250248650451945,"event_type":"price_change","market":"0x2a12fd3d8235c25c062dc9652970ef9f635636c4018df0909e1a51c673e125cb","server_ts_ms":1768250248587,"raw":{"market":"0x2a12fd3d8235c25c062dc9652970ef9f635636c4018df0909e1a51c673e125cb","price_changes":[{"asset_id":"63670753354844494163057275310194312729998307779831462269530137743341854359908","price":"0.84","size":"617.49","side":"BUY","hash":"be1bd44207d0c0e94ccb2be630f2fca479682acd","best_bid":"0.84","best_ask":"0.85"},{"asset_id":"56386988715176239099720172290594769295756680374928571099138069977179519358166","price":"0.16","size":"617.49","side":"SELL","hash":"4ec5c21dbf6bfe765cd573e50e643f8e3b55a067","best_bid":"0.15","best_ask":"0.16"}],"timestamp":"1768250248587","event_type":"price_change"}}
{"schema_version":1,"source":"clob_ws_market","recv_ts_ns":1768250248652978802,"event_type":"price_change","market":"0x2a12fd3d8235c25c062dc9652970ef9f635636c4018df0909e1a51c673e125cb","server_ts_ms":1768250248588,"raw":{"market":"0x2a12fd3d8235c25c062dc9652970ef9f635636c4018df0909e1a51c673e125cb","price_changes":[{"asset_id":"56386988715176239099720172290594769295756680374928571099138069977179519358166","price":"0.12","size":"700.75","side":"BUY","hash":"dfdcfbb3703da971a64035d426ce99788e2bf9b9","best_bid":"0.15","best_ask":"0.16"},{"asset_id":"63670753354844494163057275310194312729998307779831462269530137743341854359908","price":"0.88","size":"700.75","side":"SELL","hash":"f59e7a2fdc23ea7fb77a8c8120146449f667bc54","best_bid":"0.84","best_ask":"0.85"}],"timestamp":"1768250248588","event_type":"price_change"}}
{"schema_version":1,"source":"clob_ws_market","recv_ts_ns":1768250248655569892,"event_type":"price_change","market":"0x2a12fd3d8235c25c062dc9652970ef9f635636c4018df0909e1a51c673e125cb","server_ts_ms":1768250248589,"raw":{"market":"0x2a12fd3d8235c25c062dc9652970ef9f635636c4018df0909e1a51c673e125cb","price_changes":[{"asset_id":"56386988715176239099720172290594769295756680374928571099138069977179519358166","price":"0.1","size":"3437","side":"BUY","hash":"48b493f002bed8134f5ddf4718c35d2f24132941","best_bid":"0.15","best_ask":"0.16"},{"asset_id":"63670753354844494163057275310194312729998307779831462269530137743341854359908","price":"0.9","size":"3437","side":"SELL","hash":"b6709d100261153cefaf9a0481aa281be7ff0765","best_bid":"0.84","best_ask":"0.85"}],"timestamp":"1768250248589","event_type":"price_change"}}
{"schema_version":1,"source":"clob_ws_market","recv_ts_ns":1768250248657698325,"event_type":"price_change","market":"0x2a12fd3d8235c25c062dc9652970ef9f635636c4018df0909e1a51c673e125cb","server_ts_ms":1768250248590,"raw":{"market":"0x2a12fd3d8235c25c062dc9652970ef9f635636c4018df0909e1a51c673e125cb","price_changes":[{"asset_id":"63670753354844494163057275310194312729998307779831462269530137743341854359908","price":"0.84","size":"607.49","side":"BUY","hash":"47ccebe53dacc2b0a4a757b0eca334e7c7c3e53e","best_bid":"0.84","best_ask":"0.85"},{"asset_id":"56386988715176239099720172290594769295756680374928571099138069977179519358166","price":"0.16","size":"607.49","side":"SELL","hash":"ef85b2261d4b6a74f339de9a275b0668723bed1b","best_bid":"0.15","best_ask":"0.16"}],"timestamp":"1768250248590","event_type":"price_change"}}
{"schema_version":1,"source":"clob_ws_market","recv_ts_ns":1768250248671417582,"event_type":"price_change","market":"0x2a12fd3d8235c25c062dc9652970ef9f635636c4018df0909e1a51c673e125cb","server_ts_ms":1768250248595,"raw":{"market":"0x2a12fd3d8235c25c062dc9652970ef9f635636c4018df0909e1a51c673e125cb","price_changes":[{"asset_id":"56386988715176239099720172290594769295756680374928571099138069977179519358166","price":"0.15","size":"565.76","side":"BUY","hash":"6c0a4744f1253fb2b9a917c9f0fd7b9ee95df401","best_bid":"0.15","best_ask":"0.16"},{"asset_id":"63670753354844494163057275310194312729998307779831462269530137743341854359908","price":"0.85","size":"565.76","side":"SELL","hash":"4ce66a2d9ceb771bb8cf235c1ff18f39f2400bce","best_bid":"0.84","best_ask":"0.85"}],"timestamp":"1768250248595","event_type":"price_change"}}
{"schema_version":1,"source":"clob_ws_market","recv_ts_ns":1768250248708972482,"event_type":"price_change","market":"0x2a12fd3d8235c25c062dc9652970ef9f635636c4018df0909e1a51c673e125cb","server_ts_ms":1768250248609,"raw":{"market":"0x2a12fd3d8235c25c062dc9652970ef9f635636c4018df0909e1a51c673e125cb","price_changes":[{"asset_id":"63670753354844494163057275310194312729998307779831462269530137743341854359908","price":"0.93","size":"1406.28","side":"SELL","hash":"a86ee309703916933731d60b08d5d45b549b74d3","best_bid":"0.84","best_ask":"0.85"},{"asset_id":"56386988715176239099720172290594769295756680374928571099138069977179519358166","price":"0.07","size":"1406.28","side":"BUY","hash":"ba6985c0a63970096b9b641628b84a32fa05c18f","best_bid":"0.15","best_ask":"0.16"}],"timestamp":"1768250248609","event_type":"price_change"}}
{"schema_version":1,"source":"clob_ws_market","recv_ts_ns":1768250248711869611,"event_type":"price_change","market":"0x2a12fd3d8235c25c062dc9652970ef9f635636c4018df0909e1a51c673e125cb","server_ts_ms":1768250248611,"raw":{"market":"0x2a12fd3d8235c25c062dc9652970ef9f635636c4018df0909e1a51c673e125cb","price_changes":[{"asset_id":"63670753354844494163057275310194312729998307779831462269530137743341854359908","price":"0.84","size":"597.49","side":"BUY","hash":"bb8ff01bc03c3bbf4478d2de0dd06c792c06ccf2","best_bid":"0.84","best_ask":"0.85"},{"asset_id":"56386988715176239099720172290594769295756680374928571099138069977179519358166","price":"0.16","size":"597.49","side":"SELL","hash":"d78f6dd13c032d28f20996b8039144c53bd738c5","best_bid":"0.15","best_ask":"0.16"}],"timestamp":"1768250248611","event_type":"price_change"}}
{"schema_version":1,"source":"clob_ws_market","recv_ts_ns":1768250248715019400,"event_type":"price_change","market":"0x2a12fd3d8235c25c062dc9652970ef9f635636c4018df0909e1a51c673e125cb","server_ts_ms":1768250248612,"raw":{"market":"0x2a12fd3d8235c25c062dc9652970ef9f635636c4018df0909e1a51c673e125cb","price_changes":[{"asset_id":"63670753354844494163057275310194312729998307779831462269530137743341854359908","price":"0.77","size":"762.5","side":"BUY","hash":"28361a1fd40cc346c361f262d321f551c98a977d","best_bid":"0.84","best_ask":"0.85"},{"asset_id":"56386988715176239099720172290594769295756680374928571099138069977179519358166","price":"0.23","size":"762.5","side":"SELL","hash":"92c51ec93824bd8d392e406797767a30f5713742","best_bid":"0.15","best_ask":"0.16"}],"timestamp":"1768250248612","event_type":"price_change"}}
{"schema_version":1,"source":"clob_ws_market","recv_ts_ns":1768250248718870831,"event_type":"price_change","market":"0x2a12fd3d8235c25c062dc9652970ef9f635636c4018df0909e1a51c673e125cb","server_ts_ms":1768250248613,"raw":{"market":"0x2a12fd3d8235c25c062dc9652970ef9f635636c4018df0909e1a51c673e125cb","price_changes":[{"asset_id":"63670753354844494163057275310194312729998307779831462269530137743341854359908","price":"0.88","size":"706.75","side":"SELL","hash":"0d851009d7f438fd9f3263702aaf320615692160","best_bid":"0.84","best_ask":"0.85"},{"asset_id":"56386988715176239099720172290594769295756680374928571099138069977179519358166","price":"0.12","size":"706.75","side":"BUY","hash":"85a2b775b9bea24bbd59691b1d5a2945f025a9f3","best_bid":"0.15","best_ask":"0.16"}],"timestamp":"1768250248613","event_type":"price_change"}}
{"schema_version":1,"source":"clob_ws_market","recv_ts_ns":1768250248722284965,"event_type":"price_change","market":"0x2a12fd3d8235c25c062dc9652970ef9f635636c4018df0909e1a51c673e125cb","server_ts_ms":1768250248614,"raw":{"market":"0x2a12fd3d8235c25c062dc9652970ef9f635636c4018df0909e1a51c673e125cb","price_changes":[{"asset_id":"63670753354844494163057275310194312729998307779831462269530137743341854359908","price":"0.92","size":"1559.25","side":"SELL","hash":"922bc5b2b9465508052c48e533529f022957bcff","best_bid":"0.84","best_ask":"0.85"},{"asset_id":"56386988715176239099720172290594769295756680374928571099138069977179519358166","price":"0.08","size":"1559.25","side":"BUY","hash":"91b70a21b93b4feb106178b244062b8c3b971457","best_bid":"0.15","best_ask":"0.16"}],"timestamp":"1768250248614","event_type":"price_change"}}
{"schema_version":1,"source":"clob_ws_market","recv_ts_ns":1768250248731714289,"event_type":"price_change","market":"0x2a12fd3d8235c25c062dc9652970ef9f635636c4018df0909e1a51c673e125cb","server_ts_ms":1768250248616,"raw":{"market":"0x2a12fd3d8235c25c062dc9652970ef9f635636c4018df0909e1a51c673e125cb","price_changes":[{"asset_id":"56386988715176239099720172290594769295756680374928571099138069977179519358166","price":"0.09","size":"1373","side":"BUY","hash":"51653c454c246e5d964aa7f2916a4aff8794eb19","best_bid":"0.15","best_ask":"0.16"},{"asset_id":"63670753354844494163057275310194312729998307779831462269530137743341854359908","price":"0.91","size":"1373","side":"SELL","hash":"233fc936527fa8c070227cae324a6756fab98c3e","best_bid":"0.84","best_ask":"0.85"}],"timestamp":"1768250248616","event_type":"price_change"}}
{"schema_version":1,"source":"clob_ws_market","recv_ts_ns":1768250248746029653,"event_type":"price_change","market":"0x2a12fd3d8235c25c062dc9652970ef9f635636c4018df0909e1a51c673e125cb","server_ts_ms":1768250248627,"raw":{"market":"0x2a12fd3d8235c25c062dc9652970ef9f635636c4018df0909e1a51c673e125cb","price_changes":[{"asset_id":"63670753354844494163057275310194312729998307779831462269530137743341854359908","price":"0.84","size":"587.49","side":"BUY","hash":"76a9f22ec5b4a7cdcb04726340812fb09b407a97","best_bid":"0.84","best_ask":"0.85"},{"asset_id":"56386988715176239099720172290594769295756680374928571099138069977179519358166","price":"0.16","size":"587.49","side":"SELL","hash":"cc3d7305a28bcdacd8762fdec4642b56a9a1689b","best_bid":"0.15","best_ask":"0.16"}],"timestamp":"1768250248627","event_type":"price_change"}}
{"schema_version":1,"source":"clob_ws_market","recv_ts_ns":1768250248749756769,"event_type":"price_change","market":"0x2a12fd3d8235c25c062dc9652970ef9f635636c4018df0909e1a51c673e125cb","server_ts_ms":1768250248634,"raw":{"market":"0x2a12fd3d8235c25c062dc9652970ef9f635636c4018df0909e1a51c673e125cb","price_changes":[{"asset_id":"56386988715176239099720172290594769295756680374928571099138069977179519358166","price":"0.08","size":"1571.75","side":"BUY","hash":"4ea91d39700c8faf609ef15da4c880023e47719b","best_bid":"0.15","best_ask":"0.16"},{"asset_id":"63670753354844494163057275310194312729998307779831462269530137743341854359908","price":"0.92","size":"1571.75","side":"SELL","hash":"630fcb6bc4941d469a6b1f9dcce6b8344663f1fe","best_bid":"0.84","best_ask":"0.85"}],"timestamp":"1768250248634","event_type":"price_change"}}
{"schema_version":1,"source":"clob_ws_market","recv_ts_ns":1768250248757387572,"event_type":"price_change","market":"0x2a12fd3d8235c25c062dc9652970ef9f635636c4018df0909e1a51c673e125cb","server_ts_ms":1768250248654,"raw":{"market":"0x2a12fd3d8235c25c062dc9652970ef9f635636c4018df0909e1a51c673e125cb","price_changes":[{"asset_id":"63670753354844494163057275310194312729998307779831462269530137743341854359908","price":"0.83","size":"210.52","side":"BUY","hash":"ab794c2c218972390e8d468fa7472847469a7331","best_bid":"0.84","best_ask":"0.85"},{"asset_id":"56386988715176239099720172290594769295756680374928571099138069977179519358166","price":"0.17","size":"210.52","side":"SELL","hash":"2c22b02ca924953a0a9b9345113c73cfa7c9df33","best_bid":"0.15","best_ask":"0.16"}],"timestamp":"1768250248654","event_type":"price_change"}}
{"schema_version":1,"source":"clob_ws_market","recv_ts_ns":1768250248761378195,"event_type":"price_change","market":"0x2a12fd3d8235c25c062dc9652970ef9f635636c4018df0909e1a51c673e125cb","server_ts_ms":1768250248655,"raw":{"market":"0x2a12fd3d8235c25c062dc9652970ef9f635636c4018df0909e1a51c673e125cb","price_changes":[{"asset_id":"56386988715176239099720172290594769295756680374928571099138069977179519358166","price":"0.12","size":"716.75","side":"BUY","hash":"e893883e191946128f5bbb2910859655dbde72e1","best_bid":"0.15","best_ask":"0.16"},{"asset_id":"63670753354844494163057275310194312729998307779831462269530137743341854359908","price":"0.88","size":"716.75","side":"SELL","hash":"98b26821a2912792e351f5391129da12a2bc6898","best_bid":"0.84","best_ask":"0.85"}],"timestamp":"1768250248655","event_type":"price_change"}}
{"schema_version":1,"source":"clob_ws_market","recv_ts_ns":1768250248765805699,"event_type":"price_change","market":"0x2a12fd3d8235c25c062dc9652970ef9f635636c4018df0909e1a51c673e125cb","server_ts_ms":1768250248655,"raw":{"market":"0x2a12fd3d8235c25c062dc9652970ef9f635636c4018df0909e1a51c673e125cb","price_changes":[{"asset_id":"56386988715176239099720172290594769295756680374928571099138069977179519358166","price":"0.13","size":"1423.5","side":"BUY","hash":"5d70d7a60c8b8469f9632b12c0c7ab98c84b75e6","best_bid":"0.15","best_ask":"0.16"},{"asset_id":"63670753354844494163057275310194312729998307779831462269530137743341854359908","price":"0.87","size":"1423.5","side":"SELL","hash":"405891b28eb6fd77588c51f79bcb810c508867d3","best_bid":"0.84","best_ask":"0.85"}],"timestamp":"1768250248655","event_type":"price_change"}}
{"schema_version":1,"source":"clob_ws_market","recv_ts_ns":1768250248768956854,"event_type":"price_change","market":"0x2a12fd3d8235c25c062dc9652970ef9f635636c4018df0909e1a51c673e125cb","server_ts_ms":1768250248659,"raw":{"market":"0x2a12fd3d8235c25c062dc9652970ef9f635636c4018df0909e1a51c673e125cb","price_changes":[{"asset_id":"56386988715176239099720172290594769295756680374928571099138069977179519358166","price":"0.12","size":"726.75","side":"BUY","hash":"b3aaf935cb7fa3272d5951926db6cc54f5789dd1","best_bid":"0.15","best_ask":"0.16"},{"asset_id":"63670753354844494163057275310194312729998307779831462269530137743341854359908","price":"0.88","size":"726.75","side":"SELL","hash":"6f21ee8fc410d6e8921071f6519eeb70d083ed36","best_bid":"0.84","best_ask":"0.85"}],"timestamp":"1768250248659","event_type":"price_change"}}
{"schema_version":1,"source":"clob_ws_market","recv_ts_ns":1768250248772627293,"event_type":"price_change","market":"0x2a12fd3d8235c25c062dc9652970ef9f635636c4018df0909e1a51c673e125cb","server_ts_ms":1768250248661,"raw":{"market":"0x2a12fd3d8235c25c062dc9652970ef9f635636c4018df0909e1a51c673e125cb","price_changes":[{"asset_id":"56386988715176239099720172290594769295756680374928571099138069977179519358166","price":"0.11","size":"914.5","side":"BUY","hash":"ceead7a47459a37ed257168026a8f85097bb3e4a","best_bid":"0.15","best_ask":"0.16"},{"asset_id":"63670753354844494163057275310194312729998307779831462269530137743341854359908","price":"0.89","size":"914.5","side":"SELL","hash":"f53ac154476442800d91a7b90b6d561f9fa71959","best_bid":"0.84","best_ask":"0.85"}],"timestamp":"1768250248661","event_type":"price_change"}}
{"schema_version":1,"source":"clob_ws_market","recv_ts_ns":1768250248775190855,"event_type":"price_change","market":"0x2a12fd3d8235c25c062dc9652970ef9f635636c4018df0909e1a51c673e125cb","server_ts_ms":1768250248662,"raw":{"market":"0x2a12fd3d8235c25c062dc9652970ef9f635636c4018df0909e1a51c673e125cb","price_changes":[{"asset_id":"63670753354844494163057275310194312729998307779831462269530137743341854359908","price":"0.83","size":"220.52","side":"BUY","hash":"81c0be62021bc2a5015b58c0b162de9c9b649651","best_bid":"0.84","best_ask":"0.85"},{"asset_id":"56386988715176239099720172290594769295756680374928571099138069977179519358166","price":"0.17","size":"220.52","side":"SELL","hash":"ea363dc539f2fb0e9a0dc85dc417a5504672914a","best_bid":"0.15","best_ask":"0.16"}],"timestamp":"1768250248662","event_type":"price_change"}}
{"schema_version":1,"source":"clob_ws_market","recv_ts_ns":1768250248777703288,"event_type":"price_change","market":"0x2a12fd3d8235c25c062dc9652970ef9f635636c4018df0909e1a51c673e125cb","server_ts_ms":1768250248667,"raw":{"market":"0x2a12fd3d8235c25c062dc9652970ef9f635636c4018df0909e1a51c673e125cb","price_changes":[{"asset_id":"63670753354844494163057275310194312729998307779831462269530137743341854359908","price":"0.83","size":"230.52","side":"BUY","hash":"448e4ccba2e02ffbb59a95b00231dbdff6d45f81","best_bid":"0.84","best_ask":"0.85"},{"asset_id":"56386988715176239099720172290594769295756680374928571099138069977179519358166","price":"0.17","size":"230.52","side":"SELL","hash":"bb7bee77513fe6c200e31b6329458f3742b89802","best_bid":"0.15","best_ask":"0.16"}],"timestamp":"1768250248667","event_type":"price_change"}}
{"schema_version":1,"source":"clob_ws_market","recv_ts_ns":1768250248779965560,"event_type":"price_change","market":"0x2a12fd3d8235c25c062dc9652970ef9f635636c4018df0909e1a51c673e125cb","server_ts_ms":1768250248673,"raw":{"market":"0x2a12fd3d8235c25c062dc9652970ef9f635636c4018df0909e1a51c673e125cb","price_changes":[{"asset_id":"63670753354844494163057275310194312729998307779831462269530137743341854359908","price":"0.82","size":"881","side":"BUY","hash":"270e3c0a53b6f51f17f7a0829a8dd0cd4342c4df","best_bid":"0.84","best_ask":"0.85"},{"asset_id":"56386988715176239099720172290594769295756680374928571099138069977179519358166","price":"0.18","size":"881","side":"SELL","hash":"8d97eb38e91c06acd06e1cc977c03b4ad8578583","best_bid":"0.15","best_ask":"0.16"}],"timestamp":"1768250248673","event_type":"price_change"}}
{"schema_version":1,"source":"clob_ws_market","recv_ts_ns":1768250248782174844,"event_type":"price_change","market":"0x2a12fd3d8235c25c062dc9652970ef9f635636c4018df0909e1a51c673e125cb","server_ts_ms":1768250248681,"raw":{"market":"0x2a12fd3d8235c25c062dc9652970ef9f635636c4018df0909e1a51c673e125cb","price_changes":[{"asset_id":"63670753354844494163057275310194312729998307779831462269530137743341854359908","price":"0.83","size":"240.52","side":"BUY","hash":"fd525a834a0673e413cbdc45c4b79a9e15c54bb2","best_bid":"0.84","best_ask":"0.85"},{"asset_id":"56386988715176239099720172290594769295756680374928571099138069977179519358166","price":"0.17","size":"240.52","side":"SELL","hash":"87f06c10ea967fd225d9431771a9b7c4ce070d1e","best_bid":"0.15","best_ask":"0.16"}],"timestamp":"1768250248681","event_type":"price_change"}}
{"schema_version":1,"source":"clob_ws_market","recv_ts_ns":1768250248786763516,"event_type":"price_change","market":"0x2a12fd3d8235c25c062dc9652970ef9f635636c4018df0909e1a51c673e125cb","server_ts_ms":1768250248708,"raw":{"market":"0x2a12fd3d8235c25c062dc9652970ef9f635636c4018df0909e1a51c673e125cb","price_changes":[{"asset_id":"63670753354844494163057275310194312729998307779831462269530137743341854359908","price":"0.83","size":"250.52","side":"BUY","hash":"7d6993dbe1c7891c46525bab780f7370678a3d20","best_bid":"0.84","best_ask":"0.85"},{"asset_id":"56386988715176239099720172290594769295756680374928571099138069977179519358166","price":"0.17","size":"250.52","side":"SELL","hash":"21721c567db335c1305579449d0f3be744bdcb6d","best_bid":"0.15","best_ask":"0.16"}],"timestamp":"1768250248708","event_type":"price_change"}}
{"schema_version":1,"source":"clob_ws_market","recv_ts_ns":1768250248797118760,"event_type":"price_change","market":"0x2a12fd3d8235c25c062dc9652970ef9f635636c4018df0909e1a51c673e125cb","server_ts_ms":1768250248738,"raw":{"market":"0x2a12fd3d8235c25c062dc9652970ef9f635636c4018df0909e1a51c673e125cb","price_changes":[{"asset_id":"63670753354844494163057275310194312729998307779831462269530137743341854359908","price":"0.81","size":"723.21","side":"BUY","hash":"f2819874e107b6aae70f729b5e015dc538a4c797","best_bid":"0.84","best_ask":"0.85"},{"asset_id":"56386988715176239099720172290594769295756680374928571099138069977179519358166","price":"0.19","size":"723.21","side":"SELL","hash":"4519f1a08b071332bfc3a33e9663054e0e1d554c","best_bid":"0.15","best_ask":"0.16"}],"timestamp":"1768250248738","event_type":"price_change"}}
{"schema_version":1,"source":"clob_ws_market","recv_ts_ns":1768250248993910123,"event_type":"best_bid_ask","market":"0x2a12fd3d8235c25c062dc9652970ef9f635636c4018df0909e1a51c673e125cb","server_ts_ms":1768250248970,"raw":{"market":"0x2a12fd3d8235c25c062dc9652970ef9f635636c4018df0909e1a51c673e125cb","asset_id":"63670753354844494163057275310194312729998307779831462269530137743341854359908","best_bid":"0.84","best_ask":"0.85","spread":"0.01","timestamp":"1768250248970","event_type":"best_bid_ask"}}
{"schema_version":1,"source":"clob_ws_market","recv_ts_ns":1768250248995647827,"event_type":"price_change","market":"0x2a12fd3d8235c25c062dc9652970ef9f635636c4018df0909e1a51c673e125cb","server_ts_ms":1768250248967,"raw":{"market":"0x2a12fd3d8235c25c062dc9652970ef9f635636c4018df0909e1a51c673e125cb","price_changes":[{"asset_id":"63670753354844494163057275310194312729998307779831462269530137743341854359908","price":"0.84","size":"582.49","side":"BUY","hash":"297f7bec97791c6e284ce8ae0f9b724b03ed9c26","best_bid":"0.84","best_ask":"0.85"},{"asset_id":"56386988715176239099720172290594769295756680374928571099138069977179519358166","price":"0.16","size":"582.49","side":"SELL","hash":"3a0f7e8a20001363d097a553c60173a4accf3658","best_bid":"0.15","best_ask":"0.16"}],"timestamp":"1768250248967","event_type":"price_change"}}
{"schema_version":1,"source":"clob_ws_market","recv_ts_ns":1768250249004244230,"event_type":"book","market":"0x2a12fd3d8235c25c062dc9652970ef9f635636c4018df0909e1a51c673e125cb","server_ts_ms":1768250248967,"raw":{"market":"0x2a12fd3d8235c25c062dc9652970ef9f635636c4018df0909e1a51c673e125cb","asset_id":"63670753354844494163057275310194312729998307779831462269530137743341854359908","bids":[{"price":"0.01","size":"10189.41"},{"price":"0.02","size":"5982"},{"price":"0.03","size":"5238.94"},{"price":"0.04","size":"5040"},{"price":"0.05","size":"5050"},{"price":"0.06","size":"5005"},{"price":"0.07","size":"5019.28"},{"price":"0.08","size":"5005"},{"price":"0.09","size":"5005"},{"price":"0.1","size":"5030"},{"price":"0.11","size":"5"},{"price":"0.12","size":"5"},{"price":"0.13","size":"5"},{"price":"0.14","size":"5"},{"price":"0.15","size":"10"},{"price":"0.16","size":"5"},{"price":"0.17","size":"5"},{"price":"0.18","size":"5"},{"price":"0.19","size":"5"},{"price":"0.2","size":"5"},{"price":"0.21","size":"5"},{"price":"0.22","size":"5"},{"price":"0.23","size":"5"},{"price":"0.24","size":"5"},{"price":"0.25","size":"10"},{"price":"0.26","size":"5"},{"price":"0.27","size":"5"},{"price":"0.28","size":"5"},{"price":"0.29","size":"15"},{"price":"0.3","size":"10"},{"price":"0.31","size":"5"},{"price":"0.32","size":"5"},{"price":"0.33","size":"5"},{"price":"0.34","size":"505"},{"price":"0.35","size":"510"},{"price":"0.36","size":"510"},{"price":"0.37","size":"505"},{"price":"0.38","size":"505"},{"price":"0.39","size":"755"},{"price":"0.4","size":"760"},{"price":"0.41","size":"916"},{"price":"0.42","size":"671"},{"price":"0.43","size":"827"},{"price":"0.44","size":"827"},{"price":"0.45","size":"817"},{"price":"0.46","size":"872"},{"price":"0.47","size":"839.65"},{"price":"0.48","size":"829"},{"price":"0.49","size":"817"},{"price":"0.5","size":"838.4"},{"price":"0.51","size":"867.58"},{"price":"0.52","size":"817"},{"price":"0.53","size":"827"},{"price":"0.54","size":"847.8"},{"price":"0.55","size":"836.09"},{"price":"0.56","size":"825"},{"price":"0.57","size":"847"},{"price":"0.58","size":"817"},{"price":"0.59","size":"817"},{"price":"0.6","size":"817"},{"price":"0.61","size":"834.5"},{"price":"0.62","size":"817"},{"price":"0.63","size":"497.49"},{"price":"0.64","size":"817"},{"price":"0.65","size":"872"},{"price":"0.66","size":"997.71"},{"price":"0.67","size":"906.8"},{"price":"0.68","size":"902"},{"price":"0.69","size":"922"},{"price":"0.7","size":"911.6"},{"price":"0.71","size":"897"},{"price":"0.72","size":"899.55"},{"price":"0.73","size":"912"},{"price":"0.74","size":"1087.3"},{"price":"0.75","size":"722.5"},{"price":"0.76","size":"924.25"},{"price":"0.77","size":"762.5"},{"price":"0.78","size":"899.5"},{"price":"0.79","size":"808.5"},{"price":"0.8","size":"814.9"},{"price":"0.81","size":"723.21"},{"price":"0.82","size":"881"},{"price":"0.83","size":"250.52"},{"price":"0.84","size":"582.49"}],"asks":[{"price":"0.99","size":"10331.71"},{"price":"0.98","size":"6299.77"},{"price":"0.97","size":"5625.94"},{"price":"0.96","size":"5427"},{"price":"0.95","size":"3462"},{"price":"0.94","size":"1397"},{"price":"0.93","size":"1406.28"},{"price":"0.92","size":"1571.75"},{"price":"0.91","size":"1373"},{"price":"0.9","size":"3437"},{"price":"0.89","size":"914.5"},{"price":"0.88","size":"726.75"},{"price":"0.87","size":"1423.5"},{"price":"0.86","size":"873.29"},{"price":"0.85","size":"565.76"}],"hash":"297f7bec97791c6e284ce8ae0f9b724b03ed9c26","timestamp":"1768250248967","event_type":"book"}}
{"schema_version":1,"source":"clob_ws_market","recv_ts_ns":1768250249007122124,"event_type":"price_change","market":"0x2a12fd3d8235c25c062dc9652970ef9f635636c4018df0909e1a51c673e125cb","server_ts_ms":1768250248970,"raw":{"market":"0x2a12fd3d8235c25c062dc9652970ef9f635636c4018df0909e1a51c673e125cb","price_changes":[{"asset_id":"63670753354844494163057275310194312729998307779831462269530137743341854359908","price":"0.81","size":"223.21","side":"BUY","hash":"6f4945c975972f5554b2a1248736cac952d44881","best_bid":"0.84","best_ask":"0.85"},{"asset_id":"56386988715176239099720172290594769295756680374928571099138069977179519358166","price":"0.19","size":"223.21","side":"SELL","hash":"1b494ebf4ffde71534d30a110ab5132b88719e32","best_bid":"0.15","best_ask":"0.16"}],"timestamp":"1768250248970","event_type":"price_change"}}
{"schema_version":1,"source":"clob_ws_market","recv_ts_ns":1768250249014337804,"event_type":"price_change","market":"0x2a12fd3d8235c25c062dc9652970ef9f635636c4018df0909e1a51c673e125cb","server_ts_ms":1768250248971,"raw":{"market":"0x2a12fd3d8235c25c062dc9652970ef9f635636c4018df0909e1a51c673e125cb","price_changes":[{"asset_id":"63670753354844494163057275310194312729998307779831462269530137743341854359908","price":"0.8","size":"904.9","side":"BUY","hash":"713e410270a87b2cc2ad206b8baeff6c3f60f0ec","best_bid":"0.84","best_ask":"0.85"},{"asset_id":"56386988715176239099720172290594769295756680374928571099138069977179519358166","price":"0.2","size":"904.9","side":"SELL","hash":"d51934a9f53423519b53a1c05e06edf458d0845a","best_bid":"0.15","best_ask":"0.16"}],"timestamp":"1768250248971","event_type":"price_change"}}
{"schema_version":1,"source":"clob_ws_market","recv_ts_ns":1768250249047700212,"event_type":"best_bid_ask","market":"0x2a12fd3d8235c25c062dc9652970ef9f635636c4018df0909e1a51c673e125cb","server_ts_ms":1768250249008,"raw":{"market":"0x2a12fd3d8235c25c062dc9652970ef9f635636c4018df0909e1a51c673e125cb","asset_id":"63670753354844494163057275310194312729998307779831462269530137743341854359908","best_bid":"0.84","best_ask":"0.85","spread":"0.01","timestamp":"1768250249008","event_type":"best_bid_ask"}}
{"schema_version":1,"source":"clob_ws_market","recv_ts_ns":1768250249050345393,"event_type":"price_change","market":"0x2a12fd3d8235c25c062dc9652970ef9f635636c4018df0909e1a51c673e125cb","server_ts_ms":1768250249007,"raw":{"market":"0x2a12fd3d8235c25c062dc9652970ef9f635636c4018df0909e1a51c673e125cb","price_changes":[{"asset_id":"63670753354844494163057275310194312729998307779831462269530137743341854359908","price":"0.84","size":"569.99","side":"BUY","hash":"3b65337e7c6b56962727dfa1bc768f1935c15ed4","best_bid":"0.84","best_ask":"0.85"},{"asset_id":"56386988715176239099720172290594769295756680374928571099138069977179519358166","price":"0.16","size":"569.99","side":"SELL","hash":"8d6f965ae6074fee2e874e914997539a598e81ea","best_bid":"0.15","best_ask":"0.16"}],"timestamp":"1768250249007","event_type":"price_change"}}
{"schema_version":1,"source":"clob_ws_market","recv_ts_ns":1768250249061833294,"event_type":"book","market":"0x2a12fd3d8235c25c062dc9652970ef9f635636c4018df0909e1a51c673e125cb","server_ts_ms":1768250249007,"raw":{"market":"0x2a12fd3d8235c25c062dc9652970ef9f635636c4018df0909e1a51c673e125cb","asset_id":"63670753354844494163057275310194312729998307779831462269530137743341854359908","bids":[{"price":"0.01","size":"10189.41"},{"price":"0.02","size":"5982"},{"price":"0.03","size":"5238.94"},{"price":"0.04","size":"5040"},{"price":"0.05","size":"5050"},{"price":"0.06","size":"5005"},{"price":"0.07","size":"5019.28"},{"price":"0.08","size":"5005"},{"price":"0.09","size":"5005"},{"price":"0.1","size":"5030"},{"price":"0.11","size":"5"},{"price":"0.12","size":"5"},{"price":"0.13","size":"5"},{"price":"0.14","size":"5"},{"price":"0.15","size":"10"},{"price":"0.16","size":"5"},{"price":"0.17","size":"5"},{"price":"0.18","size":"5"},{"price":"0.19","size":"5"},{"price":"0.2","size":"5"},{"price":"0.21","size":"5"},{"price":"0.22","size":"5"},{"price":"0.23","size":"5"},{"price":"0.24","size":"5"},{"price":"0.25","size":"10"},{"price":"0.26","size":"5"},{"price":"0.27","size":"5"},{"price":"0.28","size":"5"},{"price":"0.29","size":"15"},{"price":"0.3","size":"10"},{"price":"0.31","size":"5"},{"price":"0.32","size":"5"},{"price":"0.33","size":"5"},{"price":"0.34","size":"505"},{"price":"0.35","size":"510"},{"price":"0.36","size":"510"},{"price":"0.37","size":"505"},{"price":"0.38","size":"505"},{"price":"0.39","size":"755"},{"price":"0.4","size":"760"},{"price":"0.41","size":"916"},{"price":"0.42","size":"671"},{"price":"0.43","size":"827"},{"price":"0.44","size":"827"},{"price":"0.45","size":"817"},{"price":"0.46","size":"872"},{"price":"0.47","size":"839.65"},{"price":"0.48","size":"829"},{"price":"0.49","size":"817"},{"price":"0.5","size":"838.4"},{"price":"0.51","size":"867.58"},{"price":"0.52","size":"817"},{"price":"0.53","size":"827"},{"price":"0.54","size":"847.8"},{"price":"0.55","size":"836.09"},{"price":"0.56","size":"825"},{"price":"0.57","size":"847"},{"price":"0.58","size":"817"},{"price":"0.59","size":"817"},{"price":"0.6","size":"817"},{"price":"0.61","size":"834.5"},{"price":"0.62","size":"817"},{"price":"0.63","size":"497.49"},{"price":"0.64","size":"817"},{"price":"0.65","size":"872"},{"price":"0.66","size":"997.71"},{"price":"0.67","size":"906.8"},{"price":"0.68","size":"902"},{"price":"0.69","size":"922"},{"price":"0.7","size":"911.6"},{"price":"0.71","size":"897"},{"price":"0.72","size":"899.55"},{"price":"0.73","size":"912"},{"price":"0.74","size":"1087.3"},{"price":"0.75","size":"722.5"},{"price":"0.76","size":"924.25"},{"price":"0.77","size":"762.5"},{"price":"0.78","size":"899.5"},{"price":"0.79","size":"808.5"},{"price":"0.8","size":"904.9"},{"price":"0.81","size":"223.21"},{"price":"0.82","size":"881"},{"price":"0.83","size":"250.52"},{"price":"0.84","size":"569.99"}],"asks":[{"price":"0.99","size":"10331.71"},{"price":"0.98","size":"6299.77"},{"price":"0.97","size":"5625.94"},{"price":"0.96","size":"5427"},{"price":"0.95","size":"3462"},{"price":"0.94","size":"1397"},{"price":"0.93","size":"1406.28"},{"price":"0.92","size":"1571.75"},{"price":"0.91","size":"1373"},{"price":"0.9","size":"3437"},{"price":"0.89","size":"914.5"},{"price":"0.88","size":"726.75"},{"price":"0.87","size":"1423.5"},{"price":"0.86","size":"873.29"},{"price":"0.85","size":"565.76"}],"hash":"3b65337e7c6b56962727dfa1bc768f1935c15ed4","timestamp":"1768250249007","event_type":"book"}}
{"schema_version":1,"source":"clob_ws_market","recv_ts_ns":1768250249093803197,"event_type":"price_change","market":"0x2a12fd3d8235c25c062dc9652970ef9f635636c4018df0909e1a51c673e125cb","server_ts_ms":1768250249026,"raw":{"market":"0x2a12fd3d8235c25c062dc9652970ef9f635636c4018df0909e1a51c673e125cb","price_changes":[{"asset_id":"56386988715176239099720172290594769295756680374928571099138069977179519358166","price":"0.14","size":"878.29","side":"BUY","hash":"e85e7f2224b09c353abbee0c97c3bf7a8edb249c","best_bid":"0.15","best_ask":"0.16"},{"asset_id":"63670753354844494163057275310194312729998307779831462269530137743341854359908","price":"0.86","size":"878.29","side":"SELL","hash":"d5b3d30f4feaef53f3c9cedd38f796bf736f5c46","best_bid":"0.84","best_ask":"0.85"}],"timestamp":"1768250249026","event_type":"price_change"}}
{"schema_version":1,"source":"clob_ws_market","recv_ts_ns":1768250249126534420,"event_type":"price_change","market":"0x2a12fd3d8235c25c062dc9652970ef9f635636c4018df0909e1a51c673e125cb","server_ts_ms":1768250249087,"raw":{"market":"0x2a12fd3d8235c25c062dc9652970ef9f635636c4018df0909e1a51c673e125cb","price_changes":[{"asset_id":"56386988715176239099720172290594769295756680374928571099138069977179519358166","price":"0.14","size":"868.29","side":"BUY","hash":"76187effc2f20c2acb385863b1500b04c062219f","best_bid":"0.15","best_ask":"0.16"},{"asset_id":"63670753354844494163057275310194312729998307779831462269530137743341854359908","price":"0.86","size":"868.29","side":"SELL","hash":"6e00dc5351de9498aec42167ea22ae55db25bd41","best_bid":"0.84","best_ask":"0.85"}],"timestamp":"1768250249087","event_type":"price_change"}}
{"schema_version":1,"source":"clob_ws_market","recv_ts_ns":1768250249130551951,"event_type":"price_change","market":"0x2a12fd3d8235c25c062dc9652970ef9f635636c4018df0909e1a51c673e125cb","server_ts_ms":1768250249088,"raw":{"market":"0x2a12fd3d8235c25c062dc9652970ef9f635636c4018df0909e1a51c673e125cb","price_changes":[{"asset_id":"56386988715176239099720172290594769295756680374928571099138069977179519358166","price":"0.11","size":"904.5","side":"BUY","hash":"2a32404157985ac6b6d193ac528125f09566be3e","best_bid":"0.15","best_ask":"0.16"},{"asset_id":"63670753354844494163057275310194312729998307779831462269530137743341854359908","price":"0.89","size":"904.5","side":"SELL","hash":"d4f23abced53b05f9a738288c4462719dac05743","best_bid":"0.84","best_ask":"0.85"}],"timestamp":"1768250249088","event_type":"price_change"}}
{"schema_version":1,"source":"clob_ws_market","recv_ts_ns":1768250249137954709,"event_type":"price_change","market":"0x2a12fd3d8235c25c062dc9652970ef9f635636c4018df0909e1a51c673e125cb","server_ts_ms":1768250249089,"raw":{"market":"0x2a12fd3d8235c25c062dc9652970ef9f635636c4018df0909e1a51c673e125cb","price_changes":[{"asset_id":"63670753354844494163057275310194312729998307779831462269530137743341854359908","price":"0.83","size":"240.52","side":"BUY","hash":"f9d8f8efcbf4d2f4162dbad856cc41c3a692f114","best_bid":"0.84","best_ask":"0.85"},{"asset_id":"56386988715176239099720172290594769295756680374928571099138069977179519358166","price":"0.17","size":"240.52","side":"SELL","hash":"969f738b182232a26981f208ed9a4ff0612e7611","best_bid":"0.15","best_ask":"0.16"}],"timestamp":"1768250249089","event_type":"price_change"}}
{"schema_version":1,"source":"clob_ws_market","recv_ts_ns":1768250249141114905,"event_type":"price_change","market":"0x2a12fd3d8235c25c062dc9652970ef9f635636c4018df0909e1a51c673e125cb","server_ts_ms":1768250249090,"raw":{"market":"0x2a12fd3d8235c25c062dc9652970ef9f635636c4018df0909e1a51c673e125cb","price_changes":[{"asset_id":"63670753354844494163057275310194312729998307779831462269530137743341854359908","price":"0.83","size":"230.52","side":"BUY","hash":"be35f6ff3bf3b6a2726f1261460efeeac4ce99d7","best_bid":"0.84","best_ask":"0.85"},{"asset_id":"56386988715176239099720172290594769295756680374928571099138069977179519358166","price":"0.17","size":"230.52","side":"SELL","hash":"0969f59f11ca6370271b2251cb21ee19472194b5","best_bid":"0.15","best_ask":"0.16"}],"timestamp":"1768250249090","event_type":"price_change"}}
{"schema_version":1,"source":"clob_ws_market","recv_ts_ns":1768250249143308864,"event_type":"price_change","market":"0x2a12fd3d8235c25c062dc9652970ef9f635636c4018df0909e1a51c673e125cb","server_ts_ms":1768250249091,"raw":{"market":"0x2a12fd3d8235c25c062dc9652970ef9f635636c4018df0909e1a51c673e125cb","price_changes":[{"asset_id":"56386988715176239099720172290594769295756680374928571099138069977179519358166","price":"0.12","size":"716.75","side":"BUY","hash":"c8a9000ef1b9baa17af110a472d477537e691a83","best_bid":"0.15","best_ask":"0.16"},{"asset_id":"63670753354844494163057275310194312729998307779831462269530137743341854359908","price":"0.88","size":"716.75","side":"SELL","hash":"4cd165e5a8a8cf432cf91b0cabf8aeb25d28f6e6","best_bid":"0.84","best_ask":"0.85"}],"timestamp":"1768250249091","event_type":"price_change"}}
{"schema_version":1,"source":"clob_ws_market","recv_ts_ns":1768250249146605029,"event_type":"price_change","market":"0x2a12fd3d8235c25c062dc9652970ef9f635636c4018df0909e1a51c673e125cb","server_ts_ms":1768250249093,"raw":{"market":"0x2a12fd3d8235c25c062dc9652970ef9f635636c4018df0909e1a51c673e125cb","price_changes":[{"asset_id":"63670753354844494163057275310194312729998307779831462269530137743341854359908","price":"0.84","size":"559.99","side":"BUY","hash":"bed9d4411dbc5988fc3ec37abcbb88e7740cd516","best_bid":"0.84","best_ask":"0.85"},{"asset_id":"56386988715176239099720172290594769295756680374928571099138069977179519358166","price":"0.16","size":"559.99","side":"SELL","hash":"c901d8d5eef82b7122b21471dae4e39ef84ce92a","best_bid":"0.15","best_ask":"0.16"}],"timestamp":"1768250249093","event_type":"price_change"}}
{"schema_version":1,"source":"clob_ws_market","recv_ts_ns":1768250249150503621,"event_type":"price_change","market":"0x2a12fd3d8235c25c062dc9652970ef9f635636c4018df0909e1a51c673e125cb","server_ts_ms":1768250249093,"raw":{"market":"0x2a12fd3d8235c25c062dc9652970ef9f635636c4018df0909e1a51c673e125cb","price_changes":[{"asset_id":"56386988715176239099720172290594769295756680374928571099138069977179519358166","price":"0.12","size":"706.75","side":"BUY","hash":"db0b1f94b76533ab634267c2f75a3106306c11a5","best_bid":"0.15","best_ask":"0.16"},{"asset_id":"63670753354844494163057275310194312729998307779831462269530137743341854359908","price":"0.88","size":"706.75","side":"SELL","hash":"144b14d46ba822a581ffe67152101ceedb343629","best_bid":"0.84","best_ask":"0.85"}],"timestamp":"1768250249093","event_type":"price_change"}}
{"schema_version":1,"source":"clob_ws_market","recv_ts_ns":1768250249154455221,"event_type":"price_change","market":"0x2a12fd3d8235c25c062dc9652970ef9f635636c4018df0909e1a51c673e125cb","server_ts_ms":1768250249094,"raw":{"market":"0x2a12fd3d8235c25c062dc9652970ef9f635636c4018df0909e1a51c673e125cb","price_changes":[{"asset_id":"56386988715176239099720172290594769295756680374928571099138069977179519358166","price":"0.11","size":"894.5","side":"BUY","hash":"df513a9c8b247bab9096a2cc75c926e2c3d45972","best_bid":"0.15","best_ask":"0.16"},{"asset_id":"63670753354844494163057275310194312729998307779831462269530137743341854359908","price":"0.89","size":"894.5","side":"SELL","hash":"9fd2cdc8599ba3ae6abd6cf6c1eb2c9a190eff2f","best_bid":"0.84","best_ask":"0.85"}],"timestamp":"1768250249094","event_type":"price_change"}}
{"schema_version":1,"source":"clob_ws_market","recv_ts_ns":1768250249159677102,"event_type":"price_change","market":"0x2a12fd3d8235c25c062dc9652970ef9f635636c4018df0909e1a51c673e125cb","server_ts_ms":1768250249095,"raw":{"market":"0x2a12fd3d8235c25c062dc9652970ef9f635636c4018df0909e1a51c673e125cb","price_changes":[{"asset_id":"63670753354844494163057275310194312729998307779831462269530137743341854359908","price":"0.83","size":"220.52","side":"BUY","hash":"b098353d205ed3d191248b8416fb7d9505da6860","best_bid":"0.84","best_ask":"0.85"},{"asset_id":"56386988715176239099720172290594769295756680374928571099138069977179519358166","price":"0.17","size":"220.52","side":"SELL","hash":"92b7d314e56ab384df43d041311ae44e87809e6c","best_bid":"0.15","best_ask":"0.16"}],"timestamp":"1768250249095","event_type":"price_change"}}
{"schema_version":1,"source":"clob_ws_market","recv_ts_ns":1768250249163157267,"event_type":"price_change","market":"0x2a12fd3d8235c25c062dc9652970ef9f635636c4018df0909e1a51c673e125cb","server_ts_ms":1768250249096,"raw":{"market":"0x2a12fd3d8235c25c062dc9652970ef9f635636c4018df0909e1a51c673e125cb","price_changes":[{"asset_id":"63670753354844494163057275310194312729998307779831462269530137743341854359908","price":"0.83","size":"210.52","side":"BUY","hash":"3812c2b3bcceeb3ea2fd6bc3c5ae2255545f42f7","best_bid":"0.84","best_ask":"0.85"},{"asset_id":"56386988715176239099720172290594769295756680374928571099138069977179519358166","price":"0.17","size":"210.52","side":"SELL","hash":"1e1957eed7b9205116aa43de2c7d2f74716ab143","best_bid":"0.15","best_ask":"0.16"}],"timestamp":"1768250249096","event_type":"price_change"}}
{"schema_version":1,"source":"clob_ws_market","recv_ts_ns":1768250249166264476,"event_type":"price_change","market":"0x2a12fd3d8235c25c062dc9652970ef9f635636c4018df0909e1a51c673e125cb","server_ts_ms":1768250249096,"raw":{"market":"0x2a12fd3d8235c25c062dc9652970ef9f635636c4018df0909e1a51c673e125cb","price_changes":[{"asset_id":"56386988715176239099720172290594769295756680374928571099138069977179519358166","price":"0.13","size":"1413.5","side":"BUY","hash":"1919e7a876aafc3cf6eb89b391905139d12ab761","best_bid":"0.15","best_ask":"0.16"},{"asset_id":"63670753354844494163057275310194312729998307779831462269530137743341854359908","price":"0.87","size":"1413.5","side":"SELL","hash":"3507269f20efd32b601b57674ad1b6e1c063329f","best_bid":"0.84","best_ask":"0.85"}],"timestamp":"1768250249096","event_type":"price_change"}}
{"schema_version":1,"source":"clob_ws_market","recv_ts_ns":1768250249169865209,"event_type":"price_change","market":"0x2a12fd3d8235c25c062dc9652970ef9f635636c4018df0909e1a51c673e125cb","server_ts_ms":1768250249097,"raw":{"market":"0x2a12fd3d8235c25c062dc9652970ef9f635636c4018df0909e1a51c673e125cb","price_changes":[{"asset_id":"63670753354844494163057275310194312729998307779831462269530137743341854359908","price":"0.83","size":"200.52","side":"BUY","hash":"aecce0ce5c05a1b15a89a2acff604d73cfa27403","best_bid":"0.84","best_ask":"0.85"},{"asset_id":"56386988715176239099720172290594769295756680374928571099138069977179519358166","price":"0.17","size":"200.52","side":"SELL","hash":"740d05ec4fc1db857527762292f046fb70aa0f46","best_bid":"0.15","best_ask":"0.16"}],"timestamp":"1768250249097","event_type":"price_change"}}
{"schema_version":1,"source":"clob_ws_market","recv_ts_ns":1768250249173408491,"event_type":"price_change","market":"0x2a12fd3d8235c25c062dc9652970ef9f635636c4018df0909e1a51c673e125cb","server_ts_ms":1768250249099,"raw":{"market":"0x2a12fd3d8235c25c062dc9652970ef9f635636c4018df0909e1a51c673e125cb","price_changes":[{"asset_id":"56386988715176239099720172290594769295756680374928571099138069977179519358166","price":"0.14","size":"873.29","side":"BUY","hash":"7fe226eaae48b7820bead8361732789ee5c81103","best_bid":"0.15","best_ask":"0.16"},{"asset_id":"63670753354844494163057275310194312729998307779831462269530137743341854359908","price":"0.86","size":"873.29","side":"SELL","hash":"0aa74201478c61274566ad3d8a82d1a896dd0484","best_bid":"0.84","best_ask":"0.85"}],"timestamp":"1768250249099","event_type":"price_change"}}
{"schema_version":1,"source":"clob_ws_market","recv_ts_ns":1768250249177559474,"event_type":"price_change","market":"0x2a12fd3d8235c25c062dc9652970ef9f635636c4018df0909e1a51c673e125cb","server_ts_ms":1768250249100,"raw":{"market":"0x2a12fd3d8235c25c062dc9652970ef9f635636c4018df0909e1a51c673e125cb","price_changes":[{"asset_id":"63670753354844494163057275310194312729998307779831462269530137743341854359908","price":"0.84","size":"549.99","side":"BUY","hash":"b009c9d8cd8a8fde4926305e2827ed4e3c249bfe","best_bid":"0.84","best_ask":"0.85"},{"asset_id":"56386988715176239099720172290594769295756680374928571099138069977179519358166","price":"0.16","size":"549.99","side":"SELL","hash":"9396c0b19c723653521cbd726fce619d4e58d964","best_bid":"0.15","best_ask":"0.16"}],"timestamp":"1768250249100","event_type":"price_change"}}
{"schema_version":1,"source":"clob_ws_market","recv_ts_ns":1768250249180834812,"event_type":"price_change","market":"0x2a12fd3d8235c25c062dc9652970ef9f635636c4018df0909e1a51c673e125cb","server_ts_ms":1768250249101,"raw":{"market":"0x2a12fd3d8235c25c062dc9652970ef9f635636c4018df0909e1a51c673e125cb","price_changes":[{"asset_id":"56386988715176239099720172290594769295756680374928571099138069977179519358166","price":"0.14","size":"863.29","side":"BUY","hash":"6e047d6a8e8fd6268769c6242dae3fc2694a4488","best_bid":"0.15","best_ask":"0.16"},{"asset_id":"63670753354844494163057275310194312729998307779831462269530137743341854359908","price":"0.86","size":"863.29","side":"SELL","hash":"8d452ec94bb596b670896fad8802b2cc5c76a6a6","best_bid":"0.84","best_ask":"0.85"}],"timestamp":"1768250249101","event_type":"price_change"}}
{"schema_version":1,"source":"clob_ws_market","recv_ts_ns":1768250249183090501,"event_type":"price_change","market":"0x2a12fd3d8235c25c062dc9652970ef9f635636c4018df0909e1a51c673e125cb","server_ts_ms":1768250249103,"raw":{"market":"0x2a12fd3d8235c25c062dc9652970ef9f635636c4018df0909e1a51c673e125cb","price_changes":[{"asset_id":"56386988715176239099720172290594769295756680374928571099138069977179519358166","price":"0.13","size":"1403.5","side":"BUY","hash":"d5cd5bfdcb560abddc90f0c31b38202f02455c86","best_bid":"0.15","best_ask":"0.16"},{"asset_id":"63670753354844494163057275310194312729998307779831462269530137743341854359908","price":"0.87","size":"1403.5","side":"SELL","hash":"d1a4a6f8d8ddcb57c1fb48406727aea4782b7e4e","best_bid":"0.84","best_ask":"0.85"}],"timestamp":"1768250249103","event_type":"price_change"}}
{"schema_version":1,"source":"clob_ws_market","recv_ts_ns":1768250249185121593,"event_type":"price_change","market":"0x2a12fd3d8235c25c062dc9652970ef9f635636c4018df0909e1a51c673e125cb","server_ts_ms":1768250249106,"raw":{"market":"0x2a12fd3d8235c25c062dc9652970ef9f635636c4018df0909e1a51c673e125cb","price_changes":[{"asset_id":"63670753354844494163057275310194312729998307779831462269530137743341854359908","price":"0.84","size":"539.99","side":"BUY","hash":"87a764f4e4d64f5fbe106e07091dc50c1d42c8dc","best_bid":"0.84","best_ask":"0.85"},{"asset_id":"56386988715176239099720172290594769295756680374928571099138069977179519358166","price":"0.16","size":"539.99","side":"SELL","hash":"d8349ed9f4087e67c740eccc19a45fdd3d480b2a","best_bid":"0.15","best_ask":"0.16"}],"timestamp":"1768250249106","event_type":"price_change"}}
{"schema_version":1,"source":"clob_ws_market","recv_ts_ns":1768250249187835393,"event_type":"price_change","market":"0x2a12fd3d8235c25c062dc9652970ef9f635636c4018df0909e1a51c673e125cb","server_ts_ms":1768250249107,"raw":{"market":"0x2a12fd3d8235c25c062dc9652970ef9f635636c4018df0909e1a51c673e125cb","price_changes":[{"asset_id":"63670753354844494163057275310194312729998307779831462269530137743341854359908","price":"0.83","size":"190.52","side":"BUY","hash":"b2566d109c89054d3b718dd12a896ace715de0d2","best_bid":"0.84","best_ask":"0.85"},{"asset_id":"56386988715176239099720172290594769295756680374928571099138069977179519358166","price":"0.17","size":"190.52","side":"SELL","hash":"5be27756bfe0d59f0c47f1a96bc08f18c6de6e2f","best_bid":"0.15","best_ask":"0.16"}],"timestamp":"1768250249107","event_type":"price_change"}}
{"schema_version":1,"source":"clob_ws_market","recv_ts_ns":1768250249194510105,"event_type":"price_change","market":"0x2a12fd3d8235c25c062dc9652970ef9f635636c4018df0909e1a51c673e125cb","server_ts_ms":1768250249108,"raw":{"market":"0x2a12fd3d8235c25c062dc9652970ef9f635636c4018df0909e1a51c673e125cb","price_changes":[{"asset_id":"56386988715176239099720172290594769295756680374928571099138069977179519358166","price":"0.1","size":"3427","side":"BUY","hash":"4a20ef42f3df9273f9e8a72cbf7bd9087edffd7f","best_bid":"0.15","best_ask":"0.16"},{"asset_id":"63670753354844494163057275310194312729998307779831462269530137743341854359908","price":"0.9","size":"3427","side":"SELL","hash":"6a391fd50425deafbe191712e0dc679c453019aa","best_bid":"0.84","best_ask":"0.85"}],"timestamp":"1768250249108","event_type":"price_change"}}
{"schema_version":1,"source":"clob_ws_market","recv_ts_ns":1768250249204410214,"event_type":"price_change","market":"0x2a12fd3d8235c25c062dc9652970ef9f635636c4018df0909e1a51c673e125cb","server_ts_ms":1768250249113,"raw":{"market":"0x2a12fd3d8235c25c062dc9652970ef9f635636c4018df0909e1a51c673e125cb","price_changes":[{"asset_id":"56386988715176239099720172290594769295756680374928571099138069977179519358166","price":"0.11","size":"884.5","side":"BUY","hash":"4d3f8170f3d2604a37173c0c36ff9a805b7ee6af","best_bid":"0.15","best_ask":"0.16"},{"asset_id":"63670753354844494163057275310194312729998307779831462269530137743341854359908","price":"0.89","size":"884.5","side":"SELL","hash":"8336415167cd51db4fea35772dbe90aa60614e5a","best_bid":"0.84","best_ask":"0.85"}],"timestamp":"1768250249113","event_type":"price_change"}}
{"schema_version":1,"source":"clob_ws_market","recv_ts_ns":1768250249206886460,"event_type":"price_change","market":"0x2a12fd3d8235c25c062dc9652970ef9f635636c4018df0909e1a51c673e125cb","server_ts_ms":1768250249114,"raw":{"market":"0x2a12fd3d8235c25c062dc9652970ef9f635636c4018df0909e1a51c673e125cb","price_changes":[{"asset_id":"63670753354844494163057275310194312729998307779831462269530137743341854359908","price":"0.84","size":"529.99","side":"BUY","hash":"f4d659ed345742d715591e7942a230ba6a77ea67","best_bid":"0.84","best_ask":"0.85"},{"asset_id":"56386988715176239099720172290594769295756680374928571099138069977179519358166","price":"0.16","size":"529.99","side":"SELL","hash":"d5bc92ca46dcfba4ef3dab3295373a78ab4fa37b","best_bid":"0.15","best_ask":"0.16"}],"timestamp":"1768250249114","event_type":"price_change"}}
{"schema_version":1,"source":"clob_ws_market","recv_ts_ns":1768250249209621141,"event_type":"price_change","market":"0x2a12fd3d8235c25c062dc9652970ef9f635636c4018df0909e1a51c673e125cb","server_ts_ms":1768250249131,"raw":{"market":"0x2a12fd3d8235c25c062dc9652970ef9f635636c4018df0909e1a51c673e125cb","price_changes":[{"asset_id":"56386988715176239099720172290594769295756680374928571099138069977179519358166","price":"0.12","size":"716.75","side":"BUY","hash":"0a2806f92278ad59bdf3f5445ce461c6e383d322","best_bid":"0.15","best_ask":"0.16"},{"asset_id":"63670753354844494163057275310194312729998307779831462269530137743341854359908","price":"0.88","size":"716.75","side":"SELL","hash":"2adb9b4ba028532170962cc35f706444a2507e42","best_bid":"0.84","best_ask":"0.85"}],"timestamp":"1768250249131","event_type":"price_change"}}
{"schema_version":1,"source":"clob_ws_market","recv_ts_ns":1768250249216120869,"event_type":"price_change","market":"0x2a12fd3d8235c25c062dc9652970ef9f635636c4018df0909e1a51c673e125cb","server_ts_ms":1768250249132,"raw":{"market":"0x2a12fd3d8235c25c062dc9652970ef9f635636c4018df0909e1a51c673e125cb","price_changes":[{"asset_id":"63670753354844494163057275310194312729998307779831462269530137743341854359908","price":"0.83","size":"200.52","side":"BUY","hash":"a08ced4243a4adec3f6269f43b9e4438ee409978","best_bid":"0.84","best_ask":"0.85"},{"asset_id":"56386988715176239099720172290594769295756680374928571099138069977179519358166","price":"0.17","size":"200.52","side":"SELL","hash":"f4a353e4023d8d78af7ea243fe1a5f7e10a5b2a8","best_bid":"0.15","best_ask":"0.16"}],"timestamp":"1768250249132","event_type":"price_change"}}
{"schema_version":1,"source":"clob_ws_market","recv_ts_ns":1768250249219410811,"event_type":"price_change","market":"0x2a12fd3d8235c25c062dc9652970ef9f635636c4018df0909e1a51c673e125cb","server_ts_ms":1768250249133,"raw":{"market":"0x2a12fd3d8235c25c062dc9652970ef9f635636c4018df0909e1a51c673e125cb","price_changes":[{"asset_id":"56386988715176239099720172290594769295756680374928571099138069977179519358166","price":"0.12","size":"726.75","side":"BUY","hash":"f18f84bfffaa35f0ef113c8e256256cc6cf292c4","best_bid":"0.15","best_ask":"0.16"},{"asset_id":"63670753354844494163057275310194312729998307779831462269530137743341854359908","price":"0.88","size":"726.75","side":"SELL","hash":"5055bb1e87a96fa9ff774e8b235c5ea71ad74a22","best_bid":"0.84","best_ask":"0.85"}],"timestamp":"1768250249133","event_type":"price_change"}}
{"schema_version":1,"source":"clob_ws_market","recv_ts_ns":1768250249221736295,"event_type":"price_change","market":"0x2a12fd3d8235c25c062dc9652970ef9f635636c4018df0909e1a51c673e125cb","server_ts_ms":1768250249134,"raw":{"market":"0x2a12fd3d8235c25c062dc9652970ef9f635636c4018df0909e1a51c673e125cb","price_changes":[{"asset_id":"63670753354844494163057275310194312729998307779831462269530137743341854359908","price":"0.83","size":"210.52","side":"BUY","hash":"3df5a76d6ffea5d557697be207fff9b91415237f","best_bid":"0.84","best_ask":"0.85"},{"asset_id":"56386988715176239099720172290594769295756680374928571099138069977179519358166","price":"0.17","size":"210.52","side":"SELL","hash":"621a5e85318f6cdb0662fff92c193e4f0863c28b","best_bid":"0.15","best_ask":"0.16"}],"timestamp":"1768250249134","event_type":"price_change"}}
{"schema_version":1,"source":"clob_ws_market","recv_ts_ns":1768250249223976338,"event_type":"price_change","market":"0x2a12fd3d8235c25c062dc9652970ef9f635636c4018df0909e1a51c673e125cb","server_ts_ms":1768250249135,"raw":{"market":"0x2a12fd3d8235c25c062dc9652970ef9f635636c4018df0909e1a51c673e125cb","price_changes":[{"asset_id":"56386988715176239099720172290594769295756680374928571099138069977179519358166","price":"0.14","size":"873.29","side":"BUY","hash":"e61715096b8417ef1eb7cf0f2bb541d7b5ed17fa","best_bid":"0.15","best_ask":"0.16"},{"asset_id":"63670753354844494163057275310194312729998307779831462269530137743341854359908","price":"0.86","size":"873.29","side":"SELL","hash":"9b52b519e999fbc7b37a91eab8889d2f5e570b73","best_bid":"0.84","best_ask":"0.85"}],"timestamp":"1768250249135","event_type":"price_change"}}
{"schema_version":1,"source":"clob_ws_market","recv_ts_ns":1768250249232092171,"event_type":"best_bid_ask","market":"0x2a12fd3d8235c25c062dc9652970ef9f635636c4018df0909e1a51c673e125cb","server_ts_ms":1768250249138,"raw":{"market":"0x2a12fd3d8235c25c062dc9652970ef9f635636c4018df0909e1a51c673e125cb","asset_id":"63670753354844494163057275310194312729998307779831462269530137743341854359908","best_bid":"0.84","best_ask":"0.85","spread":"0.01","timestamp":"1768250249138","event_type":"best_bid_ask"}}
{"schema_version":1,"source":"clob_ws_market","recv_ts_ns":1768250249235125176,"event_type":"price_change","market":"0x2a12fd3d8235c25c062dc9652970ef9f635636c4018df0909e1a51c673e125cb","server_ts_ms":1768250249138,"raw":{"market":"0x2a12fd3d8235c25c062dc9652970ef9f635636c4018df0909e1a51c673e125cb","price_changes":[{"asset_id":"63670753354844494163057275310194312729998307779831462269530137743341854359908","price":"0.84","size":"523.74","side":"BUY","hash":"4162e73ecf4d46a117830cee0204bbea0577431d","best_bid":"0.84","best_ask":"0.85"},{"asset_id":"56386988715176239099720172290594769295756680374928571099138069977179519358166","price":"0.16","size":"523.74","side":"SELL","hash":"23ecf71ae3638ff8cada1dbcff84be200c506ccf","best_bid":"0.15","best_ask":"0.16"}],"timestamp":"1768250249138","event_type":"price_change"}}
{"schema_version":1,"source":"clob_ws_market","recv_ts_ns":1768250249246693898,"event_type":"book","market":"0x2a12fd3d8235c25c062dc9652970ef9f635636c4018df0909e1a51c673e125cb","server_ts_ms":1768250249138,"raw":{"market":"0x2a12fd3d8235c25c062dc9652970ef9f635636c4018df0909e1a51c673e125cb","asset_id":"63670753354844494163057275310194312729998307779831462269530137743341854359908","bids":[{"price":"0.01","size":"10189.41"},{"price":"0.02","size":"5982"},{"price":"0.03","size":"5238.94"},{"price":"0.04","size":"5040"},{"price":"0.05","size":"5050"},{"price":"0.06","size":"5005"},{"price":"0.07","size":"5019.28"},{"price":"0.08","size":"5005"},{"price":"0.09","size":"5005"},{"price":"0.1","size":"5030"},{"price":"0.11","size":"5"},{"price":"0.12","size":"5"},{"price":"0.13","size":"5"},{"price":"0.14","size":"5"},{"price":"0.15","size":"10"},{"price":"0.16","size":"5"},{"price":"0.17","size":"5"},{"price":"0.18","size":"5"},{"price":"0.19","size":"5"},{"price":"0.2","size":"5"},{"price":"0.21","size":"5"},{"price":"0.22","size":"5"},{"price":"0.23","size":"5"},{"price":"0.24","size":"5"},{"price":"0.25","size":"10"},{"price":"0.26","size":"5"},{"price":"0.27","size":"5"},{"price":"0.28","size":"5"},{"price":"0.29","size":"15"},{"price":"0.3","size":"10"},{"price":"0.31","size":"5"},{"price":"0.32","size":"5"},{"price":"0.33","size":"5"},{"price":"0.34","size":"505"},{"price":"0.35","size":"510"},{"price":"0.36","size":"510"},{"price":"0.37","size":"505"},{"price":"0.38","size":"505"},{"price":"0.39","size":"755"},{"price":"0.4","size":"760"},{"price":"0.41","size":"916"},{"price":"0.42","size":"671"},{"price":"0.43","size":"827"},{"price":"0.44","size":"827"},{"price":"0.45","size":"817"},{"price":"0.46","size":"872"},{"price":"0.47","size":"839.65"},{"price":"0.48","size":"829"},{"price":"0.49","size":"817"},{"price":"0.5","size":"838.4"},{"price":"0.51","size":"867.58"},{"price":"0.52","size":"817"},{"price":"0.53","size":"827"},{"price":"0.54","size":"847.8"},{"price":"0.55","size":"836.09"},{"price":"0.56","size":"825"},{"price":"0.57","size":"847"},{"price":"0.58","size":"817"},{"price":"0.59","size":"817"},{"price":"0.6","size":"817"},{"price":"0.61","size":"834.5"},{"price":"0.62","size":"817"},{"price":"0.63","size":"497.49"},{"price":"0.64","size":"817"},{"price":"0.65","size":"872"},{"price":"0.66","size":"997.71"},{"price":"0.67","size":"906.8"},{"price":"0.68","size":"902"},{"price":"0.69","size":"922"},{"price":"0.7","size":"911.6"},{"price":"0.71","size":"897"},{"price":"0.72","size":"899.55"},{"price":"0.73","size":"912"},{"price":"0.74","size":"1087.3"},{"price":"0.75","size":"722.5"},{"price":"0.76","size":"924.25"},{"price":"0.77","size":"762.5"},{"price":"0.78","size":"899.5"},{"price":"0.79","size":"808.5"},{"price":"0.8","size":"904.9"},{"price":"0.81","size":"223.21"},{"price":"0.82","size":"881"},{"price":"0.83","size":"210.52"},{"price":"0.84","size":"523.74"}],"asks":[{"price":"0.99","size":"10331.71"},{"price":"0.98","size":"6299.77"},{"price":"0.97","size":"5625.94"},{"price":"0.96","size":"5427"},{"price":"0.95","size":"3462"},{"price":"0.94","size":"1397"},{"price":"0.93","size":"1406.28"},{"price":"0.92","size":"1571.75"},{"price":"0.91","size":"1373"},{"price":"0.9","size":"3427"},{"price":"0.89","size":"884.5"},{"price":"0.88","size":"726.75"},{"price":"0.87","size":"1403.5"},{"price":"0.86","size":"873.29"},{"price":"0.85","size":"565.76"}],"hash":"4162e73ecf4d46a117830cee0204bbea0577431d","timestamp":"1768250249138","event_type":"book"}}
{"schema_version":1,"source":"clob_ws_market","recv_ts_ns":1768250249249680575,"event_type":"price_change","market":"0x2a12fd3d8235c25c062dc9652970ef9f635636c4018df0909e1a51c673e125cb","server_ts_ms":1768250249139,"raw":{"market":"0x2a12fd3d8235c25c062dc9652970ef9f635636c4018df0909e1a51c673e125cb","price_changes":[{"asset_id":"63670753354844494163057275310194312729998307779831462269530137743341854359908","price":"0.83","size":"220.52","side":"BUY","hash":"fe4005479653120f08cfe4794913f8fdcbd1f9c8","best_bid":"0.84","best_ask":"0.85"},{"asset_id":"56386988715176239099720172290594769295756680374928571099138069977179519358166","price":"0.17","size":"220.52","side":"SELL","hash":"4d7263e9a4b269196168409f0f65f1d77b86edda","best_bid":"0.15","best_ask":"0.16"}],"timestamp":"1768250249139","event_type":"price_change"}}
{"schema_version":1,"source":"clob_ws_market","recv_ts_ns":1768250249254784426,"event_type":"price_change","market":"0x2a12fd3d8235c25c062dc9652970ef9f635636c4018df0909e1a51c673e125cb","server_ts_ms":1768250249140,"raw":{"market":"0x2a12fd3d8235c25c062dc9652970ef9f635636c4018df0909e1a51c673e125cb","price_changes":[{"asset_id":"56386988715176239099720172290594769295756680374928571099138069977179519358166","price":"0.11","size":"894.5","side":"BUY","hash":"f5b95215685091f650ed171520ca0b2501a3dce0","best_bid":"0.15","best_ask":"0.16"},{"asset_id":"63670753354844494163057275310194312729998307779831462269530137743341854359908","price":"0.89","size":"894.5","side":"SELL","hash":"3cfbf0cde04c23cc7b287204f1311b624d0ea17f","best_bid":"0.84","best_ask":"0.85"}],"timestamp":"1768250249140","event_type":"price_change"}}
{"schema_version":1,"source":"clob_ws_market","recv_ts_ns":1768250249259771927,"event_type":"price_change","market":"0x2a12fd3d8235c25c062dc9652970ef9f635636c4018df0909e1a51c673e125cb","server_ts_ms":1768250249140,"raw":{"market":"0x2a12fd3d8235c25c062dc9652970ef9f635636c4018df0909e1a51c673e125cb","price_changes":[{"asset_id":"56386988715176239099720172290594769295756680374928571099138069977179519358166","price":"0.12","size":"736.75","side":"BUY","hash":"4ace3cdcb4101b2cc2c44ccca645e090ad2d1bf8","best_bid":"0.15","best_ask":"0.16"},{"asset_id":"63670753354844494163057275310194312729998307779831462269530137743341854359908","price":"0.88","size":"736.75","side":"SELL","hash":"b35173cbf722fb0b9d57bc4f427b8b3ac173d310","best_bid":"0.84","best_ask":"0.85"}],"timestamp":"1768250249140","event_type":"price_change"}}
{"schema_version":1,"source":"clob_ws_market","recv_ts_ns":1768250249267528601,"event_type":"best_bid_ask","market":"0x2a12fd3d8235c25c062dc9652970ef9f635636c4018df0909e1a51c673e125cb","server_ts_ms":1768250249145,"raw":{"market":"0x2a12fd3d8235c25c062dc9652970ef9f635636c4018df0909e1a51c673e125cb","asset_id":"63670753354844494163057275310194312729998307779831462269530137743341854359908","best_bid":"0.84","best_ask":"0.85","spread":"0.01","timestamp":"1768250249145","event_type":"best_bid_ask"}}
{"schema_version":1,"source":"clob_ws_market","recv_ts_ns":1768250249270461604,"event_type":"price_change","market":"0x2a12fd3d8235c25c062dc9652970ef9f635636c4018df0909e1a51c673e125cb","server_ts_ms":1768250249144,"raw":{"market":"0x2a12fd3d8235c25c062dc9652970ef9f635636c4018df0909e1a51c673e125cb","price_changes":[{"asset_id":"63670753354844494163057275310194312729998307779831462269530137743341854359908","price":"0.84","size":"516.86","side":"BUY","hash":"f16d701ed780a4dfd51f51c13fd6044fcd038c46","best_bid":"0.84","best_ask":"0.85"},{"asset_id":"56386988715176239099720172290594769295756680374928571099138069977179519358166","price":"0.16","size":"516.86","side":"SELL","hash":"41445a0003623a6bdefe2456aeb4556d7586bda2","best_bid":"0.15","best_ask":"0.16"}],"timestamp":"1768250249144","event_type":"price_change"}}
{"schema_version":1,"source":"clob_ws_market","recv_ts_ns":1768250249283758999,"event_type":"book","market":"0x2a12fd3d8235c25c062dc9652970ef9f635636c4018df0909e1a51c673e125cb","server_ts_ms":1768250249144,"raw":{"market":"0x2a12fd3d8235c25c062dc9652970ef9f635636c4018df0909e1a51c673e125cb","asset_id":"63670753354844494163057275310194312729998307779831462269530137743341854359908","bids":[{"price":"0.01","size":"10189.41"},{"price":"0.02","size":"5982"},{"price":"0.03","size":"5238.94"},{"price":"0.04","size":"5040"},{"price":"0.05","size":"5050"},{"price":"0.06","size":"5005"},{"price":"0.07","size":"5019.28"},{"price":"0.08","size":"5005"},{"price":"0.09","size":"5005"},{"price":"0.1","size":"5030"},{"price":"0.11","size":"5"},{"price":"0.12","size":"5"},{"price":"0.13","size":"5"},{"price":"0.14","size":"5"},{"price":"0.15","size":"10"},{"price":"0.16","size":"5"},{"price":"0.17","size":"5"},{"price":"0.18","size":"5"},{"price":"0.19","size":"5"},{"price":"0.2","size":"5"},{"price":"0.21","size":"5"},{"price":"0.22","size":"5"},{"price":"0.23","size":"5"},{"price":"0.24","size":"5"},{"price":"0.25","size":"10"},{"price":"0.26","size":"5"},{"price":"0.27","size":"5"},{"price":"0.28","size":"5"},{"price":"0.29","size":"15"},{"price":"0.3","size":"10"},{"price":"0.31","size":"5"},{"price":"0.32","size":"5"},{"price":"0.33","size":"5"},{"price":"0.34","size":"505"},{"price":"0.35","size":"510"},{"price":"0.36","size":"510"},{"price":"0.37","size":"505"},{"price":"0.38","size":"505"},{"price":"0.39","size":"755"},{"price":"0.4","size":"760"},{"price":"0.41","size":"916"},{"price":"0.42","size":"671"},{"price":"0.43","size":"827"},{"price":"0.44","size":"827"},{"price":"0.45","size":"817"},{"price":"0.46","size":"872"},{"price":"0.47","size":"839.65"},{"price":"0.48","size":"829"},{"price":"0.49","size":"817"},{"price":"0.5","size":"838.4"},{"price":"0.51","size":"867.58"},{"price":"0.52","size":"817"},{"price":"0.53","size":"827"},{"price":"0.54","size":"847.8"},{"price":"0.55","size":"836.09"},{"price":"0.56","size":"825"},{"price":"0.57","size":"847"},{"price":"0.58","size":"817"},{"price":"0.59","size":"817"},{"price":"0.6","size":"817"},{"price":"0.61","size":"834.5"},{"price":"0.62","size":"817"},{"price":"0.63","size":"497.49"},{"price":"0.64","size":"817"},{"price":"0.65","size":"872"},{"price":"0.66","size":"997.71"},{"price":"0.67","size":"906.8"},{"price":"0.68","size":"902"},{"price":"0.69","size":"922"},{"price":"0.7","size":"911.6"},{"price":"0.71","size":"897"},{"price":"0.72","size":"899.55"},{"price":"0.73","size":"912"},{"price":"0.74","size":"1087.3"},{"price":"0.75","size":"722.5"},{"price":"0.76","size":"924.25"},{"price":"0.77","size":"762.5"},{"price":"0.78","size":"899.5"},{"price":"0.79","size":"808.5"},{"price":"0.8","size":"904.9"},{"price":"0.81","size":"223.21"},{"price":"0.82","size":"881"},{"price":"0.83","size":"220.52"},{"price":"0.84","size":"516.86"}],"asks":[{"price":"0.99","size":"10331.71"},{"price":"0.98","size":"6299.77"},{"price":"0.97","size":"5625.94"},{"price":"0.96","size":"5427"},{"price":"0.95","size":"3462"},{"price":"0.94","size":"1397"},{"price":"0.93","size":"1406.28"},{"price":"0.92","size":"1571.75"},{"price":"0.91","size":"1373"},{"price":"0.9","size":"3427"},{"price":"0.89","size":"894.5"},{"price":"0.88","size":"736.75"},{"price":"0.87","size":"1403.5"},{"price":"0.86","size":"873.29"},{"price":"0.85","size":"565.76"}],"hash":"f16d701ed780a4dfd51f51c13fd6044fcd038c46","timestamp":"1768250249144","event_type":"book"}}
{"schema_version":1,"source":"clob_ws_market","recv_ts_ns":1768250249287394387,"event_type":"price_change","market":"0x2a12fd3d8235c25c062dc9652970ef9f635636c4018df0909e1a51c673e125cb","server_ts_ms":1768250249146,"raw":{"market":"0x2a12fd3d8235c25c062dc9652970ef9f635636c4018df0909e1a51c673e125cb","price_changes":[{"asset_id":"63670753354844494163057275310194312729998307779831462269530137743341854359908","price":"0.83","size":"230.52","side":"BUY","hash":"327868d4b63db0c4585baa36719435bcdea389cf","best_bid":"0.84","best_ask":"0.85"},{"asset_id":"56386988715176239099720172290594769295756680374928571099138069977179519358166","price":"0.17","size":"230.52","side":"SELL","hash":"6682afb72d0b9164e498a6cb7916b13c0bc4e0d1","best_bid":"0.15","best_ask":"0.16"}],"timestamp":"1768250249146","event_type":"price_change"}}
{"schema_version":1,"source":"clob_ws_market","recv_ts_ns":1768250249291567825,"event_type":"price_change","market":"0x2a12fd3d8235c25c062dc9652970ef9f635636c4018df0909e1a51c673e125cb","server_ts_ms":1768250249147,"raw":{"market":"0x2a12fd3d8235c25c062dc9652970ef9f635636c4018df0909e1a51c673e125cb","price_changes":[{"asset_id":"63670753354844494163057275310194312729998307779831462269530137743341854359908","price":"0.83","size":"240.52","side":"BUY","hash":"d9df14cee06ee568ff01927b56249e80b99bc7ce","best_bid":"0.84","best_ask":"0.85"},{"asset_id":"56386988715176239099720172290594769295756680374928571099138069977179519358166","price":"0.17","size":"240.52","side":"SELL","hash":"fa23b1cb6db321ffb1033a53d85249ab1b3e0570","best_bid":"0.15","best_ask":"0.16"}],"timestamp":"1768250249147","event_type":"price_change"}}
{"schema_version":1,"source":"clob_ws_market","recv_ts_ns":1768250249296190394,"event_type":"price_change","market":"0x2a12fd3d8235c25c062dc9652970ef9f635636c4018df0909e1a51c673e125cb","server_ts_ms":1768250249148,"raw":{"market":"0x2a12fd3d8235c25c062dc9652970ef9f635636c4018df0909e1a51c673e125cb","price_changes":[{"asset_id":"56386988715176239099720172290594769295756680374928571099138069977179519358166","price":"0.15","size":"575.76","side":"BUY","hash":"f5042f466d836f152bb2887302c72cb35d9442a1","best_bid":"0.15","best_ask":"0.16"},{"asset_id":"63670753354844494163057275310194312729998307779831462269530137743341854359908","price":"0.85","size":"575.76","side":"SELL","hash":"9015a1c476563fad5fbad4cf0bcdefd2b20f63ce","best_bid":"0.84","best_ask":"0.85"}],"timestamp":"1768250249148","event_type":"price_change"}}
{"schema_version":1,"source":"clob_ws_market","recv_ts_ns":1768250249300590999,"event_type":"price_change","market":"0x2a12fd3d8235c25c062dc9652970ef9f635636c4018df0909e1a51c673e125cb","server_ts_ms":1768250249148,"raw":{"market":"0x2a12fd3d8235c25c062dc9652970ef9f635636c4018df0909e1a51c673e125cb","price_changes":[{"asset_id":"56386988715176239099720172290594769295756680374928571099138069977179519358166","price":"0.15","size":"585.76","side":"BUY","hash":"ab662c4e1bd5cfb2a51ac2045931cbab585dfffe","best_bid":"0.15","best_ask":"0.16"},{"asset_id":"63670753354844494163057275310194312729998307779831462269530137743341854359908","price":"0.85","size":"585.76","side":"SELL","hash":"a1d2229b1e1ad81ce2ba9e54c8e0e9e56d630a8e","best_bid":"0.84","best_ask":"0.85"}],"timestamp":"1768250249148","event_type":"price_change"}}
{"schema_version":1,"source":"clob_ws_market","recv_ts_ns":1768250249304759190,"event_type":"price_change","market":"0x2a12fd3d8235c25c062dc9652970ef9f635636c4018df0909e1a51c673e125cb","server_ts_ms":1768250249150,"raw":{"market":"0x2a12fd3d8235c25c062dc9652970ef9f635636c4018df0909e1a51c673e125cb","price_changes":[{"asset_id":"63670753354844494163057275310194312729998307779831462269530137743341854359908","price":"0.83","size":"250.52","side":"BUY","hash":"8e3a5bc5ad852d52419ec0631e61d08afe9d7930","best_bid":"0.84","best_ask":"0.85"},{"asset_id":"56386988715176239099720172290594769295756680374928571099138069977179519358166","price":"0.17","size":"250.52","side":"SELL","hash":"e4109179dc80388c349a6c42ef1fc3375445c981","best_bid":"0.15","best_ask":"0.16"}],"timestamp":"1768250249150","event_type":"price_change"}}
{"schema_version":1,"source":"clob_ws_market","recv_ts_ns":1768250249309492608,"event_type":"price_change","market":"0x2a12fd3d8235c25c062dc9652970ef9f635636c4018df0909e1a51c673e125cb","server_ts_ms":1768250249151,"raw":{"market":"0x2a12fd3d8235c25c062dc9652970ef9f635636c4018df0909e1a51c673e125cb","price_changes":[{"asset_id":"63670753354844494163057275310194312729998307779831462269530137743341854359908","price":"0.83","size":"260.52","side":"BUY","hash":"e75b9baf5c33ec0fae6e93219dc2ac83ece5324b","best_bid":"0.84","best_ask":"0.85"},{"asset_id":"56386988715176239099720172290594769295756680374928571099138069977179519358166","price":"0.17","size":"260.52","side":"SELL","hash":"48fc80b88f1c8c213bd71f87822568f82e92abd9","best_bid":"0.15","best_ask":"0.16"}],"timestamp":"1768250249151","event_type":"price_change"}}
{"schema_version":1,"source":"clob_ws_market","recv_ts_ns":1768250249314206047,"event_type":"price_change","market":"0x2a12fd3d8235c25c062dc9652970ef9f635636c4018df0909e1a51c673e125cb","server_ts_ms":1768250249155,"raw":{"market":"0x2a12fd3d8235c25c062dc9652970ef9f635636c4018df0909e1a51c673e125cb","price_changes":[{"asset_id":"56386988715176239099720172290594769295756680374928571099138069977179519358166","price":"0.13","size":"1413.5","side":"BUY","hash":"fb272115d41f0e42e91653bb6f6ea7bcf676c1c5","best_bid":"0.15","best_ask":"0.16"},{"asset_id":"63670753354844494163057275310194312729998307779831462269530137743341854359908","price":"0.87","size":"1413.5","side":"SELL","hash":"e9f547594e2a90495a5e55fa4bdcd0968166590e","best_bid":"0.84","best_ask":"0.85"}],"timestamp":"1768250249155","event_type":"price_change"}}
{"schema_version":1,"source":"clob_ws_market","recv_ts_ns":1768250249319115876,"event_type":"price_change","market":"0x2a12fd3d8235c25c062dc9652970ef9f635636c4018df0909e1a51c673e125cb","server_ts_ms":1768250249155,"raw":{"market":"0x2a12fd3d8235c25c062dc9652970ef9f635636c4018df0909e1a51c673e125cb","price_changes":[{"asset_id":"56386988715176239099720172290594769295756680374928571099138069977179519358166","price":"0.11","size":"904.5","side":"BUY","hash":"eb70f403c15c5b3634cb27e611d6af9b0bfa54ac","best_bid":"0.15","best_ask":"0.16"},{"asset_id":"63670753354844494163057275310194312729998307779831462269530137743341854359908","price":"0.89","size":"904.5","side":"SELL","hash":"0dff53abc0f2be34f69ad20a3825690bad5356ed","best_bid":"0.84","best_ask":"0.85"}],"timestamp":"1768250249155","event_type":"price_change"}}
{"schema_version":1,"source":"clob_ws_market","recv_ts_ns":1768250249323173208,"event_type":"price_change","market":"0x2a12fd3d8235c25c062dc9652970ef9f635636c4018df0909e1a51c673e125cb","server_ts_ms":1768250249159,"raw":{"market":"0x2a12fd3d8235c25c062dc9652970ef9f635636c4018df0909e1a51c673e125cb","price_changes":[{"asset_id":"63670753354844494163057275310194312729998307779831462269530137743341854359908","price":"0.83","size":"270.52","side":"BUY","hash":"bb00dab1ad95e69794cbcf923aa3e4f6fc560a0f","best_bid":"0.84","best_ask":"0.85"},{"asset_id":"56386988715176239099720172290594769295756680374928571099138069977179519358166","price":"0.17","size":"270.52","side":"SELL","hash":"bc03984d28459e9190b73f2030c7c01f3cc965f6","best_bid":"0.15","best_ask":"0.16"}],"timestamp":"1768250249159","event_type":"price_change"}}
{"schema_version":1,"source":"clob_ws_market","recv_ts_ns":1768250249327637032,"event_type":"price_change","market":"0x2a12fd3d8235c25c062dc9652970ef9f635636c4018df0909e1a51c673e125cb","server_ts_ms":1768250249160,"raw":{"market":"0x2a12fd3d8235c25c062dc9652970ef9f635636c4018df0909e1a51c673e125cb","price_changes":[{"asset_id":"56386988715176239099720172290594769295756680374928571099138069977179519358166","price":"0.12","size":"746.75","side":"BUY","hash":"eb671d73eb1cadf87bbc6d819a5d83fc07318781","best_bid":"0.15","best_ask":"0.16"},{"asset_id":"63670753354844494163057275310194312729998307779831462269530137743341854359908","price":"0.88","size":"746.75","side":"SELL","hash":"4af1367ea34a8aa09492541cb37356a8e3675489","best_bid":"0.84","best_ask":"0.85"}],"timestamp":"1768250249160","event_type":"price_change"}}
{"schema_version":1,"source":"clob_ws_market","recv_ts_ns":1768250249340749509,"event_type":"price_change","market":"0x2a12fd3d8235c25c062dc9652970ef9f635636c4018df0909e1a51c673e125cb","server_ts_ms":1768250249167,"raw":{"market":"0x2a12fd3d8235c25c062dc9652970ef9f635636c4018df0909e1a51c673e125cb","price_changes":[{"asset_id":"63670753354844494163057275310194312729998307779831462269530137743341854359908","price":"0.83","size":"280.52","side":"BUY","hash":"15781cac4f5ef660d0e952485a5db903ffc3614a","best_bid":"0.84","best_ask":"0.85"},{"asset_id":"56386988715176239099720172290594769295756680374928571099138069977179519358166","price":"0.17","size":"280.52","side":"SELL","hash":"517f34856548819a1b55d099b792a589577f3a21","best_bid":"0.15","best_ask":"0.16"}],"timestamp":"1768250249167","event_type":"price_change"}}
{"schema_version":1,"source":"clob_ws_market","recv_ts_ns":1768250249347594450,"event_type":"price_change","market":"0x2a12fd3d8235c25c062dc9652970ef9f635636c4018df0909e1a51c673e125cb","server_ts_ms":1768250249172,"raw":{"market":"0x2a12fd3d8235c25c062dc9652970ef9f635636c4018df0909e1a51c673e125cb","price_changes":[{"asset_id":"63670753354844494163057275310194312729998307779831462269530137743341854359908","price":"0.83","size":"290.52","side":"BUY","hash":"916593ed8a59b97b1d39b497f1c30bd192cb852a","best_bid":"0.84","best_ask":"0.85"},{"asset_id":"56386988715176239099720172290594769295756680374928571099138069977179519358166","price":"0.17","size":"290.52","side":"SELL","hash":"8880cdf186675849c6e50ce00aa574ebe123a52e","best_bid":"0.15","best_ask":"0.16"}],"timestamp":"1768250249172","event_type":"price_change"}}
{"schema_version":1,"source":"clob_ws_market","recv_ts_ns":1768250249358830080,"event_type":"price_change","market":"0x2a12fd3d8235c25c062dc9652970ef9f635636c4018df0909e1a51c673e125cb","server_ts_ms":1768250249219,"raw":{"market":"0x2a12fd3d8235c25c062dc9652970ef9f635636c4018df0909e1a51c673e125cb","price_changes":[{"asset_id":"63670753354844494163057275310194312729998307779831462269530137743341854359908","price":"0.83","size":"283.02","side":"BUY","hash":"206fd5272e108271e2bb0d5cb9fa8a6cb0f1dccf","best_bid":"0.84","best_ask":"0.85"},{"asset_id":"56386988715176239099720172290594769295756680374928571099138069977179519358166","price":"0.17","size":"283.02","side":"SELL","hash":"7908ca726bc85650d075ddd7f1b45c54b073bc0a","best_bid":"0.15","best_ask":"0.16"}],"timestamp":"1768250249219","event_type":"price_change"}}
{"schema_version":1,"source":"clob_ws_market","recv_ts_ns":1768250249361701531,"event_type":"price_change","market":"0x2a12fd3d8235c25c062dc9652970ef9f635636c4018df0909e1a51c673e125cb","server_ts_ms":1768250249220,"raw":{"market":"0x2a12fd3d8235c25c062dc9652970ef9f635636c4018df0909e1a51c673e125cb","price_changes":[{"asset_id":"56386988715176239099720172290594769295756680374928571099138069977179519358166","price":"0.14","size":"865.79","side":"BUY","hash":"15e19bc288467a30c5ef0032d83281101bb78d4f","best_bid":"0.15","best_ask":"0.16"},{"asset_id":"63670753354844494163057275310194312729998307779831462269530137743341854359908","price":"0.86","size":"865.79","side":"SELL","hash":"1f97e3e96174d19e99b01cc5fadac2cd4580745c","best_bid":"0.84","best_ask":"0.85"}],"timestamp":"1768250249220","event_type":"price_change"}}
{"schema_version":1,"source":"clob_ws_market","recv_ts_ns":1768250249365076968,"event_type":"price_change","market":"0x2a12fd3d8235c25c062dc9652970ef9f635636c4018df0909e1a51c673e125cb","server_ts_ms":1768250249221,"raw":{"market":"0x2a12fd3d8235c25c062dc9652970ef9f635636c4018df0909e1a51c673e125cb","price_changes":[{"asset_id":"56386988715176239099720172290594769295756680374928571099138069977179519358166","price":"0.15","size":"593.26","side":"BUY","hash":"87499438633ed124604b70df4196eb1ee760fa1a","best_bid":"0.15","best_ask":"0.16"},{"asset_id":"63670753354844494163057275310194312729998307779831462269530137743341854359908","price":"0.85","size":"593.26","side":"SELL","hash":"c3ec0f3f1e83de001f024d68469d1d8af8fd5b07","best_bid":"0.84","best_ask":"0.85"}],"timestamp":"1768250249221","event_type":"price_change"}}
{"schema_version":1,"source":"clob_ws_market","recv_ts_ns":1768250249368752788,"event_type":"price_change","market":"0x2a12fd3d8235c25c062dc9652970ef9f635636c4018df0909e1a51c673e125cb","server_ts_ms":1768250249223,"raw":{"market":"0x2a12fd3d8235c25c062dc9652970ef9f635636c4018df0909e1a51c673e125cb","price_changes":[{"asset_id":"63670753354844494163057275310194312729998307779831462269530137743341854359908","price":"0.85","size":"600.76","side":"SELL","hash":"694dd6870e645a392b7ab2286a732423694f66bd","best_bid":"0.84","best_ask":"0.85"},{"asset_id":"56386988715176239099720172290594769295756680374928571099138069977179519358166","price":"0.15","size":"600.76","side":"BUY","hash":"c4b74b6b970167094a6e32e07aef019c5e640e4b","best_bid":"0.15","best_ask":"0.16"}],"timestamp":"1768250249223","event_type":"price_change"}}
{"schema_version":1,"source":"clob_ws_market","recv_ts_ns":1768250249371560880,"event_type":"price_change","market":"0x2a12fd3d8235c25c062dc9652970ef9f635636c4018df0909e1a51c673e125cb","server_ts_ms":1768250249223,"raw":{"market":"0x2a12fd3d8235c25c062dc9652970ef9f635636c4018df0909e1a51c673e125cb","price_changes":[{"asset_id":"63670753354844494163057275310194312729998307779831462269530137743341854359908","price":"0.84","size":"509.36","side":"BUY","hash":"baf649308e1e700d652a39de8e75d0c46809a866","best_bid":"0.84","best_ask":"0.85"},{"asset_id":"56386988715176239099720172290594769295756680374928571099138069977179519358166","price":"0.16","size":"509.36","side":"SELL","hash":"0792916db09414368cfd4143b2243c1f2ab59f76","best_bid":"0.15","best_ask":"0.16"}],"timestamp":"1768250249223","event_type":"price_change"}}
{"schema_version":1,"source":"clob_ws_market","recv_ts_ns":1768250249374066790,"event_type":"price_change","market":"0x2a12fd3d8235c25c062dc9652970ef9f635636c4018df0909e1a51c673e125cb","server_ts_ms":1768250249224,"raw":{"market":"0x2a12fd3d8235c25c062dc9652970ef9f635636c4018df0909e1a51c673e125cb","price_changes":[{"asset_id":"63670753354844494163057275310194312729998307779831462269530137743341854359908","price":"0.86","size":"845.79","side":"SELL","hash":"fc4859d927c1711f83764b47144ea84a6997b2d1","best_bid":"0.84","best_ask":"0.85"},{"asset_id":"56386988715176239099720172290594769295756680374928571099138069977179519358166","price":"0.14","size":"845.79","side":"BUY","hash":"2902127bf3c3f6b0bc1da3251ad158ae4d471468","best_bid":"0.15","best_ask":"0.16"}],"timestamp":"1768250249224","event_type":"price_change"}}
{"schema_version":1,"source":"clob_ws_market","recv_ts_ns":1768250249376425808,"event_type":"price_change","market":"0x2a12fd3d8235c25c062dc9652970ef9f635636c4018df0909e1a51c673e125cb","server_ts_ms":1768250249225,"raw":{"market":"0x2a12fd3d8235c25c062dc9652970ef9f635636c4018df0909e1a51c673e125cb","price_changes":[{"asset_id":"56386988715176239099720172290594769295756680374928571099138069977179519358166","price":"0.17","size":"290.52","side":"SELL","hash":"e546a78ab92ef2119e6d91837e296a4be2886582","best_bid":"0.15","best_ask":"0.16"},{"asset_id":"63670753354844494163057275310194312729998307779831462269530137743341854359908","price":"0.83","size":"290.52","side":"BUY","hash":"5c9afe0eb900225e55bc0501e10b20abce3f8cbc","best_bid":"0.84","best_ask":"0.85"}],"timestamp":"1768250249225","event_type":"price_change"}}
{"schema_version":1,"source":"clob_ws_market","recv_ts_ns":1768250249378656562,"event_type":"price_change","market":"0x2a12fd3d8235c25c062dc9652970ef9f635636c4018df0909e1a51c673e125cb","server_ts_ms":1768250249225,"raw":{"market":"0x2a12fd3d8235c25c062dc9652970ef9f635636c4018df0909e1a51c673e125cb","price_changes":[{"asset_id":"56386988715176239099720172290594769295756680374928571099138069977179519358166","price":"0.15","size":"620.76","side":"BUY","hash":"7f430be9fa991093e17621cdc89b107e87e9cee7","best_bid":"0.15","best_ask":"0.16"},{"asset_id":"63670753354844494163057275310194312729998307779831462269530137743341854359908","price":"0.85","size":"620.76","side":"SELL","hash":"ab04182ce154e43fe1a39a603fbaa74cd848fae4","best_bid":"0.84","best_ask":"0.85"}],"timestamp":"1768250249225","event_type":"price_change"}}
{"schema_version":1,"source":"clob_ws_market","recv_ts_ns":1768250249380809180,"event_type":"price_change","market":"0x2a12fd3d8235c25c062dc9652970ef9f635636c4018df0909e1a51c673e125cb","server_ts_ms":1768250249226,"raw":{"market":"0x2a12fd3d8235c25c062dc9652970ef9f635636c4018df0909e1a51c673e125cb","price_changes":[{"asset_id":"56386988715176239099720172290594769295756680374928571099138069977179519358166","price":"0.16","size":"501.86","side":"SELL","hash":"02e678021e578e4bd363d786c2e3d06fc7755cbd","best_bid":"0.15","best_ask":"0.16"},{"asset_id":"63670753354844494163057275310194312729998307779831462269530137743341854359908","price":"0.84","size":"501.86","side":"BUY","hash":"ec25fea5f5bd950d3b004fc44167ad1691deab04","best_bid":"0.84","best_ask":"0.85"}],"timestamp":"1768250249226","event_type":"price_change"}}
{"schema_version":1,"source":"clob_ws_market","recv_ts_ns":1768250249383185576,"event_type":"price_change","market":"0x2a12fd3d8235c25c062dc9652970ef9f635636c4018df0909e1a51c673e125cb","server_ts_ms":1768250249227,"raw":{"market":"0x2a12fd3d8235c25c062dc9652970ef9f635636c4018df0909e1a51c673e125cb","price_changes":[{"asset_id":"56386988715176239099720172290594769295756680374928571099138069977179519358166","price":"0.13","size":"1393.5","side":"BUY","hash":"341b5b0b28a7556d52eada964f05552662ed210f","best_bid":"0.15","best_ask":"0.16"},{"asset_id":"63670753354844494163057275310194312729998307779831462269530137743341854359908","price":"0.87","size":"1393.5","side":"SELL","hash":"a3285c97de98294fe9457b35b769bf6f61c37d45","best_bid":"0.84","best_ask":"0.85"}],"timestamp":"1768250249227","event_type":"price_change"}}
{"schema_version":1,"source":"clob_ws_market","recv_ts_ns":1768250249385789772,"event_type":"price_change","market":"0x2a12fd3d8235c25c062dc9652970ef9f635636c4018df0909e1a51c673e125cb","server_ts_ms":1768250249227,"raw":{"market":"0x2a12fd3d8235c25c062dc9652970ef9f635636c4018df0909e1a51c673e125cb","price_changes":[{"asset_id":"56386988715176239099720172290594769295756680374928571099138069977179519358166","price":"0.09","size":"1385.5","side":"BUY","hash":"d85b0e6a727127ab5ea30e72c7d7821cb653cfc9","best_bid":"0.15","best_ask":"0.16"},{"asset_id":"63670753354844494163057275310194312729998307779831462269530137743341854359908","price":"0.91","size":"1385.5","side":"SELL","hash":"f45115b3a819771c002e738760bb702f95168f70","best_bid":"0.84","best_ask":"0.85"}],"timestamp":"1768250249227","event_type":"price_change"}}
{"schema_version":1,"source":"clob_ws_market","recv_ts_ns":1768250249388359744,"event_type":"price_change","market":"0x2a12fd3d8235c25c062dc9652970ef9f635636c4018df0909e1a51c673e125cb","server_ts_ms":1768250249228,"raw":{"market":"0x2a12fd3d8235c25c062dc9652970ef9f635636c4018df0909e1a51c673e125cb","price_changes":[{"asset_id":"63670753354844494163057275310194312729998307779831462269530137743341854359908","price":"0.91","size":"1398","side":"SELL","hash":"24575f179621e3ec7791dd9282c00418c9200828","best_bid":"0.84","best_ask":"0.85"},{"asset_id":"56386988715176239099720172290594769295756680374928571099138069977179519358166","price":"0.09","size":"1398","side":"BUY","hash":"adbc93bb39ae83bc4686c306750884771f7031d5","best_bid":"0.15","best_ask":"0.16"}],"timestamp":"1768250249228","event_type":"price_change"}}
{"schema_version":1,"source":"clob_ws_market","recv_ts_ns":1768250249390604139,"event_type":"price_change","market":"0x2a12fd3d8235c25c062dc9652970ef9f635636c4018df0909e1a51c673e125cb","server_ts_ms":1768250249229,"raw":{"market":"0x2a12fd3d8235c25c062dc9652970ef9f635636c4018df0909e1a51c673e125cb","price_changes":[{"asset_id":"56386988715176239099720172290594769295756680374928571099138069977179519358166","price":"0.14","size":"825.79","side":"BUY","hash":"b5c41bdeca9f14b0a22ff1956aa0901f59a560c5","best_bid":"0.15","best_ask":"0.16"},{"asset_id":"63670753354844494163057275310194312729998307779831462269530137743341854359908","price":"0.86","size":"825.79","side":"SELL","hash":"29fc037250623365fc02fe8c7a9ed1dde0c15942","best_bid":"0.84","best_ask":"0.85"}],"timestamp":"1768250249229","event_type":"price_change"}}
{"schema_version":1,"source":"clob_ws_market","recv_ts_ns":1768250249393022588,"event_type":"price_change","market":"0x2a12fd3d8235c25c062dc9652970ef9f635636c4018df0909e1a51c673e125cb","server_ts_ms":1768250249229,"raw":{"market":"0x2a12fd3d8235c25c062dc9652970ef9f635636c4018df0909e1a51c673e125cb","price_changes":[{"asset_id":"63670753354844494163057275310194312729998307779831462269530137743341854359908","price":"0.85","size":"640.76","side":"SELL","hash":"07d3892d099dd6cd6b1a8e73eb97eaa72a6b4acd","best_bid":"0.84","best_ask":"0.85"},{"asset_id":"56386988715176239099720172290594769295756680374928571099138069977179519358166","price":"0.15","size":"640.76","side":"BUY","hash":"174296f97bf141409a011f98d7cace6960d59ace","best_bid":"0.15","best_ask":"0.16"}],"timestamp":"1768250249229","event_type":"price_change"}}
{"schema_version":1,"source":"clob_ws_market","recv_ts_ns":1768250249395621425,"event_type":"price_change","market":"0x2a12fd3d8235c25c062dc9652970ef9f635636c4018df0909e1a51c673e125cb","server_ts_ms":1768250249230,"raw":{"market":"0x2a12fd3d8235c25c062dc9652970ef9f635636c4018df0909e1a51c673e125cb","price_changes":[{"asset_id":"63670753354844494163057275310194312729998307779831462269530137743341854359908","price":"0.92","size":"1559.25","side":"SELL","hash":"c627ab4cf6882515c2acdda9bb157edf49b8f817","best_bid":"0.84","best_ask":"0.85"},{"asset_id":"56386988715176239099720172290594769295756680374928571099138069977179519358166","price":"0.08","size":"1559.25","side":"BUY","hash":"8054f369c507c9ed5ee69c3c4408ef56bd24c292","best_bid":"0.15","best_ask":"0.16"}],"timestamp":"1768250249230","event_type":"price_change"}}
{"schema_version":1,"source":"clob_ws_market","recv_ts_ns":1768250249398222436,"event_type":"price_change","market":"0x2a12fd3d8235c25c062dc9652970ef9f635636c4018df0909e1a51c673e125cb","server_ts_ms":1768250249231,"raw":{"market":"0x2a12fd3d8235c25c062dc9652970ef9f635636c4018df0909e1a51c673e125cb","price_changes":[{"asset_id":"63670753354844494163057275310194312729998307779831462269530137743341854359908","price":"0.87","size":"1383.5","side":"SELL","hash":"717f73795631c9f7d51f78740dec428db19cb96d","best_bid":"0.84","best_ask":"0.85"},{"asset_id":"56386988715176239099720172290594769295756680374928571099138069977179519358166","price":"0.13","size":"1383.5","side":"BUY","hash":"2abce0a011313977253c833d973dc98dbf4135ac","best_bid":"0.15","best_ask":"0.16"}],"timestamp":"1768250249231","event_type":"price_change"}}
{"schema_version":1,"source":"clob_ws_market","recv_ts_ns":1768250249401052707,"event_type":"price_change","market":"0x2a12fd3d8235c25c062dc9652970ef9f635636c4018df0909e1a51c673e125cb","server_ts_ms":1768250249231,"raw":{"market":"0x2a12fd3d8235c25c062dc9652970ef9f635636c4018df0909e1a51c673e125cb","price_changes":[{"asset_id":"56386988715176239099720172290594769295756680374928571099138069977179519358166","price":"0.12","size":"711.75","side":"BUY","hash":"25bc934920592e71bdba65d523898b0690f3a81b","best_bid":"0.15","best_ask":"0.16"},{"asset_id":"63670753354844494163057275310194312729998307779831462269530137743341854359908","price":"0.88","size":"711.75","side":"SELL","hash":"cedcad3b7c40939cd1b2fcc0643c72a37102dfa4","best_bid":"0.84","best_ask":"0.85"}],"timestamp":"1768250249231","event_type":"price_change"}}
{"schema_version":1,"source":"clob_ws_market","recv_ts_ns":1768250249403535654,"event_type":"price_change","market":"0x2a12fd3d8235c25c062dc9652970ef9f635636c4018df0909e1a51c673e125cb","server_ts_ms":1768250249231,"raw":{"market":"0x2a12fd3d8235c25c062dc9652970ef9f635636c4018df0909e1a51c673e125cb","price_changes":[{"asset_id":"56386988715176239099720172290594769295756680374928571099138069977179519358166","price":"0.14","size":"790.79","side":"BUY","hash":"25bc934920592e71bdba65d523898b0690f3a81b","best_bid":"0.15","best_ask":"0.16"},{"asset_id":"63670753354844494163057275310194312729998307779831462269530137743341854359908","price":"0.86","size":"790.79","side":"SELL","hash":"cedcad3b7c40939cd1b2fcc0643c72a37102dfa4","best_bid":"0.84","best_ask":"0.85"}],"timestamp":"1768250249231","event_type":"price_change"}}
{"schema_version":1,"source":"clob_ws_market","recv_ts_ns":1768250249406243596,"event_type":"price_change","market":"0x2a12fd3d8235c25c062dc9652970ef9f635636c4018df0909e1a51c673e125cb","server_ts_ms":1768250249231,"raw":{"market":"0x2a12fd3d8235c25c062dc9652970ef9f635636c4018df0909e1a51c673e125cb","price_changes":[{"asset_id":"56386988715176239099720172290594769295756680374928571099138069977179519358166","price":"0.11","size":"869.5","side":"BUY","hash":"25bc934920592e71bdba65d523898b0690f3a81b","best_bid":"0.15","best_ask":"0.16"},{"asset_id":"63670753354844494163057275310194312729998307779831462269530137743341854359908","price":"0.89","size":"869.5","side":"SELL","hash":"cedcad3b7c40939cd1b2fcc0643c72a37102dfa4","best_bid":"0.84","best_ask":"0.85"}],"timestamp":"1768250249231","event_type":"price_change"}}
{"schema_version":1,"source":"clob_ws_market","recv_ts_ns":1768250249408522658,"event_type":"price_change","market":"0x2a12fd3d8235c25c062dc9652970ef9f635636c4018df0909e1a51c673e125cb","server_ts_ms":1768250249231,"raw":{"market":"0x2a12fd3d8235c25c062dc9652970ef9f635636c4018df0909e1a51c673e125cb","price_changes":[{"asset_id":"56386988715176239099720172290594769295756680374928571099138069977179519358166","price":"0.18","size":"871","side":"SELL","hash":"25bc934920592e71bdba65d523898b0690f3a81b","best_bid":"0.15","best_ask":"0.16"},{"asset_id":"63670753354844494163057275310194312729998307779831462269530137743341854359908","price":"0.82","size":"871","side":"BUY","hash":"cedcad3b7c40939cd1b2fcc0643c72a37102dfa4","best_bid":"0.84","best_ask":"0.85"}],"timestamp":"1768250249231","event_type":"price_change"}}
{"schema_version":1,"source":"clob_ws_market","recv_ts_ns":1768250249411982743,"event_type":"price_change","market":"0x2a12fd3d8235c25c062dc9652970ef9f635636c4018df0909e1a51c673e125cb","server_ts_ms":1768250249231,"raw":{"market":"0x2a12fd3d8235c25c062dc9652970ef9f635636c4018df0909e1a51c673e125cb","price_changes":[{"asset_id":"56386988715176239099720172290594769295756680374928571099138069977179519358166","price":"0.1","size":"3392","side":"BUY","hash":"25bc934920592e71bdba65d523898b0690f3a81b","best_bid":"0.15","best_ask":"0.16"},{"asset_id":"63670753354844494163057275310194312729998307779831462269530137743341854359908","price":"0.9","size":"3392","side":"SELL","hash":"cedcad3b7c40939cd1b2fcc0643c72a37102dfa4","best_bid":"0.84","best_ask":"0.85"}],"timestamp":"1768250249231","event_type":"price_change"}}
{"schema_version":1,"source":"clob_ws_market","recv_ts_ns":1768250249419629860,"event_type":"price_change","market":"0x2a12fd3d8235c25c062dc9652970ef9f635636c4018df0909e1a51c673e125cb","server_ts_ms":1768250249236,"raw":{"market":"0x2a12fd3d8235c25c062dc9652970ef9f635636c4018df0909e1a51c673e125cb","price_changes":[{"asset_id":"56386988715176239099720172290594769295756680374928571099138069977179519358166","price":"0.08","size":"1546.75","side":"BUY","hash":"6e170c05ae43f3f834e81a176e45c84460308b74","best_bid":"0.15","best_ask":"0.16"},{"asset_id":"63670753354844494163057275310194312729998307779831462269530137743341854359908","price":"0.92","size":"1546.75","side":"SELL","hash":"62ce397ec78e87356f598d3a1a8ad1a9f4fb87e9","best_bid":"0.84","best_ask":"0.85"}],"timestamp":"1768250249236","event_type":"price_change"}}
{"schema_version":1,"source":"clob_ws_market","recv_ts_ns":1768250249424637585,"event_type":"price_change","market":"0x2a12fd3d8235c25c062dc9652970ef9f635636c4018df0909e1a51c673e125cb","server_ts_ms":1768250249237,"raw":{"market":"0x2a12fd3d8235c25c062dc9652970ef9f635636c4018df0909e1a51c673e125cb","price_changes":[{"asset_id":"56386988715176239099720172290594769295756680374928571099138069977179519358166","price":"0.14","size":"810.79","side":"BUY","hash":"0cc148c0ae3270daa9bd87dc7f68cae32c276c70","best_bid":"0.15","best_ask":"0.16"},{"asset_id":"63670753354844494163057275310194312729998307779831462269530137743341854359908","price":"0.86","size":"810.79","side":"SELL","hash":"7107a85197544a0216470174e3b21dc90256cbab","best_bid":"0.84","best_ask":"0.85"}],"timestamp":"1768250249237","event_type":"price_change"}}
{"schema_version":1,"source":"clob_ws_market","recv_ts_ns":1768250249446826045,"event_type":"price_change","market":"0x2a12fd3d8235c25c062dc9652970ef9f635636c4018df0909e1a51c673e125cb","server_ts_ms":1768250249248,"raw":{"market":"0x2a12fd3d8235c25c062dc9652970ef9f635636c4018df0909e1a51c673e125cb","price_changes":[{"asset_id":"63670753354844494163057275310194312729998307779831462269530137743341854359908","price":"0.66","size":"906.8","side":"BUY","hash":"0a7815e05444ca2f67a49ccdb52aa6a3047f0919","best_bid":"0.84","best_ask":"0.85"},{"asset_id":"56386988715176239099720172290594769295756680374928571099138069977179519358166","price":"0.34","size":"906.8","side":"SELL","hash":"a39c310aa62669a25f439af49fa13b77dba7ffd7","best_bid":"0.15","best_ask":"0.16"}],"timestamp":"1768250249248","event_type":"price_change"}}
{"schema_version":1,"source":"clob_ws_market","recv_ts_ns":1768250249457596524,"event_type":"price_change","market":"0x2a12fd3d8235c25c062dc9652970ef9f635636c4018df0909e1a51c673e125cb","server_ts_ms":1768250249252,"raw":{"market":"0x2a12fd3d8235c25c062dc9652970ef9f635636c4018df0909e1a51c673e125cb","price_changes":[{"asset_id":"63670753354844494163057275310194312729998307779831462269530137743341854359908","price":"0.65","size":"964.31","side":"BUY","hash":"e92289e9ac2b2929122a1f59764c4472737d007a","best_bid":"0.84","best_ask":"0.85"},{"asset_id":"56386988715176239099720172290594769295756680374928571099138069977179519358166","price":"0.35","size":"964.31","side":"SELL","hash":"2273d7ea12af59b91d7a1afac6d2e2820b9cf4dd","best_bid":"0.15","best_ask":"0.16"}],"timestamp":"1768250249252","event_type":"price_change"}}
{"schema_version":1,"source":"clob_ws_market","recv_ts_ns":1768250249461406482,"event_type":"price_change","market":"0x2a12fd3d8235c25c062dc9652970ef9f635636c4018df0909e1a51c673e125cb","server_ts_ms":1768250249254,"raw":{"market":"0x2a12fd3d8235c25c062dc9652970ef9f635636c4018df0909e1a51c673e125cb","price_changes":[{"asset_id":"56386988715176239099720172290594769295756680374928571099138069977179519358166","price":"0.15","size":"645.76","side":"BUY","hash":"3edea95be8e759cc36e9a403ed3152c427b22bdd","best_bid":"0.15","best_ask":"0.16"},{"asset_id":"63670753354844494163057275310194312729998307779831462269530137743341854359908","price":"0.85","size":"645.76","side":"SELL","hash":"172ea71d630c17f9a7a382e7c5ca029304f1f439","best_bid":"0.84","best_ask":"0.85"}],"timestamp":"1768250249254","event_type":"price_change"}}
{"schema_version":1,"source":"clob_ws_market","recv_ts_ns":1768250249464352189,"event_type":"price_change","market":"0x2a12fd3d8235c25c062dc9652970ef9f635636c4018df0909e1a51c673e125cb","server_ts_ms":1768250249257,"raw":{"market":"0x2a12fd3d8235c25c062dc9652970ef9f635636c4018df0909e1a51c673e125cb","price_changes":[{"asset_id":"63670753354844494163057275310194312729998307779831462269530137743341854359908","price":"0.83","size":"285.02","side":"BUY","hash":"5902f1782caeab06bb77e82bbe7e1b1281ce2c08","best_bid":"0.84","best_ask":"0.85"},{"asset_id":"56386988715176239099720172290594769295756680374928571099138069977179519358166","price":"0.17","size":"285.02","side":"SELL","hash":"6a977b0a80143d42068aeca443330adb4da28d45","best_bid":"0.15","best_ask":"0.16"}],"timestamp":"1768250249257","event_type":"price_change"}}
{"schema_version":1,"source":"clob_ws_market","recv_ts_ns":1768250249467550386,"event_type":"price_change","market":"0x2a12fd3d8235c25c062dc9652970ef9f635636c4018df0909e1a51c673e125cb","server_ts_ms":1768250249260,"raw":{"market":"0x2a12fd3d8235c25c062dc9652970ef9f635636c4018df0909e1a51c673e125cb","price_changes":[{"asset_id":"56386988715176239099720172290594769295756680374928571099138069977179519358166","price":"0.05","size":"3442","side":"BUY","hash":"c6426e066687057d17f3c2c0a122e997441c6877","best_bid":"0.15","best_ask":"0.16"},{"asset_id":"63670753354844494163057275310194312729998307779831462269530137743341854359908","price":"0.95","size":"3442","side":"SELL","hash":"e4e45bd9d318975c4b97c130978a0d0699f961d9","best_bid":"0.84","best_ask":"0.85"}],"timestamp":"1768250249260","event_type":"price_change"}}
{"schema_version":1,"source":"clob_ws_market","recv_ts_ns":1768250249471277881,"event_type":"price_change","market":"0x2a12fd3d8235c25c062dc9652970ef9f635636c4018df0909e1a51c673e125cb","server_ts_ms":1768250249261,"raw":{"market":"0x2a12fd3d8235c25c062dc9652970ef9f635636c4018df0909e1a51c673e125cb","price_changes":[{"asset_id":"56386988715176239099720172290594769295756680374928571099138069977179519358166","price":"0.13","size":"683.5","side":"BUY","hash":"61eecf3770762a384c2107759713641c676087db","best_bid":"0.15","best_ask":"0.16"},{"asset_id":"63670753354844494163057275310194312729998307779831462269530137743341854359908","price":"0.87","size":"683.5","side":"SELL","hash":"78d00229a97bf1df6bc32b213e7506532f4c8b0e","best_bid":"0.84","best_ask":"0.85"}],"timestamp":"1768250249261","event_type":"price_change"}}
{"schema_version":1,"source":"clob_ws_market","recv_ts_ns":1768250249474577920,"event_type":"price_change","market":"0x2a12fd3d8235c25c062dc9652970ef9f635636c4018df0909e1a51c673e125cb","server_ts_ms":1768250249261,"raw":{"market":"0x2a12fd3d8235c25c062dc9652970ef9f635636c4018df0909e1a51c673e125cb","price_changes":[{"asset_id":"63670753354844494163057275310194312729998307779831462269530137743341854359908","price":"0.82","size":"171","side":"BUY","hash":"bb4b6f7a249623e010185a43e8efe35999d1bf37","best_bid":"0.84","best_ask":"0.85"},{"asset_id":"56386988715176239099720172290594769295756680374928571099138069977179519358166","price":"0.18","size":"171","side":"SELL","hash":"182c3662decdc6cf373f6e93a905ebe42198b184","best_bid":"0.15","best_ask":"0.16"}],"timestamp":"1768250249261","event_type":"price_change"}}
{"schema_version":1,"source":"clob_ws_market","recv_ts_ns":1768250249478474631,"event_type":"price_change","market":"0x2a12fd3d8235c25c062dc9652970ef9f635636c4018df0909e1a51c673e125cb","server_ts_ms":1768250249262,"raw":{"market":"0x2a12fd3d8235c25c062dc9652970ef9f635636c4018df0909e1a51c673e125cb","price_changes":[{"asset_id":"56386988715176239099720172290594769295756680374928571099138069977179519358166","price":"0.17","size":"277.52","side":"SELL","hash":"9c623e6da4b97a3651bee3579f5268b694ae6908","best_bid":"0.15","best_ask":"0.16"},{"asset_id":"63670753354844494163057275310194312729998307779831462269530137743341854359908","price":"0.83","size":"277.52","side":"BUY","hash":"884ae4e42c0430206b03aabcafd3b371fca2de92","best_bid":"0.84","best_ask":"0.85"}],"timestamp":"1768250249262","event_type":"price_change"}}
{"schema_version":1,"source":"clob_ws_market","recv_ts_ns":1768250249482288719,"event_type":"price_change","market":"0x2a12fd3d8235c25c062dc9652970ef9f635636c4018df0909e1a51c673e125cb","server_ts_ms":1768250249263,"raw":{"market":"0x2a12fd3d8235c25c062dc9652970ef9f635636c4018df0909e1a51c673e125cb","price_changes":[{"asset_id":"63670753354844494163057275310194312729998307779831462269530137743341854359908","price":"0.84","size":"101.86","side":"BUY","hash":"d44f317210608f2422e83551fb7ac30a04ab1c3b","best_bid":"0.84","best_ask":"0.85"},{"asset_id":"56386988715176239099720172290594769295756680374928571099138069977179519358166","price":"0.16","size":"101.86","side":"SELL","hash":"26d78c811a3b3b7a728bb7a3c0926aecacf2e1e7","best_bid":"0.15","best_ask":"0.16"}],"timestamp":"1768250249263","event_type":"price_change"}}
{"schema_version":1,"source":"clob_ws_market","recv_ts_ns":1768250249488821740,"event_type":"price_change","market":"0x2a12fd3d8235c25c062dc9652970ef9f635636c4018df0909e1a51c673e125cb","server_ts_ms":1768250249265,"raw":{"market":"0x2a12fd3d8235c25c062dc9652970ef9f635636c4018df0909e1a51c673e125cb","price_changes":[{"asset_id":"63670753354844494163057275310194312729998307779831462269530137743341854359908","price":"0.83","size":"272.02","side":"BUY","hash":"5e282a3ad6d534c7333eb74eafd564b964d506aa","best_bid":"0.84","best_ask":"0.85"},{"asset_id":"56386988715176239099720172290594769295756680374928571099138069977179519358166","price":"0.17","size":"272.02","side":"SELL","hash":"e82f94554e156411fd536c46a9b36ed0eedb2138","best_bid":"0.15","best_ask":"0.16"}],"timestamp":"1768250249265","event_type":"price_change"}}
{"schema_version":1,"source":"clob_ws_market","recv_ts_ns":1768250249495448398,"event_type":"price_change","market":"0x2a12fd3d8235c25c062dc9652970ef9f635636c4018df0909e1a51c673e125cb","server_ts_ms":1768250249268,"raw":{"market":"0x2a12fd3d8235c25c062dc9652970ef9f635636c4018df0909e1a51c673e125cb","price_changes":[{"asset_id":"56386988715176239099720172290594769295756680374928571099138069977179519358166","price":"0.16","size":"96.36","side":"SELL","hash":"5c814cd3de13574c628441c374696d7f9a619b37","best_bid":"0.15","best_ask":"0.16"},{"asset_id":"63670753354844494163057275310194312729998307779831462269530137743341854359908","price":"0.84","size":"96.36","side":"BUY","hash":"e94708b008bae881270208b91fda979c4832d59c","best_bid":"0.84","best_ask":"0.85"}],"timestamp":"1768250249268","event_type":"price_change"}}
{"schema_version":1,"source":"clob_ws_market","recv_ts_ns":1768250249503112432,"event_type":"price_change","market":"0x2a12fd3d8235c25c062dc9652970ef9f635636c4018df0909e1a51c673e125cb","server_ts_ms":1768250249270,"raw":{"market":"0x2a12fd3d8235c25c062dc9652970ef9f635636c4018df0909e1a51c673e125cb","price_changes":[{"asset_id":"63670753354844494163057275310194312729998307779831462269530137743341854359908","price":"0.83","size":"267.02","side":"BUY","hash":"54409decd9db142714845e8f0d08b483b6cd7420","best_bid":"0.84","best_ask":"0.85"},{"asset_id":"56386988715176239099720172290594769295756680374928571099138069977179519358166","price":"0.17","size":"267.02","side":"SELL","hash":"8f263f9acf1d9e88b9fc349e21b4988026aabfbe","best_bid":"0.15","best_ask":"0.16"}],"timestamp":"1768250249270","event_type":"price_change"}}
{"schema_version":1,"source":"clob_ws_market","recv_ts_ns":1768250249506516949,"event_type":"price_change","market":"0x2a12fd3d8235c25c062dc9652970ef9f635636c4018df0909e1a51c673e125cb","server_ts_ms":1768250249270,"raw":{"market":"0x2a12fd3d8235c25c062dc9652970ef9f635636c4018df0909e1a51c673e125cb","price_changes":[{"asset_id":"56386988715176239099720172290594769295756680374928571099138069977179519358166","price":"0.14","size":"800.79","side":"BUY","hash":"614fdb5e752a478c8dca6a9b39ae5bcc730961e1","best_bid":"0.15","best_ask":"0.16"},{"asset_id":"63670753354844494163057275310194312729998307779831462269530137743341854359908","price":"0.86","size":"800.79","side":"SELL","hash":"870c00042bab809ea14f9b89bc9befda81a1b54c","best_bid":"0.84","best_ask":"0.85"}],"timestamp":"1768250249270","event_type":"price_change"}}
{"schema_version":1,"source":"clob_ws_market","recv_ts_ns":1768250249510374620,"event_type":"price_change","market":"0x2a12fd3d8235c25c062dc9652970ef9f635636c4018df0909e1a51c673e125cb","server_ts_ms":1768250249271,"raw":{"market":"0x2a12fd3d8235c25c062dc9652970ef9f635636c4018df0909e1a51c673e125cb","price_changes":[{"asset_id":"63670753354844494163057275310194312729998307779831462269530137743341854359908","price":"0.83","size":"257.02","side":"BUY","hash":"2c58df67bd79a3ada5ec069b788036ebc596c318","best_bid":"0.84","best_ask":"0.85"},{"asset_id":"56386988715176239099720172290594769295756680374928571099138069977179519358166","price":"0.17","size":"257.02","side":"SELL","hash":"17f2dfc4d61bb33d714775dcc9d154ad2afcef4c","best_bid":"0.15","best_ask":"0.16"}],"timestamp":"1768250249271","event_type":"price_change"}}
{"schema_version":1,"source":"clob_ws_market","recv_ts_ns":1768250249517713808,"event_type":"price_change","market":"0x2a12fd3d8235c25c062dc9652970ef9f635636c4018df0909e1a51c673e125cb","server_ts_ms":1768250249272,"raw":{"market":"0x2a12fd3d8235c25c062dc9652970ef9f635636c4018df0909e1a51c673e125cb","price_changes":[{"asset_id":"63670753354844494163057275310194312729998307779831462269530137743341854359908","price":"0.83","size":"247.02","side":"BUY","hash":"e39ff20133535017796443a578989b3ce08e0854","best_bid":"0.84","best_ask":"0.85"},{"asset_id":"56386988715176239099720172290594769295756680374928571099138069977179519358166","price":"0.17","size":"247.02","side":"SELL","hash":"ec904e4e2faf10fa578b143a19fc7876306b98e7","best_bid":"0.15","best_ask":"0.16"}],"timestamp":"1768250249272","event_type":"price_change"}}
{"schema_version":1,"source":"clob_ws_market","recv_ts_ns":1768250249521554887,"event_type":"price_change","market":"0x2a12fd3d8235c25c062dc9652970ef9f635636c4018df0909e1a51c673e125cb","server_ts_ms":1768250249273,"raw":{"market":"0x2a12fd3d8235c25c062dc9652970ef9f635636c4018df0909e1a51c673e125cb","price_changes":[{"asset_id":"56386988715176239099720172290594769295756680374928571099138069977179519358166","price":"0.15","size":"635.76","side":"BUY","hash":"92e9fa46c59f1d432d6193138e62119e566f1f62","best_bid":"0.15","best_ask":"0.16"},{"asset_id":"63670753354844494163057275310194312729998307779831462269530137743341854359908","price":"0.85","size":"635.76","side":"SELL","hash":"4aea84f89f3d63e15e2768a88117414d26c54366","best_bid":"0.84","best_ask":"0.85"}],"timestamp":"1768250249273","event_type":"price_change"}}
{"schema_version":1,"source":"clob_ws_market","recv_ts_ns":1768250249524883337,"event_type":"price_change","market":"0x2a12fd3d8235c25c062dc9652970ef9f635636c4018df0909e1a51c673e125cb","server_ts_ms":1768250249274,"raw":{"market":"0x2a12fd3d8235c25c062dc9652970ef9f635636c4018df0909e1a51c673e125cb","price_changes":[{"asset_id":"56386988715176239099720172290594769295756680374928571099138069977179519358166","price":"0.12","size":"862.75","side":"BUY","hash":"7a930677e756cb6dbbc701cc27de7f12c6bb89d0","best_bid":"0.15","best_ask":"0.16"},{"asset_id":"63670753354844494163057275310194312729998307779831462269530137743341854359908","price":"0.88","size":"862.75","side":"SELL","hash":"d1072192cfde176ddd944bc965d10edeb54d8820","best_bid":"0.84","best_ask":"0.85"}],"timestamp":"1768250249274","event_type":"price_change"}}
{"schema_version":1,"source":"clob_ws_market","recv_ts_ns":1768250249529027616,"event_type":"price_change","market":"0x2a12fd3d8235c25c062dc9652970ef9f635636c4018df0909e1a51c673e125cb","server_ts_ms":1768250249274,"raw":{"market":"0x2a12fd3d8235c25c062dc9652970ef9f635636c4018df0909e1a51c673e125cb","price_changes":[{"asset_id":"56386988715176239099720172290594769295756680374928571099138069977179519358166","price":"0.12","size":"852.75","side":"BUY","hash":"f735e6e853e37454ebffea0443f89e76be76d235","best_bid":"0.15","best_ask":"0.16"},{"asset_id":"63670753354844494163057275310194312729998307779831462269530137743341854359908","price":"0.88","size":"852.75","side":"SELL","hash":"a293344fc970053c21d2a21858fc09b6e34fd4a8","best_bid":"0.84","best_ask":"0.85"}],"timestamp":"1768250249274","event_type":"price_change"}}
{"schema_version":1,"source":"clob_ws_market","recv_ts_ns":1768250249532237444,"event_type":"price_change","market":"0x2a12fd3d8235c25c062dc9652970ef9f635636c4018df0909e1a51c673e125cb","server_ts_ms":1768250249275,"raw":{"market":"0x2a12fd3d8235c25c062dc9652970ef9f635636c4018df0909e1a51c673e125cb","price_changes":[{"asset_id":"63670753354844494163057275310194312729998307779831462269530137743341854359908","price":"0.83","size":"237.02","side":"BUY","hash":"4c74334bed22859869bfff8ab898fe8d6ed9170e","best_bid":"0.84","best_ask":"0.85"},{"asset_id":"56386988715176239099720172290594769295756680374928571099138069977179519358166","price":"0.17","size":"237.02","side":"SELL","hash":"34b8f5d48946d56942244052a8561e201016aa3d","best_bid":"0.15","best_ask":"0.16"}],"timestamp":"1768250249275","event_type":"price_change"}}
{"schema_version":1,"source":"clob_ws_market","recv_ts_ns":1768250249535496437,"event_type":"price_change","market":"0x2a12fd3d8235c25c062dc9652970ef9f635636c4018df0909e1a51c673e125cb","server_ts_ms":1768250249275,"raw":{"market":"0x2a12fd3d8235c25c062dc9652970ef9f635636c4018df0909e1a51c673e125cb","price_changes":[{"asset_id":"63670753354844494163057275310194312729998307779831462269530137743341854359908","price":"0.83","size":"227.02","side":"BUY","hash":"5fa4022ed097e89f10227b3a911445e46994192a","best_bid":"0.84","best_ask":"0.85"},{"asset_id":"56386988715176239099720172290594769295756680374928571099138069977179519358166","price":"0.17","size":"227.02","side":"SELL","hash":"fffd073787e47923dd15e53b3ccf37927b23de56","best_bid":"0.15","best_ask":"0.16"}],"timestamp":"1768250249275","event_type":"price_change"}}
{"schema_version":1,"source":"clob_ws_market","recv_ts_ns":1768250249539190963,"event_type":"price_change","market":"0x2a12fd3d8235c25c062dc9652970ef9f635636c4018df0909e1a51c673e125cb","server_ts_ms":1768250249276,"raw":{"market":"0x2a12fd3d8235c25c062dc9652970ef9f635636c4018df0909e1a51c673e125cb","price_changes":[{"asset_id":"56386988715176239099720172290594769295756680374928571099138069977179519358166","price":"0.15","size":"796.76","side":"BUY","hash":"05f2b4336136cd1c271e06058875bd7924ab2f7e","best_bid":"0.15","best_ask":"0.16"},{"asset_id":"63670753354844494163057275310194312729998307779831462269530137743341854359908","price":"0.85","size":"796.76","side":"SELL","hash":"f72d34ec9380a6c9eeb923aad60c16201be0ce2d","best_bid":"0.84","best_ask":"0.85"}],"timestamp":"1768250249276","event_type":"price_change"}}
{"schema_version":1,"source":"clob_ws_market","recv_ts_ns":1768250249543085907,"event_type":"price_change","market":"0x2a12fd3d8235c25c062dc9652970ef9f635636c4018df0909e1a51c673e125cb","server_ts_ms":1768250249277,"raw":{"market":"0x2a12fd3d8235c25c062dc9652970ef9f635636c4018df0909e1a51c673e125cb","price_changes":[{"asset_id":"63670753354844494163057275310194312729998307779831462269530137743341854359908","price":"0.85","size":"801.76","side":"SELL","hash":"9e940fe7bc74efb659ca487129fd5a2723254dd0","best_bid":"0.84","best_ask":"0.85"},{"asset_id":"56386988715176239099720172290594769295756680374928571099138069977179519358166","price":"0.15","size":"801.76","side":"BUY","hash":"db8397f332cf76155dc7068d92cad28e47da2a01","best_bid":"0.15","best_ask":"0.16"}],"timestamp":"1768250249277","event_type":"price_change"}}
{"schema_version":1,"source":"clob_ws_market","recv_ts_ns":1768250249546790637,"event_type":"price_change","market":"0x2a12fd3d8235c25c062dc9652970ef9f635636c4018df0909e1a51c673e125cb","server_ts_ms":1768250249278,"raw":{"market":"0x2a12fd3d8235c25c062dc9652970ef9f635636c4018df0909e1a51c673e125cb","price_changes":[{"asset_id":"63670753354844494163057275310194312729998307779831462269530137743341854359908","price":"0.77","size":"754.5","side":"BUY","hash":"d187a9a27d4767ca9f4ba3cb20f95e798facad2d","best_bid":"0.84","best_ask":"0.85"},{"asset_id":"56386988715176239099720172290594769295756680374928571099138069977179519358166","price":"0.23","size":"754.5","side":"SELL","hash":"5f23c013be4bac554f744bf37e098c8ad6d7ea6d","best_bid":"0.15","best_ask":"0.16"}],"timestamp":"1768250249278","event_type":"price_change"}}
{"schema_version":1,"source":"clob_ws_market","recv_ts_ns":1768250249551697294,"event_type":"price_change","market":"0x2a12fd3d8235c25c062dc9652970ef9f635636c4018df0909e1a51c673e125cb","server_ts_ms":1768250249279,"raw":{"market":"0x2a12fd3d8235c25c062dc9652970ef9f635636c4018df0909e1a51c673e125cb","price_changes":[{"asset_id":"56386988715176239099720172290594769295756680374928571099138069977179519358166","price":"0.11","size":"844.5","side":"BUY","hash":"1126fd7162f7b436edef7a06f36ba86c989c6be2","best_bid":"0.15","best_ask":"0.16"},{"asset_id":"63670753354844494163057275310194312729998307779831462269530137743341854359908","price":"0.89","size":"844.5","side":"SELL","hash":"46499fd2e897ab7e1402cdbb6b6e9d377bc6de96","best_bid":"0.84","best_ask":"0.85"}],"timestamp":"1768250249279","event_type":"price_change"}}
{"schema_version":1,"source":"clob_ws_market","recv_ts_ns":1768250249553595409,"event_type":"price_change","market":"0x2a12fd3d8235c25c062dc9652970ef9f635636c4018df0909e1a51c673e125cb","server_ts_ms":1768250249279,"raw":{"market":"0x2a12fd3d8235c25c062dc9652970ef9f635636c4018df0909e1a51c673e125cb","price_changes":[{"asset_id":"56386988715176239099720172290594769295756680374928571099138069977179519358166","price":"0.11","size":"834.5","side":"BUY","hash":"b5122c1f5c19d00e0c5fccb03bc81bf13e122da0","best_bid":"0.15","best_ask":"0.16"},{"asset_id":"63670753354844494163057275310194312729998307779831462269530137743341854359908","price":"0.89","size":"834.5","side":"SELL","hash":"5a8f728a686be574b48d9cbd4a508d0c69f5d54a","best_bid":"0.84","best_ask":"0.85"}],"timestamp":"1768250249279","event_type":"price_change"}}
{"schema_version":1,"source":"clob_ws_market","recv_ts_ns":1768250249555764280,"event_type":"price_change","market":"0x2a12fd3d8235c25c062dc9652970ef9f635636c4018df0909e1a51c673e125cb","server_ts_ms":1768250249279,"raw":{"market":"0x2a12fd3d8235c25c062dc9652970ef9f635636c4018df0909e1a51c673e125cb","price_changes":[{"asset_id":"56386988715176239099720172290594769295756680374928571099138069977179519358166","price":"0.11","size":"859.5","side":"BUY","hash":"6c58dd7b41b1f3addd91aab1ff356758beb82722","best_bid":"0.15","best_ask":"0.16"},{"asset_id":"63670753354844494163057275310194312729998307779831462269530137743341854359908","price":"0.89","size":"859.5","side":"SELL","hash":"390e3c14e97202f35c35616f4d4f8895f3f5d249","best_bid":"0.84","best_ask":"0.85"}],"timestamp":"1768250249279","event_type":"price_change"}}
{"schema_version":1,"source":"clob_ws_market","recv_ts_ns":1768250249559376625,"event_type":"price_change","market":"0x2a12fd3d8235c25c062dc9652970ef9f635636c4018df0909e1a51c673e125cb","server_ts_ms":1768250249280,"raw":{"market":"0x2a12fd3d8235c25c062dc9652970ef9f635636c4018df0909e1a51c673e125cb","price_changes":[{"asset_id":"56386988715176239099720172290594769295756680374928571099138069977179519358166","price":"0.12","size":"842.75","side":"BUY","hash":"58ed392147c34a219f4c56676387c90ae2dee0aa","best_bid":"0.15","best_ask":"0.16"},{"asset_id":"63670753354844494163057275310194312729998307779831462269530137743341854359908","price":"0.88","size":"842.75","side":"SELL","hash":"4854067bc0f33a825112e20f3803d69fcf5768f1","best_bid":"0.84","best_ask":"0.85"}],"timestamp":"1768250249280","event_type":"price_change"}}
{"schema_version":1,"source":"clob_ws_market","recv_ts_ns":1768250249561745365,"event_type":"price_change","market":"0x2a12fd3d8235c25c062dc9652970ef9f635636c4018df0909e1a51c673e125cb","server_ts_ms":1768250249280,"raw":{"market":"0x2a12fd3d8235c25c062dc9652970ef9f635636c4018df0909e1a51c673e125cb","price_changes":[{"asset_id":"63670753354844494163057275310194312729998307779831462269530137743341854359908","price":"0.83","size":"217.02","side":"BUY","hash":"56014e5d51d0a6993e7023f74f9329271215d350","best_bid":"0.84","best_ask":"0.85"},{"asset_id":"56386988715176239099720172290594769295756680374928571099138069977179519358166","price":"0.17","size":"217.02","side":"SELL","hash":"a6dac83330c172173999d5fbb2c3a3d0cd56c886","best_bid":"0.15","best_ask":"0.16"}],"timestamp":"1768250249280","event_type":"price_change"}}
{"schema_version":1,"source":"clob_ws_market","recv_ts_ns":1768250249565224718,"event_type":"price_change","market":"0x2a12fd3d8235c25c062dc9652970ef9f635636c4018df0909e1a51c673e125cb","server_ts_ms":1768250249281,"raw":{"market":"0x2a12fd3d8235c25c062dc9652970ef9f635636c4018df0909e1a51c673e125cb","price_changes":[{"asset_id":"63670753354844494163057275310194312729998307779831462269530137743341854359908","price":"0.83","size":"207.02","side":"BUY","hash":"760cad14bede3aa15210ded94b22c477c71155eb","best_bid":"0.84","best_ask":"0.85"},{"asset_id":"56386988715176239099720172290594769295756680374928571099138069977179519358166","price":"0.17","size":"207.02","side":"SELL","hash":"8750a6d92035ff5bce37649fdcef46c220a12efb","best_bid":"0.15","best_ask":"0.16"}],"timestamp":"1768250249281","event_type":"price_change"}}
{"schema_version":1,"source":"clob_ws_market","recv_ts_ns":1768250249570501852,"event_type":"price_change","market":"0x2a12fd3d8235c25c062dc9652970ef9f635636c4018df0909e1a51c673e125cb","server_ts_ms":1768250249282,"raw":{"market":"0x2a12fd3d8235c25c062dc9652970ef9f635636c4018df0909e1a51c673e125cb","price_changes":[{"asset_id":"56386988715176239099720172290594769295756680374928571099138069977179519358166","price":"0.15","size":"791.76","side":"BUY","hash":"5e5b5534b6128b54cae7dc558541cd75c35979c1","best_bid":"0.15","best_ask":"0.16"},{"asset_id":"63670753354844494163057275310194312729998307779831462269530137743341854359908","price":"0.85","size":"791.76","side":"SELL","hash":"78774b257b14183ef295f792bd0d855d6eb3b385","best_bid":"0.84","best_ask":"0.85"}],"timestamp":"1768250249282","event_type":"price_change"}}
{"schema_version":1,"source":"clob_ws_market","recv_ts_ns":1768250249573390192,"event_type":"price_change","market":"0x2a12fd3d8235c25c062dc9652970ef9f635636c4018df0909e1a51c673e125cb","server_ts_ms":1768250249283,"raw":{"market":"0x2a12fd3d8235c25c062dc9652970ef9f635636c4018df0909e1a51c673e125cb","price_changes":[{"asset_id":"63670753354844494163057275310194312729998307779831462269530137743341854359908","price":"0.76","size":"930.05","side":"BUY","hash":"e46c4bba857576094b33da7b849dcfe2d8ebd0ae","best_bid":"0.84","best_ask":"0.85"},{"asset_id":"56386988715176239099720172290594769295756680374928571099138069977179519358166","price":"0.24","size":"930.05","side":"SELL","hash":"21493006df393437876576ad687770161ee71361","best_bid":"0.15","best_ask":"0.16"}],"timestamp":"1768250249283","event_type":"price_change"}}
{"schema_version":1,"source":"clob_ws_market","recv_ts_ns":1768250249576470949,"event_type":"price_change","market":"0x2a12fd3d8235c25c062dc9652970ef9f635636c4018df0909e1a51c673e125cb","server_ts_ms":1768250249284,"raw":{"market":"0x2a12fd3d8235c25c062dc9652970ef9f635636c4018df0909e1a51c673e125cb","price_changes":[{"asset_id":"56386988715176239099720172290594769295756680374928571099138069977179519358166","price":"0.12","size":"867.75","side":"BUY","hash":"ee0a281fffa08d12385a99551267e6c0d783473c","best_bid":"0.15","best_ask":"0.16"},{"asset_id":"63670753354844494163057275310194312729998307779831462269530137743341854359908","price":"0.88","size":"867.75","side":"SELL","hash":"f6306d00b3632648588b5e08dc630a611fa3f40d","best_bid":"0.84","best_ask":"0.85"}],"timestamp":"1768250249284","event_type":"price_change"}}
{"schema_version":1,"source":"clob_ws_market","recv_ts_ns":1768250249578815193,"event_type":"price_change","market":"0x2a12fd3d8235c25c062dc9652970ef9f635636c4018df0909e1a51c673e125cb","server_ts_ms":1768250249284,"raw":{"market":"0x2a12fd3d8235c25c062dc9652970ef9f635636c4018df0909e1a51c673e125cb","price_changes":[{"asset_id":"63670753354844494163057275310194312729998307779831462269530137743341854359908","price":"0.83","size":"197.02","side":"BUY","hash":"d7b456929454423fb4befd505330ec81cb99701f","best_bid":"0.84","best_ask":"0.85"},{"asset_id":"56386988715176239099720172290594769295756680374928571099138069977179519358166","price":"0.17","size":"197.02","side":"SELL","hash":"6e6ffea6e1420897b68a47614d04ae55c803b77e","best_bid":"0.15","best_ask":"0.16"}],"timestamp":"1768250249284","event_type":"price_change"}}
{"schema_version":1,"source":"clob_ws_market","recv_ts_ns":1768250249580735169,"event_type":"price_change","market":"0x2a12fd3d8235c25c062dc9652970ef9f635636c4018df0909e1a51c673e125cb","server_ts_ms":1768250249285,"raw":{"market":"0x2a12fd3d8235c25c062dc9652970ef9f635636c4018df0909e1a51c673e125cb","price_changes":[{"asset_id":"56386988715176239099720172290594769295756680374928571099138069977179519358166","price":"0.12","size":"857.75","side":"BUY","hash":"263e79e938cf64bd4f6700b649fee677f7f53f1e","best_bid":"0.15","best_ask":"0.16"},{"asset_id":"63670753354844494163057275310194312729998307779831462269530137743341854359908","price":"0.88","size":"857.75","side":"SELL","hash":"5270ee5f644c3a64fd6020f2aa95e21969d4b54a","best_bid":"0.84","best_ask":"0.85"}],"timestamp":"1768250249285","event_type":"price_change"}}
{"schema_version":1,"source":"clob_ws_market","recv_ts_ns":1768250249582806194,"event_type":"price_change","market":"0x2a12fd3d8235c25c062dc9652970ef9f635636c4018df0909e1a51c673e125cb","server_ts_ms":1768250249285,"raw":{"market":"0x2a12fd3d8235c25c062dc9652970ef9f635636c4018df0909e1a51c673e125cb","price_changes":[{"asset_id":"56386988715176239099720172290594769295756680374928571099138069977179519358166","price":"0.12","size":"847.75","side":"BUY","hash":"7b0fd95742d89c8462d5a4aeeec2320f313295e1","best_bid":"0.15","best_ask":"0.16"},{"asset_id":"63670753354844494163057275310194312729998307779831462269530137743341854359908","price":"0.88","size":"847.75","side":"SELL","hash":"17bec9531797d01ee97cc609c4640eca50d30f7a","best_bid":"0.84","best_ask":"0.85"}],"timestamp":"1768250249285","event_type":"price_change"}}
{"schema_version":1,"source":"clob_ws_market","recv_ts_ns":1768250249585131427,"event_type":"price_change","market":"0x2a12fd3d8235c25c062dc9652970ef9f635636c4018df0909e1a51c673e125cb","server_ts_ms":1768250249286,"raw":{"market":"0x2a12fd3d8235c25c062dc9652970ef9f635636c4018df0909e1a51c673e125cb","price_changes":[{"asset_id":"56386988715176239099720172290594769295756680374928571099138069977179519358166","price":"0.13","size":"673.5","side":"BUY","hash":"392180b05fd24258ae8b10051748fb0e1dee53ae","best_bid":"0.15","best_ask":"0.16"},{"asset_id":"63670753354844494163057275310194312729998307779831462269530137743341854359908","price":"0.87","size":"673.5","side":"SELL","hash":"ed1a384a7708b950994a6fa2c53f294c1aa694ab","best_bid":"0.84","best_ask":"0.85"}],"timestamp":"1768250249286","event_type":"price_change"}}
{"schema_version":1,"source":"clob_ws_market","recv_ts_ns":1768250249590234297,"event_type":"price_change","market":"0x2a12fd3d8235c25c062dc9652970ef9f635636c4018df0909e1a51c673e125cb","server_ts_ms":1768250249286,"raw":{"market":"0x2a12fd3d8235c25c062dc9652970ef9f635636c4018df0909e1a51c673e125cb","price_changes":[{"asset_id":"63670753354844494163057275310194312729998307779831462269530137743341854359908","price":"0.83","size":"187.02","side":"BUY","hash":"4cb6c171c1566948a208d3481f972dfa2640b314","best_bid":"0.84","best_ask":"0.85"},{"asset_id":"56386988715176239099720172290594769295756680374928571099138069977179519358166","price":"0.17","size":"187.02","side":"SELL","hash":"3adb8b9af8ce7c92ba370dcca5c350f042986752","best_bid":"0.15","best_ask":"0.16"}],"timestamp":"1768250249286","event_type":"price_change"}}
{"schema_version":1,"source":"clob_ws_market","recv_ts_ns":1768250249593119006,"event_type":"price_change","market":"0x2a12fd3d8235c25c062dc9652970ef9f635636c4018df0909e1a51c673e125cb","server_ts_ms":1768250249287,"raw":{"market":"0x2a12fd3d8235c25c062dc9652970ef9f635636c4018df0909e1a51c673e125cb","price_changes":[{"asset_id":"56386988715176239099720172290594769295756680374928571099138069977179519358166","price":"0.15","size":"776.76","side":"BUY","hash":"20f41b61ffec62f03b6b2629c144056fa3d941bb","best_bid":"0.15","best_ask":"0.16"},{"asset_id":"63670753354844494163057275310194312729998307779831462269530137743341854359908","price":"0.85","size":"776.76","side":"SELL","hash":"e746291c75b1b5b911872d700382e1572c798b3e","best_bid":"0.84","best_ask":"0.85"}],"timestamp":"1768250249287","event_type":"price_change"}}
{"schema_version":1,"source":"clob_ws_market","recv_ts_ns":1768250249595518855,"event_type":"price_change","market":"0x2a12fd3d8235c25c062dc9652970ef9f635636c4018df0909e1a51c673e125cb","server_ts_ms":1768250249287,"raw":{"market":"0x2a12fd3d8235c25c062dc9652970ef9f635636c4018df0909e1a51c673e125cb","price_changes":[{"asset_id":"56386988715176239099720172290594769295756680374928571099138069977179519358166","price":"0.11","size":"849.5","side":"BUY","hash":"9a3fe69e7c03eb951a0175e6b3a5e3b07c9f9b4d","best_bid":"0.15","best_ask":"0.16"},{"asset_id":"63670753354844494163057275310194312729998307779831462269530137743341854359908","price":"0.89","size":"849.5","side":"SELL","hash":"fa020e13871dfbc8dc79ad65e5c208872234bc42","best_bid":"0.84","best_ask":"0.85"}],"timestamp":"1768250249287","event_type":"price_change"}}
{"schema_version":1,"source":"clob_ws_market","recv_ts_ns":1768250249597908963,"event_type":"price_change","market":"0x2a12fd3d8235c25c062dc9652970ef9f635636c4018df0909e1a51c673e125cb","server_ts_ms":1768250249288,"raw":{"market":"0x2a12fd3d8235c25c062dc9652970ef9f635636c4018df0909e1a51c673e125cb","price_changes":[{"asset_id":"63670753354844494163057275310194312729998307779831462269530137743341854359908","price":"0.76","size":"917.85","side":"BUY","hash":"9cc2a63d2a98aa9a19eee895fb6b7aadb413d593","best_bid":"0.84","best_ask":"0.85"},{"asset_id":"56386988715176239099720172290594769295756680374928571099138069977179519358166","price":"0.24","size":"917.85","side":"SELL","hash":"bcdb37c1492fd658f084639e189da36d3a9ed6b4","best_bid":"0.15","best_ask":"0.16"}],"timestamp":"1768250249288","event_type":"price_change"}}
{"schema_version":1,"source":"clob_ws_market","recv_ts_ns":1768250249600714868,"event_type":"price_change","market":"0x2a12fd3d8235c25c062dc9652970ef9f635636c4018df0909e1a51c673e125cb","server_ts_ms":1768250249289,"raw":{"market":"0x2a12fd3d8235c25c062dc9652970ef9f635636c4018df0909e1a51c673e125cb","price_changes":[{"asset_id":"56386988715176239099720172290594769295756680374928571099138069977179519358166","price":"0.1","size":"3367","side":"BUY","hash":"2d0ce272f27841203f28517cbbc10eeef8690bb1","best_bid":"0.15","best_ask":"0.16"},{"asset_id":"63670753354844494163057275310194312729998307779831462269530137743341854359908","price":"0.9","size":"3367","side":"SELL","hash":"0df768475b45998a12324d2ed2916048b00c75d2","best_bid":"0.84","best_ask":"0.85"}],"timestamp":"1768250249289","event_type":"price_change"}}
{"schema_version":1,"source":"clob_ws_market","recv_ts_ns":1768250249604270125,"event_type":"price_change","market":"0x2a12fd3d8235c25c062dc9652970ef9f635636c4018df0909e1a51c673e125cb","server_ts_ms":1768250249289,"raw":{"market":"0x2a12fd3d8235c25c062dc9652970ef9f635636c4018df0909e1a51c673e125cb","price_changes":[{"asset_id":"63670753354844494163057275310194312729998307779831462269530137743341854359908","price":"0.8","size":"404.9","side":"BUY","hash":"e0cbe08b197afb89271773dc2813ac5044c51430","best_bid":"0.84","best_ask":"0.85"},{"asset_id":"56386988715176239099720172290594769295756680374928571099138069977179519358166","price":"0.2","size":"404.9","side":"SELL","hash":"1c8dc3805cee52f53f02251d4de64e19e699ee8c","best_bid":"0.15","best_ask":"0.16"}],"timestamp":"1768250249289","event_type":"price_change"}}
{"schema_version":1,"source":"clob_ws_market","recv_ts_ns":1768250249607896598,"event_type":"price_change","market":"0x2a12fd3d8235c25c062dc9652970ef9f635636c4018df0909e1a51c673e125cb","server_ts_ms":1768250249290,"raw":{"market":"0x2a12fd3d8235c25c062dc9652970ef9f635636c4018df0909e1a51c673e125cb","price_changes":[{"asset_id":"63670753354844494163057275310194312729998307779831462269530137743341854359908","price":"0.83","size":"177.02","side":"BUY","hash":"893e2d9e6ce7191f405adac73830a80633252bb3","best_bid":"0.84","best_ask":"0.85"},{"asset_id":"56386988715176239099720172290594769295756680374928571099138069977179519358166","price":"0.17","size":"177.02","side":"SELL","hash":"bd27b2eb2715bbe4efc7ee674b76fda363114950","best_bid":"0.15","best_ask":"0.16"}],"timestamp":"1768250249290","event_type":"price_change"}}
{"schema_version":1,"source":"clob_ws_market","recv_ts_ns":1768250249610850905,"event_type":"price_change","market":"0x2a12fd3d8235c25c062dc9652970ef9f635636c4018df0909e1a51c673e125cb","server_ts_ms":1768250249291,"raw":{"market":"0x2a12fd3d8235c25c062dc9652970ef9f635636c4018df0909e1a51c673e125cb","price_changes":[{"asset_id":"63670753354844494163057275310194312729998307779831462269530137743341854359908","price":"0.82","size":"176.5","side":"BUY","hash":"dc1f587407094ce98e3a3de98bc1320bd9f99e94","best_bid":"0.84","best_ask":"0.85"},{"asset_id":"56386988715176239099720172290594769295756680374928571099138069977179519358166","price":"0.18","size":"176.5","side":"SELL","hash":"83f433ca2222f111072aa56343ad19fbc00db347","best_bid":"0.15","best_ask":"0.16"}],"timestamp":"1768250249291","event_type":"price_change"}}
{"schema_version":1,"source":"clob_ws_market","recv_ts_ns":1768250249615819839,"event_type":"price_change","market":"0x2a12fd3d8235c25c062dc9652970ef9f635636c4018df0909e1a51c673e125cb","server_ts_ms":1768250249292,"raw":{"market":"0x2a12fd3d8235c25c062dc9652970ef9f635636c4018df0909e1a51c673e125cb","price_changes":[{"asset_id":"56386988715176239099720172290594769295756680374928571099138069977179519358166","price":"0.14","size":"951.79","side":"BUY","hash":"348385c93d06ced3df8f3eee66e2a65bee153700","best_bid":"0.15","best_ask":"0.16"},{"asset_id":"63670753354844494163057275310194312729998307779831462269530137743341854359908","price":"0.86","size":"951.79","side":"SELL","hash":"1c30808347f4e6a3c684f5802d0ad2be3d43516d","best_bid":"0.84","best_ask":"0.85"}],"timestamp":"1768250249292","event_type":"price_change"}}
{"schema_version":1,"source":"clob_ws_market","recv_ts_ns":1768250249617995276,"event_type":"price_change","market":"0x2a12fd3d8235c25c062dc9652970ef9f635636c4018df0909e1a51c673e125cb","server_ts_ms":1768250249293,"raw":{"market":"0x2a12fd3d8235c25c062dc9652970ef9f635636c4018df0909e1a51c673e125cb","price_changes":[{"asset_id":"56386988715176239099720172290594769295756680374928571099138069977179519358166","price":"0.13","size":"824.5","side":"BUY","hash":"e64d10a0b4662c9c11694000f443c4ceec643168","best_bid":"0.15","best_ask":"0.16"},{"asset_id":"63670753354844494163057275310194312729998307779831462269530137743341854359908","price":"0.87","size":"824.5","side":"SELL","hash":"3a5ab59ce8695b8ed3bbf0d1971cf8303746d343","best_bid":"0.84","best_ask":"0.85"}],"timestamp":"1768250249293","event_type":"price_change"}}
{"schema_version":1,"source":"clob_ws_market","recv_ts_ns":1768250249620584277,"event_type":"price_change","market":"0x2a12fd3d8235c25c062dc9652970ef9f635636c4018df0909e1a51c673e125cb","server_ts_ms":1768250249294,"raw":{"market":"0x2a12fd3d8235c25c062dc9652970ef9f635636c4018df0909e1a51c673e125cb","price_changes":[{"asset_id":"63670753354844494163057275310194312729998307779831462269530137743341854359908","price":"0.82","size":"182","side":"BUY","hash":"709a5bc6518e7ed4256c312e4fd7da893ab3113c","best_bid":"0.84","best_ask":"0.85"},{"asset_id":"56386988715176239099720172290594769295756680374928571099138069977179519358166","price":"0.18","size":"182","side":"SELL","hash":"fd0c463bf28b0c50c460fdd7197115632bbc6b06","best_bid":"0.15","best_ask":"0.16"}],"timestamp":"1768250249294","event_type":"price_change"}}
{"schema_version":1,"source":"clob_ws_market","recv_ts_ns":1768250249629835848,"event_type":"price_change","market":"0x2a12fd3d8235c25c062dc9652970ef9f635636c4018df0909e1a51c673e125cb","server_ts_ms":1768250249303,"raw":{"market":"0x2a12fd3d8235c25c062dc9652970ef9f635636c4018df0909e1a51c673e125cb","price_changes":[{"asset_id":"63670753354844494163057275310194312729998307779831462269530137743341854359908","price":"0.82","size":"192","side":"BUY","hash":"67e9a1fe9a326ef5e249bd517d9a42a609315f75","best_bid":"0.84","best_ask":"0.85"},{"asset_id":"56386988715176239099720172290594769295756680374928571099138069977179519358166","price":"0.18","size":"192","side":"SELL","hash":"a85a19606b30c43f39107c781ac913f0e7d18b5d","best_bid":"0.15","best_ask":"0.16"}],"timestamp":"1768250249303","event_type":"price_change"}}
{"schema_version":1,"source":"clob_ws_market","recv_ts_ns":1768250249632373520,"event_type":"price_change","market":"0x2a12fd3d8235c25c062dc9652970ef9f635636c4018df0909e1a51c673e125cb","server_ts_ms":1768250249304,"raw":{"market":"0x2a12fd3d8235c25c062dc9652970ef9f635636c4018df0909e1a51c673e125cb","price_changes":[{"asset_id":"63670753354844494163057275310194312729998307779831462269530137743341854359908","price":"0.83","size":"167.02","side":"BUY","hash":"928cafbaf255e93c635a9a40871be3857e2a7118","best_bid":"0.84","best_ask":"0.85"},{"asset_id":"56386988715176239099720172290594769295756680374928571099138069977179519358166","price":"0.17","size":"167.02","side":"SELL","hash":"c13cf35e7183c691587c6b56e29af63e5ca118e5","best_bid":"0.15","best_ask":"0.16"}],"timestamp":"1768250249304","event_type":"price_change"}}
{"schema_version":1,"source":"clob_ws_market","recv_ts_ns":1768250249634843243,"event_type":"price_change","market":"0x2a12fd3d8235c25c062dc9652970ef9f635636c4018df0909e1a51c673e125cb","server_ts_ms":1768250249305,"raw":{"market":"0x2a12fd3d8235c25c062dc9652970ef9f635636c4018df0909e1a51c673e125cb","price_changes":[{"asset_id":"56386988715176239099720172290594769295756680374928571099138069977179519358166","price":"0.13","size":"834.5","side":"BUY","hash":"832b859a4fa64f1cc42fddeed55eb44cccf13588","best_bid":"0.15","best_ask":"0.16"},{"asset_id":"63670753354844494163057275310194312729998307779831462269530137743341854359908","price":"0.87","size":"834.5","side":"SELL","hash":"24badf0307e471775864019dfd9e3a12744a23ed","best_bid":"0.84","best_ask":"0.85"}],"timestamp":"1768250249305","event_type":"price_change"}}
{"schema_version":1,"source":"clob_ws_market","recv_ts_ns":1768250249639453311,"event_type":"price_change","market":"0x2a12fd3d8235c25c062dc9652970ef9f635636c4018df0909e1a51c673e125cb","server_ts_ms":1768250249307,"raw":{"market":"0x2a12fd3d8235c25c062dc9652970ef9f635636c4018df0909e1a51c673e125cb","price_changes":[{"asset_id":"56386988715176239099720172290594769295756680374928571099138069977179519358166","price":"0.14","size":"956.79","side":"BUY","hash":"3bda06ccf7b1c57c3ce6637ac6ab8ac5d601b674","best_bid":"0.15","best_ask":"0.16"},{"asset_id":"63670753354844494163057275310194312729998307779831462269530137743341854359908","price":"0.86","size":"956.79","side":"SELL","hash":"47d5e57612b0d1d12b7ffd7967b138762ff5b90c","best_bid":"0.84","best_ask":"0.85"}],"timestamp":"1768250249307","event_type":"price_change"}}
{"schema_version":1,"source":"clob_ws_market","recv_ts_ns":1768250249641656340,"event_type":"price_change","market":"0x2a12fd3d8235c25c062dc9652970ef9f635636c4018df0909e1a51c673e125cb","server_ts_ms":1768250249307,"raw":{"market":"0x2a12fd3d8235c25c062dc9652970ef9f635636c4018df0909e1a51c673e125cb","price_changes":[{"asset_id":"56386988715176239099720172290594769295756680374928571099138069977179519358166","price":"0.13","size":"844.5","side":"BUY","hash":"f118dc3d1c8009ada409a753bbe9d4ecae3c32bb","best_bid":"0.15","best_ask":"0.16"},{"asset_id":"63670753354844494163057275310194312729998307779831462269530137743341854359908","price":"0.87","size":"844.5","side":"SELL","hash":"af7f2f04747529d0a41bde76b06c3b981727b395","best_bid":"0.84","best_ask":"0.85"}],"timestamp":"1768250249307","event_type":"price_change"}}
{"schema_version":1,"source":"clob_ws_market","recv_ts_ns":1768250249645680285,"event_type":"price_change","market":"0x2a12fd3d8235c25c062dc9652970ef9f635636c4018df0909e1a51c673e125cb","server_ts_ms":1768250249308,"raw":{"market":"0x2a12fd3d8235c25c062dc9652970ef9f635636c4018df0909e1a51c673e125cb","price_changes":[{"asset_id":"56386988715176239099720172290594769295756680374928571099138069977179519358166","price":"0.18","size":"197.5","side":"SELL","hash":"a7007894ae72be19d484ae0d4e41b44284f2013a","best_bid":"0.15","best_ask":"0.16"},{"asset_id":"63670753354844494163057275310194312729998307779831462269530137743341854359908","price":"0.82","size":"197.5","side":"BUY","hash":"4d61d896af9f11e1ded921c30f65830bfe3727d2","best_bid":"0.84","best_ask":"0.85"}],"timestamp":"1768250249308","event_type":"price_change"}}
{"schema_version":1,"source":"clob_ws_market","recv_ts_ns":1768250249647823989,"event_type":"price_change","market":"0x2a12fd3d8235c25c062dc9652970ef9f635636c4018df0909e1a51c673e125cb","server_ts_ms":1768250249309,"raw":{"market":"0x2a12fd3d8235c25c062dc9652970ef9f635636c4018df0909e1a51c673e125cb","price_changes":[{"asset_id":"63670753354844494163057275310194312729998307779831462269530137743341854359908","price":"0.82","size":"207.5","side":"BUY","hash":"ae74a79d9b4173ae2212f5393b677f52924c14bc","best_bid":"0.84","best_ask":"0.85"},{"asset_id":"56386988715176239099720172290594769295756680374928571099138069977179519358166","price":"0.18","size":"207.5","side":"SELL","hash":"9b063b96fc194088c7364c942d24aa80f6e65196","best_bid":"0.15","best_ask":"0.16"}],"timestamp":"1768250249309","event_type":"price_change"}}
{"schema_version":1,"source":"clob_ws_market","recv_ts_ns":1768250249651936747,"event_type":"price_change","market":"0x2a12fd3d8235c25c062dc9652970ef9f635636c4018df0909e1a51c673e125cb","server_ts_ms":1768250249310,"raw":{"market":"0x2a12fd3d8235c25c062dc9652970ef9f635636c4018df0909e1a51c673e125cb","price_changes":[{"asset_id":"63670753354844494163057275310194312729998307779831462269530137743341854359908","price":"0.82","size":"217.5","side":"BUY","hash":"9deb5ca10ee411cb01ce830e193db6b66cf0679e","best_bid":"0.84","best_ask":"0.85"},{"asset_id":"56386988715176239099720172290594769295756680374928571099138069977179519358166","price":"0.18","size":"217.5","side":"SELL","hash":"6eca7f4f5bfd7b824a1597b3baede90f1d5e2184","best_bid":"0.15","best_ask":"0.16"}],"timestamp":"1768250249310","event_type":"price_change"}}
{"schema_version":1,"source":"clob_ws_market","recv_ts_ns":1768250249653668817,"event_type":"price_change","market":"0x2a12fd3d8235c25c062dc9652970ef9f635636c4018df0909e1a51c673e125cb","server_ts_ms":1768250249312,"raw":{"market":"0x2a12fd3d8235c25c062dc9652970ef9f635636c4018df0909e1a51c673e125cb","price_changes":[{"asset_id":"63670753354844494163057275310194312729998307779831462269530137743341854359908","price":"0.81","size":"233.21","side":"BUY","hash":"22c820c2024329d2071ff2b24c9ec4658f90e60a","best_bid":"0.84","best_ask":"0.85"},{"asset_id":"56386988715176239099720172290594769295756680374928571099138069977179519358166","price":"0.19","size":"233.21","side":"SELL","hash":"da3523e689ff03dedc2dc495965522d005383105","best_bid":"0.15","best_ask":"0.16"}],"timestamp":"1768250249312","event_type":"price_change"}}
{"schema_version":1,"source":"clob_ws_market","recv_ts_ns":1768250249661310051,"event_type":"price_change","market":"0x2a12fd3d8235c25c062dc9652970ef9f635636c4018df0909e1a51c673e125cb","server_ts_ms":1768250249313,"raw":{"market":"0x2a12fd3d8235c25c062dc9652970ef9f635636c4018df0909e1a51c673e125cb","price_changes":[{"asset_id":"56386988715176239099720172290594769295756680374928571099138069977179519358166","price":"0.12","size":"857.75","side":"BUY","hash":"7129df1ad9aa6bc022dd7ceddfa5d8075127d9da","best_bid":"0.15","best_ask":"0.16"},{"asset_id":"63670753354844494163057275310194312729998307779831462269530137743341854359908","price":"0.88","size":"857.75","side":"SELL","hash":"77aa24beee0253b5ded14e9f3f0e010eb8692ce0","best_bid":"0.84","best_ask":"0.85"}],"timestamp":"1768250249313","event_type":"price_change"}}
{"schema_version":1,"source":"clob_ws_market","recv_ts_ns":1768250249667214117,"event_type":"price_change","market":"0x2a12fd3d8235c25c062dc9652970ef9f635636c4018df0909e1a51c673e125cb","server_ts_ms":1768250249318,"raw":{"market":"0x2a12fd3d8235c25c062dc9652970ef9f635636c4018df0909e1a51c673e125cb","price_changes":[{"asset_id":"56386988715176239099720172290594769295756680374928571099138069977179519358166","price":"0.09","size":"1342","side":"BUY","hash":"a5514069b4e61f2d993dc939daa7adaab05cd410","best_bid":"0.15","best_ask":"0.16"},{"asset_id":"63670753354844494163057275310194312729998307779831462269530137743341854359908","price":"0.91","size":"1342","side":"SELL","hash":"31701ad99e75d89de36df934799a96f42b947448","best_bid":"0.84","best_ask":"0.85"}],"timestamp":"1768250249318","event_type":"price_change"}}
{"schema_version":1,"source":"clob_ws_market","recv_ts_ns":1768250249669277275,"event_type":"price_change","market":"0x2a12fd3d8235c25c062dc9652970ef9f635636c4018df0909e1a51c673e125cb","server_ts_ms":1768250249318,"raw":{"market":"0x2a12fd3d8235c25c062dc9652970ef9f635636c4018df0909e1a51c673e125cb","price_changes":[{"asset_id":"63670753354844494163057275310194312729998307779831462269530137743341854359908","price":"0.77","size":"748.5","side":"BUY","hash":"00d51e023d07db4bac868212d0f52eceb89a375c","best_bid":"0.84","best_ask":"0.85"},{"asset_id":"56386988715176239099720172290594769295756680374928571099138069977179519358166","price":"0.23","size":"748.5","side":"SELL","hash":"54aaf6cefe845bc088458fc498a6771cf1d89b1a","best_bid":"0.15","best_ask":"0.16"}],"timestamp":"1768250249318","event_type":"price_change"}}
{"schema_version":1,"source":"clob_ws_market","recv_ts_ns":1768250249671200565,"event_type":"price_change","market":"0x2a12fd3d8235c25c062dc9652970ef9f635636c4018df0909e1a51c673e125cb","server_ts_ms":1768250249318,"raw":{"market":"0x2a12fd3d8235c25c062dc9652970ef9f635636c4018df0909e1a51c673e125cb","price_changes":[{"asset_id":"63670753354844494163057275310194312729998307779831462269530137743341854359908","price":"0.88","size":"851.75","side":"SELL","hash":"00d51e023d07db4bac868212d0f52eceb89a375c","best_bid":"0.84","best_ask":"0.85"},{"asset_id":"56386988715176239099720172290594769295756680374928571099138069977179519358166","price":"0.12","size":"851.75","side":"BUY","hash":"54aaf6cefe845bc088458fc498a6771cf1d89b1a","best_bid":"0.15","best_ask":"0.16"}],"timestamp":"1768250249318","event_type":"price_change"}}
{"schema_version":1,"source":"clob_ws_market","recv_ts_ns":1768250249675249918,"event_type":"price_change","market":"0x2a12fd3d8235c25c062dc9652970ef9f635636c4018df0909e1a51c673e125cb","server_ts_ms":1768250249321,"raw":{"market":"0x2a12fd3d8235c25c062dc9652970ef9f635636c4018df0909e1a51c673e125cb","price_changes":[{"asset_id":"56386988715176239099720172290594769295756680374928571099138069977179519358166","price":"0.06","size":"1414","side":"BUY","hash":"c0dccdce18b60a222325a4f35b28d95ac9a613d3","best_bid":"0.15","best_ask":"0.16"},{"asset_id":"63670753354844494163057275310194312729998307779831462269530137743341854359908","price":"0.94","size":"1414","side":"SELL","hash":"834cc5d0c17ac4941a35b08c1401d8cf9b5b4ddc","best_bid":"0.84","best_ask":"0.85"}],"timestamp":"1768250249321","event_type":"price_change"}}
{"schema_version":1,"source":"clob_ws_market","recv_ts_ns":1768250249680337090,"event_type":"price_change","market":"0x2a12fd3d8235c25c062dc9652970ef9f635636c4018df0909e1a51c673e125cb","server_ts_ms":1768250249322,"raw":{"market":"0x2a12fd3d8235c25c062dc9652970ef9f635636c4018df0909e1a51c673e125cb","price_changes":[{"asset_id":"56386988715176239099720172290594769295756680374928571099138069977179519358166","price":"0.13","size":"854.5","side":"BUY","hash":"b667bbb463dde861af774a1505814d1e1e879f54","best_bid":"0.15","best_ask":"0.16"},{"asset_id":"63670753354844494163057275310194312729998307779831462269530137743341854359908","price":"0.87","size":"854.5","side":"SELL","hash":"f9eeef706183329bbe7cc2a387c48647c2c7b78f","best_bid":"0.84","best_ask":"0.85"}],"timestamp":"1768250249322","event_type":"price_change"}}
{"schema_version":1,"source":"clob_ws_market","recv_ts_ns":1768250249692360984,"event_type":"price_change","market":"0x2a12fd3d8235c25c062dc9652970ef9f635636c4018df0909e1a51c673e125cb","server_ts_ms":1768250249325,"raw":{"market":"0x2a12fd3d8235c25c062dc9652970ef9f635636c4018df0909e1a51c673e125cb","price_changes":[{"asset_id":"63670753354844494163057275310194312729998307779831462269530137743341854359908","price":"0.81","size":"243.21","side":"BUY","hash":"5af2e032a0297eae07e63d3bc4e8394503004c0d","best_bid":"0.84","best_ask":"0.85"},{"asset_id":"56386988715176239099720172290594769295756680374928571099138069977179519358166","price":"0.19","size":"243.21","side":"SELL","hash":"6bd2ec7b47fb9c6eccdda8ff8f1abe771a78aaf5","best_bid":"0.15","best_ask":"0.16"}],"timestamp":"1768250249325","event_type":"price_change"}}
{"schema_version":1,"source":"clob_ws_market","recv_ts_ns":1768250249696711483,"event_type":"price_change","market":"0x2a12fd3d8235c25c062dc9652970ef9f635636c4018df0909e1a51c673e125cb","server_ts_ms":1768250249326,"raw":{"market":"0x2a12fd3d8235c25c062dc9652970ef9f635636c4018df0909e1a51c673e125cb","price_changes":[{"asset_id":"63670753354844494163057275310194312729998307779831462269530137743341854359908","price":"0.81","size":"253.21","side":"BUY","hash":"b281414d3a10c53f0764a1b0b94e8192066826a0","best_bid":"0.84","best_ask":"0.85"},{"asset_id":"56386988715176239099720172290594769295756680374928571099138069977179519358166","price":"0.19","size":"253.21","side":"SELL","hash":"bf226a67d7e8564861d003db3389cf17894486a5","best_bid":"0.15","best_ask":"0.16"}],"timestamp":"1768250249326","event_type":"price_change"}}
{"schema_version":1,"source":"clob_ws_market","recv_ts_ns":1768250249701166681,"event_type":"price_change","market":"0x2a12fd3d8235c25c062dc9652970ef9f635636c4018df0909e1a51c673e125cb","server_ts_ms":1768250249327,"raw":{"market":"0x2a12fd3d8235c25c062dc9652970ef9f635636c4018df0909e1a51c673e125cb","price_changes":[{"asset_id":"56386988715176239099720172290594769295756680374928571099138069977179519358166","price":"0.15","size":"786.76","side":"BUY","hash":"76ef9d60f2702eb0407539d6174f7356ed43eb7c","best_bid":"0.15","best_ask":"0.16"},{"asset_id":"63670753354844494163057275310194312729998307779831462269530137743341854359908","price":"0.85","size":"786.76","side":"SELL","hash":"c456ef569ec7323005c519089d281cb7278c1b69","best_bid":"0.84","best_ask":"0.85"}],"timestamp":"1768250249327","event_type":"price_change"}}
{"schema_version":1,"source":"clob_ws_market","recv_ts_ns":1768250249705898349,"event_type":"price_change","market":"0x2a12fd3d8235c25c062dc9652970ef9f635636c4018df0909e1a51c673e125cb","server_ts_ms":1768250249328,"raw":{"market":"0x2a12fd3d8235c25c062dc9652970ef9f635636c4018df0909e1a51c673e125cb","price_changes":[{"asset_id":"56386988715176239099720172290594769295756680374928571099138069977179519358166","price":"0.13","size":"844.5","side":"BUY","hash":"d629c9d25ffedf7f72ffbef55aafeae98c21c3f4","best_bid":"0.15","best_ask":"0.16"},{"asset_id":"63670753354844494163057275310194312729998307779831462269530137743341854359908","price":"0.87","size":"844.5","side":"SELL","hash":"1b2d54739d1b8827fcfd6150eedd51a43ab4513f","best_bid":"0.84","best_ask":"0.85"}],"timestamp":"1768250249328","event_type":"price_change"}}
{"schema_version":1,"source":"clob_ws_market","recv_ts_ns":1768250249719933722,"event_type":"price_change","market":"0x2a12fd3d8235c25c062dc9652970ef9f635636c4018df0909e1a51c673e125cb","server_ts_ms":1768250249330,"raw":{"market":"0x2a12fd3d8235c25c062dc9652970ef9f635636c4018df0909e1a51c673e125cb","price_changes":[{"asset_id":"63670753354844494163057275310194312729998307779831462269530137743341854359908","price":"0.82","size":"227.5","side":"BUY","hash":"41939615f193a7f4c9d8ea948e88c943511eba81","best_bid":"0.84","best_ask":"0.85"},{"asset_id":"56386988715176239099720172290594769295756680374928571099138069977179519358166","price":"0.18","size":"227.5","side":"SELL","hash":"2c7b8f299e57ba42123b7554a0c70408fc5ca535","best_bid":"0.15","best_ask":"0.16"}],"timestamp":"1768250249330","event_type":"price_change"}}
{"schema_version":1,"source":"clob_ws_market","recv_ts_ns":1768250249734133526,"event_type":"price_change","market":"0x2a12fd3d8235c25c062dc9652970ef9f635636c4018df0909e1a51c673e125cb","server_ts_ms":1768250249332,"raw":{"market":"0x2a12fd3d8235c25c062dc9652970ef9f635636c4018df0909e1a51c673e125cb","price_changes":[{"asset_id":"63670753354844494163057275310194312729998307779831462269530137743341854359908","price":"0.82","size":"237.5","side":"BUY","hash":"0d6ad0c77f08aaf64c300d9b4c01b8e45042137d","best_bid":"0.84","best_ask":"0.85"},{"asset_id":"56386988715176239099720172290594769295756680374928571099138069977179519358166","price":"0.18","size":"237.5","side":"SELL","hash":"a03fde6068b1cb9cffbc6c665041b4e3edca3186","best_bid":"0.15","best_ask":"0.16"}],"timestamp":"1768250249332","event_type":"price_change"}}
{"schema_version":1,"source":"clob_ws_market","recv_ts_ns":1768250249739720371,"event_type":"price_change","market":"0x2a12fd3d8235c25c062dc9652970ef9f635636c4018df0909e1a51c673e125cb","server_ts_ms":1768250249333,"raw":{"market":"0x2a12fd3d8235c25c062dc9652970ef9f635636c4018df0909e1a51c673e125cb","price_changes":[{"asset_id":"56386988715176239099720172290594769295756680374928571099138069977179519358166","price":"0.14","size":"966.79","side":"BUY","hash":"f5090b2ce594b77fe1b14e3bbbdc520bc760c20c","best_bid":"0.15","best_ask":"0.16"},{"asset_id":"63670753354844494163057275310194312729998307779831462269530137743341854359908","price":"0.86","size":"966.79","side":"SELL","hash":"f76351da71382f50877d623a027780bf69b1be18","best_bid":"0.84","best_ask":"0.85"}],"timestamp":"1768250249333","event_type":"price_change"}}
{"schema_version":1,"source":"clob_ws_market","recv_ts_ns":1768250249744140571,"event_type":"price_change","market":"0x2a12fd3d8235c25c062dc9652970ef9f635636c4018df0909e1a51c673e125cb","server_ts_ms":1768250249334,"raw":{"market":"0x2a12fd3d8235c25c062dc9652970ef9f635636c4018df0909e1a51c673e125cb","price_changes":[{"asset_id":"56386988715176239099720172290594769295756680374928571099138069977179519358166","price":"0.13","size":"854.5","side":"BUY","hash":"29febe7467c954d4433a13939d03431d662adfa2","best_bid":"0.15","best_ask":"0.16"},{"asset_id":"63670753354844494163057275310194312729998307779831462269530137743341854359908","price":"0.87","size":"854.5","side":"SELL","hash":"49c11d8e51f1730201a3c74c2073bf30da0e7c3d","best_bid":"0.84","best_ask":"0.85"}],"timestamp":"1768250249334","event_type":"price_change"}}
{"schema_version":1,"source":"clob_ws_market","recv_ts_ns":1768250249752934390,"event_type":"price_change","market":"0x2a12fd3d8235c25c062dc9652970ef9f635636c4018df0909e1a51c673e125cb","server_ts_ms":1768250249339,"raw":{"market":"0x2a12fd3d8235c25c062dc9652970ef9f635636c4018df0909e1a51c673e125cb","price_changes":[{"asset_id":"63670753354844494163057275310194312729998307779831462269530137743341854359908","price":"0.81","size":"243.21","side":"BUY","hash":"85f59f9e97babc46d356a38b05c9bba8109c6c4e","best_bid":"0.84","best_ask":"0.85"},{"asset_id":"56386988715176239099720172290594769295756680374928571099138069977179519358166","price":"0.19","size":"243.21","side":"SELL","hash":"81190a2daaa4499b100a313d34428e194c21e12e","best_bid":"0.15","best_ask":"0.16"}],"timestamp":"1768250249339","event_type":"price_change"}}
{"schema_version":1,"source":"clob_ws_market","recv_ts_ns":1768250249763471824,"event_type":"price_change","market":"0x2a12fd3d8235c25c062dc9652970ef9f635636c4018df0909e1a51c673e125cb","server_ts_ms":1768250249341,"raw":{"market":"0x2a12fd3d8235c25c062dc9652970ef9f635636c4018df0909e1a51c673e125cb","price_changes":[{"asset_id":"63670753354844494163057275310194312729998307779831462269530137743341854359908","price":"0.81","size":"253.21","side":"BUY","hash":"094fed21e31b19ed19dfbc5fb57ad9fe54305ca3","best_bid":"0.84","best_ask":"0.85"},{"asset_id":"56386988715176239099720172290594769295756680374928571099138069977179519358166","price":"0.19","size":"253.21","side":"SELL","hash":"e18291f6fbb2b31ec7b7d07007ef06e3bf4bb6ed","best_bid":"0.15","best_ask":"0.16"}],"timestamp":"1768250249341","event_type":"price_change"}}
{"schema_version":1,"source":"clob_ws_market","recv_ts_ns":1768250249767727957,"event_type":"price_change","market":"0x2a12fd3d8235c25c062dc9652970ef9f635636c4018df0909e1a51c673e125cb","server_ts_ms":1768250249342,"raw":{"market":"0x2a12fd3d8235c25c062dc9652970ef9f635636c4018df0909e1a51c673e125cb","price_changes":[{"asset_id":"56386988715176239099720172290594769295756680374928571099138069977179519358166","price":"0.1","size":"3417","side":"BUY","hash":"172691802923366a8ddc55ce6ef6c389ec73f107","best_bid":"0.15","best_ask":"0.16"},{"asset_id":"63670753354844494163057275310194312729998307779831462269530137743341854359908","price":"0.9","size":"3417","side":"SELL","hash":"bbdee2273b22850bb97636dd3126061aa70a6a1c","best_bid":"0.84","best_ask":"0.85"}],"timestamp":"1768250249342","event_type":"price_change"}}
{"schema_version":1,"source":"clob_ws_market","recv_ts_ns":1768250249771513454,"event_type":"price_change","market":"0x2a12fd3d8235c25c062dc9652970ef9f635636c4018df0909e1a51c673e125cb","server_ts_ms":1768250249343,"raw":{"market":"0x2a12fd3d8235c25c062dc9652970ef9f635636c4018df0909e1a51c673e125cb","price_changes":[{"asset_id":"63670753354844494163057275310194312729998307779831462269530137743341854359908","price":"0.81","size":"263.21","side":"BUY","hash":"9bc27363ba73a2d60332337b26fd8dd22fa49afa","best_bid":"0.84","best_ask":"0.85"},{"asset_id":"56386988715176239099720172290594769295756680374928571099138069977179519358166","price":"0.19","size":"263.21","side":"SELL","hash":"85d0cee9c7de8bb08ef879fc77132a8f2f99a5b7","best_bid":"0.15","best_ask":"0.16"}],"timestamp":"1768250249343","event_type":"price_change"}}
{"schema_version":1,"source":"clob_ws_market","recv_ts_ns":1768250249774946386,"event_type":"price_change","market":"0x2a12fd3d8235c25c062dc9652970ef9f635636c4018df0909e1a51c673e125cb","server_ts_ms":1768250249344,"raw":{"market":"0x2a12fd3d8235c25c062dc9652970ef9f635636c4018df0909e1a51c673e125cb","price_changes":[{"asset_id":"63670753354844494163057275310194312729998307779831462269530137743341854359908","price":"0.8","size":"314.9","side":"BUY","hash":"f73bbd7742a110bd916e4dc0ab11661962fdad49","best_bid":"0.84","best_ask":"0.85"},{"asset_id":"56386988715176239099720172290594769295756680374928571099138069977179519358166","price":"0.2","size":"314.9","side":"SELL","hash":"a49206cb3929041419570909f45ae5df7606ce11","best_bid":"0.15","best_ask":"0.16"}],"timestamp":"1768250249344","event_type":"price_change"}}
{"schema_version":1,"source":"clob_ws_market","recv_ts_ns":1768250249778703077,"event_type":"price_change","market":"0x2a12fd3d8235c25c062dc9652970ef9f635636c4018df0909e1a51c673e125cb","server_ts_ms":1768250249347,"raw":{"market":"0x2a12fd3d8235c25c062dc9652970ef9f635636c4018df0909e1a51c673e125cb","price_changes":[{"asset_id":"63670753354844494163057275310194312729998307779831462269530137743341854359908","price":"0.87","size":"860.5","side":"SELL","hash":"48421cc09f430eb0fe5a91a2cbd21a9c269c2afa","best_bid":"0.84","best_ask":"0.85"},{"asset_id":"56386988715176239099720172290594769295756680374928571099138069977179519358166","price":"0.13","size":"860.5","side":"BUY","hash":"eae1c194b90618ff55c750916a9d8000d5dd3839","best_bid":"0.15","best_ask":"0.16"}],"timestamp":"1768250249347","event_type":"price_change"}}
