{"schema_version":1,"source":"clob_ws_market","recv_ts_ns":1768250244737844761,"event_type":"book","market":"0x2a12fd3d8235c25c062dc9652970ef9f635636c4018df0909e1a51c673e125cb","server_ts_ms":1768250244429,"raw":{"market":"0x2a12fd3d8235c25c062dc9652970ef9f635636c4018df0909e1a51c673e125cb","asset_id":"63670753354844494163057275310194312729998307779831462269530137743341854359908","bids":[{"price":"0.01","size":"10184.18"},{"price":"0.02","size":"5982"},{"price":"0.03","size":"5238.94"},{"price":"0.04","size":"5040"},{"price":"0.05","size":"5050"},{"price":"0.06","size":"5005"},{"price":"0.07","size":"5019.28"},{"price":"0.08","size":"5005"},{"price":"0.09","size":"5005"},{"price":"0.1","size":"5030"},{"price":"0.11","size":"5"},{"price":"0.12","size":"5"},{"price":"0.13","size":"5"},{"price":"0.14","size":"5"},{"price":"0.15","size":"10"},{"price":"0.16","size":"5"},{"price":"0.17","size":"5"},{"price":"0.18","size":"5"},{"price":"0.19","size":"5"},{"price":"0.2","size":"5"},{"price":"0.21","size":"5"},{"price":"0.22","size":"5"},{"price":"0.23","size":"5"},{"price":"0.24","size":"5"},{"price":"0.25","size":"10"},{"price":"0.26","size":"5"},{"price":"0.27","size":"5"},{"price":"0.28","size":"5"},{"price":"0.29","size":"15"},{"price":"0.3","size":"10"},{"price":"0.31","size":"5"},{"price":"0.32","size":"5"},{"price":"0.33","size":"5"},{"price":"0.34","size":"505"},{"price":"0.35","size":"510"},{"price":"0.36","size":"510"},{"price":"0.37","size":"505"},{"price":"0.38","size":"505"},{"price":"0.39","size":"755"},{"price":"0.4","size":"760"},{"price":"0.41","size":"916"},{"price":"0.42","size":"671"},{"price":"0.43","size":"827"},{"price":"0.44","size":"827"},{"price":"0.45","size":"817"},{"price":"0.46","size":"872"},{"price":"0.47","size":"839.65"},{"price":"0.48","size":"829"},{"price":"0.49","size":"817"},{"price":"0.5","size":"838.4"},{"price":"0.51","size":"867.58"},{"price":"0.52","size":"817"},{"price":"0.53","size":"827"},{"price":"0.54","size":"847.8"},{"price":"0.55","size":"836.09"},{"price":"0.56","size":"825"},{"price":"0.57","size":"847"},{"price":"0.58","size":"817"},{"price":"0.59","size":"817"},{"price":"0.6","size":"817"},{"price":"0.61","size":"834.5"},{"price":"0.62","size":"817"},{"price":"0.63","size":"497.49"},{"price":"0.64","size":"817"},{"price":"0.65","size":"872"},{"price":"0.66","size":"997.71"},{"price":"0.67","size":"906.8"},{"price":"0.68","size":"902"},{"price":"0.69","size":"922"},{"price":"0.7","size":"911.6"},{"price":"0.71","size":"897"},{"price":"0.72","size":"899.55"},{"price":"0.73","size":"912"},{"price":"0.74","size":"1174.42"},{"price":"0.75","size":"722.5"},{"price":"0.76","size":"924.25"},{"price":"0.77","size":"754.5"},{"price":"0.78","size":"910.8"},{"price":"0.79","size":"808.5"},{"price":"0.8","size":"814.9"},{"price":"0.81","size":"313.21"},{"price":"0.82","size":"901"},{"price":"0.83","size":"260.52"},{"price":"0.84","size":"196.5"},{"price":"0.85","size":"213.95"}],"asks":[{"price":"0.99","size":"10331.71"},{"price":"0.98","size":"6299.77"},{"price":"0.97","size":"5625.94"},{"price":"0.96","size":"5427"},{"price":"0.95","size":"3442"},{"price":"0.94","size":"1397"},{"price":"0.93","size":"1421.28"},{"price":"0.92","size":"1496.75"},{"price":"0.91","size":"1373"},{"price":"0.9","size":"3462"},{"price":"0.89","size":"869.5"},{"price":"0.88","size":"897.75"},{"price":"0.87","size":"831"},{"price":"0.86","size":"803.29"}],"hash":"89ff773f974cd068af99420c5587409f2574ec37","timestamp":"1768250244429","event_type":"book"}}
{"schema_version":1,"source":"clob_ws_market","recv_ts_ns":1768250244740424776,"event_type":"price_change","market":"0x2a12fd3d8235c25c062dc9652970ef9f635636c4018df0909e1a51c673e125cb","server_ts_ms":1768250244430,"raw":{"market":"0x2a12fd3d8235c25c062dc9652970ef9f635636c4018df0909e1a51c673e125cb","price_changes":[{"asset_id":"63670753354844494163057275310194312729998307779831462269530137743341854359908","price":"0.82","size":"891","side":"BUY","hash":"c13b1ec4ef124213ce26f27b3f95002493929389","best_bid":"0.85","best_ask":"0.86"},{"asset_id":"56386988715176239099720172290594769295756680374928571099138069977179519358166","price":"0.18","size":"891","side":"SELL","hash":"87aece472d8a32386f05161ed362e3a50bbb7062","best_bid":"0.14","best_ask":"0.15"}],"timestamp":"1768250244430","event_type":"price_change"}}
{"schema_version":1,"source":"clob_ws_market","recv_ts_ns":1768250244743528364,"event_type":"price_change","market":"0x2a12fd3d8235c25c062dc9652970ef9f635636c4018df0909e1a51c673e125cb","server_ts_ms":1768250244431,"raw":{"market":"0x2a12fd3d8235c25c062dc9652970ef9f635636c4018df0909e1a51c673e125cb","price_changes":[{"asset_id":"63670753354844494163057275310194312729998307779831462269530137743341854359908","price":"0.83","size":"250.52","side":"BUY","hash":"c58d355b09826823e65a59240ec58e21d9f2d4da","best_bid":"0.85","best_ask":"0.86"},{"asset_id":"56386988715176239099720172290594769295756680374928571099138069977179519358166","price":"0.17","size":"250.52","side":"SELL","hash":"335a19072e6aa1e79dabbb1778f7b3a68d846401","best_bid":"0.14","best_ask":"0.15"}],"timestamp":"1768250244431","event_type":"price_change"}}
{"schema_version":1,"source":"clob_ws_market","recv_ts_ns":1768250244746281867,"event_type":"price_change","market":"0x2a12fd3d8235c25c062dc9652970ef9f635636c4018df0909e1a51c673e125cb","server_ts_ms":1768250244432,"raw":{"market":"0x2a12fd3d8235c25c062dc9652970ef9f635636c4018df0909e1a51c673e125cb","price_changes":[{"asset_id":"63670753354844494163057275310194312729998307779831462269530137743341854359908","price":"0.82","size":"881","side":"BUY","hash":"2b40114b9763504e7fa05886e79fd3708232b13a","best_bid":"0.85","best_ask":"0.86"},{"asset_id":"56386988715176239099720172290594769295756680374928571099138069977179519358166","price":"0.18","size":"881","side":"SELL","hash":"bdb2295b17194f996a40ee0b7fd94a251b8f21c9","best_bid":"0.14","best_ask":"0.15"}],"timestamp":"1768250244432","event_type":"price_change"}}
{"schema_version":1,"source":"clob_ws_market","recv_ts_ns":1768250244749169819,"event_type":"price_change","market":"0x2a12fd3d8235c25c062dc9652970ef9f635636c4018df0909e1a51c673e125cb","server_ts_ms":1768250244432,"raw":{"market":"0x2a12fd3d8235c25c062dc9652970ef9f635636c4018df0909e1a51c673e125cb","price_changes":[{"asset_id":"63670753354844494163057275310194312729998307779831462269530137743341854359908","price":"0.83","size":"240.52","side":"BUY","hash":"db9723d912a59b5ffe7b831fffbd63971a67ab8a","best_bid":"0.85","best_ask":"0.86"},{"asset_id":"56386988715176239099720172290594769295756680374928571099138069977179519358166","price":"0.17","size":"240.52","side":"SELL","hash":"3cbecc6f9d919209a6349e6bad7b0691e1fd2fd5","best_bid":"0.14","best_ask":"0.15"}],"timestamp":"1768250244432","event_type":"price_change"}}
{"schema_version":1,"source":"clob_ws_market","recv_ts_ns":1768250244751535132,"event_type":"price_change","market":"0x2a12fd3d8235c25c062dc9652970ef9f635636c4018df0909e1a51c673e125cb","server_ts_ms":1768250244433,"raw":{"market":"0x2a12fd3d8235c25c062dc9652970ef9f635636c4018df0909e1a51c673e125cb","price_changes":[{"asset_id":"63670753354844494163057275310194312729998307779831462269530137743341854359908","price":"0.83","size":"230.52","side":"BUY","hash":"de00cc95360c9220ba1dc4667e218d95beb72022","best_bid":"0.85","best_ask":"0.86"},{"asset_id":"56386988715176239099720172290594769295756680374928571099138069977179519358166","price":"0.17","size":"230.52","side":"SELL","hash":"043a1a44f0d692c47c76e75a967a35a593f6b0f5","best_bid":"0.14","best_ask":"0.15"}],"timestamp":"1768250244433","event_type":"price_change"}}
{"schema_version":1,"source":"clob_ws_market","recv_ts_ns":1768250244753919971,"event_type":"price_change","market":"0x2a12fd3d8235c25c062dc9652970ef9f635636c4018df0909e1a51c673e125cb","server_ts_ms":1768250244434,"raw":{"market":"0x2a12fd3d8235c25c062dc9652970ef9f635636c4018df0909e1a51c673e125cb","price_changes":[{"asset_id":"56386988715176239099720172290594769295756680374928571099138069977179519358166","price":"0.12","size":"887.75","side":"BUY","hash":"728f0e869059587b08dc8d4a358c241b1b82bbe4","best_bid":"0.14","best_ask":"0.15"},{"asset_id":"63670753354844494163057275310194312729998307779831462269530137743341854359908","price":"0.88","size":"887.75","side":"SELL","hash":"667aceafaa5cb677e3f46f85725143bdd401e0fd","best_bid":"0.85","best_ask":"0.86"}],"timestamp":"1768250244434","event_type":"price_change"}}
{"schema_version":1,"source":"clob_ws_market","recv_ts_ns":1768250244757087303,"event_type":"price_change","market":"0x2a12fd3d8235c25c062dc9652970ef9f635636c4018df0909e1a51c673e125cb","server_ts_ms":1768250244434,"raw":{"market":"0x2a12fd3d8235c25c062dc9652970ef9f635636c4018df0909e1a51c673e125cb","price_changes":[{"asset_id":"56386988715176239099720172290594769295756680374928571099138069977179519358166","price":"0.11","size":"859.5","side":"BUY","hash":"1cf37e9703fe1d9e5d1b76ce1ee8e43e5066f181","best_bid":"0.14","best_ask":"0.15"},{"asset_id":"63670753354844494163057275310194312729998307779831462269530137743341854359908","price":"0.89","size":"859.5","side":"SELL","hash":"bb2d5c503d7ccedec31cfb8dd3989a07762490f4","best_bid":"0.85","best_ask":"0.86"}],"timestamp":"1768250244434","event_type":"price_change"}}
{"schema_version":1,"source":"clob_ws_market","recv_ts_ns":1768250244760236733,"event_type":"price_change","market":"0x2a12fd3d8235c25c062dc9652970ef9f635636c4018df0909e1a51c673e125cb","server_ts_ms":1768250244435,"raw":{"market":"0x2a12fd3d8235c25c062dc9652970ef9f635636c4018df0909e1a51c673e125cb","price_changes":[{"asset_id":"63670753354844494163057275310194312729998307779831462269530137743341854359908","price":"0.83","size":"220.52","side":"BUY","hash":"896733469bb99a7764c509ef81444265824c66c1","best_bid":"0.85","best_ask":"0.86"},{"asset_id":"56386988715176239099720172290594769295756680374928571099138069977179519358166","price":"0.17","size":"220.52","side":"SELL","hash":"b6df1d32471171b98fa4fa8a01f9bdfc2dd43823","best_bid":"0.14","best_ask":"0.15"}],"timestamp":"1768250244435","event_type":"price_change"}}
{"schema_version":1,"source":"clob_ws_market","recv_ts_ns":1768250244764263222,"event_type":"price_change","market":"0x2a12fd3d8235c25c062dc9652970ef9f635636c4018df0909e1a51c673e125cb","server_ts_ms":1768250244436,"raw":{"market":"0x2a12fd3d8235c25c062dc9652970ef9f635636c4018df0909e1a51c673e125cb","price_changes":[{"asset_id":"56386988715176239099720172290594769295756680374928571099138069977179519358166","price":"0.12","size":"877.75","side":"BUY","hash":"ef55af5f6635537c449969ccff4f271190dbd85c","best_bid":"0.14","best_ask":"0.15"},{"asset_id":"63670753354844494163057275310194312729998307779831462269530137743341854359908","price":"0.88","size":"877.75","side":"SELL","hash":"8ae0c1fd404683bd8aac2e27db95ca9899a1fc89","best_bid":"0.85","best_ask":"0.86"}],"timestamp":"1768250244436","event_type":"price_change"}}
{"schema_version":1,"source":"clob_ws_market","recv_ts_ns":1768250244767497552,"event_type":"price_change","market":"0x2a12fd3d8235c25c062dc9652970ef9f635636c4018df0909e1a51c673e125cb","server_ts_ms":1768250244436,"raw":{"market":"0x2a12fd3d8235c25c062dc9652970ef9f635636c4018df0909e1a51c673e125cb","price_changes":[{"asset_id":"63670753354844494163057275310194312729998307779831462269530137743341854359908","price":"0.83","size":"210.52","side":"BUY","hash":"d2cacc51c0f2e45017546033f82a6b5a4f05fb09","best_bid":"0.85","best_ask":"0.86"},{"asset_id":"56386988715176239099720172290594769295756680374928571099138069977179519358166","price":"0.17","size":"210.52","side":"SELL","hash":"a6c479d4d564985e53ad2eefe53df5857c2a54c5","best_bid":"0.14","best_ask":"0.15"}],"timestamp":"1768250244436","event_type":"price_change"}}
{"schema_version":1,"source":"clob_ws_market","recv_ts_ns":1768250244771472338,"event_type":"price_change","market":"0x2a12fd3d8235c25c062dc9652970ef9f635636c4018df0909e1a51c673e125cb","server_ts_ms":1768250244437,"raw":{"market":"0x2a12fd3d8235c25c062dc9652970ef9f635636c4018df0909e1a51c673e125cb","price_changes":[{"asset_id":"63670753354844494163057275310194312729998307779831462269530137743341854359908","price":"0.83","size":"200.52","side":"BUY","hash":"64dd89cc467652d33d9deef8a9c71b3576a7054e","best_bid":"0.85","best_ask":"0.86"},{"asset_id":"56386988715176239099720172290594769295756680374928571099138069977179519358166","price":"0.17","size":"200.52","side":"SELL","hash":"6358bcde946b749fb7851a11e983ad5d6ceb18e2","best_bid":"0.14","best_ask":"0.15"}],"timestamp":"1768250244437","event_type":"price_change"}}
{"schema_version":1,"source":"clob_ws_market","recv_ts_ns":1768250244775177091,"event_type":"price_change","market":"0x2a12fd3d8235c25c062dc9652970ef9f635636c4018df0909e1a51c673e125cb","server_ts_ms":1768250244438,"raw":{"market":"0x2a12fd3d8235c25c062dc9652970ef9f635636c4018df0909e1a51c673e125cb","price_changes":[{"asset_id":"56386988715176239099720172290594769295756680374928571099138069977179519358166","price":"0.12","size":"867.75","side":"BUY","hash":"9c8c01cee4c6f14d54decd1406d6c04be647276e","best_bid":"0.14","best_ask":"0.15"},{"asset_id":"63670753354844494163057275310194312729998307779831462269530137743341854359908","price":"0.88","size":"867.75","side":"SELL","hash":"d010eac873f2cc6db741cd13cee639a4c49d1016","best_bid":"0.85","best_ask":"0.86"}],"timestamp":"1768250244438","event_type":"price_change"}}
{"schema_version":1,"source":"clob_ws_market","recv_ts_ns":1768250244778438746,"event_type":"price_change","market":"0x2a12fd3d8235c25c062dc9652970ef9f635636c4018df0909e1a51c673e125cb","server_ts_ms":1768250244438,"raw":{"market":"0x2a12fd3d8235c25c062dc9652970ef9f635636c4018df0909e1a51c673e125cb","price_changes":[{"asset_id":"56386988715176239099720172290594769295756680374928571099138069977179519358166","price":"0.1","size":"3452","side":"BUY","hash":"fff655fbee8768b072097604df51d5102ac80abe","best_bid":"0.14","best_ask":"0.15"},{"asset_id":"63670753354844494163057275310194312729998307779831462269530137743341854359908","price":"0.9","size":"3452","side":"SELL","hash":"3e246efccfc928feb54411ab4ee6e7e09503be7e","best_bid":"0.85","best_ask":"0.86"}],"timestamp":"1768250244438","event_type":"price_change"}}
{"schema_version":1,"source":"clob_ws_market","recv_ts_ns":1768250244784226908,"event_type":"price_change","market":"0x2a12fd3d8235c25c062dc9652970ef9f635636c4018df0909e1a51c673e125cb","server_ts_ms":1768250244438,"raw":{"market":"0x2a12fd3d8235c25c062dc9652970ef9f635636c4018df0909e1a51c673e125cb","price_changes":[{"asset_id":"56386988715176239099720172290594769295756680374928571099138069977179519358166","price":"0.14","size":"793.29","side":"BUY","hash":"419b3522b7e9b244a5bf83a9697179860d5d2060","best_bid":"0.14","best_ask":"0.15"},{"asset_id":"63670753354844494163057275310194312729998307779831462269530137743341854359908","price":"0.86","size":"793.29","side":"SELL","hash":"fcd31e8d5d33d16952747af59fd031ce84e564e4","best_bid":"0.85","best_ask":"0.86"}],"timestamp":"1768250244438","event_type":"price_change"}}
{"schema_version":1,"source":"clob_ws_market","recv_ts_ns":1768250244787677619,"event_type":"price_change","market":"0x2a12fd3d8235c25c062dc9652970ef9f635636c4018df0909e1a51c673e125cb","server_ts_ms":1768250244439,"raw":{"market":"0x2a12fd3d8235c25c062dc9652970ef9f635636c4018df0909e1a51c673e125cb","price_changes":[{"asset_id":"56386988715176239099720172290594769295756680374928571099138069977179519358166","price":"0.12","size":"857.75","side":"BUY","hash":"25df148922eabee61342e281b8cd8d6ffe8fd2f7","best_bid":"0.14","best_ask":"0.15"},{"asset_id":"63670753354844494163057275310194312729998307779831462269530137743341854359908","price":"0.88","size":"857.75","side":"SELL","hash":"4fff9c290ce60cb080953a1a7b0186984554fc1c","best_bid":"0.85","best_ask":"0.86"}],"timestamp":"1768250244439","event_type":"price_change"}}
{"schema_version":1,"source":"clob_ws_market","recv_ts_ns":1768250244794278858,"event_type":"price_change","market":"0x2a12fd3d8235c25c062dc9652970ef9f635636c4018df0909e1a51c673e125cb","server_ts_ms":1768250244439,"raw":{"market":"0x2a12fd3d8235c25c062dc9652970ef9f635636c4018df0909e1a51c673e125cb","price_changes":[{"asset_id":"63670753354844494163057275310194312729998307779831462269530137743341854359908","price":"0.83","size":"190.52","side":"BUY","hash":"8ddee1bd0aefbad001453ff4cfbb69dda8e37cfd","best_bid":"0.85","best_ask":"0.86"},{"asset_id":"56386988715176239099720172290594769295756680374928571099138069977179519358166","price":"0.17","size":"190.52","side":"SELL","hash":"740f0415e60a571dd6bbb84fa4a7fc7e7ffb76be","best_bid":"0.14","best_ask":"0.15"}],"timestamp":"1768250244439","event_type":"price_change"}}
{"schema_version":1,"source":"clob_ws_market","recv_ts_ns":1768250244797519817,"event_type":"price_change","market":"0x2a12fd3d8235c25c062dc9652970ef9f635636c4018df0909e1a51c673e125cb","server_ts_ms":1768250244440,"raw":{"market":"0x2a12fd3d8235c25c062dc9652970ef9f635636c4018df0909e1a51c673e125cb","price_changes":[{"asset_id":"63670753354844494163057275310194312729998307779831462269530137743341854359908","price":"0.83","size":"180.52","side":"BUY","hash":"7ee069a87a8f741416a192b0e760c7ded0e707f2","best_bid":"0.85","best_ask":"0.86"},{"asset_id":"56386988715176239099720172290594769295756680374928571099138069977179519358166","price":"0.17","size":"180.52","side":"SELL","hash":"a5574ff089f85ed86f3982e29476add80fad3b9e","best_bid":"0.14","best_ask":"0.15"}],"timestamp":"1768250244440","event_type":"price_change"}}
{"schema_version":1,"source":"clob_ws_market","recv_ts_ns":1768250244800420435,"event_type":"price_change","market":"0x2a12fd3d8235c25c062dc9652970ef9f635636c4018df0909e1a51c673e125cb","server_ts_ms":1768250244441,"raw":{"market":"0x2a12fd3d8235c25c062dc9652970ef9f635636c4018df0909e1a51c673e125cb","price_changes":[{"asset_id":"56386988715176239099720172290594769295756680374928571099138069977179519358166","price":"0.13","size":"821","side":"BUY","hash":"6d913d8cf0d82f867cc3f40d042b06db9cfbee36","best_bid":"0.14","best_ask":"0.15"},{"asset_id":"63670753354844494163057275310194312729998307779831462269530137743341854359908","price":"0.87","size":"821","side":"SELL","hash":"539e3cb63585352e125f72c33df5507b7e5b812b","best_bid":"0.85","best_ask":"0.86"}],"timestamp":"1768250244441","event_type":"price_change"}}
{"schema_version":1,"source":"clob_ws_market","recv_ts_ns":1768250244804644989,"event_type":"price_change","market":"0x2a12fd3d8235c25c062dc9652970ef9f635636c4018df0909e1a51c673e125cb","server_ts_ms":1768250244443,"raw":{"market":"0x2a12fd3d8235c25c062dc9652970ef9f635636c4018df0909e1a51c673e125cb","price_changes":[{"asset_id":"63670753354844494163057275310194312729998307779831462269530137743341854359908","price":"0.83","size":"190.52","side":"BUY","hash":"5ffbf7ac22b67048e66a8c4b9e06f73d33231ae6","best_bid":"0.85","best_ask":"0.86"},{"asset_id":"56386988715176239099720172290594769295756680374928571099138069977179519358166","price":"0.17","size":"190.52","side":"SELL","hash":"9b70afd9c7ef4f23f63719aa15c5e000cb2ccde0","best_bid":"0.14","best_ask":"0.15"}],"timestamp":"1768250244443","event_type":"price_change"}}
{"schema_version":1,"source":"clob_ws_market","recv_ts_ns":1768250244808271770,"event_type":"price_change","market":"0x2a12fd3d8235c25c062dc9652970ef9f635636c4018df0909e1a51c673e125cb","server_ts_ms":1768250244448,"raw":{"market":"0x2a12fd3d8235c25c062dc9652970ef9f635636c4018df0909e1a51c673e125cb","price_changes":[{"asset_id":"63670753354844494163057275310194312729998307779831462269530137743341854359908","price":"0.84","size":"186.5","side":"BUY","hash":"fefd8289b01924df1b5352d1dd2a927ffa24f601","best_bid":"0.85","best_ask":"0.86"},{"asset_id":"56386988715176239099720172290594769295756680374928571099138069977179519358166","price":"0.16","size":"186.5","side":"SELL","hash":"35f47ec2723d8e6733105652b10ce994c4832e9c","best_bid":"0.14","best_ask":"0.15"}],"timestamp":"1768250244448","event_type":"price_change"}}
{"schema_version":1,"source":"clob_ws_market","recv_ts_ns":1768250244815793992,"event_type":"last_trade_price","market":"0x2a12fd3d8235c25c062dc9652970ef9f635636c4018df0909e1a51c673e125cb","server_ts_ms":1768250244457,"raw":{"market":"0x2a12fd3d8235c25c062dc9652970ef9f635636c4018df0909e1a51c673e125cb","asset_id":"63670753354844494163057275310194312729998307779831462269530137743341854359908","price":"0.86","size":"1.255807","fee_rate_bps":"1000","side":"BUY","timestamp":"1768250244457","event_type":"last_trade_price","transaction_hash":"0x22241584485f5d7561d3f072798dd4bc5ac64896c2f04c48e66a7f8720415083"}}
{"schema_version":1,"source":"clob_ws_market","recv_ts_ns":1768250244817918340,"event_type":"price_change","market":"0x2a12fd3d8235c25c062dc9652970ef9f635636c4018df0909e1a51c673e125cb","server_ts_ms":1768250244464,"raw":{"market":"0x2a12fd3d8235c25c062dc9652970ef9f635636c4018df0909e1a51c673e125cb","price_changes":[{"asset_id":"63670753354844494163057275310194312729998307779831462269530137743341854359908","price":"0.83","size":"200.52","side":"BUY","hash":"c733a5b2e2da368e1d1cb43ce3a24925148e292f","best_bid":"0.85","best_ask":"0.86"},{"asset_id":"56386988715176239099720172290594769295756680374928571099138069977179519358166","price":"0.17","size":"200.52","side":"SELL","hash":"105b1781257cd552fed8205a12394b76e2da49cf","best_bid":"0.14","best_ask":"0.15"}],"timestamp":"1768250244464","event_type":"price_change"}}
{"schema_version":1,"source":"clob_ws_market","recv_ts_ns":1768250244821816423,"event_type":"price_change","market":"0x2a12fd3d8235c25c062dc9652970ef9f635636c4018df0909e1a51c673e125cb","server_ts_ms":1768250244465,"raw":{"market":"0x2a12fd3d8235c25c062dc9652970ef9f635636c4018df0909e1a51c673e125cb","price_changes":[{"asset_id":"63670753354844494163057275310194312729998307779831462269530137743341854359908","price":"0.83","size":"210.52","side":"BUY","hash":"e683b15c860959cf0c8a3b9ccdd745429b7af75b","best_bid":"0.85","best_ask":"0.86"},{"asset_id":"56386988715176239099720172290594769295756680374928571099138069977179519358166","price":"0.17","size":"210.52","side":"SELL","hash":"3ebbc5359a31c5d4cddac5ceb8cba41d25d19f10","best_bid":"0.14","best_ask":"0.15"}],"timestamp":"1768250244465","event_type":"price_change"}}
{"schema_version":1,"source":"clob_ws_market","recv_ts_ns":1768250244827079345,"event_type":"price_change","market":"0x2a12fd3d8235c25c062dc9652970ef9f635636c4018df0909e1a51c673e125cb","server_ts_ms":1768250244466,"raw":{"market":"0x2a12fd3d8235c25c062dc9652970ef9f635636c4018df0909e1a51c673e125cb","price_changes":[{"asset_id":"56386988715176239099720172290594769295756680374928571099138069977179519358166","price":"0.12","size":"867.75","side":"BUY","hash":"c8163fe72d13e1a80b6f1fddb6ca5f0668434750","best_bid":"0.14","best_ask":"0.15"},{"asset_id":"63670753354844494163057275310194312729998307779831462269530137743341854359908","price":"0.88","size":"867.75","side":"SELL","hash":"220bf84d314617349658c3546d2fbcd854ec83c1","best_bid":"0.85","best_ask":"0.86"}],"timestamp":"1768250244466","event_type":"price_change"}}
{"schema_version":1,"source":"clob_ws_market","recv_ts_ns":1768250244832129954,"event_type":"price_change","market":"0x2a12fd3d8235c25c062dc9652970ef9f635636c4018df0909e1a51c673e125cb","server_ts_ms":1768250244467,"raw":{"market":"0x2a12fd3d8235c25c062dc9652970ef9f635636c4018df0909e1a51c673e125cb","price_changes":[{"asset_id":"56386988715176239099720172290594769295756680374928571099138069977179519358166","price":"0.12","size":"877.75","side":"BUY","hash":"1516a0c9b73a25a93a69a9584c2288e6fd08b52d","best_bid":"0.14","best_ask":"0.15"},{"asset_id":"63670753354844494163057275310194312729998307779831462269530137743341854359908","price":"0.88","size":"877.75","side":"SELL","hash":"212a96c06a5ee4a761f2be03cef855703e090fd0","best_bid":"0.85","best_ask":"0.86"}],"timestamp":"1768250244467","event_type":"price_change"}}
{"schema_version":1,"source":"clob_ws_market","recv_ts_ns":1768250244836990441,"event_type":"price_change","market":"0x2a12fd3d8235c25c062dc9652970ef9f635636c4018df0909e1a51c673e125cb","server_ts_ms":1768250244468,"raw":{"market":"0x2a12fd3d8235c25c062dc9652970ef9f635636c4018df0909e1a51c673e125cb","price_changes":[{"asset_id":"56386988715176239099720172290594769295756680374928571099138069977179519358166","price":"0.12","size":"887.75","side":"BUY","hash":"64373a9bb8f798fea9f022294e19c55fc416e2f5","best_bid":"0.14","best_ask":"0.15"},{"asset_id":"63670753354844494163057275310194312729998307779831462269530137743341854359908","price":"0.88","size":"887.75","side":"SELL","hash":"74c9384e3d669798425163b1b0fdb7ec72dc190b","best_bid":"0.85","best_ask":"0.86"}],"timestamp":"1768250244468","event_type":"price_change"}}
{"schema_version":1,"source":"clob_ws_market","recv_ts_ns":1768250244841893206,"event_type":"price_change","market":"0x2a12fd3d8235c25c062dc9652970ef9f635636c4018df0909e1a51c673e125cb","server_ts_ms":1768250244468,"raw":{"market":"0x2a12fd3d8235c25c062dc9652970ef9f635636c4018df0909e1a51c673e125cb","price_changes":[{"asset_id":"63670753354844494163057275310194312729998307779831462269530137743341854359908","price":"0.83","size":"220.52","side":"BUY","hash":"dadddf602a287b5e1171b0877be613c6af419486","best_bid":"0.85","best_ask":"0.86"},{"asset_id":"56386988715176239099720172290594769295756680374928571099138069977179519358166","price":"0.17","size":"220.52","side":"SELL","hash":"692594b2e0ed6ab33aa6ee132c5746ca2c31a263","best_bid":"0.14","best_ask":"0.15"}],"timestamp":"1768250244468","event_type":"price_change"}}
{"schema_version":1,"source":"clob_ws_market","recv_ts_ns":1768250244846848467,"event_type":"price_change","market":"0x2a12fd3d8235c25c062dc9652970ef9f635636c4018df0909e1a51c673e125cb","server_ts_ms":1768250244470,"raw":{"market":"0x2a12fd3d8235c25c062dc9652970ef9f635636c4018df0909e1a51c673e125cb","price_changes":[{"asset_id":"56386988715176239099720172290594769295756680374928571099138069977179519358166","price":"0.11","size":"869.5","side":"BUY","hash":"55abe8d88ac6e79fca78dca4f0bac656d5c8d6a5","best_bid":"0.14","best_ask":"0.15"},{"asset_id":"63670753354844494163057275310194312729998307779831462269530137743341854359908","price":"0.89","size":"869.5","side":"SELL","hash":"4fd58d7bd2a9388af4197120e8b6954206244485","best_bid":"0.85","best_ask":"0.86"}],"timestamp":"1768250244470","event_type":"price_change"}}
{"schema_version":1,"source":"clob_ws_market","recv_ts_ns":1768250244852669857,"event_type":"price_change","market":"0x2a12fd3d8235c25c062dc9652970ef9f635636c4018df0909e1a51c673e125cb","server_ts_ms":1768250244471,"raw":{"market":"0x2a12fd3d8235c25c062dc9652970ef9f635636c4018df0909e1a51c673e125cb","price_changes":[{"asset_id":"63670753354844494163057275310194312729998307779831462269530137743341854359908","price":"0.83","size":"230.52","side":"BUY","hash":"6f4881ba786cb74c5e8c60d50f57138b0114212a","best_bid":"0.85","best_ask":"0.86"},{"asset_id":"56386988715176239099720172290594769295756680374928571099138069977179519358166","price":"0.17","size":"230.52","side":"SELL","hash":"42fb3d4ccbe2c49eb29fb00097377a82a8c8a93a","best_bid":"0.14","best_ask":"0.15"}],"timestamp":"1768250244471","event_type":"price_change"}}
{"schema_version":1,"source":"clob_ws_market","recv_ts_ns":1768250244859091600,"event_type":"price_change","market":"0x2a12fd3d8235c25c062dc9652970ef9f635636c4018df0909e1a51c673e125cb","server_ts_ms":1768250244473,"raw":{"market":"0x2a12fd3d8235c25c062dc9652970ef9f635636c4018df0909e1a51c673e125cb","price_changes":[{"asset_id":"63670753354844494163057275310194312729998307779831462269530137743341854359908","price":"0.82","size":"891","side":"BUY","hash":"7b227c716e299daeb301cae13538cb2a567c7335","best_bid":"0.85","best_ask":"0.86"},{"asset_id":"56386988715176239099720172290594769295756680374928571099138069977179519358166","price":"0.18","size":"891","side":"SELL","hash":"7edab323da69774aa41a28c5fb7415696360c3d9","best_bid":"0.14","best_ask":"0.15"}],"timestamp":"1768250244473","event_type":"price_change"}}
{"schema_version":1,"source":"clob_ws_market","recv_ts_ns":1768250244864455306,"event_type":"price_change","market":"0x2a12fd3d8235c25c062dc9652970ef9f635636c4018df0909e1a51c673e125cb","server_ts_ms":1768250244474,"raw":{"market":"0x2a12fd3d8235c25c062dc9652970ef9f635636c4018df0909e1a51c673e125cb","price_changes":[{"asset_id":"56386988715176239099720172290594769295756680374928571099138069977179519358166","price":"0.14","size":"803.29","side":"BUY","hash":"f90e59b6ce34c033b13b611d04691ad3c704cd49","best_bid":"0.14","best_ask":"0.15"},{"asset_id":"63670753354844494163057275310194312729998307779831462269530137743341854359908","price":"0.86","size":"803.29","side":"SELL","hash":"556c15baab5c2d5c2fe76d740364e8e7bb82fbce","best_bid":"0.85","best_ask":"0.86"}],"timestamp":"1768250244474","event_type":"price_change"}}
{"schema_version":1,"source":"clob_ws_market","recv_ts_ns":1768250244869451854,"event_type":"price_change","market":"0x2a12fd3d8235c25c062dc9652970ef9f635636c4018df0909e1a51c673e125cb","server_ts_ms":1768250244475,"raw":{"market":"0x2a12fd3d8235c25c062dc9652970ef9f635636c4018df0909e1a51c673e125cb","price_changes":[{"asset_id":"63670753354844494163057275310194312729998307779831462269530137743341854359908","price":"0.82","size":"901","side":"BUY","hash":"144dd4e21cecb0bbc87fad4f485eda6d1a314708","best_bid":"0.85","best_ask":"0.86"},{"asset_id":"56386988715176239099720172290594769295756680374928571099138069977179519358166","price":"0.18","size":"901","side":"SELL","hash":"b4eacee57771b1a0dc76fd914da02e288dd816e2","best_bid":"0.14","best_ask":"0.15"}],"timestamp":"1768250244475","event_type":"price_change"}}
{"schema_version":1,"source":"clob_ws_market","recv_ts_ns":1768250244874527335,"event_type":"price_change","market":"0x2a12fd3d8235c25c062dc9652970ef9f635636c4018df0909e1a51c673e125cb","server_ts_ms":1768250244476,"raw":{"market":"0x2a12fd3d8235c25c062dc9652970ef9f635636c4018df0909e1a51c673e125cb","price_changes":[{"asset_id":"63670753354844494163057275310194312729998307779831462269530137743341854359908","price":"0.83","size":"240.52","side":"BUY","hash":"38c1a4cc6c7c32df0c4512096226184f5e769d00","best_bid":"0.85","best_ask":"0.86"},{"asset_id":"56386988715176239099720172290594769295756680374928571099138069977179519358166","price":"0.17","size":"240.52","side":"SELL","hash":"4a6b0c6b8d863c62067936d6553935ba6411fb77","best_bid":"0.14","best_ask":"0.15"}],"timestamp":"1768250244476","event_type":"price_change"}}
{"schema_version":1,"source":"clob_ws_market","recv_ts_ns":1768250244884860695,"event_type":"price_change","market":"0x2a12fd3d8235c25c062dc9652970ef9f635636c4018df0909e1a51c673e125cb","server_ts_ms":1768250244477,"raw":{"market":"0x2a12fd3d8235c25c062dc9652970ef9f635636c4018df0909e1a51c673e125cb","price_changes":[{"asset_id":"63670753354844494163057275310194312729998307779831462269530137743341854359908","price":"0.82","size":"911","side":"BUY","hash":"2cbccd7eecc7594f438960f23c11f084c1259cec","best_bid":"0.85","best_ask":"0.86"},{"asset_id":"56386988715176239099720172290594769295756680374928571099138069977179519358166","price":"0.18","size":"911","side":"SELL","hash":"7662db217e40046ebcfa0545510bd8b9a05e4fa6","best_bid":"0.14","best_ask":"0.15"}],"timestamp":"1768250244477","event_type":"price_change"}}
{"schema_version":1,"source":"clob_ws_market","recv_ts_ns":1768250244890375377,"event_type":"price_change","market":"0x2a12fd3d8235c25c062dc9652970ef9f635636c4018df0909e1a51c673e125cb","server_ts_ms":1768250244478,"raw":{"market":"0x2a12fd3d8235c25c062dc9652970ef9f635636c4018df0909e1a51c673e125cb","price_changes":[{"asset_id":"56386988715176239099720172290594769295756680374928571099138069977179519358166","price":"0.11","size":"879.5","side":"BUY","hash":"d3b013a013bea194a343ef2ead1ef0770edf974f","best_bid":"0.14","best_ask":"0.15"},{"asset_id":"63670753354844494163057275310194312729998307779831462269530137743341854359908","price":"0.89","size":"879.5","side":"SELL","hash":"51d22e00ceb2b7f136a8031426d4ed7c2bed9e4d","best_bid":"0.85","best_ask":"0.86"}],"timestamp":"1768250244478","event_type":"price_change"}}
{"schema_version":1,"source":"clob_ws_market","recv_ts_ns":1768250244895428673,"event_type":"price_change","market":"0x2a12fd3d8235c25c062dc9652970ef9f635636c4018df0909e1a51c673e125cb","server_ts_ms":1768250244479,"raw":{"market":"0x2a12fd3d8235c25c062dc9652970ef9f635636c4018df0909e1a51c673e125cb","price_changes":[{"asset_id":"56386988715176239099720172290594769295756680374928571099138069977179519358166","price":"0.12","size":"897.75","side":"BUY","hash":"700360ede2d56dcb8845e0ac6bb32f12e1cd6c40","best_bid":"0.14","best_ask":"0.15"},{"asset_id":"63670753354844494163057275310194312729998307779831462269530137743341854359908","price":"0.88","size":"897.75","side":"SELL","hash":"40dc49b8875c400a5d3cfa1479871f454d137508","best_bid":"0.85","best_ask":"0.86"}],"timestamp":"1768250244479","event_type":"price_change"}}
{"schema_version":1,"source":"clob_ws_market","recv_ts_ns":1768250244916950002,"event_type":"price_change","market":"0x2a12fd3d8235c25c062dc9652970ef9f635636c4018df0909e1a51c673e125cb","server_ts_ms":1768250244486,"raw":{"market":"0x2a12fd3d8235c25c062dc9652970ef9f635636c4018df0909e1a51c673e125cb","price_changes":[{"asset_id":"63670753354844494163057275310194312729998307779831462269530137743341854359908","price":"0.82","size":"921","side":"BUY","hash":"484f610fea6c2bd498061f030f14d6431009ff93","best_bid":"0.85","best_ask":"0.86"},{"asset_id":"56386988715176239099720172290594769295756680374928571099138069977179519358166","price":"0.18","size":"921","side":"SELL","hash":"6178b53003b2e0fe4b23d4f53f79d0b1f3cb1c65","best_bid":"0.14","best_ask":"0.15"}],"timestamp":"1768250244486","event_type":"price_change"}}
{"schema_version":1,"source":"clob_ws_market","recv_ts_ns":1768250244921286559,"event_type":"price_change","market":"0x2a12fd3d8235c25c062dc9652970ef9f635636c4018df0909e1a51c673e125cb","server_ts_ms":1768250244491,"raw":{"market":"0x2a12fd3d8235c25c062dc9652970ef9f635636c4018df0909e1a51c673e125cb","price_changes":[{"asset_id":"63670753354844494163057275310194312729998307779831462269530137743341854359908","price":"0.83","size":"250.52","side":"BUY","hash":"c5d0021881aa5c9157c54e8e54f8b53e27f38140","best_bid":"0.85","best_ask":"0.86"},{"asset_id":"56386988715176239099720172290594769295756680374928571099138069977179519358166","price":"0.17","size":"250.52","side":"SELL","hash":"3405825f8e20eea694c213b4a449ccfc915d2677","best_bid":"0.14","best_ask":"0.15"}],"timestamp":"1768250244491","event_type":"price_change"}}
{"schema_version":1,"source":"clob_ws_market","recv_ts_ns":1768250244925583107,"event_type":"price_change","market":"0x2a12fd3d8235c25c062dc9652970ef9f635636c4018df0909e1a51c673e125cb","server_ts_ms":1768250244492,"raw":{"market":"0x2a12fd3d8235c25c062dc9652970ef9f635636c4018df0909e1a51c673e125cb","price_changes":[{"asset_id":"56386988715176239099720172290594769295756680374928571099138069977179519358166","price":"0.13","size":"831","side":"BUY","hash":"b815001f9c0ce8f3c7e9b1485c6775266fe1e971","best_bid":"0.14","best_ask":"0.15"},{"asset_id":"63670753354844494163057275310194312729998307779831462269530137743341854359908","price":"0.87","size":"831","side":"SELL","hash":"a5832b1db533a3f963e2c285babb93ce9473e7fb","best_bid":"0.85","best_ask":"0.86"}],"timestamp":"1768250244492","event_type":"price_change"}}
{"schema_version":1,"source":"clob_ws_market","recv_ts_ns":1768250244984613174,"event_type":"best_bid_ask","market":"0x2a12fd3d8235c25c062dc9652970ef9f635636c4018df0909e1a51c673e125cb","server_ts_ms":1768250244661,"raw":{"market":"0x2a12fd3d8235c25c062dc9652970ef9f635636c4018df0909e1a51c673e125cb","asset_id":"63670753354844494163057275310194312729998307779831462269530137743341854359908","best_bid":"0.85","best_ask":"0.86","spread":"0.01","timestamp":"1768250244661","event_type":"best_bid_ask"}}
{"schema_version":1,"source":"clob_ws_market","recv_ts_ns":1768250244987851123,"event_type":"price_change","market":"0x2a12fd3d8235c25c062dc9652970ef9f635636c4018df0909e1a51c673e125cb","server_ts_ms":1768250244659,"raw":{"market":"0x2a12fd3d8235c25c062dc9652970ef9f635636c4018df0909e1a51c673e125cb","price_changes":[{"asset_id":"63670753354844494163057275310194312729998307779831462269530137743341854359908","price":"0.85","size":"203.95","side":"BUY","hash":"75929f3e373831497bfcc1be0455d2102c566627","best_bid":"0.85","best_ask":"0.86"},{"asset_id":"56386988715176239099720172290594769295756680374928571099138069977179519358166","price":"0.15","size":"203.95","side":"SELL","hash":"0922515f8b4e470f5f74546f2327843e9c54f496","best_bid":"0.14","best_ask":"0.15"}],"timestamp":"1768250244659","event_type":"price_change"}}
{"schema_version":1,"source":"clob_ws_market","recv_ts_ns":1768250245001112077,"event_type":"book","market":"0x2a12fd3d8235c25c062dc9652970ef9f635636c4018df0909e1a51c673e125cb","server_ts_ms":1768250244659,"raw":{"market":"0x2a12fd3d8235c25c062dc9652970ef9f635636c4018df0909e1a51c673e125cb","asset_id":"63670753354844494163057275310194312729998307779831462269530137743341854359908","bids":[{"price":"0.01","size":"10184.18"},{"price":"0.02","size":"5982"},{"price":"0.03","size":"5238.94"},{"price":"0.04","size":"5040"},{"price":"0.05","size":"5050"},{"price":"0.06","size":"5005"},{"price":"0.07","size":"5019.28"},{"price":"0.08","size":"5005"},{"price":"0.09","size":"5005"},{"price":"0.1","size":"5030"},{"price":"0.11","size":"5"},{"price":"0.12","size":"5"},{"price":"0.13","size":"5"},{"price":"0.14","size":"5"},{"price":"0.15","size":"10"},{"price":"0.16","size":"5"},{"price":"0.17","size":"5"},{"price":"0.18","size":"5"},{"price":"0.19","size":"5"},{"price":"0.2","size":"5"},{"price":"0.21","size":"5"},{"price":"0.22","size":"5"},{"price":"0.23","size":"5"},{"price":"0.24","size":"5"},{"price":"0.25","size":"10"},{"price":"0.26","size":"5"},{"price":"0.27","size":"5"},{"price":"0.28","size":"5"},{"price":"0.29","size":"15"},{"price":"0.3","size":"10"},{"price":"0.31","size":"5"},{"price":"0.32","size":"5"},{"price":"0.33","size":"5"},{"price":"0.34","size":"505"},{"price":"0.35","size":"510"},{"price":"0.36","size":"510"},{"price":"0.37","size":"505"},{"price":"0.38","size":"505"},{"price":"0.39","size":"755"},{"price":"0.4","size":"760"},{"price":"0.41","size":"916"},{"price":"0.42","size":"671"},{"price":"0.43","size":"827"},{"price":"0.44","size":"827"},{"price":"0.45","size":"817"},{"price":"0.46","size":"872"},{"price":"0.47","size":"839.65"},{"price":"0.48","size":"829"},{"price":"0.49","size":"817"},{"price":"0.5","size":"838.4"},{"price":"0.51","size":"867.58"},{"price":"0.52","size":"817"},{"price":"0.53","size":"827"},{"price":"0.54","size":"847.8"},{"price":"0.55","size":"836.09"},{"price":"0.56","size":"825"},{"price":"0.57","size":"847"},{"price":"0.58","size":"817"},{"price":"0.59","size":"817"},{"price":"0.6","size":"817"},{"price":"0.61","size":"834.5"},{"price":"0.62","size":"817"},{"price":"0.63","size":"497.49"},{"price":"0.64","size":"817"},{"price":"0.65","size":"872"},{"price":"0.66","size":"997.71"},{"price":"0.67","size":"906.8"},{"price":"0.68","size":"902"},{"price":"0.69","size":"922"},{"price":"0.7","size":"911.6"},{"price":"0.71","size":"897"},{"price":"0.72","size":"899.55"},{"price":"0.73","size":"912"},{"price":"0.74","size":"1174.42"},{"price":"0.75","size":"722.5"},{"price":"0.76","size":"924.25"},{"price":"0.77","size":"754.5"},{"price":"0.78","size":"910.8"},{"price":"0.79","size":"808.5"},{"price":"0.8","size":"814.9"},{"price":"0.81","size":"313.21"},{"price":"0.82","size":"921"},{"price":"0.83","size":"250.52"},{"price":"0.84","size":"186.5"},{"price":"0.85","size":"203.95"}],"asks":[{"price":"0.99","size":"10331.71"},{"price":"0.98","size":"6299.77"},{"price":"0.97","size":"5625.94"},{"price":"0.96","size":"5427"},{"price":"0.95","size":"3442"},{"price":"0.94","size":"1397"},{"price":"0.93","size":"1421.28"},{"price":"0.92","size":"1496.75"},{"price":"0.91","size":"1373"},{"price":"0.9","size":"3452"},{"price":"0.89","size":"879.5"},{"price":"0.88","size":"897.75"},{"price":"0.87","size":"831"},{"price":"0.86","size":"803.29"}],"hash":"75929f3e373831497bfcc1be0455d2102c566627","timestamp":"1768250244659","event_type":"book"}}
{"schema_version":1,"source":"clob_ws_market","recv_ts_ns":1768250245044566662,"event_type":"price_change","market":"0x2a12fd3d8235c25c062dc9652970ef9f635636c4018df0909e1a51c673e125cb","server_ts_ms":1768250244673,"raw":{"market":"0x2a12fd3d8235c25c062dc9652970ef9f635636c4018df0909e1a51c673e125cb","price_changes":[{"asset_id":"63670753354844494163057275310194312729998307779831462269530137743341854359908","price":"0.78","size":"899.5","side":"BUY","hash":"74e4422551187fcc84f8b673ece869fda47ab81c","best_bid":"0.85","best_ask":"0.86"},{"asset_id":"56386988715176239099720172290594769295756680374928571099138069977179519358166","price":"0.22","size":"899.5","side":"SELL","hash":"a4ac257ea1d6330fadac694c2c0726b7b2c62329","best_bid":"0.14","best_ask":"0.15"}],"timestamp":"1768250244673","event_type":"price_change"}}
{"schema_version":1,"source":"clob_ws_market","recv_ts_ns":1768250245049999601,"event_type":"price_change","market":"0x2a12fd3d8235c25c062dc9652970ef9f635636c4018df0909e1a51c673e125cb","server_ts_ms":1768250244674,"raw":{"market":"0x2a12fd3d8235c25c062dc9652970ef9f635636c4018df0909e1a51c673e125cb","price_changes":[{"asset_id":"56386988715176239099720172290594769295756680374928571099138069977179519358166","price":"0.1","size":"3427","side":"BUY","hash":"22702885b89afd42b5fd0825f72893755d84cee1","best_bid":"0.14","best_ask":"0.15"},{"asset_id":"63670753354844494163057275310194312729998307779831462269530137743341854359908","price":"0.9","size":"3427","side":"SELL","hash":"8c3ae2060421c5622f044dc74be6fa9dc5b2b2ce","best_bid":"0.85","best_ask":"0.86"}],"timestamp":"1768250244674","event_type":"price_change"}}
{"schema_version":1,"source":"clob_ws_market","recv_ts_ns":1768250245067014212,"event_type":"price_change","market":"0x2a12fd3d8235c25c062dc9652970ef9f635636c4018df0909e1a51c673e125cb","server_ts_ms":1768250244709,"raw":{"market":"0x2a12fd3d8235c25c062dc9652970ef9f635636c4018df0909e1a51c673e125cb","price_changes":[{"asset_id":"56386988715176239099720172290594769295756680374928571099138069977179519358166","price":"0.11","size":"904.5","side":"BUY","hash":"b13cd94f89e38d18313f1a3da9b9eb2f15bc9822","best_bid":"0.14","best_ask":"0.15"},{"asset_id":"63670753354844494163057275310194312729998307779831462269530137743341854359908","price":"0.89","size":"904.5","side":"SELL","hash":"0431c4694b5508a485f9a06ce8a912bcef5d99c1","best_bid":"0.85","best_ask":"0.86"}],"timestamp":"1768250244709","event_type":"price_change"}}
{"schema_version":1,"source":"clob_ws_market","recv_ts_ns":1768250245070543766,"event_type":"price_change","market":"0x2a12fd3d8235c25c062dc9652970ef9f635636c4018df0909e1a51c673e125cb","server_ts_ms":1768250244709,"raw":{"market":"0x2a12fd3d8235c25c062dc9652970ef9f635636c4018df0909e1a51c673e125cb","price_changes":[{"asset_id":"63670753354844494163057275310194312729998307779831462269530137743341854359908","price":"0.77","size":"762.5","side":"BUY","hash":"257713f71cf4406fafd368f7066701175c363dfb","best_bid":"0.85","best_ask":"0.86"},{"asset_id":"56386988715176239099720172290594769295756680374928571099138069977179519358166","price":"0.23","size":"762.5","side":"SELL","hash":"bfb8c47d6ffef7c51f35a813f4bb10e697472bae","best_bid":"0.14","best_ask":"0.15"}],"timestamp":"1768250244709","event_type":"price_change"}}
{"schema_version":1,"source":"clob_ws_market","recv_ts_ns":1768250245075601869,"event_type":"best_bid_ask","market":"0x2a12fd3d8235c25c062dc9652970ef9f635636c4018df0909e1a51c673e125cb","server_ts_ms":1768250244719,"raw":{"market":"0x2a12fd3d8235c25c062dc9652970ef9f635636c4018df0909e1a51c673e125cb","asset_id":"63670753354844494163057275310194312729998307779831462269530137743341854359908","best_bid":"0.85","best_ask":"0.86","spread":"0.01","timestamp":"1768250244719","event_type":"best_bid_ask"}}
{"schema_version":1,"source":"clob_ws_market","recv_ts_ns":1768250245077612732,"event_type":"price_change","market":"0x2a12fd3d8235c25c062dc9652970ef9f635636c4018df0909e1a51c673e125cb","server_ts_ms":1768250244717,"raw":{"market":"0x2a12fd3d8235c25c062dc9652970ef9f635636c4018df0909e1a51c673e125cb","price_changes":[{"asset_id":"56386988715176239099720172290594769295756680374928571099138069977179519358166","price":"0.14","size":"793.29","side":"BUY","hash":"aa7429306138f559598e04c702f61134d3554450","best_bid":"0.14","best_ask":"0.15"},{"asset_id":"63670753354844494163057275310194312729998307779831462269530137743341854359908","price":"0.86","size":"793.29","side":"SELL","hash":"fc9c76d7bf2e2f7842c0cab822868d87a0930642","best_bid":"0.85","best_ask":"0.86"}],"timestamp":"1768250244717","event_type":"price_change"}}
{"schema_version":1,"source":"clob_ws_market","recv_ts_ns":1768250245084861967,"event_type":"book","market":"0x2a12fd3d8235c25c062dc9652970ef9f635636c4018df0909e1a51c673e125cb","server_ts_ms":1768250244717,"raw":{"market":"0x2a12fd3d8235c25c062dc9652970ef9f635636c4018df0909e1a51c673e125cb","asset_id":"63670753354844494163057275310194312729998307779831462269530137743341854359908","bids":[{"price":"0.01","size":"10184.18"},{"price":"0.02","size":"5982"},{"price":"0.03","size":"5238.94"},{"price":"0.04","size":"5040"},{"price":"0.05","size":"5050"},{"price":"0.06","size":"5005"},{"price":"0.07","size":"5019.28"},{"price":"0.08","size":"5005"},{"price":"0.09","size":"5005"},{"price":"0.1","size":"5030"},{"price":"0.11","size":"5"},{"price":"0.12","size":"5"},{"price":"0.13","size":"5"},{"price":"0.14","size":"5"},{"price":"0.15","size":"10"},{"price":"0.16","size":"5"},{"price":"0.17","size":"5"},{"price":"0.18","size":"5"},{"price":"0.19","size":"5"},{"price":"0.2","size":"5"},{"price":"0.21","size":"5"},{"price":"0.22","size":"5"},{"price":"0.23","size":"5"},{"price":"0.24","size":"5"},{"price":"0.25","size":"10"},{"price":"0.26","size":"5"},{"price":"0.27","size":"5"},{"price":"0.28","size":"5"},{"price":"0.29","size":"15"},{"price":"0.3","size":"10"},{"price":"0.31","size":"5"},{"price":"0.32","size":"5"},{"price":"0.33","size":"5"},{"price":"0.34","size":"505"},{"price":"0.35","size":"510"},{"price":"0.36","size":"510"},{"price":"0.37","size":"505"},{"price":"0.38","size":"505"},{"price":"0.39","size":"755"},{"price":"0.4","size":"760"},{"price":"0.41","size":"916"},{"price":"0.42","size":"671"},{"price":"0.43","size":"827"},{"price":"0.44","size":"827"},{"price":"0.45","size":"817"},{"price":"0.46","size":"872"},{"price":"0.47","size":"839.65"},{"price":"0.48","size":"829"},{"price":"0.49","size":"817"},{"price":"0.5","size":"838.4"},{"price":"0.51","size":"867.58"},{"price":"0.52","size":"817"},{"price":"0.53","size":"827"},{"price":"0.54","size":"847.8"},{"price":"0.55","size":"836.09"},{"price":"0.56","size":"825"},{"price":"0.57","size":"847"},{"price":"0.58","size":"817"},{"price":"0.59","size":"817"},{"price":"0.6","size":"817"},{"price":"0.61","size":"834.5"},{"price":"0.62","size":"817"},{"price":"0.63","size":"497.49"},{"price":"0.64","size":"817"},{"price":"0.65","size":"872"},{"price":"0.66","size":"997.71"},{"price":"0.67","size":"906.8"},{"price":"0.68","size":"902"},{"price":"0.69","size":"922"},{"price":"0.7","size":"911.6"},{"price":"0.71","size":"897"},{"price":"0.72","size":"899.55"},{"price":"0.73","size":"912"},{"price":"0.74","size":"1174.42"},{"price":"0.75","size":"722.5"},{"price":"0.76","size":"924.25"},{"price":"0.77","size":"762.5"},{"price":"0.78","size":"899.5"},{"price":"0.79","size":"808.5"},{"price":"0.8","size":"814.9"},{"price":"0.81","size":"313.21"},{"price":"0.82","size":"921"},{"price":"0.83","size":"250.52"},{"price":"0.84","size":"186.5"},{"price":"0.85","size":"203.95"}],"asks":[{"price":"0.99","size":"10331.71"},{"price":"0.98","size":"6299.77"},{"price":"0.97","size":"5625.94"},{"price":"0.96","size":"5427"},{"price":"0.95","size":"3442"},{"price":"0.94","size":"1397"},{"price":"0.93","size":"1421.28"},{"price":"0.92","size":"1496.75"},{"price":"0.91","size":"1373"},{"price":"0.9","size":"3427"},{"price":"0.89","size":"904.5"},{"price":"0.88","size":"897.75"},{"price":"0.87","size":"831"},{"price":"0.86","size":"793.29"}],"hash":"fc9c76d7bf2e2f7842c0cab822868d87a0930642","timestamp":"1768250244717","event_type":"book"}}
{"schema_version":1,"source":"clob_ws_market","recv_ts_ns":1768250245089699187,"event_type":"price_change","market":"0x2a12fd3d8235c25c062dc9652970ef9f635636c4018df0909e1a51c673e125cb","server_ts_ms":1768250244737,"raw":{"market":"0x2a12fd3d8235c25c062dc9652970ef9f635636c4018df0909e1a51c673e125cb","price_changes":[{"asset_id":"63670753354844494163057275310194312729998307779831462269530137743341854359908","price":"0.81","size":"813.21","side":"BUY","hash":"deac7bc1af20318e2f2875ed960bcf018c3a3b9c","best_bid":"0.85","best_ask":"0.86"},{"asset_id":"56386988715176239099720172290594769295756680374928571099138069977179519358166","price":"0.19","size":"813.21","side":"SELL","hash":"541d1b966d490760496866ee9aec16328d4dd658","best_bid":"0.14","best_ask":"0.15"}],"timestamp":"1768250244737","event_type":"price_change"}}
{"schema_version":1,"source":"clob_ws_market","recv_ts_ns":1768250245092523833,"event_type":"price_change","market":"0x2a12fd3d8235c25c062dc9652970ef9f635636c4018df0909e1a51c673e125cb","server_ts_ms":1768250244738,"raw":{"market":"0x2a12fd3d8235c25c062dc9652970ef9f635636c4018df0909e1a51c673e125cb","price_changes":[{"asset_id":"63670753354844494163057275310194312729998307779831462269530137743341854359908","price":"0.74","size":"1127.65","side":"BUY","hash":"cb8c65fd8ce63ecb67f5c3817660711b31673356","best_bid":"0.85","best_ask":"0.86"},{"asset_id":"56386988715176239099720172290594769295756680374928571099138069977179519358166","price":"0.26","size":"1127.65","side":"SELL","hash":"0b5e72830f9037ad9947e732d24fdb1b15c68811","best_bid":"0.14","best_ask":"0.15"}],"timestamp":"1768250244738","event_type":"price_change"}}
{"schema_version":1,"source":"clob_ws_market","recv_ts_ns":1768250245095288779,"event_type":"last_trade_price","market":"0x2a12fd3d8235c25c062dc9652970ef9f635636c4018df0909e1a51c673e125cb","server_ts_ms":1768250244745,"raw":{"market":"0x2a12fd3d8235c25c062dc9652970ef9f635636c4018df0909e1a51c673e125cb","asset_id":"63670753354844494163057275310194312729998307779831462269530137743341854359908","price":"0.86","size":"10","fee_rate_bps":"1000","side":"BUY","timestamp":"1768250244745","event_type":"last_trade_price","transaction_hash":"0xddd688cddca35791a4bcb9d52c49ae0be541211363f8fc124d4779dc3dd092ed"}}
{"schema_version":1,"source":"clob_ws_market","recv_ts_ns":1768250245096712025,"event_type":"price_change","market":"0x2a12fd3d8235c25c062dc9652970ef9f635636c4018df0909e1a51c673e125cb","server_ts_ms":1768250244755,"raw":{"market":"0x2a12fd3d8235c25c062dc9652970ef9f635636c4018df0909e1a51c673e125cb","price_changes":[{"asset_id":"63670753354844494163057275310194312729998307779831462269530137743341854359908","price":"0.84","size":"196.5","side":"BUY","hash":"1445a6997346551a1791e0d84548326e006edbb6","best_bid":"0.85","best_ask":"0.86"},{"asset_id":"56386988715176239099720172290594769295756680374928571099138069977179519358166","price":"0.16","size":"196.5","side":"SELL","hash":"d6af14ad88e3e4cf1d044d12aba2446853db3645","best_bid":"0.14","best_ask":"0.15"}],"timestamp":"1768250244755","event_type":"price_change"}}
{"schema_version":1,"source":"clob_ws_market","recv_ts_ns":1768250245100361251,"event_type":"price_change","market":"0x2a12fd3d8235c25c062dc9652970ef9f635636c4018df0909e1a51c673e125cb","server_ts_ms":1768250244760,"raw":{"market":"0x2a12fd3d8235c25c062dc9652970ef9f635636c4018df0909e1a51c673e125cb","price_changes":[{"asset_id":"63670753354844494163057275310194312729998307779831462269530137743341854359908","price":"0.83","size":"240.52","side":"BUY","hash":"46835efc15ac0c3f67a844543650bb4b07347952","best_bid":"0.85","best_ask":"0.86"},{"asset_id":"56386988715176239099720172290594769295756680374928571099138069977179519358166","price":"0.17","size":"240.52","side":"SELL","hash":"1962765a74f5380e334cf706fa5a4d7f38ace2c0","best_bid":"0.14","best_ask":"0.15"}],"timestamp":"1768250244760","event_type":"price_change"}}
{"schema_version":1,"source":"clob_ws_market","recv_ts_ns":1768250245103028977,"event_type":"price_change","market":"0x2a12fd3d8235c25c062dc9652970ef9f635636c4018df0909e1a51c673e125cb","server_ts_ms":1768250244768,"raw":{"market":"0x2a12fd3d8235c25c062dc9652970ef9f635636c4018df0909e1a51c673e125cb","price_changes":[{"asset_id":"63670753354844494163057275310194312729998307779831462269530137743341854359908","price":"0.92","size":"1484.25","side":"SELL","hash":"932f826222100addafa13f0e8b8396f8534fed92","best_bid":"0.85","best_ask":"0.86"},{"asset_id":"56386988715176239099720172290594769295756680374928571099138069977179519358166","price":"0.08","size":"1484.25","side":"BUY","hash":"62cdeac27fb65d9845bc615453d069f2ce6107e8","best_bid":"0.14","best_ask":"0.15"}],"timestamp":"1768250244768","event_type":"price_change"}}
{"schema_version":1,"source":"clob_ws_market","recv_ts_ns":1768250245105645227,"event_type":"price_change","market":"0x2a12fd3d8235c25c062dc9652970ef9f635636c4018df0909e1a51c673e125cb","server_ts_ms":1768250244769,"raw":{"market":"0x2a12fd3d8235c25c062dc9652970ef9f635636c4018df0909e1a51c673e125cb","price_changes":[{"asset_id":"56386988715176239099720172290594769295756680374928571099138069977179519358166","price":"0.08","size":"1471.75","side":"BUY","hash":"c9c0c2b9a8b920c57b39ea9a06f6e39ec0ea0cef","best_bid":"0.14","best_ask":"0.15"},{"asset_id":"63670753354844494163057275310194312729998307779831462269530137743341854359908","price":"0.92","size":"1471.75","side":"SELL","hash":"a1f7e145f04366ff067d74c3a1e19d4d27a746bd","best_bid":"0.85","best_ask":"0.86"}],"timestamp":"1768250244769","event_type":"price_change"}}
{"schema_version":1,"source":"clob_ws_market","recv_ts_ns":1768250245114747039,"event_type":"price_change","market":"0x2a12fd3d8235c25c062dc9652970ef9f635636c4018df0909e1a51c673e125cb","server_ts_ms":1768250244781,"raw":{"market":"0x2a12fd3d8235c25c062dc9652970ef9f635636c4018df0909e1a51c673e125cb","price_changes":[{"asset_id":"63670753354844494163057275310194312729998307779831462269530137743341854359908","price":"0.93","size":"1433.78","side":"SELL","hash":"03813ed7ceeb0c1a2d5829c4ecdb252b86b08309","best_bid":"0.85","best_ask":"0.86"},{"asset_id":"56386988715176239099720172290594769295756680374928571099138069977179519358166","price":"0.07","size":"1433.78","side":"BUY","hash":"62a2baa7c018092d2963c29e0daa16d679cafb7a","best_bid":"0.14","best_ask":"0.15"}],"timestamp":"1768250244781","event_type":"price_change"}}
{"schema_version":1,"source":"clob_ws_market","recv_ts_ns":1768250245118107163,"event_type":"price_change","market":"0x2a12fd3d8235c25c062dc9652970ef9f635636c4018df0909e1a51c673e125cb","server_ts_ms":1768250244787,"raw":{"market":"0x2a12fd3d8235c25c062dc9652970ef9f635636c4018df0909e1a51c673e125cb","price_changes":[{"asset_id":"63670753354844494163057275310194312729998307779831462269530137743341854359908","price":"0.83","size":"235.02","side":"BUY","hash":"40c35012b1f0e20241b3f568d802dee9433d9777","best_bid":"0.85","best_ask":"0.86"},{"asset_id":"56386988715176239099720172290594769295756680374928571099138069977179519358166","price":"0.17","size":"235.02","side":"SELL","hash":"18291b2435ba7ef274992d021afebaad02f2ec96","best_bid":"0.14","best_ask":"0.15"}],"timestamp":"1768250244787","event_type":"price_change"}}
{"schema_version":1,"source":"clob_ws_market","recv_ts_ns":1768250245124581033,"event_type":"price_change","market":"0x2a12fd3d8235c25c062dc9652970ef9f635636c4018df0909e1a51c673e125cb","server_ts_ms":1768250244805,"raw":{"market":"0x2a12fd3d8235c25c062dc9652970ef9f635636c4018df0909e1a51c673e125cb","price_changes":[{"asset_id":"56386988715176239099720172290594769295756680374928571099138069977179519358166","price":"0.14","size":"803.29","side":"BUY","hash":"cb0e9c1ac4973e86b363a52d1809571d80d6adec","best_bid":"0.14","best_ask":"0.15"},{"asset_id":"63670753354844494163057275310194312729998307779831462269530137743341854359908","price":"0.86","size":"803.29","side":"SELL","hash":"775164ed67459a49c59e1793ab878594300c5a20","best_bid":"0.85","best_ask":"0.86"}],"timestamp":"1768250244805","event_type":"price_change"}}
{"schema_version":1,"source":"clob_ws_market","recv_ts_ns":1768250245136112497,"event_type":"price_change","market":"0x2a12fd3d8235c25c062dc9652970ef9f635636c4018df0909e1a51c673e125cb","server_ts_ms":1768250244816,"raw":{"market":"0x2a12fd3d8235c25c062dc9652970ef9f635636c4018df0909e1a51c673e125cb","price_changes":[{"asset_id":"63670753354844494163057275310194312729998307779831462269530137743341854359908","price":"0.84","size":"202","side":"BUY","hash":"fb74d5d367f6310257784be9cb6f99be9d6babd0","best_bid":"0.85","best_ask":"0.86"},{"asset_id":"56386988715176239099720172290594769295756680374928571099138069977179519358166","price":"0.16","size":"202","side":"SELL","hash":"a4ae31f9f1c4642e919053ee02db8be64a002de5","best_bid":"0.14","best_ask":"0.15"}],"timestamp":"1768250244816","event_type":"price_change"}}
{"schema_version":1,"source":"clob_ws_market","recv_ts_ns":1768250245141070977,"event_type":"best_bid_ask","market":"0x2a12fd3d8235c25c062dc9652970ef9f635636c4018df0909e1a51c673e125cb","server_ts_ms":1768250244820,"raw":{"market":"0x2a12fd3d8235c25c062dc9652970ef9f635636c4018df0909e1a51c673e125cb","asset_id":"63670753354844494163057275310194312729998307779831462269530137743341854359908","best_bid":"0.84","best_ask":"0.86","spread":"0.02","timestamp":"1768250244820","event_type":"best_bid_ask"}}
{"schema_version":1,"source":"clob_ws_market","recv_ts_ns":1768250245143017426,"event_type":"price_change","market":"0x2a12fd3d8235c25c062dc9652970ef9f635636c4018df0909e1a51c673e125cb","server_ts_ms":1768250244819,"raw":{"market":"0x2a12fd3d8235c25c062dc9652970ef9f635636c4018df0909e1a51c673e125cb","price_changes":[{"asset_id":"63670753354844494163057275310194312729998307779831462269530137743341854359908","price":"0.85","size":"0","side":"BUY","hash":"d6aab7e41dea0584d31a9ffd5f8e8fb52fd9f207","best_bid":"0.84","best_ask":"0.86"},{"asset_id":"56386988715176239099720172290594769295756680374928571099138069977179519358166","price":"0.15","size":"0","side":"SELL","hash":"c6579939a8b19093920d29e59d5d14c9ec19356b","best_bid":"0.14","best_ask":"0.16"}],"timestamp":"1768250244819","event_type":"price_change"}}
{"schema_version":1,"source":"clob_ws_market","recv_ts_ns":1768250245155539280,"event_type":"book","market":"0x2a12fd3d8235c25c062dc9652970ef9f635636c4018df0909e1a51c673e125cb","server_ts_ms":1768250244819,"raw":{"market":"0x2a12fd3d8235c25c062dc9652970ef9f635636c4018df0909e1a51c673e125cb","asset_id":"63670753354844494163057275310194312729998307779831462269530137743341854359908","bids":[{"price":"0.01","size":"10184.18"},{"price":"0.02","size":"5982"},{"price":"0.03","size":"5238.94"},{"price":"0.04","size":"5040"},{"price":"0.05","size":"5050"},{"price":"0.06","size":"5005"},{"price":"0.07","size":"5019.28"},{"price":"0.08","size":"5005"},{"price":"0.09","size":"5005"},{"price":"0.1","size":"5030"},{"price":"0.11","size":"5"},{"price":"0.12","size":"5"},{"price":"0.13","size":"5"},{"price":"0.14","size":"5"},{"price":"0.15","size":"10"},{"price":"0.16","size":"5"},{"price":"0.17","size":"5"},{"price":"0.18","size":"5"},{"price":"0.19","size":"5"},{"price":"0.2","size":"5"},{"price":"0.21","size":"5"},{"price":"0.22","size":"5"},{"price":"0.23","size":"5"},{"price":"0.24","size":"5"},{"price":"0.25","size":"10"},{"price":"0.26","size":"5"},{"price":"0.27","size":"5"},{"price":"0.28","size":"5"},{"price":"0.29","size":"15"},{"price":"0.3","size":"10"},{"price":"0.31","size":"5"},{"price":"0.32","size":"5"},{"price":"0.33","size":"5"},{"price":"0.34","size":"505"},{"price":"0.35","size":"510"},{"price":"0.36","size":"510"},{"price":"0.37","size":"505"},{"price":"0.38","size":"505"},{"price":"0.39","size":"755"},{"price":"0.4","size":"760"},{"price":"0.41","size":"916"},{"price":"0.42","size":"671"},{"price":"0.43","size":"827"},{"price":"0.44","size":"827"},{"price":"0.45","size":"817"},{"price":"0.46","size":"872"},{"price":"0.47","size":"839.65"},{"price":"0.48","size":"829"},{"price":"0.49","size":"817"},{"price":"0.5","size":"838.4"},{"price":"0.51","size":"867.58"},{"price":"0.52","size":"817"},{"price":"0.53","size":"827"},{"price":"0.54","size":"847.8"},{"price":"0.55","size":"836.09"},{"price":"0.56","size":"825"},{"price":"0.57","size":"847"},{"price":"0.58","size":"817"},{"price":"0.59","size":"817"},{"price":"0.6","size":"817"},{"price":"0.61","size":"834.5"},{"price":"0.62","size":"817"},{"price":"0.63","size":"497.49"},{"price":"0.64","size":"817"},{"price":"0.65","size":"872"},{"price":"0.66","size":"997.71"},{"price":"0.67","size":"906.8"},{"price":"0.68","size":"902"},{"price":"0.69","size":"922"},{"price":"0.7","size":"911.6"},{"price":"0.71","size":"897"},{"price":"0.72","size":"899.55"},{"price":"0.73","size":"912"},{"price":"0.74","size":"1127.65"},{"price":"0.75","size":"722.5"},{"price":"0.76","size":"924.25"},{"price":"0.77","size":"762.5"},{"price":"0.78","size":"899.5"},{"price":"0.79","size":"808.5"},{"price":"0.8","size":"814.9"},{"price":"0.81","size":"813.21"},{"price":"0.82","size":"921"},{"price":"0.83","size":"235.02"},{"price":"0.84","size":"202"}],"asks":[{"price":"0.99","size":"10331.71"},{"price":"0.98","size":"6299.77"},{"price":"0.97","size":"5625.94"},{"price":"0.96","size":"5427"},{"price":"0.95","size":"3442"},{"price":"0.94","size":"1397"},{"price":"0.93","size":"1433.78"},{"price":"0.92","size":"1471.75"},{"price":"0.91","size":"1373"},{"price":"0.9","size":"3427"},{"price":"0.89","size":"904.5"},{"price":"0.88","size":"897.75"},{"price":"0.87","size":"831"},{"price":"0.86","size":"803.29"}],"hash":"d6aab7e41dea0584d31a9ffd5f8e8fb52fd9f207","timestamp":"1768250244819","event_type":"book"}}
{"schema_version":1,"source":"clob_ws_market","recv_ts_ns":1768250245164311234,"event_type":"price_change","market":"0x2a12fd3d8235c25c062dc9652970ef9f635636c4018df0909e1a51c673e125cb","server_ts_ms":1768250244839,"raw":{"market":"0x2a12fd3d8235c25c062dc9652970ef9f635636c4018df0909e1a51c673e125cb","price_changes":[{"asset_id":"63670753354844494163057275310194312729998307779831462269530137743341854359908","price":"0.82","size":"911","side":"BUY","hash":"4b6aaa9a2fad138f4f3239a53cef911009cf4b57","best_bid":"0.84","best_ask":"0.86"},{"asset_id":"56386988715176239099720172290594769295756680374928571099138069977179519358166","price":"0.18","size":"911","side":"SELL","hash":"befd7bc4252a92e946793e188522d2ca30ef27f3","best_bid":"0.14","best_ask":"0.16"}],"timestamp":"1768250244839","event_type":"price_change"}}
{"schema_version":1,"source":"clob_ws_market","recv_ts_ns":1768250245169936153,"event_type":"best_bid_ask","market":"0x2a12fd3d8235c25c062dc9652970ef9f635636c4018df0909e1a51c673e125cb","server_ts_ms":1768250244844,"raw":{"market":"0x2a12fd3d8235c25c062dc9652970ef9f635636c4018df0909e1a51c673e125cb","asset_id":"63670753354844494163057275310194312729998307779831462269530137743341854359908","best_bid":"0.84","best_ask":"0.85","spread":"0.01","timestamp":"1768250244844","event_type":"best_bid_ask"}}
{"schema_version":1,"source":"clob_ws_market","recv_ts_ns":1768250245172643374,"event_type":"price_change","market":"0x2a12fd3d8235c25c062dc9652970ef9f635636c4018df0909e1a51c673e125cb","server_ts_ms":1768250244843,"raw":{"market":"0x2a12fd3d8235c25c062dc9652970ef9f635636c4018df0909e1a51c673e125cb","price_changes":[{"asset_id":"56386988715176239099720172290594769295756680374928571099138069977179519358166","price":"0.15","size":"13.33","side":"BUY","hash":"de459d6f6152aaf1cd7c133bc9cfae778dd82d6e","best_bid":"0.15","best_ask":"0.16"},{"asset_id":"63670753354844494163057275310194312729998307779831462269530137743341854359908","price":"0.85","size":"13.33","side":"SELL","hash":"565f8d5df4fa32ec94efc84fdbb0322a47d67502","best_bid":"0.84","best_ask":"0.85"}],"timestamp":"1768250244843","event_type":"price_change"}}
{"schema_version":1,"source":"clob_ws_market","recv_ts_ns":1768250245178158088,"event_type":"price_change","market":"0x2a12fd3d8235c25c062dc9652970ef9f635636c4018df0909e1a51c673e125cb","server_ts_ms":1768250244848,"raw":{"market":"0x2a12fd3d8235c25c062dc9652970ef9f635636c4018df0909e1a51c673e125cb","price_changes":[{"asset_id":"56386988715176239099720172290594769295756680374928571099138069977179519358166","price":"0.13","size":"825.5","side":"BUY","hash":"6cc187bbbaaf810b43bd456127438dc18102011b","best_bid":"0.15","best_ask":"0.16"},{"asset_id":"63670753354844494163057275310194312729998307779831462269530137743341854359908","price":"0.87","size":"825.5","side":"SELL","hash":"b3fdbb9bab864df927c31e2093eb470838d5bc26","best_bid":"0.84","best_ask":"0.85"}],"timestamp":"1768250244848","event_type":"price_change"}}
{"schema_version":1,"source":"clob_ws_market","recv_ts_ns":1768250245185811150,"event_type":"price_change","market":"0x2a12fd3d8235c25c062dc9652970ef9f635636c4018df0909e1a51c673e125cb","server_ts_ms":1768250244852,"raw":{"market":"0x2a12fd3d8235c25c062dc9652970ef9f635636c4018df0909e1a51c673e125cb","price_changes":[{"asset_id":"63670753354844494163057275310194312729998307779831462269530137743341854359908","price":"0.87","size":"820","side":"SELL","hash":"66316d09f05535f285065aa72355446f3ad8a3bb","best_bid":"0.84","best_ask":"0.85"},{"asset_id":"56386988715176239099720172290594769295756680374928571099138069977179519358166","price":"0.13","size":"820","side":"BUY","hash":"eb1e4a56a338df5eb699bf0447395746893aa178","best_bid":"0.15","best_ask":"0.16"}],"timestamp":"1768250244852","event_type":"price_change"}}
{"schema_version":1,"source":"clob_ws_market","recv_ts_ns":1768250245190708906,"event_type":"price_change","market":"0x2a12fd3d8235c25c062dc9652970ef9f635636c4018df0909e1a51c673e125cb","server_ts_ms":1768250244853,"raw":{"market":"0x2a12fd3d8235c25c062dc9652970ef9f635636c4018df0909e1a51c673e125cb","price_changes":[{"asset_id":"63670753354844494163057275310194312729998307779831462269530137743341854359908","price":"0.87","size":"814.5","side":"SELL","hash":"a5e28b82da1be3bd340de981522924c409b4db20","best_bid":"0.84","best_ask":"0.85"},{"asset_id":"56386988715176239099720172290594769295756680374928571099138069977179519358166","price":"0.13","size":"814.5","side":"BUY","hash":"c0ee608117b1e7caf6aa696d4f89a9a868f815c8","best_bid":"0.15","best_ask":"0.16"}],"timestamp":"1768250244853","event_type":"price_change"}}
{"schema_version":1,"source":"clob_ws_market","recv_ts_ns":1768250245201608089,"event_type":"price_change","market":"0x2a12fd3d8235c25c062dc9652970ef9f635636c4018df0909e1a51c673e125cb","server_ts_ms":1768250244854,"raw":{"market":"0x2a12fd3d8235c25c062dc9652970ef9f635636c4018df0909e1a51c673e125cb","price_changes":[{"asset_id":"56386988715176239099720172290594769295756680374928571099138069977179519358166","price":"0.13","size":"809","side":"BUY","hash":"9df494ef949e33d1899f9f476dc270d68c80ac16","best_bid":"0.15","best_ask":"0.16"},{"asset_id":"63670753354844494163057275310194312729998307779831462269530137743341854359908","price":"0.87","size":"809","side":"SELL","hash":"2f4bb836bf2910399812d97941f73f1123bd8217","best_bid":"0.84","best_ask":"0.85"}],"timestamp":"1768250244854","event_type":"price_change"}}
{"schema_version":1,"source":"clob_ws_market","recv_ts_ns":1768250245214757243,"event_type":"price_change","market":"0x2a12fd3d8235c25c062dc9652970ef9f635636c4018df0909e1a51c673e125cb","server_ts_ms":1768250244855,"raw":{"market":"0x2a12fd3d8235c25c062dc9652970ef9f635636c4018df0909e1a51c673e125cb","price_changes":[{"asset_id":"56386988715176239099720172290594769295756680374928571099138069977179519358166","price":"0.13","size":"803.5","side":"BUY","hash":"7112c7ff8e0562bae83cd53cfce09399b038a302","best_bid":"0.15","best_ask":"0.16"},{"asset_id":"63670753354844494163057275310194312729998307779831462269530137743341854359908","price":"0.87","size":"803.5","side":"SELL","hash":"fbeb4a0675a5733f9b114f96eb63b496f98a6d39","best_bid":"0.84","best_ask":"0.85"}],"timestamp":"1768250244855","event_type":"price_change"}}
{"schema_version":1,"source":"clob_ws_market","recv_ts_ns":1768250245222582427,"event_type":"price_change","market":"0x2a12fd3d8235c25c062dc9652970ef9f635636c4018df0909e1a51c673e125cb","server_ts_ms":1768250244856,"raw":{"market":"0x2a12fd3d8235c25c062dc9652970ef9f635636c4018df0909e1a51c673e125cb","price_changes":[{"asset_id":"56386988715176239099720172290594769295756680374928571099138069977179519358166","price":"0.15","size":"26.66","side":"BUY","hash":"16784f73ec6554f713b7680f8d0867b7316d45d0","best_bid":"0.15","best_ask":"0.16"},{"asset_id":"63670753354844494163057275310194312729998307779831462269530137743341854359908","price":"0.85","size":"26.66","side":"SELL","hash":"3fc4592dca0f6fadd9bd3727043fa9075d3ef02b","best_bid":"0.84","best_ask":"0.85"}],"timestamp":"1768250244856","event_type":"price_change"}}
{"schema_version":1,"source":"clob_ws_market","recv_ts_ns":1768250245231851984,"event_type":"price_change","market":"0x2a12fd3d8235c25c062dc9652970ef9f635636c4018df0909e1a51c673e125cb","server_ts_ms":1768250244862,"raw":{"market":"0x2a12fd3d8235c25c062dc9652970ef9f635636c4018df0909e1a51c673e125cb","price_changes":[{"asset_id":"56386988715176239099720172290594769295756680374928571099138069977179519358166","price":"0.14","size":"773.29","side":"BUY","hash":"6dfed4f284c6d3934ea93382ffe6796f4f52deb4","best_bid":"0.15","best_ask":"0.16"},{"asset_id":"63670753354844494163057275310194312729998307779831462269530137743341854359908","price":"0.86","size":"773.29","side":"SELL","hash":"abe07bf627191d83da0dc9bee780d5b5be9904c3","best_bid":"0.84","best_ask":"0.85"}],"timestamp":"1768250244862","event_type":"price_change"}}
{"schema_version":1,"source":"clob_ws_market","recv_ts_ns":1768250245252143530,"event_type":"price_change","market":"0x2a12fd3d8235c25c062dc9652970ef9f635636c4018df0909e1a51c673e125cb","server_ts_ms":1768250244869,"raw":{"market":"0x2a12fd3d8235c25c062dc9652970ef9f635636c4018df0909e1a51c673e125cb","price_changes":[{"asset_id":"63670753354844494163057275310194312729998307779831462269530137743341854359908","price":"0.82","size":"901","side":"BUY","hash":"a5e7b56eda656bb060936b802e94af8f421f8a96","best_bid":"0.84","best_ask":"0.85"},{"asset_id":"56386988715176239099720172290594769295756680374928571099138069977179519358166","price":"0.18","size":"901","side":"SELL","hash":"504e3e9ae49aade44b9e07c8117046ead14559f8","best_bid":"0.15","best_ask":"0.16"}],"timestamp":"1768250244869","event_type":"price_change"}}
{"schema_version":1,"source":"clob_ws_market","recv_ts_ns":1768250245254441181,"event_type":"price_change","market":"0x2a12fd3d8235c25c062dc9652970ef9f635636c4018df0909e1a51c673e125cb","server_ts_ms":1768250244871,"raw":{"market":"0x2a12fd3d8235c25c062dc9652970ef9f635636c4018df0909e1a51c673e125cb","price_changes":[{"asset_id":"56386988715176239099720172290594769295756680374928571099138069977179519358166","price":"0.14","size":"783.29","side":"BUY","hash":"5743a014e6f67bf968edf3446eab78b9f7a7620f","best_bid":"0.15","best_ask":"0.16"},{"asset_id":"63670753354844494163057275310194312729998307779831462269530137743341854359908","price":"0.86","size":"783.29","side":"SELL","hash":"0e629a6644526df94a432b83dc85d6ec8983fc4b","best_bid":"0.84","best_ask":"0.85"}],"timestamp":"1768250244871","event_type":"price_change"}}
{"schema_version":1,"source":"clob_ws_market","recv_ts_ns":1768250245257611725,"event_type":"price_change","market":"0x2a12fd3d8235c25c062dc9652970ef9f635636c4018df0909e1a51c673e125cb","server_ts_ms":1768250244882,"raw":{"market":"0x2a12fd3d8235c25c062dc9652970ef9f635636c4018df0909e1a51c673e125cb","price_changes":[{"asset_id":"56386988715176239099720172290594769295756680374928571099138069977179519358166","price":"0.15","size":"32.16","side":"BUY","hash":"cdb1ca8605aaffdb5435c02c7536c88f084618c0","best_bid":"0.15","best_ask":"0.16"},{"asset_id":"63670753354844494163057275310194312729998307779831462269530137743341854359908","price":"0.85","size":"32.16","side":"SELL","hash":"f6b0187c0728359923f170a14a34ed2b637c6b9c","best_bid":"0.84","best_ask":"0.85"}],"timestamp":"1768250244882","event_type":"price_change"}}
{"schema_version":1,"source":"clob_ws_market","recv_ts_ns":1768250245260276853,"event_type":"price_change","market":"0x2a12fd3d8235c25c062dc9652970ef9f635636c4018df0909e1a51c673e125cb","server_ts_ms":1768250244883,"raw":{"market":"0x2a12fd3d8235c25c062dc9652970ef9f635636c4018df0909e1a51c673e125cb","price_changes":[{"asset_id":"63670753354844494163057275310194312729998307779831462269530137743341854359908","price":"0.85","size":"37.66","side":"SELL","hash":"1207d0226e2f7a9625052c1052a2fa2b97dfb054","best_bid":"0.84","best_ask":"0.85"},{"asset_id":"56386988715176239099720172290594769295756680374928571099138069977179519358166","price":"0.15","size":"37.66","side":"BUY","hash":"281a9dcd11e8f5f92775774579b317839409cecf","best_bid":"0.15","best_ask":"0.16"}],"timestamp":"1768250244883","event_type":"price_change"}}
{"schema_version":1,"source":"clob_ws_market","recv_ts_ns":1768250245265135276,"event_type":"price_change","market":"0x2a12fd3d8235c25c062dc9652970ef9f635636c4018df0909e1a51c673e125cb","server_ts_ms":1768250244894,"raw":{"market":"0x2a12fd3d8235c25c062dc9652970ef9f635636c4018df0909e1a51c673e125cb","price_changes":[{"asset_id":"63670753354844494163057275310194312729998307779831462269530137743341854359908","price":"0.82","size":"1401","side":"BUY","hash":"c83fd094f14e4a76554eefd34132b2fcc6ccaa48","best_bid":"0.84","best_ask":"0.85"},{"asset_id":"56386988715176239099720172290594769295756680374928571099138069977179519358166","price":"0.18","size":"1401","side":"SELL","hash":"b30511fe6af265303f5dd142145d0de15f861acc","best_bid":"0.15","best_ask":"0.16"}],"timestamp":"1768250244894","event_type":"price_change"}}
{"schema_version":1,"source":"clob_ws_market","recv_ts_ns":1768250245268094365,"event_type":"price_change","market":"0x2a12fd3d8235c25c062dc9652970ef9f635636c4018df0909e1a51c673e125cb","server_ts_ms":1768250244895,"raw":{"market":"0x2a12fd3d8235c25c062dc9652970ef9f635636c4018df0909e1a51c673e125cb","price_changes":[{"asset_id":"63670753354844494163057275310194312729998307779831462269530137743341854359908","price":"0.84","size":"196.5","side":"BUY","hash":"4c324c1eef32e027fc8ccb059390919f77d0d0d0","best_bid":"0.84","best_ask":"0.85"},{"asset_id":"56386988715176239099720172290594769295756680374928571099138069977179519358166","price":"0.16","size":"196.5","side":"SELL","hash":"a4c7bb6a1a9b78de5193dda7546e6eb851cfa5e0","best_bid":"0.15","best_ask":"0.16"}],"timestamp":"1768250244895","event_type":"price_change"}}
{"schema_version":1,"source":"clob_ws_market","recv_ts_ns":1768250245271272548,"event_type":"price_change","market":"0x2a12fd3d8235c25c062dc9652970ef9f635636c4018df0909e1a51c673e125cb","server_ts_ms":1768250244897,"raw":{"market":"0x2a12fd3d8235c25c062dc9652970ef9f635636c4018df0909e1a51c673e125cb","price_changes":[{"asset_id":"63670753354844494163057275310194312729998307779831462269530137743341854359908","price":"0.85","size":"43.16","side":"SELL","hash":"33c54db651d0e2c71d4abba94bce7c2b48f514dd","best_bid":"0.84","best_ask":"0.85"},{"asset_id":"56386988715176239099720172290594769295756680374928571099138069977179519358166","price":"0.15","size":"43.16","side":"BUY","hash":"71f86a9c67b402c0da49b2e05ac454707ad5e383","best_bid":"0.15","best_ask":"0.16"}],"timestamp":"1768250244897","event_type":"price_change"}}
{"schema_version":1,"source":"clob_ws_market","recv_ts_ns":1768250245275418372,"event_type":"price_change","market":"0x2a12fd3d8235c25c062dc9652970ef9f635636c4018df0909e1a51c673e125cb","server_ts_ms":1768250244899,"raw":{"market":"0x2a12fd3d8235c25c062dc9652970ef9f635636c4018df0909e1a51c673e125cb","price_changes":[{"asset_id":"63670753354844494163057275310194312729998307779831462269530137743341854359908","price":"0.85","size":"48.66","side":"SELL","hash":"3ef0d173f18c23695cde5169a496ad70e0e4466f","best_bid":"0.84","best_ask":"0.85"},{"asset_id":"56386988715176239099720172290594769295756680374928571099138069977179519358166","price":"0.15","size":"48.66","side":"BUY","hash":"574fe7f6bf155bb479259f4687a6a3ebb4d12644","best_bid":"0.15","best_ask":"0.16"}],"timestamp":"1768250244899","event_type":"price_change"}}
{"schema_version":1,"source":"clob_ws_market","recv_ts_ns":1768250245293080558,"event_type":"price_change","market":"0x2a12fd3d8235c25c062dc9652970ef9f635636c4018df0909e1a51c673e125cb","server_ts_ms":1768250244933,"raw":{"market":"0x2a12fd3d8235c25c062dc9652970ef9f635636c4018df0909e1a51c673e125cb","price_changes":[{"asset_id":"63670753354844494163057275310194312729998307779831462269530137743341854359908","price":"0.85","size":"54.16","side":"SELL","hash":"6b62af9b11192078767706d002863d415d69027d","best_bid":"0.84","best_ask":"0.85"},{"asset_id":"56386988715176239099720172290594769295756680374928571099138069977179519358166","price":"0.15","size":"54.16","side":"BUY","hash":"6e922715de5811fdc0fd44531f966a1cafd1fe5d","best_bid":"0.15","best_ask":"0.16"}],"timestamp":"1768250244933","event_type":"price_change"}}
{"schema_version":1,"source":"clob_ws_market","recv_ts_ns":1768250245298134345,"event_type":"price_change","market":"0x2a12fd3d8235c25c062dc9652970ef9f635636c4018df0909e1a51c673e125cb","server_ts_ms":1768250244943,"raw":{"market":"0x2a12fd3d8235c25c062dc9652970ef9f635636c4018df0909e1a51c673e125cb","price_changes":[{"asset_id":"63670753354844494163057275310194312729998307779831462269530137743341854359908","price":"0.81","size":"723.21","side":"BUY","hash":"c70c51552cf4694a967e388f0b38624196195f12","best_bid":"0.84","best_ask":"0.85"},{"asset_id":"56386988715176239099720172290594769295756680374928571099138069977179519358166","price":"0.19","size":"723.21","side":"SELL","hash":"4f626a25ff3c4bcd3049bfd7bb2853c3631795a9","best_bid":"0.15","best_ask":"0.16"}],"timestamp":"1768250244943","event_type":"price_change"}}
{"schema_version":1,"source":"clob_ws_market","recv_ts_ns":1768250245303087410,"event_type":"price_change","market":"0x2a12fd3d8235c25c062dc9652970ef9f635636c4018df0909e1a51c673e125cb","server_ts_ms":1768250244944,"raw":{"market":"0x2a12fd3d8235c25c062dc9652970ef9f635636c4018df0909e1a51c673e125cb","price_changes":[{"asset_id":"63670753354844494163057275310194312729998307779831462269530137743341854359908","price":"0.83","size":"245.02","side":"BUY","hash":"b05cbf2318e2e3af5a243d41b185345579d06133","best_bid":"0.84","best_ask":"0.85"},{"asset_id":"56386988715176239099720172290594769295756680374928571099138069977179519358166","price":"0.17","size":"245.02","side":"SELL","hash":"0fe88da647fc750195e5e072cee5284e4e120e06","best_bid":"0.15","best_ask":"0.16"}],"timestamp":"1768250244944","event_type":"price_change"}}
{"schema_version":1,"source":"clob_ws_market","recv_ts_ns":1768250245308927692,"event_type":"price_change","market":"0x2a12fd3d8235c25c062dc9652970ef9f635636c4018df0909e1a51c673e125cb","server_ts_ms":1768250244949,"raw":{"market":"0x2a12fd3d8235c25c062dc9652970ef9f635636c4018df0909e1a51c673e125cb","price_changes":[{"asset_id":"63670753354844494163057275310194312729998307779831462269530137743341854359908","price":"0.83","size":"255.02","side":"BUY","hash":"ef65621ebb559996bd9cbb3ccb3e5a004321e02a","best_bid":"0.84","best_ask":"0.85"},{"asset_id":"56386988715176239099720172290594769295756680374928571099138069977179519358166","price":"0.17","size":"255.02","side":"SELL","hash":"2a0a164dccff95a7155a72ebd3025ed88bdb49a7","best_bid":"0.15","best_ask":"0.16"}],"timestamp":"1768250244949","event_type":"price_change"}}
{"schema_version":1,"source":"clob_ws_market","recv_ts_ns":1768250245313111010,"event_type":"price_change","market":"0x2a12fd3d8235c25c062dc9652970ef9f635636c4018df0909e1a51c673e125cb","server_ts_ms":1768250244965,"raw":{"market":"0x2a12fd3d8235c25c062dc9652970ef9f635636c4018df0909e1a51c673e125cb","price_changes":[{"asset_id":"63670753354844494163057275310194312729998307779831462269530137743341854359908","price":"0.83","size":"260.52","side":"BUY","hash":"9178d7ad2c1006de3e00b637d88ada415aebbe2e","best_bid":"0.84","best_ask":"0.85"},{"asset_id":"56386988715176239099720172290594769295756680374928571099138069977179519358166","price":"0.17","size":"260.52","side":"SELL","hash":"bfcc41dfcc5dd2eaad99c387cd10a8899c4162fd","best_bid":"0.15","best_ask":"0.16"}],"timestamp":"1768250244965","event_type":"price_change"}}
{"schema_version":1,"source":"clob_ws_market","recv_ts_ns":1768250245317923933,"event_type":"price_change","market":"0x2a12fd3d8235c25c062dc9652970ef9f635636c4018df0909e1a51c673e125cb","server_ts_ms":1768250244966,"raw":{"market":"0x2a12fd3d8235c25c062dc9652970ef9f635636c4018df0909e1a51c673e125cb","price_changes":[{"asset_id":"56386988715176239099720172290594769295756680374928571099138069977179519358166","price":"0.14","size":"793.29","side":"BUY","hash":"b2514418a2ae5fcc0b3466dce49c7a2ad3ed5275","best_bid":"0.15","best_ask":"0.16"},{"asset_id":"63670753354844494163057275310194312729998307779831462269530137743341854359908","price":"0.86","size":"793.29","side":"SELL","hash":"89650dc2350d1e6e386db9d8111838008b2b472d","best_bid":"0.84","best_ask":"0.85"}],"timestamp":"1768250244966","event_type":"price_change"}}
{"schema_version":1,"source":"clob_ws_market","recv_ts_ns":1768250245324607878,"event_type":"best_bid_ask","market":"0x2a12fd3d8235c25c062dc9652970ef9f635636c4018df0909e1a51c673e125cb","server_ts_ms":1768250244973,"raw":{"market":"0x2a12fd3d8235c25c062dc9652970ef9f635636c4018df0909e1a51c673e125cb","asset_id":"63670753354844494163057275310194312729998307779831462269530137743341854359908","best_bid":"0.84","best_ask":"0.85","spread":"0.01","timestamp":"1768250244973","event_type":"best_bid_ask"}}
{"schema_version":1,"source":"clob_ws_market","recv_ts_ns":1768250245326924384,"event_type":"price_change","market":"0x2a12fd3d8235c25c062dc9652970ef9f635636c4018df0909e1a51c673e125cb","server_ts_ms":1768250244972,"raw":{"market":"0x2a12fd3d8235c25c062dc9652970ef9f635636c4018df0909e1a51c673e125cb","price_changes":[{"asset_id":"56386988715176239099720172290594769295756680374928571099138069977179519358166","price":"0.15","size":"45.92","side":"BUY","hash":"1143f7395f13731a88de45572cc35941e8fef028","best_bid":"0.15","best_ask":"0.16"},{"asset_id":"63670753354844494163057275310194312729998307779831462269530137743341854359908","price":"0.85","size":"45.92","side":"SELL","hash":"f55b93c18dca8462f55f313fef3bfe0293301800","best_bid":"0.84","best_ask":"0.85"}],"timestamp":"1768250244972","event_type":"price_change"}}
{"schema_version":1,"source":"clob_ws_market","recv_ts_ns":1768250245337867321,"event_type":"book","market":"0x2a12fd3d8235c25c062dc9652970ef9f635636c4018df0909e1a51c673e125cb","server_ts_ms":1768250244972,"raw":{"market":"0x2a12fd3d8235c25c062dc9652970ef9f635636c4018df0909e1a51c673e125cb","asset_id":"63670753354844494163057275310194312729998307779831462269530137743341854359908","bids":[{"price":"0.01","size":"10184.18"},{"price":"0.02","size":"5982"},{"price":"0.03","size":"5238.94"},{"price":"0.04","size":"5040"},{"price":"0.05","size":"5050"},{"price":"0.06","size":"5005"},{"price":"0.07","size":"5019.28"},{"price":"0.08","size":"5005"},{"price":"0.09","size":"5005"},{"price":"0.1","size":"5030"},{"price":"0.11","size":"5"},{"price":"0.12","size":"5"},{"price":"0.13","size":"5"},{"price":"0.14","size":"5"},{"price":"0.15","size":"10"},{"price":"0.16","size":"5"},{"price":"0.17","size":"5"},{"price":"0.18","size":"5"},{"price":"0.19","size":"5"},{"price":"0.2","size":"5"},{"price":"0.21","size":"5"},{"price":"0.22","size":"5"},{"price":"0.23","size":"5"},{"price":"0.24","size":"5"},{"price":"0.25","size":"10"},{"price":"0.26","size":"5"},{"price":"0.27","size":"5"},{"price":"0.28","size":"5"},{"price":"0.29","size":"15"},{"price":"0.3","size":"10"},{"price":"0.31","size":"5"},{"price":"0.32","size":"5"},{"price":"0.33","size":"5"},{"price":"0.34","size":"505"},{"price":"0.35","size":"510"},{"price":"0.36","size":"510"},{"price":"0.37","size":"505"},{"price":"0.38","size":"505"},{"price":"0.39","size":"755"},{"price":"0.4","size":"760"},{"price":"0.41","size":"916"},{"price":"0.42","size":"671"},{"price":"0.43","size":"827"},{"price":"0.44","size":"827"},{"price":"0.45","size":"817"},{"price":"0.46","size":"872"},{"price":"0.47","size":"839.65"},{"price":"0.48","size":"829"},{"price":"0.49","size":"817"},{"price":"0.5","size":"838.4"},{"price":"0.51","size":"867.58"},{"price":"0.52","size":"817"},{"price":"0.53","size":"827"},{"price":"0.54","size":"847.8"},{"price":"0.55","size":"836.09"},{"price":"0.56","size":"825"},{"price":"0.57","size":"847"},{"price":"0.58","size":"817"},{"price":"0.59","size":"817"},{"price":"0.6","size":"817"},{"price":"0.61","size":"834.5"},{"price":"0.62","size":"817"},{"price":"0.63","size":"497.49"},{"price":"0.64","size":"817"},{"price":"0.65","size":"872"},{"price":"0.66","size":"997.71"},{"price":"0.67","size":"906.8"},{"price":"0.68","size":"902"},{"price":"0.69","size":"922"},{"price":"0.7","size":"911.6"},{"price":"0.71","size":"897"},{"price":"0.72","size":"899.55"},{"price":"0.73","size":"912"},{"price":"0.74","size":"1127.65"},{"price":"0.75","size":"722.5"},{"price":"0.76","size":"924.25"},{"price":"0.77","size":"762.5"},{"price":"0.78","size":"899.5"},{"price":"0.79","size":"808.5"},{"price":"0.8","size":"814.9"},{"price":"0.81","size":"723.21"},{"price":"0.82","size":"1401"},{"price":"0.83","size":"260.52"},{"price":"0.84","size":"196.5"}],"asks":[{"price":"0.99","size":"10331.71"},{"price":"0.98","size":"6299.77"},{"price":"0.97","size":"5625.94"},{"price":"0.96","size":"5427"},{"price":"0.95","size":"3442"},{"price":"0.94","size":"1397"},{"price":"0.93","size":"1433.78"},{"price":"0.92","size":"1471.75"},{"price":"0.91","size":"1373"},{"price":"0.9","size":"3427"},{"price":"0.89","size":"904.5"},{"price":"0.88","size":"897.75"},{"price":"0.87","size":"803.5"},{"price":"0.86","size":"793.29"},{"price":"0.85","size":"45.92"}],"hash":"f55b93c18dca8462f55f313fef3bfe0293301800","timestamp":"1768250244972","event_type":"book"}}
{"schema_version":1,"source":"clob_ws_market","recv_ts_ns":1768250245344673213,"event_type":"price_change","market":"0x2a12fd3d8235c25c062dc9652970ef9f635636c4018df0909e1a51c673e125cb","server_ts_ms":1768250244987,"raw":{"market":"0x2a12fd3d8235c25c062dc9652970ef9f635636c4018df0909e1a51c673e125cb","price_changes":[{"asset_id":"63670753354844494163057275310194312729998307779831462269530137743341854359908","price":"0.82","size":"1491","side":"BUY","hash":"c3e38b6a8e7cfaea4941ad878c1a31b4ffa9ae61","best_bid":"0.84","best_ask":"0.85"},{"asset_id":"56386988715176239099720172290594769295756680374928571099138069977179519358166","price":"0.18","size":"1491","side":"SELL","hash":"36ad21ae6aaa1d1ac38275d5ebbb834baf1d2a0f","best_bid":"0.15","best_ask":"0.16"}],"timestamp":"1768250244987","event_type":"price_change"}}
{"schema_version":1,"source":"clob_ws_market","recv_ts_ns":1768250245358182280,"event_type":"last_trade_price","market":"0x2a12fd3d8235c25c062dc9652970ef9f635636c4018df0909e1a51c673e125cb","server_ts_ms":1768250245004,"raw":{"market":"0x2a12fd3d8235c25c062dc9652970ef9f635636c4018df0909e1a51c673e125cb","asset_id":"63670753354844494163057275310194312729998307779831462269530137743341854359908","price":"0.85","size":"8.235293","fee_rate_bps":"1000","side":"BUY","timestamp":"1768250245004","event_type":"last_trade_price","transaction_hash":"0x513ac8e412b081493424964cef3ef7a0caa3d371e29b44c21425f93acf92caf9"}}
{"schema_version":1,"source":"clob_ws_market","recv_ts_ns":1768250245388768516,"event_type":"price_change","market":"0x2a12fd3d8235c25c062dc9652970ef9f635636c4018df0909e1a51c673e125cb","server_ts_ms":1768250245064,"raw":{"market":"0x2a12fd3d8235c25c062dc9652970ef9f635636c4018df0909e1a51c673e125cb","price_changes":[{"asset_id":"56386988715176239099720172290594769295756680374928571099138069977179519358166","price":"0.14","size":"783.29","side":"BUY","hash":"2a43506574f8eab25883ba6e7d8b464a4d2239d5","best_bid":"0.15","best_ask":"0.16"},{"asset_id":"63670753354844494163057275310194312729998307779831462269530137743341854359908","price":"0.86","size":"783.29","side":"SELL","hash":"838c5b9ee10983dcc4750dfac15a31fbc2d96ebd","best_bid":"0.84","best_ask":"0.85"}],"timestamp":"1768250245064","event_type":"price_change"}}
{"schema_version":1,"source":"clob_ws_market","recv_ts_ns":1768250245393400978,"event_type":"price_change","market":"0x2a12fd3d8235c25c062dc9652970ef9f635636c4018df0909e1a51c673e125cb","server_ts_ms":1768250245065,"raw":{"market":"0x2a12fd3d8235c25c062dc9652970ef9f635636c4018df0909e1a51c673e125cb","price_changes":[{"asset_id":"56386988715176239099720172290594769295756680374928571099138069977179519358166","price":"0.15","size":"55.92","side":"BUY","hash":"f2feb00634fd51ceb557c9192a7c47d97b3b8972","best_bid":"0.15","best_ask":"0.16"},{"asset_id":"63670753354844494163057275310194312729998307779831462269530137743341854359908","price":"0.85","size":"55.92","side":"SELL","hash":"29a731bd8a5e9c65f30cff469ee4e509526f832f","best_bid":"0.84","best_ask":"0.85"}],"timestamp":"1768250245065","event_type":"price_change"}}
{"schema_version":1,"source":"clob_ws_market","recv_ts_ns":1768250245418588599,"event_type":"price_change","market":"0x2a12fd3d8235c25c062dc9652970ef9f635636c4018df0909e1a51c673e125cb","server_ts_ms":1768250245089,"raw":{"market":"0x2a12fd3d8235c25c062dc9652970ef9f635636c4018df0909e1a51c673e125cb","price_changes":[{"asset_id":"63670753354844494163057275310194312729998307779831462269530137743341854359908","price":"0.83","size":"270.52","side":"BUY","hash":"877dea2f622676783375ee5f95ffe7244382a7c9","best_bid":"0.84","best_ask":"0.85"},{"asset_id":"56386988715176239099720172290594769295756680374928571099138069977179519358166","price":"0.17","size":"270.52","side":"SELL","hash":"e3f7a7009e33a894c52888ced32a619fdac794af","best_bid":"0.15","best_ask":"0.16"}],"timestamp":"1768250245089","event_type":"price_change"}}
{"schema_version":1,"source":"clob_ws_market","recv_ts_ns":1768250245423203353,"event_type":"price_change","market":"0x2a12fd3d8235c25c062dc9652970ef9f635636c4018df0909e1a51c673e125cb","server_ts_ms":1768250245091,"raw":{"market":"0x2a12fd3d8235c25c062dc9652970ef9f635636c4018df0909e1a51c673e125cb","price_changes":[{"asset_id":"63670753354844494163057275310194312729998307779831462269530137743341854359908","price":"0.84","size":"186.5","side":"BUY","hash":"d9afd1e70e54324bcd3124be49c243be7b61f6b9","best_bid":"0.84","best_ask":"0.85"},{"asset_id":"56386988715176239099720172290594769295756680374928571099138069977179519358166","price":"0.16","size":"186.5","side":"SELL","hash":"36cf664c560aaad6938add517a19b3211138ecb8","best_bid":"0.15","best_ask":"0.16"}],"timestamp":"1768250245091","event_type":"price_change"}}
{"schema_version":1,"source":"clob_ws_market","recv_ts_ns":1768250245473114133,"event_type":"price_change","market":"0x2a12fd3d8235c25c062dc9652970ef9f635636c4018df0909e1a51c673e125cb","server_ts_ms":1768250245134,"raw":{"market":"0x2a12fd3d8235c25c062dc9652970ef9f635636c4018df0909e1a51c673e125cb","price_changes":[{"asset_id":"63670753354844494163057275310194312729998307779831462269530137743341854359908","price":"0.85","size":"50.42","side":"SELL","hash":"0de985ea49a765d90b7c6bb13722ce2021b7f74f","best_bid":"0.84","best_ask":"0.85"},{"asset_id":"56386988715176239099720172290594769295756680374928571099138069977179519358166","price":"0.15","size":"50.42","side":"BUY","hash":"290bee34232f4982f220600a18b227d8ca088c19","best_bid":"0.15","best_ask":"0.16"}],"timestamp":"1768250245134","event_type":"price_change"}}
{"schema_version":1,"source":"clob_ws_market","recv_ts_ns":1768250245480904133,"event_type":"price_change","market":"0x2a12fd3d8235c25c062dc9652970ef9f635636c4018df0909e1a51c673e125cb","server_ts_ms":1768250245150,"raw":{"market":"0x2a12fd3d8235c25c062dc9652970ef9f635636c4018df0909e1a51c673e125cb","price_changes":[{"asset_id":"63670753354844494163057275310194312729998307779831462269530137743341854359908","price":"0.85","size":"44.92","side":"SELL","hash":"98af4713e1a4c949dc51da6fa59c12c94175931d","best_bid":"0.84","best_ask":"0.85"},{"asset_id":"56386988715176239099720172290594769295756680374928571099138069977179519358166","price":"0.15","size":"44.92","side":"BUY","hash":"252796836275c853d6884c77553b83ca06946a4e","best_bid":"0.15","best_ask":"0.16"}],"timestamp":"1768250245150","event_type":"price_change"}}
{"schema_version":1,"source":"clob_ws_market","recv_ts_ns":1768250245485213146,"event_type":"price_change","market":"0x2a12fd3d8235c25c062dc9652970ef9f635636c4018df0909e1a51c673e125cb","server_ts_ms":1768250245151,"raw":{"market":"0x2a12fd3d8235c25c062dc9652970ef9f635636c4018df0909e1a51c673e125cb","price_changes":[{"asset_id":"56386988715176239099720172290594769295756680374928571099138069977179519358166","price":"0.15","size":"39.42","side":"BUY","hash":"2256eb6f43221d570f5c32397a55a9b512a1ea19","best_bid":"0.15","best_ask":"0.16"},{"asset_id":"63670753354844494163057275310194312729998307779831462269530137743341854359908","price":"0.85","size":"39.42","side":"SELL","hash":"86843dda67d3c6d9fb4331ba973aec5c1cea0f9f","best_bid":"0.84","best_ask":"0.85"}],"timestamp":"1768250245151","event_type":"price_change"}}
{"schema_version":1,"source":"clob_ws_market","recv_ts_ns":1768250245494467921,"event_type":"price_change","market":"0x2a12fd3d8235c25c062dc9652970ef9f635636c4018df0909e1a51c673e125cb","server_ts_ms":1768250245160,"raw":{"market":"0x2a12fd3d8235c25c062dc9652970ef9f635636c4018df0909e1a51c673e125cb","price_changes":[{"asset_id":"63670753354844494163057275310194312729998307779831462269530137743341854359908","price":"0.85","size":"33.92","side":"SELL","hash":"332739a76920c273ed9caa8c01554d791fad2d29","best_bid":"0.84","best_ask":"0.85"},{"asset_id":"56386988715176239099720172290594769295756680374928571099138069977179519358166","price":"0.15","size":"33.92","side":"BUY","hash":"48d9b70a3ea7d17ee9fba5b7f47ae1f2030a5ed8","best_bid":"0.15","best_ask":"0.16"}],"timestamp":"1768250245160","event_type":"price_change"}}
{"schema_version":1,"source":"clob_ws_market","recv_ts_ns":1768250245498667917,"event_type":"price_change","market":"0x2a12fd3d8235c25c062dc9652970ef9f635636c4018df0909e1a51c673e125cb","server_ts_ms":1768250245163,"raw":{"market":"0x2a12fd3d8235c25c062dc9652970ef9f635636c4018df0909e1a51c673e125cb","price_changes":[{"asset_id":"63670753354844494163057275310194312729998307779831462269530137743341854359908","price":"0.85","size":"28.42","side":"SELL","hash":"8218e6e70b9e96a4eba13bb0d27f73b5a9e7e899","best_bid":"0.84","best_ask":"0.85"},{"asset_id":"56386988715176239099720172290594769295756680374928571099138069977179519358166","price":"0.15","size":"28.42","side":"BUY","hash":"19ace32454db0a41eaff87d5f59a8a676aaa9913","best_bid":"0.15","best_ask":"0.16"}],"timestamp":"1768250245163","event_type":"price_change"}}
{"schema_version":1,"source":"clob_ws_market","recv_ts_ns":1768250245501825528,"event_type":"price_change","market":"0x2a12fd3d8235c25c062dc9652970ef9f635636c4018df0909e1a51c673e125cb","server_ts_ms":1768250245179,"raw":{"market":"0x2a12fd3d8235c25c062dc9652970ef9f635636c4018df0909e1a51c673e125cb","price_changes":[{"asset_id":"63670753354844494163057275310194312729998307779831462269530137743341854359908","price":"0.86","size":"788.79","side":"SELL","hash":"48950d0fc0c16ab7e9ca8d8dc419dd7e683b6207","best_bid":"0.84","best_ask":"0.85"},{"asset_id":"56386988715176239099720172290594769295756680374928571099138069977179519358166","price":"0.14","size":"788.79","side":"BUY","hash":"3e3ed16d9f6141608a3decaeb9e886aa1be887bc","best_bid":"0.15","best_ask":"0.16"}],"timestamp":"1768250245179","event_type":"price_change"}}
{"schema_version":1,"source":"clob_ws_market","recv_ts_ns":1768250245506566516,"event_type":"price_change","market":"0x2a12fd3d8235c25c062dc9652970ef9f635636c4018df0909e1a51c673e125cb","server_ts_ms":1768250245184,"raw":{"market":"0x2a12fd3d8235c25c062dc9652970ef9f635636c4018df0909e1a51c673e125cb","price_changes":[{"asset_id":"63670753354844494163057275310194312729998307779831462269530137743341854359908","price":"0.86","size":"794.29","side":"SELL","hash":"35bceddb020c8e3cdaa9c2b42227a11ec4863a03","best_bid":"0.84","best_ask":"0.85"},{"asset_id":"56386988715176239099720172290594769295756680374928571099138069977179519358166","price":"0.14","size":"794.29","side":"BUY","hash":"0fde70d21862ac36b1a51ba9dfaf0ac423b78521","best_bid":"0.15","best_ask":"0.16"}],"timestamp":"1768250245184","event_type":"price_change"}}
{"schema_version":1,"source":"clob_ws_market","recv_ts_ns":1768250245510578186,"event_type":"price_change","market":"0x2a12fd3d8235c25c062dc9652970ef9f635636c4018df0909e1a51c673e125cb","server_ts_ms":1768250245191,"raw":{"market":"0x2a12fd3d8235c25c062dc9652970ef9f635636c4018df0909e1a51c673e125cb","price_changes":[{"asset_id":"63670753354844494163057275310194312729998307779831462269530137743341854359908","price":"0.86","size":"799.79","side":"SELL","hash":"7175a2168957c07d1876a263938a594d9919b568","best_bid":"0.84","best_ask":"0.85"},{"asset_id":"56386988715176239099720172290594769295756680374928571099138069977179519358166","price":"0.14","size":"799.79","side":"BUY","hash":"78fec31e9d904e65f65d6cb4c3f4e7dc852ee417","best_bid":"0.15","best_ask":"0.16"}],"timestamp":"1768250245191","event_type":"price_change"}}
{"schema_version":1,"source":"clob_ws_market","recv_ts_ns":1768250245514897746,"event_type":"price_change","market":"0x2a12fd3d8235c25c062dc9652970ef9f635636c4018df0909e1a51c673e125cb","server_ts_ms":1768250245192,"raw":{"market":"0x2a12fd3d8235c25c062dc9652970ef9f635636c4018df0909e1a51c673e125cb","price_changes":[{"asset_id":"56386988715176239099720172290594769295756680374928571099138069977179519358166","price":"0.08","size":"1546.75","side":"BUY","hash":"b1f3be103eb6cd921025bbf5e72a8f8b794c43be","best_bid":"0.15","best_ask":"0.16"},{"asset_id":"63670753354844494163057275310194312729998307779831462269530137743341854359908","price":"0.92","size":"1546.75","side":"SELL","hash":"70aaadfb25ee63d039225a5b44f87f4da83c354c","best_bid":"0.84","best_ask":"0.85"}],"timestamp":"1768250245192","event_type":"price_change"}}
{"schema_version":1,"source":"clob_ws_market","recv_ts_ns":1768250245518837493,"event_type":"price_change","market":"0x2a12fd3d8235c25c062dc9652970ef9f635636c4018df0909e1a51c673e125cb","server_ts_ms":1768250245193,"raw":{"market":"0x2a12fd3d8235c25c062dc9652970ef9f635636c4018df0909e1a51c673e125cb","price_changes":[{"asset_id":"56386988715176239099720172290594769295756680374928571099138069977179519358166","price":"0.14","size":"805.29","side":"BUY","hash":"492305e28057a6b7cfc605c63ea85be3e220a5f0","best_bid":"0.15","best_ask":"0.16"},{"asset_id":"63670753354844494163057275310194312729998307779831462269530137743341854359908","price":"0.86","size":"805.29","side":"SELL","hash":"fa723d2f5befafae33a9b122eb27e9cb08378371","best_bid":"0.84","best_ask":"0.85"}],"timestamp":"1768250245193","event_type":"price_change"}}
{"schema_version":1,"source":"clob_ws_market","recv_ts_ns":1768250245523279820,"event_type":"price_change","market":"0x2a12fd3d8235c25c062dc9652970ef9f635636c4018df0909e1a51c673e125cb","server_ts_ms":1768250245212,"raw":{"market":"0x2a12fd3d8235c25c062dc9652970ef9f635636c4018df0909e1a51c673e125cb","price_changes":[{"asset_id":"63670753354844494163057275310194312729998307779831462269530137743341854359908","price":"0.86","size":"810.79","side":"SELL","hash":"3cd5b026bca7ff4ed60d1d15cb713f39935e8a2f","best_bid":"0.84","best_ask":"0.85"},{"asset_id":"56386988715176239099720172290594769295756680374928571099138069977179519358166","price":"0.14","size":"810.79","side":"BUY","hash":"7a8e9d7b41d1154862fa8dc8b4c8b817028bbdeb","best_bid":"0.15","best_ask":"0.16"}],"timestamp":"1768250245212","event_type":"price_change"}}
{"schema_version":1,"source":"clob_ws_market","recv_ts_ns":1768250245531343127,"event_type":"best_bid_ask","market":"0x2a12fd3d8235c25c062dc9652970ef9f635636c4018df0909e1a51c673e125cb","server_ts_ms":1768250245235,"raw":{"market":"0x2a12fd3d8235c25c062dc9652970ef9f635636c4018df0909e1a51c673e125cb","asset_id":"63670753354844494163057275310194312729998307779831462269530137743341854359908","best_bid":"0.84","best_ask":"0.85","spread":"0.01","timestamp":"1768250245235","event_type":"best_bid_ask"}}
{"schema_version":1,"source":"clob_ws_market","recv_ts_ns":1768250245534141985,"event_type":"price_change","market":"0x2a12fd3d8235c25c062dc9652970ef9f635636c4018df0909e1a51c673e125cb","server_ts_ms":1768250245233,"raw":{"market":"0x2a12fd3d8235c25c062dc9652970ef9f635636c4018df0909e1a51c673e125cb","price_changes":[{"asset_id":"63670753354844494163057275310194312729998307779831462269530137743341854359908","price":"0.84","size":"146.5","side":"BUY","hash":"bdbe17bc10c7a62e6c7a7e2f102ab313ea6ccec9","best_bid":"0.84","best_ask":"0.85"},{"asset_id":"56386988715176239099720172290594769295756680374928571099138069977179519358166","price":"0.16","size":"146.5","side":"SELL","hash":"dca95d9f92f97b2f15a57ccabbdcdf1dc0d58ee5","best_bid":"0.15","best_ask":"0.16"}],"timestamp":"1768250245233","event_type":"price_change"}}
{"schema_version":1,"source":"clob_ws_market","recv_ts_ns":1768250245538810549,"event_type":"price_change","market":"0x2a12fd3d8235c25c062dc9652970ef9f635636c4018df0909e1a51c673e125cb","server_ts_ms":1768250245233,"raw":{"market":"0x2a12fd3d8235c25c062dc9652970ef9f635636c4018df0909e1a51c673e125cb","price_changes":[{"asset_id":"56386988715176239099720172290594769295756680374928571099138069977179519358166","price":"0.16","size":"146.5","side":"SELL","hash":"dca95d9f92f97b2f15a57ccabbdcdf1dc0d58ee5","best_bid":"0.15","best_ask":"0.16"},{"asset_id":"63670753354844494163057275310194312729998307779831462269530137743341854359908","price":"0.84","size":"146.5","side":"BUY","hash":"bdbe17bc10c7a62e6c7a7e2f102ab313ea6ccec9","best_bid":"0.84","best_ask":"0.85"}],"timestamp":"1768250245233","event_type":"price_change"}}
{"schema_version":1,"source":"clob_ws_market","recv_ts_ns":1768250245554809903,"event_type":"book","market":"0x2a12fd3d8235c25c062dc9652970ef9f635636c4018df0909e1a51c673e125cb","server_ts_ms":1768250245233,"raw":{"market":"0x2a12fd3d8235c25c062dc9652970ef9f635636c4018df0909e1a51c673e125cb","asset_id":"63670753354844494163057275310194312729998307779831462269530137743341854359908","bids":[{"price":"0.01","size":"10184.18"},{"price":"0.02","size":"5982"},{"price":"0.03","size":"5238.94"},{"price":"0.04","size":"5040"},{"price":"0.05","size":"5050"},{"price":"0.06","size":"5005"},{"price":"0.07","size":"5019.28"},{"price":"0.08","size":"5005"},{"price":"0.09","size":"5005"},{"price":"0.1","size":"5030"},{"price":"0.11","size":"5"},{"price":"0.12","size":"5"},{"price":"0.13","size":"5"},{"price":"0.14","size":"5"},{"price":"0.15","size":"10"},{"price":"0.16","size":"5"},{"price":"0.17","size":"5"},{"price":"0.18","size":"5"},{"price":"0.19","size":"5"},{"price":"0.2","size":"5"},{"price":"0.21","size":"5"},{"price":"0.22","size":"5"},{"price":"0.23","size":"5"},{"price":"0.24","size":"5"},{"price":"0.25","size":"10"},{"price":"0.26","size":"5"},{"price":"0.27","size":"5"},{"price":"0.28","size":"5"},{"price":"0.29","size":"15"},{"price":"0.3","size":"10"},{"price":"0.31","size":"5"},{"price":"0.32","size":"5"},{"price":"0.33","size":"5"},{"price":"0.34","size":"505"},{"price":"0.35","size":"510"},{"price":"0.36","size":"510"},{"price":"0.37","size":"505"},{"price":"0.38","size":"505"},{"price":"0.39","size":"755"},{"price":"0.4","size":"760"},{"price":"0.41","size":"916"},{"price":"0.42","size":"671"},{"price":"0.43","size":"827"},{"price":"0.44","size":"827"},{"price":"0.45","size":"817"},{"price":"0.46","size":"872"},{"price":"0.47","size":"839.65"},{"price":"0.48","size":"829"},{"price":"0.49","size":"817"},{"price":"0.5","size":"838.4"},{"price":"0.51","size":"867.58"},{"price":"0.52","size":"817"},{"price":"0.53","size":"827"},{"price":"0.54","size":"847.8"},{"price":"0.55","size":"836.09"},{"price":"0.56","size":"825"},{"price":"0.57","size":"847"},{"price":"0.58","size":"817"},{"price":"0.59","size":"817"},{"price":"0.6","size":"817"},{"price":"0.61","size":"834.5"},{"price":"0.62","size":"817"},{"price":"0.63","size":"497.49"},{"price":"0.64","size":"817"},{"price":"0.65","size":"872"},{"price":"0.66","size":"997.71"},{"price":"0.67","size":"906.8"},{"price":"0.68","size":"902"},{"price":"0.69","size":"922"},{"price":"0.7","size":"911.6"},{"price":"0.71","size":"897"},{"price":"0.72","size":"899.55"},{"price":"0.73","size":"912"},{"price":"0.74","size":"1127.65"},{"price":"0.75","size":"722.5"},{"price":"0.76","size":"924.25"},{"price":"0.77","size":"762.5"},{"price":"0.78","size":"899.5"},{"price":"0.79","size":"808.5"},{"price":"0.8","size":"814.9"},{"price":"0.81","size":"723.21"},{"price":"0.82","size":"1491"},{"price":"0.83","size":"270.52"},{"price":"0.84","size":"146.5"}],"asks":[{"price":"0.99","size":"10331.71"},{"price":"0.98","size":"6299.77"},{"price":"0.97","size":"5625.94"},{"price":"0.96","size":"5427"},{"price":"0.95","size":"3442"},{"price":"0.94","size":"1397"},{"price":"0.93","size":"1433.78"},{"price":"0.92","size":"1546.75"},{"price":"0.91","size":"1373"},{"price":"0.9","size":"3427"},{"price":"0.89","size":"904.5"},{"price":"0.88","size":"897.75"},{"price":"0.87","size":"803.5"},{"price":"0.86","size":"810.79"},{"price":"0.85","size":"28.42"}],"hash":"bdbe17bc10c7a62e6c7a7e2f102ab313ea6ccec9","timestamp":"1768250245233","event_type":"book"}}
{"schema_version":1,"source":"clob_ws_market","recv_ts_ns":1768250245562929189,"event_type":"last_trade_price","market":"0x2a12fd3d8235c25c062dc9652970ef9f635636c4018df0909e1a51c673e125cb","server_ts_ms":1768250245263,"raw":{"market":"0x2a12fd3d8235c25c062dc9652970ef9f635636c4018df0909e1a51c673e125cb","asset_id":"63670753354844494163057275310194312729998307779831462269530137743341854359908","price":"0.84","size":"40","fee_rate_bps":"1000","side":"SELL","timestamp":"1768250245263","event_type":"last_trade_price","transaction_hash":"0x811e0aee6fed5564708222f7cbb9950cea8cd86248aae667d300c4224a3b3861"}}
{"schema_version":1,"source":"clob_ws_market","recv_ts_ns":1768250245567586761,"event_type":"best_bid_ask","market":"0x2a12fd3d8235c25c062dc9652970ef9f635636c4018df0909e1a51c673e125cb","server_ts_ms":1768250245270,"raw":{"market":"0x2a12fd3d8235c25c062dc9652970ef9f635636c4018df0909e1a51c673e125cb","asset_id":"63670753354844494163057275310194312729998307779831462269530137743341854359908","best_bid":"0.84","best_ask":"0.85","spread":"0.01","timestamp":"1768250245270","event_type":"best_bid_ask"}}
{"schema_version":1,"source":"clob_ws_market","recv_ts_ns":1768250245569283080,"event_type":"price_change","market":"0x2a12fd3d8235c25c062dc9652970ef9f635636c4018df0909e1a51c673e125cb","server_ts_ms":1768250245268,"raw":{"market":"0x2a12fd3d8235c25c062dc9652970ef9f635636c4018df0909e1a51c673e125cb","price_changes":[{"asset_id":"56386988715176239099720172290594769295756680374928571099138069977179519358166","price":"0.15","size":"27.12","side":"BUY","hash":"ddd4dd910b282a6cfadaa734a87bfbe2479d0e8b","best_bid":"0.15","best_ask":"0.16"},{"asset_id":"63670753354844494163057275310194312729998307779831462269530137743341854359908","price":"0.85","size":"27.12","side":"SELL","hash":"f9bb0410be3d178711f526730f862221ebf2b80a","best_bid":"0.84","best_ask":"0.85"}],"timestamp":"1768250245268","event_type":"price_change"}}
{"schema_version":1,"source":"clob_ws_market","recv_ts_ns":1768250245576561271,"event_type":"book","market":"0x2a12fd3d8235c25c062dc9652970ef9f635636c4018df0909e1a51c673e125cb","server_ts_ms":1768250245268,"raw":{"market":"0x2a12fd3d8235c25c062dc9652970ef9f635636c4018df0909e1a51c673e125cb","asset_id":"63670753354844494163057275310194312729998307779831462269530137743341854359908","bids":[{"price":"0.01","size":"10184.18"},{"price":"0.02","size":"5982"},{"price":"0.03","size":"5238.94"},{"price":"0.04","size":"5040"},{"price":"0.05","size":"5050"},{"price":"0.06","size":"5005"},{"price":"0.07","size":"5019.28"},{"price":"0.08","size":"5005"},{"price":"0.09","size":"5005"},{"price":"0.1","size":"5030"},{"price":"0.11","size":"5"},{"price":"0.12","size":"5"},{"price":"0.13","size":"5"},{"price":"0.14","size":"5"},{"price":"0.15","size":"10"},{"price":"0.16","size":"5"},{"price":"0.17","size":"5"},{"price":"0.18","size":"5"},{"price":"0.19","size":"5"},{"price":"0.2","size":"5"},{"price":"0.21","size":"5"},{"price":"0.22","size":"5"},{"price":"0.23","size":"5"},{"price":"0.24","size":"5"},{"price":"0.25","size":"10"},{"price":"0.26","size":"5"},{"price":"0.27","size":"5"},{"price":"0.28","size":"5"},{"price":"0.29","size":"15"},{"price":"0.3","size":"10"},{"price":"0.31","size":"5"},{"price":"0.32","size":"5"},{"price":"0.33","size":"5"},{"price":"0.34","size":"505"},{"price":"0.35","size":"510"},{"price":"0.36","size":"510"},{"price":"0.37","size":"505"},{"price":"0.38","size":"505"},{"price":"0.39","size":"755"},{"price":"0.4","size":"760"},{"price":"0.41","size":"916"},{"price":"0.42","size":"671"},{"price":"0.43","size":"827"},{"price":"0.44","size":"827"},{"price":"0.45","size":"817"},{"price":"0.46","size":"872"},{"price":"0.47","size":"839.65"},{"price":"0.48","size":"829"},{"price":"0.49","size":"817"},{"price":"0.5","size":"838.4"},{"price":"0.51","size":"867.58"},{"price":"0.52","size":"817"},{"price":"0.53","size":"827"},{"price":"0.54","size":"847.8"},{"price":"0.55","size":"836.09"},{"price":"0.56","size":"825"},{"price":"0.57","size":"847"},{"price":"0.58","size":"817"},{"price":"0.59","size":"817"},{"price":"0.6","size":"817"},{"price":"0.61","size":"834.5"},{"price":"0.62","size":"817"},{"price":"0.63","size":"497.49"},{"price":"0.64","size":"817"},{"price":"0.65","size":"872"},{"price":"0.66","size":"997.71"},{"price":"0.67","size":"906.8"},{"price":"0.68","size":"902"},{"price":"0.69","size":"922"},{"price":"0.7","size":"911.6"},{"price":"0.71","size":"897"},{"price":"0.72","size":"899.55"},{"price":"0.73","size":"912"},{"price":"0.74","size":"1127.65"},{"price":"0.75","size":"722.5"},{"price":"0.76","size":"924.25"},{"price":"0.77","size":"762.5"},{"price":"0.78","size":"899.5"},{"price":"0.79","size":"808.5"},{"price":"0.8","size":"814.9"},{"price":"0.81","size":"723.21"},{"price":"0.82","size":"1491"},{"price":"0.83","size":"270.52"},{"price":"0.84","size":"146.5"}],"asks":[{"price":"0.99","size":"10331.71"},{"price":"0.98","size":"6299.77"},{"price":"0.97","size":"5625.94"},{"price":"0.96","size":"5427"},{"price":"0.95","size":"3442"},{"price":"0.94","size":"1397"},{"price":"0.93","size":"1433.78"},{"price":"0.92","size":"1546.75"},{"price":"0.91","size":"1373"},{"price":"0.9","size":"3427"},{"price":"0.89","size":"904.5"},{"price":"0.88","size":"897.75"},{"price":"0.87","size":"803.5"},{"price":"0.86","size":"810.79"},{"price":"0.85","size":"27.12"}],"hash":"f9bb0410be3d178711f526730f862221ebf2b80a","timestamp":"1768250245268","event_type":"book"}}
{"schema_version":1,"source":"clob_ws_market","recv_ts_ns":1768250245578831737,"event_type":"price_change","market":"0x2a12fd3d8235c25c062dc9652970ef9f635636c4018df0909e1a51c673e125cb","server_ts_ms":1768250245298,"raw":{"market":"0x2a12fd3d8235c25c062dc9652970ef9f635636c4018df0909e1a51c673e125cb","price_changes":[{"asset_id":"56386988715176239099720172290594769295756680374928571099138069977179519358166","price":"0.16","size":"154","side":"SELL","hash":"6dd433640848a2fecfc2ae6c23fc253a824b5a0f","best_bid":"0.15","best_ask":"0.16"},{"asset_id":"63670753354844494163057275310194312729998307779831462269530137743341854359908","price":"0.84","size":"154","side":"BUY","hash":"f84b3b541485b140757d9e345ec3462db9dcc436","best_bid":"0.84","best_ask":"0.85"}],"timestamp":"1768250245298","event_type":"price_change"}}
{"schema_version":1,"source":"clob_ws_market","recv_ts_ns":1768250245581755169,"event_type":"price_change","market":"0x2a12fd3d8235c25c062dc9652970ef9f635636c4018df0909e1a51c673e125cb","server_ts_ms":1768250245301,"raw":{"market":"0x2a12fd3d8235c25c062dc9652970ef9f635636c4018df0909e1a51c673e125cb","price_changes":[{"asset_id":"63670753354844494163057275310194312729998307779831462269530137743341854359908","price":"0.84","size":"161.5","side":"BUY","hash":"b10a4e973ce5da4f40d5bffd8189a086fcd3c5e7","best_bid":"0.84","best_ask":"0.85"},{"asset_id":"56386988715176239099720172290594769295756680374928571099138069977179519358166","price":"0.16","size":"161.5","side":"SELL","hash":"e412b89a07fbfcba035feb0b2554724c6fc6ec54","best_bid":"0.15","best_ask":"0.16"}],"timestamp":"1768250245301","event_type":"price_change"}}
{"schema_version":1,"source":"clob_ws_market","recv_ts_ns":1768250245588994381,"event_type":"last_trade_price","market":"0x2a12fd3d8235c25c062dc9652970ef9f635636c4018df0909e1a51c673e125cb","server_ts_ms":1768250245303,"raw":{"market":"0x2a12fd3d8235c25c062dc9652970ef9f635636c4018df0909e1a51c673e125cb","asset_id":"63670753354844494163057275310194312729998307779831462269530137743341854359908","price":"0.85","size":"1.294113","fee_rate_bps":"1000","side":"BUY","timestamp":"1768250245303","event_type":"last_trade_price","transaction_hash":"0xe5112d9e1163ad8bf72eaaf8f3a76e2712b1e2e909552f74f03e76b5aca88a46"}}
{"schema_version":1,"source":"clob_ws_market","recv_ts_ns":1768250245592648344,"event_type":"best_bid_ask","market":"0x2a12fd3d8235c25c062dc9652970ef9f635636c4018df0909e1a51c673e125cb","server_ts_ms":1768250245345,"raw":{"market":"0x2a12fd3d8235c25c062dc9652970ef9f635636c4018df0909e1a51c673e125cb","asset_id":"63670753354844494163057275310194312729998307779831462269530137743341854359908","best_bid":"0.84","best_ask":"0.85","spread":"0.01","timestamp":"1768250245345","event_type":"best_bid_ask"}}
{"schema_version":1,"source":"clob_ws_market","recv_ts_ns":1768250245594864169,"event_type":"price_change","market":"0x2a12fd3d8235c25c062dc9652970ef9f635636c4018df0909e1a51c673e125cb","server_ts_ms":1768250245344,"raw":{"market":"0x2a12fd3d8235c25c062dc9652970ef9f635636c4018df0909e1a51c673e125cb","price_changes":[{"asset_id":"56386988715176239099720172290594769295756680374928571099138069977179519358166","price":"0.15","size":"25.82","side":"BUY","hash":"aa485ec250b50e0074c6c799d008cf7a2694cc03","best_bid":"0.15","best_ask":"0.16"},{"asset_id":"63670753354844494163057275310194312729998307779831462269530137743341854359908","price":"0.85","size":"25.82","side":"SELL","hash":"6eda6cbe22618a2141c18fcb93c5d0061e8f6361","best_bid":"0.84","best_ask":"0.85"}],"timestamp":"1768250245344","event_type":"price_change"}}
{"schema_version":1,"source":"clob_ws_market","recv_ts_ns":1768250245605396791,"event_type":"book","market":"0x2a12fd3d8235c25c062dc9652970ef9f635636c4018df0909e1a51c673e125cb","server_ts_ms":1768250245344,"raw":{"market":"0x2a12fd3d8235c25c062dc9652970ef9f635636c4018df0909e1a51c673e125cb","asset_id":"63670753354844494163057275310194312729998307779831462269530137743341854359908","bids":[{"price":"0.01","size":"10184.18"},{"price":"0.02","size":"5982"},{"price":"0.03","size":"5238.94"},{"price":"0.04","size":"5040"},{"price":"0.05","size":"5050"},{"price":"0.06","size":"5005"},{"price":"0.07","size":"5019.28"},{"price":"0.08","size":"5005"},{"price":"0.09","size":"5005"},{"price":"0.1","size":"5030"},{"price":"0.11","size":"5"},{"price":"0.12","size":"5"},{"price":"0.13","size":"5"},{"price":"0.14","size":"5"},{"price":"0.15","size":"10"},{"price":"0.16","size":"5"},{"price":"0.17","size":"5"},{"price":"0.18","size":"5"},{"price":"0.19","size":"5"},{"price":"0.2","size":"5"},{"price":"0.21","size":"5"},{"price":"0.22","size":"5"},{"price":"0.23","size":"5"},{"price":"0.24","size":"5"},{"price":"0.25","size":"10"},{"price":"0.26","size":"5"},{"price":"0.27","size":"5"},{"price":"0.28","size":"5"},{"price":"0.29","size":"15"},{"price":"0.3","size":"10"},{"price":"0.31","size":"5"},{"price":"0.32","size":"5"},{"price":"0.33","size":"5"},{"price":"0.34","size":"505"},{"price":"0.35","size":"510"},{"price":"0.36","size":"510"},{"price":"0.37","size":"505"},{"price":"0.38","size":"505"},{"price":"0.39","size":"755"},{"price":"0.4","size":"760"},{"price":"0.41","size":"916"},{"price":"0.42","size":"671"},{"price":"0.43","size":"827"},{"price":"0.44","size":"827"},{"price":"0.45","size":"817"},{"price":"0.46","size":"872"},{"price":"0.47","size":"839.65"},{"price":"0.48","size":"829"},{"price":"0.49","size":"817"},{"price":"0.5","size":"838.4"},{"price":"0.51","size":"867.58"},{"price":"0.52","size":"817"},{"price":"0.53","size":"827"},{"price":"0.54","size":"847.8"},{"price":"0.55","size":"836.09"},{"price":"0.56","size":"825"},{"price":"0.57","size":"847"},{"price":"0.58","size":"817"},{"price":"0.59","size":"817"},{"price":"0.6","size":"817"},{"price":"0.61","size":"834.5"},{"price":"0.62","size":"817"},{"price":"0.63","size":"497.49"},{"price":"0.64","size":"817"},{"price":"0.65","size":"872"},{"price":"0.66","size":"997.71"},{"price":"0.67","size":"906.8"},{"price":"0.68","size":"902"},{"price":"0.69","size":"922"},{"price":"0.7","size":"911.6"},{"price":"0.71","size":"897"},{"price":"0.72","size":"899.55"},{"price":"0.73","size":"912"},{"price":"0.74","size":"1127.65"},{"price":"0.75","size":"722.5"},{"price":"0.76","size":"924.25"},{"price":"0.77","size":"762.5"},{"price":"0.78","size":"899.5"},{"price":"0.79","size":"808.5"},{"price":"0.8","size":"814.9"},{"price":"0.81","size":"723.21"},{"price":"0.82","size":"1491"},{"price":"0.83","size":"270.52"},{"price":"0.84","size":"161.5"}],"asks":[{"price":"0.99","size":"10331.71"},{"price":"0.98","size":"6299.77"},{"price":"0.97","size":"5625.94"},{"price":"0.96","size":"5427"},{"price":"0.95","size":"3442"},{"price":"0.94","size":"1397"},{"price":"0.93","size":"1433.78"},{"price":"0.92","size":"1546.75"},{"price":"0.91","size":"1373"},{"price":"0.9","size":"3427"},{"price":"0.89","size":"904.5"},{"price":"0.88","size":"897.75"},{"price":"0.87","size":"803.5"},{"price":"0.86","size":"810.79"},{"price":"0.85","size":"25.82"}],"hash":"6eda6cbe22618a2141c18fcb93c5d0061e8f6361","timestamp":"1768250245344","event_type":"book"}}
{"schema_version":1,"source":"clob_ws_market","recv_ts_ns":1768250245619725265,"event_type":"price_change","market":"0x2a12fd3d8235c25c062dc9652970ef9f635636c4018df0909e1a51c673e125cb","server_ts_ms":1768250245369,"raw":{"market":"0x2a12fd3d8235c25c062dc9652970ef9f635636c4018df0909e1a51c673e125cb","price_changes":[{"asset_id":"56386988715176239099720172290594769295756680374928571099138069977179519358166","price":"0.09","size":"1317","side":"BUY","hash":"3cb42d0a1c3e6134d4d973ee6c3ea81668a4d405","best_bid":"0.15","best_ask":"0.16"},{"asset_id":"63670753354844494163057275310194312729998307779831462269530137743341854359908","price":"0.91","size":"1317","side":"SELL","hash":"865f4f800ffdf904cc376de737fcdcf58133ccca","best_bid":"0.84","best_ask":"0.85"}],"timestamp":"1768250245369","event_type":"price_change"}}
{"schema_version":1,"source":"clob_ws_market","recv_ts_ns":1768250245624025995,"event_type":"price_change","market":"0x2a12fd3d8235c25c062dc9652970ef9f635636c4018df0909e1a51c673e125cb","server_ts_ms":1768250245371,"raw":{"market":"0x2a12fd3d8235c25c062dc9652970ef9f635636c4018df0909e1a51c673e125cb","price_changes":[{"asset_id":"63670753354844494163057275310194312729998307779831462269530137743341854359908","price":"0.77","size":"756.5","side":"BUY","hash":"df5feebc32e67e3d420757dfbb9bc95d023cbb87","best_bid":"0.84","best_ask":"0.85"},{"asset_id":"56386988715176239099720172290594769295756680374928571099138069977179519358166","price":"0.23","size":"756.5","side":"SELL","hash":"7116dfa25fc99ec8fcc1ef6cffce9508b95a2559","best_bid":"0.15","best_ask":"0.16"}],"timestamp":"1768250245371","event_type":"price_change"}}
{"schema_version":1,"source":"clob_ws_market","recv_ts_ns":1768250245628458437,"event_type":"price_change","market":"0x2a12fd3d8235c25c062dc9652970ef9f635636c4018df0909e1a51c673e125cb","server_ts_ms":1768250245371,"raw":{"market":"0x2a12fd3d8235c25c062dc9652970ef9f635636c4018df0909e1a51c673e125cb","price_changes":[{"asset_id":"63670753354844494163057275310194312729998307779831462269530137743341854359908","price":"0.88","size":"891.75","side":"SELL","hash":"df5feebc32e67e3d420757dfbb9bc95d023cbb87","best_bid":"0.84","best_ask":"0.85"},{"asset_id":"56386988715176239099720172290594769295756680374928571099138069977179519358166","price":"0.12","size":"891.75","side":"BUY","hash":"7116dfa25fc99ec8fcc1ef6cffce9508b95a2559","best_bid":"0.15","best_ask":"0.16"}],"timestamp":"1768250245371","event_type":"price_change"}}
{"schema_version":1,"source":"clob_ws_market","recv_ts_ns":1768250245632917898,"event_type":"last_trade_price","market":"0x2a12fd3d8235c25c062dc9652970ef9f635636c4018df0909e1a51c673e125cb","server_ts_ms":1768250245375,"raw":{"market":"0x2a12fd3d8235c25c062dc9652970ef9f635636c4018df0909e1a51c673e125cb","asset_id":"63670753354844494163057275310194312729998307779831462269530137743341854359908","price":"0.85","size":"1.294113","fee_rate_bps":"1000","side":"BUY","timestamp":"1768250245375","event_type":"last_trade_price","transaction_hash":"0x305aadc76f3fa88eb52c70d42361a8adb0fa6b49944dcf33f662df702f019f5c"}}
{"schema_version":1,"source":"clob_ws_market","recv_ts_ns":1768250245635533152,"event_type":"price_change","market":"0x2a12fd3d8235c25c062dc9652970ef9f635636c4018df0909e1a51c673e125cb","server_ts_ms":1768250245393,"raw":{"market":"0x2a12fd3d8235c25c062dc9652970ef9f635636c4018df0909e1a51c673e125cb","price_changes":[{"asset_id":"56386988715176239099720172290594769295756680374928571099138069977179519358166","price":"0.1","size":"3477","side":"BUY","hash":"4f291eeb60d905401862d6d43aec5e22f48ab06a","best_bid":"0.15","best_ask":"0.16"},{"asset_id":"63670753354844494163057275310194312729998307779831462269530137743341854359908","price":"0.9","size":"3477","side":"SELL","hash":"2901c0539960be271f947e4d4f613c4436907bda","best_bid":"0.84","best_ask":"0.85"}],"timestamp":"1768250245393","event_type":"price_change"}}
{"schema_version":1,"source":"clob_ws_market","recv_ts_ns":1768250245639714945,"event_type":"price_change","market":"0x2a12fd3d8235c25c062dc9652970ef9f635636c4018df0909e1a51c673e125cb","server_ts_ms":1768250245398,"raw":{"market":"0x2a12fd3d8235c25c062dc9652970ef9f635636c4018df0909e1a51c673e125cb","price_changes":[{"asset_id":"63670753354844494163057275310194312729998307779831462269530137743341854359908","price":"0.87","size":"809.5","side":"SELL","hash":"4de6be80f7b7a64a8c559cfcb141cd4082463950","best_bid":"0.84","best_ask":"0.85"},{"asset_id":"56386988715176239099720172290594769295756680374928571099138069977179519358166","price":"0.13","size":"809.5","side":"BUY","hash":"78cd41b37761c1275eadd0f3f43b1946feae3b34","best_bid":"0.15","best_ask":"0.16"}],"timestamp":"1768250245398","event_type":"price_change"}}
{"schema_version":1,"source":"clob_ws_market","recv_ts_ns":1768250245644708269,"event_type":"price_change","market":"0x2a12fd3d8235c25c062dc9652970ef9f635636c4018df0909e1a51c673e125cb","server_ts_ms":1768250245399,"raw":{"market":"0x2a12fd3d8235c25c062dc9652970ef9f635636c4018df0909e1a51c673e125cb","price_changes":[{"asset_id":"63670753354844494163057275310194312729998307779831462269530137743341854359908","price":"0.76","size":"931.25","side":"BUY","hash":"495112a1d32cbffbb97553c35b7d7dbf7499d414","best_bid":"0.84","best_ask":"0.85"},{"asset_id":"56386988715176239099720172290594769295756680374928571099138069977179519358166","price":"0.24","size":"931.25","side":"SELL","hash":"90685639487e420736c0c55d667f239963d1c11c","best_bid":"0.15","best_ask":"0.16"}],"timestamp":"1768250245399","event_type":"price_change"}}
{"schema_version":1,"source":"clob_ws_market","recv_ts_ns":1768250245653775896,"event_type":"price_change","market":"0x2a12fd3d8235c25c062dc9652970ef9f635636c4018df0909e1a51c673e125cb","server_ts_ms":1768250245454,"raw":{"market":"0x2a12fd3d8235c25c062dc9652970ef9f635636c4018df0909e1a51c673e125cb","price_changes":[{"asset_id":"56386988715176239099720172290594769295756680374928571099138069977179519358166","price":"0.14","size":"820.79","side":"BUY","hash":"62848e995a94708bee7a9c81146574dd690619c7","best_bid":"0.15","best_ask":"0.16"},{"asset_id":"63670753354844494163057275310194312729998307779831462269530137743341854359908","price":"0.86","size":"820.79","side":"SELL","hash":"2910a8c627bc10607bec37877aad46820dee9e57","best_bid":"0.84","best_ask":"0.85"}],"timestamp":"1768250245454","event_type":"price_change"}}
{"schema_version":1,"source":"clob_ws_market","recv_ts_ns":1768250245658290166,"event_type":"price_change","market":"0x2a12fd3d8235c25c062dc9652970ef9f635636c4018df0909e1a51c673e125cb","server_ts_ms":1768250245458,"raw":{"market":"0x2a12fd3d8235c25c062dc9652970ef9f635636c4018df0909e1a51c673e125cb","price_changes":[{"asset_id":"56386988715176239099720172290594769295756680374928571099138069977179519358166","price":"0.15","size":"15.82","side":"BUY","hash":"add4101e92f182c45f95783dea0e5e26f621b977","best_bid":"0.15","best_ask":"0.16"},{"asset_id":"63670753354844494163057275310194312729998307779831462269530137743341854359908","price":"0.85","size":"15.82","side":"SELL","hash":"18cbdcc5ac8d720b1d483a817a01cfd57b4fb802","best_bid":"0.84","best_ask":"0.85"}],"timestamp":"1768250245458","event_type":"price_change"}}
{"schema_version":1,"source":"clob_ws_market","recv_ts_ns":1768250245662221969,"event_type":"price_change","market":"0x2a12fd3d8235c25c062dc9652970ef9f635636c4018df0909e1a51c673e125cb","server_ts_ms":1768250245477,"raw":{"market":"0x2a12fd3d8235c25c062dc9652970ef9f635636c4018df0909e1a51c673e125cb","price_changes":[{"asset_id":"63670753354844494163057275310194312729998307779831462269530137743341854359908","price":"0.83","size":"260.52","side":"BUY","hash":"3e68c9ae57fb8dd2c1de689f3dfe533287c1ee4a","best_bid":"0.84","best_ask":"0.85"},{"asset_id":"56386988715176239099720172290594769295756680374928571099138069977179519358166","price":"0.17","size":"260.52","side":"SELL","hash":"8a32e89204e7374edc5a0362e44ed4198f8417d0","best_bid":"0.15","best_ask":"0.16"}],"timestamp":"1768250245477","event_type":"price_change"}}
{"schema_version":1,"source":"clob_ws_market","recv_ts_ns":1768250245665680839,"event_type":"price_change","market":"0x2a12fd3d8235c25c062dc9652970ef9f635636c4018df0909e1a51c673e125cb","server_ts_ms":1768250245478,"raw":{"market":"0x2a12fd3d8235c25c062dc9652970ef9f635636c4018df0909e1a51c673e125cb","price_changes":[{"asset_id":"63670753354844494163057275310194312729998307779831462269530137743341854359908","price":"0.84","size":"171.5","side":"BUY","hash":"67c9057dafa01ab1ebf03cb65081cc35dc270a22","best_bid":"0.84","best_ask":"0.85"},{"asset_id":"56386988715176239099720172290594769295756680374928571099138069977179519358166","price":"0.16","size":"171.5","side":"SELL","hash":"e56019f530725fd7ff55e220182f0facd3e57ca8","best_bid":"0.15","best_ask":"0.16"}],"timestamp":"1768250245478","event_type":"price_change"}}
{"schema_version":1,"source":"clob_ws_market","recv_ts_ns":1768250245674607356,"event_type":"price_change","market":"0x2a12fd3d8235c25c062dc9652970ef9f635636c4018df0909e1a51c673e125cb","server_ts_ms":1768250245537,"raw":{"market":"0x2a12fd3d8235c25c062dc9652970ef9f635636c4018df0909e1a51c673e125cb","price_changes":[{"asset_id":"63670753354844494163057275310194312729998307779831462269530137743341854359908","price":"0.82","size":"1401","side":"BUY","hash":"8a484901cb5a886a70f3cd47a72f4f7b824b8a93","best_bid":"0.84","best_ask":"0.85"},{"asset_id":"56386988715176239099720172290594769295756680374928571099138069977179519358166","price":"0.18","size":"1401","side":"SELL","hash":"4bf244d91d6243379141c521a937a8bba3031f89","best_bid":"0.15","best_ask":"0.16"}],"timestamp":"1768250245537","event_type":"price_change"}}
{"schema_version":1,"source":"clob_ws_market","recv_ts_ns":1768250245679531342,"event_type":"price_change","market":"0x2a12fd3d8235c25c062dc9652970ef9f635636c4018df0909e1a51c673e125cb","server_ts_ms":1768250245538,"raw":{"market":"0x2a12fd3d8235c25c062dc9652970ef9f635636c4018df0909e1a51c673e125cb","price_changes":[{"asset_id":"56386988715176239099720172290594769295756680374928571099138069977179519358166","price":"0.15","size":"515.82","side":"BUY","hash":"e7f124f1f5a44d1ab3d339cdfa3c3a2f1831cf10","best_bid":"0.15","best_ask":"0.16"},{"asset_id":"63670753354844494163057275310194312729998307779831462269530137743341854359908","price":"0.85","size":"515.82","side":"SELL","hash":"4e926c86141a3938816af495f5dc1ea292bc877b","best_bid":"0.84","best_ask":"0.85"}],"timestamp":"1768250245538","event_type":"price_change"}}
{"schema_version":1,"source":"clob_ws_market","recv_ts_ns":1768250245684960754,"event_type":"price_change","market":"0x2a12fd3d8235c25c062dc9652970ef9f635636c4018df0909e1a51c673e125cb","server_ts_ms":1768250245552,"raw":{"market":"0x2a12fd3d8235c25c062dc9652970ef9f635636c4018df0909e1a51c673e125cb","price_changes":[{"asset_id":"56386988715176239099720172290594769295756680374928571099138069977179519358166","price":"0.13","size":"819.5","side":"BUY","hash":"9a38fa42fa3e5c46990c18482d810bd4b65160c4","best_bid":"0.15","best_ask":"0.16"},{"asset_id":"63670753354844494163057275310194312729998307779831462269530137743341854359908","price":"0.87","size":"819.5","side":"SELL","hash":"08b4dc3e2b616055300d9f9fe28e509834f826e2","best_bid":"0.84","best_ask":"0.85"}],"timestamp":"1768250245552","event_type":"price_change"}}
{"schema_version":1,"source":"clob_ws_market","recv_ts_ns":1768250245712636065,"event_type":"price_change","market":"0x2a12fd3d8235c25c062dc9652970ef9f635636c4018df0909e1a51c673e125cb","server_ts_ms":1768250245609,"raw":{"market":"0x2a12fd3d8235c25c062dc9652970ef9f635636c4018df0909e1a51c673e125cb","price_changes":[{"asset_id":"63670753354844494163057275310194312729998307779831462269530137743341854359908","price":"0.82","size":"1391","side":"BUY","hash":"aa94bd8bdca28181d4eef2692bd497c9873ef62f","best_bid":"0.84","best_ask":"0.85"},{"asset_id":"56386988715176239099720172290594769295756680374928571099138069977179519358166","price":"0.18","size":"1391","side":"SELL","hash":"21e5f68171620dc9bb2e882a422764d51ad942c7","best_bid":"0.15","best_ask":"0.16"}],"timestamp":"1768250245609","event_type":"price_change"}}
{"schema_version":1,"source":"clob_ws_market","recv_ts_ns":1768250245717082121,"event_type":"price_change","market":"0x2a12fd3d8235c25c062dc9652970ef9f635636c4018df0909e1a51c673e125cb","server_ts_ms":1768250245612,"raw":{"market":"0x2a12fd3d8235c25c062dc9652970ef9f635636c4018df0909e1a51c673e125cb","price_changes":[{"asset_id":"63670753354844494163057275310194312729998307779831462269530137743341854359908","price":"0.82","size":"1381","side":"BUY","hash":"94d9b6da668464d996b8da25643e67ff39054f2e","best_bid":"0.84","best_ask":"0.85"},{"asset_id":"56386988715176239099720172290594769295756680374928571099138069977179519358166","price":"0.18","size":"1381","side":"SELL","hash":"cd5e3fab0ab170c7c347b57dec290def9e2b78e1","best_bid":"0.15","best_ask":"0.16"}],"timestamp":"1768250245612","event_type":"price_change"}}
{"schema_version":1,"source":"clob_ws_market","recv_ts_ns":1768250245722124659,"event_type":"price_change","market":"0x2a12fd3d8235c25c062dc9652970ef9f635636c4018df0909e1a51c673e125cb","server_ts_ms":1768250245656,"raw":{"market":"0x2a12fd3d8235c25c062dc9652970ef9f635636c4018df0909e1a51c673e125cb","price_changes":[{"asset_id":"63670753354844494163057275310194312729998307779831462269530137743341854359908","price":"0.83","size":"270.52","side":"BUY","hash":"c0cfdc0988d81e11f69f0c6c57a12c72660f9ea8","best_bid":"0.84","best_ask":"0.85"},{"asset_id":"56386988715176239099720172290594769295756680374928571099138069977179519358166","price":"0.17","size":"270.52","side":"SELL","hash":"3d630884799ccd7a3d0953313042ca453ac607d6","best_bid":"0.15","best_ask":"0.16"}],"timestamp":"1768250245656","event_type":"price_change"}}
{"schema_version":1,"source":"clob_ws_market","recv_ts_ns":1768250245725286513,"event_type":"price_change","market":"0x2a12fd3d8235c25c062dc9652970ef9f635636c4018df0909e1a51c673e125cb","server_ts_ms":1768250245657,"raw":{"market":"0x2a12fd3d8235c25c062dc9652970ef9f635636c4018df0909e1a51c673e125cb","price_changes":[{"asset_id":"63670753354844494163057275310194312729998307779831462269530137743341854359908","price":"0.68","size":"892","side":"BUY","hash":"c24f30641c93b5b53703edd5e2b8a1507be0f8ab","best_bid":"0.84","best_ask":"0.85"},{"asset_id":"56386988715176239099720172290594769295756680374928571099138069977179519358166","price":"0.32","size":"892","side":"SELL","hash":"df83f87bf470db844892190c290d6155f96c83e1","best_bid":"0.15","best_ask":"0.16"}],"timestamp":"1768250245657","event_type":"price_change"}}
{"schema_version":1,"source":"clob_ws_market","recv_ts_ns":1768250245744700216,"event_type":"price_change","market":"0x2a12fd3d8235c25c062dc9652970ef9f635636c4018df0909e1a51c673e125cb","server_ts_ms":1768250245723,"raw":{"market":"0x2a12fd3d8235c25c062dc9652970ef9f635636c4018df0909e1a51c673e125cb","price_changes":[{"asset_id":"63670753354844494163057275310194312729998307779831462269530137743341854359908","price":"0.83","size":"280.52","side":"BUY","hash":"549424937483bd63cf22a2b0a3aaa9e9fe7495b0","best_bid":"0.84","best_ask":"0.85"},{"asset_id":"56386988715176239099720172290594769295756680374928571099138069977179519358166","price":"0.17","size":"280.52","side":"SELL","hash":"a6fcc0eb2fa8612364f7ab4e58f69f24678c6460","best_bid":"0.15","best_ask":"0.16"}],"timestamp":"1768250245723","event_type":"price_change"}}
{"schema_version":1,"source":"clob_ws_market","recv_ts_ns":1768250245755783815,"event_type":"price_change","market":"0x2a12fd3d8235c25c062dc9652970ef9f635636c4018df0909e1a51c673e125cb","server_ts_ms":1768250245731,"raw":{"market":"0x2a12fd3d8235c25c062dc9652970ef9f635636c4018df0909e1a51c673e125cb","price_changes":[{"asset_id":"63670753354844494163057275310194312729998307779831462269530137743341854359908","price":"0.86","size":"815.29","side":"SELL","hash":"0fb9f5871e7dc27dc2b38d6132997439fc1623d0","best_bid":"0.84","best_ask":"0.85"},{"asset_id":"56386988715176239099720172290594769295756680374928571099138069977179519358166","price":"0.14","size":"815.29","side":"BUY","hash":"1c203b32f91955e44c3e51b34c12f470a75671e8","best_bid":"0.15","best_ask":"0.16"}],"timestamp":"1768250245731","event_type":"price_change"}}
{"schema_version":1,"source":"clob_ws_market","recv_ts_ns":1768250245765469103,"event_type":"best_bid_ask","market":"0x2a12fd3d8235c25c062dc9652970ef9f635636c4018df0909e1a51c673e125cb","server_ts_ms":1768250245739,"raw":{"market":"0x2a12fd3d8235c25c062dc9652970ef9f635636c4018df0909e1a51c673e125cb","asset_id":"63670753354844494163057275310194312729998307779831462269530137743341854359908","best_bid":"0.84","best_ask":"0.85","spread":"0.01","timestamp":"1768250245739","event_type":"best_bid_ask"}}
{"schema_version":1,"source":"clob_ws_market","recv_ts_ns":1768250245768273606,"event_type":"price_change","market":"0x2a12fd3d8235c25c062dc9652970ef9f635636c4018df0909e1a51c673e125cb","server_ts_ms":1768250245738,"raw":{"market":"0x2a12fd3d8235c25c062dc9652970ef9f635636c4018df0909e1a51c673e125cb","price_changes":[{"asset_id":"56386988715176239099720172290594769295756680374928571099138069977179519358166","price":"0.15","size":"513.26","side":"BUY","hash":"a0ae822bc86594239feda3e7730ad77875ae9626","best_bid":"0.15","best_ask":"0.16"},{"asset_id":"63670753354844494163057275310194312729998307779831462269530137743341854359908","price":"0.85","size":"513.26","side":"SELL","hash":"aa1878934d9249c1a1b9a696bd561c2c7e4bbfb0","best_bid":"0.84","best_ask":"0.85"}],"timestamp":"1768250245738","event_type":"price_change"}}
{"schema_version":1,"source":"clob_ws_market","recv_ts_ns":1768250245780607033,"event_type":"book","market":"0x2a12fd3d8235c25c062dc9652970ef9f635636c4018df0909e1a51c673e125cb","server_ts_ms":1768250245738,"raw":{"market":"0x2a12fd3d8235c25c062dc9652970ef9f635636c4018df0909e1a51c673e125cb","asset_id":"63670753354844494163057275310194312729998307779831462269530137743341854359908","bids":[{"price":"0.01","size":"10184.18"},{"price":"0.02","size":"5982"},{"price":"0.03","size":"5238.94"},{"price":"0.04","size":"5040"},{"price":"0.05","size":"5050"},{"price":"0.06","size":"5005"},{"price":"0.07","size":"5019.28"},{"price":"0.08","size":"5005"},{"price":"0.09","size":"5005"},{"price":"0.1","size":"5030"},{"price":"0.11","size":"5"},{"price":"0.12","size":"5"},{"price":"0.13","size":"5"},{"price":"0.14","size":"5"},{"price":"0.15","size":"10"},{"price":"0.16","size":"5"},{"price":"0.17","size":"5"},{"price":"0.18","size":"5"},{"price":"0.19","size":"5"},{"price":"0.2","size":"5"},{"price":"0.21","size":"5"},{"price":"0.22","size":"5"},{"price":"0.23","size":"5"},{"price":"0.24","size":"5"},{"price":"0.25","size":"10"},{"price":"0.26","size":"5"},{"price":"0.27","size":"5"},{"price":"0.28","size":"5"},{"price":"0.29","size":"15"},{"price":"0.3","size":"10"},{"price":"0.31","size":"5"},{"price":"0.32","size":"5"},{"price":"0.33","size":"5"},{"price":"0.34","size":"505"},{"price":"0.35","size":"510"},{"price":"0.36","size":"510"},{"price":"0.37","size":"505"},{"price":"0.38","size":"505"},{"price":"0.39","size":"755"},{"price":"0.4","size":"760"},{"price":"0.41","size":"916"},{"price":"0.42","size":"671"},{"price":"0.43","size":"827"},{"price":"0.44","size":"827"},{"price":"0.45","size":"817"},{"price":"0.46","size":"872"},{"price":"0.47","size":"839.65"},{"price":"0.48","size":"829"},{"price":"0.49","size":"817"},{"price":"0.5","size":"838.4"},{"price":"0.51","size":"867.58"},{"price":"0.52","size":"817"},{"price":"0.53","size":"827"},{"price":"0.54","size":"847.8"},{"price":"0.55","size":"836.09"},{"price":"0.56","size":"825"},{"price":"0.57","size":"847"},{"price":"0.58","size":"817"},{"price":"0.59","size":"817"},{"price":"0.6","size":"817"},{"price":"0.61","size":"834.5"},{"price":"0.62","size":"817"},{"price":"0.63","size":"497.49"},{"price":"0.64","size":"817"},{"price":"0.65","size":"872"},{"price":"0.66","size":"997.71"},{"price":"0.67","size":"906.8"},{"price":"0.68","size":"892"},{"price":"0.69","size":"922"},{"price":"0.7","size":"911.6"},{"price":"0.71","size":"897"},{"price":"0.72","size":"899.55"},{"price":"0.73","size":"912"},{"price":"0.74","size":"1127.65"},{"price":"0.75","size":"722.5"},{"price":"0.76","size":"931.25"},{"price":"0.77","size":"756.5"},{"price":"0.78","size":"899.5"},{"price":"0.79","size":"808.5"},{"price":"0.8","size":"814.9"},{"price":"0.81","size":"723.21"},{"price":"0.82","size":"1381"},{"price":"0.83","size":"280.52"},{"price":"0.84","size":"171.5"}],"asks":[{"price":"0.99","size":"10331.71"},{"price":"0.98","size":"6299.77"},{"price":"0.97","size":"5625.94"},{"price":"0.96","size":"5427"},{"price":"0.95","size":"3442"},{"price":"0.94","size":"1397"},{"price":"0.93","size":"1433.78"},{"price":"0.92","size":"1546.75"},{"price":"0.91","size":"1317"},{"price":"0.9","size":"3477"},{"price":"0.89","size":"904.5"},{"price":"0.88","size":"891.75"},{"price":"0.87","size":"819.5"},{"price":"0.86","size":"815.29"},{"price":"0.85","size":"513.26"}],"hash":"aa1878934d9249c1a1b9a696bd561c2c7e4bbfb0","timestamp":"1768250245738","event_type":"book"}}
{"schema_version":1,"source":"clob_ws_market","recv_ts_ns":1768250245784417028,"event_type":"price_change","market":"0x2a12fd3d8235c25c062dc9652970ef9f635636c4018df0909e1a51c673e125cb","server_ts_ms":1768250245743,"raw":{"market":"0x2a12fd3d8235c25c062dc9652970ef9f635636c4018df0909e1a51c673e125cb","price_changes":[{"asset_id":"56386988715176239099720172290594769295756680374928571099138069977179519358166","price":"0.14","size":"805.29","side":"BUY","hash":"96340bff505190ae5368e1e2101c2a0df886cdf9","best_bid":"0.15","best_ask":"0.16"},{"asset_id":"63670753354844494163057275310194312729998307779831462269530137743341854359908","price":"0.86","size":"805.29","side":"SELL","hash":"8779eb65ab3f6078fd62e1352466b8b21c9e1e45","best_bid":"0.84","best_ask":"0.85"}],"timestamp":"1768250245743","event_type":"price_change"}}
{"schema_version":1,"source":"clob_ws_market","recv_ts_ns":1768250245788896317,"event_type":"price_change","market":"0x2a12fd3d8235c25c062dc9652970ef9f635636c4018df0909e1a51c673e125cb","server_ts_ms":1768250245749,"raw":{"market":"0x2a12fd3d8235c25c062dc9652970ef9f635636c4018df0909e1a51c673e125cb","price_changes":[{"asset_id":"56386988715176239099720172290594769295756680374928571099138069977179519358166","price":"0.15","size":"523.26","side":"BUY","hash":"41708676c2a4c69dfaf05e9c6ce792237f0f73a7","best_bid":"0.15","best_ask":"0.16"},{"asset_id":"63670753354844494163057275310194312729998307779831462269530137743341854359908","price":"0.85","size":"523.26","side":"SELL","hash":"035b81872f46acea477389e6655181060ac38210","best_bid":"0.84","best_ask":"0.85"}],"timestamp":"1768250245749","event_type":"price_change"}}
{"schema_version":1,"source":"clob_ws_market","recv_ts_ns":1768250245792505633,"event_type":"price_change","market":"0x2a12fd3d8235c25c062dc9652970ef9f635636c4018df0909e1a51c673e125cb","server_ts_ms":1768250245751,"raw":{"market":"0x2a12fd3d8235c25c062dc9652970ef9f635636c4018df0909e1a51c673e125cb","price_changes":[{"asset_id":"63670753354844494163057275310194312729998307779831462269530137743341854359908","price":"0.86","size":"799.79","side":"SELL","hash":"8d505eaffde398acb5c754f817c4086c30ec18c0","best_bid":"0.84","best_ask":"0.85"},{"asset_id":"56386988715176239099720172290594769295756680374928571099138069977179519358166","price":"0.14","size":"799.79","side":"BUY","hash":"f32a4a63d96852c62e6a36a178b28a39d4b8488c","best_bid":"0.15","best_ask":"0.16"}],"timestamp":"1768250245751","event_type":"price_change"}}
{"schema_version":1,"source":"clob_ws_market","recv_ts_ns":1768250245796302948,"event_type":"price_change","market":"0x2a12fd3d8235c25c062dc9652970ef9f635636c4018df0909e1a51c673e125cb","server_ts_ms":1768250245752,"raw":{"market":"0x2a12fd3d8235c25c062dc9652970ef9f635636c4018df0909e1a51c673e125cb","price_changes":[{"asset_id":"63670753354844494163057275310194312729998307779831462269530137743341854359908","price":"0.86","size":"794.29","side":"SELL","hash":"3ecb52b6fd0406be1d0ee4558b880756acf2bd99","best_bid":"0.84","best_ask":"0.85"},{"asset_id":"56386988715176239099720172290594769295756680374928571099138069977179519358166","price":"0.14","size":"794.29","side":"BUY","hash":"0735a4fabbee44a734b06897b7f728150195a39b","best_bid":"0.15","best_ask":"0.16"}],"timestamp":"1768250245752","event_type":"price_change"}}
{"schema_version":1,"source":"clob_ws_market","recv_ts_ns":1768250245799990870,"event_type":"price_change","market":"0x2a12fd3d8235c25c062dc9652970ef9f635636c4018df0909e1a51c673e125cb","server_ts_ms":1768250245759,"raw":{"market":"0x2a12fd3d8235c25c062dc9652970ef9f635636c4018df0909e1a51c673e125cb","price_changes":[{"asset_id":"56386988715176239099720172290594769295756680374928571099138069977179519358166","price":"0.14","size":"788.79","side":"BUY","hash":"53090fbcb58c2122928106cb57bbcdceae1084e8","best_bid":"0.15","best_ask":"0.16"},{"asset_id":"63670753354844494163057275310194312729998307779831462269530137743341854359908","price":"0.86","size":"788.79","side":"SELL","hash":"bc5f3f1c390d783d73d7aab394b6a72c2e4f1a94","best_bid":"0.84","best_ask":"0.85"}],"timestamp":"1768250245759","event_type":"price_change"}}
{"schema_version":1,"source":"clob_ws_market","recv_ts_ns":1768250245803477283,"event_type":"price_change","market":"0x2a12fd3d8235c25c062dc9652970ef9f635636c4018df0909e1a51c673e125cb","server_ts_ms":1768250245760,"raw":{"market":"0x2a12fd3d8235c25c062dc9652970ef9f635636c4018df0909e1a51c673e125cb","price_changes":[{"asset_id":"63670753354844494163057275310194312729998307779831462269530137743341854359908","price":"0.01","size":"10189.41","side":"BUY","hash":"5ad348621ca1d437d53b9487f73b4294985cf489","best_bid":"0.84","best_ask":"0.85"},{"asset_id":"56386988715176239099720172290594769295756680374928571099138069977179519358166","price":"0.99","size":"10189.41","side":"SELL","hash":"80c985a39b1f9421892a10c200ba26b4b0ba00ac","best_bid":"0.15","best_ask":"0.16"}],"timestamp":"1768250245760","event_type":"price_change"}}
{"schema_version":1,"source":"clob_ws_market","recv_ts_ns":1768250245806264346,"event_type":"last_trade_price","market":"0x2a12fd3d8235c25c062dc9652970ef9f635636c4018df0909e1a51c673e125cb","server_ts_ms":1768250245766,"raw":{"market":"0x2a12fd3d8235c25c062dc9652970ef9f635636c4018df0909e1a51c673e125cb","asset_id":"63670753354844494163057275310194312729998307779831462269530137743341854359908","price":"0.85","size":"2.55294","fee_rate_bps":"1000","side":"BUY","timestamp":"1768250245766","event_type":"last_trade_price","transaction_hash":"0x7f67e3e8845f24c2da37b14fd77c1e3b1ce52b4ff32475989fd1b78a7b4fb67e"}}
{"schema_version":1,"source":"clob_ws_market","recv_ts_ns":1768250245807810161,"event_type":"price_change","market":"0x2a12fd3d8235c25c062dc9652970ef9f635636c4018df0909e1a51c673e125cb","server_ts_ms":1768250245770,"raw":{"market":"0x2a12fd3d8235c25c062dc9652970ef9f635636c4018df0909e1a51c673e125cb","price_changes":[{"asset_id":"63670753354844494163057275310194312729998307779831462269530137743341854359908","price":"0.86","size":"783.29","side":"SELL","hash":"b35c4c608bc552eaf0a9e3831c413da1ddd16da2","best_bid":"0.84","best_ask":"0.85"},{"asset_id":"56386988715176239099720172290594769295756680374928571099138069977179519358166","price":"0.14","size":"783.29","side":"BUY","hash":"4eb99ede9c28ec8deaf0b8b74c155a577c9e3c31","best_bid":"0.15","best_ask":"0.16"}],"timestamp":"1768250245770","event_type":"price_change"}}
{"schema_version":1,"source":"clob_ws_market","recv_ts_ns":1768250245811438756,"event_type":"price_change","market":"0x2a12fd3d8235c25c062dc9652970ef9f635636c4018df0909e1a51c673e125cb","server_ts_ms":1768250245771,"raw":{"market":"0x2a12fd3d8235c25c062dc9652970ef9f635636c4018df0909e1a51c673e125cb","price_changes":[{"asset_id":"63670753354844494163057275310194312729998307779831462269530137743341854359908","price":"0.84","size":"161.5","side":"BUY","hash":"c2711fc9f7a72e3a7bb679b850b590a48f7d0578","best_bid":"0.84","best_ask":"0.85"},{"asset_id":"56386988715176239099720172290594769295756680374928571099138069977179519358166","price":"0.16","size":"161.5","side":"SELL","hash":"df8bc707dbf5001a64635e76e364700671563181","best_bid":"0.15","best_ask":"0.16"}],"timestamp":"1768250245771","event_type":"price_change"}}
{"schema_version":1,"source":"clob_ws_market","recv_ts_ns":1768250245814671744,"event_type":"price_change","market":"0x2a12fd3d8235c25c062dc9652970ef9f635636c4018df0909e1a51c673e125cb","server_ts_ms":1768250245778,"raw":{"market":"0x2a12fd3d8235c25c062dc9652970ef9f635636c4018df0909e1a51c673e125cb","price_changes":[{"asset_id":"63670753354844494163057275310194312729998307779831462269530137743341854359908","price":"0.81","size":"813.21","side":"BUY","hash":"a7272beb40af184b83cdcf4eaa9b6dfaa8d00c7d","best_bid":"0.84","best_ask":"0.85"},{"asset_id":"56386988715176239099720172290594769295756680374928571099138069977179519358166","price":"0.19","size":"813.21","side":"SELL","hash":"f4523d87a118096240816a4f3f5be8bdb05df72b","best_bid":"0.15","best_ask":"0.16"}],"timestamp":"1768250245778","event_type":"price_change"}}
{"schema_version":1,"source":"clob_ws_market","recv_ts_ns":1768250245817834196,"event_type":"price_change","market":"0x2a12fd3d8235c25c062dc9652970ef9f635636c4018df0909e1a51c673e125cb","server_ts_ms":1768250245779,"raw":{"market":"0x2a12fd3d8235c25c062dc9652970ef9f635636c4018df0909e1a51c673e125cb","price_changes":[{"asset_id":"63670753354844494163057275310194312729998307779831462269530137743341854359908","price":"0.83","size":"290.52","side":"BUY","hash":"e6e735368a2290f6d034acd85dd2d2bed2c65fb3","best_bid":"0.84","best_ask":"0.85"},{"asset_id":"56386988715176239099720172290594769295756680374928571099138069977179519358166","price":"0.17","size":"290.52","side":"SELL","hash":"6dd9394c823cbf51f7d51c311c14c9a9dfc218fe","best_bid":"0.15","best_ask":"0.16"}],"timestamp":"1768250245779","event_type":"price_change"}}
{"schema_version":1,"source":"clob_ws_market","recv_ts_ns":1768250245820790496,"event_type":"price_change","market":"0x2a12fd3d8235c25c062dc9652970ef9f635636c4018df0909e1a51c673e125cb","server_ts_ms":1768250245783,"raw":{"market":"0x2a12fd3d8235c25c062dc9652970ef9f635636c4018df0909e1a51c673e125cb","price_changes":[{"asset_id":"63670753354844494163057275310194312729998307779831462269530137743341854359908","price":"0.85","size":"528.76","side":"SELL","hash":"bcd7ba08647e53ebe5b407cde258fceee1a1d5b8","best_bid":"0.84","best_ask":"0.85"},{"asset_id":"56386988715176239099720172290594769295756680374928571099138069977179519358166","price":"0.15","size":"528.76","side":"BUY","hash":"d83d51171c143c43fd9e310091c1219711709344","best_bid":"0.15","best_ask":"0.16"}],"timestamp":"1768250245783","event_type":"price_change"}}
{"schema_version":1,"source":"clob_ws_market","recv_ts_ns":1768250245824659286,"event_type":"price_change","market":"0x2a12fd3d8235c25c062dc9652970ef9f635636c4018df0909e1a51c673e125cb","server_ts_ms":1768250245783,"raw":{"market":"0x2a12fd3d8235c25c062dc9652970ef9f635636c4018df0909e1a51c673e125cb","price_changes":[{"asset_id":"63670753354844494163057275310194312729998307779831462269530137743341854359908","price":"0.85","size":"534.26","side":"SELL","hash":"2fafd2b1c4e467e9b408c11fbd49a4d569e20428","best_bid":"0.84","best_ask":"0.85"},{"asset_id":"56386988715176239099720172290594769295756680374928571099138069977179519358166","price":"0.15","size":"534.26","side":"BUY","hash":"02dd5d5a64bfea6341c15ec16c841111a0b44d17","best_bid":"0.15","best_ask":"0.16"}],"timestamp":"1768250245783","event_type":"price_change"}}
{"schema_version":1,"source":"clob_ws_market","recv_ts_ns":1768250245828325762,"event_type":"price_change","market":"0x2a12fd3d8235c25c062dc9652970ef9f635636c4018df0909e1a51c673e125cb","server_ts_ms":1768250245786,"raw":{"market":"0x2a12fd3d8235c25c062dc9652970ef9f635636c4018df0909e1a51c673e125cb","price_changes":[{"asset_id":"63670753354844494163057275310194312729998307779831462269530137743341854359908","price":"0.85","size":"539.76","side":"SELL","hash":"4ed472a8f4217d5087ace003d45cf8996f2235b1","best_bid":"0.84","best_ask":"0.85"},{"asset_id":"56386988715176239099720172290594769295756680374928571099138069977179519358166","price":"0.15","size":"539.76","side":"BUY","hash":"7667ac7fa51fd046d18a3af2527008d7e3dbd410","best_bid":"0.15","best_ask":"0.16"}],"timestamp":"1768250245786","event_type":"price_change"}}
{"schema_version":1,"source":"clob_ws_market","recv_ts_ns":1768250245833960769,"event_type":"price_change","market":"0x2a12fd3d8235c25c062dc9652970ef9f635636c4018df0909e1a51c673e125cb","server_ts_ms":1768250245797,"raw":{"market":"0x2a12fd3d8235c25c062dc9652970ef9f635636c4018df0909e1a51c673e125cb","price_changes":[{"asset_id":"56386988715176239099720172290594769295756680374928571099138069977179519358166","price":"0.15","size":"545.26","side":"BUY","hash":"c8364a4000cd2fd5b5053ce300e8d02678835732","best_bid":"0.15","best_ask":"0.16"},{"asset_id":"63670753354844494163057275310194312729998307779831462269530137743341854359908","price":"0.85","size":"545.26","side":"SELL","hash":"02ea04e11ac0c2e4110d344f4e3f1b7d916ec258","best_bid":"0.84","best_ask":"0.85"}],"timestamp":"1768250245797","event_type":"price_change"}}
{"schema_version":1,"source":"clob_ws_market","recv_ts_ns":1768250245840377360,"event_type":"price_change","market":"0x2a12fd3d8235c25c062dc9652970ef9f635636c4018df0909e1a51c673e125cb","server_ts_ms":1768250245807,"raw":{"market":"0x2a12fd3d8235c25c062dc9652970ef9f635636c4018df0909e1a51c673e125cb","price_changes":[{"asset_id":"63670753354844494163057275310194312729998307779831462269530137743341854359908","price":"0.68","size":"902","side":"BUY","hash":"b41648671b19fb85f845420d4a84c9460786e66e","best_bid":"0.84","best_ask":"0.85"},{"asset_id":"56386988715176239099720172290594769295756680374928571099138069977179519358166","price":"0.32","size":"902","side":"SELL","hash":"08bf77c82ac5005a7ea3dae53ab6aed3f610d450","best_bid":"0.15","best_ask":"0.16"}],"timestamp":"1768250245807","event_type":"price_change"}}
{"schema_version":1,"source":"clob_ws_market","recv_ts_ns":1768250245844491677,"event_type":"price_change","market":"0x2a12fd3d8235c25c062dc9652970ef9f635636c4018df0909e1a51c673e125cb","server_ts_ms":1768250245812,"raw":{"market":"0x2a12fd3d8235c25c062dc9652970ef9f635636c4018df0909e1a51c673e125cb","price_changes":[{"asset_id":"63670753354844494163057275310194312729998307779831462269530137743341854359908","price":"0.85","size":"550.76","side":"SELL","hash":"176e1cc7202b8d65124cb3b16c88e9410f6f499b","best_bid":"0.84","best_ask":"0.85"},{"asset_id":"56386988715176239099720172290594769295756680374928571099138069977179519358166","price":"0.15","size":"550.76","side":"BUY","hash":"6b681e42ddea7fcd89a7e135ba54d9d1261ed179","best_bid":"0.15","best_ask":"0.16"}],"timestamp":"1768250245812","event_type":"price_change"}}
{"schema_version":1,"source":"clob_ws_market","recv_ts_ns":1768250245848620379,"event_type":"price_change","market":"0x2a12fd3d8235c25c062dc9652970ef9f635636c4018df0909e1a51c673e125cb","server_ts_ms":1768250245817,"raw":{"market":"0x2a12fd3d8235c25c062dc9652970ef9f635636c4018df0909e1a51c673e125cb","price_changes":[{"asset_id":"56386988715176239099720172290594769295756680374928571099138069977179519358166","price":"0.13","size":"729.5","side":"BUY","hash":"609e295aefe11493b6abd7f108622ceb89ac4884","best_bid":"0.15","best_ask":"0.16"},{"asset_id":"63670753354844494163057275310194312729998307779831462269530137743341854359908","price":"0.87","size":"729.5","side":"SELL","hash":"bfc10b280ea85e6d516afc59dd0fcb285b4a9c5c","best_bid":"0.84","best_ask":"0.85"}],"timestamp":"1768250245817","event_type":"price_change"}}
{"schema_version":1,"source":"clob_ws_market","recv_ts_ns":1768250245900860085,"event_type":"price_change","market":"0x2a12fd3d8235c25c062dc9652970ef9f635636c4018df0909e1a51c673e125cb","server_ts_ms":1768250245873,"raw":{"market":"0x2a12fd3d8235c25c062dc9652970ef9f635636c4018df0909e1a51c673e125cb","price_changes":[{"asset_id":"56386988715176239099720172290594769295756680374928571099138069977179519358166","price":"0.14","size":"873.29","side":"BUY","hash":"de0b93624095a1803ab85799d595f37cc7cb80e2","best_bid":"0.15","best_ask":"0.16"},{"asset_id":"63670753354844494163057275310194312729998307779831462269530137743341854359908","price":"0.86","size":"873.29","side":"SELL","hash":"b65116c72f2c58d2887480aaaee951d6eaf4e97f","best_bid":"0.84","best_ask":"0.85"}],"timestamp":"1768250245873","event_type":"price_change"}}
{"schema_version":1,"source":"clob_ws_market","recv_ts_ns":1768250245945991460,"event_type":"price_change","market":"0x2a12fd3d8235c25c062dc9652970ef9f635636c4018df0909e1a51c673e125cb","server_ts_ms":1768250245906,"raw":{"market":"0x2a12fd3d8235c25c062dc9652970ef9f635636c4018df0909e1a51c673e125cb","price_changes":[{"asset_id":"63670753354844494163057275310194312729998307779831462269530137743341854359908","price":"0.86","size":"853.29","side":"SELL","hash":"d861a8bbe2113b369d3eb7e072c07f89db55d3f4","best_bid":"0.84","best_ask":"0.85"},{"asset_id":"56386988715176239099720172290594769295756680374928571099138069977179519358166","price":"0.14","size":"853.29","side":"BUY","hash":"66cfc29716003582b1c839299d586029371475a3","best_bid":"0.15","best_ask":"0.16"}],"timestamp":"1768250245906","event_type":"price_change"}}
{"schema_version":1,"source":"clob_ws_market","recv_ts_ns":1768250245950568116,"event_type":"price_change","market":"0x2a12fd3d8235c25c062dc9652970ef9f635636c4018df0909e1a51c673e125cb","server_ts_ms":1768250245907,"raw":{"market":"0x2a12fd3d8235c25c062dc9652970ef9f635636c4018df0909e1a51c673e125cb","price_changes":[{"asset_id":"63670753354844494163057275310194312729998307779831462269530137743341854359908","price":"0.87","size":"749.5","side":"SELL","hash":"6d65e37abf748aaeda2dd7f5e43919e1392bc49d","best_bid":"0.84","best_ask":"0.85"},{"asset_id":"56386988715176239099720172290594769295756680374928571099138069977179519358166","price":"0.13","size":"749.5","side":"BUY","hash":"b58572d30463409a7d57866b6a367a611df5e5a5","best_bid":"0.15","best_ask":"0.16"}],"timestamp":"1768250245907","event_type":"price_change"}}
{"schema_version":1,"source":"clob_ws_market","recv_ts_ns":1768250246001297474,"event_type":"price_change","market":"0x2a12fd3d8235c25c062dc9652970ef9f635636c4018df0909e1a51c673e125cb","server_ts_ms":1768250245943,"raw":{"market":"0x2a12fd3d8235c25c062dc9652970ef9f635636c4018df0909e1a51c673e125cb","price_changes":[{"asset_id":"63670753354844494163057275310194312729998307779831462269530137743341854359908","price":"0.83","size":"280.52","side":"BUY","hash":"b4b15f0ae6753fd5e0cea78755d7399ebd7d7f89","best_bid":"0.84","best_ask":"0.85"},{"asset_id":"56386988715176239099720172290594769295756680374928571099138069977179519358166","price":"0.17","size":"280.52","side":"SELL","hash":"3e4b2961dd69d4515b8826dcecbd9b33f91f1fbc","best_bid":"0.15","best_ask":"0.16"}],"timestamp":"1768250245943","event_type":"price_change"}}
{"schema_version":1,"source":"clob_ws_market","recv_ts_ns":1768250246006808073,"event_type":"price_change","market":"0x2a12fd3d8235c25c062dc9652970ef9f635636c4018df0909e1a51c673e125cb","server_ts_ms":1768250245944,"raw":{"market":"0x2a12fd3d8235c25c062dc9652970ef9f635636c4018df0909e1a51c673e125cb","price_changes":[{"asset_id":"56386988715176239099720172290594769295756680374928571099138069977179519358166","price":"0.14","size":"843.29","side":"BUY","hash":"cae746618bbe194eb14c3203db2836ea181233e2","best_bid":"0.15","best_ask":"0.16"},{"asset_id":"63670753354844494163057275310194312729998307779831462269530137743341854359908","price":"0.86","size":"843.29","side":"SELL","hash":"4e5ba2652ee9e42dbf139a0c1a50482fc6673f94","best_bid":"0.84","best_ask":"0.85"}],"timestamp":"1768250245944","event_type":"price_change"}}
{"schema_version":1,"source":"clob_ws_market","recv_ts_ns":1768250246013383839,"event_type":"price_change","market":"0x2a12fd3d8235c25c062dc9652970ef9f635636c4018df0909e1a51c673e125cb","server_ts_ms":1768250245947,"raw":{"market":"0x2a12fd3d8235c25c062dc9652970ef9f635636c4018df0909e1a51c673e125cb","price_changes":[{"asset_id":"56386988715176239099720172290594769295756680374928571099138069977179519358166","price":"0.12","size":"881.75","side":"BUY","hash":"b2cd757b7c5bd3c2b8613e10326a3f85a42ed710","best_bid":"0.15","best_ask":"0.16"},{"asset_id":"63670753354844494163057275310194312729998307779831462269530137743341854359908","price":"0.88","size":"881.75","side":"SELL","hash":"d4955d81d509fcc28d21522104eeb503d54db02f","best_bid":"0.84","best_ask":"0.85"}],"timestamp":"1768250245947","event_type":"price_change"}}
{"schema_version":1,"source":"clob_ws_market","recv_ts_ns":1768250246018683915,"event_type":"price_change","market":"0x2a12fd3d8235c25c062dc9652970ef9f635636c4018df0909e1a51c673e125cb","server_ts_ms":1768250245950,"raw":{"market":"0x2a12fd3d8235c25c062dc9652970ef9f635636c4018df0909e1a51c673e125cb","price_changes":[{"asset_id":"56386988715176239099720172290594769295756680374928571099138069977179519358166","price":"0.11","size":"894.5","side":"BUY","hash":"8541a7e6f3303c33a931e4e313ef78c34f411b3e","best_bid":"0.15","best_ask":"0.16"},{"asset_id":"63670753354844494163057275310194312729998307779831462269530137743341854359908","price":"0.89","size":"894.5","side":"SELL","hash":"dd76776d052e04881eb8362af484b962f204f6e7","best_bid":"0.84","best_ask":"0.85"}],"timestamp":"1768250245950","event_type":"price_change"}}
{"schema_version":1,"source":"clob_ws_market","recv_ts_ns":1768250246022629635,"event_type":"price_change","market":"0x2a12fd3d8235c25c062dc9652970ef9f635636c4018df0909e1a51c673e125cb","server_ts_ms":1768250245951,"raw":{"market":"0x2a12fd3d8235c25c062dc9652970ef9f635636c4018df0909e1a51c673e125cb","price_changes":[{"asset_id":"63670753354844494163057275310194312729998307779831462269530137743341854359908","price":"0.83","size":"270.52","side":"BUY","hash":"432e082d832110294769d744708cdaeda7001103","best_bid":"0.84","best_ask":"0.85"},{"asset_id":"56386988715176239099720172290594769295756680374928571099138069977179519358166","price":"0.17","size":"270.52","side":"SELL","hash":"7d172283d201770965aefd5cb374ae3935b363ad","best_bid":"0.15","best_ask":"0.16"}],"timestamp":"1768250245951","event_type":"price_change"}}
{"schema_version":1,"source":"clob_ws_market","recv_ts_ns":1768250246027642460,"event_type":"price_change","market":"0x2a12fd3d8235c25c062dc9652970ef9f635636c4018df0909e1a51c673e125cb","server_ts_ms":1768250245952,"raw":{"market":"0x2a12fd3d8235c25c062dc9652970ef9f635636c4018df0909e1a51c673e125cb","price_changes":[{"asset_id":"56386988715176239099720172290594769295756680374928571099138069977179519358166","price":"0.14","size":"823.29","side":"BUY","hash":"4ff9e20f613e0baf4fd53d0cc7c58ba39836f199","best_bid":"0.15","best_ask":"0.16"},{"asset_id":"63670753354844494163057275310194312729998307779831462269530137743341854359908","price":"0.86","size":"823.29","side":"SELL","hash":"9d55d13ae4214d68a766201b6f0eac5ee9573e5e","best_bid":"0.84","best_ask":"0.85"}],"timestamp":"1768250245952","event_type":"price_change"}}
{"schema_version":1,"source":"clob_ws_market","recv_ts_ns":1768250246031371134,"event_type":"price_change","market":"0x2a12fd3d8235c25c062dc9652970ef9f635636c4018df0909e1a51c673e125cb","server_ts_ms":1768250245953,"raw":{"market":"0x2a12fd3d8235c25c062dc9652970ef9f635636c4018df0909e1a51c673e125cb","price_changes":[{"asset_id":"63670753354844494163057275310194312729998307779831462269530137743341854359908","price":"0.83","size":"260.52","side":"BUY","hash":"b351f1e0d2c89229ede141e580509d7290f329f2","best_bid":"0.84","best_ask":"0.85"},{"asset_id":"56386988715176239099720172290594769295756680374928571099138069977179519358166","price":"0.17","size":"260.52","side":"SELL","hash":"0e162db5544cbcb4daa3f7fd97b527e452b55e3e","best_bid":"0.15","best_ask":"0.16"}],"timestamp":"1768250245953","event_type":"price_change"}}
{"schema_version":1,"source":"clob_ws_market","recv_ts_ns":1768250246042477908,"event_type":"price_change","market":"0x2a12fd3d8235c25c062dc9652970ef9f635636c4018df0909e1a51c673e125cb","server_ts_ms":1768250245955,"raw":{"market":"0x2a12fd3d8235c25c062dc9652970ef9f635636c4018df0909e1a51c673e125cb","price_changes":[{"asset_id":"56386988715176239099720172290594769295756680374928571099138069977179519358166","price":"0.13","size":"769.5","side":"BUY","hash":"31ede29998399b7b4e3fbfff7d1ad661e9320671","best_bid":"0.15","best_ask":"0.16"},{"asset_id":"63670753354844494163057275310194312729998307779831462269530137743341854359908","price":"0.87","size":"769.5","side":"SELL","hash":"437924aa00db393670119a067f49ce095663d270","best_bid":"0.84","best_ask":"0.85"}],"timestamp":"1768250245955","event_type":"price_change"}}
{"schema_version":1,"source":"clob_ws_market","recv_ts_ns":1768250246047867645,"event_type":"price_change","market":"0x2a12fd3d8235c25c062dc9652970ef9f635636c4018df0909e1a51c673e125cb","server_ts_ms":1768250245959,"raw":{"market":"0x2a12fd3d8235c25c062dc9652970ef9f635636c4018df0909e1a51c673e125cb","price_changes":[{"asset_id":"56386988715176239099720172290594769295756680374928571099138069977179519358166","price":"0.12","size":"901.75","side":"BUY","hash":"14d784542f26c579e0db86841a40383fec3bf2d9","best_bid":"0.15","best_ask":"0.16"},{"asset_id":"63670753354844494163057275310194312729998307779831462269530137743341854359908","price":"0.88","size":"901.75","side":"SELL","hash":"aa1cd9cb0593798bbaa16c393dcd08f14f626b93","best_bid":"0.84","best_ask":"0.85"}],"timestamp":"1768250245959","event_type":"price_change"}}
{"schema_version":1,"source":"clob_ws_market","recv_ts_ns":1768250246050803870,"event_type":"price_change","market":"0x2a12fd3d8235c25c062dc9652970ef9f635636c4018df0909e1a51c673e125cb","server_ts_ms":1768250245962,"raw":{"market":"0x2a12fd3d8235c25c062dc9652970ef9f635636c4018df0909e1a51c673e125cb","price_changes":[{"asset_id":"56386988715176239099720172290594769295756680374928571099138069977179519358166","price":"0.13","size":"749.5","side":"BUY","hash":"26c8e436ba57301b15541a654003e9a4389fe9fa","best_bid":"0.15","best_ask":"0.16"},{"asset_id":"63670753354844494163057275310194312729998307779831462269530137743341854359908","price":"0.87","size":"749.5","side":"SELL","hash":"ec7f394f589c07b2bfadf430785ead6068e1faf5","best_bid":"0.84","best_ask":"0.85"}],"timestamp":"1768250245962","event_type":"price_change"}}
{"schema_version":1,"source":"clob_ws_market","recv_ts_ns":1768250246061385580,"event_type":"price_change","market":"0x2a12fd3d8235c25c062dc9652970ef9f635636c4018df0909e1a51c673e125cb","server_ts_ms":1768250245967,"raw":{"market":"0x2a12fd3d8235c25c062dc9652970ef9f635636c4018df0909e1a51c673e125cb","price_changes":[{"asset_id":"63670753354844494163057275310194312729998307779831462269530137743341854359908","price":"0.84","size":"176.5","side":"BUY","hash":"f0bf178ec1a317bfa5b2b83b5007dd085ffd4fe9","best_bid":"0.84","best_ask":"0.85"},{"asset_id":"56386988715176239099720172290594769295756680374928571099138069977179519358166","price":"0.16","size":"176.5","side":"SELL","hash":"dca4805d6d294c64af46df7273154b6f9eb97d2b","best_bid":"0.15","best_ask":"0.16"}],"timestamp":"1768250245967","event_type":"price_change"}}
{"schema_version":1,"source":"clob_ws_market","recv_ts_ns":1768250246068843675,"event_type":"price_change","market":"0x2a12fd3d8235c25c062dc9652970ef9f635636c4018df0909e1a51c673e125cb","server_ts_ms":1768250245969,"raw":{"market":"0x2a12fd3d8235c25c062dc9652970ef9f635636c4018df0909e1a51c673e125cb","price_changes":[{"asset_id":"63670753354844494163057275310194312729998307779831462269530137743341854359908","price":"0.76","size":"924.25","side":"BUY","hash":"b549130ad05a741feea9f9c439537b397f3d7de6","best_bid":"0.84","best_ask":"0.85"},{"asset_id":"56386988715176239099720172290594769295756680374928571099138069977179519358166","price":"0.24","size":"924.25","side":"SELL","hash":"d0bb7791eff02b982b595435366cbfba8a1e355c","best_bid":"0.15","best_ask":"0.16"}],"timestamp":"1768250245969","event_type":"price_change"}}
{"schema_version":1,"source":"clob_ws_market","recv_ts_ns":1768250246072763253,"event_type":"price_change","market":"0x2a12fd3d8235c25c062dc9652970ef9f635636c4018df0909e1a51c673e125cb","server_ts_ms":1768250245969,"raw":{"market":"0x2a12fd3d8235c25c062dc9652970ef9f635636c4018df0909e1a51c673e125cb","price_changes":[{"asset_id":"63670753354844494163057275310194312729998307779831462269530137743341854359908","price":"0.87","size":"743.5","side":"SELL","hash":"b549130ad05a741feea9f9c439537b397f3d7de6","best_bid":"0.84","best_ask":"0.85"},{"asset_id":"56386988715176239099720172290594769295756680374928571099138069977179519358166","price":"0.13","size":"743.5","side":"BUY","hash":"d0bb7791eff02b982b595435366cbfba8a1e355c","best_bid":"0.15","best_ask":"0.16"}],"timestamp":"1768250245969","event_type":"price_change"}}
{"schema_version":1,"source":"clob_ws_market","recv_ts_ns":1768250246075968755,"event_type":"price_change","market":"0x2a12fd3d8235c25c062dc9652970ef9f635636c4018df0909e1a51c673e125cb","server_ts_ms":1768250245971,"raw":{"market":"0x2a12fd3d8235c25c062dc9652970ef9f635636c4018df0909e1a51c673e125cb","price_changes":[{"asset_id":"56386988715176239099720172290594769295756680374928571099138069977179519358166","price":"0.13","size":"753.5","side":"BUY","hash":"136cea1607318978199444359fff8341c9d35caf","best_bid":"0.15","best_ask":"0.16"},{"asset_id":"63670753354844494163057275310194312729998307779831462269530137743341854359908","price":"0.87","size":"753.5","side":"SELL","hash":"fb6adaedca1f7e6ad0262abfcb52890c9e472cd9","best_bid":"0.84","best_ask":"0.85"}],"timestamp":"1768250245971","event_type":"price_change"}}
{"schema_version":1,"source":"clob_ws_market","recv_ts_ns":1768250246079010016,"event_type":"price_change","market":"0x2a12fd3d8235c25c062dc9652970ef9f635636c4018df0909e1a51c673e125cb","server_ts_ms":1768250245972,"raw":{"market":"0x2a12fd3d8235c25c062dc9652970ef9f635636c4018df0909e1a51c673e125cb","price_changes":[{"asset_id":"56386988715176239099720172290594769295756680374928571099138069977179519358166","price":"0.1","size":"3427","side":"BUY","hash":"637730ee825ded4f9f0943ca2c5e09b9f208544b","best_bid":"0.15","best_ask":"0.16"},{"asset_id":"63670753354844494163057275310194312729998307779831462269530137743341854359908","price":"0.9","size":"3427","side":"SELL","hash":"a1dab2cb82f5aa73cbd2602665e811c038ff5967","best_bid":"0.84","best_ask":"0.85"}],"timestamp":"1768250245972","event_type":"price_change"}}
{"schema_version":1,"source":"clob_ws_market","recv_ts_ns":1768250246083975307,"event_type":"price_change","market":"0x2a12fd3d8235c25c062dc9652970ef9f635636c4018df0909e1a51c673e125cb","server_ts_ms":1768250245975,"raw":{"market":"0x2a12fd3d8235c25c062dc9652970ef9f635636c4018df0909e1a51c673e125cb","price_changes":[{"asset_id":"56386988715176239099720172290594769295756680374928571099138069977179519358166","price":"0.1","size":"3437","side":"BUY","hash":"66864c8b2f7210b9cbef4e1a89c72d4eeea37923","best_bid":"0.15","best_ask":"0.16"},{"asset_id":"63670753354844494163057275310194312729998307779831462269530137743341854359908","price":"0.9","size":"3437","side":"SELL","hash":"09310e46c871579fc570bef4f002d1150e693330","best_bid":"0.84","best_ask":"0.85"}],"timestamp":"1768250245975","event_type":"price_change"}}
{"schema_version":1,"source":"clob_ws_market","recv_ts_ns":1768250246093272924,"event_type":"price_change","market":"0x2a12fd3d8235c25c062dc9652970ef9f635636c4018df0909e1a51c673e125cb","server_ts_ms":1768250245997,"raw":{"market":"0x2a12fd3d8235c25c062dc9652970ef9f635636c4018df0909e1a51c673e125cb","price_changes":[{"asset_id":"63670753354844494163057275310194312729998307779831462269530137743341854359908","price":"0.77","size":"762.5","side":"BUY","hash":"bdd4cfdae577f5c5dadaa167755db030b1135c07","best_bid":"0.84","best_ask":"0.85"},{"asset_id":"56386988715176239099720172290594769295756680374928571099138069977179519358166","price":"0.23","size":"762.5","side":"SELL","hash":"c4baec7e0f034655343581c42444d06354cffce2","best_bid":"0.15","best_ask":"0.16"}],"timestamp":"1768250245997","event_type":"price_change"}}
{"schema_version":1,"source":"clob_ws_market","recv_ts_ns":1768250246104272342,"event_type":"price_change","market":"0x2a12fd3d8235c25c062dc9652970ef9f635636c4018df0909e1a51c673e125cb","server_ts_ms":1768250245998,"raw":{"market":"0x2a12fd3d8235c25c062dc9652970ef9f635636c4018df0909e1a51c673e125cb","price_changes":[{"asset_id":"63670753354844494163057275310194312729998307779831462269530137743341854359908","price":"0.88","size":"907.75","side":"SELL","hash":"e3d34ea5487961766880d533aefac9186d005bf8","best_bid":"0.84","best_ask":"0.85"},{"asset_id":"56386988715176239099720172290594769295756680374928571099138069977179519358166","price":"0.12","size":"907.75","side":"BUY","hash":"5a212396aa9f74374cbf4ba56f254901869b124d","best_bid":"0.15","best_ask":"0.16"}],"timestamp":"1768250245998","event_type":"price_change"}}
{"schema_version":1,"source":"clob_ws_market","recv_ts_ns":1768250246114266650,"event_type":"price_change","market":"0x2a12fd3d8235c25c062dc9652970ef9f635636c4018df0909e1a51c673e125cb","server_ts_ms":1768250245999,"raw":{"market":"0x2a12fd3d8235c25c062dc9652970ef9f635636c4018df0909e1a51c673e125cb","price_changes":[{"asset_id":"63670753354844494163057275310194312729998307779831462269530137743341854359908","price":"0.84","size":"186.5","side":"BUY","hash":"bafb89c96b3f68722ba3d33a0b3acfad0b2fe3db","best_bid":"0.84","best_ask":"0.85"},{"asset_id":"56386988715176239099720172290594769295756680374928571099138069977179519358166","price":"0.16","size":"186.5","side":"SELL","hash":"1e0c6ab99f64cf75019714242351331e4b1c7c59","best_bid":"0.15","best_ask":"0.16"}],"timestamp":"1768250245999","event_type":"price_change"}}
{"schema_version":1,"source":"clob_ws_market","recv_ts_ns":1768250246119539587,"event_type":"price_change","market":"0x2a12fd3d8235c25c062dc9652970ef9f635636c4018df0909e1a51c673e125cb","server_ts_ms":1768250246000,"raw":{"market":"0x2a12fd3d8235c25c062dc9652970ef9f635636c4018df0909e1a51c673e125cb","price_changes":[{"asset_id":"56386988715176239099720172290594769295756680374928571099138069977179519358166","price":"0.09","size":"1373","side":"BUY","hash":"64623b74b28f08a2e17f39752f25ec90764ac5d1","best_bid":"0.15","best_ask":"0.16"},{"asset_id":"63670753354844494163057275310194312729998307779831462269530137743341854359908","price":"0.91","size":"1373","side":"SELL","hash":"2b35b31fd1b7179d70ed31459bc223ce9f4b18d1","best_bid":"0.84","best_ask":"0.85"}],"timestamp":"1768250246000","event_type":"price_change"}}
{"schema_version":1,"source":"clob_ws_market","recv_ts_ns":1768250246130147782,"event_type":"price_change","market":"0x2a12fd3d8235c25c062dc9652970ef9f635636c4018df0909e1a51c673e125cb","server_ts_ms":1768250246001,"raw":{"market":"0x2a12fd3d8235c25c062dc9652970ef9f635636c4018df0909e1a51c673e125cb","price_changes":[{"asset_id":"56386988715176239099720172290594769295756680374928571099138069977179519358166","price":"0.11","size":"904.5","side":"BUY","hash":"77ae75d49270aa9dd960461738c2255f714d1d23","best_bid":"0.15","best_ask":"0.16"},{"asset_id":"63670753354844494163057275310194312729998307779831462269530137743341854359908","price":"0.89","size":"904.5","side":"SELL","hash":"bd24cbed3951ed9d5b7ec2627213da9ab50e99c4","best_bid":"0.84","best_ask":"0.85"}],"timestamp":"1768250246001","event_type":"price_change"}}
{"schema_version":1,"source":"clob_ws_market","recv_ts_ns":1768250246138853041,"event_type":"price_change","market":"0x2a12fd3d8235c25c062dc9652970ef9f635636c4018df0909e1a51c673e125cb","server_ts_ms":1768250246002,"raw":{"market":"0x2a12fd3d8235c25c062dc9652970ef9f635636c4018df0909e1a51c673e125cb","price_changes":[{"asset_id":"63670753354844494163057275310194312729998307779831462269530137743341854359908","price":"0.83","size":"250.52","side":"BUY","hash":"2e0d1b4c62bcf849dbe9bc4f644dd9eef695d2dd","best_bid":"0.84","best_ask":"0.85"},{"asset_id":"56386988715176239099720172290594769295756680374928571099138069977179519358166","price":"0.17","size":"250.52","side":"SELL","hash":"088772f40de357e848e0be4df5255d07b4c7487f","best_bid":"0.15","best_ask":"0.16"}],"timestamp":"1768250246002","event_type":"price_change"}}
{"schema_version":1,"source":"clob_ws_market","recv_ts_ns":1768250246143717413,"event_type":"price_change","market":"0x2a12fd3d8235c25c062dc9652970ef9f635636c4018df0909e1a51c673e125cb","server_ts_ms":1768250246003,"raw":{"market":"0x2a12fd3d8235c25c062dc9652970ef9f635636c4018df0909e1a51c673e125cb","price_changes":[{"asset_id":"63670753354844494163057275310194312729998307779831462269530137743341854359908","price":"0.84","size":"171.5","side":"BUY","hash":"26d8aec9209cbcc8b1c25da359ddcf461797df65","best_bid":"0.84","best_ask":"0.85"},{"asset_id":"56386988715176239099720172290594769295756680374928571099138069977179519358166","price":"0.16","size":"171.5","side":"SELL","hash":"fce6d0a01000b242856dbfbae267f94eb6d6acbf","best_bid":"0.15","best_ask":"0.16"}],"timestamp":"1768250246003","event_type":"price_change"}}
{"schema_version":1,"source":"clob_ws_market","recv_ts_ns":1768250246148896426,"event_type":"price_change","market":"0x2a12fd3d8235c25c062dc9652970ef9f635636c4018df0909e1a51c673e125cb","server_ts_ms":1768250246004,"raw":{"market":"0x2a12fd3d8235c25c062dc9652970ef9f635636c4018df0909e1a51c673e125cb","price_changes":[{"asset_id":"63670753354844494163057275310194312729998307779831462269530137743341854359908","price":"0.83","size":"240.52","side":"BUY","hash":"430fdb2d6a78bc58c031d0bb9fbce289220587e4","best_bid":"0.84","best_ask":"0.85"},{"asset_id":"56386988715176239099720172290594769295756680374928571099138069977179519358166","price":"0.17","size":"240.52","side":"SELL","hash":"fa47bf9e149897de49f6d670da52623363ef765e","best_bid":"0.15","best_ask":"0.16"}],"timestamp":"1768250246004","event_type":"price_change"}}
{"schema_version":1,"source":"clob_ws_market","recv_ts_ns":1768250246153761058,"event_type":"price_change","market":"0x2a12fd3d8235c25c062dc9652970ef9f635636c4018df0909e1a51c673e125cb","server_ts_ms":1768250246005,"raw":{"market":"0x2a12fd3d8235c25c062dc9652970ef9f635636c4018df0909e1a51c673e125cb","price_changes":[{"asset_id":"63670753354844494163057275310194312729998307779831462269530137743341854359908","price":"0.84","size":"181.5","side":"BUY","hash":"f1e4ee862757fd004c18b54d1a5f4a54c7dadfe9","best_bid":"0.84","best_ask":"0.85"},{"asset_id":"56386988715176239099720172290594769295756680374928571099138069977179519358166","price":"0.16","size":"181.5","side":"SELL","hash":"732b68dd5def916a135e4e1257a8b06ed3831545","best_bid":"0.15","best_ask":"0.16"}],"timestamp":"1768250246005","event_type":"price_change"}}
{"schema_version":1,"source":"clob_ws_market","recv_ts_ns":1768250246158445190,"event_type":"price_change","market":"0x2a12fd3d8235c25c062dc9652970ef9f635636c4018df0909e1a51c673e125cb","server_ts_ms":1768250246006,"raw":{"market":"0x2a12fd3d8235c25c062dc9652970ef9f635636c4018df0909e1a51c673e125cb","price_changes":[{"asset_id":"63670753354844494163057275310194312729998307779831462269530137743341854359908","price":"0.83","size":"230.52","side":"BUY","hash":"f6d6feb87b51a942e582b36088e5aa2945d80516","best_bid":"0.84","best_ask":"0.85"},{"asset_id":"56386988715176239099720172290594769295756680374928571099138069977179519358166","price":"0.17","size":"230.52","side":"SELL","hash":"af8c4d98fabb3bd56864e18e44b8c9bbfd3db28d","best_bid":"0.15","best_ask":"0.16"}],"timestamp":"1768250246006","event_type":"price_change"}}
{"schema_version":1,"source":"clob_ws_market","recv_ts_ns":1768250246168208560,"event_type":"price_change","market":"0x2a12fd3d8235c25c062dc9652970ef9f635636c4018df0909e1a51c673e125cb","server_ts_ms":1768250246007,"raw":{"market":"0x2a12fd3d8235c25c062dc9652970ef9f635636c4018df0909e1a51c673e125cb","price_changes":[{"asset_id":"63670753354844494163057275310194312729998307779831462269530137743341854359908","price":"0.84","size":"191.5","side":"BUY","hash":"5afa58c305e7625ddace8c59ff8c9ac798303c05","best_bid":"0.84","best_ask":"0.85"},{"asset_id":"56386988715176239099720172290594769295756680374928571099138069977179519358166","price":"0.16","size":"191.5","side":"SELL","hash":"40a6c45ea1599bd25f85ee643a05e766bffb60e0","best_bid":"0.15","best_ask":"0.16"}],"timestamp":"1768250246007","event_type":"price_change"}}
{"schema_version":1,"source":"clob_ws_market","recv_ts_ns":1768250246172809122,"event_type":"price_change","market":"0x2a12fd3d8235c25c062dc9652970ef9f635636c4018df0909e1a51c673e125cb","server_ts_ms":1768250246008,"raw":{"market":"0x2a12fd3d8235c25c062dc9652970ef9f635636c4018df0909e1a51c673e125cb","price_changes":[{"asset_id":"56386988715176239099720172290594769295756680374928571099138069977179519358166","price":"0.12","size":"897.75","side":"BUY","hash":"af04b56ef3309b6cfb0fafaf83e4ca743dd598c6","best_bid":"0.15","best_ask":"0.16"},{"asset_id":"63670753354844494163057275310194312729998307779831462269530137743341854359908","price":"0.88","size":"897.75","side":"SELL","hash":"8b4989c180af7d20c8ff8eb81f859efa8b76485b","best_bid":"0.84","best_ask":"0.85"}],"timestamp":"1768250246008","event_type":"price_change"}}
{"schema_version":1,"source":"clob_ws_market","recv_ts_ns":1768250246177703442,"event_type":"price_change","market":"0x2a12fd3d8235c25c062dc9652970ef9f635636c4018df0909e1a51c673e125cb","server_ts_ms":1768250246008,"raw":{"market":"0x2a12fd3d8235c25c062dc9652970ef9f635636c4018df0909e1a51c673e125cb","price_changes":[{"asset_id":"63670753354844494163057275310194312729998307779831462269530137743341854359908","price":"0.83","size":"220.52","side":"BUY","hash":"b7b6508ec3cbdcbf347209dc81f1ac9caf6d3afe","best_bid":"0.84","best_ask":"0.85"},{"asset_id":"56386988715176239099720172290594769295756680374928571099138069977179519358166","price":"0.17","size":"220.52","side":"SELL","hash":"4cc32284c50a13cccc8a86b4e9d366ecc771d546","best_bid":"0.15","best_ask":"0.16"}],"timestamp":"1768250246008","event_type":"price_change"}}
{"schema_version":1,"source":"clob_ws_market","recv_ts_ns":1768250246182823228,"event_type":"price_change","market":"0x2a12fd3d8235c25c062dc9652970ef9f635636c4018df0909e1a51c673e125cb","server_ts_ms":1768250246009,"raw":{"market":"0x2a12fd3d8235c25c062dc9652970ef9f635636c4018df0909e1a51c673e125cb","price_changes":[{"asset_id":"63670753354844494163057275310194312729998307779831462269530137743341854359908","price":"0.83","size":"210.52","side":"BUY","hash":"a579951e9f79a5c061262134804897bda4254852","best_bid":"0.84","best_ask":"0.85"},{"asset_id":"56386988715176239099720172290594769295756680374928571099138069977179519358166","price":"0.17","size":"210.52","side":"SELL","hash":"1583ea6eedfee8dbb98f9e73f438710be4ca290a","best_bid":"0.15","best_ask":"0.16"}],"timestamp":"1768250246009","event_type":"price_change"}}
{"schema_version":1,"source":"clob_ws_market","recv_ts_ns":1768250246187968142,"event_type":"price_change","market":"0x2a12fd3d8235c25c062dc9652970ef9f635636c4018df0909e1a51c673e125cb","server_ts_ms":1768250246011,"raw":{"market":"0x2a12fd3d8235c25c062dc9652970ef9f635636c4018df0909e1a51c673e125cb","price_changes":[{"asset_id":"56386988715176239099720172290594769295756680374928571099138069977179519358166","price":"0.11","size":"894.5","side":"BUY","hash":"ce8e08c0dbc3a679a6a15d099d7418e125ebd4ec","best_bid":"0.15","best_ask":"0.16"},{"asset_id":"63670753354844494163057275310194312729998307779831462269530137743341854359908","price":"0.89","size":"894.5","side":"SELL","hash":"aac1a913649abc792e514ec6f0d167ae5eab03d9","best_bid":"0.84","best_ask":"0.85"}],"timestamp":"1768250246011","event_type":"price_change"}}
{"schema_version":1,"source":"clob_ws_market","recv_ts_ns":1768250246193548662,"event_type":"price_change","market":"0x2a12fd3d8235c25c062dc9652970ef9f635636c4018df0909e1a51c673e125cb","server_ts_ms":1768250246011,"raw":{"market":"0x2a12fd3d8235c25c062dc9652970ef9f635636c4018df0909e1a51c673e125cb","price_changes":[{"asset_id":"63670753354844494163057275310194312729998307779831462269530137743341854359908","price":"0.83","size":"200.52","side":"BUY","hash":"571347f47156a08e1881347a3fb2071e351c3bad","best_bid":"0.84","best_ask":"0.85"},{"asset_id":"56386988715176239099720172290594769295756680374928571099138069977179519358166","price":"0.17","size":"200.52","side":"SELL","hash":"e5d289a032a81f653d695bd5ef4fdbf6b3dcd01a","best_bid":"0.15","best_ask":"0.16"}],"timestamp":"1768250246011","event_type":"price_change"}}
{"schema_version":1,"source":"clob_ws_market","recv_ts_ns":1768250246198304056,"event_type":"price_change","market":"0x2a12fd3d8235c25c062dc9652970ef9f635636c4018df0909e1a51c673e125cb","server_ts_ms":1768250246012,"raw":{"market":"0x2a12fd3d8235c25c062dc9652970ef9f635636c4018df0909e1a51c673e125cb","price_changes":[{"asset_id":"56386988715176239099720172290594769295756680374928571099138069977179519358166","price":"0.13","size":"743.5","side":"BUY","hash":"2c175684a4ba56238432a083ec209f3da619e9f0","best_bid":"0.15","best_ask":"0.16"},{"asset_id":"63670753354844494163057275310194312729998307779831462269530137743341854359908","price":"0.87","size":"743.5","side":"SELL","hash":"90186ce92b557d644c0f53512e6f3ca4888b68d5","best_bid":"0.84","best_ask":"0.85"}],"timestamp":"1768250246012","event_type":"price_change"}}
{"schema_version":1,"source":"clob_ws_market","recv_ts_ns":1768250246202654473,"event_type":"price_change","market":"0x2a12fd3d8235c25c062dc9652970ef9f635636c4018df0909e1a51c673e125cb","server_ts_ms":1768250246013,"raw":{"market":"0x2a12fd3d8235c25c062dc9652970ef9f635636c4018df0909e1a51c673e125cb","price_changes":[{"asset_id":"56386988715176239099720172290594769295756680374928571099138069977179519358166","price":"0.12","size":"887.75","side":"BUY","hash":"a9923ca3c5917641094dddfdbcd260177e84166d","best_bid":"0.15","best_ask":"0.16"},{"asset_id":"63670753354844494163057275310194312729998307779831462269530137743341854359908","price":"0.88","size":"887.75","side":"SELL","hash":"3a85f750c40a40fe80efde608d831a53935d197b","best_bid":"0.84","best_ask":"0.85"}],"timestamp":"1768250246013","event_type":"price_change"}}
{"schema_version":1,"source":"clob_ws_market","recv_ts_ns":1768250246211496255,"event_type":"price_change","market":"0x2a12fd3d8235c25c062dc9652970ef9f635636c4018df0909e1a51c673e125cb","server_ts_ms":1768250246018,"raw":{"market":"0x2a12fd3d8235c25c062dc9652970ef9f635636c4018df0909e1a51c673e125cb","price_changes":[{"asset_id":"56386988715176239099720172290594769295756680374928571099138069977179519358166","price":"0.12","size":"877.75","side":"BUY","hash":"d752a89ea1a90771a93f1769f7836bfe6cf6277d","best_bid":"0.15","best_ask":"0.16"},{"asset_id":"63670753354844494163057275310194312729998307779831462269530137743341854359908","price":"0.88","size":"877.75","side":"SELL","hash":"470fad4241cb828008985059ab70f0bc1db2c064","best_bid":"0.84","best_ask":"0.85"}],"timestamp":"1768250246018","event_type":"price_change"}}
{"schema_version":1,"source":"clob_ws_market","recv_ts_ns":1768250246221335380,"event_type":"price_change","market":"0x2a12fd3d8235c25c062dc9652970ef9f635636c4018df0909e1a51c673e125cb","server_ts_ms":1768250246033,"raw":{"market":"0x2a12fd3d8235c25c062dc9652970ef9f635636c4018df0909e1a51c673e125cb","price_changes":[{"asset_id":"63670753354844494163057275310194312729998307779831462269530137743341854359908","price":"0.84","size":"201.5","side":"BUY","hash":"61e54d98d3c11a5800c7a483aa827eb5cc5bc936","best_bid":"0.84","best_ask":"0.85"},{"asset_id":"56386988715176239099720172290594769295756680374928571099138069977179519358166","price":"0.16","size":"201.5","side":"SELL","hash":"2e4e4888c24f34b967cd8d5bd5bd1adcc988358b","best_bid":"0.15","best_ask":"0.16"}],"timestamp":"1768250246033","event_type":"price_change"}}
{"schema_version":1,"source":"clob_ws_market","recv_ts_ns":1768250246229705982,"event_type":"price_change","market":"0x2a12fd3d8235c25c062dc9652970ef9f635636c4018df0909e1a51c673e125cb","server_ts_ms":1768250246036,"raw":{"market":"0x2a12fd3d8235c25c062dc9652970ef9f635636c4018df0909e1a51c673e125cb","price_changes":[{"asset_id":"56386988715176239099720172290594769295756680374928571099138069977179519358166","price":"0.11","size":"904.5","side":"BUY","hash":"ead5562d24a22b9ec1859b9744c6e5611ad2b185","best_bid":"0.15","best_ask":"0.16"},{"asset_id":"63670753354844494163057275310194312729998307779831462269530137743341854359908","price":"0.89","size":"904.5","side":"SELL","hash":"5b5589533c728256fa9da1453f1e1431732ee580","best_bid":"0.84","best_ask":"0.85"}],"timestamp":"1768250246036","event_type":"price_change"}}
{"schema_version":1,"source":"clob_ws_market","recv_ts_ns":1768250246233968404,"event_type":"price_change","market":"0x2a12fd3d8235c25c062dc9652970ef9f635636c4018df0909e1a51c673e125cb","server_ts_ms":1768250246040,"raw":{"market":"0x2a12fd3d8235c25c062dc9652970ef9f635636c4018df0909e1a51c673e125cb","price_changes":[{"asset_id":"63670753354844494163057275310194312729998307779831462269530137743341854359908","price":"0.84","size":"211.5","side":"BUY","hash":"69621032a7ac16627ea01ed77a6682d9260859f8","best_bid":"0.84","best_ask":"0.85"},{"asset_id":"56386988715176239099720172290594769295756680374928571099138069977179519358166","price":"0.16","size":"211.5","side":"SELL","hash":"80bff5e6fcacef4f11a957206d081fd623f7339d","best_bid":"0.15","best_ask":"0.16"}],"timestamp":"1768250246040","event_type":"price_change"}}
{"schema_version":1,"source":"clob_ws_market","recv_ts_ns":1768250246248475333,"event_type":"price_change","market":"0x2a12fd3d8235c25c062dc9652970ef9f635636c4018df0909e1a51c673e125cb","server_ts_ms":1768250246051,"raw":{"market":"0x2a12fd3d8235c25c062dc9652970ef9f635636c4018df0909e1a51c673e125cb","price_changes":[{"asset_id":"63670753354844494163057275310194312729998307779831462269530137743341854359908","price":"0.84","size":"221.5","side":"BUY","hash":"895de522505c9f99a04446ba47813e97a998e53b","best_bid":"0.84","best_ask":"0.85"},{"asset_id":"56386988715176239099720172290594769295756680374928571099138069977179519358166","price":"0.16","size":"221.5","side":"SELL","hash":"aaa7c46c43938e770c804506a55735eb7cc43bd2","best_bid":"0.15","best_ask":"0.16"}],"timestamp":"1768250246051","event_type":"price_change"}}
{"schema_version":1,"source":"clob_ws_market","recv_ts_ns":1768250246253229446,"event_type":"price_change","market":"0x2a12fd3d8235c25c062dc9652970ef9f635636c4018df0909e1a51c673e125cb","server_ts_ms":1768250246054,"raw":{"market":"0x2a12fd3d8235c25c062dc9652970ef9f635636c4018df0909e1a51c673e125cb","price_changes":[{"asset_id":"56386988715176239099720172290594769295756680374928571099138069977179519358166","price":"0.12","size":"887.75","side":"BUY","hash":"d6074d34efdb75512cf412387936bcb462054e1a","best_bid":"0.15","best_ask":"0.16"},{"asset_id":"63670753354844494163057275310194312729998307779831462269530137743341854359908","price":"0.88","size":"887.75","side":"SELL","hash":"6652784e37f2c7c9a7c298be61e5ac063fd605f3","best_bid":"0.84","best_ask":"0.85"}],"timestamp":"1768250246054","event_type":"price_change"}}
{"schema_version":1,"source":"clob_ws_market","recv_ts_ns":1768250246268103001,"event_type":"price_change","market":"0x2a12fd3d8235c25c062dc9652970ef9f635636c4018df0909e1a51c673e125cb","server_ts_ms":1768250246055,"raw":{"market":"0x2a12fd3d8235c25c062dc9652970ef9f635636c4018df0909e1a51c673e125cb","price_changes":[{"asset_id":"63670753354844494163057275310194312729998307779831462269530137743341854359908","price":"0.84","size":"231.5","side":"BUY","hash":"4b7fb26c01f1993e7f9bfeffed8fffb9deff911d","best_bid":"0.84","best_ask":"0.85"},{"asset_id":"56386988715176239099720172290594769295756680374928571099138069977179519358166","price":"0.16","size":"231.5","side":"SELL","hash":"8b731215967257a08167acc5eec96c379b91bef2","best_bid":"0.15","best_ask":"0.16"}],"timestamp":"1768250246055","event_type":"price_change"}}
{"schema_version":1,"source":"clob_ws_market","recv_ts_ns":1768250246273894201,"event_type":"price_change","market":"0x2a12fd3d8235c25c062dc9652970ef9f635636c4018df0909e1a51c673e125cb","server_ts_ms":1768250246058,"raw":{"market":"0x2a12fd3d8235c25c062dc9652970ef9f635636c4018df0909e1a51c673e125cb","price_changes":[{"asset_id":"63670753354844494163057275310194312729998307779831462269530137743341854359908","price":"0.84","size":"241.5","side":"BUY","hash":"a934b03dc96729042e88770b13f3598666ce5ec0","best_bid":"0.84","best_ask":"0.85"},{"asset_id":"56386988715176239099720172290594769295756680374928571099138069977179519358166","price":"0.16","size":"241.5","side":"SELL","hash":"8704c1b6088fa8c355055bae1167ad53d92d2858","best_bid":"0.15","best_ask":"0.16"}],"timestamp":"1768250246058","event_type":"price_change"}}
{"schema_version":1,"source":"clob_ws_market","recv_ts_ns":1768250246278428928,"event_type":"price_change","market":"0x2a12fd3d8235c25c062dc9652970ef9f635636c4018df0909e1a51c673e125cb","server_ts_ms":1768250246059,"raw":{"market":"0x2a12fd3d8235c25c062dc9652970ef9f635636c4018df0909e1a51c673e125cb","price_changes":[{"asset_id":"56386988715176239099720172290594769295756680374928571099138069977179519358166","price":"0.11","size":"914.5","side":"BUY","hash":"3f8b6ecaab5630c5fcfed1508dc09cd615959be9","best_bid":"0.15","best_ask":"0.16"},{"asset_id":"63670753354844494163057275310194312729998307779831462269530137743341854359908","price":"0.89","size":"914.5","side":"SELL","hash":"c9a2c13e4258ab417ce51dc8bf4951d8771c4ef4","best_bid":"0.84","best_ask":"0.85"}],"timestamp":"1768250246059","event_type":"price_change"}}
{"schema_version":1,"source":"clob_ws_market","recv_ts_ns":1768250246282476032,"event_type":"price_change","market":"0x2a12fd3d8235c25c062dc9652970ef9f635636c4018df0909e1a51c673e125cb","server_ts_ms":1768250246059,"raw":{"market":"0x2a12fd3d8235c25c062dc9652970ef9f635636c4018df0909e1a51c673e125cb","price_changes":[{"asset_id":"56386988715176239099720172290594769295756680374928571099138069977179519358166","price":"0.1","size":"3447","side":"BUY","hash":"3554346da4a628345e5fcb12910a798b4e359aa6","best_bid":"0.15","best_ask":"0.16"},{"asset_id":"63670753354844494163057275310194312729998307779831462269530137743341854359908","price":"0.9","size":"3447","side":"SELL","hash":"52a36decccabd5e81ca36ce97ce22d0932a12d44","best_bid":"0.84","best_ask":"0.85"}],"timestamp":"1768250246059","event_type":"price_change"}}
{"schema_version":1,"source":"clob_ws_market","recv_ts_ns":1768250246287179178,"event_type":"price_change","market":"0x2a12fd3d8235c25c062dc9652970ef9f635636c4018df0909e1a51c673e125cb","server_ts_ms":1768250246061,"raw":{"market":"0x2a12fd3d8235c25c062dc9652970ef9f635636c4018df0909e1a51c673e125cb","price_changes":[{"asset_id":"63670753354844494163057275310194312729998307779831462269530137743341854359908","price":"0.84","size":"251.5","side":"BUY","hash":"483d47e11b0871ecb9da85f8be66f983a6269389","best_bid":"0.84","best_ask":"0.85"},{"asset_id":"56386988715176239099720172290594769295756680374928571099138069977179519358166","price":"0.16","size":"251.5","side":"SELL","hash":"69f666fb20e372098892a20deec11ef960b13798","best_bid":"0.15","best_ask":"0.16"}],"timestamp":"1768250246061","event_type":"price_change"}}
{"schema_version":1,"source":"clob_ws_market","recv_ts_ns":1768250246304784118,"event_type":"price_change","market":"0x2a12fd3d8235c25c062dc9652970ef9f635636c4018df0909e1a51c673e125cb","server_ts_ms":1768250246072,"raw":{"market":"0x2a12fd3d8235c25c062dc9652970ef9f635636c4018df0909e1a51c673e125cb","price_changes":[{"asset_id":"56386988715176239099720172290594769295756680374928571099138069977179519358166","price":"0.11","size":"924.5","side":"BUY","hash":"33339b9d98a8c84c35969a3c92e474955bd99e07","best_bid":"0.15","best_ask":"0.16"},{"asset_id":"63670753354844494163057275310194312729998307779831462269530137743341854359908","price":"0.89","size":"924.5","side":"SELL","hash":"a01ee9743bdf81a110c687f62dbaba52e0a9c654","best_bid":"0.84","best_ask":"0.85"}],"timestamp":"1768250246072","event_type":"price_change"}}
{"schema_version":1,"source":"clob_ws_market","recv_ts_ns":1768250246309548788,"event_type":"price_change","market":"0x2a12fd3d8235c25c062dc9652970ef9f635636c4018df0909e1a51c673e125cb","server_ts_ms":1768250246080,"raw":{"market":"0x2a12fd3d8235c25c062dc9652970ef9f635636c4018df0909e1a51c673e125cb","price_changes":[{"asset_id":"63670753354844494163057275310194312729998307779831462269530137743341854359908","price":"0.83","size":"700.52","side":"BUY","hash":"cd615be166f76b6935a05fbfaf5dbb393b475baf","best_bid":"0.84","best_ask":"0.85"},{"asset_id":"56386988715176239099720172290594769295756680374928571099138069977179519358166","price":"0.17","size":"700.52","side":"SELL","hash":"91b2e76c5f8a24c998ff0ecd6e8779f3f9d986bb","best_bid":"0.15","best_ask":"0.16"}],"timestamp":"1768250246080","event_type":"price_change"}}
{"schema_version":1,"source":"clob_ws_market","recv_ts_ns":1768250246458553582,"event_type":"price_change","market":"0x2a12fd3d8235c25c062dc9652970ef9f635636c4018df0909e1a51c673e125cb","server_ts_ms":1768250246235,"raw":{"market":"0x2a12fd3d8235c25c062dc9652970ef9f635636c4018df0909e1a51c673e125cb","price_changes":[{"asset_id":"63670753354844494163057275310194312729998307779831462269530137743341854359908","price":"0.74","size":"1087.3","side":"BUY","hash":"0d53e6dbd5eaa0333fcf8ac12e78ed59a1d4c7c4","best_bid":"0.84","best_ask":"0.85"},{"asset_id":"56386988715176239099720172290594769295756680374928571099138069977179519358166","price":"0.26","size":"1087.3","side":"SELL","hash":"2577cbc225f4521d4d4bb70e1a5b68ba5569ed2f","best_bid":"0.15","best_ask":"0.16"}],"timestamp":"1768250246235","event_type":"price_change"}}
{"schema_version":1,"source":"clob_ws_market","recv_ts_ns":1768250246532132910,"event_type":"price_change","market":"0x2a12fd3d8235c25c062dc9652970ef9f635636c4018df0909e1a51c673e125cb","server_ts_ms":1768250246289,"raw":{"market":"0x2a12fd3d8235c25c062dc9652970ef9f635636c4018df0909e1a51c673e125cb","price_changes":[{"asset_id":"63670753354844494163057275310194312729998307779831462269530137743341854359908","price":"0.83","size":"200.52","side":"BUY","hash":"4274ecd81e6ad29f5e204f074ed72d9896c40a37","best_bid":"0.84","best_ask":"0.85"},{"asset_id":"56386988715176239099720172290594769295756680374928571099138069977179519358166","price":"0.17","size":"200.52","side":"SELL","hash":"e0665b8426b50f293c0641d16f6330e71f77fef2","best_bid":"0.15","best_ask":"0.16"}],"timestamp":"1768250246289","event_type":"price_change"}}
{"schema_version":1,"source":"clob_ws_market","recv_ts_ns":1768250246633794250,"event_type":"price_change","market":"0x2a12fd3d8235c25c062dc9652970ef9f635636c4018df0909e1a51c673e125cb","server_ts_ms":1768250246384,"raw":{"market":"0x2a12fd3d8235c25c062dc9652970ef9f635636c4018df0909e1a51c673e125cb","price_changes":[{"asset_id":"63670753354844494163057275310194312729998307779831462269530137743341854359908","price":"0.83","size":"700.52","side":"BUY","hash":"e3931e59ae19c8a560e5588f4219796e106f9c80","best_bid":"0.84","best_ask":"0.85"},{"asset_id":"56386988715176239099720172290594769295756680374928571099138069977179519358166","price":"0.17","size":"700.52","side":"SELL","hash":"ac48de56eed9384004ebafd088093b8bd505ebe9","best_bid":"0.15","best_ask":"0.16"}],"timestamp":"1768250246384","event_type":"price_change"}}
{"schema_version":1,"source":"clob_ws_market","recv_ts_ns":1768250246652331981,"event_type":"price_change","market":"0x2a12fd3d8235c25c062dc9652970ef9f635636c4018df0909e1a51c673e125cb","server_ts_ms":1768250246424,"raw":{"market":"0x2a12fd3d8235c25c062dc9652970ef9f635636c4018df0909e1a51c673e125cb","price_changes":[{"asset_id":"63670753354844494163057275310194312729998307779831462269530137743341854359908","price":"0.83","size":"200.52","side":"BUY","hash":"7bed46feca2003e93671833e2f168b0368ee47ba","best_bid":"0.84","best_ask":"0.85"},{"asset_id":"56386988715176239099720172290594769295756680374928571099138069977179519358166","price":"0.17","size":"200.52","side":"SELL","hash":"d34e28c10aec41e56f3df94c252bb225b768ebc3","best_bid":"0.15","best_ask":"0.16"}],"timestamp":"1768250246424","event_type":"price_change"}}
{"schema_version":1,"source":"clob_ws_market","recv_ts_ns":1768250246661260482,"event_type":"best_bid_ask","market":"0x2a12fd3d8235c25c062dc9652970ef9f635636c4018df0909e1a51c673e125cb","server_ts_ms":1768250246440,"raw":{"market":"0x2a12fd3d8235c25c062dc9652970ef9f635636c4018df0909e1a51c673e125cb","asset_id":"63670753354844494163057275310194312729998307779831462269530137743341854359908","best_bid":"0.84","best_ask":"0.85","spread":"0.01","timestamp":"1768250246440","event_type":"best_bid_ask"}}
{"schema_version":1,"source":"clob_ws_market","recv_ts_ns":1768250246664092165,"event_type":"price_change","market":"0x2a12fd3d8235c25c062dc9652970ef9f635636c4018df0909e1a51c673e125cb","server_ts_ms":1768250246439,"raw":{"market":"0x2a12fd3d8235c25c062dc9652970ef9f635636c4018df0909e1a51c673e125cb","price_changes":[{"asset_id":"63670753354844494163057275310194312729998307779831462269530137743341854359908","price":"0.84","size":"244.37","side":"BUY","hash":"579dee2b52f1f4f1382f7e5124f791248926b055","best_bid":"0.84","best_ask":"0.85"},{"asset_id":"56386988715176239099720172290594769295756680374928571099138069977179519358166","price":"0.16","size":"244.37","side":"SELL","hash":"a2f27bb4b44a32b6b12232040711ae2c975b7a04","best_bid":"0.15","best_ask":"0.16"}],"timestamp":"1768250246439","event_type":"price_change"}}
