{"schema_version":1,"source":"clob_ws_market","recv_ts_ns":1768250243419580192,"event_type":"book","market":"0x2a12fd3d8235c25c062dc9652970ef9f635636c4018df0909e1a51c673e125cb","server_ts_ms":1768250243378,"raw":{"market":"0x2a12fd3d8235c25c062dc9652970ef9f635636c4018df0909e1a51c673e125cb","asset_id":"63670753354844494163057275310194312729998307779831462269530137743341854359908","bids":[{"price":"0.01","size":"10184.18"},{"price":"0.02","size":"5982"},{"price":"0.03","size":"5238.94"},{"price":"0.04","size":"5040"},{"price":"0.05","size":"5050"},{"price":"0.06","size":"5005"},{"price":"0.07","size":"5019.28"},{"price":"0.08","size":"5005"},{"price":"0.09","size":"5005"},{"price":"0.1","size":"5030"},{"price":"0.11","size":"5"},{"price":"0.12","size":"5"},{"price":"0.13","size":"5"},{"price":"0.14","size":"5"},{"price":"0.15","size":"10"},{"price":"0.16","size":"5"},{"price":"0.17","size":"5"},{"price":"0.18","size":"5"},{"price":"0.19","size":"5"},{"price":"0.2","size":"5"},{"price":"0.21","size":"5"},{"price":"0.22","size":"5"},{"price":"0.23","size":"5"},{"price":"0.24","size":"5"},{"price":"0.25","size":"10"},{"price":"0.26","size":"5"},{"price":"0.27","size":"5"},{"price":"0.28","size":"5"},{"price":"0.29","size":"15"},{"price":"0.3","size":"10"},{"price":"0.31","size":"5"},{"price":"0.32","size":"5"},{"price":"0.33","size":"5"},{"price":"0.34","size":"505"},{"price":"0.35","size":"510"},{"price":"0.36","size":"510"},{"price":"0.37","size":"505"},{"price":"0.38","size":"505"},{"price":"0.39","size":"755"},{"price":"0.4","size":"760"},{"price":"0.41","size":"916"},{"price":"0.42","size":"671"},{"price":"0.43","size":"827"},{"price":"0.44","size":"827"},{"price":"0.45","size":"817"},{"price":"0.46","size":"872"},{"price":"0.47","size":"839.65"},{"price":"0.48","size":"829"},{"price":"0.49","size":"817"},{"price":"0.5","size":"838.4"},{"price":"0.51","size":"867.58"},{"price":"0.52","size":"817"},{"price":"0.53","size":"827"},{"price":"0.54","size":"847.8"},{"price":"0.55","size":"836.09"},{"price":"0.56","size":"825"},{"price":"0.57","size":"847"},{"price":"0.58","size":"817"},{"price":"0.59","size":"817"},{"price":"0.6","size":"817"},{"price":"0.61","size":"834.5"},{"price":"0.62","size":"817"},{"price":"0.63","size":"497.49"},{"price":"0.64","size":"817"},{"price":"0.65","size":"872"},{"price":"0.66","size":"906.8"},{"price":"0.67","size":"996.36"},{"price":"0.68","size":"902"},{"price":"0.69","size":"922"},{"price":"0.7","size":"911.6"},{"price":"0.71","size":"897"},{"price":"0.72","size":"899.55"},{"price":"0.73","size":"912"},{"price":"0.74","size":"1174.42"},{"price":"0.75","size":"722.5"},{"price":"0.76","size":"912.05"},{"price":"0.77","size":"748.5"},{"price":"0.78","size":"916.9"},{"price":"0.79","size":"814.5"},{"price":"0.8","size":"814.9"},{"price":"0.81","size":"888.21"},{"price":"0.82","size":"171"},{"price":"0.83","size":"189.52"},{"price":"0.84","size":"302.5"},{"price":"0.85","size":"56.65"}],"asks":[{"price":"0.99","size":"10331.71"},{"price":"0.98","size":"6299.77"},{"price":"0.97","size":"5625.94"},{"price":"0.96","size":"5427"},{"price":"0.95","size":"3442"},{"price":"0.94","size":"1397"},{"price":"0.93","size":"1433.78"},{"price":"0.92","size":"1559.75"},{"price":"0.91","size":"1327"},{"price":"0.9","size":"3443"},{"price":"0.89","size":"899.5"},{"price":"0.88","size":"1430.75"},{"price":"0.87","size":"361"},{"price":"0.86","size":"227.93"}],"hash":"3c7046e9b37431f01356c22b5d0de116d0812a36","timestamp":"1768250243378","event_type":"book"}}
{"schema_version":1,"source":"clob_ws_market","recv_ts_ns":1768250243501425741,"event_type":"price_change","market":"0x2a12fd3d8235c25c062dc9652970ef9f635636c4018df0909e1a51c673e125cb","server_ts_ms":1768250243432,"raw":{"market":"0x2a12fd3d8235c25c062dc9652970ef9f635636c4018df0909e1a51c673e125cb","price_changes":[{"asset_id":"63670753354844494163057275310194312729998307779831462269530137743341854359908","price":"0.84","size":"297","side":"BUY","hash":"f4a12c51423b112d5138ec63415beb3971153b3d","best_bid":"0.85","best_ask":"0.86"},{"asset_id":"56386988715176239099720172290594769295756680374928571099138069977179519358166","price":"0.16","size":"297","side":"SELL","hash":"d3aaac0ad63e332f372c3b6d315fee7b583e26d2","best_bid":"0.14","best_ask":"0.15"}],"timestamp":"1768250243432","event_type":"price_change"}}
{"schema_version":1,"source":"clob_ws_market","recv_ts_ns":1768250243529799986,"event_type":"price_change","market":"0x2a12fd3d8235c25c062dc9652970ef9f635636c4018df0909e1a51c673e125cb","server_ts_ms":1768250243438,"raw":{"market":"0x2a12fd3d8235c25c062dc9652970ef9f635636c4018df0909e1a51c673e125cb","price_changes":[{"asset_id":"63670753354844494163057275310194312729998307779831462269530137743341854359908","price":"0.85","size":"66.65","side":"BUY","hash":"078c5ae97a1b8d2bc9768746cdf37255c933bee6","best_bid":"0.85","best_ask":"0.86"},{"asset_id":"56386988715176239099720172290594769295756680374928571099138069977179519358166","price":"0.15","size":"66.65","side":"SELL","hash":"4d817c69cb5bb8c92ca2a139b2ce8ef708c81d5f","best_bid":"0.14","best_ask":"0.15"}],"timestamp":"1768250243438","event_type":"price_change"}}
{"schema_version":1,"source":"clob_ws_market","recv_ts_ns":1768250243544700616,"event_type":"price_change","market":"0x2a12fd3d8235c25c062dc9652970ef9f635636c4018df0909e1a51c673e125cb","server_ts_ms":1768250243448,"raw":{"market":"0x2a12fd3d8235c25c062dc9652970ef9f635636c4018df0909e1a51c673e125cb","price_changes":[{"asset_id":"63670753354844494163057275310194312729998307779831462269530137743341854359908","price":"0.78","size":"910.8","side":"BUY","hash":"cd51e48b8b9f72bcce80c8d2192f8f68dd8d71a4","best_bid":"0.85","best_ask":"0.86"},{"asset_id":"56386988715176239099720172290594769295756680374928571099138069977179519358166","price":"0.22","size":"910.8","side":"SELL","hash":"acf11c723b3cbdffa4ade38db3f65c2c221f1ce4","best_bid":"0.14","best_ask":"0.15"}],"timestamp":"1768250243448","event_type":"price_change"}}
{"schema_version":1,"source":"clob_ws_market","recv_ts_ns":1768250243550478211,"event_type":"price_change","market":"0x2a12fd3d8235c25c062dc9652970ef9f635636c4018df0909e1a51c673e125cb","server_ts_ms":1768250243450,"raw":{"market":"0x2a12fd3d8235c25c062dc9652970ef9f635636c4018df0909e1a51c673e125cb","price_changes":[{"asset_id":"56386988715176239099720172290594769295756680374928571099138069977179519358166","price":"0.08","size":"1534.75","side":"BUY","hash":"65bcbf8e843cbf042f437532c9673b3f727fc913","best_bid":"0.14","best_ask":"0.15"},{"asset_id":"63670753354844494163057275310194312729998307779831462269530137743341854359908","price":"0.92","size":"1534.75","side":"SELL","hash":"1001c8cec62917b88f683159cbe32688c959fd2d","best_bid":"0.85","best_ask":"0.86"}],"timestamp":"1768250243450","event_type":"price_change"}}
{"schema_version":1,"source":"clob_ws_market","recv_ts_ns":1768250243556182819,"event_type":"price_change","market":"0x2a12fd3d8235c25c062dc9652970ef9f635636c4018df0909e1a51c673e125cb","server_ts_ms":1768250243452,"raw":{"market":"0x2a12fd3d8235c25c062dc9652970ef9f635636c4018df0909e1a51c673e125cb","price_changes":[{"asset_id":"56386988715176239099720172290594769295756680374928571099138069977179519358166","price":"0.1","size":"3468","side":"BUY","hash":"64f6c990b333c588aa1d45da2ac12f13265ad2ea","best_bid":"0.14","best_ask":"0.15"},{"asset_id":"63670753354844494163057275310194312729998307779831462269530137743341854359908","price":"0.9","size":"3468","side":"SELL","hash":"43bb37e286133b929b916205746811a6bd7275d0","best_bid":"0.85","best_ask":"0.86"}],"timestamp":"1768250243452","event_type":"price_change"}}
{"schema_version":1,"source":"clob_ws_market","recv_ts_ns":1768250243561137856,"event_type":"price_change","market":"0x2a12fd3d8235c25c062dc9652970ef9f635636c4018df0909e1a51c673e125cb","server_ts_ms":1768250243452,"raw":{"market":"0x2a12fd3d8235c25c062dc9652970ef9f635636c4018df0909e1a51c673e125cb","price_changes":[{"asset_id":"63670753354844494163057275310194312729998307779831462269530137743341854359908","price":"0.76","size":"924.25","side":"BUY","hash":"3afa6a1a7661a57b280cca4756d9ebcb851dde5a","best_bid":"0.85","best_ask":"0.86"},{"asset_id":"56386988715176239099720172290594769295756680374928571099138069977179519358166","price":"0.24","size":"924.25","side":"SELL","hash":"eedc4cd4ec1ca93cacc13ba1f6782496d102f59c","best_bid":"0.14","best_ask":"0.15"}],"timestamp":"1768250243452","event_type":"price_change"}}
{"schema_version":1,"source":"clob_ws_market","recv_ts_ns":1768250243571074437,"event_type":"price_change","market":"0x2a12fd3d8235c25c062dc9652970ef9f635636c4018df0909e1a51c673e125cb","server_ts_ms":1768250243469,"raw":{"market":"0x2a12fd3d8235c25c062dc9652970ef9f635636c4018df0909e1a51c673e125cb","price_changes":[{"asset_id":"63670753354844494163057275310194312729998307779831462269530137743341854359908","price":"0.79","size":"808.5","side":"BUY","hash":"d1cbff00ff497e387b6c2dbacb79f7e1f81959b4","best_bid":"0.85","best_ask":"0.86"},{"asset_id":"56386988715176239099720172290594769295756680374928571099138069977179519358166","price":"0.21","size":"808.5","side":"SELL","hash":"58b0b23b7f7f60ce78e4504cc006a21f5acffde4","best_bid":"0.14","best_ask":"0.15"}],"timestamp":"1768250243469","event_type":"price_change"}}
{"schema_version":1,"source":"clob_ws_market","recv_ts_ns":1768250243577493170,"event_type":"price_change","market":"0x2a12fd3d8235c25c062dc9652970ef9f635636c4018df0909e1a51c673e125cb","server_ts_ms":1768250243469,"raw":{"market":"0x2a12fd3d8235c25c062dc9652970ef9f635636c4018df0909e1a51c673e125cb","price_changes":[{"asset_id":"63670753354844494163057275310194312729998307779831462269530137743341854359908","price":"0.9","size":"3462","side":"SELL","hash":"d1cbff00ff497e387b6c2dbacb79f7e1f81959b4","best_bid":"0.85","best_ask":"0.86"},{"asset_id":"56386988715176239099720172290594769295756680374928571099138069977179519358166","price":"0.1","size":"3462","side":"BUY","hash":"58b0b23b7f7f60ce78e4504cc006a21f5acffde4","best_bid":"0.14","best_ask":"0.15"}],"timestamp":"1768250243469","event_type":"price_change"}}
{"schema_version":1,"source":"clob_ws_market","recv_ts_ns":1768250243589300556,"event_type":"price_change","market":"0x2a12fd3d8235c25c062dc9652970ef9f635636c4018df0909e1a51c673e125cb","server_ts_ms":1768250243498,"raw":{"market":"0x2a12fd3d8235c25c062dc9652970ef9f635636c4018df0909e1a51c673e125cb","price_changes":[{"asset_id":"63670753354844494163057275310194312729998307779831462269530137743341854359908","price":"0.89","size":"905.5","side":"SELL","hash":"306e24e0b5eb0fd6fa44cecade43729012324cff","best_bid":"0.85","best_ask":"0.86"},{"asset_id":"56386988715176239099720172290594769295756680374928571099138069977179519358166","price":"0.11","size":"905.5","side":"BUY","hash":"56db8ca11fff26ff2b4c96102c436de0a528bfd9","best_bid":"0.14","best_ask":"0.15"}],"timestamp":"1768250243498","event_type":"price_change"}}
{"schema_version":1,"source":"clob_ws_market","recv_ts_ns":1768250243600844330,"event_type":"price_change","market":"0x2a12fd3d8235c25c062dc9652970ef9f635636c4018df0909e1a51c673e125cb","server_ts_ms":1768250243498,"raw":{"market":"0x2a12fd3d8235c25c062dc9652970ef9f635636c4018df0909e1a51c673e125cb","price_changes":[{"asset_id":"63670753354844494163057275310194312729998307779831462269530137743341854359908","price":"0.78","size":"916.8","side":"BUY","hash":"8db2e34836075d501460dc0e700a62e48c774e00","best_bid":"0.85","best_ask":"0.86"},{"asset_id":"56386988715176239099720172290594769295756680374928571099138069977179519358166","price":"0.22","size":"916.8","side":"SELL","hash":"2c4f31ee9cc57040c9acd3a498b1ba911433e429","best_bid":"0.14","best_ask":"0.15"}],"timestamp":"1768250243498","event_type":"price_change"}}
{"schema_version":1,"source":"clob_ws_market","recv_ts_ns":1768250243607678672,"event_type":"price_change","market":"0x2a12fd3d8235c25c062dc9652970ef9f635636c4018df0909e1a51c673e125cb","server_ts_ms":1768250243507,"raw":{"market":"0x2a12fd3d8235c25c062dc9652970ef9f635636c4018df0909e1a51c673e125cb","price_changes":[{"asset_id":"63670753354844494163057275310194312729998307779831462269530137743341854359908","price":"0.83","size":"195.02","side":"BUY","hash":"7c2b7ae250a820824d4a63af0e92ecbd47e3e6ab","best_bid":"0.85","best_ask":"0.86"},{"asset_id":"56386988715176239099720172290594769295756680374928571099138069977179519358166","price":"0.17","size":"195.02","side":"SELL","hash":"10d1977c29d57ea0aecb0f5745611caa02e37a6f","best_bid":"0.14","best_ask":"0.15"}],"timestamp":"1768250243507","event_type":"price_change"}}
{"schema_version":1,"source":"clob_ws_market","recv_ts_ns":1768250243709872901,"event_type":"price_change","market":"0x2a12fd3d8235c25c062dc9652970ef9f635636c4018df0909e1a51c673e125cb","server_ts_ms":1768250243688,"raw":{"market":"0x2a12fd3d8235c25c062dc9652970ef9f635636c4018df0909e1a51c673e125cb","price_changes":[{"asset_id":"63670753354844494163057275310194312729998307779831462269530137743341854359908","price":"0.82","size":"671","side":"BUY","hash":"28f3175380eae19f2fd805121a9fe102bf24886d","best_bid":"0.85","best_ask":"0.86"},{"asset_id":"56386988715176239099720172290594769295756680374928571099138069977179519358166","price":"0.18","size":"671","side":"SELL","hash":"15016c914dde82988c2c8fd72138abefc705fd3a","best_bid":"0.14","best_ask":"0.15"}],"timestamp":"1768250243688","event_type":"price_change"}}
{"schema_version":1,"source":"clob_ws_market","recv_ts_ns":1768250243752692596,"event_type":"price_change","market":"0x2a12fd3d8235c25c062dc9652970ef9f635636c4018df0909e1a51c673e125cb","server_ts_ms":1768250243711,"raw":{"market":"0x2a12fd3d8235c25c062dc9652970ef9f635636c4018df0909e1a51c673e125cb","price_changes":[{"asset_id":"63670753354844494163057275310194312729998307779831462269530137743341854359908","price":"0.84","size":"287","side":"BUY","hash":"0e34e530fbc4f6ae4cc4c48d8041b8c8f1238793","best_bid":"0.85","best_ask":"0.86"},{"asset_id":"56386988715176239099720172290594769295756680374928571099138069977179519358166","price":"0.16","size":"287","side":"SELL","hash":"ee9153c69d821e1cdd346a0ec1ae616ed9898617","best_bid":"0.14","best_ask":"0.15"}],"timestamp":"1768250243711","event_type":"price_change"}}
{"schema_version":1,"source":"clob_ws_market","recv_ts_ns":1768250243757886491,"event_type":"price_change","market":"0x2a12fd3d8235c25c062dc9652970ef9f635636c4018df0909e1a51c673e125cb","server_ts_ms":1768250243712,"raw":{"market":"0x2a12fd3d8235c25c062dc9652970ef9f635636c4018df0909e1a51c673e125cb","price_changes":[{"asset_id":"63670753354844494163057275310194312729998307779831462269530137743341854359908","price":"0.84","size":"277","side":"BUY","hash":"5e42ebaac97c755ab96fc76d2f656871c8c64254","best_bid":"0.85","best_ask":"0.86"},{"asset_id":"56386988715176239099720172290594769295756680374928571099138069977179519358166","price":"0.16","size":"277","side":"SELL","hash":"dbad9de345e70aef6453982e5cf710257b297826","best_bid":"0.14","best_ask":"0.15"}],"timestamp":"1768250243712","event_type":"price_change"}}
{"schema_version":1,"source":"clob_ws_market","recv_ts_ns":1768250243762771154,"event_type":"price_change","market":"0x2a12fd3d8235c25c062dc9652970ef9f635636c4018df0909e1a51c673e125cb","server_ts_ms":1768250243713,"raw":{"market":"0x2a12fd3d8235c25c062dc9652970ef9f635636c4018df0909e1a51c673e125cb","price_changes":[{"asset_id":"56386988715176239099720172290594769295756680374928571099138069977179519358166","price":"0.11","size":"895.5","side":"BUY","hash":"64a51ac8510db412e8473760a862979f61aed13c","best_bid":"0.14","best_ask":"0.15"},{"asset_id":"63670753354844494163057275310194312729998307779831462269530137743341854359908","price":"0.89","size":"895.5","side":"SELL","hash":"ffd6b350503a9cb7366a6b6d6255ca16f54aa775","best_bid":"0.85","best_ask":"0.86"}],"timestamp":"1768250243713","event_type":"price_change"}}
{"schema_version":1,"source":"clob_ws_market","recv_ts_ns":1768250243766788460,"event_type":"price_change","market":"0x2a12fd3d8235c25c062dc9652970ef9f635636c4018df0909e1a51c673e125cb","server_ts_ms":1768250243714,"raw":{"market":"0x2a12fd3d8235c25c062dc9652970ef9f635636c4018df0909e1a51c673e125cb","price_changes":[{"asset_id":"56386988715176239099720172290594769295756680374928571099138069977179519358166","price":"0.13","size":"351","side":"BUY","hash":"6c4fbaf5eb1aafcd0df38b5ed8058b8a435095af","best_bid":"0.14","best_ask":"0.15"},{"asset_id":"63670753354844494163057275310194312729998307779831462269530137743341854359908","price":"0.87","size":"351","side":"SELL","hash":"122fa8889da55b22e711607a30ea02d91ef7e0d0","best_bid":"0.85","best_ask":"0.86"}],"timestamp":"1768250243714","event_type":"price_change"}}
{"schema_version":1,"source":"clob_ws_market","recv_ts_ns":1768250243770432489,"event_type":"price_change","market":"0x2a12fd3d8235c25c062dc9652970ef9f635636c4018df0909e1a51c673e125cb","server_ts_ms":1768250243714,"raw":{"market":"0x2a12fd3d8235c25c062dc9652970ef9f635636c4018df0909e1a51c673e125cb","price_changes":[{"asset_id":"63670753354844494163057275310194312729998307779831462269530137743341854359908","price":"0.83","size":"185.02","side":"BUY","hash":"517430a54f58a011af8b4d87e653358684e4ce1e","best_bid":"0.85","best_ask":"0.86"},{"asset_id":"56386988715176239099720172290594769295756680374928571099138069977179519358166","price":"0.17","size":"185.02","side":"SELL","hash":"d5c0216f0bf1f7a498d82ab0b0f23f7aedda5529","best_bid":"0.14","best_ask":"0.15"}],"timestamp":"1768250243714","event_type":"price_change"}}
{"schema_version":1,"source":"clob_ws_market","recv_ts_ns":1768250243774878216,"event_type":"price_change","market":"0x2a12fd3d8235c25c062dc9652970ef9f635636c4018df0909e1a51c673e125cb","server_ts_ms":1768250243715,"raw":{"market":"0x2a12fd3d8235c25c062dc9652970ef9f635636c4018df0909e1a51c673e125cb","price_changes":[{"asset_id":"63670753354844494163057275310194312729998307779831462269530137743341854359908","price":"0.84","size":"267","side":"BUY","hash":"0f28d62233287039defbec8824b32451b22b9ece","best_bid":"0.85","best_ask":"0.86"},{"asset_id":"56386988715176239099720172290594769295756680374928571099138069977179519358166","price":"0.16","size":"267","side":"SELL","hash":"8292d85c1f36d01619c65f4b9f50a3724a51240a","best_bid":"0.14","best_ask":"0.15"}],"timestamp":"1768250243715","event_type":"price_change"}}
{"schema_version":1,"source":"clob_ws_market","recv_ts_ns":1768250243778920855,"event_type":"price_change","market":"0x2a12fd3d8235c25c062dc9652970ef9f635636c4018df0909e1a51c673e125cb","server_ts_ms":1768250243717,"raw":{"market":"0x2a12fd3d8235c25c062dc9652970ef9f635636c4018df0909e1a51c673e125cb","price_changes":[{"asset_id":"63670753354844494163057275310194312729998307779831462269530137743341854359908","price":"0.86","size":"235.43","side":"SELL","hash":"24f98902408b59d2d186a308ecabe13abe681076","best_bid":"0.85","best_ask":"0.86"},{"asset_id":"56386988715176239099720172290594769295756680374928571099138069977179519358166","price":"0.14","size":"235.43","side":"BUY","hash":"24c6c14d7f82fa322e1b85d9f72bb252c1bd859e","best_bid":"0.14","best_ask":"0.15"}],"timestamp":"1768250243717","event_type":"price_change"}}
{"schema_version":1,"source":"clob_ws_market","recv_ts_ns":1768250243783852319,"event_type":"price_change","market":"0x2a12fd3d8235c25c062dc9652970ef9f635636c4018df0909e1a51c673e125cb","server_ts_ms":1768250243717,"raw":{"market":"0x2a12fd3d8235c25c062dc9652970ef9f635636c4018df0909e1a51c673e125cb","price_changes":[{"asset_id":"63670753354844494163057275310194312729998307779831462269530137743341854359908","price":"0.84","size":"257","side":"BUY","hash":"cc4617a3991eb740a43358d1ae699411cc2a381f","best_bid":"0.85","best_ask":"0.86"},{"asset_id":"56386988715176239099720172290594769295756680374928571099138069977179519358166","price":"0.16","size":"257","side":"SELL","hash":"089404d1809b78ea34ffff8f7bf6421dfb658582","best_bid":"0.14","best_ask":"0.15"}],"timestamp":"1768250243717","event_type":"price_change"}}
{"schema_version":1,"source":"clob_ws_market","recv_ts_ns":1768250243788331372,"event_type":"price_change","market":"0x2a12fd3d8235c25c062dc9652970ef9f635636c4018df0909e1a51c673e125cb","server_ts_ms":1768250243718,"raw":{"market":"0x2a12fd3d8235c25c062dc9652970ef9f635636c4018df0909e1a51c673e125cb","price_changes":[{"asset_id":"56386988715176239099720172290594769295756680374928571099138069977179519358166","price":"0.12","size":"1420.75","side":"BUY","hash":"0181b2df58f430586521947cf25a311912d95cdc","best_bid":"0.14","best_ask":"0.15"},{"asset_id":"63670753354844494163057275310194312729998307779831462269530137743341854359908","price":"0.88","size":"1420.75","side":"SELL","hash":"9282cf5811e8fd9768bc4d4034c7a846b153364e","best_bid":"0.85","best_ask":"0.86"}],"timestamp":"1768250243718","event_type":"price_change"}}
{"schema_version":1,"source":"clob_ws_market","recv_ts_ns":1768250243792759043,"event_type":"price_change","market":"0x2a12fd3d8235c25c062dc9652970ef9f635636c4018df0909e1a51c673e125cb","server_ts_ms":1768250243718,"raw":{"market":"0x2a12fd3d8235c25c062dc9652970ef9f635636c4018df0909e1a51c673e125cb","price_changes":[{"asset_id":"63670753354844494163057275310194312729998307779831462269530137743341854359908","price":"0.84","size":"247","side":"BUY","hash":"30940e95b5df3f717cb536d90d75722b4a4ee093","best_bid":"0.85","best_ask":"0.86"},{"asset_id":"56386988715176239099720172290594769295756680374928571099138069977179519358166","price":"0.16","size":"247","side":"SELL","hash":"b6111440e4858aa917444d174a6d5589c88a0ce3","best_bid":"0.14","best_ask":"0.15"}],"timestamp":"1768250243718","event_type":"price_change"}}
{"schema_version":1,"source":"clob_ws_market","recv_ts_ns":1768250243798265721,"event_type":"price_change","market":"0x2a12fd3d8235c25c062dc9652970ef9f635636c4018df0909e1a51c673e125cb","server_ts_ms":1768250243719,"raw":{"market":"0x2a12fd3d8235c25c062dc9652970ef9f635636c4018df0909e1a51c673e125cb","price_changes":[{"asset_id":"56386988715176239099720172290594769295756680374928571099138069977179519358166","price":"0.11","size":"885.5","side":"BUY","hash":"50813b7388683065701dca7a68739d641fbdac94","best_bid":"0.14","best_ask":"0.15"},{"asset_id":"63670753354844494163057275310194312729998307779831462269530137743341854359908","price":"0.89","size":"885.5","side":"SELL","hash":"20a453d5c83a256a2575bfa1659f60275978ebb9","best_bid":"0.85","best_ask":"0.86"}],"timestamp":"1768250243719","event_type":"price_change"}}
{"schema_version":1,"source":"clob_ws_market","recv_ts_ns":1768250243802452370,"event_type":"price_change","market":"0x2a12fd3d8235c25c062dc9652970ef9f635636c4018df0909e1a51c673e125cb","server_ts_ms":1768250243720,"raw":{"market":"0x2a12fd3d8235c25c062dc9652970ef9f635636c4018df0909e1a51c673e125cb","price_changes":[{"asset_id":"56386988715176239099720172290594769295756680374928571099138069977179519358166","price":"0.14","size":"225.43","side":"BUY","hash":"5f5de4e14950c66ad7e0ad49bbb2347451f928e0","best_bid":"0.14","best_ask":"0.15"},{"asset_id":"63670753354844494163057275310194312729998307779831462269530137743341854359908","price":"0.86","size":"225.43","side":"SELL","hash":"2b243bf9859ad92c871c1cf1703f65a8fec86a27","best_bid":"0.85","best_ask":"0.86"}],"timestamp":"1768250243720","event_type":"price_change"}}
{"schema_version":1,"source":"clob_ws_market","recv_ts_ns":1768250243807593674,"event_type":"price_change","market":"0x2a12fd3d8235c25c062dc9652970ef9f635636c4018df0909e1a51c673e125cb","server_ts_ms":1768250243720,"raw":{"market":"0x2a12fd3d8235c25c062dc9652970ef9f635636c4018df0909e1a51c673e125cb","price_changes":[{"asset_id":"63670753354844494163057275310194312729998307779831462269530137743341854359908","price":"0.84","size":"237","side":"BUY","hash":"d725313091c059d36e28049de6e1e52bbc9203ac","best_bid":"0.85","best_ask":"0.86"},{"asset_id":"56386988715176239099720172290594769295756680374928571099138069977179519358166","price":"0.16","size":"237","side":"SELL","hash":"981dcc437c86c2179a07b655aba6266f3713b12a","best_bid":"0.14","best_ask":"0.15"}],"timestamp":"1768250243720","event_type":"price_change"}}
{"schema_version":1,"source":"clob_ws_market","recv_ts_ns":1768250243812861980,"event_type":"price_change","market":"0x2a12fd3d8235c25c062dc9652970ef9f635636c4018df0909e1a51c673e125cb","server_ts_ms":1768250243721,"raw":{"market":"0x2a12fd3d8235c25c062dc9652970ef9f635636c4018df0909e1a51c673e125cb","price_changes":[{"asset_id":"63670753354844494163057275310194312729998307779831462269530137743341854359908","price":"0.84","size":"227","side":"BUY","hash":"e59e2195afe8a6d760e4902b19f7eba14fd0c1f4","best_bid":"0.85","best_ask":"0.86"},{"asset_id":"56386988715176239099720172290594769295756680374928571099138069977179519358166","price":"0.16","size":"227","side":"SELL","hash":"efd83a36829695b10ac751e7eeccacf8458ab053","best_bid":"0.14","best_ask":"0.15"}],"timestamp":"1768250243721","event_type":"price_change"}}
{"schema_version":1,"source":"clob_ws_market","recv_ts_ns":1768250243817856960,"event_type":"price_change","market":"0x2a12fd3d8235c25c062dc9652970ef9f635636c4018df0909e1a51c673e125cb","server_ts_ms":1768250243722,"raw":{"market":"0x2a12fd3d8235c25c062dc9652970ef9f635636c4018df0909e1a51c673e125cb","price_changes":[{"asset_id":"63670753354844494163057275310194312729998307779831462269530137743341854359908","price":"0.84","size":"217","side":"BUY","hash":"a05975ef6facf81f18a31e4ad55c61e9ac21587b","best_bid":"0.85","best_ask":"0.86"},{"asset_id":"56386988715176239099720172290594769295756680374928571099138069977179519358166","price":"0.16","size":"217","side":"SELL","hash":"8a91dd5f8626e6ab12f9f2fb52aa880038cd27fc","best_bid":"0.14","best_ask":"0.15"}],"timestamp":"1768250243722","event_type":"price_change"}}
{"schema_version":1,"source":"clob_ws_market","recv_ts_ns":1768250243822296009,"event_type":"price_change","market":"0x2a12fd3d8235c25c062dc9652970ef9f635636c4018df0909e1a51c673e125cb","server_ts_ms":1768250243722,"raw":{"market":"0x2a12fd3d8235c25c062dc9652970ef9f635636c4018df0909e1a51c673e125cb","price_changes":[{"asset_id":"63670753354844494163057275310194312729998307779831462269530137743341854359908","price":"0.84","size":"207","side":"BUY","hash":"a56c9feb604894ee7a927b14646cd47804b494c2","best_bid":"0.85","best_ask":"0.86"},{"asset_id":"56386988715176239099720172290594769295756680374928571099138069977179519358166","price":"0.16","size":"207","side":"SELL","hash":"b03489cdf7203d2ab4b4fa1ac23d60bc676724d0","best_bid":"0.14","best_ask":"0.15"}],"timestamp":"1768250243722","event_type":"price_change"}}
{"schema_version":1,"source":"clob_ws_market","recv_ts_ns":1768250243826915773,"event_type":"price_change","market":"0x2a12fd3d8235c25c062dc9652970ef9f635636c4018df0909e1a51c673e125cb","server_ts_ms":1768250243723,"raw":{"market":"0x2a12fd3d8235c25c062dc9652970ef9f635636c4018df0909e1a51c673e125cb","price_changes":[{"asset_id":"56386988715176239099720172290594769295756680374928571099138069977179519358166","price":"0.17","size":"175.02","side":"SELL","hash":"fb24799f784f339e4ce0730c888411ba6e30fb41","best_bid":"0.14","best_ask":"0.15"},{"asset_id":"63670753354844494163057275310194312729998307779831462269530137743341854359908","price":"0.83","size":"175.02","side":"BUY","hash":"5b980a55058b1ab9bc67cb216e12380e8d9e94b4","best_bid":"0.85","best_ask":"0.86"}],"timestamp":"1768250243723","event_type":"price_change"}}
{"schema_version":1,"source":"clob_ws_market","recv_ts_ns":1768250243830919027,"event_type":"price_change","market":"0x2a12fd3d8235c25c062dc9652970ef9f635636c4018df0909e1a51c673e125cb","server_ts_ms":1768250243724,"raw":{"market":"0x2a12fd3d8235c25c062dc9652970ef9f635636c4018df0909e1a51c673e125cb","price_changes":[{"asset_id":"56386988715176239099720172290594769295756680374928571099138069977179519358166","price":"0.11","size":"875.5","side":"BUY","hash":"db353d975e34bb9a1f68667b27b60d501a3a92cf","best_bid":"0.14","best_ask":"0.15"},{"asset_id":"63670753354844494163057275310194312729998307779831462269530137743341854359908","price":"0.89","size":"875.5","side":"SELL","hash":"9ed7c0b302d1f795e2943b2585e34e7622a93404","best_bid":"0.85","best_ask":"0.86"}],"timestamp":"1768250243724","event_type":"price_change"}}
{"schema_version":1,"source":"clob_ws_market","recv_ts_ns":1768250243835172432,"event_type":"price_change","market":"0x2a12fd3d8235c25c062dc9652970ef9f635636c4018df0909e1a51c673e125cb","server_ts_ms":1768250243725,"raw":{"market":"0x2a12fd3d8235c25c062dc9652970ef9f635636c4018df0909e1a51c673e125cb","price_changes":[{"asset_id":"56386988715176239099720172290594769295756680374928571099138069977179519358166","price":"0.14","size":"232.93","side":"BUY","hash":"19d70f2f4b69eaf315ae587418eef18ef207b463","best_bid":"0.14","best_ask":"0.15"},{"asset_id":"63670753354844494163057275310194312729998307779831462269530137743341854359908","price":"0.86","size":"232.93","side":"SELL","hash":"01ea9aa26dfb58855d661731030b48f7e8b764e2","best_bid":"0.85","best_ask":"0.86"}],"timestamp":"1768250243725","event_type":"price_change"}}
{"schema_version":1,"source":"clob_ws_market","recv_ts_ns":1768250243839567453,"event_type":"price_change","market":"0x2a12fd3d8235c25c062dc9652970ef9f635636c4018df0909e1a51c673e125cb","server_ts_ms":1768250243725,"raw":{"market":"0x2a12fd3d8235c25c062dc9652970ef9f635636c4018df0909e1a51c673e125cb","price_changes":[{"asset_id":"56386988715176239099720172290594769295756680374928571099138069977179519358166","price":"0.11","size":"865.5","side":"BUY","hash":"f80814c4551ac9b6006d61580eb46a8f05cc794e","best_bid":"0.14","best_ask":"0.15"},{"asset_id":"63670753354844494163057275310194312729998307779831462269530137743341854359908","price":"0.89","size":"865.5","side":"SELL","hash":"b464ddc60a86ece77983b6354b60da1c1fdbf68f","best_bid":"0.85","best_ask":"0.86"}],"timestamp":"1768250243725","event_type":"price_change"}}
{"schema_version":1,"source":"clob_ws_market","recv_ts_ns":1768250243844591531,"event_type":"price_change","market":"0x2a12fd3d8235c25c062dc9652970ef9f635636c4018df0909e1a51c673e125cb","server_ts_ms":1768250243726,"raw":{"market":"0x2a12fd3d8235c25c062dc9652970ef9f635636c4018df0909e1a51c673e125cb","price_changes":[{"asset_id":"56386988715176239099720172290594769295756680374928571099138069977179519358166","price":"0.1","size":"3452","side":"BUY","hash":"fe04ca1911ce87106095c1f927c5369db905ed51","best_bid":"0.14","best_ask":"0.15"},{"asset_id":"63670753354844494163057275310194312729998307779831462269530137743341854359908","price":"0.9","size":"3452","side":"SELL","hash":"d86fde7698f7b48edc6105de57965bbbd0c355a3","best_bid":"0.85","best_ask":"0.86"}],"timestamp":"1768250243726","event_type":"price_change"}}
{"schema_version":1,"source":"clob_ws_market","recv_ts_ns":1768250243850301647,"event_type":"price_change","market":"0x2a12fd3d8235c25c062dc9652970ef9f635636c4018df0909e1a51c673e125cb","server_ts_ms":1768250243727,"raw":{"market":"0x2a12fd3d8235c25c062dc9652970ef9f635636c4018df0909e1a51c673e125cb","price_changes":[{"asset_id":"56386988715176239099720172290594769295756680374928571099138069977179519358166","price":"0.09","size":"1317","side":"BUY","hash":"deb24969c1fdee1a6f3339de13887ca23a25f9c9","best_bid":"0.14","best_ask":"0.15"},{"asset_id":"63670753354844494163057275310194312729998307779831462269530137743341854359908","price":"0.91","size":"1317","side":"SELL","hash":"cece011d4101338cbf84ede5dd1603b4dc585333","best_bid":"0.85","best_ask":"0.86"}],"timestamp":"1768250243727","event_type":"price_change"}}
{"schema_version":1,"source":"clob_ws_market","recv_ts_ns":1768250243855677111,"event_type":"price_change","market":"0x2a12fd3d8235c25c062dc9652970ef9f635636c4018df0909e1a51c673e125cb","server_ts_ms":1768250243731,"raw":{"market":"0x2a12fd3d8235c25c062dc9652970ef9f635636c4018df0909e1a51c673e125cb","price_changes":[{"asset_id":"63670753354844494163057275310194312729998307779831462269530137743341854359908","price":"0.86","size":"252.93","side":"SELL","hash":"51d410c24aadfcf9ecbfec8948dacf33be0f247a","best_bid":"0.85","best_ask":"0.86"},{"asset_id":"56386988715176239099720172290594769295756680374928571099138069977179519358166","price":"0.14","size":"252.93","side":"BUY","hash":"76b18d3e06fa129b6d9f01097321340fd310dfcf","best_bid":"0.14","best_ask":"0.15"}],"timestamp":"1768250243731","event_type":"price_change"}}
{"schema_version":1,"source":"clob_ws_market","recv_ts_ns":1768250243860705342,"event_type":"price_change","market":"0x2a12fd3d8235c25c062dc9652970ef9f635636c4018df0909e1a51c673e125cb","server_ts_ms":1768250243736,"raw":{"market":"0x2a12fd3d8235c25c062dc9652970ef9f635636c4018df0909e1a51c673e125cb","price_changes":[{"asset_id":"63670753354844494163057275310194312729998307779831462269530137743341854359908","price":"0.87","size":"331","side":"SELL","hash":"f877b3cce74148253d1c7bd6af5852af7036b575","best_bid":"0.85","best_ask":"0.86"},{"asset_id":"56386988715176239099720172290594769295756680374928571099138069977179519358166","price":"0.13","size":"331","side":"BUY","hash":"62a61de3473425a6914dc066b807f06fce2899e8","best_bid":"0.14","best_ask":"0.15"}],"timestamp":"1768250243736","event_type":"price_change"}}
{"schema_version":1,"source":"clob_ws_market","recv_ts_ns":1768250243864619284,"event_type":"price_change","market":"0x2a12fd3d8235c25c062dc9652970ef9f635636c4018df0909e1a51c673e125cb","server_ts_ms":1768250243743,"raw":{"market":"0x2a12fd3d8235c25c062dc9652970ef9f635636c4018df0909e1a51c673e125cb","price_changes":[{"asset_id":"63670753354844494163057275310194312729998307779831462269530137743341854359908","price":"0.82","size":"171","side":"BUY","hash":"5658fa5b648ee874e4d97c364d02a4b8bc6d725f","best_bid":"0.85","best_ask":"0.86"},{"asset_id":"56386988715176239099720172290594769295756680374928571099138069977179519358166","price":"0.18","size":"171","side":"SELL","hash":"063ecae6c22c1008cffb47a9886e7cda4f97db3e","best_bid":"0.14","best_ask":"0.15"}],"timestamp":"1768250243743","event_type":"price_change"}}
{"schema_version":1,"source":"clob_ws_market","recv_ts_ns":1768250243868408571,"event_type":"price_change","market":"0x2a12fd3d8235c25c062dc9652970ef9f635636c4018df0909e1a51c673e125cb","server_ts_ms":1768250243747,"raw":{"market":"0x2a12fd3d8235c25c062dc9652970ef9f635636c4018df0909e1a51c673e125cb","price_changes":[{"asset_id":"63670753354844494163057275310194312729998307779831462269530137743341854359908","price":"0.85","size":"466.65","side":"BUY","hash":"a7c099625ae34b295f4b325880ecc54687261b74","best_bid":"0.85","best_ask":"0.86"},{"asset_id":"56386988715176239099720172290594769295756680374928571099138069977179519358166","price":"0.15","size":"466.65","side":"SELL","hash":"a81e41345d3201d36ae40ba09a88539db75700c4","best_bid":"0.14","best_ask":"0.15"}],"timestamp":"1768250243747","event_type":"price_change"}}
{"schema_version":1,"source":"clob_ws_market","recv_ts_ns":1768250243876523469,"event_type":"price_change","market":"0x2a12fd3d8235c25c062dc9652970ef9f635636c4018df0909e1a51c673e125cb","server_ts_ms":1768250243750,"raw":{"market":"0x2a12fd3d8235c25c062dc9652970ef9f635636c4018df0909e1a51c673e125cb","price_changes":[{"asset_id":"56386988715176239099720172290594769295756680374928571099138069977179519358166","price":"0.11","size":"875.5","side":"BUY","hash":"1bb91619e4c07f697e5be10e4c95027f9bd7a397","best_bid":"0.14","best_ask":"0.15"},{"asset_id":"63670753354844494163057275310194312729998307779831462269530137743341854359908","price":"0.89","size":"875.5","side":"SELL","hash":"5d3ca995a4b620c5e24e33b22d9d11dabe406028","best_bid":"0.85","best_ask":"0.86"}],"timestamp":"1768250243750","event_type":"price_change"}}
{"schema_version":1,"source":"clob_ws_market","recv_ts_ns":1768250243879371495,"event_type":"price_change","market":"0x2a12fd3d8235c25c062dc9652970ef9f635636c4018df0909e1a51c673e125cb","server_ts_ms":1768250243753,"raw":{"market":"0x2a12fd3d8235c25c062dc9652970ef9f635636c4018df0909e1a51c673e125cb","price_changes":[{"asset_id":"63670753354844494163057275310194312729998307779831462269530137743341854359908","price":"0.82","size":"871","side":"BUY","hash":"12aefec44a7f027786b6f99f532b0e1991e5089c","best_bid":"0.85","best_ask":"0.86"},{"asset_id":"56386988715176239099720172290594769295756680374928571099138069977179519358166","price":"0.18","size":"871","side":"SELL","hash":"799adf3dddcac2c54b1c9e134df2a5c34d0b42b7","best_bid":"0.14","best_ask":"0.15"}],"timestamp":"1768250243753","event_type":"price_change"}}
{"schema_version":1,"source":"clob_ws_market","recv_ts_ns":1768250243885370550,"event_type":"price_change","market":"0x2a12fd3d8235c25c062dc9652970ef9f635636c4018df0909e1a51c673e125cb","server_ts_ms":1768250243756,"raw":{"market":"0x2a12fd3d8235c25c062dc9652970ef9f635636c4018df0909e1a51c673e125cb","price_changes":[{"asset_id":"63670753354844494163057275310194312729998307779831462269530137743341854359908","price":"0.83","size":"185.02","side":"BUY","hash":"7ea4b85cb72b68a46950d7770a6d94973faeca53","best_bid":"0.85","best_ask":"0.86"},{"asset_id":"56386988715176239099720172290594769295756680374928571099138069977179519358166","price":"0.17","size":"185.02","side":"SELL","hash":"a0f78f4e3194defaeb6bc9aeb304b086894c47ac","best_bid":"0.14","best_ask":"0.15"}],"timestamp":"1768250243756","event_type":"price_change"}}
{"schema_version":1,"source":"clob_ws_market","recv_ts_ns":1768250243888399245,"event_type":"price_change","market":"0x2a12fd3d8235c25c062dc9652970ef9f635636c4018df0909e1a51c673e125cb","server_ts_ms":1768250243757,"raw":{"market":"0x2a12fd3d8235c25c062dc9652970ef9f635636c4018df0909e1a51c673e125cb","price_changes":[{"asset_id":"56386988715176239099720172290594769295756680374928571099138069977179519358166","price":"0.13","size":"341","side":"BUY","hash":"a27a4c400d416a21d4e3f7ce21276a0e2692a12f","best_bid":"0.14","best_ask":"0.15"},{"asset_id":"63670753354844494163057275310194312729998307779831462269530137743341854359908","price":"0.87","size":"341","side":"SELL","hash":"475d663f7c7d5c200e62ed30e301bf082745f719","best_bid":"0.85","best_ask":"0.86"}],"timestamp":"1768250243757","event_type":"price_change"}}
{"schema_version":1,"source":"clob_ws_market","recv_ts_ns":1768250243892855834,"event_type":"price_change","market":"0x2a12fd3d8235c25c062dc9652970ef9f635636c4018df0909e1a51c673e125cb","server_ts_ms":1768250243758,"raw":{"market":"0x2a12fd3d8235c25c062dc9652970ef9f635636c4018df0909e1a51c673e125cb","price_changes":[{"asset_id":"63670753354844494163057275310194312729998307779831462269530137743341854359908","price":"0.84","size":"217","side":"BUY","hash":"c13e0f8d9cf5218369546e779d56f11f0250a98d","best_bid":"0.85","best_ask":"0.86"},{"asset_id":"56386988715176239099720172290594769295756680374928571099138069977179519358166","price":"0.16","size":"217","side":"SELL","hash":"5172cd22b937113bfbbedc12604c3262b3b9f064","best_bid":"0.14","best_ask":"0.15"}],"timestamp":"1768250243758","event_type":"price_change"}}
{"schema_version":1,"source":"clob_ws_market","recv_ts_ns":1768250243896984396,"event_type":"price_change","market":"0x2a12fd3d8235c25c062dc9652970ef9f635636c4018df0909e1a51c673e125cb","server_ts_ms":1768250243759,"raw":{"market":"0x2a12fd3d8235c25c062dc9652970ef9f635636c4018df0909e1a51c673e125cb","price_changes":[{"asset_id":"56386988715176239099720172290594769295756680374928571099138069977179519358166","price":"0.12","size":"1430.75","side":"BUY","hash":"0fef938c2256206208fdab6cb1bc9f730bc442c3","best_bid":"0.14","best_ask":"0.15"},{"asset_id":"63670753354844494163057275310194312729998307779831462269530137743341854359908","price":"0.88","size":"1430.75","side":"SELL","hash":"2fd33bad7bd7114de6e5c2c51256dbb8bd399783","best_bid":"0.85","best_ask":"0.86"}],"timestamp":"1768250243759","event_type":"price_change"}}
{"schema_version":1,"source":"clob_ws_market","recv_ts_ns":1768250243900864240,"event_type":"price_change","market":"0x2a12fd3d8235c25c062dc9652970ef9f635636c4018df0909e1a51c673e125cb","server_ts_ms":1768250243759,"raw":{"market":"0x2a12fd3d8235c25c062dc9652970ef9f635636c4018df0909e1a51c673e125cb","price_changes":[{"asset_id":"56386988715176239099720172290594769295756680374928571099138069977179519358166","price":"0.14","size":"262.93","side":"BUY","hash":"96a3f264e8effe686a990f5dccdcf4b04fa2578f","best_bid":"0.14","best_ask":"0.15"},{"asset_id":"63670753354844494163057275310194312729998307779831462269530137743341854359908","price":"0.86","size":"262.93","side":"SELL","hash":"2c474f557bc133c2dcb89a5ea361a908959143d6","best_bid":"0.85","best_ask":"0.86"}],"timestamp":"1768250243759","event_type":"price_change"}}
{"schema_version":1,"source":"clob_ws_market","recv_ts_ns":1768250243904538573,"event_type":"price_change","market":"0x2a12fd3d8235c25c062dc9652970ef9f635636c4018df0909e1a51c673e125cb","server_ts_ms":1768250243760,"raw":{"market":"0x2a12fd3d8235c25c062dc9652970ef9f635636c4018df0909e1a51c673e125cb","price_changes":[{"asset_id":"63670753354844494163057275310194312729998307779831462269530137743341854359908","price":"0.84","size":"227","side":"BUY","hash":"baf04e077181ece93493ff94e27d30ec7bcdfccc","best_bid":"0.85","best_ask":"0.86"},{"asset_id":"56386988715176239099720172290594769295756680374928571099138069977179519358166","price":"0.16","size":"227","side":"SELL","hash":"3d67b8281b9a1fba599e4f6803e695ecdd2c73bf","best_bid":"0.14","best_ask":"0.15"}],"timestamp":"1768250243760","event_type":"price_change"}}
{"schema_version":1,"source":"clob_ws_market","recv_ts_ns":1768250243907964669,"event_type":"price_change","market":"0x2a12fd3d8235c25c062dc9652970ef9f635636c4018df0909e1a51c673e125cb","server_ts_ms":1768250243761,"raw":{"market":"0x2a12fd3d8235c25c062dc9652970ef9f635636c4018df0909e1a51c673e125cb","price_changes":[{"asset_id":"56386988715176239099720172290594769295756680374928571099138069977179519358166","price":"0.1","size":"3462","side":"BUY","hash":"ddd094df245b469aa0031b74624d293200765d48","best_bid":"0.14","best_ask":"0.15"},{"asset_id":"63670753354844494163057275310194312729998307779831462269530137743341854359908","price":"0.9","size":"3462","side":"SELL","hash":"28fd89cf601dbafcab3e0cdcb7d2be8f54f859d1","best_bid":"0.85","best_ask":"0.86"}],"timestamp":"1768250243761","event_type":"price_change"}}
{"schema_version":1,"source":"clob_ws_market","recv_ts_ns":1768250243911697927,"event_type":"price_change","market":"0x2a12fd3d8235c25c062dc9652970ef9f635636c4018df0909e1a51c673e125cb","server_ts_ms":1768250243761,"raw":{"market":"0x2a12fd3d8235c25c062dc9652970ef9f635636c4018df0909e1a51c673e125cb","price_changes":[{"asset_id":"56386988715176239099720172290594769295756680374928571099138069977179519358166","price":"0.11","size":"885.5","side":"BUY","hash":"59d9dc1e15fac71caa1a0c64fc1ff3215728b00e","best_bid":"0.14","best_ask":"0.15"},{"asset_id":"63670753354844494163057275310194312729998307779831462269530137743341854359908","price":"0.89","size":"885.5","side":"SELL","hash":"a0e1ad1e2f23f24841840521cc88e6ea25600c1d","best_bid":"0.85","best_ask":"0.86"}],"timestamp":"1768250243761","event_type":"price_change"}}
{"schema_version":1,"source":"clob_ws_market","recv_ts_ns":1768250243915272131,"event_type":"price_change","market":"0x2a12fd3d8235c25c062dc9652970ef9f635636c4018df0909e1a51c673e125cb","server_ts_ms":1768250243762,"raw":{"market":"0x2a12fd3d8235c25c062dc9652970ef9f635636c4018df0909e1a51c673e125cb","price_changes":[{"asset_id":"63670753354844494163057275310194312729998307779831462269530137743341854359908","price":"0.84","size":"237","side":"BUY","hash":"4edf5711f843dc417d8c16366f16387621ad7154","best_bid":"0.85","best_ask":"0.86"},{"asset_id":"56386988715176239099720172290594769295756680374928571099138069977179519358166","price":"0.16","size":"237","side":"SELL","hash":"48d2ba24dbb75c120bef6af34679b87e15c1b44f","best_bid":"0.14","best_ask":"0.15"}],"timestamp":"1768250243762","event_type":"price_change"}}
{"schema_version":1,"source":"clob_ws_market","recv_ts_ns":1768250243919269941,"event_type":"price_change","market":"0x2a12fd3d8235c25c062dc9652970ef9f635636c4018df0909e1a51c673e125cb","server_ts_ms":1768250243763,"raw":{"market":"0x2a12fd3d8235c25c062dc9652970ef9f635636c4018df0909e1a51c673e125cb","price_changes":[{"asset_id":"63670753354844494163057275310194312729998307779831462269530137743341854359908","price":"0.84","size":"247","side":"BUY","hash":"434135cafb0735d384ed54bcedddfb007d0ce6d7","best_bid":"0.85","best_ask":"0.86"},{"asset_id":"56386988715176239099720172290594769295756680374928571099138069977179519358166","price":"0.16","size":"247","side":"SELL","hash":"7f64613f97a4f5ca0dcfbc6de4ed67538d2ab5d6","best_bid":"0.14","best_ask":"0.15"}],"timestamp":"1768250243763","event_type":"price_change"}}
{"schema_version":1,"source":"clob_ws_market","recv_ts_ns":1768250243922901464,"event_type":"price_change","market":"0x2a12fd3d8235c25c062dc9652970ef9f635636c4018df0909e1a51c673e125cb","server_ts_ms":1768250243764,"raw":{"market":"0x2a12fd3d8235c25c062dc9652970ef9f635636c4018df0909e1a51c673e125cb","price_changes":[{"asset_id":"56386988715176239099720172290594769295756680374928571099138069977179519358166","price":"0.11","size":"895.5","side":"BUY","hash":"fcb2faa052556de77ed882ab12b17a4b54c2aeed","best_bid":"0.14","best_ask":"0.15"},{"asset_id":"63670753354844494163057275310194312729998307779831462269530137743341854359908","price":"0.89","size":"895.5","side":"SELL","hash":"3638812262e0fea4a315ec8583fb91ef1e77f7bd","best_bid":"0.85","best_ask":"0.86"}],"timestamp":"1768250243764","event_type":"price_change"}}
{"schema_version":1,"source":"clob_ws_market","recv_ts_ns":1768250243926343518,"event_type":"price_change","market":"0x2a12fd3d8235c25c062dc9652970ef9f635636c4018df0909e1a51c673e125cb","server_ts_ms":1768250243765,"raw":{"market":"0x2a12fd3d8235c25c062dc9652970ef9f635636c4018df0909e1a51c673e125cb","price_changes":[{"asset_id":"56386988715176239099720172290594769295756680374928571099138069977179519358166","price":"0.12","size":"730.75","side":"BUY","hash":"6587f42a58bac432b52918bd88d55cbc93b84f55","best_bid":"0.14","best_ask":"0.15"},{"asset_id":"63670753354844494163057275310194312729998307779831462269530137743341854359908","price":"0.88","size":"730.75","side":"SELL","hash":"0d807b89f69489f77d0a36dd5332368a41d1ec9d","best_bid":"0.85","best_ask":"0.86"}],"timestamp":"1768250243765","event_type":"price_change"}}
{"schema_version":1,"source":"clob_ws_market","recv_ts_ns":1768250243929688473,"event_type":"price_change","market":"0x2a12fd3d8235c25c062dc9652970ef9f635636c4018df0909e1a51c673e125cb","server_ts_ms":1768250243765,"raw":{"market":"0x2a12fd3d8235c25c062dc9652970ef9f635636c4018df0909e1a51c673e125cb","price_changes":[{"asset_id":"63670753354844494163057275310194312729998307779831462269530137743341854359908","price":"0.84","size":"257","side":"BUY","hash":"892737c1857284ad632fa3bfba400f41b25f8ece","best_bid":"0.85","best_ask":"0.86"},{"asset_id":"56386988715176239099720172290594769295756680374928571099138069977179519358166","price":"0.16","size":"257","side":"SELL","hash":"c8ae4b3bd2b266036a11507b8511d8fdc3958e17","best_bid":"0.14","best_ask":"0.15"}],"timestamp":"1768250243765","event_type":"price_change"}}
{"schema_version":1,"source":"clob_ws_market","recv_ts_ns":1768250243932153083,"event_type":"price_change","market":"0x2a12fd3d8235c25c062dc9652970ef9f635636c4018df0909e1a51c673e125cb","server_ts_ms":1768250243766,"raw":{"market":"0x2a12fd3d8235c25c062dc9652970ef9f635636c4018df0909e1a51c673e125cb","price_changes":[{"asset_id":"56386988715176239099720172290594769295756680374928571099138069977179519358166","price":"0.12","size":"710.75","side":"BUY","hash":"c39dd901afd53e7352b3e5df8d6dafe7e9d1258e","best_bid":"0.14","best_ask":"0.15"},{"asset_id":"63670753354844494163057275310194312729998307779831462269530137743341854359908","price":"0.88","size":"710.75","side":"SELL","hash":"4878699e462765238b5c6057b1fa40c8b7c1d786","best_bid":"0.85","best_ask":"0.86"}],"timestamp":"1768250243766","event_type":"price_change"}}
{"schema_version":1,"source":"clob_ws_market","recv_ts_ns":1768250243934370836,"event_type":"price_change","market":"0x2a12fd3d8235c25c062dc9652970ef9f635636c4018df0909e1a51c673e125cb","server_ts_ms":1768250243767,"raw":{"market":"0x2a12fd3d8235c25c062dc9652970ef9f635636c4018df0909e1a51c673e125cb","price_changes":[{"asset_id":"63670753354844494163057275310194312729998307779831462269530137743341854359908","price":"0.67","size":"906.8","side":"BUY","hash":"4866705dfebbdd7d8f511885c2a4695775e6e01b","best_bid":"0.85","best_ask":"0.86"},{"asset_id":"56386988715176239099720172290594769295756680374928571099138069977179519358166","price":"0.33","size":"906.8","side":"SELL","hash":"00c9895775a1344b40bfbfb0514c470623f0f7c1","best_bid":"0.14","best_ask":"0.15"}],"timestamp":"1768250243767","event_type":"price_change"}}
{"schema_version":1,"source":"clob_ws_market","recv_ts_ns":1768250243936452225,"event_type":"price_change","market":"0x2a12fd3d8235c25c062dc9652970ef9f635636c4018df0909e1a51c673e125cb","server_ts_ms":1768250243768,"raw":{"market":"0x2a12fd3d8235c25c062dc9652970ef9f635636c4018df0909e1a51c673e125cb","price_changes":[{"asset_id":"63670753354844494163057275310194312729998307779831462269530137743341854359908","price":"0.84","size":"267","side":"BUY","hash":"6eff24f8e2b4ae501b0bbaecf167b64d0504884e","best_bid":"0.85","best_ask":"0.86"},{"asset_id":"56386988715176239099720172290594769295756680374928571099138069977179519358166","price":"0.16","size":"267","side":"SELL","hash":"b3e75ef62170c29362aa1b2f896ccff8882cfa4b","best_bid":"0.14","best_ask":"0.15"}],"timestamp":"1768250243768","event_type":"price_change"}}
{"schema_version":1,"source":"clob_ws_market","recv_ts_ns":1768250243938349634,"event_type":"price_change","market":"0x2a12fd3d8235c25c062dc9652970ef9f635636c4018df0909e1a51c673e125cb","server_ts_ms":1768250243769,"raw":{"market":"0x2a12fd3d8235c25c062dc9652970ef9f635636c4018df0909e1a51c673e125cb","price_changes":[{"asset_id":"63670753354844494163057275310194312729998307779831462269530137743341854359908","price":"0.84","size":"277","side":"BUY","hash":"8ba3a7b8ace931f02e62d96461da8783559280ef","best_bid":"0.85","best_ask":"0.86"},{"asset_id":"56386988715176239099720172290594769295756680374928571099138069977179519358166","price":"0.16","size":"277","side":"SELL","hash":"70d76e78395607121fec9d4f28245f5eb455cae7","best_bid":"0.14","best_ask":"0.15"}],"timestamp":"1768250243769","event_type":"price_change"}}
{"schema_version":1,"source":"clob_ws_market","recv_ts_ns":1768250243940396092,"event_type":"price_change","market":"0x2a12fd3d8235c25c062dc9652970ef9f635636c4018df0909e1a51c673e125cb","server_ts_ms":1768250243770,"raw":{"market":"0x2a12fd3d8235c25c062dc9652970ef9f635636c4018df0909e1a51c673e125cb","price_changes":[{"asset_id":"56386988715176239099720172290594769295756680374928571099138069977179519358166","price":"0.14","size":"282.93","side":"BUY","hash":"89a67747864e35bb769ed984abb9de5d836e9caf","best_bid":"0.14","best_ask":"0.15"},{"asset_id":"63670753354844494163057275310194312729998307779831462269530137743341854359908","price":"0.86","size":"282.93","side":"SELL","hash":"f9a986de73d417f990b342096ef3b9a181d5fe54","best_bid":"0.85","best_ask":"0.86"}],"timestamp":"1768250243770","event_type":"price_change"}}
{"schema_version":1,"source":"clob_ws_market","recv_ts_ns":1768250243942335467,"event_type":"price_change","market":"0x2a12fd3d8235c25c062dc9652970ef9f635636c4018df0909e1a51c673e125cb","server_ts_ms":1768250243770,"raw":{"market":"0x2a12fd3d8235c25c062dc9652970ef9f635636c4018df0909e1a51c673e125cb","price_changes":[{"asset_id":"56386988715176239099720172290594769295756680374928571099138069977179519358166","price":"0.13","size":"321","side":"BUY","hash":"e7780edec1ac7d2923755322ca9ca65ce1616f90","best_bid":"0.14","best_ask":"0.15"},{"asset_id":"63670753354844494163057275310194312729998307779831462269530137743341854359908","price":"0.87","size":"321","side":"SELL","hash":"b58ea6db6a17947a51901ad41688621a8e8eb83d","best_bid":"0.85","best_ask":"0.86"}],"timestamp":"1768250243770","event_type":"price_change"}}
{"schema_version":1,"source":"clob_ws_market","recv_ts_ns":1768250243944716823,"event_type":"price_change","market":"0x2a12fd3d8235c25c062dc9652970ef9f635636c4018df0909e1a51c673e125cb","server_ts_ms":1768250243771,"raw":{"market":"0x2a12fd3d8235c25c062dc9652970ef9f635636c4018df0909e1a51c673e125cb","price_changes":[{"asset_id":"56386988715176239099720172290594769295756680374928571099138069977179519358166","price":"0.13","size":"311","side":"BUY","hash":"ca211fd0c30f1deefba254365f5822bb8e69b6e3","best_bid":"0.14","best_ask":"0.15"},{"asset_id":"63670753354844494163057275310194312729998307779831462269530137743341854359908","price":"0.87","size":"311","side":"SELL","hash":"837c6d457e577abcce1f1b86441b13173b572c1a","best_bid":"0.85","best_ask":"0.86"}],"timestamp":"1768250243771","event_type":"price_change"}}
{"schema_version":1,"source":"clob_ws_market","recv_ts_ns":1768250243946727171,"event_type":"price_change","market":"0x2a12fd3d8235c25c062dc9652970ef9f635636c4018df0909e1a51c673e125cb","server_ts_ms":1768250243771,"raw":{"market":"0x2a12fd3d8235c25c062dc9652970ef9f635636c4018df0909e1a51c673e125cb","price_changes":[{"asset_id":"56386988715176239099720172290594769295756680374928571099138069977179519358166","price":"0.13","size":"331","side":"BUY","hash":"71e13851d4e2b78485b0312c752d24a8b401e0af","best_bid":"0.14","best_ask":"0.15"},{"asset_id":"63670753354844494163057275310194312729998307779831462269530137743341854359908","price":"0.87","size":"331","side":"SELL","hash":"c72dffb2605b632f700956d733326f99d9b69611","best_bid":"0.85","best_ask":"0.86"}],"timestamp":"1768250243771","event_type":"price_change"}}
{"schema_version":1,"source":"clob_ws_market","recv_ts_ns":1768250243949627827,"event_type":"price_change","market":"0x2a12fd3d8235c25c062dc9652970ef9f635636c4018df0909e1a51c673e125cb","server_ts_ms":1768250243772,"raw":{"market":"0x2a12fd3d8235c25c062dc9652970ef9f635636c4018df0909e1a51c673e125cb","price_changes":[{"asset_id":"63670753354844494163057275310194312729998307779831462269530137743341854359908","price":"0.84","size":"287","side":"BUY","hash":"a04523c2b831e28452516b27f21196c009e142a6","best_bid":"0.85","best_ask":"0.86"},{"asset_id":"56386988715176239099720172290594769295756680374928571099138069977179519358166","price":"0.16","size":"287","side":"SELL","hash":"c21f3402d395200f9359f04a47c53ee3a35a0a69","best_bid":"0.14","best_ask":"0.15"}],"timestamp":"1768250243772","event_type":"price_change"}}
{"schema_version":1,"source":"clob_ws_market","recv_ts_ns":1768250243952769041,"event_type":"price_change","market":"0x2a12fd3d8235c25c062dc9652970ef9f635636c4018df0909e1a51c673e125cb","server_ts_ms":1768250243773,"raw":{"market":"0x2a12fd3d8235c25c062dc9652970ef9f635636c4018df0909e1a51c673e125cb","price_changes":[{"asset_id":"63670753354844494163057275310194312729998307779831462269530137743341854359908","price":"0.93","size":"1421.28","side":"SELL","hash":"f9a716b47811db302c1c77b06ea4fca657f18b59","best_bid":"0.85","best_ask":"0.86"},{"asset_id":"56386988715176239099720172290594769295756680374928571099138069977179519358166","price":"0.07","size":"1421.28","side":"BUY","hash":"6f255370f7704816034c2e7e57568cf82bc6d0f8","best_bid":"0.14","best_ask":"0.15"}],"timestamp":"1768250243773","event_type":"price_change"}}
{"schema_version":1,"source":"clob_ws_market","recv_ts_ns":1768250243960522113,"event_type":"price_change","market":"0x2a12fd3d8235c25c062dc9652970ef9f635636c4018df0909e1a51c673e125cb","server_ts_ms":1768250243773,"raw":{"market":"0x2a12fd3d8235c25c062dc9652970ef9f635636c4018df0909e1a51c673e125cb","price_changes":[{"asset_id":"56386988715176239099720172290594769295756680374928571099138069977179519358166","price":"0.12","size":"861.75","side":"BUY","hash":"1277dca5993b7901fb8440d66994749a13ffc54b","best_bid":"0.14","best_ask":"0.15"},{"asset_id":"63670753354844494163057275310194312729998307779831462269530137743341854359908","price":"0.88","size":"861.75","side":"SELL","hash":"53c5b66b0923cb049d4a08ce9555339d6ae6f9a6","best_bid":"0.85","best_ask":"0.86"}],"timestamp":"1768250243773","event_type":"price_change"}}
{"schema_version":1,"source":"clob_ws_market","recv_ts_ns":1768250243964147866,"event_type":"price_change","market":"0x2a12fd3d8235c25c062dc9652970ef9f635636c4018df0909e1a51c673e125cb","server_ts_ms":1768250243774,"raw":{"market":"0x2a12fd3d8235c25c062dc9652970ef9f635636c4018df0909e1a51c673e125cb","price_changes":[{"asset_id":"63670753354844494163057275310194312729998307779831462269530137743341854359908","price":"0.84","size":"282","side":"BUY","hash":"3afd957aed09c6c051b638c80166e4db13bd8010","best_bid":"0.85","best_ask":"0.86"},{"asset_id":"56386988715176239099720172290594769295756680374928571099138069977179519358166","price":"0.16","size":"282","side":"SELL","hash":"6ce2613cb37d0a949a83b259499febfa686fab49","best_bid":"0.14","best_ask":"0.15"}],"timestamp":"1768250243774","event_type":"price_change"}}
{"schema_version":1,"source":"clob_ws_market","recv_ts_ns":1768250243968562401,"event_type":"price_change","market":"0x2a12fd3d8235c25c062dc9652970ef9f635636c4018df0909e1a51c673e125cb","server_ts_ms":1768250243775,"raw":{"market":"0x2a12fd3d8235c25c062dc9652970ef9f635636c4018df0909e1a51c673e125cb","price_changes":[{"asset_id":"63670753354844494163057275310194312729998307779831462269530137743341854359908","price":"0.86","size":"287.93","side":"SELL","hash":"df2cbe820655fdc849f8fa8c89fa75dcbeeda60c","best_bid":"0.85","best_ask":"0.86"},{"asset_id":"56386988715176239099720172290594769295756680374928571099138069977179519358166","price":"0.14","size":"287.93","side":"BUY","hash":"b21bf39f10dc4a86bc0dbe2e0f206a2f6461899a","best_bid":"0.14","best_ask":"0.15"}],"timestamp":"1768250243775","event_type":"price_change"}}
{"schema_version":1,"source":"clob_ws_market","recv_ts_ns":1768250243973581498,"event_type":"price_change","market":"0x2a12fd3d8235c25c062dc9652970ef9f635636c4018df0909e1a51c673e125cb","server_ts_ms":1768250243776,"raw":{"market":"0x2a12fd3d8235c25c062dc9652970ef9f635636c4018df0909e1a51c673e125cb","price_changes":[{"asset_id":"63670753354844494163057275310194312729998307779831462269530137743341854359908","price":"0.92","size":"1547.25","side":"SELL","hash":"01c56b2eca0e68c095594f1b47bc8bcdf53ff636","best_bid":"0.85","best_ask":"0.86"},{"asset_id":"56386988715176239099720172290594769295756680374928571099138069977179519358166","price":"0.08","size":"1547.25","side":"BUY","hash":"8207dc6aa99558e3d33c2b2f7fb2beb6d18b4510","best_bid":"0.14","best_ask":"0.15"}],"timestamp":"1768250243776","event_type":"price_change"}}
{"schema_version":1,"source":"clob_ws_market","recv_ts_ns":1768250243978514385,"event_type":"price_change","market":"0x2a12fd3d8235c25c062dc9652970ef9f635636c4018df0909e1a51c673e125cb","server_ts_ms":1768250243776,"raw":{"market":"0x2a12fd3d8235c25c062dc9652970ef9f635636c4018df0909e1a51c673e125cb","price_changes":[{"asset_id":"56386988715176239099720172290594769295756680374928571099138069977179519358166","price":"0.11","size":"905.5","side":"BUY","hash":"5e5689346d4001a151ec11737cb5935d5c28803f","best_bid":"0.14","best_ask":"0.15"},{"asset_id":"63670753354844494163057275310194312729998307779831462269530137743341854359908","price":"0.89","size":"905.5","side":"SELL","hash":"04b3999e194fa91e7fd33a4f00b40fe68e9a63dc","best_bid":"0.85","best_ask":"0.86"}],"timestamp":"1768250243776","event_type":"price_change"}}
{"schema_version":1,"source":"clob_ws_market","recv_ts_ns":1768250243982673043,"event_type":"price_change","market":"0x2a12fd3d8235c25c062dc9652970ef9f635636c4018df0909e1a51c673e125cb","server_ts_ms":1768250243777,"raw":{"market":"0x2a12fd3d8235c25c062dc9652970ef9f635636c4018df0909e1a51c673e125cb","price_changes":[{"asset_id":"56386988715176239099720172290594769295756680374928571099138069977179519358166","price":"0.13","size":"361","side":"BUY","hash":"1f429be39dce68571e6b02efb49d55beb209b06f","best_bid":"0.14","best_ask":"0.15"},{"asset_id":"63670753354844494163057275310194312729998307779831462269530137743341854359908","price":"0.87","size":"361","side":"SELL","hash":"1d9fbe96536b1ad375d6bf62f19e8efa40fd7141","best_bid":"0.85","best_ask":"0.86"}],"timestamp":"1768250243777","event_type":"price_change"}}
{"schema_version":1,"source":"clob_ws_market","recv_ts_ns":1768250243987014131,"event_type":"price_change","market":"0x2a12fd3d8235c25c062dc9652970ef9f635636c4018df0909e1a51c673e125cb","server_ts_ms":1768250243778,"raw":{"market":"0x2a12fd3d8235c25c062dc9652970ef9f635636c4018df0909e1a51c673e125cb","price_changes":[{"asset_id":"63670753354844494163057275310194312729998307779831462269530137743341854359908","price":"0.66","size":"997.71","side":"BUY","hash":"0efcd07244b3823e2031b4ea675139aba2e20444","best_bid":"0.85","best_ask":"0.86"},{"asset_id":"56386988715176239099720172290594769295756680374928571099138069977179519358166","price":"0.34","size":"997.71","side":"SELL","hash":"e2e87d2c986223f3c7eb18eaef00e84581a49f3c","best_bid":"0.14","best_ask":"0.15"}],"timestamp":"1768250243778","event_type":"price_change"}}
{"schema_version":1,"source":"clob_ws_market","recv_ts_ns":1768250243996203656,"event_type":"price_change","market":"0x2a12fd3d8235c25c062dc9652970ef9f635636c4018df0909e1a51c673e125cb","server_ts_ms":1768250243779,"raw":{"market":"0x2a12fd3d8235c25c062dc9652970ef9f635636c4018df0909e1a51c673e125cb","price_changes":[{"asset_id":"56386988715176239099720172290594769295756680374928571099138069977179519358166","price":"0.1","size":"3472","side":"BUY","hash":"d1bc73334419134d7b4d5109a6c4be389bead8d2","best_bid":"0.14","best_ask":"0.15"},{"asset_id":"63670753354844494163057275310194312729998307779831462269530137743341854359908","price":"0.9","size":"3472","side":"SELL","hash":"d108c024e1349f8ddc53c5114f4bc457298174fb","best_bid":"0.85","best_ask":"0.86"}],"timestamp":"1768250243779","event_type":"price_change"}}
{"schema_version":1,"source":"clob_ws_market","recv_ts_ns":1768250244000672573,"event_type":"price_change","market":"0x2a12fd3d8235c25c062dc9652970ef9f635636c4018df0909e1a51c673e125cb","server_ts_ms":1768250243780,"raw":{"market":"0x2a12fd3d8235c25c062dc9652970ef9f635636c4018df0909e1a51c673e125cb","price_changes":[{"asset_id":"63670753354844494163057275310194312729998307779831462269530137743341854359908","price":"0.84","size":"276.5","side":"BUY","hash":"534f33461dee0ee2e14392fa2d04180532d68ba1","best_bid":"0.85","best_ask":"0.86"},{"asset_id":"56386988715176239099720172290594769295756680374928571099138069977179519358166","price":"0.16","size":"276.5","side":"SELL","hash":"44377a7c9b0066e0a32f98448ce731b47d22553e","best_bid":"0.14","best_ask":"0.15"}],"timestamp":"1768250243780","event_type":"price_change"}}
{"schema_version":1,"source":"clob_ws_market","recv_ts_ns":1768250244005908160,"event_type":"price_change","market":"0x2a12fd3d8235c25c062dc9652970ef9f635636c4018df0909e1a51c673e125cb","server_ts_ms":1768250243781,"raw":{"market":"0x2a12fd3d8235c25c062dc9652970ef9f635636c4018df0909e1a51c673e125cb","price_changes":[{"asset_id":"63670753354844494163057275310194312729998307779831462269530137743341854359908","price":"0.84","size":"266.5","side":"BUY","hash":"04c8d4786aa1c58d6a16a749a0ef1fa44e1721e9","best_bid":"0.85","best_ask":"0.86"},{"asset_id":"56386988715176239099720172290594769295756680374928571099138069977179519358166","price":"0.16","size":"266.5","side":"SELL","hash":"44b33b300ab862a8253bc01d29e8f2aa4fe69fd3","best_bid":"0.14","best_ask":"0.15"}],"timestamp":"1768250243781","event_type":"price_change"}}
{"schema_version":1,"source":"clob_ws_market","recv_ts_ns":1768250244010615762,"event_type":"price_change","market":"0x2a12fd3d8235c25c062dc9652970ef9f635636c4018df0909e1a51c673e125cb","server_ts_ms":1768250243782,"raw":{"market":"0x2a12fd3d8235c25c062dc9652970ef9f635636c4018df0909e1a51c673e125cb","price_changes":[{"asset_id":"56386988715176239099720172290594769295756680374928571099138069977179519358166","price":"0.08","size":"1559.75","side":"BUY","hash":"856ac43932b30dc47262319753abd6d1b20c7a10","best_bid":"0.14","best_ask":"0.15"},{"asset_id":"63670753354844494163057275310194312729998307779831462269530137743341854359908","price":"0.92","size":"1559.75","side":"SELL","hash":"e0411a54e0eefd55d1bbbe5e6ec6cb04ec847db3","best_bid":"0.85","best_ask":"0.86"}],"timestamp":"1768250243782","event_type":"price_change"}}
{"schema_version":1,"source":"clob_ws_market","recv_ts_ns":1768250244038543068,"event_type":"best_bid_ask","market":"0x2a12fd3d8235c25c062dc9652970ef9f635636c4018df0909e1a51c673e125cb","server_ts_ms":1768250243792,"raw":{"market":"0x2a12fd3d8235c25c062dc9652970ef9f635636c4018df0909e1a51c673e125cb","asset_id":"63670753354844494163057275310194312729998307779831462269530137743341854359908","best_bid":"0.85","best_ask":"0.86","spread":"0.01","timestamp":"1768250243792","event_type":"best_bid_ask"}}
{"schema_version":1,"source":"clob_ws_market","recv_ts_ns":1768250244041103018,"event_type":"price_change","market":"0x2a12fd3d8235c25c062dc9652970ef9f635636c4018df0909e1a51c673e125cb","server_ts_ms":1768250243791,"raw":{"market":"0x2a12fd3d8235c25c062dc9652970ef9f635636c4018df0909e1a51c673e125cb","price_changes":[{"asset_id":"63670753354844494163057275310194312729998307779831462269530137743341854359908","price":"0.85","size":"459.31","side":"BUY","hash":"a49b240fcc4a7875b8df1d4b46ac51a7511e6003","best_bid":"0.85","best_ask":"0.86"},{"asset_id":"56386988715176239099720172290594769295756680374928571099138069977179519358166","price":"0.15","size":"459.31","side":"SELL","hash":"9e5d94a24ab353bf3d581c9c31d2d3829712d758","best_bid":"0.14","best_ask":"0.15"}],"timestamp":"1768250243791","event_type":"price_change"}}
{"schema_version":1,"source":"clob_ws_market","recv_ts_ns":1768250244045490627,"event_type":"price_change","market":"0x2a12fd3d8235c25c062dc9652970ef9f635636c4018df0909e1a51c673e125cb","server_ts_ms":1768250243791,"raw":{"market":"0x2a12fd3d8235c25c062dc9652970ef9f635636c4018df0909e1a51c673e125cb","price_changes":[{"asset_id":"56386988715176239099720172290594769295756680374928571099138069977179519358166","price":"0.15","size":"459.31","side":"SELL","hash":"9e5d94a24ab353bf3d581c9c31d2d3829712d758","best_bid":"0.14","best_ask":"0.15"},{"asset_id":"63670753354844494163057275310194312729998307779831462269530137743341854359908","price":"0.85","size":"459.31","side":"BUY","hash":"a49b240fcc4a7875b8df1d4b46ac51a7511e6003","best_bid":"0.85","best_ask":"0.86"}],"timestamp":"1768250243791","event_type":"price_change"}}
{"schema_version":1,"source":"clob_ws_market","recv_ts_ns":1768250244058633686,"event_type":"book","market":"0x2a12fd3d8235c25c062dc9652970ef9f635636c4018df0909e1a51c673e125cb","server_ts_ms":1768250243791,"raw":{"market":"0x2a12fd3d8235c25c062dc9652970ef9f635636c4018df0909e1a51c673e125cb","asset_id":"63670753354844494163057275310194312729998307779831462269530137743341854359908","bids":[{"price":"0.01","size":"10184.18"},{"price":"0.02","size":"5982"},{"price":"0.03","size":"5238.94"},{"price":"0.04","size":"5040"},{"price":"0.05","size":"5050"},{"price":"0.06","size":"5005"},{"price":"0.07","size":"5019.28"},{"price":"0.08","size":"5005"},{"price":"0.09","size":"5005"},{"price":"0.1","size":"5030"},{"price":"0.11","size":"5"},{"price":"0.12","size":"5"},{"price":"0.13","size":"5"},{"price":"0.14","size":"5"},{"price":"0.15","size":"10"},{"price":"0.16","size":"5"},{"price":"0.17","size":"5"},{"price":"0.18","size":"5"},{"price":"0.19","size":"5"},{"price":"0.2","size":"5"},{"price":"0.21","size":"5"},{"price":"0.22","size":"5"},{"price":"0.23","size":"5"},{"price":"0.24","size":"5"},{"price":"0.25","size":"10"},{"price":"0.26","size":"5"},{"price":"0.27","size":"5"},{"price":"0.28","size":"5"},{"price":"0.29","size":"15"},{"price":"0.3","size":"10"},{"price":"0.31","size":"5"},{"price":"0.32","size":"5"},{"price":"0.33","size":"5"},{"price":"0.34","size":"505"},{"price":"0.35","size":"510"},{"price":"0.36","size":"510"},{"price":"0.37","size":"505"},{"price":"0.38","size":"505"},{"price":"0.39","size":"755"},{"price":"0.4","size":"760"},{"price":"0.41","size":"916"},{"price":"0.42","size":"671"},{"price":"0.43","size":"827"},{"price":"0.44","size":"827"},{"price":"0.45","size":"817"},{"price":"0.46","size":"872"},{"price":"0.47","size":"839.65"},{"price":"0.48","size":"829"},{"price":"0.49","size":"817"},{"price":"0.5","size":"838.4"},{"price":"0.51","size":"867.58"},{"price":"0.52","size":"817"},{"price":"0.53","size":"827"},{"price":"0.54","size":"847.8"},{"price":"0.55","size":"836.09"},{"price":"0.56","size":"825"},{"price":"0.57","size":"847"},{"price":"0.58","size":"817"},{"price":"0.59","size":"817"},{"price":"0.6","size":"817"},{"price":"0.61","size":"834.5"},{"price":"0.62","size":"817"},{"price":"0.63","size":"497.49"},{"price":"0.64","size":"817"},{"price":"0.65","size":"872"},{"price":"0.66","size":"997.71"},{"price":"0.67","size":"906.8"},{"price":"0.68","size":"902"},{"price":"0.69","size":"922"},{"price":"0.7","size":"911.6"},{"price":"0.71","size":"897"},{"price":"0.72","size":"899.55"},{"price":"0.73","size":"912"},{"price":"0.74","size":"1174.42"},{"price":"0.75","size":"722.5"},{"price":"0.76","size":"924.25"},{"price":"0.77","size":"748.5"},{"price":"0.78","size":"916.8"},{"price":"0.79","size":"808.5"},{"price":"0.8","size":"814.9"},{"price":"0.81","size":"888.21"},{"price":"0.82","size":"871"},{"price":"0.83","size":"185.02"},{"price":"0.84","size":"266.5"},{"price":"0.85","size":"459.31"}],"asks":[{"price":"0.99","size":"10331.71"},{"price":"0.98","size":"6299.77"},{"price":"0.97","size":"5625.94"},{"price":"0.96","size":"5427"},{"price":"0.95","size":"3442"},{"price":"0.94","size":"1397"},{"price":"0.93","size":"1421.28"},{"price":"0.92","size":"1559.75"},{"price":"0.91","size":"1317"},{"price":"0.9","size":"3472"},{"price":"0.89","size":"905.5"},{"price":"0.88","size":"861.75"},{"price":"0.87","size":"361"},{"price":"0.86","size":"287.93"}],"hash":"a49b240fcc4a7875b8df1d4b46ac51a7511e6003","timestamp":"1768250243791","event_type":"book"}}
{"schema_version":1,"source":"clob_ws_market","recv_ts_ns":1768250244062445601,"event_type":"price_change","market":"0x2a12fd3d8235c25c062dc9652970ef9f635636c4018df0909e1a51c673e125cb","server_ts_ms":1768250243792,"raw":{"market":"0x2a12fd3d8235c25c062dc9652970ef9f635636c4018df0909e1a51c673e125cb","price_changes":[{"asset_id":"63670753354844494163057275310194312729998307779831462269530137743341854359908","price":"0.84","size":"256.5","side":"BUY","hash":"1e45d3dfb578d5c68263e3b4efa479abfcd30058","best_bid":"0.85","best_ask":"0.86"},{"asset_id":"56386988715176239099720172290594769295756680374928571099138069977179519358166","price":"0.16","size":"256.5","side":"SELL","hash":"895244a0b7a23a939724baa2e3da3a97a53e3257","best_bid":"0.14","best_ask":"0.15"}],"timestamp":"1768250243792","event_type":"price_change"}}
{"schema_version":1,"source":"clob_ws_market","recv_ts_ns":1768250244067762903,"event_type":"price_change","market":"0x2a12fd3d8235c25c062dc9652970ef9f635636c4018df0909e1a51c673e125cb","server_ts_ms":1768250243793,"raw":{"market":"0x2a12fd3d8235c25c062dc9652970ef9f635636c4018df0909e1a51c673e125cb","price_changes":[{"asset_id":"63670753354844494163057275310194312729998307779831462269530137743341854359908","price":"0.81","size":"388.21","side":"BUY","hash":"62d3bcdd7ac3614aded6a1674063df9a1d6a2136","best_bid":"0.85","best_ask":"0.86"},{"asset_id":"56386988715176239099720172290594769295756680374928571099138069977179519358166","price":"0.19","size":"388.21","side":"SELL","hash":"6e683e72100224e388484b30530502a8b1ef4092","best_bid":"0.14","best_ask":"0.15"}],"timestamp":"1768250243793","event_type":"price_change"}}
{"schema_version":1,"source":"clob_ws_market","recv_ts_ns":1768250244071944812,"event_type":"price_change","market":"0x2a12fd3d8235c25c062dc9652970ef9f635636c4018df0909e1a51c673e125cb","server_ts_ms":1768250243795,"raw":{"market":"0x2a12fd3d8235c25c062dc9652970ef9f635636c4018df0909e1a51c673e125cb","price_changes":[{"asset_id":"63670753354844494163057275310194312729998307779831462269530137743341854359908","price":"0.83","size":"195.02","side":"BUY","hash":"715ece2faaf45e0f8e4649e2fcf87a08a5d54e9b","best_bid":"0.85","best_ask":"0.86"},{"asset_id":"56386988715176239099720172290594769295756680374928571099138069977179519358166","price":"0.17","size":"195.02","side":"SELL","hash":"b956eb2d1acb66967e261e41f681f9ac716b074c","best_bid":"0.14","best_ask":"0.15"}],"timestamp":"1768250243795","event_type":"price_change"}}
{"schema_version":1,"source":"clob_ws_market","recv_ts_ns":1768250244080883185,"event_type":"price_change","market":"0x2a12fd3d8235c25c062dc9652970ef9f635636c4018df0909e1a51c673e125cb","server_ts_ms":1768250243796,"raw":{"market":"0x2a12fd3d8235c25c062dc9652970ef9f635636c4018df0909e1a51c673e125cb","price_changes":[{"asset_id":"63670753354844494163057275310194312729998307779831462269530137743341854359908","price":"0.84","size":"266.5","side":"BUY","hash":"b1faf1c4edf53222ae55f7b466ae41ab8e3af543","best_bid":"0.85","best_ask":"0.86"},{"asset_id":"56386988715176239099720172290594769295756680374928571099138069977179519358166","price":"0.16","size":"266.5","side":"SELL","hash":"2e5f94884378f1b7b1050d3a6eae8cd2f4e568cf","best_bid":"0.14","best_ask":"0.15"}],"timestamp":"1768250243796","event_type":"price_change"}}
{"schema_version":1,"source":"clob_ws_market","recv_ts_ns":1768250244085417850,"event_type":"price_change","market":"0x2a12fd3d8235c25c062dc9652970ef9f635636c4018df0909e1a51c673e125cb","server_ts_ms":1768250243797,"raw":{"market":"0x2a12fd3d8235c25c062dc9652970ef9f635636c4018df0909e1a51c673e125cb","price_changes":[{"asset_id":"63670753354844494163057275310194312729998307779831462269530137743341854359908","price":"0.84","size":"256.5","side":"BUY","hash":"789e7e5669bde3ae5c3e69c3e7cb61d69c5e7c75","best_bid":"0.85","best_ask":"0.86"},{"asset_id":"56386988715176239099720172290594769295756680374928571099138069977179519358166","price":"0.16","size":"256.5","side":"SELL","hash":"d15855767606de5dbdc150d7f9eb4e07816fa5f8","best_bid":"0.14","best_ask":"0.15"}],"timestamp":"1768250243797","event_type":"price_change"}}
{"schema_version":1,"source":"clob_ws_market","recv_ts_ns":1768250244090753155,"event_type":"price_change","market":"0x2a12fd3d8235c25c062dc9652970ef9f635636c4018df0909e1a51c673e125cb","server_ts_ms":1768250243797,"raw":{"market":"0x2a12fd3d8235c25c062dc9652970ef9f635636c4018df0909e1a51c673e125cb","price_changes":[{"asset_id":"63670753354844494163057275310194312729998307779831462269530137743341854359908","price":"0.84","size":"246.5","side":"BUY","hash":"454d67bd89d829f0b667aa694bab6cb5b6910642","best_bid":"0.85","best_ask":"0.86"},{"asset_id":"56386988715176239099720172290594769295756680374928571099138069977179519358166","price":"0.16","size":"246.5","side":"SELL","hash":"dcbbfdc510d11dea85c2986e5e14a89598821fd4","best_bid":"0.14","best_ask":"0.15"}],"timestamp":"1768250243797","event_type":"price_change"}}
{"schema_version":1,"source":"clob_ws_market","recv_ts_ns":1768250244096165774,"event_type":"price_change","market":"0x2a12fd3d8235c25c062dc9652970ef9f635636c4018df0909e1a51c673e125cb","server_ts_ms":1768250243798,"raw":{"market":"0x2a12fd3d8235c25c062dc9652970ef9f635636c4018df0909e1a51c673e125cb","price_changes":[{"asset_id":"63670753354844494163057275310194312729998307779831462269530137743341854359908","price":"0.84","size":"236.5","side":"BUY","hash":"e4f239a5ff1a6a84588bb9932dcf8d31b0d9b59d","best_bid":"0.85","best_ask":"0.86"},{"asset_id":"56386988715176239099720172290594769295756680374928571099138069977179519358166","price":"0.16","size":"236.5","side":"SELL","hash":"5de9ef3a180fcd1cffc356ea37f45867f316885a","best_bid":"0.14","best_ask":"0.15"}],"timestamp":"1768250243798","event_type":"price_change"}}
{"schema_version":1,"source":"clob_ws_market","recv_ts_ns":1768250244101728586,"event_type":"price_change","market":"0x2a12fd3d8235c25c062dc9652970ef9f635636c4018df0909e1a51c673e125cb","server_ts_ms":1768250243799,"raw":{"market":"0x2a12fd3d8235c25c062dc9652970ef9f635636c4018df0909e1a51c673e125cb","price_changes":[{"asset_id":"63670753354844494163057275310194312729998307779831462269530137743341854359908","price":"0.84","size":"226.5","side":"BUY","hash":"490c765d2572ac7c5cbe3e3065b019bf97891a2c","best_bid":"0.85","best_ask":"0.86"},{"asset_id":"56386988715176239099720172290594769295756680374928571099138069977179519358166","price":"0.16","size":"226.5","side":"SELL","hash":"2ee991101b2ccf56db48bc6edc05b2f19c5f846b","best_bid":"0.14","best_ask":"0.15"}],"timestamp":"1768250243799","event_type":"price_change"}}
{"schema_version":1,"source":"clob_ws_market","recv_ts_ns":1768250244106821755,"event_type":"price_change","market":"0x2a12fd3d8235c25c062dc9652970ef9f635636c4018df0909e1a51c673e125cb","server_ts_ms":1768250243800,"raw":{"market":"0x2a12fd3d8235c25c062dc9652970ef9f635636c4018df0909e1a51c673e125cb","price_changes":[{"asset_id":"63670753354844494163057275310194312729998307779831462269530137743341854359908","price":"0.84","size":"216.5","side":"BUY","hash":"1cd78259edca2c5f9936150562a8a8b76e313eb4","best_bid":"0.85","best_ask":"0.86"},{"asset_id":"56386988715176239099720172290594769295756680374928571099138069977179519358166","price":"0.16","size":"216.5","side":"SELL","hash":"b3e4788036ecd770928d75977b76eb91ba328529","best_bid":"0.14","best_ask":"0.15"}],"timestamp":"1768250243800","event_type":"price_change"}}
{"schema_version":1,"source":"clob_ws_market","recv_ts_ns":1768250244112087944,"event_type":"price_change","market":"0x2a12fd3d8235c25c062dc9652970ef9f635636c4018df0909e1a51c673e125cb","server_ts_ms":1768250243801,"raw":{"market":"0x2a12fd3d8235c25c062dc9652970ef9f635636c4018df0909e1a51c673e125cb","price_changes":[{"asset_id":"63670753354844494163057275310194312729998307779831462269530137743341854359908","price":"0.84","size":"206.5","side":"BUY","hash":"58187b56c8e7c53782285f24705ba2e4ecd831e5","best_bid":"0.85","best_ask":"0.86"},{"asset_id":"56386988715176239099720172290594769295756680374928571099138069977179519358166","price":"0.16","size":"206.5","side":"SELL","hash":"a80491c0af6210d16e8ebe773912aa40967cce90","best_bid":"0.14","best_ask":"0.15"}],"timestamp":"1768250243801","event_type":"price_change"}}
{"schema_version":1,"source":"clob_ws_market","recv_ts_ns":1768250244116074456,"event_type":"price_change","market":"0x2a12fd3d8235c25c062dc9652970ef9f635636c4018df0909e1a51c673e125cb","server_ts_ms":1768250243803,"raw":{"market":"0x2a12fd3d8235c25c062dc9652970ef9f635636c4018df0909e1a51c673e125cb","price_changes":[{"asset_id":"56386988715176239099720172290594769295756680374928571099138069977179519358166","price":"0.14","size":"297.93","side":"BUY","hash":"2e1a084bd5cde2cfc513dd9880aee76f8d51f015","best_bid":"0.14","best_ask":"0.15"},{"asset_id":"63670753354844494163057275310194312729998307779831462269530137743341854359908","price":"0.86","size":"297.93","side":"SELL","hash":"498b0f2accbd97bbe408c8fb6b498cc0d6208233","best_bid":"0.85","best_ask":"0.86"}],"timestamp":"1768250243803","event_type":"price_change"}}
{"schema_version":1,"source":"clob_ws_market","recv_ts_ns":1768250244121737073,"event_type":"price_change","market":"0x2a12fd3d8235c25c062dc9652970ef9f635636c4018df0909e1a51c673e125cb","server_ts_ms":1768250243810,"raw":{"market":"0x2a12fd3d8235c25c062dc9652970ef9f635636c4018df0909e1a51c673e125cb","price_changes":[{"asset_id":"63670753354844494163057275310194312729998307779831462269530137743341854359908","price":"0.84","size":"216.5","side":"BUY","hash":"605253b7dce1101abae20e5e4fdbf517c7e3e579","best_bid":"0.85","best_ask":"0.86"},{"asset_id":"56386988715176239099720172290594769295756680374928571099138069977179519358166","price":"0.16","size":"216.5","side":"SELL","hash":"39908014486d425562dd62bba6d2671659ce6273","best_bid":"0.14","best_ask":"0.15"}],"timestamp":"1768250243810","event_type":"price_change"}}
{"schema_version":1,"source":"clob_ws_market","recv_ts_ns":1768250244126703727,"event_type":"price_change","market":"0x2a12fd3d8235c25c062dc9652970ef9f635636c4018df0909e1a51c673e125cb","server_ts_ms":1768250243811,"raw":{"market":"0x2a12fd3d8235c25c062dc9652970ef9f635636c4018df0909e1a51c673e125cb","price_changes":[{"asset_id":"63670753354844494163057275310194312729998307779831462269530137743341854359908","price":"0.83","size":"200.52","side":"BUY","hash":"258658c625282be67de8b0d6fa86061cccfa6d09","best_bid":"0.85","best_ask":"0.86"},{"asset_id":"56386988715176239099720172290594769295756680374928571099138069977179519358166","price":"0.17","size":"200.52","side":"SELL","hash":"b1d79f6b19771c4c064ea74b4b3294a1b33ec43c","best_bid":"0.14","best_ask":"0.15"}],"timestamp":"1768250243811","event_type":"price_change"}}
{"schema_version":1,"source":"clob_ws_market","recv_ts_ns":1768250244130959510,"event_type":"price_change","market":"0x2a12fd3d8235c25c062dc9652970ef9f635636c4018df0909e1a51c673e125cb","server_ts_ms":1768250243812,"raw":{"market":"0x2a12fd3d8235c25c062dc9652970ef9f635636c4018df0909e1a51c673e125cb","price_changes":[{"asset_id":"63670753354844494163057275310194312729998307779831462269530137743341854359908","price":"0.84","size":"206.5","side":"BUY","hash":"20a81d7661309f2f2ad9de7dfc8898e88f1d7009","best_bid":"0.85","best_ask":"0.86"},{"asset_id":"56386988715176239099720172290594769295756680374928571099138069977179519358166","price":"0.16","size":"206.5","side":"SELL","hash":"251cbf2d2921e523f2df91585c0019350e1e8826","best_bid":"0.14","best_ask":"0.15"}],"timestamp":"1768250243812","event_type":"price_change"}}
{"schema_version":1,"source":"clob_ws_market","recv_ts_ns":1768250244135424792,"event_type":"price_change","market":"0x2a12fd3d8235c25c062dc9652970ef9f635636c4018df0909e1a51c673e125cb","server_ts_ms":1768250243813,"raw":{"market":"0x2a12fd3d8235c25c062dc9652970ef9f635636c4018df0909e1a51c673e125cb","price_changes":[{"asset_id":"63670753354844494163057275310194312729998307779831462269530137743341854359908","price":"0.78","size":"910.8","side":"BUY","hash":"97a16eedcfc50bff1faf2c4acccc15de2c28badd","best_bid":"0.85","best_ask":"0.86"},{"asset_id":"56386988715176239099720172290594769295756680374928571099138069977179519358166","price":"0.22","size":"910.8","side":"SELL","hash":"54b26d4ef6c504a5e1bb198d65b646c3ad594615","best_bid":"0.14","best_ask":"0.15"}],"timestamp":"1768250243813","event_type":"price_change"}}
{"schema_version":1,"source":"clob_ws_market","recv_ts_ns":1768250244140388875,"event_type":"price_change","market":"0x2a12fd3d8235c25c062dc9652970ef9f635636c4018df0909e1a51c673e125cb","server_ts_ms":1768250243813,"raw":{"market":"0x2a12fd3d8235c25c062dc9652970ef9f635636c4018df0909e1a51c673e125cb","price_changes":[{"asset_id":"63670753354844494163057275310194312729998307779831462269530137743341854359908","price":"0.89","size":"899.5","side":"SELL","hash":"97a16eedcfc50bff1faf2c4acccc15de2c28badd","best_bid":"0.85","best_ask":"0.86"},{"asset_id":"56386988715176239099720172290594769295756680374928571099138069977179519358166","price":"0.11","size":"899.5","side":"BUY","hash":"54b26d4ef6c504a5e1bb198d65b646c3ad594615","best_bid":"0.14","best_ask":"0.15"}],"timestamp":"1768250243813","event_type":"price_change"}}
{"schema_version":1,"source":"clob_ws_market","recv_ts_ns":1768250244144353403,"event_type":"price_change","market":"0x2a12fd3d8235c25c062dc9652970ef9f635636c4018df0909e1a51c673e125cb","server_ts_ms":1768250243814,"raw":{"market":"0x2a12fd3d8235c25c062dc9652970ef9f635636c4018df0909e1a51c673e125cb","price_changes":[{"asset_id":"56386988715176239099720172290594769295756680374928571099138069977179519358166","price":"0.08","size":"1496.75","side":"BUY","hash":"d09ca324da9b7300dad21de72c5fd69b4670e9dc","best_bid":"0.14","best_ask":"0.15"},{"asset_id":"63670753354844494163057275310194312729998307779831462269530137743341854359908","price":"0.92","size":"1496.75","side":"SELL","hash":"d252361ab8efd66f7ba4b871d5c5a0baf0c05bca","best_bid":"0.85","best_ask":"0.86"}],"timestamp":"1768250243814","event_type":"price_change"}}
{"schema_version":1,"source":"clob_ws_market","recv_ts_ns":1768250244149672392,"event_type":"price_change","market":"0x2a12fd3d8235c25c062dc9652970ef9f635636c4018df0909e1a51c673e125cb","server_ts_ms":1768250243817,"raw":{"market":"0x2a12fd3d8235c25c062dc9652970ef9f635636c4018df0909e1a51c673e125cb","price_changes":[{"asset_id":"56386988715176239099720172290594769295756680374928571099138069977179519358166","price":"0.14","size":"287.93","side":"BUY","hash":"0561681749535749008b9d912a737d590ba22dff","best_bid":"0.14","best_ask":"0.15"},{"asset_id":"63670753354844494163057275310194312729998307779831462269530137743341854359908","price":"0.86","size":"287.93","side":"SELL","hash":"898c67f46cb7d3b3431600e5053788f213f31fa8","best_bid":"0.85","best_ask":"0.86"}],"timestamp":"1768250243817","event_type":"price_change"}}
{"schema_version":1,"source":"clob_ws_market","recv_ts_ns":1768250244152506568,"event_type":"price_change","market":"0x2a12fd3d8235c25c062dc9652970ef9f635636c4018df0909e1a51c673e125cb","server_ts_ms":1768250243818,"raw":{"market":"0x2a12fd3d8235c25c062dc9652970ef9f635636c4018df0909e1a51c673e125cb","price_changes":[{"asset_id":"56386988715176239099720172290594769295756680374928571099138069977179519358166","price":"0.11","size":"889.5","side":"BUY","hash":"c989e38d5a24f23a306a1657d03d2ee7db914584","best_bid":"0.14","best_ask":"0.15"},{"asset_id":"63670753354844494163057275310194312729998307779831462269530137743341854359908","price":"0.89","size":"889.5","side":"SELL","hash":"b739cd737fc7e1e7b6566e14f20e7a0f8414fd55","best_bid":"0.85","best_ask":"0.86"}],"timestamp":"1768250243818","event_type":"price_change"}}
{"schema_version":1,"source":"clob_ws_market","recv_ts_ns":1768250244155287500,"event_type":"price_change","market":"0x2a12fd3d8235c25c062dc9652970ef9f635636c4018df0909e1a51c673e125cb","server_ts_ms":1768250243820,"raw":{"market":"0x2a12fd3d8235c25c062dc9652970ef9f635636c4018df0909e1a51c673e125cb","price_changes":[{"asset_id":"56386988715176239099720172290594769295756680374928571099138069977179519358166","price":"0.1","size":"3462","side":"BUY","hash":"60041255c202661ef5691fb8ff9c0ee11094c4d3","best_bid":"0.14","best_ask":"0.15"},{"asset_id":"63670753354844494163057275310194312729998307779831462269530137743341854359908","price":"0.9","size":"3462","side":"SELL","hash":"57417c3ec083ea0107d21e2cdfb801a918972ff8","best_bid":"0.85","best_ask":"0.86"}],"timestamp":"1768250243820","event_type":"price_change"}}
{"schema_version":1,"source":"clob_ws_market","recv_ts_ns":1768250244158741715,"event_type":"price_change","market":"0x2a12fd3d8235c25c062dc9652970ef9f635636c4018df0909e1a51c673e125cb","server_ts_ms":1768250243821,"raw":{"market":"0x2a12fd3d8235c25c062dc9652970ef9f635636c4018df0909e1a51c673e125cb","price_changes":[{"asset_id":"56386988715176239099720172290594769295756680374928571099138069977179519358166","price":"0.12","size":"851.75","side":"BUY","hash":"bb414279ea6cba1249f325364895df98113dd4f8","best_bid":"0.14","best_ask":"0.15"},{"asset_id":"63670753354844494163057275310194312729998307779831462269530137743341854359908","price":"0.88","size":"851.75","side":"SELL","hash":"314c75c690e19aa1116823ee6df1ff50e856d549","best_bid":"0.85","best_ask":"0.86"}],"timestamp":"1768250243821","event_type":"price_change"}}
{"schema_version":1,"source":"clob_ws_market","recv_ts_ns":1768250244167176473,"event_type":"price_change","market":"0x2a12fd3d8235c25c062dc9652970ef9f635636c4018df0909e1a51c673e125cb","server_ts_ms":1768250243821,"raw":{"market":"0x2a12fd3d8235c25c062dc9652970ef9f635636c4018df0909e1a51c673e125cb","price_changes":[{"asset_id":"63670753354844494163057275310194312729998307779831462269530137743341854359908","price":"0.83","size":"210.52","side":"BUY","hash":"4fc9374ce1e821aec3b01a1cb86440ab94118191","best_bid":"0.85","best_ask":"0.86"},{"asset_id":"56386988715176239099720172290594769295756680374928571099138069977179519358166","price":"0.17","size":"210.52","side":"SELL","hash":"bfcb04da07111f972b57d25a0ce6703605ef0eb2","best_bid":"0.14","best_ask":"0.15"}],"timestamp":"1768250243821","event_type":"price_change"}}
{"schema_version":1,"source":"clob_ws_market","recv_ts_ns":1768250244170130583,"event_type":"price_change","market":"0x2a12fd3d8235c25c062dc9652970ef9f635636c4018df0909e1a51c673e125cb","server_ts_ms":1768250243823,"raw":{"market":"0x2a12fd3d8235c25c062dc9652970ef9f635636c4018df0909e1a51c673e125cb","price_changes":[{"asset_id":"56386988715176239099720172290594769295756680374928571099138069977179519358166","price":"0.11","size":"879.5","side":"BUY","hash":"62ac16a877d45a8301de2b6b55158e7c9ae90320","best_bid":"0.14","best_ask":"0.15"},{"asset_id":"63670753354844494163057275310194312729998307779831462269530137743341854359908","price":"0.89","size":"879.5","side":"SELL","hash":"10bf3eacf1254368ad3e1eef8db25b740e479cca","best_bid":"0.85","best_ask":"0.86"}],"timestamp":"1768250243823","event_type":"price_change"}}
{"schema_version":1,"source":"clob_ws_market","recv_ts_ns":1768250244172383131,"event_type":"price_change","market":"0x2a12fd3d8235c25c062dc9652970ef9f635636c4018df0909e1a51c673e125cb","server_ts_ms":1768250243824,"raw":{"market":"0x2a12fd3d8235c25c062dc9652970ef9f635636c4018df0909e1a51c673e125cb","price_changes":[{"asset_id":"56386988715176239099720172290594769295756680374928571099138069977179519358166","price":"0.11","size":"869.5","side":"BUY","hash":"50deb27255e7d60686a89af9b53fecb4ecd45340","best_bid":"0.14","best_ask":"0.15"},{"asset_id":"63670753354844494163057275310194312729998307779831462269530137743341854359908","price":"0.89","size":"869.5","side":"SELL","hash":"6ea0821dd8724bd2883ef40e5f20908bdc6b3e1d","best_bid":"0.85","best_ask":"0.86"}],"timestamp":"1768250243824","event_type":"price_change"}}
{"schema_version":1,"source":"clob_ws_market","recv_ts_ns":1768250244174852734,"event_type":"price_change","market":"0x2a12fd3d8235c25c062dc9652970ef9f635636c4018df0909e1a51c673e125cb","server_ts_ms":1768250243826,"raw":{"market":"0x2a12fd3d8235c25c062dc9652970ef9f635636c4018df0909e1a51c673e125cb","price_changes":[{"asset_id":"56386988715176239099720172290594769295756680374928571099138069977179519358166","price":"0.13","size":"351","side":"BUY","hash":"1d029e904b0da8e3e36da52e866772d68b847b28","best_bid":"0.14","best_ask":"0.15"},{"asset_id":"63670753354844494163057275310194312729998307779831462269530137743341854359908","price":"0.87","size":"351","side":"SELL","hash":"8ec4b1678887d2394467095790e3b3ac2d916692","best_bid":"0.85","best_ask":"0.86"}],"timestamp":"1768250243826","event_type":"price_change"}}
{"schema_version":1,"source":"clob_ws_market","recv_ts_ns":1768250244180502792,"event_type":"price_change","market":"0x2a12fd3d8235c25c062dc9652970ef9f635636c4018df0909e1a51c673e125cb","server_ts_ms":1768250243829,"raw":{"market":"0x2a12fd3d8235c25c062dc9652970ef9f635636c4018df0909e1a51c673e125cb","price_changes":[{"asset_id":"63670753354844494163057275310194312729998307779831462269530137743341854359908","price":"0.83","size":"220.52","side":"BUY","hash":"354d85215ec8f7849fc7b6c9541fa03dd04071df","best_bid":"0.85","best_ask":"0.86"},{"asset_id":"56386988715176239099720172290594769295756680374928571099138069977179519358166","price":"0.17","size":"220.52","side":"SELL","hash":"9cc08f5de97ca43c94ceb3e34aafe26b5dc7401e","best_bid":"0.14","best_ask":"0.15"}],"timestamp":"1768250243829","event_type":"price_change"}}
{"schema_version":1,"source":"clob_ws_market","recv_ts_ns":1768250244184474314,"event_type":"price_change","market":"0x2a12fd3d8235c25c062dc9652970ef9f635636c4018df0909e1a51c673e125cb","server_ts_ms":1768250243834,"raw":{"market":"0x2a12fd3d8235c25c062dc9652970ef9f635636c4018df0909e1a51c673e125cb","price_changes":[{"asset_id":"63670753354844494163057275310194312729998307779831462269530137743341854359908","price":"0.84","size":"196.5","side":"BUY","hash":"c56061231b731d06f689833b2a27f8930d99a321","best_bid":"0.85","best_ask":"0.86"},{"asset_id":"56386988715176239099720172290594769295756680374928571099138069977179519358166","price":"0.16","size":"196.5","side":"SELL","hash":"0aedd7a74175ed104e61d7b41a5dfe7b7f42c904","best_bid":"0.14","best_ask":"0.15"}],"timestamp":"1768250243834","event_type":"price_change"}}
{"schema_version":1,"source":"clob_ws_market","recv_ts_ns":1768250244187546327,"event_type":"price_change","market":"0x2a12fd3d8235c25c062dc9652970ef9f635636c4018df0909e1a51c673e125cb","server_ts_ms":1768250243835,"raw":{"market":"0x2a12fd3d8235c25c062dc9652970ef9f635636c4018df0909e1a51c673e125cb","price_changes":[{"asset_id":"56386988715176239099720172290594769295756680374928571099138069977179519358166","price":"0.11","size":"859.5","side":"BUY","hash":"971985a6db18f818e71f81eefe98b37524d068dd","best_bid":"0.14","best_ask":"0.15"},{"asset_id":"63670753354844494163057275310194312729998307779831462269530137743341854359908","price":"0.89","size":"859.5","side":"SELL","hash":"eb3b296108661fb14bbbf5621c0a493fc4c27852","best_bid":"0.85","best_ask":"0.86"}],"timestamp":"1768250243835","event_type":"price_change"}}
{"schema_version":1,"source":"clob_ws_market","recv_ts_ns":1768250244189882323,"event_type":"price_change","market":"0x2a12fd3d8235c25c062dc9652970ef9f635636c4018df0909e1a51c673e125cb","server_ts_ms":1768250243836,"raw":{"market":"0x2a12fd3d8235c25c062dc9652970ef9f635636c4018df0909e1a51c673e125cb","price_changes":[{"asset_id":"56386988715176239099720172290594769295756680374928571099138069977179519358166","price":"0.14","size":"277.93","side":"BUY","hash":"efb838caa9b8180aad7e4b42a8cc332a0deabcb4","best_bid":"0.14","best_ask":"0.15"},{"asset_id":"63670753354844494163057275310194312729998307779831462269530137743341854359908","price":"0.86","size":"277.93","side":"SELL","hash":"10c67b134636bc5f1a3f72e53023b982b4e013cb","best_bid":"0.85","best_ask":"0.86"}],"timestamp":"1768250243836","event_type":"price_change"}}
{"schema_version":1,"source":"clob_ws_market","recv_ts_ns":1768250244192428787,"event_type":"price_change","market":"0x2a12fd3d8235c25c062dc9652970ef9f635636c4018df0909e1a51c673e125cb","server_ts_ms":1768250243837,"raw":{"market":"0x2a12fd3d8235c25c062dc9652970ef9f635636c4018df0909e1a51c673e125cb","price_changes":[{"asset_id":"63670753354844494163057275310194312729998307779831462269530137743341854359908","price":"0.83","size":"230.52","side":"BUY","hash":"43dfc256dd5512cf1e2f64103492c3c82ebb6aca","best_bid":"0.85","best_ask":"0.86"},{"asset_id":"56386988715176239099720172290594769295756680374928571099138069977179519358166","price":"0.17","size":"230.52","side":"SELL","hash":"7fd84457d161bc19c7f6cbd20a4cd3735da45db1","best_bid":"0.14","best_ask":"0.15"}],"timestamp":"1768250243837","event_type":"price_change"}}
{"schema_version":1,"source":"clob_ws_market","recv_ts_ns":1768250244195984756,"event_type":"price_change","market":"0x2a12fd3d8235c25c062dc9652970ef9f635636c4018df0909e1a51c673e125cb","server_ts_ms":1768250243838,"raw":{"market":"0x2a12fd3d8235c25c062dc9652970ef9f635636c4018df0909e1a51c673e125cb","price_changes":[{"asset_id":"63670753354844494163057275310194312729998307779831462269530137743341854359908","price":"0.83","size":"240.52","side":"BUY","hash":"7fd2c48deffa93e268c1acbd20b1ecdeac83c62b","best_bid":"0.85","best_ask":"0.86"},{"asset_id":"56386988715176239099720172290594769295756680374928571099138069977179519358166","price":"0.17","size":"240.52","side":"SELL","hash":"47e402e2eaf9e4f38343d6d5620fc3585dce7fd0","best_bid":"0.14","best_ask":"0.15"}],"timestamp":"1768250243838","event_type":"price_change"}}
{"schema_version":1,"source":"clob_ws_market","recv_ts_ns":1768250244200998482,"event_type":"price_change","market":"0x2a12fd3d8235c25c062dc9652970ef9f635636c4018df0909e1a51c673e125cb","server_ts_ms":1768250243839,"raw":{"market":"0x2a12fd3d8235c25c062dc9652970ef9f635636c4018df0909e1a51c673e125cb","price_changes":[{"asset_id":"63670753354844494163057275310194312729998307779831462269530137743341854359908","price":"0.77","size":"754.5","side":"BUY","hash":"0845775b4ea857a9aa29248032d1178814fe6b17","best_bid":"0.85","best_ask":"0.86"},{"asset_id":"56386988715176239099720172290594769295756680374928571099138069977179519358166","price":"0.23","size":"754.5","side":"SELL","hash":"25d01a75d28ef553d308ed0774a3e7c64ed09600","best_bid":"0.14","best_ask":"0.15"}],"timestamp":"1768250243839","event_type":"price_change"}}
{"schema_version":1,"source":"clob_ws_market","recv_ts_ns":1768250244206365484,"event_type":"price_change","market":"0x2a12fd3d8235c25c062dc9652970ef9f635636c4018df0909e1a51c673e125cb","server_ts_ms":1768250243840,"raw":{"market":"0x2a12fd3d8235c25c062dc9652970ef9f635636c4018df0909e1a51c673e125cb","price_changes":[{"asset_id":"63670753354844494163057275310194312729998307779831462269530137743341854359908","price":"0.88","size":"857.75","side":"SELL","hash":"09a72b730b2a01c8ffc6a7b192ffcbdfd013370a","best_bid":"0.85","best_ask":"0.86"},{"asset_id":"56386988715176239099720172290594769295756680374928571099138069977179519358166","price":"0.12","size":"857.75","side":"BUY","hash":"37b190b0c8b8e62a134ce11a997f2d109a71a413","best_bid":"0.14","best_ask":"0.15"}],"timestamp":"1768250243840","event_type":"price_change"}}
{"schema_version":1,"source":"clob_ws_market","recv_ts_ns":1768250244212026021,"event_type":"price_change","market":"0x2a12fd3d8235c25c062dc9652970ef9f635636c4018df0909e1a51c673e125cb","server_ts_ms":1768250243843,"raw":{"market":"0x2a12fd3d8235c25c062dc9652970ef9f635636c4018df0909e1a51c673e125cb","price_changes":[{"asset_id":"63670753354844494163057275310194312729998307779831462269530137743341854359908","price":"0.83","size":"250.52","side":"BUY","hash":"f56713d461ddb4cb5e41f3b92cd76a707ffc779f","best_bid":"0.85","best_ask":"0.86"},{"asset_id":"56386988715176239099720172290594769295756680374928571099138069977179519358166","price":"0.17","size":"250.52","side":"SELL","hash":"2768c5ea8bedd9f07f766f794be7f93b55129c70","best_bid":"0.14","best_ask":"0.15"}],"timestamp":"1768250243843","event_type":"price_change"}}
{"schema_version":1,"source":"clob_ws_market","recv_ts_ns":1768250244216424789,"event_type":"price_change","market":"0x2a12fd3d8235c25c062dc9652970ef9f635636c4018df0909e1a51c673e125cb","server_ts_ms":1768250243844,"raw":{"market":"0x2a12fd3d8235c25c062dc9652970ef9f635636c4018df0909e1a51c673e125cb","price_changes":[{"asset_id":"63670753354844494163057275310194312729998307779831462269530137743341854359908","price":"0.83","size":"240.52","side":"BUY","hash":"3478d2bed02f3793711da83f1e20a2adf4079d4a","best_bid":"0.85","best_ask":"0.86"},{"asset_id":"56386988715176239099720172290594769295756680374928571099138069977179519358166","price":"0.17","size":"240.52","side":"SELL","hash":"b28de571bc2f18c0d12bf63880a471dbdd96c62c","best_bid":"0.14","best_ask":"0.15"}],"timestamp":"1768250243844","event_type":"price_change"}}
{"schema_version":1,"source":"clob_ws_market","recv_ts_ns":1768250244219169334,"event_type":"price_change","market":"0x2a12fd3d8235c25c062dc9652970ef9f635636c4018df0909e1a51c673e125cb","server_ts_ms":1768250243846,"raw":{"market":"0x2a12fd3d8235c25c062dc9652970ef9f635636c4018df0909e1a51c673e125cb","price_changes":[{"asset_id":"56386988715176239099720172290594769295756680374928571099138069977179519358166","price":"0.09","size":"1373","side":"BUY","hash":"f282b706d50151a0ebe00031937cda66dcd5292b","best_bid":"0.14","best_ask":"0.15"},{"asset_id":"63670753354844494163057275310194312729998307779831462269530137743341854359908","price":"0.91","size":"1373","side":"SELL","hash":"53488e3b43f440bcbc6c820476520a862c379834","best_bid":"0.85","best_ask":"0.86"}],"timestamp":"1768250243846","event_type":"price_change"}}
{"schema_version":1,"source":"clob_ws_market","recv_ts_ns":1768250244221997771,"event_type":"price_change","market":"0x2a12fd3d8235c25c062dc9652970ef9f635636c4018df0909e1a51c673e125cb","server_ts_ms":1768250243848,"raw":{"market":"0x2a12fd3d8235c25c062dc9652970ef9f635636c4018df0909e1a51c673e125cb","price_changes":[{"asset_id":"63670753354844494163057275310194312729998307779831462269530137743341854359908","price":"0.83","size":"250.52","side":"BUY","hash":"57d06f0f5ab69bd4f655c242b4d9a9484262f46f","best_bid":"0.85","best_ask":"0.86"},{"asset_id":"56386988715176239099720172290594769295756680374928571099138069977179519358166","price":"0.17","size":"250.52","side":"SELL","hash":"85aed612c508599e783ad50f2e6ef858bd7f0f4b","best_bid":"0.14","best_ask":"0.15"}],"timestamp":"1768250243848","event_type":"price_change"}}
{"schema_version":1,"source":"clob_ws_market","recv_ts_ns":1768250244225815082,"event_type":"price_change","market":"0x2a12fd3d8235c25c062dc9652970ef9f635636c4018df0909e1a51c673e125cb","server_ts_ms":1768250243849,"raw":{"market":"0x2a12fd3d8235c25c062dc9652970ef9f635636c4018df0909e1a51c673e125cb","price_changes":[{"asset_id":"63670753354844494163057275310194312729998307779831462269530137743341854359908","price":"0.83","size":"260.52","side":"BUY","hash":"172bc1cac343c53a30215bc0655161035ad19f99","best_bid":"0.85","best_ask":"0.86"},{"asset_id":"56386988715176239099720172290594769295756680374928571099138069977179519358166","price":"0.17","size":"260.52","side":"SELL","hash":"58afd87d7ea9e876767abd29fee5e13b9fca9a02","best_bid":"0.14","best_ask":"0.15"}],"timestamp":"1768250243849","event_type":"price_change"}}
{"schema_version":1,"source":"clob_ws_market","recv_ts_ns":1768250244229774962,"event_type":"price_change","market":"0x2a12fd3d8235c25c062dc9652970ef9f635636c4018df0909e1a51c673e125cb","server_ts_ms":1768250243855,"raw":{"market":"0x2a12fd3d8235c25c062dc9652970ef9f635636c4018df0909e1a51c673e125cb","price_changes":[{"asset_id":"56386988715176239099720172290594769295756680374928571099138069977179519358166","price":"0.12","size":"867.75","side":"BUY","hash":"93901bb1b55eec694a0ff7ada089b7d1f36326be","best_bid":"0.14","best_ask":"0.15"},{"asset_id":"63670753354844494163057275310194312729998307779831462269530137743341854359908","price":"0.88","size":"867.75","side":"SELL","hash":"93fa3fd2eb4ba20911788315489f6d76a1516a3c","best_bid":"0.85","best_ask":"0.86"}],"timestamp":"1768250243855","event_type":"price_change"}}
{"schema_version":1,"source":"clob_ws_market","recv_ts_ns":1768250244233650179,"event_type":"price_change","market":"0x2a12fd3d8235c25c062dc9652970ef9f635636c4018df0909e1a51c673e125cb","server_ts_ms":1768250243856,"raw":{"market":"0x2a12fd3d8235c25c062dc9652970ef9f635636c4018df0909e1a51c673e125cb","price_changes":[{"asset_id":"56386988715176239099720172290594769295756680374928571099138069977179519358166","price":"0.14","size":"287.93","side":"BUY","hash":"df25fe671bbe4a9e6e7c3bfe7033ea2f3e1439f8","best_bid":"0.14","best_ask":"0.15"},{"asset_id":"63670753354844494163057275310194312729998307779831462269530137743341854359908","price":"0.86","size":"287.93","side":"SELL","hash":"2000dae1deb331643612a97dfc99fc4cc3a39e58","best_bid":"0.85","best_ask":"0.86"}],"timestamp":"1768250243856","event_type":"price_change"}}
{"schema_version":1,"source":"clob_ws_market","recv_ts_ns":1768250244238195032,"event_type":"price_change","market":"0x2a12fd3d8235c25c062dc9652970ef9f635636c4018df0909e1a51c673e125cb","server_ts_ms":1768250243856,"raw":{"market":"0x2a12fd3d8235c25c062dc9652970ef9f635636c4018df0909e1a51c673e125cb","price_changes":[{"asset_id":"56386988715176239099720172290594769295756680374928571099138069977179519358166","price":"0.13","size":"361","side":"BUY","hash":"6bd00982e93e6c26c30fb37c2fb9a16535fdb63a","best_bid":"0.14","best_ask":"0.15"},{"asset_id":"63670753354844494163057275310194312729998307779831462269530137743341854359908","price":"0.87","size":"361","side":"SELL","hash":"1247e7ff0bbf937a8ab3974ac4415ce5033a50ac","best_bid":"0.85","best_ask":"0.86"}],"timestamp":"1768250243856","event_type":"price_change"}}
{"schema_version":1,"source":"clob_ws_market","recv_ts_ns":1768250244242933345,"event_type":"price_change","market":"0x2a12fd3d8235c25c062dc9652970ef9f635636c4018df0909e1a51c673e125cb","server_ts_ms":1768250243859,"raw":{"market":"0x2a12fd3d8235c25c062dc9652970ef9f635636c4018df0909e1a51c673e125cb","price_changes":[{"asset_id":"56386988715176239099720172290594769295756680374928571099138069977179519358166","price":"0.11","size":"869.5","side":"BUY","hash":"1154ffa754489f56b8e4f006f7ba66127778a3f5","best_bid":"0.14","best_ask":"0.15"},{"asset_id":"63670753354844494163057275310194312729998307779831462269530137743341854359908","price":"0.89","size":"869.5","side":"SELL","hash":"96aabc4abaa3e8f1445da2871d7050a12797d1fe","best_bid":"0.85","best_ask":"0.86"}],"timestamp":"1768250243859","event_type":"price_change"}}
{"schema_version":1,"source":"clob_ws_market","recv_ts_ns":1768250244247776118,"event_type":"price_change","market":"0x2a12fd3d8235c25c062dc9652970ef9f635636c4018df0909e1a51c673e125cb","server_ts_ms":1768250243861,"raw":{"market":"0x2a12fd3d8235c25c062dc9652970ef9f635636c4018df0909e1a51c673e125cb","price_changes":[{"asset_id":"56386988715176239099720172290594769295756680374928571099138069977179519358166","price":"0.12","size":"877.75","side":"BUY","hash":"edc7a78520b030979d2d7e6597066e6c1eb35ada","best_bid":"0.14","best_ask":"0.15"},{"asset_id":"63670753354844494163057275310194312729998307779831462269530137743341854359908","price":"0.88","size":"877.75","side":"SELL","hash":"9ffd7c9d2c46e4db9c0474a32c8268b19c4863dc","best_bid":"0.85","best_ask":"0.86"}],"timestamp":"1768250243861","event_type":"price_change"}}
{"schema_version":1,"source":"clob_ws_market","recv_ts_ns":1768250244251684686,"event_type":"price_change","market":"0x2a12fd3d8235c25c062dc9652970ef9f635636c4018df0909e1a51c673e125cb","server_ts_ms":1768250243863,"raw":{"market":"0x2a12fd3d8235c25c062dc9652970ef9f635636c4018df0909e1a51c673e125cb","price_changes":[{"asset_id":"56386988715176239099720172290594769295756680374928571099138069977179519358166","price":"0.12","size":"887.75","side":"BUY","hash":"daaa5427349bac0e48f5a2f7db1b91acc326a17e","best_bid":"0.14","best_ask":"0.15"},{"asset_id":"63670753354844494163057275310194312729998307779831462269530137743341854359908","price":"0.88","size":"887.75","side":"SELL","hash":"06989931fa4b0671cd59967e511e6b084bb3d130","best_bid":"0.85","best_ask":"0.86"}],"timestamp":"1768250243863","event_type":"price_change"}}
{"schema_version":1,"source":"clob_ws_market","recv_ts_ns":1768250244256813386,"event_type":"price_change","market":"0x2a12fd3d8235c25c062dc9652970ef9f635636c4018df0909e1a51c673e125cb","server_ts_ms":1768250243864,"raw":{"market":"0x2a12fd3d8235c25c062dc9652970ef9f635636c4018df0909e1a51c673e125cb","price_changes":[{"asset_id":"56386988715176239099720172290594769295756680374928571099138069977179519358166","price":"0.14","size":"297.93","side":"BUY","hash":"6b2da68c2c9445f4f5205bbe22cec518323ce3f8","best_bid":"0.14","best_ask":"0.15"},{"asset_id":"63670753354844494163057275310194312729998307779831462269530137743341854359908","price":"0.86","size":"297.93","side":"SELL","hash":"2859b6edf46537e0bfa3071d984a1aa3b9c81bc8","best_bid":"0.85","best_ask":"0.86"}],"timestamp":"1768250243864","event_type":"price_change"}}
{"schema_version":1,"source":"clob_ws_market","recv_ts_ns":1768250244262020217,"event_type":"price_change","market":"0x2a12fd3d8235c25c062dc9652970ef9f635636c4018df0909e1a51c673e125cb","server_ts_ms":1768250243865,"raw":{"market":"0x2a12fd3d8235c25c062dc9652970ef9f635636c4018df0909e1a51c673e125cb","price_changes":[{"asset_id":"63670753354844494163057275310194312729998307779831462269530137743341854359908","price":"0.83","size":"270.52","side":"BUY","hash":"d3bedfac82f22424ed915bd0a755ec0bab3e9a2e","best_bid":"0.85","best_ask":"0.86"},{"asset_id":"56386988715176239099720172290594769295756680374928571099138069977179519358166","price":"0.17","size":"270.52","side":"SELL","hash":"65b8fad1ea7145378f40d7ee137403afebdc8522","best_bid":"0.14","best_ask":"0.15"}],"timestamp":"1768250243865","event_type":"price_change"}}
{"schema_version":1,"source":"clob_ws_market","recv_ts_ns":1768250244273621939,"event_type":"price_change","market":"0x2a12fd3d8235c25c062dc9652970ef9f635636c4018df0909e1a51c673e125cb","server_ts_ms":1768250243883,"raw":{"market":"0x2a12fd3d8235c25c062dc9652970ef9f635636c4018df0909e1a51c673e125cb","price_changes":[{"asset_id":"63670753354844494163057275310194312729998307779831462269530137743341854359908","price":"0.84","size":"186.5","side":"BUY","hash":"bcc274e6d2246a6e26e6e53a94848a83a4abf2bb","best_bid":"0.85","best_ask":"0.86"},{"asset_id":"56386988715176239099720172290594769295756680374928571099138069977179519358166","price":"0.16","size":"186.5","side":"SELL","hash":"3fbfc0e755b5289ef24460020980bafc01e4766b","best_bid":"0.14","best_ask":"0.15"}],"timestamp":"1768250243883","event_type":"price_change"}}
{"schema_version":1,"source":"clob_ws_market","recv_ts_ns":1768250244279613422,"event_type":"best_bid_ask","market":"0x2a12fd3d8235c25c062dc9652970ef9f635636c4018df0909e1a51c673e125cb","server_ts_ms":1768250243895,"raw":{"market":"0x2a12fd3d8235c25c062dc9652970ef9f635636c4018df0909e1a51c673e125cb","asset_id":"63670753354844494163057275310194312729998307779831462269530137743341854359908","best_bid":"0.85","best_ask":"0.86","spread":"0.01","timestamp":"1768250243895","event_type":"best_bid_ask"}}
{"schema_version":1,"source":"clob_ws_market","recv_ts_ns":1768250244282760962,"event_type":"price_change","market":"0x2a12fd3d8235c25c062dc9652970ef9f635636c4018df0909e1a51c673e125cb","server_ts_ms":1768250243894,"raw":{"market":"0x2a12fd3d8235c25c062dc9652970ef9f635636c4018df0909e1a51c673e125cb","price_changes":[{"asset_id":"56386988715176239099720172290594769295756680374928571099138069977179519358166","price":"0.14","size":"287.66","side":"BUY","hash":"9aeecd1305bdc8437afe21eb6f23ae1f587f8d1c","best_bid":"0.14","best_ask":"0.15"},{"asset_id":"63670753354844494163057275310194312729998307779831462269530137743341854359908","price":"0.86","size":"287.66","side":"SELL","hash":"3c8b2df673beeb6b185e38664feeefb9ce0c4698","best_bid":"0.85","best_ask":"0.86"}],"timestamp":"1768250243894","event_type":"price_change"}}
{"schema_version":1,"source":"clob_ws_market","recv_ts_ns":1768250244287734108,"event_type":"price_change","market":"0x2a12fd3d8235c25c062dc9652970ef9f635636c4018df0909e1a51c673e125cb","server_ts_ms":1768250243894,"raw":{"market":"0x2a12fd3d8235c25c062dc9652970ef9f635636c4018df0909e1a51c673e125cb","price_changes":[{"asset_id":"63670753354844494163057275310194312729998307779831462269530137743341854359908","price":"0.86","size":"287.66","side":"SELL","hash":"3c8b2df673beeb6b185e38664feeefb9ce0c4698","best_bid":"0.85","best_ask":"0.86"},{"asset_id":"56386988715176239099720172290594769295756680374928571099138069977179519358166","price":"0.14","size":"287.66","side":"BUY","hash":"9aeecd1305bdc8437afe21eb6f23ae1f587f8d1c","best_bid":"0.14","best_ask":"0.15"}],"timestamp":"1768250243894","event_type":"price_change"}}
{"schema_version":1,"source":"clob_ws_market","recv_ts_ns":1768250244300700553,"event_type":"book","market":"0x2a12fd3d8235c25c062dc9652970ef9f635636c4018df0909e1a51c673e125cb","server_ts_ms":1768250243894,"raw":{"market":"0x2a12fd3d8235c25c062dc9652970ef9f635636c4018df0909e1a51c673e125cb","asset_id":"63670753354844494163057275310194312729998307779831462269530137743341854359908","bids":[{"price":"0.01","size":"10184.18"},{"price":"0.02","size":"5982"},{"price":"0.03","size":"5238.94"},{"price":"0.04","size":"5040"},{"price":"0.05","size":"5050"},{"price":"0.06","size":"5005"},{"price":"0.07","size":"5019.28"},{"price":"0.08","size":"5005"},{"price":"0.09","size":"5005"},{"price":"0.1","size":"5030"},{"price":"0.11","size":"5"},{"price":"0.12","size":"5"},{"price":"0.13","size":"5"},{"price":"0.14","size":"5"},{"price":"0.15","size":"10"},{"price":"0.16","size":"5"},{"price":"0.17","size":"5"},{"price":"0.18","size":"5"},{"price":"0.19","size":"5"},{"price":"0.2","size":"5"},{"price":"0.21","size":"5"},{"price":"0.22","size":"5"},{"price":"0.23","size":"5"},{"price":"0.24","size":"5"},{"price":"0.25","size":"10"},{"price":"0.26","size":"5"},{"price":"0.27","size":"5"},{"price":"0.28","size":"5"},{"price":"0.29","size":"15"},{"price":"0.3","size":"10"},{"price":"0.31","size":"5"},{"price":"0.32","size":"5"},{"price":"0.33","size":"5"},{"price":"0.34","size":"505"},{"price":"0.35","size":"510"},{"price":"0.36","size":"510"},{"price":"0.37","size":"505"},{"price":"0.38","size":"505"},{"price":"0.39","size":"755"},{"price":"0.4","size":"760"},{"price":"0.41","size":"916"},{"price":"0.42","size":"671"},{"price":"0.43","size":"827"},{"price":"0.44","size":"827"},{"price":"0.45","size":"817"},{"price":"0.46","size":"872"},{"price":"0.47","size":"839.65"},{"price":"0.48","size":"829"},{"price":"0.49","size":"817"},{"price":"0.5","size":"838.4"},{"price":"0.51","size":"867.58"},{"price":"0.52","size":"817"},{"price":"0.53","size":"827"},{"price":"0.54","size":"847.8"},{"price":"0.55","size":"836.09"},{"price":"0.56","size":"825"},{"price":"0.57","size":"847"},{"price":"0.58","size":"817"},{"price":"0.59","size":"817"},{"price":"0.6","size":"817"},{"price":"0.61","size":"834.5"},{"price":"0.62","size":"817"},{"price":"0.63","size":"497.49"},{"price":"0.64","size":"817"},{"price":"0.65","size":"872"},{"price":"0.66","size":"997.71"},{"price":"0.67","size":"906.8"},{"price":"0.68","size":"902"},{"price":"0.69","size":"922"},{"price":"0.7","size":"911.6"},{"price":"0.71","size":"897"},{"price":"0.72","size":"899.55"},{"price":"0.73","size":"912"},{"price":"0.74","size":"1174.42"},{"price":"0.75","size":"722.5"},{"price":"0.76","size":"924.25"},{"price":"0.77","size":"754.5"},{"price":"0.78","size":"910.8"},{"price":"0.79","size":"808.5"},{"price":"0.8","size":"814.9"},{"price":"0.81","size":"388.21"},{"price":"0.82","size":"871"},{"price":"0.83","size":"270.52"},{"price":"0.84","size":"186.5"},{"price":"0.85","size":"459.31"}],"asks":[{"price":"0.99","size":"10331.71"},{"price":"0.98","size":"6299.77"},{"price":"0.97","size":"5625.94"},{"price":"0.96","size":"5427"},{"price":"0.95","size":"3442"},{"price":"0.94","size":"1397"},{"price":"0.93","size":"1421.28"},{"price":"0.92","size":"1496.75"},{"price":"0.91","size":"1373"},{"price":"0.9","size":"3462"},{"price":"0.89","size":"869.5"},{"price":"0.88","size":"887.75"},{"price":"0.87","size":"361"},{"price":"0.86","size":"287.66"}],"hash":"3c8b2df673beeb6b185e38664feeefb9ce0c4698","timestamp":"1768250243894","event_type":"book"}}
{"schema_version":1,"source":"clob_ws_market","recv_ts_ns":1768250244307653537,"event_type":"best_bid_ask","market":"0x2a12fd3d8235c25c062dc9652970ef9f635636c4018df0909e1a51c673e125cb","server_ts_ms":1768250243906,"raw":{"market":"0x2a12fd3d8235c25c062dc9652970ef9f635636c4018df0909e1a51c673e125cb","asset_id":"63670753354844494163057275310194312729998307779831462269530137743341854359908","best_bid":"0.85","best_ask":"0.86","spread":"0.01","timestamp":"1768250243906","event_type":"best_bid_ask"}}
{"schema_version":1,"source":"clob_ws_market","recv_ts_ns":1768250244310297885,"event_type":"price_change","market":"0x2a12fd3d8235c25c062dc9652970ef9f635636c4018df0909e1a51c673e125cb","server_ts_ms":1768250243905,"raw":{"market":"0x2a12fd3d8235c25c062dc9652970ef9f635636c4018df0909e1a51c673e125cb","price_changes":[{"asset_id":"56386988715176239099720172290594769295756680374928571099138069977179519358166","price":"0.14","size":"285.81","side":"BUY","hash":"5bad64c3c4d3ae7e8cfd5aefb0227d692f04a3e4","best_bid":"0.14","best_ask":"0.15"},{"asset_id":"63670753354844494163057275310194312729998307779831462269530137743341854359908","price":"0.86","size":"285.81","side":"SELL","hash":"7b6fe5a5578a37a00b490d5473a1ceefe46eaf62","best_bid":"0.85","best_ask":"0.86"}],"timestamp":"1768250243905","event_type":"price_change"}}
{"schema_version":1,"source":"clob_ws_market","recv_ts_ns":1768250244319736584,"event_type":"book","market":"0x2a12fd3d8235c25c062dc9652970ef9f635636c4018df0909e1a51c673e125cb","server_ts_ms":1768250243905,"raw":{"market":"0x2a12fd3d8235c25c062dc9652970ef9f635636c4018df0909e1a51c673e125cb","asset_id":"63670753354844494163057275310194312729998307779831462269530137743341854359908","bids":[{"price":"0.01","size":"10184.18"},{"price":"0.02","size":"5982"},{"price":"0.03","size":"5238.94"},{"price":"0.04","size":"5040"},{"price":"0.05","size":"5050"},{"price":"0.06","size":"5005"},{"price":"0.07","size":"5019.28"},{"price":"0.08","size":"5005"},{"price":"0.09","size":"5005"},{"price":"0.1","size":"5030"},{"price":"0.11","size":"5"},{"price":"0.12","size":"5"},{"price":"0.13","size":"5"},{"price":"0.14","size":"5"},{"price":"0.15","size":"10"},{"price":"0.16","size":"5"},{"price":"0.17","size":"5"},{"price":"0.18","size":"5"},{"price":"0.19","size":"5"},{"price":"0.2","size":"5"},{"price":"0.21","size":"5"},{"price":"0.22","size":"5"},{"price":"0.23","size":"5"},{"price":"0.24","size":"5"},{"price":"0.25","size":"10"},{"price":"0.26","size":"5"},{"price":"0.27","size":"5"},{"price":"0.28","size":"5"},{"price":"0.29","size":"15"},{"price":"0.3","size":"10"},{"price":"0.31","size":"5"},{"price":"0.32","size":"5"},{"price":"0.33","size":"5"},{"price":"0.34","size":"505"},{"price":"0.35","size":"510"},{"price":"0.36","size":"510"},{"price":"0.37","size":"505"},{"price":"0.38","size":"505"},{"price":"0.39","size":"755"},{"price":"0.4","size":"760"},{"price":"0.41","size":"916"},{"price":"0.42","size":"671"},{"price":"0.43","size":"827"},{"price":"0.44","size":"827"},{"price":"0.45","size":"817"},{"price":"0.46","size":"872"},{"price":"0.47","size":"839.65"},{"price":"0.48","size":"829"},{"price":"0.49","size":"817"},{"price":"0.5","size":"838.4"},{"price":"0.51","size":"867.58"},{"price":"0.52","size":"817"},{"price":"0.53","size":"827"},{"price":"0.54","size":"847.8"},{"price":"0.55","size":"836.09"},{"price":"0.56","size":"825"},{"price":"0.57","size":"847"},{"price":"0.58","size":"817"},{"price":"0.59","size":"817"},{"price":"0.6","size":"817"},{"price":"0.61","size":"834.5"},{"price":"0.62","size":"817"},{"price":"0.63","size":"497.49"},{"price":"0.64","size":"817"},{"price":"0.65","size":"872"},{"price":"0.66","size":"997.71"},{"price":"0.67","size":"906.8"},{"price":"0.68","size":"902"},{"price":"0.69","size":"922"},{"price":"0.7","size":"911.6"},{"price":"0.71","size":"897"},{"price":"0.72","size":"899.55"},{"price":"0.73","size":"912"},{"price":"0.74","size":"1174.42"},{"price":"0.75","size":"722.5"},{"price":"0.76","size":"924.25"},{"price":"0.77","size":"754.5"},{"price":"0.78","size":"910.8"},{"price":"0.79","size":"808.5"},{"price":"0.8","size":"814.9"},{"price":"0.81","size":"388.21"},{"price":"0.82","size":"871"},{"price":"0.83","size":"270.52"},{"price":"0.84","size":"186.5"},{"price":"0.85","size":"459.31"}],"asks":[{"price":"0.99","size":"10331.71"},{"price":"0.98","size":"6299.77"},{"price":"0.97","size":"5625.94"},{"price":"0.96","size":"5427"},{"price":"0.95","size":"3442"},{"price":"0.94","size":"1397"},{"price":"0.93","size":"1421.28"},{"price":"0.92","size":"1496.75"},{"price":"0.91","size":"1373"},{"price":"0.9","size":"3462"},{"price":"0.89","size":"869.5"},{"price":"0.88","size":"887.75"},{"price":"0.87","size":"361"},{"price":"0.86","size":"285.81"}],"hash":"7b6fe5a5578a37a00b490d5473a1ceefe46eaf62","timestamp":"1768250243905","event_type":"book"}}
{"schema_version":1,"source":"clob_ws_market","recv_ts_ns":1768250244323109548,"event_type":"price_change","market":"0x2a12fd3d8235c25c062dc9652970ef9f635636c4018df0909e1a51c673e125cb","server_ts_ms":1768250243907,"raw":{"market":"0x2a12fd3d8235c25c062dc9652970ef9f635636c4018df0909e1a51c673e125cb","price_changes":[{"asset_id":"56386988715176239099720172290594769295756680374928571099138069977179519358166","price":"0.12","size":"897.75","side":"BUY","hash":"d9e643e566b1c9cb6b43c870ce5bf9e368523e71","best_bid":"0.14","best_ask":"0.15"},{"asset_id":"63670753354844494163057275310194312729998307779831462269530137743341854359908","price":"0.88","size":"897.75","side":"SELL","hash":"d43f08cc1487e06f068dc34700b45b771d7917e6","best_bid":"0.85","best_ask":"0.86"}],"timestamp":"1768250243907","event_type":"price_change"}}
{"schema_version":1,"source":"clob_ws_market","recv_ts_ns":1768250244327822395,"event_type":"price_change","market":"0x2a12fd3d8235c25c062dc9652970ef9f635636c4018df0909e1a51c673e125cb","server_ts_ms":1768250243907,"raw":{"market":"0x2a12fd3d8235c25c062dc9652970ef9f635636c4018df0909e1a51c673e125cb","price_changes":[{"asset_id":"63670753354844494163057275310194312729998307779831462269530137743341854359908","price":"0.82","size":"881","side":"BUY","hash":"0af224b392b04f66c3a2566a851d4558a7a2e7b5","best_bid":"0.85","best_ask":"0.86"},{"asset_id":"56386988715176239099720172290594769295756680374928571099138069977179519358166","price":"0.18","size":"881","side":"SELL","hash":"8aa126e57786428c961b3f5d859a96a960a3180a","best_bid":"0.14","best_ask":"0.15"}],"timestamp":"1768250243907","event_type":"price_change"}}
{"schema_version":1,"source":"clob_ws_market","recv_ts_ns":1768250244331697736,"event_type":"price_change","market":"0x2a12fd3d8235c25c062dc9652970ef9f635636c4018df0909e1a51c673e125cb","server_ts_ms":1768250243923,"raw":{"market":"0x2a12fd3d8235c25c062dc9652970ef9f635636c4018df0909e1a51c673e125cb","price_changes":[{"asset_id":"63670753354844494163057275310194312729998307779831462269530137743341854359908","price":"0.81","size":"313.21","side":"BUY","hash":"f6b82ee035c99f3e973bab372c7ffe5449f09755","best_bid":"0.85","best_ask":"0.86"},{"asset_id":"56386988715176239099720172290594769295756680374928571099138069977179519358166","price":"0.19","size":"313.21","side":"SELL","hash":"c37fc57e5e64d4afbcf1f21c8c23a43de9d15651","best_bid":"0.14","best_ask":"0.15"}],"timestamp":"1768250243923","event_type":"price_change"}}
{"schema_version":1,"source":"clob_ws_market","recv_ts_ns":1768250244335362651,"event_type":"last_trade_price","market":"0x2a12fd3d8235c25c062dc9652970ef9f635636c4018df0909e1a51c673e125cb","server_ts_ms":1768250243927,"raw":{"market":"0x2a12fd3d8235c25c062dc9652970ef9f635636c4018df0909e1a51c673e125cb","asset_id":"63670753354844494163057275310194312729998307779831462269530137743341854359908","price":"0.86","size":"10.267435","fee_rate_bps":"1000","side":"BUY","timestamp":"1768250243927","event_type":"last_trade_price","transaction_hash":"0xc1af211b1dda67b919102be47d6f4215aeb4bcaa56db502baf4b1d855b941f0a"}}
{"schema_version":1,"source":"clob_ws_market","recv_ts_ns":1768250244337075333,"event_type":"last_trade_price","market":"0x2a12fd3d8235c25c062dc9652970ef9f635636c4018df0909e1a51c673e125cb","server_ts_ms":1768250243933,"raw":{"market":"0x2a12fd3d8235c25c062dc9652970ef9f635636c4018df0909e1a51c673e125cb","asset_id":"63670753354844494163057275310194312729998307779831462269530137743341854359908","price":"0.86","size":"1.848835","fee_rate_bps":"1000","side":"BUY","timestamp":"1768250243933","event_type":"last_trade_price","transaction_hash":"0x7671d448e8852d7a2aeeade84da019cd5645919d62ae6ccad79f598e8d6801d3"}}
{"schema_version":1,"source":"clob_ws_market","recv_ts_ns":1768250244338729701,"event_type":"price_change","market":"0x2a12fd3d8235c25c062dc9652970ef9f635636c4018df0909e1a51c673e125cb","server_ts_ms":1768250243951,"raw":{"market":"0x2a12fd3d8235c25c062dc9652970ef9f635636c4018df0909e1a51c673e125cb","price_changes":[{"asset_id":"63670753354844494163057275310194312729998307779831462269530137743341854359908","price":"0.83","size":"280.52","side":"BUY","hash":"049ed1379d2bb0680d5858d821d17de5b4ae1b69","best_bid":"0.85","best_ask":"0.86"},{"asset_id":"56386988715176239099720172290594769295756680374928571099138069977179519358166","price":"0.17","size":"280.52","side":"SELL","hash":"9af10606769c68a4c31764c025a81739b6afeef2","best_bid":"0.14","best_ask":"0.15"}],"timestamp":"1768250243951","event_type":"price_change"}}
{"schema_version":1,"source":"clob_ws_market","recv_ts_ns":1768250244366755447,"event_type":"price_change","market":"0x2a12fd3d8235c25c062dc9652970ef9f635636c4018df0909e1a51c673e125cb","server_ts_ms":1768250244053,"raw":{"market":"0x2a12fd3d8235c25c062dc9652970ef9f635636c4018df0909e1a51c673e125cb","price_changes":[{"asset_id":"63670753354844494163057275310194312729998307779831462269530137743341854359908","price":"0.83","size":"270.52","side":"BUY","hash":"fed84544354b7247e829f340e91db332d0fbf0bb","best_bid":"0.85","best_ask":"0.86"},{"asset_id":"56386988715176239099720172290594769295756680374928571099138069977179519358166","price":"0.17","size":"270.52","side":"SELL","hash":"14f15f48616a3da343595461f62c505f20a3be48","best_bid":"0.14","best_ask":"0.15"}],"timestamp":"1768250244053","event_type":"price_change"}}
{"schema_version":1,"source":"clob_ws_market","recv_ts_ns":1768250244372564554,"event_type":"price_change","market":"0x2a12fd3d8235c25c062dc9652970ef9f635636c4018df0909e1a51c673e125cb","server_ts_ms":1768250244059,"raw":{"market":"0x2a12fd3d8235c25c062dc9652970ef9f635636c4018df0909e1a51c673e125cb","price_changes":[{"asset_id":"63670753354844494163057275310194312729998307779831462269530137743341854359908","price":"0.84","size":"196.5","side":"BUY","hash":"609704fdfb90c9bb0ccd158fe573563f61b143a7","best_bid":"0.85","best_ask":"0.86"},{"asset_id":"56386988715176239099720172290594769295756680374928571099138069977179519358166","price":"0.16","size":"196.5","side":"SELL","hash":"d6d27760895b7beb5a8787b3f7f2856762e04db0","best_bid":"0.14","best_ask":"0.15"}],"timestamp":"1768250244059","event_type":"price_change"}}
{"schema_version":1,"source":"clob_ws_market","recv_ts_ns":1768250244402182423,"event_type":"best_bid_ask","market":"0x2a12fd3d8235c25c062dc9652970ef9f635636c4018df0909e1a51c673e125cb","server_ts_ms":1768250244235,"raw":{"market":"0x2a12fd3d8235c25c062dc9652970ef9f635636c4018df0909e1a51c673e125cb","asset_id":"63670753354844494163057275310194312729998307779831462269530137743341854359908","best_bid":"0.85","best_ask":"0.86","spread":"0.01","timestamp":"1768250244235","event_type":"best_bid_ask"}}
{"schema_version":1,"source":"clob_ws_market","recv_ts_ns":1768250244403459093,"event_type":"price_change","market":"0x2a12fd3d8235c25c062dc9652970ef9f635636c4018df0909e1a51c673e125cb","server_ts_ms":1768250244233,"raw":{"market":"0x2a12fd3d8235c25c062dc9652970ef9f635636c4018df0909e1a51c673e125cb","price_changes":[{"asset_id":"63670753354844494163057275310194312729998307779831462269530137743341854359908","price":"0.85","size":"405.97","side":"BUY","hash":"930b594c6f6529d73e503b373a7e2a2cb9ed1a28","best_bid":"0.85","best_ask":"0.86"},{"asset_id":"56386988715176239099720172290594769295756680374928571099138069977179519358166","price":"0.15","size":"405.97","side":"SELL","hash":"522677c89fd5d955769eede23275119471d5fe73","best_bid":"0.14","best_ask":"0.15"}],"timestamp":"1768250244233","event_type":"price_change"}}
{"schema_version":1,"source":"clob_ws_market","recv_ts_ns":1768250244406013895,"event_type":"price_change","market":"0x2a12fd3d8235c25c062dc9652970ef9f635636c4018df0909e1a51c673e125cb","server_ts_ms":1768250244233,"raw":{"market":"0x2a12fd3d8235c25c062dc9652970ef9f635636c4018df0909e1a51c673e125cb","price_changes":[{"asset_id":"56386988715176239099720172290594769295756680374928571099138069977179519358166","price":"0.15","size":"405.97","side":"SELL","hash":"522677c89fd5d955769eede23275119471d5fe73","best_bid":"0.14","best_ask":"0.15"},{"asset_id":"63670753354844494163057275310194312729998307779831462269530137743341854359908","price":"0.85","size":"405.97","side":"BUY","hash":"930b594c6f6529d73e503b373a7e2a2cb9ed1a28","best_bid":"0.85","best_ask":"0.86"}],"timestamp":"1768250244233","event_type":"price_change"}}
{"schema_version":1,"source":"clob_ws_market","recv_ts_ns":1768250244411522046,"event_type":"book","market":"0x2a12fd3d8235c25c062dc9652970ef9f635636c4018df0909e1a51c673e125cb","server_ts_ms":1768250244233,"raw":{"market":"0x2a12fd3d8235c25c062dc9652970ef9f635636c4018df0909e1a51c673e125cb","asset_id":"63670753354844494163057275310194312729998307779831462269530137743341854359908","bids":[{"price":"0.01","size":"10184.18"},{"price":"0.02","size":"5982"},{"price":"0.03","size":"5238.94"},{"price":"0.04","size":"5040"},{"price":"0.05","size":"5050"},{"price":"0.06","size":"5005"},{"price":"0.07","size":"5019.28"},{"price":"0.08","size":"5005"},{"price":"0.09","size":"5005"},{"price":"0.1","size":"5030"},{"price":"0.11","size":"5"},{"price":"0.12","size":"5"},{"price":"0.13","size":"5"},{"price":"0.14","size":"5"},{"price":"0.15","size":"10"},{"price":"0.16","size":"5"},{"price":"0.17","size":"5"},{"price":"0.18","size":"5"},{"price":"0.19","size":"5"},{"price":"0.2","size":"5"},{"price":"0.21","size":"5"},{"price":"0.22","size":"5"},{"price":"0.23","size":"5"},{"price":"0.24","size":"5"},{"price":"0.25","size":"10"},{"price":"0.26","size":"5"},{"price":"0.27","size":"5"},{"price":"0.28","size":"5"},{"price":"0.29","size":"15"},{"price":"0.3","size":"10"},{"price":"0.31","size":"5"},{"price":"0.32","size":"5"},{"price":"0.33","size":"5"},{"price":"0.34","size":"505"},{"price":"0.35","size":"510"},{"price":"0.36","size":"510"},{"price":"0.37","size":"505"},{"price":"0.38","size":"505"},{"price":"0.39","size":"755"},{"price":"0.4","size":"760"},{"price":"0.41","size":"916"},{"price":"0.42","size":"671"},{"price":"0.43","size":"827"},{"price":"0.44","size":"827"},{"price":"0.45","size":"817"},{"price":"0.46","size":"872"},{"price":"0.47","size":"839.65"},{"price":"0.48","size":"829"},{"price":"0.49","size":"817"},{"price":"0.5","size":"838.4"},{"price":"0.51","size":"867.58"},{"price":"0.52","size":"817"},{"price":"0.53","size":"827"},{"price":"0.54","size":"847.8"},{"price":"0.55","size":"836.09"},{"price":"0.56","size":"825"},{"price":"0.57","size":"847"},{"price":"0.58","size":"817"},{"price":"0.59","size":"817"},{"price":"0.6","size":"817"},{"price":"0.61","size":"834.5"},{"price":"0.62","size":"817"},{"price":"0.63","size":"497.49"},{"price":"0.64","size":"817"},{"price":"0.65","size":"872"},{"price":"0.66","size":"997.71"},{"price":"0.67","size":"906.8"},{"price":"0.68","size":"902"},{"price":"0.69","size":"922"},{"price":"0.7","size":"911.6"},{"price":"0.71","size":"897"},{"price":"0.72","size":"899.55"},{"price":"0.73","size":"912"},{"price":"0.74","size":"1174.42"},{"price":"0.75","size":"722.5"},{"price":"0.76","size":"924.25"},{"price":"0.77","size":"754.5"},{"price":"0.78","size":"910.8"},{"price":"0.79","size":"808.5"},{"price":"0.8","size":"814.9"},{"price":"0.81","size":"313.21"},{"price":"0.82","size":"881"},{"price":"0.83","size":"270.52"},{"price":"0.84","size":"196.5"},{"price":"0.85","size":"405.97"}],"asks":[{"price":"0.99","size":"10331.71"},{"price":"0.98","size":"6299.77"},{"price":"0.97","size":"5625.94"},{"price":"0.96","size":"5427"},{"price":"0.95","size":"3442"},{"price":"0.94","size":"1397"},{"price":"0.93","size":"1421.28"},{"price":"0.92","size":"1496.75"},{"price":"0.91","size":"1373"},{"price":"0.9","size":"3462"},{"price":"0.89","size":"869.5"},{"price":"0.88","size":"897.75"},{"price":"0.87","size":"361"},{"price":"0.86","size":"285.81"}],"hash":"930b594c6f6529d73e503b373a7e2a2cb9ed1a28","timestamp":"1768250244233","event_type":"book"}}
{"schema_version":1,"source":"clob_ws_market","recv_ts_ns":1768250244415947055,"event_type":"best_bid_ask","market":"0x2a12fd3d8235c25c062dc9652970ef9f635636c4018df0909e1a51c673e125cb","server_ts_ms":1768250244239,"raw":{"market":"0x2a12fd3d8235c25c062dc9652970ef9f635636c4018df0909e1a51c673e125cb","asset_id":"63670753354844494163057275310194312729998307779831462269530137743341854359908","best_bid":"0.85","best_ask":"0.86","spread":"0.01","timestamp":"1768250244239","event_type":"best_bid_ask"}}
{"schema_version":1,"source":"clob_ws_market","recv_ts_ns":1768250244417279163,"event_type":"price_change","market":"0x2a12fd3d8235c25c062dc9652970ef9f635636c4018df0909e1a51c673e125cb","server_ts_ms":1768250244238,"raw":{"market":"0x2a12fd3d8235c25c062dc9652970ef9f635636c4018df0909e1a51c673e125cb","price_changes":[{"asset_id":"63670753354844494163057275310194312729998307779831462269530137743341854359908","price":"0.85","size":"373.97","side":"BUY","hash":"2af7a27fcd37370a105a499cb8cc1e2f0d084497","best_bid":"0.85","best_ask":"0.86"},{"asset_id":"56386988715176239099720172290594769295756680374928571099138069977179519358166","price":"0.15","size":"373.97","side":"SELL","hash":"930a29ee3da6e02941f650cb7430f9730dd1c221","best_bid":"0.14","best_ask":"0.15"}],"timestamp":"1768250244238","event_type":"price_change"}}
{"schema_version":1,"source":"clob_ws_market","recv_ts_ns":1768250244422811585,"event_type":"book","market":"0x2a12fd3d8235c25c062dc9652970ef9f635636c4018df0909e1a51c673e125cb","server_ts_ms":1768250244238,"raw":{"market":"0x2a12fd3d8235c25c062dc9652970ef9f635636c4018df0909e1a51c673e125cb","asset_id":"63670753354844494163057275310194312729998307779831462269530137743341854359908","bids":[{"price":"0.01","size":"10184.18"},{"price":"0.02","size":"5982"},{"price":"0.03","size":"5238.94"},{"price":"0.04","size":"5040"},{"price":"0.05","size":"5050"},{"price":"0.06","size":"5005"},{"price":"0.07","size":"5019.28"},{"price":"0.08","size":"5005"},{"price":"0.09","size":"5005"},{"price":"0.1","size":"5030"},{"price":"0.11","size":"5"},{"price":"0.12","size":"5"},{"price":"0.13","size":"5"},{"price":"0.14","size":"5"},{"price":"0.15","size":"10"},{"price":"0.16","size":"5"},{"price":"0.17","size":"5"},{"price":"0.18","size":"5"},{"price":"0.19","size":"5"},{"price":"0.2","size":"5"},{"price":"0.21","size":"5"},{"price":"0.22","size":"5"},{"price":"0.23","size":"5"},{"price":"0.24","size":"5"},{"price":"0.25","size":"10"},{"price":"0.26","size":"5"},{"price":"0.27","size":"5"},{"price":"0.28","size":"5"},{"price":"0.29","size":"15"},{"price":"0.3","size":"10"},{"price":"0.31","size":"5"},{"price":"0.32","size":"5"},{"price":"0.33","size":"5"},{"price":"0.34","size":"505"},{"price":"0.35","size":"510"},{"price":"0.36","size":"510"},{"price":"0.37","size":"505"},{"price":"0.38","size":"505"},{"price":"0.39","size":"755"},{"price":"0.4","size":"760"},{"price":"0.41","size":"916"},{"price":"0.42","size":"671"},{"price":"0.43","size":"827"},{"price":"0.44","size":"827"},{"price":"0.45","size":"817"},{"price":"0.46","size":"872"},{"price":"0.47","size":"839.65"},{"price":"0.48","size":"829"},{"price":"0.49","size":"817"},{"price":"0.5","size":"838.4"},{"price":"0.51","size":"867.58"},{"price":"0.52","size":"817"},{"price":"0.53","size":"827"},{"price":"0.54","size":"847.8"},{"price":"0.55","size":"836.09"},{"price":"0.56","size":"825"},{"price":"0.57","size":"847"},{"price":"0.58","size":"817"},{"price":"0.59","size":"817"},{"price":"0.6","size":"817"},{"price":"0.61","size":"834.5"},{"price":"0.62","size":"817"},{"price":"0.63","size":"497.49"},{"price":"0.64","size":"817"},{"price":"0.65","size":"872"},{"price":"0.66","size":"997.71"},{"price":"0.67","size":"906.8"},{"price":"0.68","size":"902"},{"price":"0.69","size":"922"},{"price":"0.7","size":"911.6"},{"price":"0.71","size":"897"},{"price":"0.72","size":"899.55"},{"price":"0.73","size":"912"},{"price":"0.74","size":"1174.42"},{"price":"0.75","size":"722.5"},{"price":"0.76","size":"924.25"},{"price":"0.77","size":"754.5"},{"price":"0.78","size":"910.8"},{"price":"0.79","size":"808.5"},{"price":"0.8","size":"814.9"},{"price":"0.81","size":"313.21"},{"price":"0.82","size":"881"},{"price":"0.83","size":"270.52"},{"price":"0.84","size":"196.5"},{"price":"0.85","size":"373.97"}],"asks":[{"price":"0.99","size":"10331.71"},{"price":"0.98","size":"6299.77"},{"price":"0.97","size":"5625.94"},{"price":"0.96","size":"5427"},{"price":"0.95","size":"3442"},{"price":"0.94","size":"1397"},{"price":"0.93","size":"1421.28"},{"price":"0.92","size":"1496.75"},{"price":"0.91","size":"1373"},{"price":"0.9","size":"3462"},{"price":"0.89","size":"869.5"},{"price":"0.88","size":"897.75"},{"price":"0.87","size":"361"},{"price":"0.86","size":"285.81"}],"hash":"2af7a27fcd37370a105a499cb8cc1e2f0d084497","timestamp":"1768250244238","event_type":"book"}}
{"schema_version":1,"source":"clob_ws_market","recv_ts_ns":1768250244425686039,"event_type":"best_bid_ask","market":"0x2a12fd3d8235c25c062dc9652970ef9f635636c4018df0909e1a51c673e125cb","server_ts_ms":1768250244243,"raw":{"market":"0x2a12fd3d8235c25c062dc9652970ef9f635636c4018df0909e1a51c673e125cb","asset_id":"63670753354844494163057275310194312729998307779831462269530137743341854359908","best_bid":"0.85","best_ask":"0.86","spread":"0.01","timestamp":"1768250244243","event_type":"best_bid_ask"}}
{"schema_version":1,"source":"clob_ws_market","recv_ts_ns":1768250244427051573,"event_type":"price_change","market":"0x2a12fd3d8235c25c062dc9652970ef9f635636c4018df0909e1a51c673e125cb","server_ts_ms":1768250244242,"raw":{"market":"0x2a12fd3d8235c25c062dc9652970ef9f635636c4018df0909e1a51c673e125cb","price_changes":[{"asset_id":"63670753354844494163057275310194312729998307779831462269530137743341854359908","price":"0.85","size":"320.63","side":"BUY","hash":"798e439e5472bff1fd689dcbd98065fe8b8e2205","best_bid":"0.85","best_ask":"0.86"},{"asset_id":"56386988715176239099720172290594769295756680374928571099138069977179519358166","price":"0.15","size":"320.63","side":"SELL","hash":"5f49610649f4d6b9b85cbaff7aee54739e581dbf","best_bid":"0.14","best_ask":"0.15"}],"timestamp":"1768250244242","event_type":"price_change"}}
{"schema_version":1,"source":"clob_ws_market","recv_ts_ns":1768250244432589885,"event_type":"book","market":"0x2a12fd3d8235c25c062dc9652970ef9f635636c4018df0909e1a51c673e125cb","server_ts_ms":1768250244242,"raw":{"market":"0x2a12fd3d8235c25c062dc9652970ef9f635636c4018df0909e1a51c673e125cb","asset_id":"63670753354844494163057275310194312729998307779831462269530137743341854359908","bids":[{"price":"0.01","size":"10184.18"},{"price":"0.02","size":"5982"},{"price":"0.03","size":"5238.94"},{"price":"0.04","size":"5040"},{"price":"0.05","size":"5050"},{"price":"0.06","size":"5005"},{"price":"0.07","size":"5019.28"},{"price":"0.08","size":"5005"},{"price":"0.09","size":"5005"},{"price":"0.1","size":"5030"},{"price":"0.11","size":"5"},{"price":"0.12","size":"5"},{"price":"0.13","size":"5"},{"price":"0.14","size":"5"},{"price":"0.15","size":"10"},{"price":"0.16","size":"5"},{"price":"0.17","size":"5"},{"price":"0.18","size":"5"},{"price":"0.19","size":"5"},{"price":"0.2","size":"5"},{"price":"0.21","size":"5"},{"price":"0.22","size":"5"},{"price":"0.23","size":"5"},{"price":"0.24","size":"5"},{"price":"0.25","size":"10"},{"price":"0.26","size":"5"},{"price":"0.27","size":"5"},{"price":"0.28","size":"5"},{"price":"0.29","size":"15"},{"price":"0.3","size":"10"},{"price":"0.31","size":"5"},{"price":"0.32","size":"5"},{"price":"0.33","size":"5"},{"price":"0.34","size":"505"},{"price":"0.35","size":"510"},{"price":"0.36","size":"510"},{"price":"0.37","size":"505"},{"price":"0.38","size":"505"},{"price":"0.39","size":"755"},{"price":"0.4","size":"760"},{"price":"0.41","size":"916"},{"price":"0.42","size":"671"},{"price":"0.43","size":"827"},{"price":"0.44","size":"827"},{"price":"0.45","size":"817"},{"price":"0.46","size":"872"},{"price":"0.47","size":"839.65"},{"price":"0.48","size":"829"},{"price":"0.49","size":"817"},{"price":"0.5","size":"838.4"},{"price":"0.51","size":"867.58"},{"price":"0.52","size":"817"},{"price":"0.53","size":"827"},{"price":"0.54","size":"847.8"},{"price":"0.55","size":"836.09"},{"price":"0.56","size":"825"},{"price":"0.57","size":"847"},{"price":"0.58","size":"817"},{"price":"0.59","size":"817"},{"price":"0.6","size":"817"},{"price":"0.61","size":"834.5"},{"price":"0.62","size":"817"},{"price":"0.63","size":"497.49"},{"price":"0.64","size":"817"},{"price":"0.65","size":"872"},{"price":"0.66","size":"997.71"},{"price":"0.67","size":"906.8"},{"price":"0.68","size":"902"},{"price":"0.69","size":"922"},{"price":"0.7","size":"911.6"},{"price":"0.71","size":"897"},{"price":"0.72","size":"899.55"},{"price":"0.73","size":"912"},{"price":"0.74","size":"1174.42"},{"price":"0.75","size":"722.5"},{"price":"0.76","size":"924.25"},{"price":"0.77","size":"754.5"},{"price":"0.78","size":"910.8"},{"price":"0.79","size":"808.5"},{"price":"0.8","size":"814.9"},{"price":"0.81","size":"313.21"},{"price":"0.82","size":"881"},{"price":"0.83","size":"270.52"},{"price":"0.84","size":"196.5"},{"price":"0.85","size":"320.63"}],"asks":[{"price":"0.99","size":"10331.71"},{"price":"0.98","size":"6299.77"},{"price":"0.97","size":"5625.94"},{"price":"0.96","size":"5427"},{"price":"0.95","size":"3442"},{"price":"0.94","size":"1397"},{"price":"0.93","size":"1421.28"},{"price":"0.92","size":"1496.75"},{"price":"0.91","size":"1373"},{"price":"0.9","size":"3462"},{"price":"0.89","size":"869.5"},{"price":"0.88","size":"897.75"},{"price":"0.87","size":"361"},{"price":"0.86","size":"285.81"}],"hash":"798e439e5472bff1fd689dcbd98065fe8b8e2205","timestamp":"1768250244242","event_type":"book"}}
{"schema_version":1,"source":"clob_ws_market","recv_ts_ns":1768250244435815828,"event_type":"best_bid_ask","market":"0x2a12fd3d8235c25c062dc9652970ef9f635636c4018df0909e1a51c673e125cb","server_ts_ms":1768250244247,"raw":{"market":"0x2a12fd3d8235c25c062dc9652970ef9f635636c4018df0909e1a51c673e125cb","asset_id":"63670753354844494163057275310194312729998307779831462269530137743341854359908","best_bid":"0.85","best_ask":"0.86","spread":"0.01","timestamp":"1768250244247","event_type":"best_bid_ask"}}
{"schema_version":1,"source":"clob_ws_market","recv_ts_ns":1768250244437075775,"event_type":"price_change","market":"0x2a12fd3d8235c25c062dc9652970ef9f635636c4018df0909e1a51c673e125cb","server_ts_ms":1768250244246,"raw":{"market":"0x2a12fd3d8235c25c062dc9652970ef9f635636c4018df0909e1a51c673e125cb","price_changes":[{"asset_id":"63670753354844494163057275310194312729998307779831462269530137743341854359908","price":"0.85","size":"267.29","side":"BUY","hash":"9364383d7f1b6c498cd87b311e381f8834fea67a","best_bid":"0.85","best_ask":"0.86"},{"asset_id":"56386988715176239099720172290594769295756680374928571099138069977179519358166","price":"0.15","size":"267.29","side":"SELL","hash":"8bb0ea327660a984d2422baee2e4014819e54b23","best_bid":"0.14","best_ask":"0.15"}],"timestamp":"1768250244246","event_type":"price_change"}}
{"schema_version":1,"source":"clob_ws_market","recv_ts_ns":1768250244441751406,"event_type":"book","market":"0x2a12fd3d8235c25c062dc9652970ef9f635636c4018df0909e1a51c673e125cb","server_ts_ms":1768250244246,"raw":{"market":"0x2a12fd3d8235c25c062dc9652970ef9f635636c4018df0909e1a51c673e125cb","asset_id":"63670753354844494163057275310194312729998307779831462269530137743341854359908","bids":[{"price":"0.01","size":"10184.18"},{"price":"0.02","size":"5982"},{"price":"0.03","size":"5238.94"},{"price":"0.04","size":"5040"},{"price":"0.05","size":"5050"},{"price":"0.06","size":"5005"},{"price":"0.07","size":"5019.28"},{"price":"0.08","size":"5005"},{"price":"0.09","size":"5005"},{"price":"0.1","size":"5030"},{"price":"0.11","size":"5"},{"price":"0.12","size":"5"},{"price":"0.13","size":"5"},{"price":"0.14","size":"5"},{"price":"0.15","size":"10"},{"price":"0.16","size":"5"},{"price":"0.17","size":"5"},{"price":"0.18","size":"5"},{"price":"0.19","size":"5"},{"price":"0.2","size":"5"},{"price":"0.21","size":"5"},{"price":"0.22","size":"5"},{"price":"0.23","size":"5"},{"price":"0.24","size":"5"},{"price":"0.25","size":"10"},{"price":"0.26","size":"5"},{"price":"0.27","size":"5"},{"price":"0.28","size":"5"},{"price":"0.29","size":"15"},{"price":"0.3","size":"10"},{"price":"0.31","size":"5"},{"price":"0.32","size":"5"},{"price":"0.33","size":"5"},{"price":"0.34","size":"505"},{"price":"0.35","size":"510"},{"price":"0.36","size":"510"},{"price":"0.37","size":"505"},{"price":"0.38","size":"505"},{"price":"0.39","size":"755"},{"price":"0.4","size":"760"},{"price":"0.41","size":"916"},{"price":"0.42","size":"671"},{"price":"0.43","size":"827"},{"price":"0.44","size":"827"},{"price":"0.45","size":"817"},{"price":"0.46","size":"872"},{"price":"0.47","size":"839.65"},{"price":"0.48","size":"829"},{"price":"0.49","size":"817"},{"price":"0.5","size":"838.4"},{"price":"0.51","size":"867.58"},{"price":"0.52","size":"817"},{"price":"0.53","size":"827"},{"price":"0.54","size":"847.8"},{"price":"0.55","size":"836.09"},{"price":"0.56","size":"825"},{"price":"0.57","size":"847"},{"price":"0.58","size":"817"},{"price":"0.59","size":"817"},{"price":"0.6","size":"817"},{"price":"0.61","size":"834.5"},{"price":"0.62","size":"817"},{"price":"0.63","size":"497.49"},{"price":"0.64","size":"817"},{"price":"0.65","size":"872"},{"price":"0.66","size":"997.71"},{"price":"0.67","size":"906.8"},{"price":"0.68","size":"902"},{"price":"0.69","size":"922"},{"price":"0.7","size":"911.6"},{"price":"0.71","size":"897"},{"price":"0.72","size":"899.55"},{"price":"0.73","size":"912"},{"price":"0.74","size":"1174.42"},{"price":"0.75","size":"722.5"},{"price":"0.76","size":"924.25"},{"price":"0.77","size":"754.5"},{"price":"0.78","size":"910.8"},{"price":"0.79","size":"808.5"},{"price":"0.8","size":"814.9"},{"price":"0.81","size":"313.21"},{"price":"0.82","size":"881"},{"price":"0.83","size":"270.52"},{"price":"0.84","size":"196.5"},{"price":"0.85","size":"267.29"}],"asks":[{"price":"0.99","size":"10331.71"},{"price":"0.98","size":"6299.77"},{"price":"0.97","size":"5625.94"},{"price":"0.96","size":"5427"},{"price":"0.95","size":"3442"},{"price":"0.94","size":"1397"},{"price":"0.93","size":"1421.28"},{"price":"0.92","size":"1496.75"},{"price":"0.91","size":"1373"},{"price":"0.9","size":"3462"},{"price":"0.89","size":"869.5"},{"price":"0.88","size":"897.75"},{"price":"0.87","size":"361"},{"price":"0.86","size":"285.81"}],"hash":"9364383d7f1b6c498cd87b311e381f8834fea67a","timestamp":"1768250244246","event_type":"book"}}
{"schema_version":1,"source":"clob_ws_market","recv_ts_ns":1768250244444149923,"event_type":"best_bid_ask","market":"0x2a12fd3d8235c25c062dc9652970ef9f635636c4018df0909e1a51c673e125cb","server_ts_ms":1768250244252,"raw":{"market":"0x2a12fd3d8235c25c062dc9652970ef9f635636c4018df0909e1a51c673e125cb","asset_id":"63670753354844494163057275310194312729998307779831462269530137743341854359908","best_bid":"0.85","best_ask":"0.86","spread":"0.01","timestamp":"1768250244252","event_type":"best_bid_ask"}}
{"schema_version":1,"source":"clob_ws_market","recv_ts_ns":1768250244445286801,"event_type":"price_change","market":"0x2a12fd3d8235c25c062dc9652970ef9f635636c4018df0909e1a51c673e125cb","server_ts_ms":1768250244251,"raw":{"market":"0x2a12fd3d8235c25c062dc9652970ef9f635636c4018df0909e1a51c673e125cb","price_changes":[{"asset_id":"63670753354844494163057275310194312729998307779831462269530137743341854359908","price":"0.85","size":"213.95","side":"BUY","hash":"11bce78d346c7d6d6c365178722f9ca66e3bcc3b","best_bid":"0.85","best_ask":"0.86"},{"asset_id":"56386988715176239099720172290594769295756680374928571099138069977179519358166","price":"0.15","size":"213.95","side":"SELL","hash":"5871d226747883e20e4060550f317e744189058f","best_bid":"0.14","best_ask":"0.15"}],"timestamp":"1768250244251","event_type":"price_change"}}
{"schema_version":1,"source":"clob_ws_market","recv_ts_ns":1768250244450567500,"event_type":"book","market":"0x2a12fd3d8235c25c062dc9652970ef9f635636c4018df0909e1a51c673e125cb","server_ts_ms":1768250244251,"raw":{"market":"0x2a12fd3d8235c25c062dc9652970ef9f635636c4018df0909e1a51c673e125cb","asset_id":"63670753354844494163057275310194312729998307779831462269530137743341854359908","bids":[{"price":"0.01","size":"10184.18"},{"price":"0.02","size":"5982"},{"price":"0.03","size":"5238.94"},{"price":"0.04","size":"5040"},{"price":"0.05","size":"5050"},{"price":"0.06","size":"5005"},{"price":"0.07","size":"5019.28"},{"price":"0.08","size":"5005"},{"price":"0.09","size":"5005"},{"price":"0.1","size":"5030"},{"price":"0.11","size":"5"},{"price":"0.12","size":"5"},{"price":"0.13","size":"5"},{"price":"0.14","size":"5"},{"price":"0.15","size":"10"},{"price":"0.16","size":"5"},{"price":"0.17","size":"5"},{"price":"0.18","size":"5"},{"price":"0.19","size":"5"},{"price":"0.2","size":"5"},{"price":"0.21","size":"5"},{"price":"0.22","size":"5"},{"price":"0.23","size":"5"},{"price":"0.24","size":"5"},{"price":"0.25","size":"10"},{"price":"0.26","size":"5"},{"price":"0.27","size":"5"},{"price":"0.28","size":"5"},{"price":"0.29","size":"15"},{"price":"0.3","size":"10"},{"price":"0.31","size":"5"},{"price":"0.32","size":"5"},{"price":"0.33","size":"5"},{"price":"0.34","size":"505"},{"price":"0.35","size":"510"},{"price":"0.36","size":"510"},{"price":"0.37","size":"505"},{"price":"0.38","size":"505"},{"price":"0.39","size":"755"},{"price":"0.4","size":"760"},{"price":"0.41","size":"916"},{"price":"0.42","size":"671"},{"price":"0.43","size":"827"},{"price":"0.44","size":"827"},{"price":"0.45","size":"817"},{"price":"0.46","size":"872"},{"price":"0.47","size":"839.65"},{"price":"0.48","size":"829"},{"price":"0.49","size":"817"},{"price":"0.5","size":"838.4"},{"price":"0.51","size":"867.58"},{"price":"0.52","size":"817"},{"price":"0.53","size":"827"},{"price":"0.54","size":"847.8"},{"price":"0.55","size":"836.09"},{"price":"0.56","size":"825"},{"price":"0.57","size":"847"},{"price":"0.58","size":"817"},{"price":"0.59","size":"817"},{"price":"0.6","size":"817"},{"price":"0.61","size":"834.5"},{"price":"0.62","size":"817"},{"price":"0.63","size":"497.49"},{"price":"0.64","size":"817"},{"price":"0.65","size":"872"},{"price":"0.66","size":"997.71"},{"price":"0.67","size":"906.8"},{"price":"0.68","size":"902"},{"price":"0.69","size":"922"},{"price":"0.7","size":"911.6"},{"price":"0.71","size":"897"},{"price":"0.72","size":"899.55"},{"price":"0.73","size":"912"},{"price":"0.74","size":"1174.42"},{"price":"0.75","size":"722.5"},{"price":"0.76","size":"924.25"},{"price":"0.77","size":"754.5"},{"price":"0.78","size":"910.8"},{"price":"0.79","size":"808.5"},{"price":"0.8","size":"814.9"},{"price":"0.81","size":"313.21"},{"price":"0.82","size":"881"},{"price":"0.83","size":"270.52"},{"price":"0.84","size":"196.5"},{"price":"0.85","size":"213.95"}],"asks":[{"price":"0.99","size":"10331.71"},{"price":"0.98","size":"6299.77"},{"price":"0.97","size":"5625.94"},{"price":"0.96","size":"5427"},{"price":"0.95","size":"3442"},{"price":"0.94","size":"1397"},{"price":"0.93","size":"1421.28"},{"price":"0.92","size":"1496.75"},{"price":"0.91","size":"1373"},{"price":"0.9","size":"3462"},{"price":"0.89","size":"869.5"},{"price":"0.88","size":"897.75"},{"price":"0.87","size":"361"},{"price":"0.86","size":"285.81"}],"hash":"11bce78d346c7d6d6c365178722f9ca66e3bcc3b","timestamp":"1768250244251","event_type":"book"}}
{"schema_version":1,"source":"clob_ws_market","recv_ts_ns":1768250244455449836,"event_type":"price_change","market":"0x2a12fd3d8235c25c062dc9652970ef9f635636c4018df0909e1a51c673e125cb","server_ts_ms":1768250244270,"raw":{"market":"0x2a12fd3d8235c25c062dc9652970ef9f635636c4018df0909e1a51c673e125cb","price_changes":[{"asset_id":"56386988715176239099720172290594769295756680374928571099138069977179519358166","price":"0.14","size":"315.81","side":"BUY","hash":"cf37a4dcabec7c54b85ed273c577ddbdf6af9406","best_bid":"0.14","best_ask":"0.15"},{"asset_id":"63670753354844494163057275310194312729998307779831462269530137743341854359908","price":"0.86","size":"315.81","side":"SELL","hash":"257bb260fe4957e7d251c4053125351174c5efae","best_bid":"0.85","best_ask":"0.86"}],"timestamp":"1768250244270","event_type":"price_change"}}
{"schema_version":1,"source":"clob_ws_market","recv_ts_ns":1768250244459598337,"event_type":"price_change","market":"0x2a12fd3d8235c25c062dc9652970ef9f635636c4018df0909e1a51c673e125cb","server_ts_ms":1768250244296,"raw":{"market":"0x2a12fd3d8235c25c062dc9652970ef9f635636c4018df0909e1a51c673e125cb","price_changes":[{"asset_id":"56386988715176239099720172290594769295756680374928571099138069977179519358166","price":"0.14","size":"305.81","side":"BUY","hash":"72c24872667e9a5677a54a0a870d40be832a36d1","best_bid":"0.14","best_ask":"0.15"},{"asset_id":"63670753354844494163057275310194312729998307779831462269530137743341854359908","price":"0.86","size":"305.81","side":"SELL","hash":"9e64517934ac0e2ef33c1c1adc0fc35955a96780","best_bid":"0.85","best_ask":"0.86"}],"timestamp":"1768250244296","event_type":"price_change"}}
{"schema_version":1,"source":"clob_ws_market","recv_ts_ns":1768250244462489393,"event_type":"price_change","market":"0x2a12fd3d8235c25c062dc9652970ef9f635636c4018df0909e1a51c673e125cb","server_ts_ms":1768250244299,"raw":{"market":"0x2a12fd3d8235c25c062dc9652970ef9f635636c4018df0909e1a51c673e125cb","price_changes":[{"asset_id":"56386988715176239099720172290594769295756680374928571099138069977179519358166","price":"0.14","size":"295.81","side":"BUY","hash":"9a1185a7e4a44b5e3031924fa8aea1b627ba8fb6","best_bid":"0.14","best_ask":"0.15"},{"asset_id":"63670753354844494163057275310194312729998307779831462269530137743341854359908","price":"0.86","size":"295.81","side":"SELL","hash":"d2ac4a052ac0dddc0bd31412d5c784ce7b0c032e","best_bid":"0.85","best_ask":"0.86"}],"timestamp":"1768250244299","event_type":"price_change"}}
{"schema_version":1,"source":"clob_ws_market","recv_ts_ns":1768250244466549614,"event_type":"price_change","market":"0x2a12fd3d8235c25c062dc9652970ef9f635636c4018df0909e1a51c673e125cb","server_ts_ms":1768250244299,"raw":{"market":"0x2a12fd3d8235c25c062dc9652970ef9f635636c4018df0909e1a51c673e125cb","price_changes":[{"asset_id":"63670753354844494163057275310194312729998307779831462269530137743341854359908","price":"0.83","size":"260.52","side":"BUY","hash":"0fd48aa43bdc4424d85dea0db9eb1e26ceedefb1","best_bid":"0.85","best_ask":"0.86"},{"asset_id":"56386988715176239099720172290594769295756680374928571099138069977179519358166","price":"0.17","size":"260.52","side":"SELL","hash":"82f2d97629df04dc089ed9b5186f0f503e2460c8","best_bid":"0.14","best_ask":"0.15"}],"timestamp":"1768250244299","event_type":"price_change"}}
{"schema_version":1,"source":"clob_ws_market","recv_ts_ns":1768250244470760088,"event_type":"price_change","market":"0x2a12fd3d8235c25c062dc9652970ef9f635636c4018df0909e1a51c673e125cb","server_ts_ms":1768250244300,"raw":{"market":"0x2a12fd3d8235c25c062dc9652970ef9f635636c4018df0909e1a51c673e125cb","price_changes":[{"asset_id":"63670753354844494163057275310194312729998307779831462269530137743341854359908","price":"0.82","size":"871","side":"BUY","hash":"69e6314c1eb20a1246e927559d464f34648bc240","best_bid":"0.85","best_ask":"0.86"},{"asset_id":"56386988715176239099720172290594769295756680374928571099138069977179519358166","price":"0.18","size":"871","side":"SELL","hash":"5547644eeb6282f9bbbbd15400b15911063af55b","best_bid":"0.14","best_ask":"0.15"}],"timestamp":"1768250244300","event_type":"price_change"}}
{"schema_version":1,"source":"clob_ws_market","recv_ts_ns":1768250244474603820,"event_type":"price_change","market":"0x2a12fd3d8235c25c062dc9652970ef9f635636c4018df0909e1a51c673e125cb","server_ts_ms":1768250244302,"raw":{"market":"0x2a12fd3d8235c25c062dc9652970ef9f635636c4018df0909e1a51c673e125cb","price_changes":[{"asset_id":"56386988715176239099720172290594769295756680374928571099138069977179519358166","price":"0.13","size":"351","side":"BUY","hash":"335601b6ea933eb4658b85aba3ccffe174eaaf66","best_bid":"0.14","best_ask":"0.15"},{"asset_id":"63670753354844494163057275310194312729998307779831462269530137743341854359908","price":"0.87","size":"351","side":"SELL","hash":"4088dff4ed169eb35926a52ebace33617753db34","best_bid":"0.85","best_ask":"0.86"}],"timestamp":"1768250244302","event_type":"price_change"}}
{"schema_version":1,"source":"clob_ws_market","recv_ts_ns":1768250244478720987,"event_type":"price_change","market":"0x2a12fd3d8235c25c062dc9652970ef9f635636c4018df0909e1a51c673e125cb","server_ts_ms":1768250244301,"raw":{"market":"0x2a12fd3d8235c25c062dc9652970ef9f635636c4018df0909e1a51c673e125cb","price_changes":[{"asset_id":"63670753354844494163057275310194312729998307779831462269530137743341854359908","price":"0.83","size":"250.52","side":"BUY","hash":"07633bb5f0b99e61fdfbfe408c564f08e8a2e691","best_bid":"0.85","best_ask":"0.86"},{"asset_id":"56386988715176239099720172290594769295756680374928571099138069977179519358166","price":"0.17","size":"250.52","side":"SELL","hash":"bde8e7b78a111d5a8b34a0fb1bb6257432b1aaa0","best_bid":"0.14","best_ask":"0.15"}],"timestamp":"1768250244301","event_type":"price_change"}}
{"schema_version":1,"source":"clob_ws_market","recv_ts_ns":1768250244495699261,"event_type":"price_change","market":"0x2a12fd3d8235c25c062dc9652970ef9f635636c4018df0909e1a51c673e125cb","server_ts_ms":1768250244305,"raw":{"market":"0x2a12fd3d8235c25c062dc9652970ef9f635636c4018df0909e1a51c673e125cb","price_changes":[{"asset_id":"63670753354844494163057275310194312729998307779831462269530137743341854359908","price":"0.83","size":"240.52","side":"BUY","hash":"a271b743a3d533c98709d28cb15edbed1210f283","best_bid":"0.85","best_ask":"0.86"},{"asset_id":"56386988715176239099720172290594769295756680374928571099138069977179519358166","price":"0.17","size":"240.52","side":"SELL","hash":"3a397ae9709bd32fe7e42e3adedae2ba9ada22c1","best_bid":"0.14","best_ask":"0.15"}],"timestamp":"1768250244305","event_type":"price_change"}}
{"schema_version":1,"source":"clob_ws_market","recv_ts_ns":1768250244499597724,"event_type":"price_change","market":"0x2a12fd3d8235c25c062dc9652970ef9f635636c4018df0909e1a51c673e125cb","server_ts_ms":1768250244304,"raw":{"market":"0x2a12fd3d8235c25c062dc9652970ef9f635636c4018df0909e1a51c673e125cb","price_changes":[{"asset_id":"56386988715176239099720172290594769295756680374928571099138069977179519358166","price":"0.11","size":"859.5","side":"BUY","hash":"42da019cea15aba9a5d7c5dfaf073d7c95d3cafe","best_bid":"0.14","best_ask":"0.15"},{"asset_id":"63670753354844494163057275310194312729998307779831462269530137743341854359908","price":"0.89","size":"859.5","side":"SELL","hash":"75abee37f6b324bc3807cb474f187f2e8de97d4a","best_bid":"0.85","best_ask":"0.86"}],"timestamp":"1768250244304","event_type":"price_change"}}
{"schema_version":1,"source":"clob_ws_market","recv_ts_ns":1768250244502599373,"event_type":"price_change","market":"0x2a12fd3d8235c25c062dc9652970ef9f635636c4018df0909e1a51c673e125cb","server_ts_ms":1768250244305,"raw":{"market":"0x2a12fd3d8235c25c062dc9652970ef9f635636c4018df0909e1a51c673e125cb","price_changes":[{"asset_id":"56386988715176239099720172290594769295756680374928571099138069977179519358166","price":"0.12","size":"887.75","side":"BUY","hash":"b74fe547cfa70c3fe15be5b86ea3952210e94d4d","best_bid":"0.14","best_ask":"0.15"},{"asset_id":"63670753354844494163057275310194312729998307779831462269530137743341854359908","price":"0.88","size":"887.75","side":"SELL","hash":"4c4d864dc8b03ebb6e83007ef7a3deaceb758a1a","best_bid":"0.85","best_ask":"0.86"}],"timestamp":"1768250244305","event_type":"price_change"}}
{"schema_version":1,"source":"clob_ws_market","recv_ts_ns":1768250244505439283,"event_type":"price_change","market":"0x2a12fd3d8235c25c062dc9652970ef9f635636c4018df0909e1a51c673e125cb","server_ts_ms":1768250244306,"raw":{"market":"0x2a12fd3d8235c25c062dc9652970ef9f635636c4018df0909e1a51c673e125cb","price_changes":[{"asset_id":"63670753354844494163057275310194312729998307779831462269530137743341854359908","price":"0.83","size":"230.52","side":"BUY","hash":"1d7212d50713dc2197326c91ce076e17b8b7405b","best_bid":"0.85","best_ask":"0.86"},{"asset_id":"56386988715176239099720172290594769295756680374928571099138069977179519358166","price":"0.17","size":"230.52","side":"SELL","hash":"599d7b254044692c51d2938401a07fd81fc58cd3","best_bid":"0.14","best_ask":"0.15"}],"timestamp":"1768250244306","event_type":"price_change"}}
{"schema_version":1,"source":"clob_ws_market","recv_ts_ns":1768250244508339001,"event_type":"price_change","market":"0x2a12fd3d8235c25c062dc9652970ef9f635636c4018df0909e1a51c673e125cb","server_ts_ms":1768250244307,"raw":{"market":"0x2a12fd3d8235c25c062dc9652970ef9f635636c4018df0909e1a51c673e125cb","price_changes":[{"asset_id":"56386988715176239099720172290594769295756680374928571099138069977179519358166","price":"0.14","size":"305.81","side":"BUY","hash":"87c0ba5fcf52e36e0008a8600988b4875dd219d4","best_bid":"0.14","best_ask":"0.15"},{"asset_id":"63670753354844494163057275310194312729998307779831462269530137743341854359908","price":"0.86","size":"305.81","side":"SELL","hash":"ac7fb092ea8faa55a53e71ba3bc3a4928ab34da7","best_bid":"0.85","best_ask":"0.86"}],"timestamp":"1768250244307","event_type":"price_change"}}
{"schema_version":1,"source":"clob_ws_market","recv_ts_ns":1768250244515381849,"event_type":"price_change","market":"0x2a12fd3d8235c25c062dc9652970ef9f635636c4018df0909e1a51c673e125cb","server_ts_ms":1768250244307,"raw":{"market":"0x2a12fd3d8235c25c062dc9652970ef9f635636c4018df0909e1a51c673e125cb","price_changes":[{"asset_id":"63670753354844494163057275310194312729998307779831462269530137743341854359908","price":"0.83","size":"220.52","side":"BUY","hash":"8ee39875800f968a020308798005323533ace151","best_bid":"0.85","best_ask":"0.86"},{"asset_id":"56386988715176239099720172290594769295756680374928571099138069977179519358166","price":"0.17","size":"220.52","side":"SELL","hash":"17232d1b931ebc1ed27a6bb429a31a3d92ed5e3f","best_bid":"0.14","best_ask":"0.15"}],"timestamp":"1768250244307","event_type":"price_change"}}
{"schema_version":1,"source":"clob_ws_market","recv_ts_ns":1768250244520835274,"event_type":"price_change","market":"0x2a12fd3d8235c25c062dc9652970ef9f635636c4018df0909e1a51c673e125cb","server_ts_ms":1768250244308,"raw":{"market":"0x2a12fd3d8235c25c062dc9652970ef9f635636c4018df0909e1a51c673e125cb","price_changes":[{"asset_id":"56386988715176239099720172290594769295756680374928571099138069977179519358166","price":"0.12","size":"877.75","side":"BUY","hash":"5cd994530ddba71f3c6b34ab8022ffd98bbffbeb","best_bid":"0.14","best_ask":"0.15"},{"asset_id":"63670753354844494163057275310194312729998307779831462269530137743341854359908","price":"0.88","size":"877.75","side":"SELL","hash":"8d38cff5e3bcc70aa339c4343703395ca3fbac9c","best_bid":"0.85","best_ask":"0.86"}],"timestamp":"1768250244308","event_type":"price_change"}}
{"schema_version":1,"source":"clob_ws_market","recv_ts_ns":1768250244527727619,"event_type":"price_change","market":"0x2a12fd3d8235c25c062dc9652970ef9f635636c4018df0909e1a51c673e125cb","server_ts_ms":1768250244308,"raw":{"market":"0x2a12fd3d8235c25c062dc9652970ef9f635636c4018df0909e1a51c673e125cb","price_changes":[{"asset_id":"63670753354844494163057275310194312729998307779831462269530137743341854359908","price":"0.83","size":"210.52","side":"BUY","hash":"e3142a27aa9f892685aae61e1d1739325cfc1ef8","best_bid":"0.85","best_ask":"0.86"},{"asset_id":"56386988715176239099720172290594769295756680374928571099138069977179519358166","price":"0.17","size":"210.52","side":"SELL","hash":"ba7faa114d2d1209e129a648f5efaa51d6239a1d","best_bid":"0.14","best_ask":"0.15"}],"timestamp":"1768250244308","event_type":"price_change"}}
{"schema_version":1,"source":"clob_ws_market","recv_ts_ns":1768250244532600093,"event_type":"price_change","market":"0x2a12fd3d8235c25c062dc9652970ef9f635636c4018df0909e1a51c673e125cb","server_ts_ms":1768250244309,"raw":{"market":"0x2a12fd3d8235c25c062dc9652970ef9f635636c4018df0909e1a51c673e125cb","price_changes":[{"asset_id":"63670753354844494163057275310194312729998307779831462269530137743341854359908","price":"0.83","size":"200.52","side":"BUY","hash":"60b78a2e706706a0752cc50949962dac327e34a9","best_bid":"0.85","best_ask":"0.86"},{"asset_id":"56386988715176239099720172290594769295756680374928571099138069977179519358166","price":"0.17","size":"200.52","side":"SELL","hash":"db260ab895128fbc6bd683cc6118dc85017d973e","best_bid":"0.14","best_ask":"0.15"}],"timestamp":"1768250244309","event_type":"price_change"}}
{"schema_version":1,"source":"clob_ws_market","recv_ts_ns":1768250244537011231,"event_type":"price_change","market":"0x2a12fd3d8235c25c062dc9652970ef9f635636c4018df0909e1a51c673e125cb","server_ts_ms":1768250244310,"raw":{"market":"0x2a12fd3d8235c25c062dc9652970ef9f635636c4018df0909e1a51c673e125cb","price_changes":[{"asset_id":"56386988715176239099720172290594769295756680374928571099138069977179519358166","price":"0.12","size":"867.75","side":"BUY","hash":"282837a92ac639fcfdcdd58d4a3e9839c49d0219","best_bid":"0.14","best_ask":"0.15"},{"asset_id":"63670753354844494163057275310194312729998307779831462269530137743341854359908","price":"0.88","size":"867.75","side":"SELL","hash":"c621c958f8b9d52d1fb0b4a000948b5edd09ccde","best_bid":"0.85","best_ask":"0.86"}],"timestamp":"1768250244310","event_type":"price_change"}}
{"schema_version":1,"source":"clob_ws_market","recv_ts_ns":1768250244563763526,"event_type":"price_change","market":"0x2a12fd3d8235c25c062dc9652970ef9f635636c4018df0909e1a51c673e125cb","server_ts_ms":1768250244310,"raw":{"market":"0x2a12fd3d8235c25c062dc9652970ef9f635636c4018df0909e1a51c673e125cb","price_changes":[{"asset_id":"63670753354844494163057275310194312729998307779831462269530137743341854359908","price":"0.83","size":"190.52","side":"BUY","hash":"6a04b1fa9ecf94544e652d26116fe7c235ebce08","best_bid":"0.85","best_ask":"0.86"},{"asset_id":"56386988715176239099720172290594769295756680374928571099138069977179519358166","price":"0.17","size":"190.52","side":"SELL","hash":"d65b55477fa4716f599d708a38c77cb7f398b644","best_bid":"0.14","best_ask":"0.15"}],"timestamp":"1768250244310","event_type":"price_change"}}
{"schema_version":1,"source":"clob_ws_market","recv_ts_ns":1768250244568442753,"event_type":"price_change","market":"0x2a12fd3d8235c25c062dc9652970ef9f635636c4018df0909e1a51c673e125cb","server_ts_ms":1768250244311,"raw":{"market":"0x2a12fd3d8235c25c062dc9652970ef9f635636c4018df0909e1a51c673e125cb","price_changes":[{"asset_id":"56386988715176239099720172290594769295756680374928571099138069977179519358166","price":"0.12","size":"857.75","side":"BUY","hash":"ffb57b69f03540a916bb53b790d9f4d0968ba0fc","best_bid":"0.14","best_ask":"0.15"},{"asset_id":"63670753354844494163057275310194312729998307779831462269530137743341854359908","price":"0.88","size":"857.75","side":"SELL","hash":"d216cc3064b0144f6dec83ec2ce22b2f5084478f","best_bid":"0.85","best_ask":"0.86"}],"timestamp":"1768250244311","event_type":"price_change"}}
{"schema_version":1,"source":"clob_ws_market","recv_ts_ns":1768250244576880729,"event_type":"price_change","market":"0x2a12fd3d8235c25c062dc9652970ef9f635636c4018df0909e1a51c673e125cb","server_ts_ms":1768250244315,"raw":{"market":"0x2a12fd3d8235c25c062dc9652970ef9f635636c4018df0909e1a51c673e125cb","price_changes":[{"asset_id":"63670753354844494163057275310194312729998307779831462269530137743341854359908","price":"0.83","size":"180.52","side":"BUY","hash":"3210dff7546bbce6a46c34047a5e9223d46f48a8","best_bid":"0.85","best_ask":"0.86"},{"asset_id":"56386988715176239099720172290594769295756680374928571099138069977179519358166","price":"0.17","size":"180.52","side":"SELL","hash":"4f81ea43dcb8dfce31d350b31dae07e208c85b20","best_bid":"0.14","best_ask":"0.15"}],"timestamp":"1768250244315","event_type":"price_change"}}
{"schema_version":1,"source":"clob_ws_market","recv_ts_ns":1768250244587588742,"event_type":"price_change","market":"0x2a12fd3d8235c25c062dc9652970ef9f635636c4018df0909e1a51c673e125cb","server_ts_ms":1768250244327,"raw":{"market":"0x2a12fd3d8235c25c062dc9652970ef9f635636c4018df0909e1a51c673e125cb","price_changes":[{"asset_id":"56386988715176239099720172290594769295756680374928571099138069977179519358166","price":"0.18","size":"881","side":"SELL","hash":"d05efcd9c044eb971a7f978e42b103d176d21c0c","best_bid":"0.14","best_ask":"0.15"},{"asset_id":"63670753354844494163057275310194312729998307779831462269530137743341854359908","price":"0.82","size":"881","side":"BUY","hash":"6354f744baf4f34261d49219b15e7f46e2464bc6","best_bid":"0.85","best_ask":"0.86"}],"timestamp":"1768250244327","event_type":"price_change"}}
{"schema_version":1,"source":"clob_ws_market","recv_ts_ns":1768250244591841529,"event_type":"price_change","market":"0x2a12fd3d8235c25c062dc9652970ef9f635636c4018df0909e1a51c673e125cb","server_ts_ms":1768250244334,"raw":{"market":"0x2a12fd3d8235c25c062dc9652970ef9f635636c4018df0909e1a51c673e125cb","price_changes":[{"asset_id":"56386988715176239099720172290594769295756680374928571099138069977179519358166","price":"0.14","size":"295.81","side":"BUY","hash":"7e75a5d96025cd47a52b0f603ea3d43b93a807a6","best_bid":"0.14","best_ask":"0.15"},{"asset_id":"63670753354844494163057275310194312729998307779831462269530137743341854359908","price":"0.86","size":"295.81","side":"SELL","hash":"1163dd650c5f58b56040e5604695d2430f7b9103","best_bid":"0.85","best_ask":"0.86"}],"timestamp":"1768250244334","event_type":"price_change"}}
{"schema_version":1,"source":"clob_ws_market","recv_ts_ns":1768250244596453395,"event_type":"price_change","market":"0x2a12fd3d8235c25c062dc9652970ef9f635636c4018df0909e1a51c673e125cb","server_ts_ms":1768250244336,"raw":{"market":"0x2a12fd3d8235c25c062dc9652970ef9f635636c4018df0909e1a51c673e125cb","price_changes":[{"asset_id":"56386988715176239099720172290594769295756680374928571099138069977179519358166","price":"0.13","size":"321","side":"BUY","hash":"43a39867ec46aaa83c1c966744072e7815c7fd56","best_bid":"0.14","best_ask":"0.15"},{"asset_id":"63670753354844494163057275310194312729998307779831462269530137743341854359908","price":"0.87","size":"321","side":"SELL","hash":"f862a3b7341b842643ba8b64323f384f4a7a4a9c","best_bid":"0.85","best_ask":"0.86"}],"timestamp":"1768250244336","event_type":"price_change"}}
{"schema_version":1,"source":"clob_ws_market","recv_ts_ns":1768250244627888327,"event_type":"price_change","market":"0x2a12fd3d8235c25c062dc9652970ef9f635636c4018df0909e1a51c673e125cb","server_ts_ms":1768250244350,"raw":{"market":"0x2a12fd3d8235c25c062dc9652970ef9f635636c4018df0909e1a51c673e125cb","price_changes":[{"asset_id":"63670753354844494163057275310194312729998307779831462269530137743341854359908","price":"0.83","size":"190.52","side":"BUY","hash":"2d419c780bdbf8bf5ddfe40426bd91d1a1cdcfbb","best_bid":"0.85","best_ask":"0.86"},{"asset_id":"56386988715176239099720172290594769295756680374928571099138069977179519358166","price":"0.17","size":"190.52","side":"SELL","hash":"965d385018b34c513d34efaf1f1e59eef2397561","best_bid":"0.14","best_ask":"0.15"}],"timestamp":"1768250244350","event_type":"price_change"}}
{"schema_version":1,"source":"clob_ws_market","recv_ts_ns":1768250244633440882,"event_type":"price_change","market":"0x2a12fd3d8235c25c062dc9652970ef9f635636c4018df0909e1a51c673e125cb","server_ts_ms":1768250244354,"raw":{"market":"0x2a12fd3d8235c25c062dc9652970ef9f635636c4018df0909e1a51c673e125cb","price_changes":[{"asset_id":"56386988715176239099720172290594769295756680374928571099138069977179519358166","price":"0.12","size":"867.75","side":"BUY","hash":"5be4f543cb29aa725ce86b287ee2bcf595db518a","best_bid":"0.14","best_ask":"0.15"},{"asset_id":"63670753354844494163057275310194312729998307779831462269530137743341854359908","price":"0.88","size":"867.75","side":"SELL","hash":"76e23803cebf1d567fefde6050530a54e2993b26","best_bid":"0.85","best_ask":"0.86"}],"timestamp":"1768250244354","event_type":"price_change"}}
{"schema_version":1,"source":"clob_ws_market","recv_ts_ns":1768250244637116609,"event_type":"price_change","market":"0x2a12fd3d8235c25c062dc9652970ef9f635636c4018df0909e1a51c673e125cb","server_ts_ms":1768250244355,"raw":{"market":"0x2a12fd3d8235c25c062dc9652970ef9f635636c4018df0909e1a51c673e125cb","price_changes":[{"asset_id":"63670753354844494163057275310194312729998307779831462269530137743341854359908","price":"0.83","size":"200.52","side":"BUY","hash":"9776d9e77fc95e14ee0cc319a95a7b4f09e77548","best_bid":"0.85","best_ask":"0.86"},{"asset_id":"56386988715176239099720172290594769295756680374928571099138069977179519358166","price":"0.17","size":"200.52","side":"SELL","hash":"f1e5228ef992782027a9f77f25bef6eb6f463274","best_bid":"0.14","best_ask":"0.15"}],"timestamp":"1768250244355","event_type":"price_change"}}
{"schema_version":1,"source":"clob_ws_market","recv_ts_ns":1768250244640894881,"event_type":"price_change","market":"0x2a12fd3d8235c25c062dc9652970ef9f635636c4018df0909e1a51c673e125cb","server_ts_ms":1768250244356,"raw":{"market":"0x2a12fd3d8235c25c062dc9652970ef9f635636c4018df0909e1a51c673e125cb","price_changes":[{"asset_id":"56386988715176239099720172290594769295756680374928571099138069977179519358166","price":"0.12","size":"877.75","side":"BUY","hash":"62dcbfeff13e1c08c872c7d4c3c25243288b2148","best_bid":"0.14","best_ask":"0.15"},{"asset_id":"63670753354844494163057275310194312729998307779831462269530137743341854359908","price":"0.88","size":"877.75","side":"SELL","hash":"41d9290202faf8aef07b07cadd99548367a67086","best_bid":"0.85","best_ask":"0.86"}],"timestamp":"1768250244356","event_type":"price_change"}}
{"schema_version":1,"source":"clob_ws_market","recv_ts_ns":1768250244644842186,"event_type":"price_change","market":"0x2a12fd3d8235c25c062dc9652970ef9f635636c4018df0909e1a51c673e125cb","server_ts_ms":1768250244356,"raw":{"market":"0x2a12fd3d8235c25c062dc9652970ef9f635636c4018df0909e1a51c673e125cb","price_changes":[{"asset_id":"63670753354844494163057275310194312729998307779831462269530137743341854359908","price":"0.82","size":"891","side":"BUY","hash":"fb2d4145981f4cf84c49df32c09cbaf3c615b28e","best_bid":"0.85","best_ask":"0.86"},{"asset_id":"56386988715176239099720172290594769295756680374928571099138069977179519358166","price":"0.18","size":"891","side":"SELL","hash":"084225c23c1336b846fc8f072c5c576bb0fd9af7","best_bid":"0.14","best_ask":"0.15"}],"timestamp":"1768250244356","event_type":"price_change"}}
{"schema_version":1,"source":"clob_ws_market","recv_ts_ns":1768250244648706653,"event_type":"price_change","market":"0x2a12fd3d8235c25c062dc9652970ef9f635636c4018df0909e1a51c673e125cb","server_ts_ms":1768250244357,"raw":{"market":"0x2a12fd3d8235c25c062dc9652970ef9f635636c4018df0909e1a51c673e125cb","price_changes":[{"asset_id":"63670753354844494163057275310194312729998307779831462269530137743341854359908","price":"0.82","size":"901","side":"BUY","hash":"0d7ec90e84f4334e9bec47d725af9b41cbe0a8ac","best_bid":"0.85","best_ask":"0.86"},{"asset_id":"56386988715176239099720172290594769295756680374928571099138069977179519358166","price":"0.18","size":"901","side":"SELL","hash":"45d3accc6811b8a9afb9f8528dfa944f284a1923","best_bid":"0.14","best_ask":"0.15"}],"timestamp":"1768250244357","event_type":"price_change"}}
{"schema_version":1,"source":"clob_ws_market","recv_ts_ns":1768250244652162389,"event_type":"price_change","market":"0x2a12fd3d8235c25c062dc9652970ef9f635636c4018df0909e1a51c673e125cb","server_ts_ms":1768250244358,"raw":{"market":"0x2a12fd3d8235c25c062dc9652970ef9f635636c4018df0909e1a51c673e125cb","price_changes":[{"asset_id":"63670753354844494163057275310194312729998307779831462269530137743341854359908","price":"0.83","size":"210.52","side":"BUY","hash":"16cdd880f8a22db2a0807e68dc3c79f9f040a2df","best_bid":"0.85","best_ask":"0.86"},{"asset_id":"56386988715176239099720172290594769295756680374928571099138069977179519358166","price":"0.17","size":"210.52","side":"SELL","hash":"c62abfa8ccf11b6e3f8b578730303ca4bf9faf8d","best_bid":"0.14","best_ask":"0.15"}],"timestamp":"1768250244358","event_type":"price_change"}}
{"schema_version":1,"source":"clob_ws_market","recv_ts_ns":1768250244655901971,"event_type":"price_change","market":"0x2a12fd3d8235c25c062dc9652970ef9f635636c4018df0909e1a51c673e125cb","server_ts_ms":1768250244359,"raw":{"market":"0x2a12fd3d8235c25c062dc9652970ef9f635636c4018df0909e1a51c673e125cb","price_changes":[{"asset_id":"56386988715176239099720172290594769295756680374928571099138069977179519358166","price":"0.14","size":"305.81","side":"BUY","hash":"8bf036b155d0262f3c8647eabeeb18b799710c20","best_bid":"0.14","best_ask":"0.15"},{"asset_id":"63670753354844494163057275310194312729998307779831462269530137743341854359908","price":"0.86","size":"305.81","side":"SELL","hash":"323e5dce00653149b6113e717acd2a2e9d8080f4","best_bid":"0.85","best_ask":"0.86"}],"timestamp":"1768250244359","event_type":"price_change"}}
{"schema_version":1,"source":"clob_ws_market","recv_ts_ns":1768250244659350863,"event_type":"price_change","market":"0x2a12fd3d8235c25c062dc9652970ef9f635636c4018df0909e1a51c673e125cb","server_ts_ms":1768250244360,"raw":{"market":"0x2a12fd3d8235c25c062dc9652970ef9f635636c4018df0909e1a51c673e125cb","price_changes":[{"asset_id":"56386988715176239099720172290594769295756680374928571099138069977179519358166","price":"0.13","size":"331","side":"BUY","hash":"672b11888db719f4b172e63a880bf993545124cc","best_bid":"0.14","best_ask":"0.15"},{"asset_id":"63670753354844494163057275310194312729998307779831462269530137743341854359908","price":"0.87","size":"331","side":"SELL","hash":"feb96883c5be0cf4454d75d4a754c118fddfd8e7","best_bid":"0.85","best_ask":"0.86"}],"timestamp":"1768250244360","event_type":"price_change"}}
{"schema_version":1,"source":"clob_ws_market","recv_ts_ns":1768250244663459860,"event_type":"price_change","market":"0x2a12fd3d8235c25c062dc9652970ef9f635636c4018df0909e1a51c673e125cb","server_ts_ms":1768250244360,"raw":{"market":"0x2a12fd3d8235c25c062dc9652970ef9f635636c4018df0909e1a51c673e125cb","price_changes":[{"asset_id":"56386988715176239099720172290594769295756680374928571099138069977179519358166","price":"0.12","size":"887.75","side":"BUY","hash":"9324e2ccacae54529ead75a558ac2001c416a5dc","best_bid":"0.14","best_ask":"0.15"},{"asset_id":"63670753354844494163057275310194312729998307779831462269530137743341854359908","price":"0.88","size":"887.75","side":"SELL","hash":"42b2c53a0efd932bbc8ca9510bb4898c2142de09","best_bid":"0.85","best_ask":"0.86"}],"timestamp":"1768250244360","event_type":"price_change"}}
{"schema_version":1,"source":"clob_ws_market","recv_ts_ns":1768250244666939265,"event_type":"price_change","market":"0x2a12fd3d8235c25c062dc9652970ef9f635636c4018df0909e1a51c673e125cb","server_ts_ms":1768250244361,"raw":{"market":"0x2a12fd3d8235c25c062dc9652970ef9f635636c4018df0909e1a51c673e125cb","price_changes":[{"asset_id":"63670753354844494163057275310194312729998307779831462269530137743341854359908","price":"0.83","size":"220.52","side":"BUY","hash":"138ff5bb1c9439e2d6d521708d5a9cd3a957a12a","best_bid":"0.85","best_ask":"0.86"},{"asset_id":"56386988715176239099720172290594769295756680374928571099138069977179519358166","price":"0.17","size":"220.52","side":"SELL","hash":"1951513e37a5acf0e80fa0cbfbbfdc53dae13225","best_bid":"0.14","best_ask":"0.15"}],"timestamp":"1768250244361","event_type":"price_change"}}
{"schema_version":1,"source":"clob_ws_market","recv_ts_ns":1768250244669704929,"event_type":"price_change","market":"0x2a12fd3d8235c25c062dc9652970ef9f635636c4018df0909e1a51c673e125cb","server_ts_ms":1768250244362,"raw":{"market":"0x2a12fd3d8235c25c062dc9652970ef9f635636c4018df0909e1a51c673e125cb","price_changes":[{"asset_id":"56386988715176239099720172290594769295756680374928571099138069977179519358166","price":"0.12","size":"897.75","side":"BUY","hash":"b22d58a79dff88d6a764f5cb54119cd477874d24","best_bid":"0.14","best_ask":"0.15"},{"asset_id":"63670753354844494163057275310194312729998307779831462269530137743341854359908","price":"0.88","size":"897.75","side":"SELL","hash":"eadfc8d7e4772e0f7b4bf7eb71546f5d802302df","best_bid":"0.85","best_ask":"0.86"}],"timestamp":"1768250244362","event_type":"price_change"}}
{"schema_version":1,"source":"clob_ws_market","recv_ts_ns":1768250244673572433,"event_type":"price_change","market":"0x2a12fd3d8235c25c062dc9652970ef9f635636c4018df0909e1a51c673e125cb","server_ts_ms":1768250244362,"raw":{"market":"0x2a12fd3d8235c25c062dc9652970ef9f635636c4018df0909e1a51c673e125cb","price_changes":[{"asset_id":"56386988715176239099720172290594769295756680374928571099138069977179519358166","price":"0.11","size":"869.5","side":"BUY","hash":"8d6c82e69b8e66a1f51df0386dc5b08927e24e20","best_bid":"0.14","best_ask":"0.15"},{"asset_id":"63670753354844494163057275310194312729998307779831462269530137743341854359908","price":"0.89","size":"869.5","side":"SELL","hash":"8a7181893936bc30c755c66ede3bd2e56022674d","best_bid":"0.85","best_ask":"0.86"}],"timestamp":"1768250244362","event_type":"price_change"}}
{"schema_version":1,"source":"clob_ws_market","recv_ts_ns":1768250244677647409,"event_type":"price_change","market":"0x2a12fd3d8235c25c062dc9652970ef9f635636c4018df0909e1a51c673e125cb","server_ts_ms":1768250244363,"raw":{"market":"0x2a12fd3d8235c25c062dc9652970ef9f635636c4018df0909e1a51c673e125cb","price_changes":[{"asset_id":"63670753354844494163057275310194312729998307779831462269530137743341854359908","price":"0.83","size":"230.52","side":"BUY","hash":"e7359819a103ef750da22f0a432ef12a46f52b41","best_bid":"0.85","best_ask":"0.86"},{"asset_id":"56386988715176239099720172290594769295756680374928571099138069977179519358166","price":"0.17","size":"230.52","side":"SELL","hash":"0739056f5f4e00d464e3902fa81ae88b449b242a","best_bid":"0.14","best_ask":"0.15"}],"timestamp":"1768250244363","event_type":"price_change"}}
{"schema_version":1,"source":"clob_ws_market","recv_ts_ns":1768250244688462908,"event_type":"best_bid_ask","market":"0x2a12fd3d8235c25c062dc9652970ef9f635636c4018df0909e1a51c673e125cb","server_ts_ms":1768250244379,"raw":{"market":"0x2a12fd3d8235c25c062dc9652970ef9f635636c4018df0909e1a51c673e125cb","asset_id":"63670753354844494163057275310194312729998307779831462269530137743341854359908","best_bid":"0.85","best_ask":"0.86","spread":"0.01","timestamp":"1768250244379","event_type":"best_bid_ask"}}
{"schema_version":1,"source":"clob_ws_market","recv_ts_ns":1768250244691250155,"event_type":"price_change","market":"0x2a12fd3d8235c25c062dc9652970ef9f635636c4018df0909e1a51c673e125cb","server_ts_ms":1768250244378,"raw":{"market":"0x2a12fd3d8235c25c062dc9652970ef9f635636c4018df0909e1a51c673e125cb","price_changes":[{"asset_id":"56386988715176239099720172290594769295756680374928571099138069977179519358166","price":"0.14","size":"304.55","side":"BUY","hash":"3698ac27486c71cefd8a1debb6bd14d16473ee4c","best_bid":"0.14","best_ask":"0.15"},{"asset_id":"63670753354844494163057275310194312729998307779831462269530137743341854359908","price":"0.86","size":"304.55","side":"SELL","hash":"5fa9d8b52d36f7946c901353c3d5a489e634328b","best_bid":"0.85","best_ask":"0.86"}],"timestamp":"1768250244378","event_type":"price_change"}}
{"schema_version":1,"source":"clob_ws_market","recv_ts_ns":1768250244700005013,"event_type":"book","market":"0x2a12fd3d8235c25c062dc9652970ef9f635636c4018df0909e1a51c673e125cb","server_ts_ms":1768250244378,"raw":{"market":"0x2a12fd3d8235c25c062dc9652970ef9f635636c4018df0909e1a51c673e125cb","asset_id":"63670753354844494163057275310194312729998307779831462269530137743341854359908","bids":[{"price":"0.01","size":"10184.18"},{"price":"0.02","size":"5982"},{"price":"0.03","size":"5238.94"},{"price":"0.04","size":"5040"},{"price":"0.05","size":"5050"},{"price":"0.06","size":"5005"},{"price":"0.07","size":"5019.28"},{"price":"0.08","size":"5005"},{"price":"0.09","size":"5005"},{"price":"0.1","size":"5030"},{"price":"0.11","size":"5"},{"price":"0.12","size":"5"},{"price":"0.13","size":"5"},{"price":"0.14","size":"5"},{"price":"0.15","size":"10"},{"price":"0.16","size":"5"},{"price":"0.17","size":"5"},{"price":"0.18","size":"5"},{"price":"0.19","size":"5"},{"price":"0.2","size":"5"},{"price":"0.21","size":"5"},{"price":"0.22","size":"5"},{"price":"0.23","size":"5"},{"price":"0.24","size":"5"},{"price":"0.25","size":"10"},{"price":"0.26","size":"5"},{"price":"0.27","size":"5"},{"price":"0.28","size":"5"},{"price":"0.29","size":"15"},{"price":"0.3","size":"10"},{"price":"0.31","size":"5"},{"price":"0.32","size":"5"},{"price":"0.33","size":"5"},{"price":"0.34","size":"505"},{"price":"0.35","size":"510"},{"price":"0.36","size":"510"},{"price":"0.37","size":"505"},{"price":"0.38","size":"505"},{"price":"0.39","size":"755"},{"price":"0.4","size":"760"},{"price":"0.41","size":"916"},{"price":"0.42","size":"671"},{"price":"0.43","size":"827"},{"price":"0.44","size":"827"},{"price":"0.45","size":"817"},{"price":"0.46","size":"872"},{"price":"0.47","size":"839.65"},{"price":"0.48","size":"829"},{"price":"0.49","size":"817"},{"price":"0.5","size":"838.4"},{"price":"0.51","size":"867.58"},{"price":"0.52","size":"817"},{"price":"0.53","size":"827"},{"price":"0.54","size":"847.8"},{"price":"0.55","size":"836.09"},{"price":"0.56","size":"825"},{"price":"0.57","size":"847"},{"price":"0.58","size":"817"},{"price":"0.59","size":"817"},{"price":"0.6","size":"817"},{"price":"0.61","size":"834.5"},{"price":"0.62","size":"817"},{"price":"0.63","size":"497.49"},{"price":"0.64","size":"817"},{"price":"0.65","size":"872"},{"price":"0.66","size":"997.71"},{"price":"0.67","size":"906.8"},{"price":"0.68","size":"902"},{"price":"0.69","size":"922"},{"price":"0.7","size":"911.6"},{"price":"0.71","size":"897"},{"price":"0.72","size":"899.55"},{"price":"0.73","size":"912"},{"price":"0.74","size":"1174.42"},{"price":"0.75","size":"722.5"},{"price":"0.76","size":"924.25"},{"price":"0.77","size":"754.5"},{"price":"0.78","size":"910.8"},{"price":"0.79","size":"808.5"},{"price":"0.8","size":"814.9"},{"price":"0.81","size":"313.21"},{"price":"0.82","size":"901"},{"price":"0.83","size":"230.52"},{"price":"0.84","size":"196.5"},{"price":"0.85","size":"213.95"}],"asks":[{"price":"0.99","size":"10331.71"},{"price":"0.98","size":"6299.77"},{"price":"0.97","size":"5625.94"},{"price":"0.96","size":"5427"},{"price":"0.95","size":"3442"},{"price":"0.94","size":"1397"},{"price":"0.93","size":"1421.28"},{"price":"0.92","size":"1496.75"},{"price":"0.91","size":"1373"},{"price":"0.9","size":"3462"},{"price":"0.89","size":"869.5"},{"price":"0.88","size":"897.75"},{"price":"0.87","size":"331"},{"price":"0.86","size":"304.55"}],"hash":"5fa9d8b52d36f7946c901353c3d5a489e634328b","timestamp":"1768250244378","event_type":"book"}}
{"schema_version":1,"source":"clob_ws_market","recv_ts_ns":1768250244702960052,"event_type":"price_change","market":"0x2a12fd3d8235c25c062dc9652970ef9f635636c4018df0909e1a51c673e125cb","server_ts_ms":1768250244379,"raw":{"market":"0x2a12fd3d8235c25c062dc9652970ef9f635636c4018df0909e1a51c673e125cb","price_changes":[{"asset_id":"63670753354844494163057275310194312729998307779831462269530137743341854359908","price":"0.83","size":"240.52","side":"BUY","hash":"87bd5f3c4d474098a23fbf9bfe541353ce60ac84","best_bid":"0.85","best_ask":"0.86"},{"asset_id":"56386988715176239099720172290594769295756680374928571099138069977179519358166","price":"0.17","size":"240.52","side":"SELL","hash":"087dfc676f557ad4e035d8a21882b47c759af49c","best_bid":"0.14","best_ask":"0.15"}],"timestamp":"1768250244379","event_type":"price_change"}}
{"schema_version":1,"source":"clob_ws_market","recv_ts_ns":1768250244706720620,"event_type":"price_change","market":"0x2a12fd3d8235c25c062dc9652970ef9f635636c4018df0909e1a51c673e125cb","server_ts_ms":1768250244380,"raw":{"market":"0x2a12fd3d8235c25c062dc9652970ef9f635636c4018df0909e1a51c673e125cb","price_changes":[{"asset_id":"63670753354844494163057275310194312729998307779831462269530137743341854359908","price":"0.83","size":"250.52","side":"BUY","hash":"37589d83b2afc3777d1aef287334cb1c683dc58d","best_bid":"0.85","best_ask":"0.86"},{"asset_id":"56386988715176239099720172290594769295756680374928571099138069977179519358166","price":"0.17","size":"250.52","side":"SELL","hash":"a836b77bffccd8bbcddaf98d5beb7e85c46c6419","best_bid":"0.14","best_ask":"0.15"}],"timestamp":"1768250244380","event_type":"price_change"}}
{"schema_version":1,"source":"clob_ws_market","recv_ts_ns":1768250244710369459,"event_type":"price_change","market":"0x2a12fd3d8235c25c062dc9652970ef9f635636c4018df0909e1a51c673e125cb","server_ts_ms":1768250244381,"raw":{"market":"0x2a12fd3d8235c25c062dc9652970ef9f635636c4018df0909e1a51c673e125cb","price_changes":[{"asset_id":"56386988715176239099720172290594769295756680374928571099138069977179519358166","price":"0.14","size":"804.55","side":"BUY","hash":"78186913363d1dc2f62b41a8ff9d69ce49c508cd","best_bid":"0.14","best_ask":"0.15"},{"asset_id":"63670753354844494163057275310194312729998307779831462269530137743341854359908","price":"0.86","size":"804.55","side":"SELL","hash":"e81c13849d7997b1c1b9e273c2cc0e40d420b20f","best_bid":"0.85","best_ask":"0.86"}],"timestamp":"1768250244381","event_type":"price_change"}}
{"schema_version":1,"source":"clob_ws_market","recv_ts_ns":1768250244714087706,"event_type":"price_change","market":"0x2a12fd3d8235c25c062dc9652970ef9f635636c4018df0909e1a51c673e125cb","server_ts_ms":1768250244382,"raw":{"market":"0x2a12fd3d8235c25c062dc9652970ef9f635636c4018df0909e1a51c673e125cb","price_changes":[{"asset_id":"56386988715176239099720172290594769295756680374928571099138069977179519358166","price":"0.13","size":"831","side":"BUY","hash":"0c19352fdc8f6ea00a1a00a49189c3b1c1720061","best_bid":"0.14","best_ask":"0.15"},{"asset_id":"63670753354844494163057275310194312729998307779831462269530137743341854359908","price":"0.87","size":"831","side":"SELL","hash":"921e80739c93b6cc113fb1d7d59c7658e4e4d545","best_bid":"0.85","best_ask":"0.86"}],"timestamp":"1768250244382","event_type":"price_change"}}
{"schema_version":1,"source":"clob_ws_market","recv_ts_ns":1768250244718098415,"event_type":"price_change","market":"0x2a12fd3d8235c25c062dc9652970ef9f635636c4018df0909e1a51c673e125cb","server_ts_ms":1768250244382,"raw":{"market":"0x2a12fd3d8235c25c062dc9652970ef9f635636c4018df0909e1a51c673e125cb","price_changes":[{"asset_id":"63670753354844494163057275310194312729998307779831462269530137743341854359908","price":"0.83","size":"260.52","side":"BUY","hash":"88628f5a8a5f0e783f35325494c3559b7473de3b","best_bid":"0.85","best_ask":"0.86"},{"asset_id":"56386988715176239099720172290594769295756680374928571099138069977179519358166","price":"0.17","size":"260.52","side":"SELL","hash":"aa4aa9b8833d587e40d7fab57d8e02ef25384fad","best_bid":"0.14","best_ask":"0.15"}],"timestamp":"1768250244382","event_type":"price_change"}}
{"schema_version":1,"source":"clob_ws_market","recv_ts_ns":1768250244721509475,"event_type":"last_trade_price","market":"0x2a12fd3d8235c25c062dc9652970ef9f635636c4018df0909e1a51c673e125cb","server_ts_ms":1768250244405,"raw":{"market":"0x2a12fd3d8235c25c062dc9652970ef9f635636c4018df0909e1a51c673e125cb","asset_id":"63670753354844494163057275310194312729998307779831462269530137743341854359908","price":"0.86","size":"1.255807","fee_rate_bps":"1000","side":"BUY","timestamp":"1768250244405","event_type":"last_trade_price","transaction_hash":"0x15ba13a4efa6db7377146e74e9c11868f82bf69100e9e6eb985183a908be6c65"}}
{"schema_version":1,"source":"clob_ws_market","recv_ts_ns":1768250244727259373,"event_type":"best_bid_ask","market":"0x2a12fd3d8235c25c062dc9652970ef9f635636c4018df0909e1a51c673e125cb","server_ts_ms":1768250244430,"raw":{"market":"0x2a12fd3d8235c25c062dc9652970ef9f635636c4018df0909e1a51c673e125cb","asset_id":"63670753354844494163057275310194312729998307779831462269530137743341854359908","best_bid":"0.85","best_ask":"0.86","spread":"0.01","timestamp":"1768250244430","event_type":"best_bid_ask"}}
{"schema_version":1,"source":"clob_ws_market","recv_ts_ns":1768250244728914764,"event_type":"price_change","market":"0x2a12fd3d8235c25c062dc9652970ef9f635636c4018df0909e1a51c673e125cb","server_ts_ms":1768250244429,"raw":{"market":"0x2a12fd3d8235c25c062dc9652970ef9f635636c4018df0909e1a51c673e125cb","price_changes":[{"asset_id":"56386988715176239099720172290594769295756680374928571099138069977179519358166","price":"0.14","size":"803.29","side":"BUY","hash":"5e19e8cf53c3cf4ba1d71d91c8d80f10cb47e88c","best_bid":"0.14","best_ask":"0.15"},{"asset_id":"63670753354844494163057275310194312729998307779831462269530137743341854359908","price":"0.86","size":"803.29","side":"SELL","hash":"89ff773f974cd068af99420c5587409f2574ec37","best_bid":"0.85","best_ask":"0.86"}],"timestamp":"1768250244429","event_type":"price_change"}}
